Build Started 21_01_2025_10_15_02
2025-01-21 10:15:13.856 7 INFO oslo_service.service [None req-a1c5ad72-a4e2-447b-b1fb-87c882820507 - - - - - -] Caught SIGTERM, stopping children
2025-01-21 10:15:13.867 7 INFO oslo_service.service [None req-a1c5ad72-a4e2-447b-b1fb-87c882820507 - - - - - -] Waiting on 1 children to exit
2025-01-21 10:15:15.452 25 ERROR cinder.service [-] Manager for service cinder-volume rack13-server67@LIGHTOSyilgqu is reporting problems, not sending heartbeat. Service will appear "down".
2025-01-21 10:15:16.697 25 WARNING amqp [None req-a1c5ad72-a4e2-447b-b1fb-87c882820507 - - - - - -] Received method (60, 30) during closing channel 1. This method will be ignored
2025-01-21 10:15:16.705 25 WARNING amqp [None req-a1c5ad72-a4e2-447b-b1fb-87c882820507 - - - - - -] Received method (60, 30) during closing channel 1. This method will be ignored
2025-01-21 10:15:16.712 25 WARNING amqp [None req-a1c5ad72-a4e2-447b-b1fb-87c882820507 - - - - - -] Received method (60, 30) during closing channel 1. This method will be ignored
2025-01-21 10:15:16.723 7 INFO oslo_service.service [None req-a1c5ad72-a4e2-447b-b1fb-87c882820507 - - - - - -] Child 25 exited with status 0
2025-01-21 10:15:31.922 7 INFO cinder.rpc [None req-56b6df71-dd5e-4cd7-a304-650689278f4c - - - - - -] Automatically selected cinder-scheduler objects version 1.39 as minimum service version.
2025-01-21 10:15:31.926 7 INFO cinder.rpc [None req-56b6df71-dd5e-4cd7-a304-650689278f4c - - - - - -] Automatically selected cinder-scheduler RPC version 3.12 as minimum service version.
2025-01-21 10:15:31.962 7 INFO cinder.volume.manager [None req-56b6df71-dd5e-4cd7-a304-650689278f4c - - - - - -] Determined volume DB was empty at startup.
2025-01-21 10:15:31.980 7 INFO cinder.volume.manager [None req-56b6df71-dd5e-4cd7-a304-650689278f4c - - - - - -] Image-volume cache disabled for host rack13-server67@LIGHTOSyilgqu.
2025-01-21 10:15:31.995 7 INFO oslo_service.service [None req-56b6df71-dd5e-4cd7-a304-650689278f4c - - - - - -] Starting 1 workers
2025-01-21 10:15:32.008 25 INFO cinder.service [-] Starting cinder-volume node (version 25.1.0)
2025-01-21 10:15:32.012 7 WARNING oslo_config.cfg [None req-56b6df71-dd5e-4cd7-a304-650689278f4c - - - - - -] Deprecated: Option "heartbeat_in_pthread" from group "oslo_messaging_rabbit" is deprecated for removal (The option is related to Eventlet which will be removed. In addition this has never worked as expected with services using eventlet for core service framework.).  Its value may be silently ignored in the future.
2025-01-21 10:15:32.027 25 INFO cinder.volume.manager [None req-a64abf7e-20c6-4725-9cfb-78c20b6d991f - - - - - -] Starting volume driver LightOSVolumeDriver (2.3.12)
2025-01-21 10:15:32.027 25 INFO cinder.volume.drivers.lightos [None req-a64abf7e-20c6-4725-9cfb-78c20b6d991f - - - - - -] Invoking get_cluster_info using GET url: /api/v2/clusterinfo             request.body: {} ssl_verify: False
2025-01-21 10:15:32.030 25 ERROR cinder.volume.drivers.lightos [None req-a64abf7e-20c6-4725-9cfb-78c20b6d991f - - - - - -] REST server not responding at 'https://[LB_IP_ADDRESS]:443/api/v2/clusterinfo': requests.exceptions.ConnectionError: HTTPSConnectionPool(host='[LB_IP_ADDRESS]', port=443): Max retries exceeded with url: /api/v2/clusterinfo (Caused by NewConnectionError('<urllib3.connection.HTTPSConnection object at 0x7f1a88d6dba0>: Failed to establish a new connection: [Errno 111] ECONNREFUSED'))
2025-01-21 10:15:32.030 25 ERROR cinder.volume.drivers.lightos Traceback (most recent call last):
2025-01-21 10:15:32.030 25 ERROR cinder.volume.drivers.lightos   File "/var/lib/kolla/venv/lib/python3.10/site-packages/urllib3/connection.py", line 174, in _new_conn
2025-01-21 10:15:32.030 25 ERROR cinder.volume.drivers.lightos     conn = connection.create_connection(
2025-01-21 10:15:32.030 25 ERROR cinder.volume.drivers.lightos   File "/var/lib/kolla/venv/lib/python3.10/site-packages/urllib3/util/connection.py", line 95, in create_connection
2025-01-21 10:15:32.030 25 ERROR cinder.volume.drivers.lightos     raise err
2025-01-21 10:15:32.030 25 ERROR cinder.volume.drivers.lightos   File "/var/lib/kolla/venv/lib/python3.10/site-packages/urllib3/util/connection.py", line 85, in create_connection
2025-01-21 10:15:32.030 25 ERROR cinder.volume.drivers.lightos     sock.connect(sa)
2025-01-21 10:15:32.030 25 ERROR cinder.volume.drivers.lightos   File "/var/lib/kolla/venv/lib/python3.10/site-packages/eventlet/greenio/base.py", line 265, in connect
2025-01-21 10:15:32.030 25 ERROR cinder.volume.drivers.lightos     socket_checkerr(fd)
2025-01-21 10:15:32.030 25 ERROR cinder.volume.drivers.lightos   File "/var/lib/kolla/venv/lib/python3.10/site-packages/eventlet/greenio/base.py", line 50, in socket_checkerr
2025-01-21 10:15:32.030 25 ERROR cinder.volume.drivers.lightos     raise OSError(err, errno.errorcode[err])
2025-01-21 10:15:32.030 25 ERROR cinder.volume.drivers.lightos ConnectionRefusedError: [Errno 111] ECONNREFUSED
2025-01-21 10:15:32.030 25 ERROR cinder.volume.drivers.lightos 
2025-01-21 10:15:32.030 25 ERROR cinder.volume.drivers.lightos During handling of the above exception, another exception occurred:
2025-01-21 10:15:32.030 25 ERROR cinder.volume.drivers.lightos 
2025-01-21 10:15:32.030 25 ERROR cinder.volume.drivers.lightos Traceback (most recent call last):
2025-01-21 10:15:32.030 25 ERROR cinder.volume.drivers.lightos   File "/var/lib/kolla/venv/lib/python3.10/site-packages/urllib3/connectionpool.py", line 715, in urlopen
2025-01-21 10:15:32.030 25 ERROR cinder.volume.drivers.lightos     httplib_response = self._make_request(
2025-01-21 10:15:32.030 25 ERROR cinder.volume.drivers.lightos   File "/var/lib/kolla/venv/lib/python3.10/site-packages/urllib3/connectionpool.py", line 404, in _make_request
2025-01-21 10:15:32.030 25 ERROR cinder.volume.drivers.lightos     self._validate_conn(conn)
2025-01-21 10:15:32.030 25 ERROR cinder.volume.drivers.lightos   File "/var/lib/kolla/venv/lib/python3.10/site-packages/urllib3/connectionpool.py", line 1060, in _validate_conn
2025-01-21 10:15:32.030 25 ERROR cinder.volume.drivers.lightos     conn.connect()
2025-01-21 10:15:32.030 25 ERROR cinder.volume.drivers.lightos   File "/var/lib/kolla/venv/lib/python3.10/site-packages/urllib3/connection.py", line 363, in connect
2025-01-21 10:15:32.030 25 ERROR cinder.volume.drivers.lightos     self.sock = conn = self._new_conn()
2025-01-21 10:15:32.030 25 ERROR cinder.volume.drivers.lightos   File "/var/lib/kolla/venv/lib/python3.10/site-packages/urllib3/connection.py", line 186, in _new_conn
2025-01-21 10:15:32.030 25 ERROR cinder.volume.drivers.lightos     raise NewConnectionError(
2025-01-21 10:15:32.030 25 ERROR cinder.volume.drivers.lightos urllib3.exceptions.NewConnectionError: <urllib3.connection.HTTPSConnection object at 0x7f1a88d6dba0>: Failed to establish a new connection: [Errno 111] ECONNREFUSED
2025-01-21 10:15:32.030 25 ERROR cinder.volume.drivers.lightos 
2025-01-21 10:15:32.030 25 ERROR cinder.volume.drivers.lightos During handling of the above exception, another exception occurred:
2025-01-21 10:15:32.030 25 ERROR cinder.volume.drivers.lightos 
2025-01-21 10:15:32.030 25 ERROR cinder.volume.drivers.lightos Traceback (most recent call last):
2025-01-21 10:15:32.030 25 ERROR cinder.volume.drivers.lightos   File "/var/lib/kolla/venv/lib/python3.10/site-packages/requests/adapters.py", line 667, in send
2025-01-21 10:15:32.030 25 ERROR cinder.volume.drivers.lightos     resp = conn.urlopen(
2025-01-21 10:15:32.030 25 ERROR cinder.volume.drivers.lightos   File "/var/lib/kolla/venv/lib/python3.10/site-packages/urllib3/connectionpool.py", line 801, in urlopen
2025-01-21 10:15:32.030 25 ERROR cinder.volume.drivers.lightos     retries = retries.increment(
2025-01-21 10:15:32.030 25 ERROR cinder.volume.drivers.lightos   File "/var/lib/kolla/venv/lib/python3.10/site-packages/urllib3/util/retry.py", line 594, in increment
2025-01-21 10:15:32.030 25 ERROR cinder.volume.drivers.lightos     raise MaxRetryError(_pool, url, error or ResponseError(cause))
2025-01-21 10:15:32.030 25 ERROR cinder.volume.drivers.lightos urllib3.exceptions.MaxRetryError: HTTPSConnectionPool(host='[LB_IP_ADDRESS]', port=443): Max retries exceeded with url: /api/v2/clusterinfo (Caused by NewConnectionError('<urllib3.connection.HTTPSConnection object at 0x7f1a88d6dba0>: Failed to establish a new connection: [Errno 111] ECONNREFUSED'))
2025-01-21 10:15:32.030 25 ERROR cinder.volume.drivers.lightos 
2025-01-21 10:15:32.030 25 ERROR cinder.volume.drivers.lightos During handling of the above exception, another exception occurred:
2025-01-21 10:15:32.030 25 ERROR cinder.volume.drivers.lightos 
2025-01-21 10:15:32.030 25 ERROR cinder.volume.drivers.lightos Traceback (most recent call last):
2025-01-21 10:15:32.030 25 ERROR cinder.volume.drivers.lightos   File "/var/lib/kolla/venv/lib/python3.10/site-packages/cinder/volume/drivers/lightos.py", line 356, in __send_cmd
2025-01-21 10:15:32.030 25 ERROR cinder.volume.drivers.lightos     response = session.send(
2025-01-21 10:15:32.030 25 ERROR cinder.volume.drivers.lightos   File "/var/lib/kolla/venv/lib/python3.10/site-packages/requests/sessions.py", line 703, in send
2025-01-21 10:15:32.030 25 ERROR cinder.volume.drivers.lightos     r = adapter.send(request, **kwargs)
2025-01-21 10:15:32.030 25 ERROR cinder.volume.drivers.lightos   File "/var/lib/kolla/venv/lib/python3.10/site-packages/requests/adapters.py", line 700, in send
2025-01-21 10:15:32.030 25 ERROR cinder.volume.drivers.lightos     raise ConnectionError(e, request=request)
2025-01-21 10:15:32.030 25 ERROR cinder.volume.drivers.lightos requests.exceptions.ConnectionError: HTTPSConnectionPool(host='[LB_IP_ADDRESS]', port=443): Max retries exceeded with url: /api/v2/clusterinfo (Caused by NewConnectionError('<urllib3.connection.HTTPSConnection object at 0x7f1a88d6dba0>: Failed to establish a new connection: [Errno 111] ECONNREFUSED'))
2025-01-21 10:15:32.030 25 ERROR cinder.volume.drivers.lightos 
2025-01-21 10:15:32.032 25 INFO cinder.volume.drivers.lightos [None req-a64abf7e-20c6-4725-9cfb-78c20b6d991f - - - - - -] Invoking get_cluster_info using GET url: /api/v2/clusterinfo             request.body: {} ssl_verify: False
2025-01-21 10:15:32.033 25 ERROR cinder.volume.drivers.lightos [None req-a64abf7e-20c6-4725-9cfb-78c20b6d991f - - - - - -] REST server not responding at 'https://[LB_IP_ADDRESS]:443/api/v2/clusterinfo': requests.exceptions.ConnectionError: HTTPSConnectionPool(host='[LB_IP_ADDRESS]', port=443): Max retries exceeded with url: /api/v2/clusterinfo (Caused by NewConnectionError('<urllib3.connection.HTTPSConnection object at 0x7f1a88d6cee0>: Failed to establish a new connection: [Errno 111] ECONNREFUSED'))
2025-01-21 10:15:32.033 25 ERROR cinder.volume.drivers.lightos Traceback (most recent call last):
2025-01-21 10:15:32.033 25 ERROR cinder.volume.drivers.lightos   File "/var/lib/kolla/venv/lib/python3.10/site-packages/urllib3/connection.py", line 174, in _new_conn
2025-01-21 10:15:32.033 25 ERROR cinder.volume.drivers.lightos     conn = connection.create_connection(
2025-01-21 10:15:32.033 25 ERROR cinder.volume.drivers.lightos   File "/var/lib/kolla/venv/lib/python3.10/site-packages/urllib3/util/connection.py", line 95, in create_connection
2025-01-21 10:15:32.033 25 ERROR cinder.volume.drivers.lightos     raise err
2025-01-21 10:15:32.033 25 ERROR cinder.volume.drivers.lightos   File "/var/lib/kolla/venv/lib/python3.10/site-packages/urllib3/util/connection.py", line 85, in create_connection
2025-01-21 10:15:32.033 25 ERROR cinder.volume.drivers.lightos     sock.connect(sa)
2025-01-21 10:15:32.033 25 ERROR cinder.volume.drivers.lightos   File "/var/lib/kolla/venv/lib/python3.10/site-packages/eventlet/greenio/base.py", line 265, in connect
2025-01-21 10:15:32.033 25 ERROR cinder.volume.drivers.lightos     socket_checkerr(fd)
2025-01-21 10:15:32.033 25 ERROR cinder.volume.drivers.lightos   File "/var/lib/kolla/venv/lib/python3.10/site-packages/eventlet/greenio/base.py", line 50, in socket_checkerr
2025-01-21 10:15:32.033 25 ERROR cinder.volume.drivers.lightos     raise OSError(err, errno.errorcode[err])
2025-01-21 10:15:32.033 25 ERROR cinder.volume.drivers.lightos ConnectionRefusedError: [Errno 111] ECONNREFUSED
2025-01-21 10:15:32.033 25 ERROR cinder.volume.drivers.lightos 
2025-01-21 10:15:32.033 25 ERROR cinder.volume.drivers.lightos During handling of the above exception, another exception occurred:
2025-01-21 10:15:32.033 25 ERROR cinder.volume.drivers.lightos 
2025-01-21 10:15:32.033 25 ERROR cinder.volume.drivers.lightos Traceback (most recent call last):
2025-01-21 10:15:32.033 25 ERROR cinder.volume.drivers.lightos   File "/var/lib/kolla/venv/lib/python3.10/site-packages/urllib3/connectionpool.py", line 715, in urlopen
2025-01-21 10:15:32.033 25 ERROR cinder.volume.drivers.lightos     httplib_response = self._make_request(
2025-01-21 10:15:32.033 25 ERROR cinder.volume.drivers.lightos   File "/var/lib/kolla/venv/lib/python3.10/site-packages/urllib3/connectionpool.py", line 404, in _make_request
2025-01-21 10:15:32.033 25 ERROR cinder.volume.drivers.lightos     self._validate_conn(conn)
2025-01-21 10:15:32.033 25 ERROR cinder.volume.drivers.lightos   File "/var/lib/kolla/venv/lib/python3.10/site-packages/urllib3/connectionpool.py", line 1060, in _validate_conn
2025-01-21 10:15:32.033 25 ERROR cinder.volume.drivers.lightos     conn.connect()
2025-01-21 10:15:32.033 25 ERROR cinder.volume.drivers.lightos   File "/var/lib/kolla/venv/lib/python3.10/site-packages/urllib3/connection.py", line 363, in connect
2025-01-21 10:15:32.033 25 ERROR cinder.volume.drivers.lightos     self.sock = conn = self._new_conn()
2025-01-21 10:15:32.033 25 ERROR cinder.volume.drivers.lightos   File "/var/lib/kolla/venv/lib/python3.10/site-packages/urllib3/connection.py", line 186, in _new_conn
2025-01-21 10:15:32.033 25 ERROR cinder.volume.drivers.lightos     raise NewConnectionError(
2025-01-21 10:15:32.033 25 ERROR cinder.volume.drivers.lightos urllib3.exceptions.NewConnectionError: <urllib3.connection.HTTPSConnection object at 0x7f1a88d6cee0>: Failed to establish a new connection: [Errno 111] ECONNREFUSED
2025-01-21 10:15:32.033 25 ERROR cinder.volume.drivers.lightos 
2025-01-21 10:15:32.033 25 ERROR cinder.volume.drivers.lightos During handling of the above exception, another exception occurred:
2025-01-21 10:15:32.033 25 ERROR cinder.volume.drivers.lightos 
2025-01-21 10:15:32.033 25 ERROR cinder.volume.drivers.lightos Traceback (most recent call last):
2025-01-21 10:15:32.033 25 ERROR cinder.volume.drivers.lightos   File "/var/lib/kolla/venv/lib/python3.10/site-packages/requests/adapters.py", line 667, in send
2025-01-21 10:15:32.033 25 ERROR cinder.volume.drivers.lightos     resp = conn.urlopen(
2025-01-21 10:15:32.033 25 ERROR cinder.volume.drivers.lightos   File "/var/lib/kolla/venv/lib/python3.10/site-packages/urllib3/connectionpool.py", line 801, in urlopen
2025-01-21 10:15:32.033 25 ERROR cinder.volume.drivers.lightos     retries = retries.increment(
2025-01-21 10:15:32.033 25 ERROR cinder.volume.drivers.lightos   File "/var/lib/kolla/venv/lib/python3.10/site-packages/urllib3/util/retry.py", line 594, in increment
2025-01-21 10:15:32.033 25 ERROR cinder.volume.drivers.lightos     raise MaxRetryError(_pool, url, error or ResponseError(cause))
2025-01-21 10:15:32.033 25 ERROR cinder.volume.drivers.lightos urllib3.exceptions.MaxRetryError: HTTPSConnectionPool(host='[LB_IP_ADDRESS]', port=443): Max retries exceeded with url: /api/v2/clusterinfo (Caused by NewConnectionError('<urllib3.connection.HTTPSConnection object at 0x7f1a88d6cee0>: Failed to establish a new connection: [Errno 111] ECONNREFUSED'))
2025-01-21 10:15:32.033 25 ERROR cinder.volume.drivers.lightos 
2025-01-21 10:15:32.033 25 ERROR cinder.volume.drivers.lightos During handling of the above exception, another exception occurred:
2025-01-21 10:15:32.033 25 ERROR cinder.volume.drivers.lightos 
2025-01-21 10:15:32.033 25 ERROR cinder.volume.drivers.lightos Traceback (most recent call last):
2025-01-21 10:15:32.033 25 ERROR cinder.volume.drivers.lightos   File "/var/lib/kolla/venv/lib/python3.10/site-packages/cinder/volume/drivers/lightos.py", line 356, in __send_cmd
2025-01-21 10:15:32.033 25 ERROR cinder.volume.drivers.lightos     response = session.send(
2025-01-21 10:15:32.033 25 ERROR cinder.volume.drivers.lightos   File "/var/lib/kolla/venv/lib/python3.10/site-packages/requests/sessions.py", line 703, in send
2025-01-21 10:15:32.033 25 ERROR cinder.volume.drivers.lightos     r = adapter.send(request, **kwargs)
2025-01-21 10:15:32.033 25 ERROR cinder.volume.drivers.lightos   File "/var/lib/kolla/venv/lib/python3.10/site-packages/requests/adapters.py", line 700, in send
2025-01-21 10:15:32.033 25 ERROR cinder.volume.drivers.lightos     raise ConnectionError(e, request=request)
2025-01-21 10:15:32.033 25 ERROR cinder.volume.drivers.lightos requests.exceptions.ConnectionError: HTTPSConnectionPool(host='[LB_IP_ADDRESS]', port=443): Max retries exceeded with url: /api/v2/clusterinfo (Caused by NewConnectionError('<urllib3.connection.HTTPSConnection object at 0x7f1a88d6cee0>: Failed to establish a new connection: [Errno 111] ECONNREFUSED'))
2025-01-21 10:15:32.033 25 ERROR cinder.volume.drivers.lightos 
2025-01-21 10:15:32.033 25 INFO cinder.volume.drivers.lightos [None req-a64abf7e-20c6-4725-9cfb-78c20b6d991f - - - - - -] Invoking get_cluster_info using GET url: /api/v2/clusterinfo             request.body: {} ssl_verify: False
2025-01-21 10:15:35.106 25 ERROR cinder.volume.drivers.lightos [None req-a64abf7e-20c6-4725-9cfb-78c20b6d991f - - - - - -] REST server not responding at 'https://[LB_IP_ADDRESS]:443/api/v2/clusterinfo': requests.exceptions.ConnectionError: HTTPSConnectionPool(host='[LB_IP_ADDRESS]', port=443): Max retries exceeded with url: /api/v2/clusterinfo (Caused by NewConnectionError('<urllib3.connection.HTTPSConnection object at 0x7f1a88d6c400>: Failed to establish a new connection: [Errno 113] EHOSTUNREACH'))
2025-01-21 10:15:35.106 25 ERROR cinder.volume.drivers.lightos Traceback (most recent call last):
2025-01-21 10:15:35.106 25 ERROR cinder.volume.drivers.lightos   File "/var/lib/kolla/venv/lib/python3.10/site-packages/urllib3/connection.py", line 174, in _new_conn
2025-01-21 10:15:35.106 25 ERROR cinder.volume.drivers.lightos     conn = connection.create_connection(
2025-01-21 10:15:35.106 25 ERROR cinder.volume.drivers.lightos   File "/var/lib/kolla/venv/lib/python3.10/site-packages/urllib3/util/connection.py", line 95, in create_connection
2025-01-21 10:15:35.106 25 ERROR cinder.volume.drivers.lightos     raise err
2025-01-21 10:15:35.106 25 ERROR cinder.volume.drivers.lightos   File "/var/lib/kolla/venv/lib/python3.10/site-packages/urllib3/util/connection.py", line 85, in create_connection
2025-01-21 10:15:35.106 25 ERROR cinder.volume.drivers.lightos     sock.connect(sa)
2025-01-21 10:15:35.106 25 ERROR cinder.volume.drivers.lightos   File "/var/lib/kolla/venv/lib/python3.10/site-packages/eventlet/greenio/base.py", line 265, in connect
2025-01-21 10:15:35.106 25 ERROR cinder.volume.drivers.lightos     socket_checkerr(fd)
2025-01-21 10:15:35.106 25 ERROR cinder.volume.drivers.lightos   File "/var/lib/kolla/venv/lib/python3.10/site-packages/eventlet/greenio/base.py", line 50, in socket_checkerr
2025-01-21 10:15:35.106 25 ERROR cinder.volume.drivers.lightos     raise OSError(err, errno.errorcode[err])
2025-01-21 10:15:35.106 25 ERROR cinder.volume.drivers.lightos OSError: [Errno 113] EHOSTUNREACH
2025-01-21 10:15:35.106 25 ERROR cinder.volume.drivers.lightos 
2025-01-21 10:15:35.106 25 ERROR cinder.volume.drivers.lightos During handling of the above exception, another exception occurred:
2025-01-21 10:15:35.106 25 ERROR cinder.volume.drivers.lightos 
2025-01-21 10:15:35.106 25 ERROR cinder.volume.drivers.lightos Traceback (most recent call last):
2025-01-21 10:15:35.106 25 ERROR cinder.volume.drivers.lightos   File "/var/lib/kolla/venv/lib/python3.10/site-packages/urllib3/connectionpool.py", line 715, in urlopen
2025-01-21 10:15:35.106 25 ERROR cinder.volume.drivers.lightos     httplib_response = self._make_request(
2025-01-21 10:15:35.106 25 ERROR cinder.volume.drivers.lightos   File "/var/lib/kolla/venv/lib/python3.10/site-packages/urllib3/connectionpool.py", line 404, in _make_request
2025-01-21 10:15:35.106 25 ERROR cinder.volume.drivers.lightos     self._validate_conn(conn)
2025-01-21 10:15:35.106 25 ERROR cinder.volume.drivers.lightos   File "/var/lib/kolla/venv/lib/python3.10/site-packages/urllib3/connectionpool.py", line 1060, in _validate_conn
2025-01-21 10:15:35.106 25 ERROR cinder.volume.drivers.lightos     conn.connect()
2025-01-21 10:15:35.106 25 ERROR cinder.volume.drivers.lightos   File "/var/lib/kolla/venv/lib/python3.10/site-packages/urllib3/connection.py", line 363, in connect
2025-01-21 10:15:35.106 25 ERROR cinder.volume.drivers.lightos     self.sock = conn = self._new_conn()
2025-01-21 10:15:35.106 25 ERROR cinder.volume.drivers.lightos   File "/var/lib/kolla/venv/lib/python3.10/site-packages/urllib3/connection.py", line 186, in _new_conn
2025-01-21 10:15:35.106 25 ERROR cinder.volume.drivers.lightos     raise NewConnectionError(
2025-01-21 10:15:35.106 25 ERROR cinder.volume.drivers.lightos urllib3.exceptions.NewConnectionError: <urllib3.connection.HTTPSConnection object at 0x7f1a88d6c400>: Failed to establish a new connection: [Errno 113] EHOSTUNREACH
2025-01-21 10:15:35.106 25 ERROR cinder.volume.drivers.lightos 
2025-01-21 10:15:35.106 25 ERROR cinder.volume.drivers.lightos During handling of the above exception, another exception occurred:
2025-01-21 10:15:35.106 25 ERROR cinder.volume.drivers.lightos 
2025-01-21 10:15:35.106 25 ERROR cinder.volume.drivers.lightos Traceback (most recent call last):
2025-01-21 10:15:35.106 25 ERROR cinder.volume.drivers.lightos   File "/var/lib/kolla/venv/lib/python3.10/site-packages/requests/adapters.py", line 667, in send
2025-01-21 10:15:35.106 25 ERROR cinder.volume.drivers.lightos     resp = conn.urlopen(
2025-01-21 10:15:35.106 25 ERROR cinder.volume.drivers.lightos   File "/var/lib/kolla/venv/lib/python3.10/site-packages/urllib3/connectionpool.py", line 801, in urlopen
2025-01-21 10:15:35.106 25 ERROR cinder.volume.drivers.lightos     retries = retries.increment(
2025-01-21 10:15:35.106 25 ERROR cinder.volume.drivers.lightos   File "/var/lib/kolla/venv/lib/python3.10/site-packages/urllib3/util/retry.py", line 594, in increment
2025-01-21 10:15:35.106 25 ERROR cinder.volume.drivers.lightos     raise MaxRetryError(_pool, url, error or ResponseError(cause))
2025-01-21 10:15:35.106 25 ERROR cinder.volume.drivers.lightos urllib3.exceptions.MaxRetryError: HTTPSConnectionPool(host='[LB_IP_ADDRESS]', port=443): Max retries exceeded with url: /api/v2/clusterinfo (Caused by NewConnectionError('<urllib3.connection.HTTPSConnection object at 0x7f1a88d6c400>: Failed to establish a new connection: [Errno 113] EHOSTUNREACH'))
2025-01-21 10:15:35.106 25 ERROR cinder.volume.drivers.lightos 
2025-01-21 10:15:35.106 25 ERROR cinder.volume.drivers.lightos During handling of the above exception, another exception occurred:
2025-01-21 10:15:35.106 25 ERROR cinder.volume.drivers.lightos 
2025-01-21 10:15:35.106 25 ERROR cinder.volume.drivers.lightos Traceback (most recent call last):
2025-01-21 10:15:35.106 25 ERROR cinder.volume.drivers.lightos   File "/var/lib/kolla/venv/lib/python3.10/site-packages/cinder/volume/drivers/lightos.py", line 356, in __send_cmd
2025-01-21 10:15:35.106 25 ERROR cinder.volume.drivers.lightos     response = session.send(
2025-01-21 10:15:35.106 25 ERROR cinder.volume.drivers.lightos   File "/var/lib/kolla/venv/lib/python3.10/site-packages/requests/sessions.py", line 703, in send
2025-01-21 10:15:35.106 25 ERROR cinder.volume.drivers.lightos     r = adapter.send(request, **kwargs)
2025-01-21 10:15:35.106 25 ERROR cinder.volume.drivers.lightos   File "/var/lib/kolla/venv/lib/python3.10/site-packages/requests/adapters.py", line 700, in send
2025-01-21 10:15:35.106 25 ERROR cinder.volume.drivers.lightos     raise ConnectionError(e, request=request)
2025-01-21 10:15:35.106 25 ERROR cinder.volume.drivers.lightos requests.exceptions.ConnectionError: HTTPSConnectionPool(host='[LB_IP_ADDRESS]', port=443): Max retries exceeded with url: /api/v2/clusterinfo (Caused by NewConnectionError('<urllib3.connection.HTTPSConnection object at 0x7f1a88d6c400>: Failed to establish a new connection: [Errno 113] EHOSTUNREACH'))
2025-01-21 10:15:35.106 25 ERROR cinder.volume.drivers.lightos 
2025-01-21 10:15:35.108 25 ERROR cinder.volume.manager [None req-a64abf7e-20c6-4725-9cfb-78c20b6d991f - - - - - -] Failed to initialize driver.: cinder.exception.VolumeDriverException: Volume driver reported an error: Could not get a response from any API server
2025-01-21 10:15:35.108 25 ERROR cinder.volume.manager Traceback (most recent call last):
2025-01-21 10:15:35.108 25 ERROR cinder.volume.manager   File "/var/lib/kolla/venv/lib/python3.10/site-packages/cinder/volume/manager.py", line 523, in _init_host
2025-01-21 10:15:35.108 25 ERROR cinder.volume.manager     self.driver.do_setup(ctxt)
2025-01-21 10:15:35.108 25 ERROR cinder.volume.manager   File "/var/lib/kolla/venv/lib/python3.10/site-packages/cinder/volume/drivers/lightos.py", line 922, in do_setup
2025-01-21 10:15:35.108 25 ERROR cinder.volume.manager     self.get_cluster_info()
2025-01-21 10:15:35.108 25 ERROR cinder.volume.manager   File "/var/lib/kolla/venv/lib/python3.10/site-packages/cinder/volume/drivers/lightos.py", line 873, in get_cluster_info
2025-01-21 10:15:35.108 25 ERROR cinder.volume.manager     status_code, cluster_info = self.cluster.send_cmd(
2025-01-21 10:15:35.108 25 ERROR cinder.volume.manager   File "/var/lib/kolla/venv/lib/python3.10/site-packages/cinder/volume/drivers/lightos.py", line 315, in send_cmd
2025-01-21 10:15:35.108 25 ERROR cinder.volume.manager     raise exception.VolumeDriverException(
2025-01-21 10:15:35.108 25 ERROR cinder.volume.manager cinder.exception.VolumeDriverException: Volume driver reported an error: Could not get a response from any API server
2025-01-21 10:15:35.108 25 ERROR cinder.volume.manager 
2025-01-21 10:15:36.113 25 INFO cinder.volume.manager [None req-a64abf7e-20c6-4725-9cfb-78c20b6d991f - - - - - -] Starting volume driver LightOSVolumeDriver (2.3.12)
2025-01-21 10:15:36.114 25 INFO cinder.volume.drivers.lightos [None req-a64abf7e-20c6-4725-9cfb-78c20b6d991f - - - - - -] Invoking get_cluster_info using GET url: /api/v2/clusterinfo             request.body: {} ssl_verify: False
2025-01-21 10:15:36.118 25 ERROR cinder.volume.drivers.lightos [None req-a64abf7e-20c6-4725-9cfb-78c20b6d991f - - - - - -] REST server not responding at 'https://[LB_IP_ADDRESS]:443/api/v2/clusterinfo': requests.exceptions.ConnectionError: HTTPSConnectionPool(host='[LB_IP_ADDRESS]', port=443): Max retries exceeded with url: /api/v2/clusterinfo (Caused by NewConnectionError('<urllib3.connection.HTTPSConnection object at 0x7f1a88d6c790>: Failed to establish a new connection: [Errno 111] ECONNREFUSED'))
2025-01-21 10:15:36.118 25 ERROR cinder.volume.drivers.lightos Traceback (most recent call last):
2025-01-21 10:15:36.118 25 ERROR cinder.volume.drivers.lightos   File "/var/lib/kolla/venv/lib/python3.10/site-packages/urllib3/connection.py", line 174, in _new_conn
2025-01-21 10:15:36.118 25 ERROR cinder.volume.drivers.lightos     conn = connection.create_connection(
2025-01-21 10:15:36.118 25 ERROR cinder.volume.drivers.lightos   File "/var/lib/kolla/venv/lib/python3.10/site-packages/urllib3/util/connection.py", line 95, in create_connection
2025-01-21 10:15:36.118 25 ERROR cinder.volume.drivers.lightos     raise err
2025-01-21 10:15:36.118 25 ERROR cinder.volume.drivers.lightos   File "/var/lib/kolla/venv/lib/python3.10/site-packages/urllib3/util/connection.py", line 85, in create_connection
2025-01-21 10:15:36.118 25 ERROR cinder.volume.drivers.lightos     sock.connect(sa)
2025-01-21 10:15:36.118 25 ERROR cinder.volume.drivers.lightos   File "/var/lib/kolla/venv/lib/python3.10/site-packages/eventlet/greenio/base.py", line 265, in connect
2025-01-21 10:15:36.118 25 ERROR cinder.volume.drivers.lightos     socket_checkerr(fd)
2025-01-21 10:15:36.118 25 ERROR cinder.volume.drivers.lightos   File "/var/lib/kolla/venv/lib/python3.10/site-packages/eventlet/greenio/base.py", line 50, in socket_checkerr
2025-01-21 10:15:36.118 25 ERROR cinder.volume.drivers.lightos     raise OSError(err, errno.errorcode[err])
2025-01-21 10:15:36.118 25 ERROR cinder.volume.drivers.lightos ConnectionRefusedError: [Errno 111] ECONNREFUSED
2025-01-21 10:15:36.118 25 ERROR cinder.volume.drivers.lightos 
2025-01-21 10:15:36.118 25 ERROR cinder.volume.drivers.lightos During handling of the above exception, another exception occurred:
2025-01-21 10:15:36.118 25 ERROR cinder.volume.drivers.lightos 
2025-01-21 10:15:36.118 25 ERROR cinder.volume.drivers.lightos Traceback (most recent call last):
2025-01-21 10:15:36.118 25 ERROR cinder.volume.drivers.lightos   File "/var/lib/kolla/venv/lib/python3.10/site-packages/urllib3/connectionpool.py", line 715, in urlopen
2025-01-21 10:15:36.118 25 ERROR cinder.volume.drivers.lightos     httplib_response = self._make_request(
2025-01-21 10:15:36.118 25 ERROR cinder.volume.drivers.lightos   File "/var/lib/kolla/venv/lib/python3.10/site-packages/urllib3/connectionpool.py", line 404, in _make_request
2025-01-21 10:15:36.118 25 ERROR cinder.volume.drivers.lightos     self._validate_conn(conn)
2025-01-21 10:15:36.118 25 ERROR cinder.volume.drivers.lightos   File "/var/lib/kolla/venv/lib/python3.10/site-packages/urllib3/connectionpool.py", line 1060, in _validate_conn
2025-01-21 10:15:36.118 25 ERROR cinder.volume.drivers.lightos     conn.connect()
2025-01-21 10:15:36.118 25 ERROR cinder.volume.drivers.lightos   File "/var/lib/kolla/venv/lib/python3.10/site-packages/urllib3/connection.py", line 363, in connect
2025-01-21 10:15:36.118 25 ERROR cinder.volume.drivers.lightos     self.sock = conn = self._new_conn()
2025-01-21 10:15:36.118 25 ERROR cinder.volume.drivers.lightos   File "/var/lib/kolla/venv/lib/python3.10/site-packages/urllib3/connection.py", line 186, in _new_conn
2025-01-21 10:15:36.118 25 ERROR cinder.volume.drivers.lightos     raise NewConnectionError(
2025-01-21 10:15:36.118 25 ERROR cinder.volume.drivers.lightos urllib3.exceptions.NewConnectionError: <urllib3.connection.HTTPSConnection object at 0x7f1a88d6c790>: Failed to establish a new connection: [Errno 111] ECONNREFUSED
2025-01-21 10:15:36.118 25 ERROR cinder.volume.drivers.lightos 
2025-01-21 10:15:36.118 25 ERROR cinder.volume.drivers.lightos During handling of the above exception, another exception occurred:
2025-01-21 10:15:36.118 25 ERROR cinder.volume.drivers.lightos 
2025-01-21 10:15:36.118 25 ERROR cinder.volume.drivers.lightos Traceback (most recent call last):
2025-01-21 10:15:36.118 25 ERROR cinder.volume.drivers.lightos   File "/var/lib/kolla/venv/lib/python3.10/site-packages/requests/adapters.py", line 667, in send
2025-01-21 10:15:36.118 25 ERROR cinder.volume.drivers.lightos     resp = conn.urlopen(
2025-01-21 10:15:36.118 25 ERROR cinder.volume.drivers.lightos   File "/var/lib/kolla/venv/lib/python3.10/site-packages/urllib3/connectionpool.py", line 801, in urlopen
2025-01-21 10:15:36.118 25 ERROR cinder.volume.drivers.lightos     retries = retries.increment(
2025-01-21 10:15:36.118 25 ERROR cinder.volume.drivers.lightos   File "/var/lib/kolla/venv/lib/python3.10/site-packages/urllib3/util/retry.py", line 594, in increment
2025-01-21 10:15:36.118 25 ERROR cinder.volume.drivers.lightos     raise MaxRetryError(_pool, url, error or ResponseError(cause))
2025-01-21 10:15:36.118 25 ERROR cinder.volume.drivers.lightos urllib3.exceptions.MaxRetryError: HTTPSConnectionPool(host='[LB_IP_ADDRESS]', port=443): Max retries exceeded with url: /api/v2/clusterinfo (Caused by NewConnectionError('<urllib3.connection.HTTPSConnection object at 0x7f1a88d6c790>: Failed to establish a new connection: [Errno 111] ECONNREFUSED'))
2025-01-21 10:15:36.118 25 ERROR cinder.volume.drivers.lightos 
2025-01-21 10:15:36.118 25 ERROR cinder.volume.drivers.lightos During handling of the above exception, another exception occurred:
2025-01-21 10:15:36.118 25 ERROR cinder.volume.drivers.lightos 
2025-01-21 10:15:36.118 25 ERROR cinder.volume.drivers.lightos Traceback (most recent call last):
2025-01-21 10:15:36.118 25 ERROR cinder.volume.drivers.lightos   File "/var/lib/kolla/venv/lib/python3.10/site-packages/cinder/volume/drivers/lightos.py", line 356, in __send_cmd
2025-01-21 10:15:36.118 25 ERROR cinder.volume.drivers.lightos     response = session.send(
2025-01-21 10:15:36.118 25 ERROR cinder.volume.drivers.lightos   File "/var/lib/kolla/venv/lib/python3.10/site-packages/requests/sessions.py", line 703, in send
2025-01-21 10:15:36.118 25 ERROR cinder.volume.drivers.lightos     r = adapter.send(request, **kwargs)
2025-01-21 10:15:36.118 25 ERROR cinder.volume.drivers.lightos   File "/var/lib/kolla/venv/lib/python3.10/site-packages/requests/adapters.py", line 700, in send
2025-01-21 10:15:36.118 25 ERROR cinder.volume.drivers.lightos     raise ConnectionError(e, request=request)
2025-01-21 10:15:36.118 25 ERROR cinder.volume.drivers.lightos requests.exceptions.ConnectionError: HTTPSConnectionPool(host='[LB_IP_ADDRESS]', port=443): Max retries exceeded with url: /api/v2/clusterinfo (Caused by NewConnectionError('<urllib3.connection.HTTPSConnection object at 0x7f1a88d6c790>: Failed to establish a new connection: [Errno 111] ECONNREFUSED'))
2025-01-21 10:15:36.118 25 ERROR cinder.volume.drivers.lightos 
2025-01-21 10:15:36.120 25 INFO cinder.volume.drivers.lightos [None req-a64abf7e-20c6-4725-9cfb-78c20b6d991f - - - - - -] Invoking get_cluster_info using GET url: /api/v2/clusterinfo             request.body: {} ssl_verify: False
2025-01-21 10:15:36.122 25 ERROR cinder.volume.drivers.lightos [None req-a64abf7e-20c6-4725-9cfb-78c20b6d991f - - - - - -] REST server not responding at 'https://[LB_IP_ADDRESS]:443/api/v2/clusterinfo': requests.exceptions.ConnectionError: HTTPSConnectionPool(host='[LB_IP_ADDRESS]', port=443): Max retries exceeded with url: /api/v2/clusterinfo (Caused by NewConnectionError('<urllib3.connection.HTTPSConnection object at 0x7f1a88d6d1e0>: Failed to establish a new connection: [Errno 111] ECONNREFUSED'))
2025-01-21 10:15:36.122 25 ERROR cinder.volume.drivers.lightos Traceback (most recent call last):
2025-01-21 10:15:36.122 25 ERROR cinder.volume.drivers.lightos   File "/var/lib/kolla/venv/lib/python3.10/site-packages/urllib3/connection.py", line 174, in _new_conn
2025-01-21 10:15:36.122 25 ERROR cinder.volume.drivers.lightos     conn = connection.create_connection(
2025-01-21 10:15:36.122 25 ERROR cinder.volume.drivers.lightos   File "/var/lib/kolla/venv/lib/python3.10/site-packages/urllib3/util/connection.py", line 95, in create_connection
2025-01-21 10:15:36.122 25 ERROR cinder.volume.drivers.lightos     raise err
2025-01-21 10:15:36.122 25 ERROR cinder.volume.drivers.lightos   File "/var/lib/kolla/venv/lib/python3.10/site-packages/urllib3/util/connection.py", line 85, in create_connection
2025-01-21 10:15:36.122 25 ERROR cinder.volume.drivers.lightos     sock.connect(sa)
2025-01-21 10:15:36.122 25 ERROR cinder.volume.drivers.lightos   File "/var/lib/kolla/venv/lib/python3.10/site-packages/eventlet/greenio/base.py", line 265, in connect
2025-01-21 10:15:36.122 25 ERROR cinder.volume.drivers.lightos     socket_checkerr(fd)
2025-01-21 10:15:36.122 25 ERROR cinder.volume.drivers.lightos   File "/var/lib/kolla/venv/lib/python3.10/site-packages/eventlet/greenio/base.py", line 50, in socket_checkerr
2025-01-21 10:15:36.122 25 ERROR cinder.volume.drivers.lightos     raise OSError(err, errno.errorcode[err])
2025-01-21 10:15:36.122 25 ERROR cinder.volume.drivers.lightos ConnectionRefusedError: [Errno 111] ECONNREFUSED
2025-01-21 10:15:36.122 25 ERROR cinder.volume.drivers.lightos 
2025-01-21 10:15:36.122 25 ERROR cinder.volume.drivers.lightos During handling of the above exception, another exception occurred:
2025-01-21 10:15:36.122 25 ERROR cinder.volume.drivers.lightos 
2025-01-21 10:15:36.122 25 ERROR cinder.volume.drivers.lightos Traceback (most recent call last):
2025-01-21 10:15:36.122 25 ERROR cinder.volume.drivers.lightos   File "/var/lib/kolla/venv/lib/python3.10/site-packages/urllib3/connectionpool.py", line 715, in urlopen
2025-01-21 10:15:36.122 25 ERROR cinder.volume.drivers.lightos     httplib_response = self._make_request(
2025-01-21 10:15:36.122 25 ERROR cinder.volume.drivers.lightos   File "/var/lib/kolla/venv/lib/python3.10/site-packages/urllib3/connectionpool.py", line 404, in _make_request
2025-01-21 10:15:36.122 25 ERROR cinder.volume.drivers.lightos     self._validate_conn(conn)
2025-01-21 10:15:36.122 25 ERROR cinder.volume.drivers.lightos   File "/var/lib/kolla/venv/lib/python3.10/site-packages/urllib3/connectionpool.py", line 1060, in _validate_conn
2025-01-21 10:15:36.122 25 ERROR cinder.volume.drivers.lightos     conn.connect()
2025-01-21 10:15:36.122 25 ERROR cinder.volume.drivers.lightos   File "/var/lib/kolla/venv/lib/python3.10/site-packages/urllib3/connection.py", line 363, in connect
2025-01-21 10:15:36.122 25 ERROR cinder.volume.drivers.lightos     self.sock = conn = self._new_conn()
2025-01-21 10:15:36.122 25 ERROR cinder.volume.drivers.lightos   File "/var/lib/kolla/venv/lib/python3.10/site-packages/urllib3/connection.py", line 186, in _new_conn
2025-01-21 10:15:36.122 25 ERROR cinder.volume.drivers.lightos     raise NewConnectionError(
2025-01-21 10:15:36.122 25 ERROR cinder.volume.drivers.lightos urllib3.exceptions.NewConnectionError: <urllib3.connection.HTTPSConnection object at 0x7f1a88d6d1e0>: Failed to establish a new connection: [Errno 111] ECONNREFUSED
2025-01-21 10:15:36.122 25 ERROR cinder.volume.drivers.lightos 
2025-01-21 10:15:36.122 25 ERROR cinder.volume.drivers.lightos During handling of the above exception, another exception occurred:
2025-01-21 10:15:36.122 25 ERROR cinder.volume.drivers.lightos 
2025-01-21 10:15:36.122 25 ERROR cinder.volume.drivers.lightos Traceback (most recent call last):
2025-01-21 10:15:36.122 25 ERROR cinder.volume.drivers.lightos   File "/var/lib/kolla/venv/lib/python3.10/site-packages/requests/adapters.py", line 667, in send
2025-01-21 10:15:36.122 25 ERROR cinder.volume.drivers.lightos     resp = conn.urlopen(
2025-01-21 10:15:36.122 25 ERROR cinder.volume.drivers.lightos   File "/var/lib/kolla/venv/lib/python3.10/site-packages/urllib3/connectionpool.py", line 801, in urlopen
2025-01-21 10:15:36.122 25 ERROR cinder.volume.drivers.lightos     retries = retries.increment(
2025-01-21 10:15:36.122 25 ERROR cinder.volume.drivers.lightos   File "/var/lib/kolla/venv/lib/python3.10/site-packages/urllib3/util/retry.py", line 594, in increment
2025-01-21 10:15:36.122 25 ERROR cinder.volume.drivers.lightos     raise MaxRetryError(_pool, url, error or ResponseError(cause))
2025-01-21 10:15:36.122 25 ERROR cinder.volume.drivers.lightos urllib3.exceptions.MaxRetryError: HTTPSConnectionPool(host='[LB_IP_ADDRESS]', port=443): Max retries exceeded with url: /api/v2/clusterinfo (Caused by NewConnectionError('<urllib3.connection.HTTPSConnection object at 0x7f1a88d6d1e0>: Failed to establish a new connection: [Errno 111] ECONNREFUSED'))
2025-01-21 10:15:36.122 25 ERROR cinder.volume.drivers.lightos 
2025-01-21 10:15:36.122 25 ERROR cinder.volume.drivers.lightos During handling of the above exception, another exception occurred:
2025-01-21 10:15:36.122 25 ERROR cinder.volume.drivers.lightos 
2025-01-21 10:15:36.122 25 ERROR cinder.volume.drivers.lightos Traceback (most recent call last):
2025-01-21 10:15:36.122 25 ERROR cinder.volume.drivers.lightos   File "/var/lib/kolla/venv/lib/python3.10/site-packages/cinder/volume/drivers/lightos.py", line 356, in __send_cmd
2025-01-21 10:15:36.122 25 ERROR cinder.volume.drivers.lightos     response = session.send(
2025-01-21 10:15:36.122 25 ERROR cinder.volume.drivers.lightos   File "/var/lib/kolla/venv/lib/python3.10/site-packages/requests/sessions.py", line 703, in send
2025-01-21 10:15:36.122 25 ERROR cinder.volume.drivers.lightos     r = adapter.send(request, **kwargs)
2025-01-21 10:15:36.122 25 ERROR cinder.volume.drivers.lightos   File "/var/lib/kolla/venv/lib/python3.10/site-packages/requests/adapters.py", line 700, in send
2025-01-21 10:15:36.122 25 ERROR cinder.volume.drivers.lightos     raise ConnectionError(e, request=request)
2025-01-21 10:15:36.122 25 ERROR cinder.volume.drivers.lightos requests.exceptions.ConnectionError: HTTPSConnectionPool(host='[LB_IP_ADDRESS]', port=443): Max retries exceeded with url: /api/v2/clusterinfo (Caused by NewConnectionError('<urllib3.connection.HTTPSConnection object at 0x7f1a88d6d1e0>: Failed to establish a new connection: [Errno 111] ECONNREFUSED'))
2025-01-21 10:15:36.122 25 ERROR cinder.volume.drivers.lightos 
2025-01-21 10:15:36.124 25 INFO cinder.volume.drivers.lightos [None req-a64abf7e-20c6-4725-9cfb-78c20b6d991f - - - - - -] Invoking get_cluster_info using GET url: /api/v2/clusterinfo             request.body: {} ssl_verify: False
2025-01-21 10:15:38.177 25 ERROR cinder.volume.drivers.lightos [None req-a64abf7e-20c6-4725-9cfb-78c20b6d991f - - - - - -] REST server not responding at 'https://[LB_IP_ADDRESS]:443/api/v2/clusterinfo': requests.exceptions.ConnectionError: HTTPSConnectionPool(host='[LB_IP_ADDRESS]', port=443): Max retries exceeded with url: /api/v2/clusterinfo (Caused by NewConnectionError('<urllib3.connection.HTTPSConnection object at 0x7f1a88d6e260>: Failed to establish a new connection: [Errno 113] EHOSTUNREACH'))
2025-01-21 10:15:38.177 25 ERROR cinder.volume.drivers.lightos Traceback (most recent call last):
2025-01-21 10:15:38.177 25 ERROR cinder.volume.drivers.lightos   File "/var/lib/kolla/venv/lib/python3.10/site-packages/urllib3/connection.py", line 174, in _new_conn
2025-01-21 10:15:38.177 25 ERROR cinder.volume.drivers.lightos     conn = connection.create_connection(
2025-01-21 10:15:38.177 25 ERROR cinder.volume.drivers.lightos   File "/var/lib/kolla/venv/lib/python3.10/site-packages/urllib3/util/connection.py", line 95, in create_connection
2025-01-21 10:15:38.177 25 ERROR cinder.volume.drivers.lightos     raise err
2025-01-21 10:15:38.177 25 ERROR cinder.volume.drivers.lightos   File "/var/lib/kolla/venv/lib/python3.10/site-packages/urllib3/util/connection.py", line 85, in create_connection
2025-01-21 10:15:38.177 25 ERROR cinder.volume.drivers.lightos     sock.connect(sa)
2025-01-21 10:15:38.177 25 ERROR cinder.volume.drivers.lightos   File "/var/lib/kolla/venv/lib/python3.10/site-packages/eventlet/greenio/base.py", line 265, in connect
2025-01-21 10:15:38.177 25 ERROR cinder.volume.drivers.lightos     socket_checkerr(fd)
2025-01-21 10:15:38.177 25 ERROR cinder.volume.drivers.lightos   File "/var/lib/kolla/venv/lib/python3.10/site-packages/eventlet/greenio/base.py", line 50, in socket_checkerr
2025-01-21 10:15:38.177 25 ERROR cinder.volume.drivers.lightos     raise OSError(err, errno.errorcode[err])
2025-01-21 10:15:38.177 25 ERROR cinder.volume.drivers.lightos OSError: [Errno 113] EHOSTUNREACH
2025-01-21 10:15:38.177 25 ERROR cinder.volume.drivers.lightos 
2025-01-21 10:15:38.177 25 ERROR cinder.volume.drivers.lightos During handling of the above exception, another exception occurred:
2025-01-21 10:15:38.177 25 ERROR cinder.volume.drivers.lightos 
2025-01-21 10:15:38.177 25 ERROR cinder.volume.drivers.lightos Traceback (most recent call last):
2025-01-21 10:15:38.177 25 ERROR cinder.volume.drivers.lightos   File "/var/lib/kolla/venv/lib/python3.10/site-packages/urllib3/connectionpool.py", line 715, in urlopen
2025-01-21 10:15:38.177 25 ERROR cinder.volume.drivers.lightos     httplib_response = self._make_request(
2025-01-21 10:15:38.177 25 ERROR cinder.volume.drivers.lightos   File "/var/lib/kolla/venv/lib/python3.10/site-packages/urllib3/connectionpool.py", line 404, in _make_request
2025-01-21 10:15:38.177 25 ERROR cinder.volume.drivers.lightos     self._validate_conn(conn)
2025-01-21 10:15:38.177 25 ERROR cinder.volume.drivers.lightos   File "/var/lib/kolla/venv/lib/python3.10/site-packages/urllib3/connectionpool.py", line 1060, in _validate_conn
2025-01-21 10:15:38.177 25 ERROR cinder.volume.drivers.lightos     conn.connect()
2025-01-21 10:15:38.177 25 ERROR cinder.volume.drivers.lightos   File "/var/lib/kolla/venv/lib/python3.10/site-packages/urllib3/connection.py", line 363, in connect
2025-01-21 10:15:38.177 25 ERROR cinder.volume.drivers.lightos     self.sock = conn = self._new_conn()
2025-01-21 10:15:38.177 25 ERROR cinder.volume.drivers.lightos   File "/var/lib/kolla/venv/lib/python3.10/site-packages/urllib3/connection.py", line 186, in _new_conn
2025-01-21 10:15:38.177 25 ERROR cinder.volume.drivers.lightos     raise NewConnectionError(
2025-01-21 10:15:38.177 25 ERROR cinder.volume.drivers.lightos urllib3.exceptions.NewConnectionError: <urllib3.connection.HTTPSConnection object at 0x7f1a88d6e260>: Failed to establish a new connection: [Errno 113] EHOSTUNREACH
2025-01-21 10:15:38.177 25 ERROR cinder.volume.drivers.lightos 
2025-01-21 10:15:38.177 25 ERROR cinder.volume.drivers.lightos During handling of the above exception, another exception occurred:
2025-01-21 10:15:38.177 25 ERROR cinder.volume.drivers.lightos 
2025-01-21 10:15:38.177 25 ERROR cinder.volume.drivers.lightos Traceback (most recent call last):
2025-01-21 10:15:38.177 25 ERROR cinder.volume.drivers.lightos   File "/var/lib/kolla/venv/lib/python3.10/site-packages/requests/adapters.py", line 667, in send
2025-01-21 10:15:38.177 25 ERROR cinder.volume.drivers.lightos     resp = conn.urlopen(
2025-01-21 10:15:38.177 25 ERROR cinder.volume.drivers.lightos   File "/var/lib/kolla/venv/lib/python3.10/site-packages/urllib3/connectionpool.py", line 801, in urlopen
2025-01-21 10:15:38.177 25 ERROR cinder.volume.drivers.lightos     retries = retries.increment(
2025-01-21 10:15:38.177 25 ERROR cinder.volume.drivers.lightos   File "/var/lib/kolla/venv/lib/python3.10/site-packages/urllib3/util/retry.py", line 594, in increment
2025-01-21 10:15:38.177 25 ERROR cinder.volume.drivers.lightos     raise MaxRetryError(_pool, url, error or ResponseError(cause))
2025-01-21 10:15:38.177 25 ERROR cinder.volume.drivers.lightos urllib3.exceptions.MaxRetryError: HTTPSConnectionPool(host='[LB_IP_ADDRESS]', port=443): Max retries exceeded with url: /api/v2/clusterinfo (Caused by NewConnectionError('<urllib3.connection.HTTPSConnection object at 0x7f1a88d6e260>: Failed to establish a new connection: [Errno 113] EHOSTUNREACH'))
2025-01-21 10:15:38.177 25 ERROR cinder.volume.drivers.lightos 
2025-01-21 10:15:38.177 25 ERROR cinder.volume.drivers.lightos During handling of the above exception, another exception occurred:
2025-01-21 10:15:38.177 25 ERROR cinder.volume.drivers.lightos 
2025-01-21 10:15:38.177 25 ERROR cinder.volume.drivers.lightos Traceback (most recent call last):
2025-01-21 10:15:38.177 25 ERROR cinder.volume.drivers.lightos   File "/var/lib/kolla/venv/lib/python3.10/site-packages/cinder/volume/drivers/lightos.py", line 356, in __send_cmd
2025-01-21 10:15:38.177 25 ERROR cinder.volume.drivers.lightos     response = session.send(
2025-01-21 10:15:38.177 25 ERROR cinder.volume.drivers.lightos   File "/var/lib/kolla/venv/lib/python3.10/site-packages/requests/sessions.py", line 703, in send
2025-01-21 10:15:38.177 25 ERROR cinder.volume.drivers.lightos     r = adapter.send(request, **kwargs)
2025-01-21 10:15:38.177 25 ERROR cinder.volume.drivers.lightos   File "/var/lib/kolla/venv/lib/python3.10/site-packages/requests/adapters.py", line 700, in send
2025-01-21 10:15:38.177 25 ERROR cinder.volume.drivers.lightos     raise ConnectionError(e, request=request)
2025-01-21 10:15:38.177 25 ERROR cinder.volume.drivers.lightos requests.exceptions.ConnectionError: HTTPSConnectionPool(host='[LB_IP_ADDRESS]', port=443): Max retries exceeded with url: /api/v2/clusterinfo (Caused by NewConnectionError('<urllib3.connection.HTTPSConnection object at 0x7f1a88d6e260>: Failed to establish a new connection: [Errno 113] EHOSTUNREACH'))
2025-01-21 10:15:38.177 25 ERROR cinder.volume.drivers.lightos 
2025-01-21 10:15:38.180 25 ERROR cinder.volume.manager [None req-a64abf7e-20c6-4725-9cfb-78c20b6d991f - - - - - -] Failed to initialize driver.: cinder.exception.VolumeDriverException: Volume driver reported an error: Could not get a response from any API server
2025-01-21 10:15:38.180 25 ERROR cinder.volume.manager Traceback (most recent call last):
2025-01-21 10:15:38.180 25 ERROR cinder.volume.manager   File "/var/lib/kolla/venv/lib/python3.10/site-packages/cinder/volume/manager.py", line 523, in _init_host
2025-01-21 10:15:38.180 25 ERROR cinder.volume.manager     self.driver.do_setup(ctxt)
2025-01-21 10:15:38.180 25 ERROR cinder.volume.manager   File "/var/lib/kolla/venv/lib/python3.10/site-packages/cinder/volume/drivers/lightos.py", line 922, in do_setup
2025-01-21 10:15:38.180 25 ERROR cinder.volume.manager     self.get_cluster_info()
2025-01-21 10:15:38.180 25 ERROR cinder.volume.manager   File "/var/lib/kolla/venv/lib/python3.10/site-packages/cinder/volume/drivers/lightos.py", line 873, in get_cluster_info
2025-01-21 10:15:38.180 25 ERROR cinder.volume.manager     status_code, cluster_info = self.cluster.send_cmd(
2025-01-21 10:15:38.180 25 ERROR cinder.volume.manager   File "/var/lib/kolla/venv/lib/python3.10/site-packages/cinder/volume/drivers/lightos.py", line 315, in send_cmd
2025-01-21 10:15:38.180 25 ERROR cinder.volume.manager     raise exception.VolumeDriverException(
2025-01-21 10:15:38.180 25 ERROR cinder.volume.manager cinder.exception.VolumeDriverException: Volume driver reported an error: Could not get a response from any API server
2025-01-21 10:15:38.180 25 ERROR cinder.volume.manager 
2025-01-21 10:15:40.183 25 INFO cinder.volume.manager [None req-a64abf7e-20c6-4725-9cfb-78c20b6d991f - - - - - -] Starting volume driver LightOSVolumeDriver (2.3.12)
2025-01-21 10:15:40.184 25 INFO cinder.volume.drivers.lightos [None req-a64abf7e-20c6-4725-9cfb-78c20b6d991f - - - - - -] Invoking get_cluster_info using GET url: /api/v2/clusterinfo             request.body: {} ssl_verify: False
2025-01-21 10:15:40.188 25 ERROR cinder.volume.drivers.lightos [None req-a64abf7e-20c6-4725-9cfb-78c20b6d991f - - - - - -] REST server not responding at 'https://[LB_IP_ADDRESS]:443/api/v2/clusterinfo': requests.exceptions.ConnectionError: HTTPSConnectionPool(host='[LB_IP_ADDRESS]', port=443): Max retries exceeded with url: /api/v2/clusterinfo (Caused by NewConnectionError('<urllib3.connection.HTTPSConnection object at 0x7f1a88d00880>: Failed to establish a new connection: [Errno 111] ECONNREFUSED'))
2025-01-21 10:15:40.188 25 ERROR cinder.volume.drivers.lightos Traceback (most recent call last):
2025-01-21 10:15:40.188 25 ERROR cinder.volume.drivers.lightos   File "/var/lib/kolla/venv/lib/python3.10/site-packages/urllib3/connection.py", line 174, in _new_conn
2025-01-21 10:15:40.188 25 ERROR cinder.volume.drivers.lightos     conn = connection.create_connection(
2025-01-21 10:15:40.188 25 ERROR cinder.volume.drivers.lightos   File "/var/lib/kolla/venv/lib/python3.10/site-packages/urllib3/util/connection.py", line 95, in create_connection
2025-01-21 10:15:40.188 25 ERROR cinder.volume.drivers.lightos     raise err
2025-01-21 10:15:40.188 25 ERROR cinder.volume.drivers.lightos   File "/var/lib/kolla/venv/lib/python3.10/site-packages/urllib3/util/connection.py", line 85, in create_connection
2025-01-21 10:15:40.188 25 ERROR cinder.volume.drivers.lightos     sock.connect(sa)
2025-01-21 10:15:40.188 25 ERROR cinder.volume.drivers.lightos   File "/var/lib/kolla/venv/lib/python3.10/site-packages/eventlet/greenio/base.py", line 265, in connect
2025-01-21 10:15:40.188 25 ERROR cinder.volume.drivers.lightos     socket_checkerr(fd)
2025-01-21 10:15:40.188 25 ERROR cinder.volume.drivers.lightos   File "/var/lib/kolla/venv/lib/python3.10/site-packages/eventlet/greenio/base.py", line 50, in socket_checkerr
2025-01-21 10:15:40.188 25 ERROR cinder.volume.drivers.lightos     raise OSError(err, errno.errorcode[err])
2025-01-21 10:15:40.188 25 ERROR cinder.volume.drivers.lightos ConnectionRefusedError: [Errno 111] ECONNREFUSED
2025-01-21 10:15:40.188 25 ERROR cinder.volume.drivers.lightos 
2025-01-21 10:15:40.188 25 ERROR cinder.volume.drivers.lightos During handling of the above exception, another exception occurred:
2025-01-21 10:15:40.188 25 ERROR cinder.volume.drivers.lightos 
2025-01-21 10:15:40.188 25 ERROR cinder.volume.drivers.lightos Traceback (most recent call last):
2025-01-21 10:15:40.188 25 ERROR cinder.volume.drivers.lightos   File "/var/lib/kolla/venv/lib/python3.10/site-packages/urllib3/connectionpool.py", line 715, in urlopen
2025-01-21 10:15:40.188 25 ERROR cinder.volume.drivers.lightos     httplib_response = self._make_request(
2025-01-21 10:15:40.188 25 ERROR cinder.volume.drivers.lightos   File "/var/lib/kolla/venv/lib/python3.10/site-packages/urllib3/connectionpool.py", line 404, in _make_request
2025-01-21 10:15:40.188 25 ERROR cinder.volume.drivers.lightos     self._validate_conn(conn)
2025-01-21 10:15:40.188 25 ERROR cinder.volume.drivers.lightos   File "/var/lib/kolla/venv/lib/python3.10/site-packages/urllib3/connectionpool.py", line 1060, in _validate_conn
2025-01-21 10:15:40.188 25 ERROR cinder.volume.drivers.lightos     conn.connect()
2025-01-21 10:15:40.188 25 ERROR cinder.volume.drivers.lightos   File "/var/lib/kolla/venv/lib/python3.10/site-packages/urllib3/connection.py", line 363, in connect
2025-01-21 10:15:40.188 25 ERROR cinder.volume.drivers.lightos     self.sock = conn = self._new_conn()
2025-01-21 10:15:40.188 25 ERROR cinder.volume.drivers.lightos   File "/var/lib/kolla/venv/lib/python3.10/site-packages/urllib3/connection.py", line 186, in _new_conn
2025-01-21 10:15:40.188 25 ERROR cinder.volume.drivers.lightos     raise NewConnectionError(
2025-01-21 10:15:40.188 25 ERROR cinder.volume.drivers.lightos urllib3.exceptions.NewConnectionError: <urllib3.connection.HTTPSConnection object at 0x7f1a88d00880>: Failed to establish a new connection: [Errno 111] ECONNREFUSED
2025-01-21 10:15:40.188 25 ERROR cinder.volume.drivers.lightos 
2025-01-21 10:15:40.188 25 ERROR cinder.volume.drivers.lightos During handling of the above exception, another exception occurred:
2025-01-21 10:15:40.188 25 ERROR cinder.volume.drivers.lightos 
2025-01-21 10:15:40.188 25 ERROR cinder.volume.drivers.lightos Traceback (most recent call last):
2025-01-21 10:15:40.188 25 ERROR cinder.volume.drivers.lightos   File "/var/lib/kolla/venv/lib/python3.10/site-packages/requests/adapters.py", line 667, in send
2025-01-21 10:15:40.188 25 ERROR cinder.volume.drivers.lightos     resp = conn.urlopen(
2025-01-21 10:15:40.188 25 ERROR cinder.volume.drivers.lightos   File "/var/lib/kolla/venv/lib/python3.10/site-packages/urllib3/connectionpool.py", line 801, in urlopen
2025-01-21 10:15:40.188 25 ERROR cinder.volume.drivers.lightos     retries = retries.increment(
2025-01-21 10:15:40.188 25 ERROR cinder.volume.drivers.lightos   File "/var/lib/kolla/venv/lib/python3.10/site-packages/urllib3/util/retry.py", line 594, in increment
2025-01-21 10:15:40.188 25 ERROR cinder.volume.drivers.lightos     raise MaxRetryError(_pool, url, error or ResponseError(cause))
2025-01-21 10:15:40.188 25 ERROR cinder.volume.drivers.lightos urllib3.exceptions.MaxRetryError: HTTPSConnectionPool(host='[LB_IP_ADDRESS]', port=443): Max retries exceeded with url: /api/v2/clusterinfo (Caused by NewConnectionError('<urllib3.connection.HTTPSConnection object at 0x7f1a88d00880>: Failed to establish a new connection: [Errno 111] ECONNREFUSED'))
2025-01-21 10:15:40.188 25 ERROR cinder.volume.drivers.lightos 
2025-01-21 10:15:40.188 25 ERROR cinder.volume.drivers.lightos During handling of the above exception, another exception occurred:
2025-01-21 10:15:40.188 25 ERROR cinder.volume.drivers.lightos 
2025-01-21 10:15:40.188 25 ERROR cinder.volume.drivers.lightos Traceback (most recent call last):
2025-01-21 10:15:40.188 25 ERROR cinder.volume.drivers.lightos   File "/var/lib/kolla/venv/lib/python3.10/site-packages/cinder/volume/drivers/lightos.py", line 356, in __send_cmd
2025-01-21 10:15:40.188 25 ERROR cinder.volume.drivers.lightos     response = session.send(
2025-01-21 10:15:40.188 25 ERROR cinder.volume.drivers.lightos   File "/var/lib/kolla/venv/lib/python3.10/site-packages/requests/sessions.py", line 703, in send
2025-01-21 10:15:40.188 25 ERROR cinder.volume.drivers.lightos     r = adapter.send(request, **kwargs)
2025-01-21 10:15:40.188 25 ERROR cinder.volume.drivers.lightos   File "/var/lib/kolla/venv/lib/python3.10/site-packages/requests/adapters.py", line 700, in send
2025-01-21 10:15:40.188 25 ERROR cinder.volume.drivers.lightos     raise ConnectionError(e, request=request)
2025-01-21 10:15:40.188 25 ERROR cinder.volume.drivers.lightos requests.exceptions.ConnectionError: HTTPSConnectionPool(host='[LB_IP_ADDRESS]', port=443): Max retries exceeded with url: /api/v2/clusterinfo (Caused by NewConnectionError('<urllib3.connection.HTTPSConnection object at 0x7f1a88d00880>: Failed to establish a new connection: [Errno 111] ECONNREFUSED'))
2025-01-21 10:15:40.188 25 ERROR cinder.volume.drivers.lightos 
2025-01-21 10:15:40.190 25 INFO cinder.volume.drivers.lightos [None req-a64abf7e-20c6-4725-9cfb-78c20b6d991f - - - - - -] Invoking get_cluster_info using GET url: /api/v2/clusterinfo             request.body: {} ssl_verify: False
2025-01-21 10:15:40.193 25 ERROR cinder.volume.drivers.lightos [None req-a64abf7e-20c6-4725-9cfb-78c20b6d991f - - - - - -] REST server not responding at 'https://[LB_IP_ADDRESS]:443/api/v2/clusterinfo': requests.exceptions.ConnectionError: HTTPSConnectionPool(host='[LB_IP_ADDRESS]', port=443): Max retries exceeded with url: /api/v2/clusterinfo (Caused by NewConnectionError('<urllib3.connection.HTTPSConnection object at 0x7f1a88d01360>: Failed to establish a new connection: [Errno 111] ECONNREFUSED'))
2025-01-21 10:15:40.193 25 ERROR cinder.volume.drivers.lightos Traceback (most recent call last):
2025-01-21 10:15:40.193 25 ERROR cinder.volume.drivers.lightos   File "/var/lib/kolla/venv/lib/python3.10/site-packages/urllib3/connection.py", line 174, in _new_conn
2025-01-21 10:15:40.193 25 ERROR cinder.volume.drivers.lightos     conn = connection.create_connection(
2025-01-21 10:15:40.193 25 ERROR cinder.volume.drivers.lightos   File "/var/lib/kolla/venv/lib/python3.10/site-packages/urllib3/util/connection.py", line 95, in create_connection
2025-01-21 10:15:40.193 25 ERROR cinder.volume.drivers.lightos     raise err
2025-01-21 10:15:40.193 25 ERROR cinder.volume.drivers.lightos   File "/var/lib/kolla/venv/lib/python3.10/site-packages/urllib3/util/connection.py", line 85, in create_connection
2025-01-21 10:15:40.193 25 ERROR cinder.volume.drivers.lightos     sock.connect(sa)
2025-01-21 10:15:40.193 25 ERROR cinder.volume.drivers.lightos   File "/var/lib/kolla/venv/lib/python3.10/site-packages/eventlet/greenio/base.py", line 265, in connect
2025-01-21 10:15:40.193 25 ERROR cinder.volume.drivers.lightos     socket_checkerr(fd)
2025-01-21 10:15:40.193 25 ERROR cinder.volume.drivers.lightos   File "/var/lib/kolla/venv/lib/python3.10/site-packages/eventlet/greenio/base.py", line 50, in socket_checkerr
2025-01-21 10:15:40.193 25 ERROR cinder.volume.drivers.lightos     raise OSError(err, errno.errorcode[err])
2025-01-21 10:15:40.193 25 ERROR cinder.volume.drivers.lightos ConnectionRefusedError: [Errno 111] ECONNREFUSED
2025-01-21 10:15:40.193 25 ERROR cinder.volume.drivers.lightos 
2025-01-21 10:15:40.193 25 ERROR cinder.volume.drivers.lightos During handling of the above exception, another exception occurred:
2025-01-21 10:15:40.193 25 ERROR cinder.volume.drivers.lightos 
2025-01-21 10:15:40.193 25 ERROR cinder.volume.drivers.lightos Traceback (most recent call last):
2025-01-21 10:15:40.193 25 ERROR cinder.volume.drivers.lightos   File "/var/lib/kolla/venv/lib/python3.10/site-packages/urllib3/connectionpool.py", line 715, in urlopen
2025-01-21 10:15:40.193 25 ERROR cinder.volume.drivers.lightos     httplib_response = self._make_request(
2025-01-21 10:15:40.193 25 ERROR cinder.volume.drivers.lightos   File "/var/lib/kolla/venv/lib/python3.10/site-packages/urllib3/connectionpool.py", line 404, in _make_request
2025-01-21 10:15:40.193 25 ERROR cinder.volume.drivers.lightos     self._validate_conn(conn)
2025-01-21 10:15:40.193 25 ERROR cinder.volume.drivers.lightos   File "/var/lib/kolla/venv/lib/python3.10/site-packages/urllib3/connectionpool.py", line 1060, in _validate_conn
2025-01-21 10:15:40.193 25 ERROR cinder.volume.drivers.lightos     conn.connect()
2025-01-21 10:15:40.193 25 ERROR cinder.volume.drivers.lightos   File "/var/lib/kolla/venv/lib/python3.10/site-packages/urllib3/connection.py", line 363, in connect
2025-01-21 10:15:40.193 25 ERROR cinder.volume.drivers.lightos     self.sock = conn = self._new_conn()
2025-01-21 10:15:40.193 25 ERROR cinder.volume.drivers.lightos   File "/var/lib/kolla/venv/lib/python3.10/site-packages/urllib3/connection.py", line 186, in _new_conn
2025-01-21 10:15:40.193 25 ERROR cinder.volume.drivers.lightos     raise NewConnectionError(
2025-01-21 10:15:40.193 25 ERROR cinder.volume.drivers.lightos urllib3.exceptions.NewConnectionError: <urllib3.connection.HTTPSConnection object at 0x7f1a88d01360>: Failed to establish a new connection: [Errno 111] ECONNREFUSED
2025-01-21 10:15:40.193 25 ERROR cinder.volume.drivers.lightos 
2025-01-21 10:15:40.193 25 ERROR cinder.volume.drivers.lightos During handling of the above exception, another exception occurred:
2025-01-21 10:15:40.193 25 ERROR cinder.volume.drivers.lightos 
2025-01-21 10:15:40.193 25 ERROR cinder.volume.drivers.lightos Traceback (most recent call last):
2025-01-21 10:15:40.193 25 ERROR cinder.volume.drivers.lightos   File "/var/lib/kolla/venv/lib/python3.10/site-packages/requests/adapters.py", line 667, in send
2025-01-21 10:15:40.193 25 ERROR cinder.volume.drivers.lightos     resp = conn.urlopen(
2025-01-21 10:15:40.193 25 ERROR cinder.volume.drivers.lightos   File "/var/lib/kolla/venv/lib/python3.10/site-packages/urllib3/connectionpool.py", line 801, in urlopen
2025-01-21 10:15:40.193 25 ERROR cinder.volume.drivers.lightos     retries = retries.increment(
2025-01-21 10:15:40.193 25 ERROR cinder.volume.drivers.lightos   File "/var/lib/kolla/venv/lib/python3.10/site-packages/urllib3/util/retry.py", line 594, in increment
2025-01-21 10:15:40.193 25 ERROR cinder.volume.drivers.lightos     raise MaxRetryError(_pool, url, error or ResponseError(cause))
2025-01-21 10:15:40.193 25 ERROR cinder.volume.drivers.lightos urllib3.exceptions.MaxRetryError: HTTPSConnectionPool(host='[LB_IP_ADDRESS]', port=443): Max retries exceeded with url: /api/v2/clusterinfo (Caused by NewConnectionError('<urllib3.connection.HTTPSConnection object at 0x7f1a88d01360>: Failed to establish a new connection: [Errno 111] ECONNREFUSED'))
2025-01-21 10:15:40.193 25 ERROR cinder.volume.drivers.lightos 
2025-01-21 10:15:40.193 25 ERROR cinder.volume.drivers.lightos During handling of the above exception, another exception occurred:
2025-01-21 10:15:40.193 25 ERROR cinder.volume.drivers.lightos 
2025-01-21 10:15:40.193 25 ERROR cinder.volume.drivers.lightos Traceback (most recent call last):
2025-01-21 10:15:40.193 25 ERROR cinder.volume.drivers.lightos   File "/var/lib/kolla/venv/lib/python3.10/site-packages/cinder/volume/drivers/lightos.py", line 356, in __send_cmd
2025-01-21 10:15:40.193 25 ERROR cinder.volume.drivers.lightos     response = session.send(
2025-01-21 10:15:40.193 25 ERROR cinder.volume.drivers.lightos   File "/var/lib/kolla/venv/lib/python3.10/site-packages/requests/sessions.py", line 703, in send
2025-01-21 10:15:40.193 25 ERROR cinder.volume.drivers.lightos     r = adapter.send(request, **kwargs)
2025-01-21 10:15:40.193 25 ERROR cinder.volume.drivers.lightos   File "/var/lib/kolla/venv/lib/python3.10/site-packages/requests/adapters.py", line 700, in send
2025-01-21 10:15:40.193 25 ERROR cinder.volume.drivers.lightos     raise ConnectionError(e, request=request)
2025-01-21 10:15:40.193 25 ERROR cinder.volume.drivers.lightos requests.exceptions.ConnectionError: HTTPSConnectionPool(host='[LB_IP_ADDRESS]', port=443): Max retries exceeded with url: /api/v2/clusterinfo (Caused by NewConnectionError('<urllib3.connection.HTTPSConnection object at 0x7f1a88d01360>: Failed to establish a new connection: [Errno 111] ECONNREFUSED'))
2025-01-21 10:15:40.193 25 ERROR cinder.volume.drivers.lightos 
2025-01-21 10:15:40.196 25 INFO cinder.volume.drivers.lightos [None req-a64abf7e-20c6-4725-9cfb-78c20b6d991f - - - - - -] Invoking get_cluster_info using GET url: /api/v2/clusterinfo             request.body: {} ssl_verify: False
2025-01-21 10:15:41.250 25 ERROR cinder.volume.drivers.lightos [None req-a64abf7e-20c6-4725-9cfb-78c20b6d991f - - - - - -] REST server not responding at 'https://[LB_IP_ADDRESS]:443/api/v2/clusterinfo': requests.exceptions.ConnectionError: HTTPSConnectionPool(host='[LB_IP_ADDRESS]', port=443): Max retries exceeded with url: /api/v2/clusterinfo (Caused by NewConnectionError('<urllib3.connection.HTTPSConnection object at 0x7f1a88d6e110>: Failed to establish a new connection: [Errno 113] EHOSTUNREACH'))
2025-01-21 10:15:41.250 25 ERROR cinder.volume.drivers.lightos Traceback (most recent call last):
2025-01-21 10:15:41.250 25 ERROR cinder.volume.drivers.lightos   File "/var/lib/kolla/venv/lib/python3.10/site-packages/urllib3/connection.py", line 174, in _new_conn
2025-01-21 10:15:41.250 25 ERROR cinder.volume.drivers.lightos     conn = connection.create_connection(
2025-01-21 10:15:41.250 25 ERROR cinder.volume.drivers.lightos   File "/var/lib/kolla/venv/lib/python3.10/site-packages/urllib3/util/connection.py", line 95, in create_connection
2025-01-21 10:15:41.250 25 ERROR cinder.volume.drivers.lightos     raise err
2025-01-21 10:15:41.250 25 ERROR cinder.volume.drivers.lightos   File "/var/lib/kolla/venv/lib/python3.10/site-packages/urllib3/util/connection.py", line 85, in create_connection
2025-01-21 10:15:41.250 25 ERROR cinder.volume.drivers.lightos     sock.connect(sa)
2025-01-21 10:15:41.250 25 ERROR cinder.volume.drivers.lightos   File "/var/lib/kolla/venv/lib/python3.10/site-packages/eventlet/greenio/base.py", line 265, in connect
2025-01-21 10:15:41.250 25 ERROR cinder.volume.drivers.lightos     socket_checkerr(fd)
2025-01-21 10:15:41.250 25 ERROR cinder.volume.drivers.lightos   File "/var/lib/kolla/venv/lib/python3.10/site-packages/eventlet/greenio/base.py", line 50, in socket_checkerr
2025-01-21 10:15:41.250 25 ERROR cinder.volume.drivers.lightos     raise OSError(err, errno.errorcode[err])
2025-01-21 10:15:41.250 25 ERROR cinder.volume.drivers.lightos OSError: [Errno 113] EHOSTUNREACH
2025-01-21 10:15:41.250 25 ERROR cinder.volume.drivers.lightos 
2025-01-21 10:15:41.250 25 ERROR cinder.volume.drivers.lightos During handling of the above exception, another exception occurred:
2025-01-21 10:15:41.250 25 ERROR cinder.volume.drivers.lightos 
2025-01-21 10:15:41.250 25 ERROR cinder.volume.drivers.lightos Traceback (most recent call last):
2025-01-21 10:15:41.250 25 ERROR cinder.volume.drivers.lightos   File "/var/lib/kolla/venv/lib/python3.10/site-packages/urllib3/connectionpool.py", line 715, in urlopen
2025-01-21 10:15:41.250 25 ERROR cinder.volume.drivers.lightos     httplib_response = self._make_request(
2025-01-21 10:15:41.250 25 ERROR cinder.volume.drivers.lightos   File "/var/lib/kolla/venv/lib/python3.10/site-packages/urllib3/connectionpool.py", line 404, in _make_request
2025-01-21 10:15:41.250 25 ERROR cinder.volume.drivers.lightos     self._validate_conn(conn)
2025-01-21 10:15:41.250 25 ERROR cinder.volume.drivers.lightos   File "/var/lib/kolla/venv/lib/python3.10/site-packages/urllib3/connectionpool.py", line 1060, in _validate_conn
2025-01-21 10:15:41.250 25 ERROR cinder.volume.drivers.lightos     conn.connect()
2025-01-21 10:15:41.250 25 ERROR cinder.volume.drivers.lightos   File "/var/lib/kolla/venv/lib/python3.10/site-packages/urllib3/connection.py", line 363, in connect
2025-01-21 10:15:41.250 25 ERROR cinder.volume.drivers.lightos     self.sock = conn = self._new_conn()
2025-01-21 10:15:41.250 25 ERROR cinder.volume.drivers.lightos   File "/var/lib/kolla/venv/lib/python3.10/site-packages/urllib3/connection.py", line 186, in _new_conn
2025-01-21 10:15:41.250 25 ERROR cinder.volume.drivers.lightos     raise NewConnectionError(
2025-01-21 10:15:41.250 25 ERROR cinder.volume.drivers.lightos urllib3.exceptions.NewConnectionError: <urllib3.connection.HTTPSConnection object at 0x7f1a88d6e110>: Failed to establish a new connection: [Errno 113] EHOSTUNREACH
2025-01-21 10:15:41.250 25 ERROR cinder.volume.drivers.lightos 
2025-01-21 10:15:41.250 25 ERROR cinder.volume.drivers.lightos During handling of the above exception, another exception occurred:
2025-01-21 10:15:41.250 25 ERROR cinder.volume.drivers.lightos 
2025-01-21 10:15:41.250 25 ERROR cinder.volume.drivers.lightos Traceback (most recent call last):
2025-01-21 10:15:41.250 25 ERROR cinder.volume.drivers.lightos   File "/var/lib/kolla/venv/lib/python3.10/site-packages/requests/adapters.py", line 667, in send
2025-01-21 10:15:41.250 25 ERROR cinder.volume.drivers.lightos     resp = conn.urlopen(
2025-01-21 10:15:41.250 25 ERROR cinder.volume.drivers.lightos   File "/var/lib/kolla/venv/lib/python3.10/site-packages/urllib3/connectionpool.py", line 801, in urlopen
2025-01-21 10:15:41.250 25 ERROR cinder.volume.drivers.lightos     retries = retries.increment(
2025-01-21 10:15:41.250 25 ERROR cinder.volume.drivers.lightos   File "/var/lib/kolla/venv/lib/python3.10/site-packages/urllib3/util/retry.py", line 594, in increment
2025-01-21 10:15:41.250 25 ERROR cinder.volume.drivers.lightos     raise MaxRetryError(_pool, url, error or ResponseError(cause))
2025-01-21 10:15:41.250 25 ERROR cinder.volume.drivers.lightos urllib3.exceptions.MaxRetryError: HTTPSConnectionPool(host='[LB_IP_ADDRESS]', port=443): Max retries exceeded with url: /api/v2/clusterinfo (Caused by NewConnectionError('<urllib3.connection.HTTPSConnection object at 0x7f1a88d6e110>: Failed to establish a new connection: [Errno 113] EHOSTUNREACH'))
2025-01-21 10:15:41.250 25 ERROR cinder.volume.drivers.lightos 
2025-01-21 10:15:41.250 25 ERROR cinder.volume.drivers.lightos During handling of the above exception, another exception occurred:
2025-01-21 10:15:41.250 25 ERROR cinder.volume.drivers.lightos 
2025-01-21 10:15:41.250 25 ERROR cinder.volume.drivers.lightos Traceback (most recent call last):
2025-01-21 10:15:41.250 25 ERROR cinder.volume.drivers.lightos   File "/var/lib/kolla/venv/lib/python3.10/site-packages/cinder/volume/drivers/lightos.py", line 356, in __send_cmd
2025-01-21 10:15:41.250 25 ERROR cinder.volume.drivers.lightos     response = session.send(
2025-01-21 10:15:41.250 25 ERROR cinder.volume.drivers.lightos   File "/var/lib/kolla/venv/lib/python3.10/site-packages/requests/sessions.py", line 703, in send
2025-01-21 10:15:41.250 25 ERROR cinder.volume.drivers.lightos     r = adapter.send(request, **kwargs)
2025-01-21 10:15:41.250 25 ERROR cinder.volume.drivers.lightos   File "/var/lib/kolla/venv/lib/python3.10/site-packages/requests/adapters.py", line 700, in send
2025-01-21 10:15:41.250 25 ERROR cinder.volume.drivers.lightos     raise ConnectionError(e, request=request)
2025-01-21 10:15:41.250 25 ERROR cinder.volume.drivers.lightos requests.exceptions.ConnectionError: HTTPSConnectionPool(host='[LB_IP_ADDRESS]', port=443): Max retries exceeded with url: /api/v2/clusterinfo (Caused by NewConnectionError('<urllib3.connection.HTTPSConnection object at 0x7f1a88d6e110>: Failed to establish a new connection: [Errno 113] EHOSTUNREACH'))
2025-01-21 10:15:41.250 25 ERROR cinder.volume.drivers.lightos 
2025-01-21 10:15:41.252 25 ERROR cinder.volume.manager [None req-a64abf7e-20c6-4725-9cfb-78c20b6d991f - - - - - -] Failed to initialize driver.: cinder.exception.VolumeDriverException: Volume driver reported an error: Could not get a response from any API server
2025-01-21 10:15:41.252 25 ERROR cinder.volume.manager Traceback (most recent call last):
2025-01-21 10:15:41.252 25 ERROR cinder.volume.manager   File "/var/lib/kolla/venv/lib/python3.10/site-packages/cinder/volume/manager.py", line 523, in _init_host
2025-01-21 10:15:41.252 25 ERROR cinder.volume.manager     self.driver.do_setup(ctxt)
2025-01-21 10:15:41.252 25 ERROR cinder.volume.manager   File "/var/lib/kolla/venv/lib/python3.10/site-packages/cinder/volume/drivers/lightos.py", line 922, in do_setup
2025-01-21 10:15:41.252 25 ERROR cinder.volume.manager     self.get_cluster_info()
2025-01-21 10:15:41.252 25 ERROR cinder.volume.manager   File "/var/lib/kolla/venv/lib/python3.10/site-packages/cinder/volume/drivers/lightos.py", line 873, in get_cluster_info
2025-01-21 10:15:41.252 25 ERROR cinder.volume.manager     status_code, cluster_info = self.cluster.send_cmd(
2025-01-21 10:15:41.252 25 ERROR cinder.volume.manager   File "/var/lib/kolla/venv/lib/python3.10/site-packages/cinder/volume/drivers/lightos.py", line 315, in send_cmd
2025-01-21 10:15:41.252 25 ERROR cinder.volume.manager     raise exception.VolumeDriverException(
2025-01-21 10:15:41.252 25 ERROR cinder.volume.manager cinder.exception.VolumeDriverException: Volume driver reported an error: Could not get a response from any API server
2025-01-21 10:15:41.252 25 ERROR cinder.volume.manager 
2025-01-21 10:15:45.257 25 INFO cinder.volume.manager [None req-a64abf7e-20c6-4725-9cfb-78c20b6d991f - - - - - -] Starting volume driver LightOSVolumeDriver (2.3.12)
2025-01-21 10:15:45.258 25 INFO cinder.volume.drivers.lightos [None req-a64abf7e-20c6-4725-9cfb-78c20b6d991f - - - - - -] Invoking get_cluster_info using GET url: /api/v2/clusterinfo             request.body: {} ssl_verify: False
2025-01-21 10:15:45.262 25 ERROR cinder.volume.drivers.lightos [None req-a64abf7e-20c6-4725-9cfb-78c20b6d991f - - - - - -] REST server not responding at 'https://[LB_IP_ADDRESS]:443/api/v2/clusterinfo': requests.exceptions.ConnectionError: HTTPSConnectionPool(host='[LB_IP_ADDRESS]', port=443): Max retries exceeded with url: /api/v2/clusterinfo (Caused by NewConnectionError('<urllib3.connection.HTTPSConnection object at 0x7f1a88d6ca30>: Failed to establish a new connection: [Errno 111] ECONNREFUSED'))
2025-01-21 10:15:45.262 25 ERROR cinder.volume.drivers.lightos Traceback (most recent call last):
2025-01-21 10:15:45.262 25 ERROR cinder.volume.drivers.lightos   File "/var/lib/kolla/venv/lib/python3.10/site-packages/urllib3/connection.py", line 174, in _new_conn
2025-01-21 10:15:45.262 25 ERROR cinder.volume.drivers.lightos     conn = connection.create_connection(
2025-01-21 10:15:45.262 25 ERROR cinder.volume.drivers.lightos   File "/var/lib/kolla/venv/lib/python3.10/site-packages/urllib3/util/connection.py", line 95, in create_connection
2025-01-21 10:15:45.262 25 ERROR cinder.volume.drivers.lightos     raise err
2025-01-21 10:15:45.262 25 ERROR cinder.volume.drivers.lightos   File "/var/lib/kolla/venv/lib/python3.10/site-packages/urllib3/util/connection.py", line 85, in create_connection
2025-01-21 10:15:45.262 25 ERROR cinder.volume.drivers.lightos     sock.connect(sa)
2025-01-21 10:15:45.262 25 ERROR cinder.volume.drivers.lightos   File "/var/lib/kolla/venv/lib/python3.10/site-packages/eventlet/greenio/base.py", line 265, in connect
2025-01-21 10:15:45.262 25 ERROR cinder.volume.drivers.lightos     socket_checkerr(fd)
2025-01-21 10:15:45.262 25 ERROR cinder.volume.drivers.lightos   File "/var/lib/kolla/venv/lib/python3.10/site-packages/eventlet/greenio/base.py", line 50, in socket_checkerr
2025-01-21 10:15:45.262 25 ERROR cinder.volume.drivers.lightos     raise OSError(err, errno.errorcode[err])
2025-01-21 10:15:45.262 25 ERROR cinder.volume.drivers.lightos ConnectionRefusedError: [Errno 111] ECONNREFUSED
2025-01-21 10:15:45.262 25 ERROR cinder.volume.drivers.lightos 
2025-01-21 10:15:45.262 25 ERROR cinder.volume.drivers.lightos During handling of the above exception, another exception occurred:
2025-01-21 10:15:45.262 25 ERROR cinder.volume.drivers.lightos 
2025-01-21 10:15:45.262 25 ERROR cinder.volume.drivers.lightos Traceback (most recent call last):
2025-01-21 10:15:45.262 25 ERROR cinder.volume.drivers.lightos   File "/var/lib/kolla/venv/lib/python3.10/site-packages/urllib3/connectionpool.py", line 715, in urlopen
2025-01-21 10:15:45.262 25 ERROR cinder.volume.drivers.lightos     httplib_response = self._make_request(
2025-01-21 10:15:45.262 25 ERROR cinder.volume.drivers.lightos   File "/var/lib/kolla/venv/lib/python3.10/site-packages/urllib3/connectionpool.py", line 404, in _make_request
2025-01-21 10:15:45.262 25 ERROR cinder.volume.drivers.lightos     self._validate_conn(conn)
2025-01-21 10:15:45.262 25 ERROR cinder.volume.drivers.lightos   File "/var/lib/kolla/venv/lib/python3.10/site-packages/urllib3/connectionpool.py", line 1060, in _validate_conn
2025-01-21 10:15:45.262 25 ERROR cinder.volume.drivers.lightos     conn.connect()
2025-01-21 10:15:45.262 25 ERROR cinder.volume.drivers.lightos   File "/var/lib/kolla/venv/lib/python3.10/site-packages/urllib3/connection.py", line 363, in connect
2025-01-21 10:15:45.262 25 ERROR cinder.volume.drivers.lightos     self.sock = conn = self._new_conn()
2025-01-21 10:15:45.262 25 ERROR cinder.volume.drivers.lightos   File "/var/lib/kolla/venv/lib/python3.10/site-packages/urllib3/connection.py", line 186, in _new_conn
2025-01-21 10:15:45.262 25 ERROR cinder.volume.drivers.lightos     raise NewConnectionError(
2025-01-21 10:15:45.262 25 ERROR cinder.volume.drivers.lightos urllib3.exceptions.NewConnectionError: <urllib3.connection.HTTPSConnection object at 0x7f1a88d6ca30>: Failed to establish a new connection: [Errno 111] ECONNREFUSED
2025-01-21 10:15:45.262 25 ERROR cinder.volume.drivers.lightos 
2025-01-21 10:15:45.262 25 ERROR cinder.volume.drivers.lightos During handling of the above exception, another exception occurred:
2025-01-21 10:15:45.262 25 ERROR cinder.volume.drivers.lightos 
2025-01-21 10:15:45.262 25 ERROR cinder.volume.drivers.lightos Traceback (most recent call last):
2025-01-21 10:15:45.262 25 ERROR cinder.volume.drivers.lightos   File "/var/lib/kolla/venv/lib/python3.10/site-packages/requests/adapters.py", line 667, in send
2025-01-21 10:15:45.262 25 ERROR cinder.volume.drivers.lightos     resp = conn.urlopen(
2025-01-21 10:15:45.262 25 ERROR cinder.volume.drivers.lightos   File "/var/lib/kolla/venv/lib/python3.10/site-packages/urllib3/connectionpool.py", line 801, in urlopen
2025-01-21 10:15:45.262 25 ERROR cinder.volume.drivers.lightos     retries = retries.increment(
2025-01-21 10:15:45.262 25 ERROR cinder.volume.drivers.lightos   File "/var/lib/kolla/venv/lib/python3.10/site-packages/urllib3/util/retry.py", line 594, in increment
2025-01-21 10:15:45.262 25 ERROR cinder.volume.drivers.lightos     raise MaxRetryError(_pool, url, error or ResponseError(cause))
2025-01-21 10:15:45.262 25 ERROR cinder.volume.drivers.lightos urllib3.exceptions.MaxRetryError: HTTPSConnectionPool(host='[LB_IP_ADDRESS]', port=443): Max retries exceeded with url: /api/v2/clusterinfo (Caused by NewConnectionError('<urllib3.connection.HTTPSConnection object at 0x7f1a88d6ca30>: Failed to establish a new connection: [Errno 111] ECONNREFUSED'))
2025-01-21 10:15:45.262 25 ERROR cinder.volume.drivers.lightos 
2025-01-21 10:15:45.262 25 ERROR cinder.volume.drivers.lightos During handling of the above exception, another exception occurred:
2025-01-21 10:15:45.262 25 ERROR cinder.volume.drivers.lightos 
2025-01-21 10:15:45.262 25 ERROR cinder.volume.drivers.lightos Traceback (most recent call last):
2025-01-21 10:15:45.262 25 ERROR cinder.volume.drivers.lightos   File "/var/lib/kolla/venv/lib/python3.10/site-packages/cinder/volume/drivers/lightos.py", line 356, in __send_cmd
2025-01-21 10:15:45.262 25 ERROR cinder.volume.drivers.lightos     response = session.send(
2025-01-21 10:15:45.262 25 ERROR cinder.volume.drivers.lightos   File "/var/lib/kolla/venv/lib/python3.10/site-packages/requests/sessions.py", line 703, in send
2025-01-21 10:15:45.262 25 ERROR cinder.volume.drivers.lightos     r = adapter.send(request, **kwargs)
2025-01-21 10:15:45.262 25 ERROR cinder.volume.drivers.lightos   File "/var/lib/kolla/venv/lib/python3.10/site-packages/requests/adapters.py", line 700, in send
2025-01-21 10:15:45.262 25 ERROR cinder.volume.drivers.lightos     raise ConnectionError(e, request=request)
2025-01-21 10:15:45.262 25 ERROR cinder.volume.drivers.lightos requests.exceptions.ConnectionError: HTTPSConnectionPool(host='[LB_IP_ADDRESS]', port=443): Max retries exceeded with url: /api/v2/clusterinfo (Caused by NewConnectionError('<urllib3.connection.HTTPSConnection object at 0x7f1a88d6ca30>: Failed to establish a new connection: [Errno 111] ECONNREFUSED'))
2025-01-21 10:15:45.262 25 ERROR cinder.volume.drivers.lightos 
2025-01-21 10:15:45.264 25 INFO cinder.volume.drivers.lightos [None req-a64abf7e-20c6-4725-9cfb-78c20b6d991f - - - - - -] Invoking get_cluster_info using GET url: /api/v2/clusterinfo             request.body: {} ssl_verify: False
2025-01-21 10:15:45.267 25 ERROR cinder.volume.drivers.lightos [None req-a64abf7e-20c6-4725-9cfb-78c20b6d991f - - - - - -] REST server not responding at 'https://[LB_IP_ADDRESS]:443/api/v2/clusterinfo': requests.exceptions.ConnectionError: HTTPSConnectionPool(host='[LB_IP_ADDRESS]', port=443): Max retries exceeded with url: /api/v2/clusterinfo (Caused by NewConnectionError('<urllib3.connection.HTTPSConnection object at 0x7f1a88d6c610>: Failed to establish a new connection: [Errno 111] ECONNREFUSED'))
2025-01-21 10:15:45.267 25 ERROR cinder.volume.drivers.lightos Traceback (most recent call last):
2025-01-21 10:15:45.267 25 ERROR cinder.volume.drivers.lightos   File "/var/lib/kolla/venv/lib/python3.10/site-packages/urllib3/connection.py", line 174, in _new_conn
2025-01-21 10:15:45.267 25 ERROR cinder.volume.drivers.lightos     conn = connection.create_connection(
2025-01-21 10:15:45.267 25 ERROR cinder.volume.drivers.lightos   File "/var/lib/kolla/venv/lib/python3.10/site-packages/urllib3/util/connection.py", line 95, in create_connection
2025-01-21 10:15:45.267 25 ERROR cinder.volume.drivers.lightos     raise err
2025-01-21 10:15:45.267 25 ERROR cinder.volume.drivers.lightos   File "/var/lib/kolla/venv/lib/python3.10/site-packages/urllib3/util/connection.py", line 85, in create_connection
2025-01-21 10:15:45.267 25 ERROR cinder.volume.drivers.lightos     sock.connect(sa)
2025-01-21 10:15:45.267 25 ERROR cinder.volume.drivers.lightos   File "/var/lib/kolla/venv/lib/python3.10/site-packages/eventlet/greenio/base.py", line 265, in connect
2025-01-21 10:15:45.267 25 ERROR cinder.volume.drivers.lightos     socket_checkerr(fd)
2025-01-21 10:15:45.267 25 ERROR cinder.volume.drivers.lightos   File "/var/lib/kolla/venv/lib/python3.10/site-packages/eventlet/greenio/base.py", line 50, in socket_checkerr
2025-01-21 10:15:45.267 25 ERROR cinder.volume.drivers.lightos     raise OSError(err, errno.errorcode[err])
2025-01-21 10:15:45.267 25 ERROR cinder.volume.drivers.lightos ConnectionRefusedError: [Errno 111] ECONNREFUSED
2025-01-21 10:15:45.267 25 ERROR cinder.volume.drivers.lightos 
2025-01-21 10:15:45.267 25 ERROR cinder.volume.drivers.lightos During handling of the above exception, another exception occurred:
2025-01-21 10:15:45.267 25 ERROR cinder.volume.drivers.lightos 
2025-01-21 10:15:45.267 25 ERROR cinder.volume.drivers.lightos Traceback (most recent call last):
2025-01-21 10:15:45.267 25 ERROR cinder.volume.drivers.lightos   File "/var/lib/kolla/venv/lib/python3.10/site-packages/urllib3/connectionpool.py", line 715, in urlopen
2025-01-21 10:15:45.267 25 ERROR cinder.volume.drivers.lightos     httplib_response = self._make_request(
2025-01-21 10:15:45.267 25 ERROR cinder.volume.drivers.lightos   File "/var/lib/kolla/venv/lib/python3.10/site-packages/urllib3/connectionpool.py", line 404, in _make_request
2025-01-21 10:15:45.267 25 ERROR cinder.volume.drivers.lightos     self._validate_conn(conn)
2025-01-21 10:15:45.267 25 ERROR cinder.volume.drivers.lightos   File "/var/lib/kolla/venv/lib/python3.10/site-packages/urllib3/connectionpool.py", line 1060, in _validate_conn
2025-01-21 10:15:45.267 25 ERROR cinder.volume.drivers.lightos     conn.connect()
2025-01-21 10:15:45.267 25 ERROR cinder.volume.drivers.lightos   File "/var/lib/kolla/venv/lib/python3.10/site-packages/urllib3/connection.py", line 363, in connect
2025-01-21 10:15:45.267 25 ERROR cinder.volume.drivers.lightos     self.sock = conn = self._new_conn()
2025-01-21 10:15:45.267 25 ERROR cinder.volume.drivers.lightos   File "/var/lib/kolla/venv/lib/python3.10/site-packages/urllib3/connection.py", line 186, in _new_conn
2025-01-21 10:15:45.267 25 ERROR cinder.volume.drivers.lightos     raise NewConnectionError(
2025-01-21 10:15:45.267 25 ERROR cinder.volume.drivers.lightos urllib3.exceptions.NewConnectionError: <urllib3.connection.HTTPSConnection object at 0x7f1a88d6c610>: Failed to establish a new connection: [Errno 111] ECONNREFUSED
2025-01-21 10:15:45.267 25 ERROR cinder.volume.drivers.lightos 
2025-01-21 10:15:45.267 25 ERROR cinder.volume.drivers.lightos During handling of the above exception, another exception occurred:
2025-01-21 10:15:45.267 25 ERROR cinder.volume.drivers.lightos 
2025-01-21 10:15:45.267 25 ERROR cinder.volume.drivers.lightos Traceback (most recent call last):
2025-01-21 10:15:45.267 25 ERROR cinder.volume.drivers.lightos   File "/var/lib/kolla/venv/lib/python3.10/site-packages/requests/adapters.py", line 667, in send
2025-01-21 10:15:45.267 25 ERROR cinder.volume.drivers.lightos     resp = conn.urlopen(
2025-01-21 10:15:45.267 25 ERROR cinder.volume.drivers.lightos   File "/var/lib/kolla/venv/lib/python3.10/site-packages/urllib3/connectionpool.py", line 801, in urlopen
2025-01-21 10:15:45.267 25 ERROR cinder.volume.drivers.lightos     retries = retries.increment(
2025-01-21 10:15:45.267 25 ERROR cinder.volume.drivers.lightos   File "/var/lib/kolla/venv/lib/python3.10/site-packages/urllib3/util/retry.py", line 594, in increment
2025-01-21 10:15:45.267 25 ERROR cinder.volume.drivers.lightos     raise MaxRetryError(_pool, url, error or ResponseError(cause))
2025-01-21 10:15:45.267 25 ERROR cinder.volume.drivers.lightos urllib3.exceptions.MaxRetryError: HTTPSConnectionPool(host='[LB_IP_ADDRESS]', port=443): Max retries exceeded with url: /api/v2/clusterinfo (Caused by NewConnectionError('<urllib3.connection.HTTPSConnection object at 0x7f1a88d6c610>: Failed to establish a new connection: [Errno 111] ECONNREFUSED'))
2025-01-21 10:15:45.267 25 ERROR cinder.volume.drivers.lightos 
2025-01-21 10:15:45.267 25 ERROR cinder.volume.drivers.lightos During handling of the above exception, another exception occurred:
2025-01-21 10:15:45.267 25 ERROR cinder.volume.drivers.lightos 
2025-01-21 10:15:45.267 25 ERROR cinder.volume.drivers.lightos Traceback (most recent call last):
2025-01-21 10:15:45.267 25 ERROR cinder.volume.drivers.lightos   File "/var/lib/kolla/venv/lib/python3.10/site-packages/cinder/volume/drivers/lightos.py", line 356, in __send_cmd
2025-01-21 10:15:45.267 25 ERROR cinder.volume.drivers.lightos     response = session.send(
2025-01-21 10:15:45.267 25 ERROR cinder.volume.drivers.lightos   File "/var/lib/kolla/venv/lib/python3.10/site-packages/requests/sessions.py", line 703, in send
2025-01-21 10:15:45.267 25 ERROR cinder.volume.drivers.lightos     r = adapter.send(request, **kwargs)
2025-01-21 10:15:45.267 25 ERROR cinder.volume.drivers.lightos   File "/var/lib/kolla/venv/lib/python3.10/site-packages/requests/adapters.py", line 700, in send
2025-01-21 10:15:45.267 25 ERROR cinder.volume.drivers.lightos     raise ConnectionError(e, request=request)
2025-01-21 10:15:45.267 25 ERROR cinder.volume.drivers.lightos requests.exceptions.ConnectionError: HTTPSConnectionPool(host='[LB_IP_ADDRESS]', port=443): Max retries exceeded with url: /api/v2/clusterinfo (Caused by NewConnectionError('<urllib3.connection.HTTPSConnection object at 0x7f1a88d6c610>: Failed to establish a new connection: [Errno 111] ECONNREFUSED'))
2025-01-21 10:15:45.267 25 ERROR cinder.volume.drivers.lightos 
2025-01-21 10:15:45.268 25 INFO cinder.volume.drivers.lightos [None req-a64abf7e-20c6-4725-9cfb-78c20b6d991f - - - - - -] Invoking get_cluster_info using GET url: /api/v2/clusterinfo             request.body: {} ssl_verify: False
2025-01-21 10:15:48.322 25 ERROR cinder.volume.drivers.lightos [None req-a64abf7e-20c6-4725-9cfb-78c20b6d991f - - - - - -] REST server not responding at 'https://[LB_IP_ADDRESS]:443/api/v2/clusterinfo': requests.exceptions.ConnectionError: HTTPSConnectionPool(host='[LB_IP_ADDRESS]', port=443): Max retries exceeded with url: /api/v2/clusterinfo (Caused by NewConnectionError('<urllib3.connection.HTTPSConnection object at 0x7f1a88d001f0>: Failed to establish a new connection: [Errno 113] EHOSTUNREACH'))
2025-01-21 10:15:48.322 25 ERROR cinder.volume.drivers.lightos Traceback (most recent call last):
2025-01-21 10:15:48.322 25 ERROR cinder.volume.drivers.lightos   File "/var/lib/kolla/venv/lib/python3.10/site-packages/urllib3/connection.py", line 174, in _new_conn
2025-01-21 10:15:48.322 25 ERROR cinder.volume.drivers.lightos     conn = connection.create_connection(
2025-01-21 10:15:48.322 25 ERROR cinder.volume.drivers.lightos   File "/var/lib/kolla/venv/lib/python3.10/site-packages/urllib3/util/connection.py", line 95, in create_connection
2025-01-21 10:15:48.322 25 ERROR cinder.volume.drivers.lightos     raise err
2025-01-21 10:15:48.322 25 ERROR cinder.volume.drivers.lightos   File "/var/lib/kolla/venv/lib/python3.10/site-packages/urllib3/util/connection.py", line 85, in create_connection
2025-01-21 10:15:48.322 25 ERROR cinder.volume.drivers.lightos     sock.connect(sa)
2025-01-21 10:15:48.322 25 ERROR cinder.volume.drivers.lightos   File "/var/lib/kolla/venv/lib/python3.10/site-packages/eventlet/greenio/base.py", line 265, in connect
2025-01-21 10:15:48.322 25 ERROR cinder.volume.drivers.lightos     socket_checkerr(fd)
2025-01-21 10:15:48.322 25 ERROR cinder.volume.drivers.lightos   File "/var/lib/kolla/venv/lib/python3.10/site-packages/eventlet/greenio/base.py", line 50, in socket_checkerr
2025-01-21 10:15:48.322 25 ERROR cinder.volume.drivers.lightos     raise OSError(err, errno.errorcode[err])
2025-01-21 10:15:48.322 25 ERROR cinder.volume.drivers.lightos OSError: [Errno 113] EHOSTUNREACH
2025-01-21 10:15:48.322 25 ERROR cinder.volume.drivers.lightos 
2025-01-21 10:15:48.322 25 ERROR cinder.volume.drivers.lightos During handling of the above exception, another exception occurred:
2025-01-21 10:15:48.322 25 ERROR cinder.volume.drivers.lightos 
2025-01-21 10:15:48.322 25 ERROR cinder.volume.drivers.lightos Traceback (most recent call last):
2025-01-21 10:15:48.322 25 ERROR cinder.volume.drivers.lightos   File "/var/lib/kolla/venv/lib/python3.10/site-packages/urllib3/connectionpool.py", line 715, in urlopen
2025-01-21 10:15:48.322 25 ERROR cinder.volume.drivers.lightos     httplib_response = self._make_request(
2025-01-21 10:15:48.322 25 ERROR cinder.volume.drivers.lightos   File "/var/lib/kolla/venv/lib/python3.10/site-packages/urllib3/connectionpool.py", line 404, in _make_request
2025-01-21 10:15:48.322 25 ERROR cinder.volume.drivers.lightos     self._validate_conn(conn)
2025-01-21 10:15:48.322 25 ERROR cinder.volume.drivers.lightos   File "/var/lib/kolla/venv/lib/python3.10/site-packages/urllib3/connectionpool.py", line 1060, in _validate_conn
2025-01-21 10:15:48.322 25 ERROR cinder.volume.drivers.lightos     conn.connect()
2025-01-21 10:15:48.322 25 ERROR cinder.volume.drivers.lightos   File "/var/lib/kolla/venv/lib/python3.10/site-packages/urllib3/connection.py", line 363, in connect
2025-01-21 10:15:48.322 25 ERROR cinder.volume.drivers.lightos     self.sock = conn = self._new_conn()
2025-01-21 10:15:48.322 25 ERROR cinder.volume.drivers.lightos   File "/var/lib/kolla/venv/lib/python3.10/site-packages/urllib3/connection.py", line 186, in _new_conn
2025-01-21 10:15:48.322 25 ERROR cinder.volume.drivers.lightos     raise NewConnectionError(
2025-01-21 10:15:48.322 25 ERROR cinder.volume.drivers.lightos urllib3.exceptions.NewConnectionError: <urllib3.connection.HTTPSConnection object at 0x7f1a88d001f0>: Failed to establish a new connection: [Errno 113] EHOSTUNREACH
2025-01-21 10:15:48.322 25 ERROR cinder.volume.drivers.lightos 
2025-01-21 10:15:48.322 25 ERROR cinder.volume.drivers.lightos During handling of the above exception, another exception occurred:
2025-01-21 10:15:48.322 25 ERROR cinder.volume.drivers.lightos 
2025-01-21 10:15:48.322 25 ERROR cinder.volume.drivers.lightos Traceback (most recent call last):
2025-01-21 10:15:48.322 25 ERROR cinder.volume.drivers.lightos   File "/var/lib/kolla/venv/lib/python3.10/site-packages/requests/adapters.py", line 667, in send
2025-01-21 10:15:48.322 25 ERROR cinder.volume.drivers.lightos     resp = conn.urlopen(
2025-01-21 10:15:48.322 25 ERROR cinder.volume.drivers.lightos   File "/var/lib/kolla/venv/lib/python3.10/site-packages/urllib3/connectionpool.py", line 801, in urlopen
2025-01-21 10:15:48.322 25 ERROR cinder.volume.drivers.lightos     retries = retries.increment(
2025-01-21 10:15:48.322 25 ERROR cinder.volume.drivers.lightos   File "/var/lib/kolla/venv/lib/python3.10/site-packages/urllib3/util/retry.py", line 594, in increment
2025-01-21 10:15:48.322 25 ERROR cinder.volume.drivers.lightos     raise MaxRetryError(_pool, url, error or ResponseError(cause))
2025-01-21 10:15:48.322 25 ERROR cinder.volume.drivers.lightos urllib3.exceptions.MaxRetryError: HTTPSConnectionPool(host='[LB_IP_ADDRESS]', port=443): Max retries exceeded with url: /api/v2/clusterinfo (Caused by NewConnectionError('<urllib3.connection.HTTPSConnection object at 0x7f1a88d001f0>: Failed to establish a new connection: [Errno 113] EHOSTUNREACH'))
2025-01-21 10:15:48.322 25 ERROR cinder.volume.drivers.lightos 
2025-01-21 10:15:48.322 25 ERROR cinder.volume.drivers.lightos During handling of the above exception, another exception occurred:
2025-01-21 10:15:48.322 25 ERROR cinder.volume.drivers.lightos 
2025-01-21 10:15:48.322 25 ERROR cinder.volume.drivers.lightos Traceback (most recent call last):
2025-01-21 10:15:48.322 25 ERROR cinder.volume.drivers.lightos   File "/var/lib/kolla/venv/lib/python3.10/site-packages/cinder/volume/drivers/lightos.py", line 356, in __send_cmd
2025-01-21 10:15:48.322 25 ERROR cinder.volume.drivers.lightos     response = session.send(
2025-01-21 10:15:48.322 25 ERROR cinder.volume.drivers.lightos   File "/var/lib/kolla/venv/lib/python3.10/site-packages/requests/sessions.py", line 703, in send
2025-01-21 10:15:48.322 25 ERROR cinder.volume.drivers.lightos     r = adapter.send(request, **kwargs)
2025-01-21 10:15:48.322 25 ERROR cinder.volume.drivers.lightos   File "/var/lib/kolla/venv/lib/python3.10/site-packages/requests/adapters.py", line 700, in send
2025-01-21 10:15:48.322 25 ERROR cinder.volume.drivers.lightos     raise ConnectionError(e, request=request)
2025-01-21 10:15:48.322 25 ERROR cinder.volume.drivers.lightos requests.exceptions.ConnectionError: HTTPSConnectionPool(host='[LB_IP_ADDRESS]', port=443): Max retries exceeded with url: /api/v2/clusterinfo (Caused by NewConnectionError('<urllib3.connection.HTTPSConnection object at 0x7f1a88d001f0>: Failed to establish a new connection: [Errno 113] EHOSTUNREACH'))
2025-01-21 10:15:48.322 25 ERROR cinder.volume.drivers.lightos 
2025-01-21 10:15:48.324 25 ERROR cinder.volume.manager [None req-a64abf7e-20c6-4725-9cfb-78c20b6d991f - - - - - -] Failed to initialize driver.: cinder.exception.VolumeDriverException: Volume driver reported an error: Could not get a response from any API server
2025-01-21 10:15:48.324 25 ERROR cinder.volume.manager Traceback (most recent call last):
2025-01-21 10:15:48.324 25 ERROR cinder.volume.manager   File "/var/lib/kolla/venv/lib/python3.10/site-packages/cinder/volume/manager.py", line 523, in _init_host
2025-01-21 10:15:48.324 25 ERROR cinder.volume.manager     self.driver.do_setup(ctxt)
2025-01-21 10:15:48.324 25 ERROR cinder.volume.manager   File "/var/lib/kolla/venv/lib/python3.10/site-packages/cinder/volume/drivers/lightos.py", line 922, in do_setup
2025-01-21 10:15:48.324 25 ERROR cinder.volume.manager     self.get_cluster_info()
2025-01-21 10:15:48.324 25 ERROR cinder.volume.manager   File "/var/lib/kolla/venv/lib/python3.10/site-packages/cinder/volume/drivers/lightos.py", line 873, in get_cluster_info
2025-01-21 10:15:48.324 25 ERROR cinder.volume.manager     status_code, cluster_info = self.cluster.send_cmd(
2025-01-21 10:15:48.324 25 ERROR cinder.volume.manager   File "/var/lib/kolla/venv/lib/python3.10/site-packages/cinder/volume/drivers/lightos.py", line 315, in send_cmd
2025-01-21 10:15:48.324 25 ERROR cinder.volume.manager     raise exception.VolumeDriverException(
2025-01-21 10:15:48.324 25 ERROR cinder.volume.manager cinder.exception.VolumeDriverException: Volume driver reported an error: Could not get a response from any API server
2025-01-21 10:15:48.324 25 ERROR cinder.volume.manager 
2025-01-21 10:15:48.347 25 WARNING oslo_config.cfg [None req-a64abf7e-20c6-4725-9cfb-78c20b6d991f - - - - - -] Deprecated: Option "heartbeat_in_pthread" from group "oslo_messaging_rabbit" is deprecated for removal (The option is related to Eventlet which will be removed. In addition this has never worked as expected with services using eventlet for core service framework.).  Its value may be silently ignored in the future.
2025-01-21 10:15:48.396 25 INFO cinder.service [None req-a64abf7e-20c6-4725-9cfb-78c20b6d991f - - - - - -] Starting cinder-volume cluster lightos_cinder_cluster@LIGHTOSyilgqu (version 25.1.0)
2025-01-21 10:15:48.418 25 INFO cinder.volume.manager [None req-a64abf7e-20c6-4725-9cfb-78c20b6d991f - - - - - -] Initializing RPC dependent components of volume driver LightOSVolumeDriver (2.3.12)
2025-01-21 10:15:48.418 25 ERROR cinder.volume.volume_utils [None req-a64abf7e-20c6-4725-9cfb-78c20b6d991f - - - - - -] Volume driver LightOSVolumeDriver not initialized
2025-01-21 10:15:48.418 25 ERROR cinder.volume.manager [None req-a64abf7e-20c6-4725-9cfb-78c20b6d991f - - - - - -] Cannot complete RPC initialization because driver isn't initialized properly.: cinder.exception.DriverNotInitialized: Volume driver not ready.
2025-01-21 10:15:58.420 25 ERROR cinder.service [-] Manager for service cinder-volume rack13-server67@LIGHTOSyilgqu is reporting problems, not sending heartbeat. Service will appear "down".
2025-01-21 10:16:08.423 25 ERROR cinder.service [-] Manager for service cinder-volume rack13-server67@LIGHTOSyilgqu is reporting problems, not sending heartbeat. Service will appear "down".
2025-01-21 10:16:18.425 25 ERROR cinder.service [-] Manager for service cinder-volume rack13-server67@LIGHTOSyilgqu is reporting problems, not sending heartbeat. Service will appear "down".
2025-01-21 10:16:28.427 25 ERROR cinder.service [-] Manager for service cinder-volume rack13-server67@LIGHTOSyilgqu is reporting problems, not sending heartbeat. Service will appear "down".
2025-01-21 10:16:38.428 25 ERROR cinder.service [-] Manager for service cinder-volume rack13-server67@LIGHTOSyilgqu is reporting problems, not sending heartbeat. Service will appear "down".
2025-01-21 10:16:48.430 25 ERROR cinder.service [-] Manager for service cinder-volume rack13-server67@LIGHTOSyilgqu is reporting problems, not sending heartbeat. Service will appear "down".
2025-01-21 10:16:57.422 25 WARNING cinder.volume.manager [None req-1776abbf-83f8-4d93-975f-08491e4294a4 - - - - - -] Update driver status failed: (config name LIGHTOSyilgqu) is uninitialized.
2025-01-21 10:16:58.431 25 ERROR cinder.service [-] Manager for service cinder-volume rack13-server67@LIGHTOSyilgqu is reporting problems, not sending heartbeat. Service will appear "down".
2025-01-21 10:17:08.432 25 ERROR cinder.service [-] Manager for service cinder-volume rack13-server67@LIGHTOSyilgqu is reporting problems, not sending heartbeat. Service will appear "down".
2025-01-21 10:17:18.434 25 ERROR cinder.service [-] Manager for service cinder-volume rack13-server67@LIGHTOSyilgqu is reporting problems, not sending heartbeat. Service will appear "down".
2025-01-21 10:17:28.436 25 ERROR cinder.service [-] Manager for service cinder-volume rack13-server67@LIGHTOSyilgqu is reporting problems, not sending heartbeat. Service will appear "down".
2025-01-21 10:17:38.437 25 ERROR cinder.service [-] Manager for service cinder-volume rack13-server67@LIGHTOSyilgqu is reporting problems, not sending heartbeat. Service will appear "down".
2025-01-21 10:17:48.438 25 ERROR cinder.service [-] Manager for service cinder-volume rack13-server67@LIGHTOSyilgqu is reporting problems, not sending heartbeat. Service will appear "down".
2025-01-21 10:17:57.425 25 WARNING cinder.volume.manager [None req-1776abbf-83f8-4d93-975f-08491e4294a4 - - - - - -] Update driver status failed: (config name LIGHTOSyilgqu) is uninitialized.
2025-01-21 10:17:58.439 25 ERROR cinder.service [-] Manager for service cinder-volume rack13-server67@LIGHTOSyilgqu is reporting problems, not sending heartbeat. Service will appear "down".
2025-01-21 10:18:08.440 25 ERROR cinder.service [-] Manager for service cinder-volume rack13-server67@LIGHTOSyilgqu is reporting problems, not sending heartbeat. Service will appear "down".
2025-01-21 10:18:18.442 25 ERROR cinder.service [-] Manager for service cinder-volume rack13-server67@LIGHTOSyilgqu is reporting problems, not sending heartbeat. Service will appear "down".
2025-01-21 10:18:28.443 25 ERROR cinder.service [-] Manager for service cinder-volume rack13-server67@LIGHTOSyilgqu is reporting problems, not sending heartbeat. Service will appear "down".
2025-01-21 10:18:38.447 25 ERROR cinder.service [-] Manager for service cinder-volume rack13-server67@LIGHTOSyilgqu is reporting problems, not sending heartbeat. Service will appear "down".
2025-01-21 10:18:48.449 25 ERROR cinder.service [-] Manager for service cinder-volume rack13-server67@LIGHTOSyilgqu is reporting problems, not sending heartbeat. Service will appear "down".
2025-01-21 10:18:57.427 25 WARNING cinder.volume.manager [None req-1776abbf-83f8-4d93-975f-08491e4294a4 - - - - - -] Update driver status failed: (config name LIGHTOSyilgqu) is uninitialized.
2025-01-21 10:18:58.450 25 ERROR cinder.service [-] Manager for service cinder-volume rack13-server67@LIGHTOSyilgqu is reporting problems, not sending heartbeat. Service will appear "down".
2025-01-21 10:19:08.452 25 ERROR cinder.service [-] Manager for service cinder-volume rack13-server67@LIGHTOSyilgqu is reporting problems, not sending heartbeat. Service will appear "down".
2025-01-21 10:19:18.454 25 ERROR cinder.service [-] Manager for service cinder-volume rack13-server67@LIGHTOSyilgqu is reporting problems, not sending heartbeat. Service will appear "down".
2025-01-21 10:19:28.455 25 ERROR cinder.service [-] Manager for service cinder-volume rack13-server67@LIGHTOSyilgqu is reporting problems, not sending heartbeat. Service will appear "down".
