Build Started 21_01_2025_16_24_00
2025-01-21 16:24:09.135 25 ERROR cinder.service [-] Manager for service cinder-volume rack13-server67@LIGHTOSyilgqu is reporting problems, not sending heartbeat. Service will appear "down".
2025-01-21 16:24:10.808 7 INFO oslo_service.service [None req-3846d742-4e00-445b-9562-452ad327f681 - - - - - -] Caught SIGTERM, stopping children
2025-01-21 16:24:10.819 7 INFO oslo_service.service [None req-3846d742-4e00-445b-9562-452ad327f681 - - - - - -] Waiting on 1 children to exit
2025-01-21 16:24:14.028 25 WARNING amqp [None req-3846d742-4e00-445b-9562-452ad327f681 - - - - - -] Received method (60, 30) during closing channel 1. This method will be ignored
2025-01-21 16:24:14.036 25 WARNING amqp [None req-3846d742-4e00-445b-9562-452ad327f681 - - - - - -] Received method (60, 30) during closing channel 1. This method will be ignored
2025-01-21 16:24:14.043 25 WARNING amqp [None req-3846d742-4e00-445b-9562-452ad327f681 - - - - - -] Received method (60, 30) during closing channel 1. This method will be ignored
2025-01-21 16:24:14.054 7 INFO oslo_service.service [None req-3846d742-4e00-445b-9562-452ad327f681 - - - - - -] Child 25 exited with status 0
2025-01-21 16:24:29.589 7 INFO cinder.rpc [None req-d60ce701-9252-43f1-8852-0a335e3e7150 - - - - - -] Automatically selected cinder-scheduler objects version 1.39 as minimum service version.
2025-01-21 16:24:29.593 7 INFO cinder.rpc [None req-d60ce701-9252-43f1-8852-0a335e3e7150 - - - - - -] Automatically selected cinder-scheduler RPC version 3.12 as minimum service version.
2025-01-21 16:24:29.628 7 INFO cinder.volume.manager [None req-d60ce701-9252-43f1-8852-0a335e3e7150 - - - - - -] Determined volume DB was empty at startup.
2025-01-21 16:24:29.646 7 INFO cinder.volume.manager [None req-d60ce701-9252-43f1-8852-0a335e3e7150 - - - - - -] Image-volume cache disabled for host rack13-server67@LIGHTOSyilgqu.
2025-01-21 16:24:29.662 7 INFO oslo_service.service [None req-d60ce701-9252-43f1-8852-0a335e3e7150 - - - - - -] Starting 1 workers
2025-01-21 16:24:29.673 25 INFO cinder.service [-] Starting cinder-volume node (version 25.1.0)
2025-01-21 16:24:29.679 7 WARNING oslo_config.cfg [None req-d60ce701-9252-43f1-8852-0a335e3e7150 - - - - - -] Deprecated: Option "heartbeat_in_pthread" from group "oslo_messaging_rabbit" is deprecated for removal (The option is related to Eventlet which will be removed. In addition this has never worked as expected with services using eventlet for core service framework.).  Its value may be silently ignored in the future.
2025-01-21 16:24:29.692 25 INFO cinder.volume.manager [None req-9e00f5ec-d1cd-4f24-bf2a-c5a2c03ca1d3 - - - - - -] Starting volume driver LightOSVolumeDriver (2.3.12)
2025-01-21 16:24:29.693 25 INFO cinder.volume.drivers.lightos [None req-9e00f5ec-d1cd-4f24-bf2a-c5a2c03ca1d3 - - - - - -] Invoking get_cluster_info using GET url: /api/v2/clusterinfo             request.body: {} ssl_verify: False
2025-01-21 16:24:29.695 25 ERROR cinder.volume.drivers.lightos [None req-9e00f5ec-d1cd-4f24-bf2a-c5a2c03ca1d3 - - - - - -] REST server not responding at 'https://[LB_IP_ADDRESS]:443/api/v2/clusterinfo': requests.exceptions.ConnectionError: HTTPSConnectionPool(host='[LB_IP_ADDRESS]', port=443): Max retries exceeded with url: /api/v2/clusterinfo (Caused by NewConnectionError('<urllib3.connection.HTTPSConnection object at 0x7f57f4bf9c30>: Failed to establish a new connection: [Errno 111] ECONNREFUSED'))
2025-01-21 16:24:29.695 25 ERROR cinder.volume.drivers.lightos Traceback (most recent call last):
2025-01-21 16:24:29.695 25 ERROR cinder.volume.drivers.lightos   File "/var/lib/kolla/venv/lib/python3.10/site-packages/urllib3/connection.py", line 174, in _new_conn
2025-01-21 16:24:29.695 25 ERROR cinder.volume.drivers.lightos     conn = connection.create_connection(
2025-01-21 16:24:29.695 25 ERROR cinder.volume.drivers.lightos   File "/var/lib/kolla/venv/lib/python3.10/site-packages/urllib3/util/connection.py", line 95, in create_connection
2025-01-21 16:24:29.695 25 ERROR cinder.volume.drivers.lightos     raise err
2025-01-21 16:24:29.695 25 ERROR cinder.volume.drivers.lightos   File "/var/lib/kolla/venv/lib/python3.10/site-packages/urllib3/util/connection.py", line 85, in create_connection
2025-01-21 16:24:29.695 25 ERROR cinder.volume.drivers.lightos     sock.connect(sa)
2025-01-21 16:24:29.695 25 ERROR cinder.volume.drivers.lightos   File "/var/lib/kolla/venv/lib/python3.10/site-packages/eventlet/greenio/base.py", line 265, in connect
2025-01-21 16:24:29.695 25 ERROR cinder.volume.drivers.lightos     socket_checkerr(fd)
2025-01-21 16:24:29.695 25 ERROR cinder.volume.drivers.lightos   File "/var/lib/kolla/venv/lib/python3.10/site-packages/eventlet/greenio/base.py", line 50, in socket_checkerr
2025-01-21 16:24:29.695 25 ERROR cinder.volume.drivers.lightos     raise OSError(err, errno.errorcode[err])
2025-01-21 16:24:29.695 25 ERROR cinder.volume.drivers.lightos ConnectionRefusedError: [Errno 111] ECONNREFUSED
2025-01-21 16:24:29.695 25 ERROR cinder.volume.drivers.lightos 
2025-01-21 16:24:29.695 25 ERROR cinder.volume.drivers.lightos During handling of the above exception, another exception occurred:
2025-01-21 16:24:29.695 25 ERROR cinder.volume.drivers.lightos 
2025-01-21 16:24:29.695 25 ERROR cinder.volume.drivers.lightos Traceback (most recent call last):
2025-01-21 16:24:29.695 25 ERROR cinder.volume.drivers.lightos   File "/var/lib/kolla/venv/lib/python3.10/site-packages/urllib3/connectionpool.py", line 715, in urlopen
2025-01-21 16:24:29.695 25 ERROR cinder.volume.drivers.lightos     httplib_response = self._make_request(
2025-01-21 16:24:29.695 25 ERROR cinder.volume.drivers.lightos   File "/var/lib/kolla/venv/lib/python3.10/site-packages/urllib3/connectionpool.py", line 404, in _make_request
2025-01-21 16:24:29.695 25 ERROR cinder.volume.drivers.lightos     self._validate_conn(conn)
2025-01-21 16:24:29.695 25 ERROR cinder.volume.drivers.lightos   File "/var/lib/kolla/venv/lib/python3.10/site-packages/urllib3/connectionpool.py", line 1060, in _validate_conn
2025-01-21 16:24:29.695 25 ERROR cinder.volume.drivers.lightos     conn.connect()
2025-01-21 16:24:29.695 25 ERROR cinder.volume.drivers.lightos   File "/var/lib/kolla/venv/lib/python3.10/site-packages/urllib3/connection.py", line 363, in connect
2025-01-21 16:24:29.695 25 ERROR cinder.volume.drivers.lightos     self.sock = conn = self._new_conn()
2025-01-21 16:24:29.695 25 ERROR cinder.volume.drivers.lightos   File "/var/lib/kolla/venv/lib/python3.10/site-packages/urllib3/connection.py", line 186, in _new_conn
2025-01-21 16:24:29.695 25 ERROR cinder.volume.drivers.lightos     raise NewConnectionError(
2025-01-21 16:24:29.695 25 ERROR cinder.volume.drivers.lightos urllib3.exceptions.NewConnectionError: <urllib3.connection.HTTPSConnection object at 0x7f57f4bf9c30>: Failed to establish a new connection: [Errno 111] ECONNREFUSED
2025-01-21 16:24:29.695 25 ERROR cinder.volume.drivers.lightos 
2025-01-21 16:24:29.695 25 ERROR cinder.volume.drivers.lightos During handling of the above exception, another exception occurred:
2025-01-21 16:24:29.695 25 ERROR cinder.volume.drivers.lightos 
2025-01-21 16:24:29.695 25 ERROR cinder.volume.drivers.lightos Traceback (most recent call last):
2025-01-21 16:24:29.695 25 ERROR cinder.volume.drivers.lightos   File "/var/lib/kolla/venv/lib/python3.10/site-packages/requests/adapters.py", line 667, in send
2025-01-21 16:24:29.695 25 ERROR cinder.volume.drivers.lightos     resp = conn.urlopen(
2025-01-21 16:24:29.695 25 ERROR cinder.volume.drivers.lightos   File "/var/lib/kolla/venv/lib/python3.10/site-packages/urllib3/connectionpool.py", line 801, in urlopen
2025-01-21 16:24:29.695 25 ERROR cinder.volume.drivers.lightos     retries = retries.increment(
2025-01-21 16:24:29.695 25 ERROR cinder.volume.drivers.lightos   File "/var/lib/kolla/venv/lib/python3.10/site-packages/urllib3/util/retry.py", line 594, in increment
2025-01-21 16:24:29.695 25 ERROR cinder.volume.drivers.lightos     raise MaxRetryError(_pool, url, error or ResponseError(cause))
2025-01-21 16:24:29.695 25 ERROR cinder.volume.drivers.lightos urllib3.exceptions.MaxRetryError: HTTPSConnectionPool(host='[LB_IP_ADDRESS]', port=443): Max retries exceeded with url: /api/v2/clusterinfo (Caused by NewConnectionError('<urllib3.connection.HTTPSConnection object at 0x7f57f4bf9c30>: Failed to establish a new connection: [Errno 111] ECONNREFUSED'))
2025-01-21 16:24:29.695 25 ERROR cinder.volume.drivers.lightos 
2025-01-21 16:24:29.695 25 ERROR cinder.volume.drivers.lightos During handling of the above exception, another exception occurred:
2025-01-21 16:24:29.695 25 ERROR cinder.volume.drivers.lightos 
2025-01-21 16:24:29.695 25 ERROR cinder.volume.drivers.lightos Traceback (most recent call last):
2025-01-21 16:24:29.695 25 ERROR cinder.volume.drivers.lightos   File "/var/lib/kolla/venv/lib/python3.10/site-packages/cinder/volume/drivers/lightos.py", line 356, in __send_cmd
2025-01-21 16:24:29.695 25 ERROR cinder.volume.drivers.lightos     response = session.send(
2025-01-21 16:24:29.695 25 ERROR cinder.volume.drivers.lightos   File "/var/lib/kolla/venv/lib/python3.10/site-packages/requests/sessions.py", line 703, in send
2025-01-21 16:24:29.695 25 ERROR cinder.volume.drivers.lightos     r = adapter.send(request, **kwargs)
2025-01-21 16:24:29.695 25 ERROR cinder.volume.drivers.lightos   File "/var/lib/kolla/venv/lib/python3.10/site-packages/requests/adapters.py", line 700, in send
2025-01-21 16:24:29.695 25 ERROR cinder.volume.drivers.lightos     raise ConnectionError(e, request=request)
2025-01-21 16:24:29.695 25 ERROR cinder.volume.drivers.lightos requests.exceptions.ConnectionError: HTTPSConnectionPool(host='[LB_IP_ADDRESS]', port=443): Max retries exceeded with url: /api/v2/clusterinfo (Caused by NewConnectionError('<urllib3.connection.HTTPSConnection object at 0x7f57f4bf9c30>: Failed to establish a new connection: [Errno 111] ECONNREFUSED'))
2025-01-21 16:24:29.695 25 ERROR cinder.volume.drivers.lightos 
2025-01-21 16:24:29.697 25 INFO cinder.volume.drivers.lightos [None req-9e00f5ec-d1cd-4f24-bf2a-c5a2c03ca1d3 - - - - - -] Invoking get_cluster_info using GET url: /api/v2/clusterinfo             request.body: {} ssl_verify: False
2025-01-21 16:24:32.769 25 ERROR cinder.volume.drivers.lightos [None req-9e00f5ec-d1cd-4f24-bf2a-c5a2c03ca1d3 - - - - - -] REST server not responding at 'https://[LB_IP_ADDRESS]:443/api/v2/clusterinfo': requests.exceptions.ConnectionError: HTTPSConnectionPool(host='[LB_IP_ADDRESS]', port=443): Max retries exceeded with url: /api/v2/clusterinfo (Caused by NewConnectionError('<urllib3.connection.HTTPSConnection object at 0x7f57f4bf8f70>: Failed to establish a new connection: [Errno 113] EHOSTUNREACH'))
2025-01-21 16:24:32.769 25 ERROR cinder.volume.drivers.lightos Traceback (most recent call last):
2025-01-21 16:24:32.769 25 ERROR cinder.volume.drivers.lightos   File "/var/lib/kolla/venv/lib/python3.10/site-packages/urllib3/connection.py", line 174, in _new_conn
2025-01-21 16:24:32.769 25 ERROR cinder.volume.drivers.lightos     conn = connection.create_connection(
2025-01-21 16:24:32.769 25 ERROR cinder.volume.drivers.lightos   File "/var/lib/kolla/venv/lib/python3.10/site-packages/urllib3/util/connection.py", line 95, in create_connection
2025-01-21 16:24:32.769 25 ERROR cinder.volume.drivers.lightos     raise err
2025-01-21 16:24:32.769 25 ERROR cinder.volume.drivers.lightos   File "/var/lib/kolla/venv/lib/python3.10/site-packages/urllib3/util/connection.py", line 85, in create_connection
2025-01-21 16:24:32.769 25 ERROR cinder.volume.drivers.lightos     sock.connect(sa)
2025-01-21 16:24:32.769 25 ERROR cinder.volume.drivers.lightos   File "/var/lib/kolla/venv/lib/python3.10/site-packages/eventlet/greenio/base.py", line 265, in connect
2025-01-21 16:24:32.769 25 ERROR cinder.volume.drivers.lightos     socket_checkerr(fd)
2025-01-21 16:24:32.769 25 ERROR cinder.volume.drivers.lightos   File "/var/lib/kolla/venv/lib/python3.10/site-packages/eventlet/greenio/base.py", line 50, in socket_checkerr
2025-01-21 16:24:32.769 25 ERROR cinder.volume.drivers.lightos     raise OSError(err, errno.errorcode[err])
2025-01-21 16:24:32.769 25 ERROR cinder.volume.drivers.lightos OSError: [Errno 113] EHOSTUNREACH
2025-01-21 16:24:32.769 25 ERROR cinder.volume.drivers.lightos 
2025-01-21 16:24:32.769 25 ERROR cinder.volume.drivers.lightos During handling of the above exception, another exception occurred:
2025-01-21 16:24:32.769 25 ERROR cinder.volume.drivers.lightos 
2025-01-21 16:24:32.769 25 ERROR cinder.volume.drivers.lightos Traceback (most recent call last):
2025-01-21 16:24:32.769 25 ERROR cinder.volume.drivers.lightos   File "/var/lib/kolla/venv/lib/python3.10/site-packages/urllib3/connectionpool.py", line 715, in urlopen
2025-01-21 16:24:32.769 25 ERROR cinder.volume.drivers.lightos     httplib_response = self._make_request(
2025-01-21 16:24:32.769 25 ERROR cinder.volume.drivers.lightos   File "/var/lib/kolla/venv/lib/python3.10/site-packages/urllib3/connectionpool.py", line 404, in _make_request
2025-01-21 16:24:32.769 25 ERROR cinder.volume.drivers.lightos     self._validate_conn(conn)
2025-01-21 16:24:32.769 25 ERROR cinder.volume.drivers.lightos   File "/var/lib/kolla/venv/lib/python3.10/site-packages/urllib3/connectionpool.py", line 1060, in _validate_conn
2025-01-21 16:24:32.769 25 ERROR cinder.volume.drivers.lightos     conn.connect()
2025-01-21 16:24:32.769 25 ERROR cinder.volume.drivers.lightos   File "/var/lib/kolla/venv/lib/python3.10/site-packages/urllib3/connection.py", line 363, in connect
2025-01-21 16:24:32.769 25 ERROR cinder.volume.drivers.lightos     self.sock = conn = self._new_conn()
2025-01-21 16:24:32.769 25 ERROR cinder.volume.drivers.lightos   File "/var/lib/kolla/venv/lib/python3.10/site-packages/urllib3/connection.py", line 186, in _new_conn
2025-01-21 16:24:32.769 25 ERROR cinder.volume.drivers.lightos     raise NewConnectionError(
2025-01-21 16:24:32.769 25 ERROR cinder.volume.drivers.lightos urllib3.exceptions.NewConnectionError: <urllib3.connection.HTTPSConnection object at 0x7f57f4bf8f70>: Failed to establish a new connection: [Errno 113] EHOSTUNREACH
2025-01-21 16:24:32.769 25 ERROR cinder.volume.drivers.lightos 
2025-01-21 16:24:32.769 25 ERROR cinder.volume.drivers.lightos During handling of the above exception, another exception occurred:
2025-01-21 16:24:32.769 25 ERROR cinder.volume.drivers.lightos 
2025-01-21 16:24:32.769 25 ERROR cinder.volume.drivers.lightos Traceback (most recent call last):
2025-01-21 16:24:32.769 25 ERROR cinder.volume.drivers.lightos   File "/var/lib/kolla/venv/lib/python3.10/site-packages/requests/adapters.py", line 667, in send
2025-01-21 16:24:32.769 25 ERROR cinder.volume.drivers.lightos     resp = conn.urlopen(
2025-01-21 16:24:32.769 25 ERROR cinder.volume.drivers.lightos   File "/var/lib/kolla/venv/lib/python3.10/site-packages/urllib3/connectionpool.py", line 801, in urlopen
2025-01-21 16:24:32.769 25 ERROR cinder.volume.drivers.lightos     retries = retries.increment(
2025-01-21 16:24:32.769 25 ERROR cinder.volume.drivers.lightos   File "/var/lib/kolla/venv/lib/python3.10/site-packages/urllib3/util/retry.py", line 594, in increment
2025-01-21 16:24:32.769 25 ERROR cinder.volume.drivers.lightos     raise MaxRetryError(_pool, url, error or ResponseError(cause))
2025-01-21 16:24:32.769 25 ERROR cinder.volume.drivers.lightos urllib3.exceptions.MaxRetryError: HTTPSConnectionPool(host='[LB_IP_ADDRESS]', port=443): Max retries exceeded with url: /api/v2/clusterinfo (Caused by NewConnectionError('<urllib3.connection.HTTPSConnection object at 0x7f57f4bf8f70>: Failed to establish a new connection: [Errno 113] EHOSTUNREACH'))
2025-01-21 16:24:32.769 25 ERROR cinder.volume.drivers.lightos 
2025-01-21 16:24:32.769 25 ERROR cinder.volume.drivers.lightos During handling of the above exception, another exception occurred:
2025-01-21 16:24:32.769 25 ERROR cinder.volume.drivers.lightos 
2025-01-21 16:24:32.769 25 ERROR cinder.volume.drivers.lightos Traceback (most recent call last):
2025-01-21 16:24:32.769 25 ERROR cinder.volume.drivers.lightos   File "/var/lib/kolla/venv/lib/python3.10/site-packages/cinder/volume/drivers/lightos.py", line 356, in __send_cmd
2025-01-21 16:24:32.769 25 ERROR cinder.volume.drivers.lightos     response = session.send(
2025-01-21 16:24:32.769 25 ERROR cinder.volume.drivers.lightos   File "/var/lib/kolla/venv/lib/python3.10/site-packages/requests/sessions.py", line 703, in send
2025-01-21 16:24:32.769 25 ERROR cinder.volume.drivers.lightos     r = adapter.send(request, **kwargs)
2025-01-21 16:24:32.769 25 ERROR cinder.volume.drivers.lightos   File "/var/lib/kolla/venv/lib/python3.10/site-packages/requests/adapters.py", line 700, in send
2025-01-21 16:24:32.769 25 ERROR cinder.volume.drivers.lightos     raise ConnectionError(e, request=request)
2025-01-21 16:24:32.769 25 ERROR cinder.volume.drivers.lightos requests.exceptions.ConnectionError: HTTPSConnectionPool(host='[LB_IP_ADDRESS]', port=443): Max retries exceeded with url: /api/v2/clusterinfo (Caused by NewConnectionError('<urllib3.connection.HTTPSConnection object at 0x7f57f4bf8f70>: Failed to establish a new connection: [Errno 113] EHOSTUNREACH'))
2025-01-21 16:24:32.769 25 ERROR cinder.volume.drivers.lightos 
2025-01-21 16:24:32.772 25 INFO cinder.volume.drivers.lightos [None req-9e00f5ec-d1cd-4f24-bf2a-c5a2c03ca1d3 - - - - - -] Invoking get_cluster_info using GET url: /api/v2/clusterinfo             request.body: {} ssl_verify: False
2025-01-21 16:24:32.775 25 ERROR cinder.volume.drivers.lightos [None req-9e00f5ec-d1cd-4f24-bf2a-c5a2c03ca1d3 - - - - - -] REST server not responding at 'https://[LB_IP_ADDRESS]:443/api/v2/clusterinfo': requests.exceptions.ConnectionError: HTTPSConnectionPool(host='[LB_IP_ADDRESS]', port=443): Max retries exceeded with url: /api/v2/clusterinfo (Caused by NewConnectionError('<urllib3.connection.HTTPSConnection object at 0x7f57f4bf8490>: Failed to establish a new connection: [Errno 111] ECONNREFUSED'))
2025-01-21 16:24:32.775 25 ERROR cinder.volume.drivers.lightos Traceback (most recent call last):
2025-01-21 16:24:32.775 25 ERROR cinder.volume.drivers.lightos   File "/var/lib/kolla/venv/lib/python3.10/site-packages/urllib3/connection.py", line 174, in _new_conn
2025-01-21 16:24:32.775 25 ERROR cinder.volume.drivers.lightos     conn = connection.create_connection(
2025-01-21 16:24:32.775 25 ERROR cinder.volume.drivers.lightos   File "/var/lib/kolla/venv/lib/python3.10/site-packages/urllib3/util/connection.py", line 95, in create_connection
2025-01-21 16:24:32.775 25 ERROR cinder.volume.drivers.lightos     raise err
2025-01-21 16:24:32.775 25 ERROR cinder.volume.drivers.lightos   File "/var/lib/kolla/venv/lib/python3.10/site-packages/urllib3/util/connection.py", line 85, in create_connection
2025-01-21 16:24:32.775 25 ERROR cinder.volume.drivers.lightos     sock.connect(sa)
2025-01-21 16:24:32.775 25 ERROR cinder.volume.drivers.lightos   File "/var/lib/kolla/venv/lib/python3.10/site-packages/eventlet/greenio/base.py", line 265, in connect
2025-01-21 16:24:32.775 25 ERROR cinder.volume.drivers.lightos     socket_checkerr(fd)
2025-01-21 16:24:32.775 25 ERROR cinder.volume.drivers.lightos   File "/var/lib/kolla/venv/lib/python3.10/site-packages/eventlet/greenio/base.py", line 50, in socket_checkerr
2025-01-21 16:24:32.775 25 ERROR cinder.volume.drivers.lightos     raise OSError(err, errno.errorcode[err])
2025-01-21 16:24:32.775 25 ERROR cinder.volume.drivers.lightos ConnectionRefusedError: [Errno 111] ECONNREFUSED
2025-01-21 16:24:32.775 25 ERROR cinder.volume.drivers.lightos 
2025-01-21 16:24:32.775 25 ERROR cinder.volume.drivers.lightos During handling of the above exception, another exception occurred:
2025-01-21 16:24:32.775 25 ERROR cinder.volume.drivers.lightos 
2025-01-21 16:24:32.775 25 ERROR cinder.volume.drivers.lightos Traceback (most recent call last):
2025-01-21 16:24:32.775 25 ERROR cinder.volume.drivers.lightos   File "/var/lib/kolla/venv/lib/python3.10/site-packages/urllib3/connectionpool.py", line 715, in urlopen
2025-01-21 16:24:32.775 25 ERROR cinder.volume.drivers.lightos     httplib_response = self._make_request(
2025-01-21 16:24:32.775 25 ERROR cinder.volume.drivers.lightos   File "/var/lib/kolla/venv/lib/python3.10/site-packages/urllib3/connectionpool.py", line 404, in _make_request
2025-01-21 16:24:32.775 25 ERROR cinder.volume.drivers.lightos     self._validate_conn(conn)
2025-01-21 16:24:32.775 25 ERROR cinder.volume.drivers.lightos   File "/var/lib/kolla/venv/lib/python3.10/site-packages/urllib3/connectionpool.py", line 1060, in _validate_conn
2025-01-21 16:24:32.775 25 ERROR cinder.volume.drivers.lightos     conn.connect()
2025-01-21 16:24:32.775 25 ERROR cinder.volume.drivers.lightos   File "/var/lib/kolla/venv/lib/python3.10/site-packages/urllib3/connection.py", line 363, in connect
2025-01-21 16:24:32.775 25 ERROR cinder.volume.drivers.lightos     self.sock = conn = self._new_conn()
2025-01-21 16:24:32.775 25 ERROR cinder.volume.drivers.lightos   File "/var/lib/kolla/venv/lib/python3.10/site-packages/urllib3/connection.py", line 186, in _new_conn
2025-01-21 16:24:32.775 25 ERROR cinder.volume.drivers.lightos     raise NewConnectionError(
2025-01-21 16:24:32.775 25 ERROR cinder.volume.drivers.lightos urllib3.exceptions.NewConnectionError: <urllib3.connection.HTTPSConnection object at 0x7f57f4bf8490>: Failed to establish a new connection: [Errno 111] ECONNREFUSED
2025-01-21 16:24:32.775 25 ERROR cinder.volume.drivers.lightos 
2025-01-21 16:24:32.775 25 ERROR cinder.volume.drivers.lightos During handling of the above exception, another exception occurred:
2025-01-21 16:24:32.775 25 ERROR cinder.volume.drivers.lightos 
2025-01-21 16:24:32.775 25 ERROR cinder.volume.drivers.lightos Traceback (most recent call last):
2025-01-21 16:24:32.775 25 ERROR cinder.volume.drivers.lightos   File "/var/lib/kolla/venv/lib/python3.10/site-packages/requests/adapters.py", line 667, in send
2025-01-21 16:24:32.775 25 ERROR cinder.volume.drivers.lightos     resp = conn.urlopen(
2025-01-21 16:24:32.775 25 ERROR cinder.volume.drivers.lightos   File "/var/lib/kolla/venv/lib/python3.10/site-packages/urllib3/connectionpool.py", line 801, in urlopen
2025-01-21 16:24:32.775 25 ERROR cinder.volume.drivers.lightos     retries = retries.increment(
2025-01-21 16:24:32.775 25 ERROR cinder.volume.drivers.lightos   File "/var/lib/kolla/venv/lib/python3.10/site-packages/urllib3/util/retry.py", line 594, in increment
2025-01-21 16:24:32.775 25 ERROR cinder.volume.drivers.lightos     raise MaxRetryError(_pool, url, error or ResponseError(cause))
2025-01-21 16:24:32.775 25 ERROR cinder.volume.drivers.lightos urllib3.exceptions.MaxRetryError: HTTPSConnectionPool(host='[LB_IP_ADDRESS]', port=443): Max retries exceeded with url: /api/v2/clusterinfo (Caused by NewConnectionError('<urllib3.connection.HTTPSConnection object at 0x7f57f4bf8490>: Failed to establish a new connection: [Errno 111] ECONNREFUSED'))
2025-01-21 16:24:32.775 25 ERROR cinder.volume.drivers.lightos 
2025-01-21 16:24:32.775 25 ERROR cinder.volume.drivers.lightos During handling of the above exception, another exception occurred:
2025-01-21 16:24:32.775 25 ERROR cinder.volume.drivers.lightos 
2025-01-21 16:24:32.775 25 ERROR cinder.volume.drivers.lightos Traceback (most recent call last):
2025-01-21 16:24:32.775 25 ERROR cinder.volume.drivers.lightos   File "/var/lib/kolla/venv/lib/python3.10/site-packages/cinder/volume/drivers/lightos.py", line 356, in __send_cmd
2025-01-21 16:24:32.775 25 ERROR cinder.volume.drivers.lightos     response = session.send(
2025-01-21 16:24:32.775 25 ERROR cinder.volume.drivers.lightos   File "/var/lib/kolla/venv/lib/python3.10/site-packages/requests/sessions.py", line 703, in send
2025-01-21 16:24:32.775 25 ERROR cinder.volume.drivers.lightos     r = adapter.send(request, **kwargs)
2025-01-21 16:24:32.775 25 ERROR cinder.volume.drivers.lightos   File "/var/lib/kolla/venv/lib/python3.10/site-packages/requests/adapters.py", line 700, in send
2025-01-21 16:24:32.775 25 ERROR cinder.volume.drivers.lightos     raise ConnectionError(e, request=request)
2025-01-21 16:24:32.775 25 ERROR cinder.volume.drivers.lightos requests.exceptions.ConnectionError: HTTPSConnectionPool(host='[LB_IP_ADDRESS]', port=443): Max retries exceeded with url: /api/v2/clusterinfo (Caused by NewConnectionError('<urllib3.connection.HTTPSConnection object at 0x7f57f4bf8490>: Failed to establish a new connection: [Errno 111] ECONNREFUSED'))
2025-01-21 16:24:32.775 25 ERROR cinder.volume.drivers.lightos 
2025-01-21 16:24:32.778 25 ERROR cinder.volume.manager [None req-9e00f5ec-d1cd-4f24-bf2a-c5a2c03ca1d3 - - - - - -] Failed to initialize driver.: cinder.exception.VolumeDriverException: Volume driver reported an error: Could not get a response from any API server
2025-01-21 16:24:32.778 25 ERROR cinder.volume.manager Traceback (most recent call last):
2025-01-21 16:24:32.778 25 ERROR cinder.volume.manager   File "/var/lib/kolla/venv/lib/python3.10/site-packages/cinder/volume/manager.py", line 523, in _init_host
2025-01-21 16:24:32.778 25 ERROR cinder.volume.manager     self.driver.do_setup(ctxt)
2025-01-21 16:24:32.778 25 ERROR cinder.volume.manager   File "/var/lib/kolla/venv/lib/python3.10/site-packages/cinder/volume/drivers/lightos.py", line 922, in do_setup
2025-01-21 16:24:32.778 25 ERROR cinder.volume.manager     self.get_cluster_info()
2025-01-21 16:24:32.778 25 ERROR cinder.volume.manager   File "/var/lib/kolla/venv/lib/python3.10/site-packages/cinder/volume/drivers/lightos.py", line 873, in get_cluster_info
2025-01-21 16:24:32.778 25 ERROR cinder.volume.manager     status_code, cluster_info = self.cluster.send_cmd(
2025-01-21 16:24:32.778 25 ERROR cinder.volume.manager   File "/var/lib/kolla/venv/lib/python3.10/site-packages/cinder/volume/drivers/lightos.py", line 315, in send_cmd
2025-01-21 16:24:32.778 25 ERROR cinder.volume.manager     raise exception.VolumeDriverException(
2025-01-21 16:24:32.778 25 ERROR cinder.volume.manager cinder.exception.VolumeDriverException: Volume driver reported an error: Could not get a response from any API server
2025-01-21 16:24:32.778 25 ERROR cinder.volume.manager 
2025-01-21 16:24:33.783 25 INFO cinder.volume.manager [None req-9e00f5ec-d1cd-4f24-bf2a-c5a2c03ca1d3 - - - - - -] Starting volume driver LightOSVolumeDriver (2.3.12)
2025-01-21 16:24:33.783 25 INFO cinder.volume.drivers.lightos [None req-9e00f5ec-d1cd-4f24-bf2a-c5a2c03ca1d3 - - - - - -] Invoking get_cluster_info using GET url: /api/v2/clusterinfo             request.body: {} ssl_verify: False
2025-01-21 16:24:33.787 25 ERROR cinder.volume.drivers.lightos [None req-9e00f5ec-d1cd-4f24-bf2a-c5a2c03ca1d3 - - - - - -] REST server not responding at 'https://[LB_IP_ADDRESS]:443/api/v2/clusterinfo': requests.exceptions.ConnectionError: HTTPSConnectionPool(host='[LB_IP_ADDRESS]', port=443): Max retries exceeded with url: /api/v2/clusterinfo (Caused by NewConnectionError('<urllib3.connection.HTTPSConnection object at 0x7f57f4bf8820>: Failed to establish a new connection: [Errno 111] ECONNREFUSED'))
2025-01-21 16:24:33.787 25 ERROR cinder.volume.drivers.lightos Traceback (most recent call last):
2025-01-21 16:24:33.787 25 ERROR cinder.volume.drivers.lightos   File "/var/lib/kolla/venv/lib/python3.10/site-packages/urllib3/connection.py", line 174, in _new_conn
2025-01-21 16:24:33.787 25 ERROR cinder.volume.drivers.lightos     conn = connection.create_connection(
2025-01-21 16:24:33.787 25 ERROR cinder.volume.drivers.lightos   File "/var/lib/kolla/venv/lib/python3.10/site-packages/urllib3/util/connection.py", line 95, in create_connection
2025-01-21 16:24:33.787 25 ERROR cinder.volume.drivers.lightos     raise err
2025-01-21 16:24:33.787 25 ERROR cinder.volume.drivers.lightos   File "/var/lib/kolla/venv/lib/python3.10/site-packages/urllib3/util/connection.py", line 85, in create_connection
2025-01-21 16:24:33.787 25 ERROR cinder.volume.drivers.lightos     sock.connect(sa)
2025-01-21 16:24:33.787 25 ERROR cinder.volume.drivers.lightos   File "/var/lib/kolla/venv/lib/python3.10/site-packages/eventlet/greenio/base.py", line 265, in connect
2025-01-21 16:24:33.787 25 ERROR cinder.volume.drivers.lightos     socket_checkerr(fd)
2025-01-21 16:24:33.787 25 ERROR cinder.volume.drivers.lightos   File "/var/lib/kolla/venv/lib/python3.10/site-packages/eventlet/greenio/base.py", line 50, in socket_checkerr
2025-01-21 16:24:33.787 25 ERROR cinder.volume.drivers.lightos     raise OSError(err, errno.errorcode[err])
2025-01-21 16:24:33.787 25 ERROR cinder.volume.drivers.lightos ConnectionRefusedError: [Errno 111] ECONNREFUSED
2025-01-21 16:24:33.787 25 ERROR cinder.volume.drivers.lightos 
2025-01-21 16:24:33.787 25 ERROR cinder.volume.drivers.lightos During handling of the above exception, another exception occurred:
2025-01-21 16:24:33.787 25 ERROR cinder.volume.drivers.lightos 
2025-01-21 16:24:33.787 25 ERROR cinder.volume.drivers.lightos Traceback (most recent call last):
2025-01-21 16:24:33.787 25 ERROR cinder.volume.drivers.lightos   File "/var/lib/kolla/venv/lib/python3.10/site-packages/urllib3/connectionpool.py", line 715, in urlopen
2025-01-21 16:24:33.787 25 ERROR cinder.volume.drivers.lightos     httplib_response = self._make_request(
2025-01-21 16:24:33.787 25 ERROR cinder.volume.drivers.lightos   File "/var/lib/kolla/venv/lib/python3.10/site-packages/urllib3/connectionpool.py", line 404, in _make_request
2025-01-21 16:24:33.787 25 ERROR cinder.volume.drivers.lightos     self._validate_conn(conn)
2025-01-21 16:24:33.787 25 ERROR cinder.volume.drivers.lightos   File "/var/lib/kolla/venv/lib/python3.10/site-packages/urllib3/connectionpool.py", line 1060, in _validate_conn
2025-01-21 16:24:33.787 25 ERROR cinder.volume.drivers.lightos     conn.connect()
2025-01-21 16:24:33.787 25 ERROR cinder.volume.drivers.lightos   File "/var/lib/kolla/venv/lib/python3.10/site-packages/urllib3/connection.py", line 363, in connect
2025-01-21 16:24:33.787 25 ERROR cinder.volume.drivers.lightos     self.sock = conn = self._new_conn()
2025-01-21 16:24:33.787 25 ERROR cinder.volume.drivers.lightos   File "/var/lib/kolla/venv/lib/python3.10/site-packages/urllib3/connection.py", line 186, in _new_conn
2025-01-21 16:24:33.787 25 ERROR cinder.volume.drivers.lightos     raise NewConnectionError(
2025-01-21 16:24:33.787 25 ERROR cinder.volume.drivers.lightos urllib3.exceptions.NewConnectionError: <urllib3.connection.HTTPSConnection object at 0x7f57f4bf8820>: Failed to establish a new connection: [Errno 111] ECONNREFUSED
2025-01-21 16:24:33.787 25 ERROR cinder.volume.drivers.lightos 
2025-01-21 16:24:33.787 25 ERROR cinder.volume.drivers.lightos During handling of the above exception, another exception occurred:
2025-01-21 16:24:33.787 25 ERROR cinder.volume.drivers.lightos 
2025-01-21 16:24:33.787 25 ERROR cinder.volume.drivers.lightos Traceback (most recent call last):
2025-01-21 16:24:33.787 25 ERROR cinder.volume.drivers.lightos   File "/var/lib/kolla/venv/lib/python3.10/site-packages/requests/adapters.py", line 667, in send
2025-01-21 16:24:33.787 25 ERROR cinder.volume.drivers.lightos     resp = conn.urlopen(
2025-01-21 16:24:33.787 25 ERROR cinder.volume.drivers.lightos   File "/var/lib/kolla/venv/lib/python3.10/site-packages/urllib3/connectionpool.py", line 801, in urlopen
2025-01-21 16:24:33.787 25 ERROR cinder.volume.drivers.lightos     retries = retries.increment(
2025-01-21 16:24:33.787 25 ERROR cinder.volume.drivers.lightos   File "/var/lib/kolla/venv/lib/python3.10/site-packages/urllib3/util/retry.py", line 594, in increment
2025-01-21 16:24:33.787 25 ERROR cinder.volume.drivers.lightos     raise MaxRetryError(_pool, url, error or ResponseError(cause))
2025-01-21 16:24:33.787 25 ERROR cinder.volume.drivers.lightos urllib3.exceptions.MaxRetryError: HTTPSConnectionPool(host='[LB_IP_ADDRESS]', port=443): Max retries exceeded with url: /api/v2/clusterinfo (Caused by NewConnectionError('<urllib3.connection.HTTPSConnection object at 0x7f57f4bf8820>: Failed to establish a new connection: [Errno 111] ECONNREFUSED'))
2025-01-21 16:24:33.787 25 ERROR cinder.volume.drivers.lightos 
2025-01-21 16:24:33.787 25 ERROR cinder.volume.drivers.lightos During handling of the above exception, another exception occurred:
2025-01-21 16:24:33.787 25 ERROR cinder.volume.drivers.lightos 
2025-01-21 16:24:33.787 25 ERROR cinder.volume.drivers.lightos Traceback (most recent call last):
2025-01-21 16:24:33.787 25 ERROR cinder.volume.drivers.lightos   File "/var/lib/kolla/venv/lib/python3.10/site-packages/cinder/volume/drivers/lightos.py", line 356, in __send_cmd
2025-01-21 16:24:33.787 25 ERROR cinder.volume.drivers.lightos     response = session.send(
2025-01-21 16:24:33.787 25 ERROR cinder.volume.drivers.lightos   File "/var/lib/kolla/venv/lib/python3.10/site-packages/requests/sessions.py", line 703, in send
2025-01-21 16:24:33.787 25 ERROR cinder.volume.drivers.lightos     r = adapter.send(request, **kwargs)
2025-01-21 16:24:33.787 25 ERROR cinder.volume.drivers.lightos   File "/var/lib/kolla/venv/lib/python3.10/site-packages/requests/adapters.py", line 700, in send
2025-01-21 16:24:33.787 25 ERROR cinder.volume.drivers.lightos     raise ConnectionError(e, request=request)
2025-01-21 16:24:33.787 25 ERROR cinder.volume.drivers.lightos requests.exceptions.ConnectionError: HTTPSConnectionPool(host='[LB_IP_ADDRESS]', port=443): Max retries exceeded with url: /api/v2/clusterinfo (Caused by NewConnectionError('<urllib3.connection.HTTPSConnection object at 0x7f57f4bf8820>: Failed to establish a new connection: [Errno 111] ECONNREFUSED'))
2025-01-21 16:24:33.787 25 ERROR cinder.volume.drivers.lightos 
2025-01-21 16:24:33.789 25 INFO cinder.volume.drivers.lightos [None req-9e00f5ec-d1cd-4f24-bf2a-c5a2c03ca1d3 - - - - - -] Invoking get_cluster_info using GET url: /api/v2/clusterinfo             request.body: {} ssl_verify: False
2025-01-21 16:24:35.841 25 ERROR cinder.volume.drivers.lightos [None req-9e00f5ec-d1cd-4f24-bf2a-c5a2c03ca1d3 - - - - - -] REST server not responding at 'https://[LB_IP_ADDRESS]:443/api/v2/clusterinfo': requests.exceptions.ConnectionError: HTTPSConnectionPool(host='[LB_IP_ADDRESS]', port=443): Max retries exceeded with url: /api/v2/clusterinfo (Caused by NewConnectionError('<urllib3.connection.HTTPSConnection object at 0x7f57f4bf9270>: Failed to establish a new connection: [Errno 113] EHOSTUNREACH'))
2025-01-21 16:24:35.841 25 ERROR cinder.volume.drivers.lightos Traceback (most recent call last):
2025-01-21 16:24:35.841 25 ERROR cinder.volume.drivers.lightos   File "/var/lib/kolla/venv/lib/python3.10/site-packages/urllib3/connection.py", line 174, in _new_conn
2025-01-21 16:24:35.841 25 ERROR cinder.volume.drivers.lightos     conn = connection.create_connection(
2025-01-21 16:24:35.841 25 ERROR cinder.volume.drivers.lightos   File "/var/lib/kolla/venv/lib/python3.10/site-packages/urllib3/util/connection.py", line 95, in create_connection
2025-01-21 16:24:35.841 25 ERROR cinder.volume.drivers.lightos     raise err
2025-01-21 16:24:35.841 25 ERROR cinder.volume.drivers.lightos   File "/var/lib/kolla/venv/lib/python3.10/site-packages/urllib3/util/connection.py", line 85, in create_connection
2025-01-21 16:24:35.841 25 ERROR cinder.volume.drivers.lightos     sock.connect(sa)
2025-01-21 16:24:35.841 25 ERROR cinder.volume.drivers.lightos   File "/var/lib/kolla/venv/lib/python3.10/site-packages/eventlet/greenio/base.py", line 265, in connect
2025-01-21 16:24:35.841 25 ERROR cinder.volume.drivers.lightos     socket_checkerr(fd)
2025-01-21 16:24:35.841 25 ERROR cinder.volume.drivers.lightos   File "/var/lib/kolla/venv/lib/python3.10/site-packages/eventlet/greenio/base.py", line 50, in socket_checkerr
2025-01-21 16:24:35.841 25 ERROR cinder.volume.drivers.lightos     raise OSError(err, errno.errorcode[err])
2025-01-21 16:24:35.841 25 ERROR cinder.volume.drivers.lightos OSError: [Errno 113] EHOSTUNREACH
2025-01-21 16:24:35.841 25 ERROR cinder.volume.drivers.lightos 
2025-01-21 16:24:35.841 25 ERROR cinder.volume.drivers.lightos During handling of the above exception, another exception occurred:
2025-01-21 16:24:35.841 25 ERROR cinder.volume.drivers.lightos 
2025-01-21 16:24:35.841 25 ERROR cinder.volume.drivers.lightos Traceback (most recent call last):
2025-01-21 16:24:35.841 25 ERROR cinder.volume.drivers.lightos   File "/var/lib/kolla/venv/lib/python3.10/site-packages/urllib3/connectionpool.py", line 715, in urlopen
2025-01-21 16:24:35.841 25 ERROR cinder.volume.drivers.lightos     httplib_response = self._make_request(
2025-01-21 16:24:35.841 25 ERROR cinder.volume.drivers.lightos   File "/var/lib/kolla/venv/lib/python3.10/site-packages/urllib3/connectionpool.py", line 404, in _make_request
2025-01-21 16:24:35.841 25 ERROR cinder.volume.drivers.lightos     self._validate_conn(conn)
2025-01-21 16:24:35.841 25 ERROR cinder.volume.drivers.lightos   File "/var/lib/kolla/venv/lib/python3.10/site-packages/urllib3/connectionpool.py", line 1060, in _validate_conn
2025-01-21 16:24:35.841 25 ERROR cinder.volume.drivers.lightos     conn.connect()
2025-01-21 16:24:35.841 25 ERROR cinder.volume.drivers.lightos   File "/var/lib/kolla/venv/lib/python3.10/site-packages/urllib3/connection.py", line 363, in connect
2025-01-21 16:24:35.841 25 ERROR cinder.volume.drivers.lightos     self.sock = conn = self._new_conn()
2025-01-21 16:24:35.841 25 ERROR cinder.volume.drivers.lightos   File "/var/lib/kolla/venv/lib/python3.10/site-packages/urllib3/connection.py", line 186, in _new_conn
2025-01-21 16:24:35.841 25 ERROR cinder.volume.drivers.lightos     raise NewConnectionError(
2025-01-21 16:24:35.841 25 ERROR cinder.volume.drivers.lightos urllib3.exceptions.NewConnectionError: <urllib3.connection.HTTPSConnection object at 0x7f57f4bf9270>: Failed to establish a new connection: [Errno 113] EHOSTUNREACH
2025-01-21 16:24:35.841 25 ERROR cinder.volume.drivers.lightos 
2025-01-21 16:24:35.841 25 ERROR cinder.volume.drivers.lightos During handling of the above exception, another exception occurred:
2025-01-21 16:24:35.841 25 ERROR cinder.volume.drivers.lightos 
2025-01-21 16:24:35.841 25 ERROR cinder.volume.drivers.lightos Traceback (most recent call last):
2025-01-21 16:24:35.841 25 ERROR cinder.volume.drivers.lightos   File "/var/lib/kolla/venv/lib/python3.10/site-packages/requests/adapters.py", line 667, in send
2025-01-21 16:24:35.841 25 ERROR cinder.volume.drivers.lightos     resp = conn.urlopen(
2025-01-21 16:24:35.841 25 ERROR cinder.volume.drivers.lightos   File "/var/lib/kolla/venv/lib/python3.10/site-packages/urllib3/connectionpool.py", line 801, in urlopen
2025-01-21 16:24:35.841 25 ERROR cinder.volume.drivers.lightos     retries = retries.increment(
2025-01-21 16:24:35.841 25 ERROR cinder.volume.drivers.lightos   File "/var/lib/kolla/venv/lib/python3.10/site-packages/urllib3/util/retry.py", line 594, in increment
2025-01-21 16:24:35.841 25 ERROR cinder.volume.drivers.lightos     raise MaxRetryError(_pool, url, error or ResponseError(cause))
2025-01-21 16:24:35.841 25 ERROR cinder.volume.drivers.lightos urllib3.exceptions.MaxRetryError: HTTPSConnectionPool(host='[LB_IP_ADDRESS]', port=443): Max retries exceeded with url: /api/v2/clusterinfo (Caused by NewConnectionError('<urllib3.connection.HTTPSConnection object at 0x7f57f4bf9270>: Failed to establish a new connection: [Errno 113] EHOSTUNREACH'))
2025-01-21 16:24:35.841 25 ERROR cinder.volume.drivers.lightos 
2025-01-21 16:24:35.841 25 ERROR cinder.volume.drivers.lightos During handling of the above exception, another exception occurred:
2025-01-21 16:24:35.841 25 ERROR cinder.volume.drivers.lightos 
2025-01-21 16:24:35.841 25 ERROR cinder.volume.drivers.lightos Traceback (most recent call last):
2025-01-21 16:24:35.841 25 ERROR cinder.volume.drivers.lightos   File "/var/lib/kolla/venv/lib/python3.10/site-packages/cinder/volume/drivers/lightos.py", line 356, in __send_cmd
2025-01-21 16:24:35.841 25 ERROR cinder.volume.drivers.lightos     response = session.send(
2025-01-21 16:24:35.841 25 ERROR cinder.volume.drivers.lightos   File "/var/lib/kolla/venv/lib/python3.10/site-packages/requests/sessions.py", line 703, in send
2025-01-21 16:24:35.841 25 ERROR cinder.volume.drivers.lightos     r = adapter.send(request, **kwargs)
2025-01-21 16:24:35.841 25 ERROR cinder.volume.drivers.lightos   File "/var/lib/kolla/venv/lib/python3.10/site-packages/requests/adapters.py", line 700, in send
2025-01-21 16:24:35.841 25 ERROR cinder.volume.drivers.lightos     raise ConnectionError(e, request=request)
2025-01-21 16:24:35.841 25 ERROR cinder.volume.drivers.lightos requests.exceptions.ConnectionError: HTTPSConnectionPool(host='[LB_IP_ADDRESS]', port=443): Max retries exceeded with url: /api/v2/clusterinfo (Caused by NewConnectionError('<urllib3.connection.HTTPSConnection object at 0x7f57f4bf9270>: Failed to establish a new connection: [Errno 113] EHOSTUNREACH'))
2025-01-21 16:24:35.841 25 ERROR cinder.volume.drivers.lightos 
2025-01-21 16:24:35.844 25 INFO cinder.volume.drivers.lightos [None req-9e00f5ec-d1cd-4f24-bf2a-c5a2c03ca1d3 - - - - - -] Invoking get_cluster_info using GET url: /api/v2/clusterinfo             request.body: {} ssl_verify: False
2025-01-21 16:24:35.851 25 ERROR cinder.volume.drivers.lightos [None req-9e00f5ec-d1cd-4f24-bf2a-c5a2c03ca1d3 - - - - - -] REST server not responding at 'https://[LB_IP_ADDRESS]:443/api/v2/clusterinfo': requests.exceptions.ConnectionError: HTTPSConnectionPool(host='[LB_IP_ADDRESS]', port=443): Max retries exceeded with url: /api/v2/clusterinfo (Caused by NewConnectionError('<urllib3.connection.HTTPSConnection object at 0x7f57f4bfa2f0>: Failed to establish a new connection: [Errno 111] ECONNREFUSED'))
2025-01-21 16:24:35.851 25 ERROR cinder.volume.drivers.lightos Traceback (most recent call last):
2025-01-21 16:24:35.851 25 ERROR cinder.volume.drivers.lightos   File "/var/lib/kolla/venv/lib/python3.10/site-packages/urllib3/connection.py", line 174, in _new_conn
2025-01-21 16:24:35.851 25 ERROR cinder.volume.drivers.lightos     conn = connection.create_connection(
2025-01-21 16:24:35.851 25 ERROR cinder.volume.drivers.lightos   File "/var/lib/kolla/venv/lib/python3.10/site-packages/urllib3/util/connection.py", line 95, in create_connection
2025-01-21 16:24:35.851 25 ERROR cinder.volume.drivers.lightos     raise err
2025-01-21 16:24:35.851 25 ERROR cinder.volume.drivers.lightos   File "/var/lib/kolla/venv/lib/python3.10/site-packages/urllib3/util/connection.py", line 85, in create_connection
2025-01-21 16:24:35.851 25 ERROR cinder.volume.drivers.lightos     sock.connect(sa)
2025-01-21 16:24:35.851 25 ERROR cinder.volume.drivers.lightos   File "/var/lib/kolla/venv/lib/python3.10/site-packages/eventlet/greenio/base.py", line 265, in connect
2025-01-21 16:24:35.851 25 ERROR cinder.volume.drivers.lightos     socket_checkerr(fd)
2025-01-21 16:24:35.851 25 ERROR cinder.volume.drivers.lightos   File "/var/lib/kolla/venv/lib/python3.10/site-packages/eventlet/greenio/base.py", line 50, in socket_checkerr
2025-01-21 16:24:35.851 25 ERROR cinder.volume.drivers.lightos     raise OSError(err, errno.errorcode[err])
2025-01-21 16:24:35.851 25 ERROR cinder.volume.drivers.lightos ConnectionRefusedError: [Errno 111] ECONNREFUSED
2025-01-21 16:24:35.851 25 ERROR cinder.volume.drivers.lightos 
2025-01-21 16:24:35.851 25 ERROR cinder.volume.drivers.lightos During handling of the above exception, another exception occurred:
2025-01-21 16:24:35.851 25 ERROR cinder.volume.drivers.lightos 
2025-01-21 16:24:35.851 25 ERROR cinder.volume.drivers.lightos Traceback (most recent call last):
2025-01-21 16:24:35.851 25 ERROR cinder.volume.drivers.lightos   File "/var/lib/kolla/venv/lib/python3.10/site-packages/urllib3/connectionpool.py", line 715, in urlopen
2025-01-21 16:24:35.851 25 ERROR cinder.volume.drivers.lightos     httplib_response = self._make_request(
2025-01-21 16:24:35.851 25 ERROR cinder.volume.drivers.lightos   File "/var/lib/kolla/venv/lib/python3.10/site-packages/urllib3/connectionpool.py", line 404, in _make_request
2025-01-21 16:24:35.851 25 ERROR cinder.volume.drivers.lightos     self._validate_conn(conn)
2025-01-21 16:24:35.851 25 ERROR cinder.volume.drivers.lightos   File "/var/lib/kolla/venv/lib/python3.10/site-packages/urllib3/connectionpool.py", line 1060, in _validate_conn
2025-01-21 16:24:35.851 25 ERROR cinder.volume.drivers.lightos     conn.connect()
2025-01-21 16:24:35.851 25 ERROR cinder.volume.drivers.lightos   File "/var/lib/kolla/venv/lib/python3.10/site-packages/urllib3/connection.py", line 363, in connect
2025-01-21 16:24:35.851 25 ERROR cinder.volume.drivers.lightos     self.sock = conn = self._new_conn()
2025-01-21 16:24:35.851 25 ERROR cinder.volume.drivers.lightos   File "/var/lib/kolla/venv/lib/python3.10/site-packages/urllib3/connection.py", line 186, in _new_conn
2025-01-21 16:24:35.851 25 ERROR cinder.volume.drivers.lightos     raise NewConnectionError(
2025-01-21 16:24:35.851 25 ERROR cinder.volume.drivers.lightos urllib3.exceptions.NewConnectionError: <urllib3.connection.HTTPSConnection object at 0x7f57f4bfa2f0>: Failed to establish a new connection: [Errno 111] ECONNREFUSED
2025-01-21 16:24:35.851 25 ERROR cinder.volume.drivers.lightos 
2025-01-21 16:24:35.851 25 ERROR cinder.volume.drivers.lightos During handling of the above exception, another exception occurred:
2025-01-21 16:24:35.851 25 ERROR cinder.volume.drivers.lightos 
2025-01-21 16:24:35.851 25 ERROR cinder.volume.drivers.lightos Traceback (most recent call last):
2025-01-21 16:24:35.851 25 ERROR cinder.volume.drivers.lightos   File "/var/lib/kolla/venv/lib/python3.10/site-packages/requests/adapters.py", line 667, in send
2025-01-21 16:24:35.851 25 ERROR cinder.volume.drivers.lightos     resp = conn.urlopen(
2025-01-21 16:24:35.851 25 ERROR cinder.volume.drivers.lightos   File "/var/lib/kolla/venv/lib/python3.10/site-packages/urllib3/connectionpool.py", line 801, in urlopen
2025-01-21 16:24:35.851 25 ERROR cinder.volume.drivers.lightos     retries = retries.increment(
2025-01-21 16:24:35.851 25 ERROR cinder.volume.drivers.lightos   File "/var/lib/kolla/venv/lib/python3.10/site-packages/urllib3/util/retry.py", line 594, in increment
2025-01-21 16:24:35.851 25 ERROR cinder.volume.drivers.lightos     raise MaxRetryError(_pool, url, error or ResponseError(cause))
2025-01-21 16:24:35.851 25 ERROR cinder.volume.drivers.lightos urllib3.exceptions.MaxRetryError: HTTPSConnectionPool(host='[LB_IP_ADDRESS]', port=443): Max retries exceeded with url: /api/v2/clusterinfo (Caused by NewConnectionError('<urllib3.connection.HTTPSConnection object at 0x7f57f4bfa2f0>: Failed to establish a new connection: [Errno 111] ECONNREFUSED'))
2025-01-21 16:24:35.851 25 ERROR cinder.volume.drivers.lightos 
2025-01-21 16:24:35.851 25 ERROR cinder.volume.drivers.lightos During handling of the above exception, another exception occurred:
2025-01-21 16:24:35.851 25 ERROR cinder.volume.drivers.lightos 
2025-01-21 16:24:35.851 25 ERROR cinder.volume.drivers.lightos Traceback (most recent call last):
2025-01-21 16:24:35.851 25 ERROR cinder.volume.drivers.lightos   File "/var/lib/kolla/venv/lib/python3.10/site-packages/cinder/volume/drivers/lightos.py", line 356, in __send_cmd
2025-01-21 16:24:35.851 25 ERROR cinder.volume.drivers.lightos     response = session.send(
2025-01-21 16:24:35.851 25 ERROR cinder.volume.drivers.lightos   File "/var/lib/kolla/venv/lib/python3.10/site-packages/requests/sessions.py", line 703, in send
2025-01-21 16:24:35.851 25 ERROR cinder.volume.drivers.lightos     r = adapter.send(request, **kwargs)
2025-01-21 16:24:35.851 25 ERROR cinder.volume.drivers.lightos   File "/var/lib/kolla/venv/lib/python3.10/site-packages/requests/adapters.py", line 700, in send
2025-01-21 16:24:35.851 25 ERROR cinder.volume.drivers.lightos     raise ConnectionError(e, request=request)
2025-01-21 16:24:35.851 25 ERROR cinder.volume.drivers.lightos requests.exceptions.ConnectionError: HTTPSConnectionPool(host='[LB_IP_ADDRESS]', port=443): Max retries exceeded with url: /api/v2/clusterinfo (Caused by NewConnectionError('<urllib3.connection.HTTPSConnection object at 0x7f57f4bfa2f0>: Failed to establish a new connection: [Errno 111] ECONNREFUSED'))
2025-01-21 16:24:35.851 25 ERROR cinder.volume.drivers.lightos 
2025-01-21 16:24:35.853 25 ERROR cinder.volume.manager [None req-9e00f5ec-d1cd-4f24-bf2a-c5a2c03ca1d3 - - - - - -] Failed to initialize driver.: cinder.exception.VolumeDriverException: Volume driver reported an error: Could not get a response from any API server
2025-01-21 16:24:35.853 25 ERROR cinder.volume.manager Traceback (most recent call last):
2025-01-21 16:24:35.853 25 ERROR cinder.volume.manager   File "/var/lib/kolla/venv/lib/python3.10/site-packages/cinder/volume/manager.py", line 523, in _init_host
2025-01-21 16:24:35.853 25 ERROR cinder.volume.manager     self.driver.do_setup(ctxt)
2025-01-21 16:24:35.853 25 ERROR cinder.volume.manager   File "/var/lib/kolla/venv/lib/python3.10/site-packages/cinder/volume/drivers/lightos.py", line 922, in do_setup
2025-01-21 16:24:35.853 25 ERROR cinder.volume.manager     self.get_cluster_info()
2025-01-21 16:24:35.853 25 ERROR cinder.volume.manager   File "/var/lib/kolla/venv/lib/python3.10/site-packages/cinder/volume/drivers/lightos.py", line 873, in get_cluster_info
2025-01-21 16:24:35.853 25 ERROR cinder.volume.manager     status_code, cluster_info = self.cluster.send_cmd(
2025-01-21 16:24:35.853 25 ERROR cinder.volume.manager   File "/var/lib/kolla/venv/lib/python3.10/site-packages/cinder/volume/drivers/lightos.py", line 315, in send_cmd
2025-01-21 16:24:35.853 25 ERROR cinder.volume.manager     raise exception.VolumeDriverException(
2025-01-21 16:24:35.853 25 ERROR cinder.volume.manager cinder.exception.VolumeDriverException: Volume driver reported an error: Could not get a response from any API server
2025-01-21 16:24:35.853 25 ERROR cinder.volume.manager 
2025-01-21 16:24:37.856 25 INFO cinder.volume.manager [None req-9e00f5ec-d1cd-4f24-bf2a-c5a2c03ca1d3 - - - - - -] Starting volume driver LightOSVolumeDriver (2.3.12)
2025-01-21 16:24:37.857 25 INFO cinder.volume.drivers.lightos [None req-9e00f5ec-d1cd-4f24-bf2a-c5a2c03ca1d3 - - - - - -] Invoking get_cluster_info using GET url: /api/v2/clusterinfo             request.body: {} ssl_verify: False
2025-01-21 16:24:37.860 25 ERROR cinder.volume.drivers.lightos [None req-9e00f5ec-d1cd-4f24-bf2a-c5a2c03ca1d3 - - - - - -] REST server not responding at 'https://[LB_IP_ADDRESS]:443/api/v2/clusterinfo': requests.exceptions.ConnectionError: HTTPSConnectionPool(host='[LB_IP_ADDRESS]', port=443): Max retries exceeded with url: /api/v2/clusterinfo (Caused by NewConnectionError('<urllib3.connection.HTTPSConnection object at 0x7f57f4b847f0>: Failed to establish a new connection: [Errno 111] ECONNREFUSED'))
2025-01-21 16:24:37.860 25 ERROR cinder.volume.drivers.lightos Traceback (most recent call last):
2025-01-21 16:24:37.860 25 ERROR cinder.volume.drivers.lightos   File "/var/lib/kolla/venv/lib/python3.10/site-packages/urllib3/connection.py", line 174, in _new_conn
2025-01-21 16:24:37.860 25 ERROR cinder.volume.drivers.lightos     conn = connection.create_connection(
2025-01-21 16:24:37.860 25 ERROR cinder.volume.drivers.lightos   File "/var/lib/kolla/venv/lib/python3.10/site-packages/urllib3/util/connection.py", line 95, in create_connection
2025-01-21 16:24:37.860 25 ERROR cinder.volume.drivers.lightos     raise err
2025-01-21 16:24:37.860 25 ERROR cinder.volume.drivers.lightos   File "/var/lib/kolla/venv/lib/python3.10/site-packages/urllib3/util/connection.py", line 85, in create_connection
2025-01-21 16:24:37.860 25 ERROR cinder.volume.drivers.lightos     sock.connect(sa)
2025-01-21 16:24:37.860 25 ERROR cinder.volume.drivers.lightos   File "/var/lib/kolla/venv/lib/python3.10/site-packages/eventlet/greenio/base.py", line 265, in connect
2025-01-21 16:24:37.860 25 ERROR cinder.volume.drivers.lightos     socket_checkerr(fd)
2025-01-21 16:24:37.860 25 ERROR cinder.volume.drivers.lightos   File "/var/lib/kolla/venv/lib/python3.10/site-packages/eventlet/greenio/base.py", line 50, in socket_checkerr
2025-01-21 16:24:37.860 25 ERROR cinder.volume.drivers.lightos     raise OSError(err, errno.errorcode[err])
2025-01-21 16:24:37.860 25 ERROR cinder.volume.drivers.lightos ConnectionRefusedError: [Errno 111] ECONNREFUSED
2025-01-21 16:24:37.860 25 ERROR cinder.volume.drivers.lightos 
2025-01-21 16:24:37.860 25 ERROR cinder.volume.drivers.lightos During handling of the above exception, another exception occurred:
2025-01-21 16:24:37.860 25 ERROR cinder.volume.drivers.lightos 
2025-01-21 16:24:37.860 25 ERROR cinder.volume.drivers.lightos Traceback (most recent call last):
2025-01-21 16:24:37.860 25 ERROR cinder.volume.drivers.lightos   File "/var/lib/kolla/venv/lib/python3.10/site-packages/urllib3/connectionpool.py", line 715, in urlopen
2025-01-21 16:24:37.860 25 ERROR cinder.volume.drivers.lightos     httplib_response = self._make_request(
2025-01-21 16:24:37.860 25 ERROR cinder.volume.drivers.lightos   File "/var/lib/kolla/venv/lib/python3.10/site-packages/urllib3/connectionpool.py", line 404, in _make_request
2025-01-21 16:24:37.860 25 ERROR cinder.volume.drivers.lightos     self._validate_conn(conn)
2025-01-21 16:24:37.860 25 ERROR cinder.volume.drivers.lightos   File "/var/lib/kolla/venv/lib/python3.10/site-packages/urllib3/connectionpool.py", line 1060, in _validate_conn
2025-01-21 16:24:37.860 25 ERROR cinder.volume.drivers.lightos     conn.connect()
2025-01-21 16:24:37.860 25 ERROR cinder.volume.drivers.lightos   File "/var/lib/kolla/venv/lib/python3.10/site-packages/urllib3/connection.py", line 363, in connect
2025-01-21 16:24:37.860 25 ERROR cinder.volume.drivers.lightos     self.sock = conn = self._new_conn()
2025-01-21 16:24:37.860 25 ERROR cinder.volume.drivers.lightos   File "/var/lib/kolla/venv/lib/python3.10/site-packages/urllib3/connection.py", line 186, in _new_conn
2025-01-21 16:24:37.860 25 ERROR cinder.volume.drivers.lightos     raise NewConnectionError(
2025-01-21 16:24:37.860 25 ERROR cinder.volume.drivers.lightos urllib3.exceptions.NewConnectionError: <urllib3.connection.HTTPSConnection object at 0x7f57f4b847f0>: Failed to establish a new connection: [Errno 111] ECONNREFUSED
2025-01-21 16:24:37.860 25 ERROR cinder.volume.drivers.lightos 
2025-01-21 16:24:37.860 25 ERROR cinder.volume.drivers.lightos During handling of the above exception, another exception occurred:
2025-01-21 16:24:37.860 25 ERROR cinder.volume.drivers.lightos 
2025-01-21 16:24:37.860 25 ERROR cinder.volume.drivers.lightos Traceback (most recent call last):
2025-01-21 16:24:37.860 25 ERROR cinder.volume.drivers.lightos   File "/var/lib/kolla/venv/lib/python3.10/site-packages/requests/adapters.py", line 667, in send
2025-01-21 16:24:37.860 25 ERROR cinder.volume.drivers.lightos     resp = conn.urlopen(
2025-01-21 16:24:37.860 25 ERROR cinder.volume.drivers.lightos   File "/var/lib/kolla/venv/lib/python3.10/site-packages/urllib3/connectionpool.py", line 801, in urlopen
2025-01-21 16:24:37.860 25 ERROR cinder.volume.drivers.lightos     retries = retries.increment(
2025-01-21 16:24:37.860 25 ERROR cinder.volume.drivers.lightos   File "/var/lib/kolla/venv/lib/python3.10/site-packages/urllib3/util/retry.py", line 594, in increment
2025-01-21 16:24:37.860 25 ERROR cinder.volume.drivers.lightos     raise MaxRetryError(_pool, url, error or ResponseError(cause))
2025-01-21 16:24:37.860 25 ERROR cinder.volume.drivers.lightos urllib3.exceptions.MaxRetryError: HTTPSConnectionPool(host='[LB_IP_ADDRESS]', port=443): Max retries exceeded with url: /api/v2/clusterinfo (Caused by NewConnectionError('<urllib3.connection.HTTPSConnection object at 0x7f57f4b847f0>: Failed to establish a new connection: [Errno 111] ECONNREFUSED'))
2025-01-21 16:24:37.860 25 ERROR cinder.volume.drivers.lightos 
2025-01-21 16:24:37.860 25 ERROR cinder.volume.drivers.lightos During handling of the above exception, another exception occurred:
2025-01-21 16:24:37.860 25 ERROR cinder.volume.drivers.lightos 
2025-01-21 16:24:37.860 25 ERROR cinder.volume.drivers.lightos Traceback (most recent call last):
2025-01-21 16:24:37.860 25 ERROR cinder.volume.drivers.lightos   File "/var/lib/kolla/venv/lib/python3.10/site-packages/cinder/volume/drivers/lightos.py", line 356, in __send_cmd
2025-01-21 16:24:37.860 25 ERROR cinder.volume.drivers.lightos     response = session.send(
2025-01-21 16:24:37.860 25 ERROR cinder.volume.drivers.lightos   File "/var/lib/kolla/venv/lib/python3.10/site-packages/requests/sessions.py", line 703, in send
2025-01-21 16:24:37.860 25 ERROR cinder.volume.drivers.lightos     r = adapter.send(request, **kwargs)
2025-01-21 16:24:37.860 25 ERROR cinder.volume.drivers.lightos   File "/var/lib/kolla/venv/lib/python3.10/site-packages/requests/adapters.py", line 700, in send
2025-01-21 16:24:37.860 25 ERROR cinder.volume.drivers.lightos     raise ConnectionError(e, request=request)
2025-01-21 16:24:37.860 25 ERROR cinder.volume.drivers.lightos requests.exceptions.ConnectionError: HTTPSConnectionPool(host='[LB_IP_ADDRESS]', port=443): Max retries exceeded with url: /api/v2/clusterinfo (Caused by NewConnectionError('<urllib3.connection.HTTPSConnection object at 0x7f57f4b847f0>: Failed to establish a new connection: [Errno 111] ECONNREFUSED'))
2025-01-21 16:24:37.860 25 ERROR cinder.volume.drivers.lightos 
2025-01-21 16:24:37.863 25 INFO cinder.volume.drivers.lightos [None req-9e00f5ec-d1cd-4f24-bf2a-c5a2c03ca1d3 - - - - - -] Invoking get_cluster_info using GET url: /api/v2/clusterinfo             request.body: {} ssl_verify: False
2025-01-21 16:24:38.913 25 ERROR cinder.volume.drivers.lightos [None req-9e00f5ec-d1cd-4f24-bf2a-c5a2c03ca1d3 - - - - - -] REST server not responding at 'https://[LB_IP_ADDRESS]:443/api/v2/clusterinfo': requests.exceptions.ConnectionError: HTTPSConnectionPool(host='[LB_IP_ADDRESS]', port=443): Max retries exceeded with url: /api/v2/clusterinfo (Caused by NewConnectionError('<urllib3.connection.HTTPSConnection object at 0x7f57f4b852d0>: Failed to establish a new connection: [Errno 113] EHOSTUNREACH'))
2025-01-21 16:24:38.913 25 ERROR cinder.volume.drivers.lightos Traceback (most recent call last):
2025-01-21 16:24:38.913 25 ERROR cinder.volume.drivers.lightos   File "/var/lib/kolla/venv/lib/python3.10/site-packages/urllib3/connection.py", line 174, in _new_conn
2025-01-21 16:24:38.913 25 ERROR cinder.volume.drivers.lightos     conn = connection.create_connection(
2025-01-21 16:24:38.913 25 ERROR cinder.volume.drivers.lightos   File "/var/lib/kolla/venv/lib/python3.10/site-packages/urllib3/util/connection.py", line 95, in create_connection
2025-01-21 16:24:38.913 25 ERROR cinder.volume.drivers.lightos     raise err
2025-01-21 16:24:38.913 25 ERROR cinder.volume.drivers.lightos   File "/var/lib/kolla/venv/lib/python3.10/site-packages/urllib3/util/connection.py", line 85, in create_connection
2025-01-21 16:24:38.913 25 ERROR cinder.volume.drivers.lightos     sock.connect(sa)
2025-01-21 16:24:38.913 25 ERROR cinder.volume.drivers.lightos   File "/var/lib/kolla/venv/lib/python3.10/site-packages/eventlet/greenio/base.py", line 265, in connect
2025-01-21 16:24:38.913 25 ERROR cinder.volume.drivers.lightos     socket_checkerr(fd)
2025-01-21 16:24:38.913 25 ERROR cinder.volume.drivers.lightos   File "/var/lib/kolla/venv/lib/python3.10/site-packages/eventlet/greenio/base.py", line 50, in socket_checkerr
2025-01-21 16:24:38.913 25 ERROR cinder.volume.drivers.lightos     raise OSError(err, errno.errorcode[err])
2025-01-21 16:24:38.913 25 ERROR cinder.volume.drivers.lightos OSError: [Errno 113] EHOSTUNREACH
2025-01-21 16:24:38.913 25 ERROR cinder.volume.drivers.lightos 
2025-01-21 16:24:38.913 25 ERROR cinder.volume.drivers.lightos During handling of the above exception, another exception occurred:
2025-01-21 16:24:38.913 25 ERROR cinder.volume.drivers.lightos 
2025-01-21 16:24:38.913 25 ERROR cinder.volume.drivers.lightos Traceback (most recent call last):
2025-01-21 16:24:38.913 25 ERROR cinder.volume.drivers.lightos   File "/var/lib/kolla/venv/lib/python3.10/site-packages/urllib3/connectionpool.py", line 715, in urlopen
2025-01-21 16:24:38.913 25 ERROR cinder.volume.drivers.lightos     httplib_response = self._make_request(
2025-01-21 16:24:38.913 25 ERROR cinder.volume.drivers.lightos   File "/var/lib/kolla/venv/lib/python3.10/site-packages/urllib3/connectionpool.py", line 404, in _make_request
2025-01-21 16:24:38.913 25 ERROR cinder.volume.drivers.lightos     self._validate_conn(conn)
2025-01-21 16:24:38.913 25 ERROR cinder.volume.drivers.lightos   File "/var/lib/kolla/venv/lib/python3.10/site-packages/urllib3/connectionpool.py", line 1060, in _validate_conn
2025-01-21 16:24:38.913 25 ERROR cinder.volume.drivers.lightos     conn.connect()
2025-01-21 16:24:38.913 25 ERROR cinder.volume.drivers.lightos   File "/var/lib/kolla/venv/lib/python3.10/site-packages/urllib3/connection.py", line 363, in connect
2025-01-21 16:24:38.913 25 ERROR cinder.volume.drivers.lightos     self.sock = conn = self._new_conn()
2025-01-21 16:24:38.913 25 ERROR cinder.volume.drivers.lightos   File "/var/lib/kolla/venv/lib/python3.10/site-packages/urllib3/connection.py", line 186, in _new_conn
2025-01-21 16:24:38.913 25 ERROR cinder.volume.drivers.lightos     raise NewConnectionError(
2025-01-21 16:24:38.913 25 ERROR cinder.volume.drivers.lightos urllib3.exceptions.NewConnectionError: <urllib3.connection.HTTPSConnection object at 0x7f57f4b852d0>: Failed to establish a new connection: [Errno 113] EHOSTUNREACH
2025-01-21 16:24:38.913 25 ERROR cinder.volume.drivers.lightos 
2025-01-21 16:24:38.913 25 ERROR cinder.volume.drivers.lightos During handling of the above exception, another exception occurred:
2025-01-21 16:24:38.913 25 ERROR cinder.volume.drivers.lightos 
2025-01-21 16:24:38.913 25 ERROR cinder.volume.drivers.lightos Traceback (most recent call last):
2025-01-21 16:24:38.913 25 ERROR cinder.volume.drivers.lightos   File "/var/lib/kolla/venv/lib/python3.10/site-packages/requests/adapters.py", line 667, in send
2025-01-21 16:24:38.913 25 ERROR cinder.volume.drivers.lightos     resp = conn.urlopen(
2025-01-21 16:24:38.913 25 ERROR cinder.volume.drivers.lightos   File "/var/lib/kolla/venv/lib/python3.10/site-packages/urllib3/connectionpool.py", line 801, in urlopen
2025-01-21 16:24:38.913 25 ERROR cinder.volume.drivers.lightos     retries = retries.increment(
2025-01-21 16:24:38.913 25 ERROR cinder.volume.drivers.lightos   File "/var/lib/kolla/venv/lib/python3.10/site-packages/urllib3/util/retry.py", line 594, in increment
2025-01-21 16:24:38.913 25 ERROR cinder.volume.drivers.lightos     raise MaxRetryError(_pool, url, error or ResponseError(cause))
2025-01-21 16:24:38.913 25 ERROR cinder.volume.drivers.lightos urllib3.exceptions.MaxRetryError: HTTPSConnectionPool(host='[LB_IP_ADDRESS]', port=443): Max retries exceeded with url: /api/v2/clusterinfo (Caused by NewConnectionError('<urllib3.connection.HTTPSConnection object at 0x7f57f4b852d0>: Failed to establish a new connection: [Errno 113] EHOSTUNREACH'))
2025-01-21 16:24:38.913 25 ERROR cinder.volume.drivers.lightos 
2025-01-21 16:24:38.913 25 ERROR cinder.volume.drivers.lightos During handling of the above exception, another exception occurred:
2025-01-21 16:24:38.913 25 ERROR cinder.volume.drivers.lightos 
2025-01-21 16:24:38.913 25 ERROR cinder.volume.drivers.lightos Traceback (most recent call last):
2025-01-21 16:24:38.913 25 ERROR cinder.volume.drivers.lightos   File "/var/lib/kolla/venv/lib/python3.10/site-packages/cinder/volume/drivers/lightos.py", line 356, in __send_cmd
2025-01-21 16:24:38.913 25 ERROR cinder.volume.drivers.lightos     response = session.send(
2025-01-21 16:24:38.913 25 ERROR cinder.volume.drivers.lightos   File "/var/lib/kolla/venv/lib/python3.10/site-packages/requests/sessions.py", line 703, in send
2025-01-21 16:24:38.913 25 ERROR cinder.volume.drivers.lightos     r = adapter.send(request, **kwargs)
2025-01-21 16:24:38.913 25 ERROR cinder.volume.drivers.lightos   File "/var/lib/kolla/venv/lib/python3.10/site-packages/requests/adapters.py", line 700, in send
2025-01-21 16:24:38.913 25 ERROR cinder.volume.drivers.lightos     raise ConnectionError(e, request=request)
2025-01-21 16:24:38.913 25 ERROR cinder.volume.drivers.lightos requests.exceptions.ConnectionError: HTTPSConnectionPool(host='[LB_IP_ADDRESS]', port=443): Max retries exceeded with url: /api/v2/clusterinfo (Caused by NewConnectionError('<urllib3.connection.HTTPSConnection object at 0x7f57f4b852d0>: Failed to establish a new connection: [Errno 113] EHOSTUNREACH'))
2025-01-21 16:24:38.913 25 ERROR cinder.volume.drivers.lightos 
2025-01-21 16:24:38.917 25 INFO cinder.volume.drivers.lightos [None req-9e00f5ec-d1cd-4f24-bf2a-c5a2c03ca1d3 - - - - - -] Invoking get_cluster_info using GET url: /api/v2/clusterinfo             request.body: {} ssl_verify: False
2025-01-21 16:24:38.920 25 ERROR cinder.volume.drivers.lightos [None req-9e00f5ec-d1cd-4f24-bf2a-c5a2c03ca1d3 - - - - - -] REST server not responding at 'https://[LB_IP_ADDRESS]:443/api/v2/clusterinfo': requests.exceptions.ConnectionError: HTTPSConnectionPool(host='[LB_IP_ADDRESS]', port=443): Max retries exceeded with url: /api/v2/clusterinfo (Caused by NewConnectionError('<urllib3.connection.HTTPSConnection object at 0x7f57f4bfa1a0>: Failed to establish a new connection: [Errno 111] ECONNREFUSED'))
2025-01-21 16:24:38.920 25 ERROR cinder.volume.drivers.lightos Traceback (most recent call last):
2025-01-21 16:24:38.920 25 ERROR cinder.volume.drivers.lightos   File "/var/lib/kolla/venv/lib/python3.10/site-packages/urllib3/connection.py", line 174, in _new_conn
2025-01-21 16:24:38.920 25 ERROR cinder.volume.drivers.lightos     conn = connection.create_connection(
2025-01-21 16:24:38.920 25 ERROR cinder.volume.drivers.lightos   File "/var/lib/kolla/venv/lib/python3.10/site-packages/urllib3/util/connection.py", line 95, in create_connection
2025-01-21 16:24:38.920 25 ERROR cinder.volume.drivers.lightos     raise err
2025-01-21 16:24:38.920 25 ERROR cinder.volume.drivers.lightos   File "/var/lib/kolla/venv/lib/python3.10/site-packages/urllib3/util/connection.py", line 85, in create_connection
2025-01-21 16:24:38.920 25 ERROR cinder.volume.drivers.lightos     sock.connect(sa)
2025-01-21 16:24:38.920 25 ERROR cinder.volume.drivers.lightos   File "/var/lib/kolla/venv/lib/python3.10/site-packages/eventlet/greenio/base.py", line 265, in connect
2025-01-21 16:24:38.920 25 ERROR cinder.volume.drivers.lightos     socket_checkerr(fd)
2025-01-21 16:24:38.920 25 ERROR cinder.volume.drivers.lightos   File "/var/lib/kolla/venv/lib/python3.10/site-packages/eventlet/greenio/base.py", line 50, in socket_checkerr
2025-01-21 16:24:38.920 25 ERROR cinder.volume.drivers.lightos     raise OSError(err, errno.errorcode[err])
2025-01-21 16:24:38.920 25 ERROR cinder.volume.drivers.lightos ConnectionRefusedError: [Errno 111] ECONNREFUSED
2025-01-21 16:24:38.920 25 ERROR cinder.volume.drivers.lightos 
2025-01-21 16:24:38.920 25 ERROR cinder.volume.drivers.lightos During handling of the above exception, another exception occurred:
2025-01-21 16:24:38.920 25 ERROR cinder.volume.drivers.lightos 
2025-01-21 16:24:38.920 25 ERROR cinder.volume.drivers.lightos Traceback (most recent call last):
2025-01-21 16:24:38.920 25 ERROR cinder.volume.drivers.lightos   File "/var/lib/kolla/venv/lib/python3.10/site-packages/urllib3/connectionpool.py", line 715, in urlopen
2025-01-21 16:24:38.920 25 ERROR cinder.volume.drivers.lightos     httplib_response = self._make_request(
2025-01-21 16:24:38.920 25 ERROR cinder.volume.drivers.lightos   File "/var/lib/kolla/venv/lib/python3.10/site-packages/urllib3/connectionpool.py", line 404, in _make_request
2025-01-21 16:24:38.920 25 ERROR cinder.volume.drivers.lightos     self._validate_conn(conn)
2025-01-21 16:24:38.920 25 ERROR cinder.volume.drivers.lightos   File "/var/lib/kolla/venv/lib/python3.10/site-packages/urllib3/connectionpool.py", line 1060, in _validate_conn
2025-01-21 16:24:38.920 25 ERROR cinder.volume.drivers.lightos     conn.connect()
2025-01-21 16:24:38.920 25 ERROR cinder.volume.drivers.lightos   File "/var/lib/kolla/venv/lib/python3.10/site-packages/urllib3/connection.py", line 363, in connect
2025-01-21 16:24:38.920 25 ERROR cinder.volume.drivers.lightos     self.sock = conn = self._new_conn()
2025-01-21 16:24:38.920 25 ERROR cinder.volume.drivers.lightos   File "/var/lib/kolla/venv/lib/python3.10/site-packages/urllib3/connection.py", line 186, in _new_conn
2025-01-21 16:24:38.920 25 ERROR cinder.volume.drivers.lightos     raise NewConnectionError(
2025-01-21 16:24:38.920 25 ERROR cinder.volume.drivers.lightos urllib3.exceptions.NewConnectionError: <urllib3.connection.HTTPSConnection object at 0x7f57f4bfa1a0>: Failed to establish a new connection: [Errno 111] ECONNREFUSED
2025-01-21 16:24:38.920 25 ERROR cinder.volume.drivers.lightos 
2025-01-21 16:24:38.920 25 ERROR cinder.volume.drivers.lightos During handling of the above exception, another exception occurred:
2025-01-21 16:24:38.920 25 ERROR cinder.volume.drivers.lightos 
2025-01-21 16:24:38.920 25 ERROR cinder.volume.drivers.lightos Traceback (most recent call last):
2025-01-21 16:24:38.920 25 ERROR cinder.volume.drivers.lightos   File "/var/lib/kolla/venv/lib/python3.10/site-packages/requests/adapters.py", line 667, in send
2025-01-21 16:24:38.920 25 ERROR cinder.volume.drivers.lightos     resp = conn.urlopen(
2025-01-21 16:24:38.920 25 ERROR cinder.volume.drivers.lightos   File "/var/lib/kolla/venv/lib/python3.10/site-packages/urllib3/connectionpool.py", line 801, in urlopen
2025-01-21 16:24:38.920 25 ERROR cinder.volume.drivers.lightos     retries = retries.increment(
2025-01-21 16:24:38.920 25 ERROR cinder.volume.drivers.lightos   File "/var/lib/kolla/venv/lib/python3.10/site-packages/urllib3/util/retry.py", line 594, in increment
2025-01-21 16:24:38.920 25 ERROR cinder.volume.drivers.lightos     raise MaxRetryError(_pool, url, error or ResponseError(cause))
2025-01-21 16:24:38.920 25 ERROR cinder.volume.drivers.lightos urllib3.exceptions.MaxRetryError: HTTPSConnectionPool(host='[LB_IP_ADDRESS]', port=443): Max retries exceeded with url: /api/v2/clusterinfo (Caused by NewConnectionError('<urllib3.connection.HTTPSConnection object at 0x7f57f4bfa1a0>: Failed to establish a new connection: [Errno 111] ECONNREFUSED'))
2025-01-21 16:24:38.920 25 ERROR cinder.volume.drivers.lightos 
2025-01-21 16:24:38.920 25 ERROR cinder.volume.drivers.lightos During handling of the above exception, another exception occurred:
2025-01-21 16:24:38.920 25 ERROR cinder.volume.drivers.lightos 
2025-01-21 16:24:38.920 25 ERROR cinder.volume.drivers.lightos Traceback (most recent call last):
2025-01-21 16:24:38.920 25 ERROR cinder.volume.drivers.lightos   File "/var/lib/kolla/venv/lib/python3.10/site-packages/cinder/volume/drivers/lightos.py", line 356, in __send_cmd
2025-01-21 16:24:38.920 25 ERROR cinder.volume.drivers.lightos     response = session.send(
2025-01-21 16:24:38.920 25 ERROR cinder.volume.drivers.lightos   File "/var/lib/kolla/venv/lib/python3.10/site-packages/requests/sessions.py", line 703, in send
2025-01-21 16:24:38.920 25 ERROR cinder.volume.drivers.lightos     r = adapter.send(request, **kwargs)
2025-01-21 16:24:38.920 25 ERROR cinder.volume.drivers.lightos   File "/var/lib/kolla/venv/lib/python3.10/site-packages/requests/adapters.py", line 700, in send
2025-01-21 16:24:38.920 25 ERROR cinder.volume.drivers.lightos     raise ConnectionError(e, request=request)
2025-01-21 16:24:38.920 25 ERROR cinder.volume.drivers.lightos requests.exceptions.ConnectionError: HTTPSConnectionPool(host='[LB_IP_ADDRESS]', port=443): Max retries exceeded with url: /api/v2/clusterinfo (Caused by NewConnectionError('<urllib3.connection.HTTPSConnection object at 0x7f57f4bfa1a0>: Failed to establish a new connection: [Errno 111] ECONNREFUSED'))
2025-01-21 16:24:38.920 25 ERROR cinder.volume.drivers.lightos 
2025-01-21 16:24:38.922 25 ERROR cinder.volume.manager [None req-9e00f5ec-d1cd-4f24-bf2a-c5a2c03ca1d3 - - - - - -] Failed to initialize driver.: cinder.exception.VolumeDriverException: Volume driver reported an error: Could not get a response from any API server
2025-01-21 16:24:38.922 25 ERROR cinder.volume.manager Traceback (most recent call last):
2025-01-21 16:24:38.922 25 ERROR cinder.volume.manager   File "/var/lib/kolla/venv/lib/python3.10/site-packages/cinder/volume/manager.py", line 523, in _init_host
2025-01-21 16:24:38.922 25 ERROR cinder.volume.manager     self.driver.do_setup(ctxt)
2025-01-21 16:24:38.922 25 ERROR cinder.volume.manager   File "/var/lib/kolla/venv/lib/python3.10/site-packages/cinder/volume/drivers/lightos.py", line 922, in do_setup
2025-01-21 16:24:38.922 25 ERROR cinder.volume.manager     self.get_cluster_info()
2025-01-21 16:24:38.922 25 ERROR cinder.volume.manager   File "/var/lib/kolla/venv/lib/python3.10/site-packages/cinder/volume/drivers/lightos.py", line 873, in get_cluster_info
2025-01-21 16:24:38.922 25 ERROR cinder.volume.manager     status_code, cluster_info = self.cluster.send_cmd(
2025-01-21 16:24:38.922 25 ERROR cinder.volume.manager   File "/var/lib/kolla/venv/lib/python3.10/site-packages/cinder/volume/drivers/lightos.py", line 315, in send_cmd
2025-01-21 16:24:38.922 25 ERROR cinder.volume.manager     raise exception.VolumeDriverException(
2025-01-21 16:24:38.922 25 ERROR cinder.volume.manager cinder.exception.VolumeDriverException: Volume driver reported an error: Could not get a response from any API server
2025-01-21 16:24:38.922 25 ERROR cinder.volume.manager 
2025-01-21 16:24:42.927 25 INFO cinder.volume.manager [None req-9e00f5ec-d1cd-4f24-bf2a-c5a2c03ca1d3 - - - - - -] Starting volume driver LightOSVolumeDriver (2.3.12)
2025-01-21 16:24:42.928 25 INFO cinder.volume.drivers.lightos [None req-9e00f5ec-d1cd-4f24-bf2a-c5a2c03ca1d3 - - - - - -] Invoking get_cluster_info using GET url: /api/v2/clusterinfo             request.body: {} ssl_verify: False
2025-01-21 16:24:42.931 25 ERROR cinder.volume.drivers.lightos [None req-9e00f5ec-d1cd-4f24-bf2a-c5a2c03ca1d3 - - - - - -] REST server not responding at 'https://[LB_IP_ADDRESS]:443/api/v2/clusterinfo': requests.exceptions.ConnectionError: HTTPSConnectionPool(host='[LB_IP_ADDRESS]', port=443): Max retries exceeded with url: /api/v2/clusterinfo (Caused by NewConnectionError('<urllib3.connection.HTTPSConnection object at 0x7f57f4bf8ac0>: Failed to establish a new connection: [Errno 111] ECONNREFUSED'))
2025-01-21 16:24:42.931 25 ERROR cinder.volume.drivers.lightos Traceback (most recent call last):
2025-01-21 16:24:42.931 25 ERROR cinder.volume.drivers.lightos   File "/var/lib/kolla/venv/lib/python3.10/site-packages/urllib3/connection.py", line 174, in _new_conn
2025-01-21 16:24:42.931 25 ERROR cinder.volume.drivers.lightos     conn = connection.create_connection(
2025-01-21 16:24:42.931 25 ERROR cinder.volume.drivers.lightos   File "/var/lib/kolla/venv/lib/python3.10/site-packages/urllib3/util/connection.py", line 95, in create_connection
2025-01-21 16:24:42.931 25 ERROR cinder.volume.drivers.lightos     raise err
2025-01-21 16:24:42.931 25 ERROR cinder.volume.drivers.lightos   File "/var/lib/kolla/venv/lib/python3.10/site-packages/urllib3/util/connection.py", line 85, in create_connection
2025-01-21 16:24:42.931 25 ERROR cinder.volume.drivers.lightos     sock.connect(sa)
2025-01-21 16:24:42.931 25 ERROR cinder.volume.drivers.lightos   File "/var/lib/kolla/venv/lib/python3.10/site-packages/eventlet/greenio/base.py", line 265, in connect
2025-01-21 16:24:42.931 25 ERROR cinder.volume.drivers.lightos     socket_checkerr(fd)
2025-01-21 16:24:42.931 25 ERROR cinder.volume.drivers.lightos   File "/var/lib/kolla/venv/lib/python3.10/site-packages/eventlet/greenio/base.py", line 50, in socket_checkerr
2025-01-21 16:24:42.931 25 ERROR cinder.volume.drivers.lightos     raise OSError(err, errno.errorcode[err])
2025-01-21 16:24:42.931 25 ERROR cinder.volume.drivers.lightos ConnectionRefusedError: [Errno 111] ECONNREFUSED
2025-01-21 16:24:42.931 25 ERROR cinder.volume.drivers.lightos 
2025-01-21 16:24:42.931 25 ERROR cinder.volume.drivers.lightos During handling of the above exception, another exception occurred:
2025-01-21 16:24:42.931 25 ERROR cinder.volume.drivers.lightos 
2025-01-21 16:24:42.931 25 ERROR cinder.volume.drivers.lightos Traceback (most recent call last):
2025-01-21 16:24:42.931 25 ERROR cinder.volume.drivers.lightos   File "/var/lib/kolla/venv/lib/python3.10/site-packages/urllib3/connectionpool.py", line 715, in urlopen
2025-01-21 16:24:42.931 25 ERROR cinder.volume.drivers.lightos     httplib_response = self._make_request(
2025-01-21 16:24:42.931 25 ERROR cinder.volume.drivers.lightos   File "/var/lib/kolla/venv/lib/python3.10/site-packages/urllib3/connectionpool.py", line 404, in _make_request
2025-01-21 16:24:42.931 25 ERROR cinder.volume.drivers.lightos     self._validate_conn(conn)
2025-01-21 16:24:42.931 25 ERROR cinder.volume.drivers.lightos   File "/var/lib/kolla/venv/lib/python3.10/site-packages/urllib3/connectionpool.py", line 1060, in _validate_conn
2025-01-21 16:24:42.931 25 ERROR cinder.volume.drivers.lightos     conn.connect()
2025-01-21 16:24:42.931 25 ERROR cinder.volume.drivers.lightos   File "/var/lib/kolla/venv/lib/python3.10/site-packages/urllib3/connection.py", line 363, in connect
2025-01-21 16:24:42.931 25 ERROR cinder.volume.drivers.lightos     self.sock = conn = self._new_conn()
2025-01-21 16:24:42.931 25 ERROR cinder.volume.drivers.lightos   File "/var/lib/kolla/venv/lib/python3.10/site-packages/urllib3/connection.py", line 186, in _new_conn
2025-01-21 16:24:42.931 25 ERROR cinder.volume.drivers.lightos     raise NewConnectionError(
2025-01-21 16:24:42.931 25 ERROR cinder.volume.drivers.lightos urllib3.exceptions.NewConnectionError: <urllib3.connection.HTTPSConnection object at 0x7f57f4bf8ac0>: Failed to establish a new connection: [Errno 111] ECONNREFUSED
2025-01-21 16:24:42.931 25 ERROR cinder.volume.drivers.lightos 
2025-01-21 16:24:42.931 25 ERROR cinder.volume.drivers.lightos During handling of the above exception, another exception occurred:
2025-01-21 16:24:42.931 25 ERROR cinder.volume.drivers.lightos 
2025-01-21 16:24:42.931 25 ERROR cinder.volume.drivers.lightos Traceback (most recent call last):
2025-01-21 16:24:42.931 25 ERROR cinder.volume.drivers.lightos   File "/var/lib/kolla/venv/lib/python3.10/site-packages/requests/adapters.py", line 667, in send
2025-01-21 16:24:42.931 25 ERROR cinder.volume.drivers.lightos     resp = conn.urlopen(
2025-01-21 16:24:42.931 25 ERROR cinder.volume.drivers.lightos   File "/var/lib/kolla/venv/lib/python3.10/site-packages/urllib3/connectionpool.py", line 801, in urlopen
2025-01-21 16:24:42.931 25 ERROR cinder.volume.drivers.lightos     retries = retries.increment(
2025-01-21 16:24:42.931 25 ERROR cinder.volume.drivers.lightos   File "/var/lib/kolla/venv/lib/python3.10/site-packages/urllib3/util/retry.py", line 594, in increment
2025-01-21 16:24:42.931 25 ERROR cinder.volume.drivers.lightos     raise MaxRetryError(_pool, url, error or ResponseError(cause))
2025-01-21 16:24:42.931 25 ERROR cinder.volume.drivers.lightos urllib3.exceptions.MaxRetryError: HTTPSConnectionPool(host='[LB_IP_ADDRESS]', port=443): Max retries exceeded with url: /api/v2/clusterinfo (Caused by NewConnectionError('<urllib3.connection.HTTPSConnection object at 0x7f57f4bf8ac0>: Failed to establish a new connection: [Errno 111] ECONNREFUSED'))
2025-01-21 16:24:42.931 25 ERROR cinder.volume.drivers.lightos 
2025-01-21 16:24:42.931 25 ERROR cinder.volume.drivers.lightos During handling of the above exception, another exception occurred:
2025-01-21 16:24:42.931 25 ERROR cinder.volume.drivers.lightos 
2025-01-21 16:24:42.931 25 ERROR cinder.volume.drivers.lightos Traceback (most recent call last):
2025-01-21 16:24:42.931 25 ERROR cinder.volume.drivers.lightos   File "/var/lib/kolla/venv/lib/python3.10/site-packages/cinder/volume/drivers/lightos.py", line 356, in __send_cmd
2025-01-21 16:24:42.931 25 ERROR cinder.volume.drivers.lightos     response = session.send(
2025-01-21 16:24:42.931 25 ERROR cinder.volume.drivers.lightos   File "/var/lib/kolla/venv/lib/python3.10/site-packages/requests/sessions.py", line 703, in send
2025-01-21 16:24:42.931 25 ERROR cinder.volume.drivers.lightos     r = adapter.send(request, **kwargs)
2025-01-21 16:24:42.931 25 ERROR cinder.volume.drivers.lightos   File "/var/lib/kolla/venv/lib/python3.10/site-packages/requests/adapters.py", line 700, in send
2025-01-21 16:24:42.931 25 ERROR cinder.volume.drivers.lightos     raise ConnectionError(e, request=request)
2025-01-21 16:24:42.931 25 ERROR cinder.volume.drivers.lightos requests.exceptions.ConnectionError: HTTPSConnectionPool(host='[LB_IP_ADDRESS]', port=443): Max retries exceeded with url: /api/v2/clusterinfo (Caused by NewConnectionError('<urllib3.connection.HTTPSConnection object at 0x7f57f4bf8ac0>: Failed to establish a new connection: [Errno 111] ECONNREFUSED'))
2025-01-21 16:24:42.931 25 ERROR cinder.volume.drivers.lightos 
2025-01-21 16:24:42.934 25 INFO cinder.volume.drivers.lightos [None req-9e00f5ec-d1cd-4f24-bf2a-c5a2c03ca1d3 - - - - - -] Invoking get_cluster_info using GET url: /api/v2/clusterinfo             request.body: {} ssl_verify: False
2025-01-21 16:24:45.985 25 ERROR cinder.volume.drivers.lightos [None req-9e00f5ec-d1cd-4f24-bf2a-c5a2c03ca1d3 - - - - - -] REST server not responding at 'https://[LB_IP_ADDRESS]:443/api/v2/clusterinfo': requests.exceptions.ConnectionError: HTTPSConnectionPool(host='[LB_IP_ADDRESS]', port=443): Max retries exceeded with url: /api/v2/clusterinfo (Caused by NewConnectionError('<urllib3.connection.HTTPSConnection object at 0x7f57f4bf8460>: Failed to establish a new connection: [Errno 113] EHOSTUNREACH'))
2025-01-21 16:24:45.985 25 ERROR cinder.volume.drivers.lightos Traceback (most recent call last):
2025-01-21 16:24:45.985 25 ERROR cinder.volume.drivers.lightos   File "/var/lib/kolla/venv/lib/python3.10/site-packages/urllib3/connection.py", line 174, in _new_conn
2025-01-21 16:24:45.985 25 ERROR cinder.volume.drivers.lightos     conn = connection.create_connection(
2025-01-21 16:24:45.985 25 ERROR cinder.volume.drivers.lightos   File "/var/lib/kolla/venv/lib/python3.10/site-packages/urllib3/util/connection.py", line 95, in create_connection
2025-01-21 16:24:45.985 25 ERROR cinder.volume.drivers.lightos     raise err
2025-01-21 16:24:45.985 25 ERROR cinder.volume.drivers.lightos   File "/var/lib/kolla/venv/lib/python3.10/site-packages/urllib3/util/connection.py", line 85, in create_connection
2025-01-21 16:24:45.985 25 ERROR cinder.volume.drivers.lightos     sock.connect(sa)
2025-01-21 16:24:45.985 25 ERROR cinder.volume.drivers.lightos   File "/var/lib/kolla/venv/lib/python3.10/site-packages/eventlet/greenio/base.py", line 265, in connect
2025-01-21 16:24:45.985 25 ERROR cinder.volume.drivers.lightos     socket_checkerr(fd)
2025-01-21 16:24:45.985 25 ERROR cinder.volume.drivers.lightos   File "/var/lib/kolla/venv/lib/python3.10/site-packages/eventlet/greenio/base.py", line 50, in socket_checkerr
2025-01-21 16:24:45.985 25 ERROR cinder.volume.drivers.lightos     raise OSError(err, errno.errorcode[err])
2025-01-21 16:24:45.985 25 ERROR cinder.volume.drivers.lightos OSError: [Errno 113] EHOSTUNREACH
2025-01-21 16:24:45.985 25 ERROR cinder.volume.drivers.lightos 
2025-01-21 16:24:45.985 25 ERROR cinder.volume.drivers.lightos During handling of the above exception, another exception occurred:
2025-01-21 16:24:45.985 25 ERROR cinder.volume.drivers.lightos 
2025-01-21 16:24:45.985 25 ERROR cinder.volume.drivers.lightos Traceback (most recent call last):
2025-01-21 16:24:45.985 25 ERROR cinder.volume.drivers.lightos   File "/var/lib/kolla/venv/lib/python3.10/site-packages/urllib3/connectionpool.py", line 715, in urlopen
2025-01-21 16:24:45.985 25 ERROR cinder.volume.drivers.lightos     httplib_response = self._make_request(
2025-01-21 16:24:45.985 25 ERROR cinder.volume.drivers.lightos   File "/var/lib/kolla/venv/lib/python3.10/site-packages/urllib3/connectionpool.py", line 404, in _make_request
2025-01-21 16:24:45.985 25 ERROR cinder.volume.drivers.lightos     self._validate_conn(conn)
2025-01-21 16:24:45.985 25 ERROR cinder.volume.drivers.lightos   File "/var/lib/kolla/venv/lib/python3.10/site-packages/urllib3/connectionpool.py", line 1060, in _validate_conn
2025-01-21 16:24:45.985 25 ERROR cinder.volume.drivers.lightos     conn.connect()
2025-01-21 16:24:45.985 25 ERROR cinder.volume.drivers.lightos   File "/var/lib/kolla/venv/lib/python3.10/site-packages/urllib3/connection.py", line 363, in connect
2025-01-21 16:24:45.985 25 ERROR cinder.volume.drivers.lightos     self.sock = conn = self._new_conn()
2025-01-21 16:24:45.985 25 ERROR cinder.volume.drivers.lightos   File "/var/lib/kolla/venv/lib/python3.10/site-packages/urllib3/connection.py", line 186, in _new_conn
2025-01-21 16:24:45.985 25 ERROR cinder.volume.drivers.lightos     raise NewConnectionError(
2025-01-21 16:24:45.985 25 ERROR cinder.volume.drivers.lightos urllib3.exceptions.NewConnectionError: <urllib3.connection.HTTPSConnection object at 0x7f57f4bf8460>: Failed to establish a new connection: [Errno 113] EHOSTUNREACH
2025-01-21 16:24:45.985 25 ERROR cinder.volume.drivers.lightos 
2025-01-21 16:24:45.985 25 ERROR cinder.volume.drivers.lightos During handling of the above exception, another exception occurred:
2025-01-21 16:24:45.985 25 ERROR cinder.volume.drivers.lightos 
2025-01-21 16:24:45.985 25 ERROR cinder.volume.drivers.lightos Traceback (most recent call last):
2025-01-21 16:24:45.985 25 ERROR cinder.volume.drivers.lightos   File "/var/lib/kolla/venv/lib/python3.10/site-packages/requests/adapters.py", line 667, in send
2025-01-21 16:24:45.985 25 ERROR cinder.volume.drivers.lightos     resp = conn.urlopen(
2025-01-21 16:24:45.985 25 ERROR cinder.volume.drivers.lightos   File "/var/lib/kolla/venv/lib/python3.10/site-packages/urllib3/connectionpool.py", line 801, in urlopen
2025-01-21 16:24:45.985 25 ERROR cinder.volume.drivers.lightos     retries = retries.increment(
2025-01-21 16:24:45.985 25 ERROR cinder.volume.drivers.lightos   File "/var/lib/kolla/venv/lib/python3.10/site-packages/urllib3/util/retry.py", line 594, in increment
2025-01-21 16:24:45.985 25 ERROR cinder.volume.drivers.lightos     raise MaxRetryError(_pool, url, error or ResponseError(cause))
2025-01-21 16:24:45.985 25 ERROR cinder.volume.drivers.lightos urllib3.exceptions.MaxRetryError: HTTPSConnectionPool(host='[LB_IP_ADDRESS]', port=443): Max retries exceeded with url: /api/v2/clusterinfo (Caused by NewConnectionError('<urllib3.connection.HTTPSConnection object at 0x7f57f4bf8460>: Failed to establish a new connection: [Errno 113] EHOSTUNREACH'))
2025-01-21 16:24:45.985 25 ERROR cinder.volume.drivers.lightos 
2025-01-21 16:24:45.985 25 ERROR cinder.volume.drivers.lightos During handling of the above exception, another exception occurred:
2025-01-21 16:24:45.985 25 ERROR cinder.volume.drivers.lightos 
2025-01-21 16:24:45.985 25 ERROR cinder.volume.drivers.lightos Traceback (most recent call last):
2025-01-21 16:24:45.985 25 ERROR cinder.volume.drivers.lightos   File "/var/lib/kolla/venv/lib/python3.10/site-packages/cinder/volume/drivers/lightos.py", line 356, in __send_cmd
2025-01-21 16:24:45.985 25 ERROR cinder.volume.drivers.lightos     response = session.send(
2025-01-21 16:24:45.985 25 ERROR cinder.volume.drivers.lightos   File "/var/lib/kolla/venv/lib/python3.10/site-packages/requests/sessions.py", line 703, in send
2025-01-21 16:24:45.985 25 ERROR cinder.volume.drivers.lightos     r = adapter.send(request, **kwargs)
2025-01-21 16:24:45.985 25 ERROR cinder.volume.drivers.lightos   File "/var/lib/kolla/venv/lib/python3.10/site-packages/requests/adapters.py", line 700, in send
2025-01-21 16:24:45.985 25 ERROR cinder.volume.drivers.lightos     raise ConnectionError(e, request=request)
2025-01-21 16:24:45.985 25 ERROR cinder.volume.drivers.lightos requests.exceptions.ConnectionError: HTTPSConnectionPool(host='[LB_IP_ADDRESS]', port=443): Max retries exceeded with url: /api/v2/clusterinfo (Caused by NewConnectionError('<urllib3.connection.HTTPSConnection object at 0x7f57f4bf8460>: Failed to establish a new connection: [Errno 113] EHOSTUNREACH'))
2025-01-21 16:24:45.985 25 ERROR cinder.volume.drivers.lightos 
2025-01-21 16:24:45.988 25 INFO cinder.volume.drivers.lightos [None req-9e00f5ec-d1cd-4f24-bf2a-c5a2c03ca1d3 - - - - - -] Invoking get_cluster_info using GET url: /api/v2/clusterinfo             request.body: {} ssl_verify: False
2025-01-21 16:24:45.991 25 ERROR cinder.volume.drivers.lightos [None req-9e00f5ec-d1cd-4f24-bf2a-c5a2c03ca1d3 - - - - - -] REST server not responding at 'https://[LB_IP_ADDRESS]:443/api/v2/clusterinfo': requests.exceptions.ConnectionError: HTTPSConnectionPool(host='[LB_IP_ADDRESS]', port=443): Max retries exceeded with url: /api/v2/clusterinfo (Caused by NewConnectionError('<urllib3.connection.HTTPSConnection object at 0x7f57f4b84370>: Failed to establish a new connection: [Errno 111] ECONNREFUSED'))
2025-01-21 16:24:45.991 25 ERROR cinder.volume.drivers.lightos Traceback (most recent call last):
2025-01-21 16:24:45.991 25 ERROR cinder.volume.drivers.lightos   File "/var/lib/kolla/venv/lib/python3.10/site-packages/urllib3/connection.py", line 174, in _new_conn
2025-01-21 16:24:45.991 25 ERROR cinder.volume.drivers.lightos     conn = connection.create_connection(
2025-01-21 16:24:45.991 25 ERROR cinder.volume.drivers.lightos   File "/var/lib/kolla/venv/lib/python3.10/site-packages/urllib3/util/connection.py", line 95, in create_connection
2025-01-21 16:24:45.991 25 ERROR cinder.volume.drivers.lightos     raise err
2025-01-21 16:24:45.991 25 ERROR cinder.volume.drivers.lightos   File "/var/lib/kolla/venv/lib/python3.10/site-packages/urllib3/util/connection.py", line 85, in create_connection
2025-01-21 16:24:45.991 25 ERROR cinder.volume.drivers.lightos     sock.connect(sa)
2025-01-21 16:24:45.991 25 ERROR cinder.volume.drivers.lightos   File "/var/lib/kolla/venv/lib/python3.10/site-packages/eventlet/greenio/base.py", line 265, in connect
2025-01-21 16:24:45.991 25 ERROR cinder.volume.drivers.lightos     socket_checkerr(fd)
2025-01-21 16:24:45.991 25 ERROR cinder.volume.drivers.lightos   File "/var/lib/kolla/venv/lib/python3.10/site-packages/eventlet/greenio/base.py", line 50, in socket_checkerr
2025-01-21 16:24:45.991 25 ERROR cinder.volume.drivers.lightos     raise OSError(err, errno.errorcode[err])
2025-01-21 16:24:45.991 25 ERROR cinder.volume.drivers.lightos ConnectionRefusedError: [Errno 111] ECONNREFUSED
2025-01-21 16:24:45.991 25 ERROR cinder.volume.drivers.lightos 
2025-01-21 16:24:45.991 25 ERROR cinder.volume.drivers.lightos During handling of the above exception, another exception occurred:
2025-01-21 16:24:45.991 25 ERROR cinder.volume.drivers.lightos 
2025-01-21 16:24:45.991 25 ERROR cinder.volume.drivers.lightos Traceback (most recent call last):
2025-01-21 16:24:45.991 25 ERROR cinder.volume.drivers.lightos   File "/var/lib/kolla/venv/lib/python3.10/site-packages/urllib3/connectionpool.py", line 715, in urlopen
2025-01-21 16:24:45.991 25 ERROR cinder.volume.drivers.lightos     httplib_response = self._make_request(
2025-01-21 16:24:45.991 25 ERROR cinder.volume.drivers.lightos   File "/var/lib/kolla/venv/lib/python3.10/site-packages/urllib3/connectionpool.py", line 404, in _make_request
2025-01-21 16:24:45.991 25 ERROR cinder.volume.drivers.lightos     self._validate_conn(conn)
2025-01-21 16:24:45.991 25 ERROR cinder.volume.drivers.lightos   File "/var/lib/kolla/venv/lib/python3.10/site-packages/urllib3/connectionpool.py", line 1060, in _validate_conn
2025-01-21 16:24:45.991 25 ERROR cinder.volume.drivers.lightos     conn.connect()
2025-01-21 16:24:45.991 25 ERROR cinder.volume.drivers.lightos   File "/var/lib/kolla/venv/lib/python3.10/site-packages/urllib3/connection.py", line 363, in connect
2025-01-21 16:24:45.991 25 ERROR cinder.volume.drivers.lightos     self.sock = conn = self._new_conn()
2025-01-21 16:24:45.991 25 ERROR cinder.volume.drivers.lightos   File "/var/lib/kolla/venv/lib/python3.10/site-packages/urllib3/connection.py", line 186, in _new_conn
2025-01-21 16:24:45.991 25 ERROR cinder.volume.drivers.lightos     raise NewConnectionError(
2025-01-21 16:24:45.991 25 ERROR cinder.volume.drivers.lightos urllib3.exceptions.NewConnectionError: <urllib3.connection.HTTPSConnection object at 0x7f57f4b84370>: Failed to establish a new connection: [Errno 111] ECONNREFUSED
2025-01-21 16:24:45.991 25 ERROR cinder.volume.drivers.lightos 
2025-01-21 16:24:45.991 25 ERROR cinder.volume.drivers.lightos During handling of the above exception, another exception occurred:
2025-01-21 16:24:45.991 25 ERROR cinder.volume.drivers.lightos 
2025-01-21 16:24:45.991 25 ERROR cinder.volume.drivers.lightos Traceback (most recent call last):
2025-01-21 16:24:45.991 25 ERROR cinder.volume.drivers.lightos   File "/var/lib/kolla/venv/lib/python3.10/site-packages/requests/adapters.py", line 667, in send
2025-01-21 16:24:45.991 25 ERROR cinder.volume.drivers.lightos     resp = conn.urlopen(
2025-01-21 16:24:45.991 25 ERROR cinder.volume.drivers.lightos   File "/var/lib/kolla/venv/lib/python3.10/site-packages/urllib3/connectionpool.py", line 801, in urlopen
2025-01-21 16:24:45.991 25 ERROR cinder.volume.drivers.lightos     retries = retries.increment(
2025-01-21 16:24:45.991 25 ERROR cinder.volume.drivers.lightos   File "/var/lib/kolla/venv/lib/python3.10/site-packages/urllib3/util/retry.py", line 594, in increment
2025-01-21 16:24:45.991 25 ERROR cinder.volume.drivers.lightos     raise MaxRetryError(_pool, url, error or ResponseError(cause))
2025-01-21 16:24:45.991 25 ERROR cinder.volume.drivers.lightos urllib3.exceptions.MaxRetryError: HTTPSConnectionPool(host='[LB_IP_ADDRESS]', port=443): Max retries exceeded with url: /api/v2/clusterinfo (Caused by NewConnectionError('<urllib3.connection.HTTPSConnection object at 0x7f57f4b84370>: Failed to establish a new connection: [Errno 111] ECONNREFUSED'))
2025-01-21 16:24:45.991 25 ERROR cinder.volume.drivers.lightos 
2025-01-21 16:24:45.991 25 ERROR cinder.volume.drivers.lightos During handling of the above exception, another exception occurred:
2025-01-21 16:24:45.991 25 ERROR cinder.volume.drivers.lightos 
2025-01-21 16:24:45.991 25 ERROR cinder.volume.drivers.lightos Traceback (most recent call last):
2025-01-21 16:24:45.991 25 ERROR cinder.volume.drivers.lightos   File "/var/lib/kolla/venv/lib/python3.10/site-packages/cinder/volume/drivers/lightos.py", line 356, in __send_cmd
2025-01-21 16:24:45.991 25 ERROR cinder.volume.drivers.lightos     response = session.send(
2025-01-21 16:24:45.991 25 ERROR cinder.volume.drivers.lightos   File "/var/lib/kolla/venv/lib/python3.10/site-packages/requests/sessions.py", line 703, in send
2025-01-21 16:24:45.991 25 ERROR cinder.volume.drivers.lightos     r = adapter.send(request, **kwargs)
2025-01-21 16:24:45.991 25 ERROR cinder.volume.drivers.lightos   File "/var/lib/kolla/venv/lib/python3.10/site-packages/requests/adapters.py", line 700, in send
2025-01-21 16:24:45.991 25 ERROR cinder.volume.drivers.lightos     raise ConnectionError(e, request=request)
2025-01-21 16:24:45.991 25 ERROR cinder.volume.drivers.lightos requests.exceptions.ConnectionError: HTTPSConnectionPool(host='[LB_IP_ADDRESS]', port=443): Max retries exceeded with url: /api/v2/clusterinfo (Caused by NewConnectionError('<urllib3.connection.HTTPSConnection object at 0x7f57f4b84370>: Failed to establish a new connection: [Errno 111] ECONNREFUSED'))
2025-01-21 16:24:45.991 25 ERROR cinder.volume.drivers.lightos 
2025-01-21 16:24:45.993 25 ERROR cinder.volume.manager [None req-9e00f5ec-d1cd-4f24-bf2a-c5a2c03ca1d3 - - - - - -] Failed to initialize driver.: cinder.exception.VolumeDriverException: Volume driver reported an error: Could not get a response from any API server
2025-01-21 16:24:45.993 25 ERROR cinder.volume.manager Traceback (most recent call last):
2025-01-21 16:24:45.993 25 ERROR cinder.volume.manager   File "/var/lib/kolla/venv/lib/python3.10/site-packages/cinder/volume/manager.py", line 523, in _init_host
2025-01-21 16:24:45.993 25 ERROR cinder.volume.manager     self.driver.do_setup(ctxt)
2025-01-21 16:24:45.993 25 ERROR cinder.volume.manager   File "/var/lib/kolla/venv/lib/python3.10/site-packages/cinder/volume/drivers/lightos.py", line 922, in do_setup
2025-01-21 16:24:45.993 25 ERROR cinder.volume.manager     self.get_cluster_info()
2025-01-21 16:24:45.993 25 ERROR cinder.volume.manager   File "/var/lib/kolla/venv/lib/python3.10/site-packages/cinder/volume/drivers/lightos.py", line 873, in get_cluster_info
2025-01-21 16:24:45.993 25 ERROR cinder.volume.manager     status_code, cluster_info = self.cluster.send_cmd(
2025-01-21 16:24:45.993 25 ERROR cinder.volume.manager   File "/var/lib/kolla/venv/lib/python3.10/site-packages/cinder/volume/drivers/lightos.py", line 315, in send_cmd
2025-01-21 16:24:45.993 25 ERROR cinder.volume.manager     raise exception.VolumeDriverException(
2025-01-21 16:24:45.993 25 ERROR cinder.volume.manager cinder.exception.VolumeDriverException: Volume driver reported an error: Could not get a response from any API server
2025-01-21 16:24:45.993 25 ERROR cinder.volume.manager 
2025-01-21 16:24:46.012 25 WARNING oslo_config.cfg [None req-9e00f5ec-d1cd-4f24-bf2a-c5a2c03ca1d3 - - - - - -] Deprecated: Option "heartbeat_in_pthread" from group "oslo_messaging_rabbit" is deprecated for removal (The option is related to Eventlet which will be removed. In addition this has never worked as expected with services using eventlet for core service framework.).  Its value may be silently ignored in the future.
2025-01-21 16:24:46.054 25 INFO cinder.service [None req-9e00f5ec-d1cd-4f24-bf2a-c5a2c03ca1d3 - - - - - -] Starting cinder-volume cluster lightos_cinder_cluster@LIGHTOSyilgqu (version 25.1.0)
2025-01-21 16:24:46.073 25 INFO cinder.volume.manager [None req-9e00f5ec-d1cd-4f24-bf2a-c5a2c03ca1d3 - - - - - -] Initializing RPC dependent components of volume driver LightOSVolumeDriver (2.3.12)
2025-01-21 16:24:46.074 25 ERROR cinder.volume.volume_utils [None req-9e00f5ec-d1cd-4f24-bf2a-c5a2c03ca1d3 - - - - - -] Volume driver LightOSVolumeDriver not initialized
2025-01-21 16:24:46.075 25 ERROR cinder.volume.manager [None req-9e00f5ec-d1cd-4f24-bf2a-c5a2c03ca1d3 - - - - - -] Cannot complete RPC initialization because driver isn't initialized properly.: cinder.exception.DriverNotInitialized: Volume driver not ready.
2025-01-21 16:24:56.077 25 ERROR cinder.service [-] Manager for service cinder-volume rack13-server67@LIGHTOSyilgqu is reporting problems, not sending heartbeat. Service will appear "down".
2025-01-21 16:25:06.079 25 ERROR cinder.service [-] Manager for service cinder-volume rack13-server67@LIGHTOSyilgqu is reporting problems, not sending heartbeat. Service will appear "down".
2025-01-21 16:25:16.080 25 ERROR cinder.service [-] Manager for service cinder-volume rack13-server67@LIGHTOSyilgqu is reporting problems, not sending heartbeat. Service will appear "down".
2025-01-21 16:25:26.082 25 ERROR cinder.service [-] Manager for service cinder-volume rack13-server67@LIGHTOSyilgqu is reporting problems, not sending heartbeat. Service will appear "down".
2025-01-21 16:25:36.083 25 ERROR cinder.service [-] Manager for service cinder-volume rack13-server67@LIGHTOSyilgqu is reporting problems, not sending heartbeat. Service will appear "down".
2025-01-21 16:25:46.084 25 ERROR cinder.service [-] Manager for service cinder-volume rack13-server67@LIGHTOSyilgqu is reporting problems, not sending heartbeat. Service will appear "down".
2025-01-21 16:25:56.086 25 ERROR cinder.service [-] Manager for service cinder-volume rack13-server67@LIGHTOSyilgqu is reporting problems, not sending heartbeat. Service will appear "down".
2025-01-21 16:26:06.088 25 ERROR cinder.service [-] Manager for service cinder-volume rack13-server67@LIGHTOSyilgqu is reporting problems, not sending heartbeat. Service will appear "down".
2025-01-21 16:26:12.079 25 WARNING cinder.volume.manager [None req-ec965c91-53f5-41ba-8d9a-d00e91ae7a97 - - - - - -] Update driver status failed: (config name LIGHTOSyilgqu) is uninitialized.
2025-01-21 16:26:16.089 25 ERROR cinder.service [-] Manager for service cinder-volume rack13-server67@LIGHTOSyilgqu is reporting problems, not sending heartbeat. Service will appear "down".
2025-01-21 16:26:26.091 25 ERROR cinder.service [-] Manager for service cinder-volume rack13-server67@LIGHTOSyilgqu is reporting problems, not sending heartbeat. Service will appear "down".
2025-01-21 16:26:36.092 25 ERROR cinder.service [-] Manager for service cinder-volume rack13-server67@LIGHTOSyilgqu is reporting problems, not sending heartbeat. Service will appear "down".
2025-01-21 16:26:46.094 25 ERROR cinder.service [-] Manager for service cinder-volume rack13-server67@LIGHTOSyilgqu is reporting problems, not sending heartbeat. Service will appear "down".
2025-01-21 16:26:56.095 25 ERROR cinder.service [-] Manager for service cinder-volume rack13-server67@LIGHTOSyilgqu is reporting problems, not sending heartbeat. Service will appear "down".
2025-01-21 16:27:06.097 25 ERROR cinder.service [-] Manager for service cinder-volume rack13-server67@LIGHTOSyilgqu is reporting problems, not sending heartbeat. Service will appear "down".
2025-01-21 16:27:12.083 25 WARNING cinder.volume.manager [None req-ec965c91-53f5-41ba-8d9a-d00e91ae7a97 - - - - - -] Update driver status failed: (config name LIGHTOSyilgqu) is uninitialized.
2025-01-21 16:27:16.098 25 ERROR cinder.service [-] Manager for service cinder-volume rack13-server67@LIGHTOSyilgqu is reporting problems, not sending heartbeat. Service will appear "down".
2025-01-21 16:27:26.100 25 ERROR cinder.service [-] Manager for service cinder-volume rack13-server67@LIGHTOSyilgqu is reporting problems, not sending heartbeat. Service will appear "down".
2025-01-21 16:27:36.102 25 ERROR cinder.service [-] Manager for service cinder-volume rack13-server67@LIGHTOSyilgqu is reporting problems, not sending heartbeat. Service will appear "down".
2025-01-21 16:27:46.103 25 ERROR cinder.service [-] Manager for service cinder-volume rack13-server67@LIGHTOSyilgqu is reporting problems, not sending heartbeat. Service will appear "down".
2025-01-21 16:27:56.104 25 ERROR cinder.service [-] Manager for service cinder-volume rack13-server67@LIGHTOSyilgqu is reporting problems, not sending heartbeat. Service will appear "down".
2025-01-21 16:28:06.106 25 ERROR cinder.service [-] Manager for service cinder-volume rack13-server67@LIGHTOSyilgqu is reporting problems, not sending heartbeat. Service will appear "down".
2025-01-21 16:28:12.086 25 WARNING cinder.volume.manager [None req-ec965c91-53f5-41ba-8d9a-d00e91ae7a97 - - - - - -] Update driver status failed: (config name LIGHTOSyilgqu) is uninitialized.
2025-01-21 16:28:16.107 25 ERROR cinder.service [-] Manager for service cinder-volume rack13-server67@LIGHTOSyilgqu is reporting problems, not sending heartbeat. Service will appear "down".
