Build Started 21_01_2025_04_05_20
2025-01-21 04:05:30.037 7 INFO oslo_service.service [None req-c7f20337-86a6-44a6-991d-96f093a6e6e7 - - - - - -] Caught SIGTERM, stopping children
2025-01-21 04:05:30.039 7 INFO oslo_service.service [None req-c7f20337-86a6-44a6-991d-96f093a6e6e7 - - - - - -] Waiting on 1 children to exit
2025-01-21 04:05:30.783 25 WARNING amqp [None req-c7f20337-86a6-44a6-991d-96f093a6e6e7 - - - - - -] Received method (60, 30) during closing channel 1. This method will be ignored
2025-01-21 04:05:30.796 25 WARNING amqp [None req-c7f20337-86a6-44a6-991d-96f093a6e6e7 - - - - - -] Received method (60, 30) during closing channel 1. This method will be ignored
2025-01-21 04:05:30.804 25 WARNING amqp [None req-c7f20337-86a6-44a6-991d-96f093a6e6e7 - - - - - -] Received method (60, 30) during closing channel 1. This method will be ignored
2025-01-21 04:05:30.812 7 INFO oslo_service.service [None req-c7f20337-86a6-44a6-991d-96f093a6e6e7 - - - - - -] Child 25 exited with status 0
2025-01-21 04:05:46.033 7 INFO cinder.rpc [None req-b80c094d-6a5b-4cc3-8d90-4f59ebbfc8a8 - - - - - -] Automatically selected cinder-scheduler objects version 1.39 as minimum service version.
2025-01-21 04:05:46.037 7 INFO cinder.rpc [None req-b80c094d-6a5b-4cc3-8d90-4f59ebbfc8a8 - - - - - -] Automatically selected cinder-scheduler RPC version 3.12 as minimum service version.
2025-01-21 04:05:46.073 7 INFO cinder.volume.manager [None req-b80c094d-6a5b-4cc3-8d90-4f59ebbfc8a8 - - - - - -] Determined volume DB was empty at startup.
2025-01-21 04:05:46.090 7 INFO cinder.volume.manager [None req-b80c094d-6a5b-4cc3-8d90-4f59ebbfc8a8 - - - - - -] Image-volume cache disabled for host rack13-server67@LIGHTOSyilgqu.
2025-01-21 04:05:46.105 7 INFO oslo_service.service [None req-b80c094d-6a5b-4cc3-8d90-4f59ebbfc8a8 - - - - - -] Starting 1 workers
2025-01-21 04:05:46.116 25 INFO cinder.service [-] Starting cinder-volume node (version 25.1.0)
2025-01-21 04:05:46.120 7 WARNING oslo_config.cfg [None req-b80c094d-6a5b-4cc3-8d90-4f59ebbfc8a8 - - - - - -] Deprecated: Option "heartbeat_in_pthread" from group "oslo_messaging_rabbit" is deprecated for removal (The option is related to Eventlet which will be removed. In addition this has never worked as expected with services using eventlet for core service framework.).  Its value may be silently ignored in the future.
2025-01-21 04:05:46.135 25 INFO cinder.volume.manager [None req-571cc66b-a331-4771-8119-dcb3407556c2 - - - - - -] Starting volume driver LightOSVolumeDriver (2.3.12)
2025-01-21 04:05:46.135 25 INFO cinder.volume.drivers.lightos [None req-571cc66b-a331-4771-8119-dcb3407556c2 - - - - - -] Invoking get_cluster_info using GET url: /api/v2/clusterinfo             request.body: {} ssl_verify: False
2025-01-21 04:05:46.138 25 ERROR cinder.volume.drivers.lightos [None req-571cc66b-a331-4771-8119-dcb3407556c2 - - - - - -] REST server not responding at 'https://[LB_IP_ADDRESS]:443/api/v2/clusterinfo': requests.exceptions.ConnectionError: HTTPSConnectionPool(host='[LB_IP_ADDRESS]', port=443): Max retries exceeded with url: /api/v2/clusterinfo (Caused by NewConnectionError('<urllib3.connection.HTTPSConnection object at 0x7ffa58aa9c30>: Failed to establish a new connection: [Errno 111] ECONNREFUSED'))
2025-01-21 04:05:46.138 25 ERROR cinder.volume.drivers.lightos Traceback (most recent call last):
2025-01-21 04:05:46.138 25 ERROR cinder.volume.drivers.lightos   File "/var/lib/kolla/venv/lib/python3.10/site-packages/urllib3/connection.py", line 174, in _new_conn
2025-01-21 04:05:46.138 25 ERROR cinder.volume.drivers.lightos     conn = connection.create_connection(
2025-01-21 04:05:46.138 25 ERROR cinder.volume.drivers.lightos   File "/var/lib/kolla/venv/lib/python3.10/site-packages/urllib3/util/connection.py", line 95, in create_connection
2025-01-21 04:05:46.138 25 ERROR cinder.volume.drivers.lightos     raise err
2025-01-21 04:05:46.138 25 ERROR cinder.volume.drivers.lightos   File "/var/lib/kolla/venv/lib/python3.10/site-packages/urllib3/util/connection.py", line 85, in create_connection
2025-01-21 04:05:46.138 25 ERROR cinder.volume.drivers.lightos     sock.connect(sa)
2025-01-21 04:05:46.138 25 ERROR cinder.volume.drivers.lightos   File "/var/lib/kolla/venv/lib/python3.10/site-packages/eventlet/greenio/base.py", line 265, in connect
2025-01-21 04:05:46.138 25 ERROR cinder.volume.drivers.lightos     socket_checkerr(fd)
2025-01-21 04:05:46.138 25 ERROR cinder.volume.drivers.lightos   File "/var/lib/kolla/venv/lib/python3.10/site-packages/eventlet/greenio/base.py", line 50, in socket_checkerr
2025-01-21 04:05:46.138 25 ERROR cinder.volume.drivers.lightos     raise OSError(err, errno.errorcode[err])
2025-01-21 04:05:46.138 25 ERROR cinder.volume.drivers.lightos ConnectionRefusedError: [Errno 111] ECONNREFUSED
2025-01-21 04:05:46.138 25 ERROR cinder.volume.drivers.lightos 
2025-01-21 04:05:46.138 25 ERROR cinder.volume.drivers.lightos During handling of the above exception, another exception occurred:
2025-01-21 04:05:46.138 25 ERROR cinder.volume.drivers.lightos 
2025-01-21 04:05:46.138 25 ERROR cinder.volume.drivers.lightos Traceback (most recent call last):
2025-01-21 04:05:46.138 25 ERROR cinder.volume.drivers.lightos   File "/var/lib/kolla/venv/lib/python3.10/site-packages/urllib3/connectionpool.py", line 715, in urlopen
2025-01-21 04:05:46.138 25 ERROR cinder.volume.drivers.lightos     httplib_response = self._make_request(
2025-01-21 04:05:46.138 25 ERROR cinder.volume.drivers.lightos   File "/var/lib/kolla/venv/lib/python3.10/site-packages/urllib3/connectionpool.py", line 404, in _make_request
2025-01-21 04:05:46.138 25 ERROR cinder.volume.drivers.lightos     self._validate_conn(conn)
2025-01-21 04:05:46.138 25 ERROR cinder.volume.drivers.lightos   File "/var/lib/kolla/venv/lib/python3.10/site-packages/urllib3/connectionpool.py", line 1060, in _validate_conn
2025-01-21 04:05:46.138 25 ERROR cinder.volume.drivers.lightos     conn.connect()
2025-01-21 04:05:46.138 25 ERROR cinder.volume.drivers.lightos   File "/var/lib/kolla/venv/lib/python3.10/site-packages/urllib3/connection.py", line 363, in connect
2025-01-21 04:05:46.138 25 ERROR cinder.volume.drivers.lightos     self.sock = conn = self._new_conn()
2025-01-21 04:05:46.138 25 ERROR cinder.volume.drivers.lightos   File "/var/lib/kolla/venv/lib/python3.10/site-packages/urllib3/connection.py", line 186, in _new_conn
2025-01-21 04:05:46.138 25 ERROR cinder.volume.drivers.lightos     raise NewConnectionError(
2025-01-21 04:05:46.138 25 ERROR cinder.volume.drivers.lightos urllib3.exceptions.NewConnectionError: <urllib3.connection.HTTPSConnection object at 0x7ffa58aa9c30>: Failed to establish a new connection: [Errno 111] ECONNREFUSED
2025-01-21 04:05:46.138 25 ERROR cinder.volume.drivers.lightos 
2025-01-21 04:05:46.138 25 ERROR cinder.volume.drivers.lightos During handling of the above exception, another exception occurred:
2025-01-21 04:05:46.138 25 ERROR cinder.volume.drivers.lightos 
2025-01-21 04:05:46.138 25 ERROR cinder.volume.drivers.lightos Traceback (most recent call last):
2025-01-21 04:05:46.138 25 ERROR cinder.volume.drivers.lightos   File "/var/lib/kolla/venv/lib/python3.10/site-packages/requests/adapters.py", line 667, in send
2025-01-21 04:05:46.138 25 ERROR cinder.volume.drivers.lightos     resp = conn.urlopen(
2025-01-21 04:05:46.138 25 ERROR cinder.volume.drivers.lightos   File "/var/lib/kolla/venv/lib/python3.10/site-packages/urllib3/connectionpool.py", line 801, in urlopen
2025-01-21 04:05:46.138 25 ERROR cinder.volume.drivers.lightos     retries = retries.increment(
2025-01-21 04:05:46.138 25 ERROR cinder.volume.drivers.lightos   File "/var/lib/kolla/venv/lib/python3.10/site-packages/urllib3/util/retry.py", line 594, in increment
2025-01-21 04:05:46.138 25 ERROR cinder.volume.drivers.lightos     raise MaxRetryError(_pool, url, error or ResponseError(cause))
2025-01-21 04:05:46.138 25 ERROR cinder.volume.drivers.lightos urllib3.exceptions.MaxRetryError: HTTPSConnectionPool(host='[LB_IP_ADDRESS]', port=443): Max retries exceeded with url: /api/v2/clusterinfo (Caused by NewConnectionError('<urllib3.connection.HTTPSConnection object at 0x7ffa58aa9c30>: Failed to establish a new connection: [Errno 111] ECONNREFUSED'))
2025-01-21 04:05:46.138 25 ERROR cinder.volume.drivers.lightos 
2025-01-21 04:05:46.138 25 ERROR cinder.volume.drivers.lightos During handling of the above exception, another exception occurred:
2025-01-21 04:05:46.138 25 ERROR cinder.volume.drivers.lightos 
2025-01-21 04:05:46.138 25 ERROR cinder.volume.drivers.lightos Traceback (most recent call last):
2025-01-21 04:05:46.138 25 ERROR cinder.volume.drivers.lightos   File "/var/lib/kolla/venv/lib/python3.10/site-packages/cinder/volume/drivers/lightos.py", line 356, in __send_cmd
2025-01-21 04:05:46.138 25 ERROR cinder.volume.drivers.lightos     response = session.send(
2025-01-21 04:05:46.138 25 ERROR cinder.volume.drivers.lightos   File "/var/lib/kolla/venv/lib/python3.10/site-packages/requests/sessions.py", line 703, in send
2025-01-21 04:05:46.138 25 ERROR cinder.volume.drivers.lightos     r = adapter.send(request, **kwargs)
2025-01-21 04:05:46.138 25 ERROR cinder.volume.drivers.lightos   File "/var/lib/kolla/venv/lib/python3.10/site-packages/requests/adapters.py", line 700, in send
2025-01-21 04:05:46.138 25 ERROR cinder.volume.drivers.lightos     raise ConnectionError(e, request=request)
2025-01-21 04:05:46.138 25 ERROR cinder.volume.drivers.lightos requests.exceptions.ConnectionError: HTTPSConnectionPool(host='[LB_IP_ADDRESS]', port=443): Max retries exceeded with url: /api/v2/clusterinfo (Caused by NewConnectionError('<urllib3.connection.HTTPSConnection object at 0x7ffa58aa9c30>: Failed to establish a new connection: [Errno 111] ECONNREFUSED'))
2025-01-21 04:05:46.138 25 ERROR cinder.volume.drivers.lightos 
2025-01-21 04:05:46.140 25 INFO cinder.volume.drivers.lightos [None req-571cc66b-a331-4771-8119-dcb3407556c2 - - - - - -] Invoking get_cluster_info using GET url: /api/v2/clusterinfo             request.body: {} ssl_verify: False
2025-01-21 04:05:49.218 25 ERROR cinder.volume.drivers.lightos [None req-571cc66b-a331-4771-8119-dcb3407556c2 - - - - - -] REST server not responding at 'https://[LB_IP_ADDRESS]:443/api/v2/clusterinfo': requests.exceptions.ConnectionError: HTTPSConnectionPool(host='[LB_IP_ADDRESS]', port=443): Max retries exceeded with url: /api/v2/clusterinfo (Caused by NewConnectionError('<urllib3.connection.HTTPSConnection object at 0x7ffa58aa8f70>: Failed to establish a new connection: [Errno 113] EHOSTUNREACH'))
2025-01-21 04:05:49.218 25 ERROR cinder.volume.drivers.lightos Traceback (most recent call last):
2025-01-21 04:05:49.218 25 ERROR cinder.volume.drivers.lightos   File "/var/lib/kolla/venv/lib/python3.10/site-packages/urllib3/connection.py", line 174, in _new_conn
2025-01-21 04:05:49.218 25 ERROR cinder.volume.drivers.lightos     conn = connection.create_connection(
2025-01-21 04:05:49.218 25 ERROR cinder.volume.drivers.lightos   File "/var/lib/kolla/venv/lib/python3.10/site-packages/urllib3/util/connection.py", line 95, in create_connection
2025-01-21 04:05:49.218 25 ERROR cinder.volume.drivers.lightos     raise err
2025-01-21 04:05:49.218 25 ERROR cinder.volume.drivers.lightos   File "/var/lib/kolla/venv/lib/python3.10/site-packages/urllib3/util/connection.py", line 85, in create_connection
2025-01-21 04:05:49.218 25 ERROR cinder.volume.drivers.lightos     sock.connect(sa)
2025-01-21 04:05:49.218 25 ERROR cinder.volume.drivers.lightos   File "/var/lib/kolla/venv/lib/python3.10/site-packages/eventlet/greenio/base.py", line 265, in connect
2025-01-21 04:05:49.218 25 ERROR cinder.volume.drivers.lightos     socket_checkerr(fd)
2025-01-21 04:05:49.218 25 ERROR cinder.volume.drivers.lightos   File "/var/lib/kolla/venv/lib/python3.10/site-packages/eventlet/greenio/base.py", line 50, in socket_checkerr
2025-01-21 04:05:49.218 25 ERROR cinder.volume.drivers.lightos     raise OSError(err, errno.errorcode[err])
2025-01-21 04:05:49.218 25 ERROR cinder.volume.drivers.lightos OSError: [Errno 113] EHOSTUNREACH
2025-01-21 04:05:49.218 25 ERROR cinder.volume.drivers.lightos 
2025-01-21 04:05:49.218 25 ERROR cinder.volume.drivers.lightos During handling of the above exception, another exception occurred:
2025-01-21 04:05:49.218 25 ERROR cinder.volume.drivers.lightos 
2025-01-21 04:05:49.218 25 ERROR cinder.volume.drivers.lightos Traceback (most recent call last):
2025-01-21 04:05:49.218 25 ERROR cinder.volume.drivers.lightos   File "/var/lib/kolla/venv/lib/python3.10/site-packages/urllib3/connectionpool.py", line 715, in urlopen
2025-01-21 04:05:49.218 25 ERROR cinder.volume.drivers.lightos     httplib_response = self._make_request(
2025-01-21 04:05:49.218 25 ERROR cinder.volume.drivers.lightos   File "/var/lib/kolla/venv/lib/python3.10/site-packages/urllib3/connectionpool.py", line 404, in _make_request
2025-01-21 04:05:49.218 25 ERROR cinder.volume.drivers.lightos     self._validate_conn(conn)
2025-01-21 04:05:49.218 25 ERROR cinder.volume.drivers.lightos   File "/var/lib/kolla/venv/lib/python3.10/site-packages/urllib3/connectionpool.py", line 1060, in _validate_conn
2025-01-21 04:05:49.218 25 ERROR cinder.volume.drivers.lightos     conn.connect()
2025-01-21 04:05:49.218 25 ERROR cinder.volume.drivers.lightos   File "/var/lib/kolla/venv/lib/python3.10/site-packages/urllib3/connection.py", line 363, in connect
2025-01-21 04:05:49.218 25 ERROR cinder.volume.drivers.lightos     self.sock = conn = self._new_conn()
2025-01-21 04:05:49.218 25 ERROR cinder.volume.drivers.lightos   File "/var/lib/kolla/venv/lib/python3.10/site-packages/urllib3/connection.py", line 186, in _new_conn
2025-01-21 04:05:49.218 25 ERROR cinder.volume.drivers.lightos     raise NewConnectionError(
2025-01-21 04:05:49.218 25 ERROR cinder.volume.drivers.lightos urllib3.exceptions.NewConnectionError: <urllib3.connection.HTTPSConnection object at 0x7ffa58aa8f70>: Failed to establish a new connection: [Errno 113] EHOSTUNREACH
2025-01-21 04:05:49.218 25 ERROR cinder.volume.drivers.lightos 
2025-01-21 04:05:49.218 25 ERROR cinder.volume.drivers.lightos During handling of the above exception, another exception occurred:
2025-01-21 04:05:49.218 25 ERROR cinder.volume.drivers.lightos 
2025-01-21 04:05:49.218 25 ERROR cinder.volume.drivers.lightos Traceback (most recent call last):
2025-01-21 04:05:49.218 25 ERROR cinder.volume.drivers.lightos   File "/var/lib/kolla/venv/lib/python3.10/site-packages/requests/adapters.py", line 667, in send
2025-01-21 04:05:49.218 25 ERROR cinder.volume.drivers.lightos     resp = conn.urlopen(
2025-01-21 04:05:49.218 25 ERROR cinder.volume.drivers.lightos   File "/var/lib/kolla/venv/lib/python3.10/site-packages/urllib3/connectionpool.py", line 801, in urlopen
2025-01-21 04:05:49.218 25 ERROR cinder.volume.drivers.lightos     retries = retries.increment(
2025-01-21 04:05:49.218 25 ERROR cinder.volume.drivers.lightos   File "/var/lib/kolla/venv/lib/python3.10/site-packages/urllib3/util/retry.py", line 594, in increment
2025-01-21 04:05:49.218 25 ERROR cinder.volume.drivers.lightos     raise MaxRetryError(_pool, url, error or ResponseError(cause))
2025-01-21 04:05:49.218 25 ERROR cinder.volume.drivers.lightos urllib3.exceptions.MaxRetryError: HTTPSConnectionPool(host='[LB_IP_ADDRESS]', port=443): Max retries exceeded with url: /api/v2/clusterinfo (Caused by NewConnectionError('<urllib3.connection.HTTPSConnection object at 0x7ffa58aa8f70>: Failed to establish a new connection: [Errno 113] EHOSTUNREACH'))
2025-01-21 04:05:49.218 25 ERROR cinder.volume.drivers.lightos 
2025-01-21 04:05:49.218 25 ERROR cinder.volume.drivers.lightos During handling of the above exception, another exception occurred:
2025-01-21 04:05:49.218 25 ERROR cinder.volume.drivers.lightos 
2025-01-21 04:05:49.218 25 ERROR cinder.volume.drivers.lightos Traceback (most recent call last):
2025-01-21 04:05:49.218 25 ERROR cinder.volume.drivers.lightos   File "/var/lib/kolla/venv/lib/python3.10/site-packages/cinder/volume/drivers/lightos.py", line 356, in __send_cmd
2025-01-21 04:05:49.218 25 ERROR cinder.volume.drivers.lightos     response = session.send(
2025-01-21 04:05:49.218 25 ERROR cinder.volume.drivers.lightos   File "/var/lib/kolla/venv/lib/python3.10/site-packages/requests/sessions.py", line 703, in send
2025-01-21 04:05:49.218 25 ERROR cinder.volume.drivers.lightos     r = adapter.send(request, **kwargs)
2025-01-21 04:05:49.218 25 ERROR cinder.volume.drivers.lightos   File "/var/lib/kolla/venv/lib/python3.10/site-packages/requests/adapters.py", line 700, in send
2025-01-21 04:05:49.218 25 ERROR cinder.volume.drivers.lightos     raise ConnectionError(e, request=request)
2025-01-21 04:05:49.218 25 ERROR cinder.volume.drivers.lightos requests.exceptions.ConnectionError: HTTPSConnectionPool(host='[LB_IP_ADDRESS]', port=443): Max retries exceeded with url: /api/v2/clusterinfo (Caused by NewConnectionError('<urllib3.connection.HTTPSConnection object at 0x7ffa58aa8f70>: Failed to establish a new connection: [Errno 113] EHOSTUNREACH'))
2025-01-21 04:05:49.218 25 ERROR cinder.volume.drivers.lightos 
2025-01-21 04:05:49.220 25 INFO cinder.volume.drivers.lightos [None req-571cc66b-a331-4771-8119-dcb3407556c2 - - - - - -] Invoking get_cluster_info using GET url: /api/v2/clusterinfo             request.body: {} ssl_verify: False
2025-01-21 04:05:49.223 25 ERROR cinder.volume.drivers.lightos [None req-571cc66b-a331-4771-8119-dcb3407556c2 - - - - - -] REST server not responding at 'https://[LB_IP_ADDRESS]:443/api/v2/clusterinfo': requests.exceptions.ConnectionError: HTTPSConnectionPool(host='[LB_IP_ADDRESS]', port=443): Max retries exceeded with url: /api/v2/clusterinfo (Caused by NewConnectionError('<urllib3.connection.HTTPSConnection object at 0x7ffa58aa8490>: Failed to establish a new connection: [Errno 111] ECONNREFUSED'))
2025-01-21 04:05:49.223 25 ERROR cinder.volume.drivers.lightos Traceback (most recent call last):
2025-01-21 04:05:49.223 25 ERROR cinder.volume.drivers.lightos   File "/var/lib/kolla/venv/lib/python3.10/site-packages/urllib3/connection.py", line 174, in _new_conn
2025-01-21 04:05:49.223 25 ERROR cinder.volume.drivers.lightos     conn = connection.create_connection(
2025-01-21 04:05:49.223 25 ERROR cinder.volume.drivers.lightos   File "/var/lib/kolla/venv/lib/python3.10/site-packages/urllib3/util/connection.py", line 95, in create_connection
2025-01-21 04:05:49.223 25 ERROR cinder.volume.drivers.lightos     raise err
2025-01-21 04:05:49.223 25 ERROR cinder.volume.drivers.lightos   File "/var/lib/kolla/venv/lib/python3.10/site-packages/urllib3/util/connection.py", line 85, in create_connection
2025-01-21 04:05:49.223 25 ERROR cinder.volume.drivers.lightos     sock.connect(sa)
2025-01-21 04:05:49.223 25 ERROR cinder.volume.drivers.lightos   File "/var/lib/kolla/venv/lib/python3.10/site-packages/eventlet/greenio/base.py", line 265, in connect
2025-01-21 04:05:49.223 25 ERROR cinder.volume.drivers.lightos     socket_checkerr(fd)
2025-01-21 04:05:49.223 25 ERROR cinder.volume.drivers.lightos   File "/var/lib/kolla/venv/lib/python3.10/site-packages/eventlet/greenio/base.py", line 50, in socket_checkerr
2025-01-21 04:05:49.223 25 ERROR cinder.volume.drivers.lightos     raise OSError(err, errno.errorcode[err])
2025-01-21 04:05:49.223 25 ERROR cinder.volume.drivers.lightos ConnectionRefusedError: [Errno 111] ECONNREFUSED
2025-01-21 04:05:49.223 25 ERROR cinder.volume.drivers.lightos 
2025-01-21 04:05:49.223 25 ERROR cinder.volume.drivers.lightos During handling of the above exception, another exception occurred:
2025-01-21 04:05:49.223 25 ERROR cinder.volume.drivers.lightos 
2025-01-21 04:05:49.223 25 ERROR cinder.volume.drivers.lightos Traceback (most recent call last):
2025-01-21 04:05:49.223 25 ERROR cinder.volume.drivers.lightos   File "/var/lib/kolla/venv/lib/python3.10/site-packages/urllib3/connectionpool.py", line 715, in urlopen
2025-01-21 04:05:49.223 25 ERROR cinder.volume.drivers.lightos     httplib_response = self._make_request(
2025-01-21 04:05:49.223 25 ERROR cinder.volume.drivers.lightos   File "/var/lib/kolla/venv/lib/python3.10/site-packages/urllib3/connectionpool.py", line 404, in _make_request
2025-01-21 04:05:49.223 25 ERROR cinder.volume.drivers.lightos     self._validate_conn(conn)
2025-01-21 04:05:49.223 25 ERROR cinder.volume.drivers.lightos   File "/var/lib/kolla/venv/lib/python3.10/site-packages/urllib3/connectionpool.py", line 1060, in _validate_conn
2025-01-21 04:05:49.223 25 ERROR cinder.volume.drivers.lightos     conn.connect()
2025-01-21 04:05:49.223 25 ERROR cinder.volume.drivers.lightos   File "/var/lib/kolla/venv/lib/python3.10/site-packages/urllib3/connection.py", line 363, in connect
2025-01-21 04:05:49.223 25 ERROR cinder.volume.drivers.lightos     self.sock = conn = self._new_conn()
2025-01-21 04:05:49.223 25 ERROR cinder.volume.drivers.lightos   File "/var/lib/kolla/venv/lib/python3.10/site-packages/urllib3/connection.py", line 186, in _new_conn
2025-01-21 04:05:49.223 25 ERROR cinder.volume.drivers.lightos     raise NewConnectionError(
2025-01-21 04:05:49.223 25 ERROR cinder.volume.drivers.lightos urllib3.exceptions.NewConnectionError: <urllib3.connection.HTTPSConnection object at 0x7ffa58aa8490>: Failed to establish a new connection: [Errno 111] ECONNREFUSED
2025-01-21 04:05:49.223 25 ERROR cinder.volume.drivers.lightos 
2025-01-21 04:05:49.223 25 ERROR cinder.volume.drivers.lightos During handling of the above exception, another exception occurred:
2025-01-21 04:05:49.223 25 ERROR cinder.volume.drivers.lightos 
2025-01-21 04:05:49.223 25 ERROR cinder.volume.drivers.lightos Traceback (most recent call last):
2025-01-21 04:05:49.223 25 ERROR cinder.volume.drivers.lightos   File "/var/lib/kolla/venv/lib/python3.10/site-packages/requests/adapters.py", line 667, in send
2025-01-21 04:05:49.223 25 ERROR cinder.volume.drivers.lightos     resp = conn.urlopen(
2025-01-21 04:05:49.223 25 ERROR cinder.volume.drivers.lightos   File "/var/lib/kolla/venv/lib/python3.10/site-packages/urllib3/connectionpool.py", line 801, in urlopen
2025-01-21 04:05:49.223 25 ERROR cinder.volume.drivers.lightos     retries = retries.increment(
2025-01-21 04:05:49.223 25 ERROR cinder.volume.drivers.lightos   File "/var/lib/kolla/venv/lib/python3.10/site-packages/urllib3/util/retry.py", line 594, in increment
2025-01-21 04:05:49.223 25 ERROR cinder.volume.drivers.lightos     raise MaxRetryError(_pool, url, error or ResponseError(cause))
2025-01-21 04:05:49.223 25 ERROR cinder.volume.drivers.lightos urllib3.exceptions.MaxRetryError: HTTPSConnectionPool(host='[LB_IP_ADDRESS]', port=443): Max retries exceeded with url: /api/v2/clusterinfo (Caused by NewConnectionError('<urllib3.connection.HTTPSConnection object at 0x7ffa58aa8490>: Failed to establish a new connection: [Errno 111] ECONNREFUSED'))
2025-01-21 04:05:49.223 25 ERROR cinder.volume.drivers.lightos 
2025-01-21 04:05:49.223 25 ERROR cinder.volume.drivers.lightos During handling of the above exception, another exception occurred:
2025-01-21 04:05:49.223 25 ERROR cinder.volume.drivers.lightos 
2025-01-21 04:05:49.223 25 ERROR cinder.volume.drivers.lightos Traceback (most recent call last):
2025-01-21 04:05:49.223 25 ERROR cinder.volume.drivers.lightos   File "/var/lib/kolla/venv/lib/python3.10/site-packages/cinder/volume/drivers/lightos.py", line 356, in __send_cmd
2025-01-21 04:05:49.223 25 ERROR cinder.volume.drivers.lightos     response = session.send(
2025-01-21 04:05:49.223 25 ERROR cinder.volume.drivers.lightos   File "/var/lib/kolla/venv/lib/python3.10/site-packages/requests/sessions.py", line 703, in send
2025-01-21 04:05:49.223 25 ERROR cinder.volume.drivers.lightos     r = adapter.send(request, **kwargs)
2025-01-21 04:05:49.223 25 ERROR cinder.volume.drivers.lightos   File "/var/lib/kolla/venv/lib/python3.10/site-packages/requests/adapters.py", line 700, in send
2025-01-21 04:05:49.223 25 ERROR cinder.volume.drivers.lightos     raise ConnectionError(e, request=request)
2025-01-21 04:05:49.223 25 ERROR cinder.volume.drivers.lightos requests.exceptions.ConnectionError: HTTPSConnectionPool(host='[LB_IP_ADDRESS]', port=443): Max retries exceeded with url: /api/v2/clusterinfo (Caused by NewConnectionError('<urllib3.connection.HTTPSConnection object at 0x7ffa58aa8490>: Failed to establish a new connection: [Errno 111] ECONNREFUSED'))
2025-01-21 04:05:49.223 25 ERROR cinder.volume.drivers.lightos 
2025-01-21 04:05:49.225 25 ERROR cinder.volume.manager [None req-571cc66b-a331-4771-8119-dcb3407556c2 - - - - - -] Failed to initialize driver.: cinder.exception.VolumeDriverException: Volume driver reported an error: Could not get a response from any API server
2025-01-21 04:05:49.225 25 ERROR cinder.volume.manager Traceback (most recent call last):
2025-01-21 04:05:49.225 25 ERROR cinder.volume.manager   File "/var/lib/kolla/venv/lib/python3.10/site-packages/cinder/volume/manager.py", line 523, in _init_host
2025-01-21 04:05:49.225 25 ERROR cinder.volume.manager     self.driver.do_setup(ctxt)
2025-01-21 04:05:49.225 25 ERROR cinder.volume.manager   File "/var/lib/kolla/venv/lib/python3.10/site-packages/cinder/volume/drivers/lightos.py", line 922, in do_setup
2025-01-21 04:05:49.225 25 ERROR cinder.volume.manager     self.get_cluster_info()
2025-01-21 04:05:49.225 25 ERROR cinder.volume.manager   File "/var/lib/kolla/venv/lib/python3.10/site-packages/cinder/volume/drivers/lightos.py", line 873, in get_cluster_info
2025-01-21 04:05:49.225 25 ERROR cinder.volume.manager     status_code, cluster_info = self.cluster.send_cmd(
2025-01-21 04:05:49.225 25 ERROR cinder.volume.manager   File "/var/lib/kolla/venv/lib/python3.10/site-packages/cinder/volume/drivers/lightos.py", line 315, in send_cmd
2025-01-21 04:05:49.225 25 ERROR cinder.volume.manager     raise exception.VolumeDriverException(
2025-01-21 04:05:49.225 25 ERROR cinder.volume.manager cinder.exception.VolumeDriverException: Volume driver reported an error: Could not get a response from any API server
2025-01-21 04:05:49.225 25 ERROR cinder.volume.manager 
2025-01-21 04:05:50.229 25 INFO cinder.volume.manager [None req-571cc66b-a331-4771-8119-dcb3407556c2 - - - - - -] Starting volume driver LightOSVolumeDriver (2.3.12)
2025-01-21 04:05:50.230 25 INFO cinder.volume.drivers.lightos [None req-571cc66b-a331-4771-8119-dcb3407556c2 - - - - - -] Invoking get_cluster_info using GET url: /api/v2/clusterinfo             request.body: {} ssl_verify: False
2025-01-21 04:05:50.234 25 ERROR cinder.volume.drivers.lightos [None req-571cc66b-a331-4771-8119-dcb3407556c2 - - - - - -] REST server not responding at 'https://[LB_IP_ADDRESS]:443/api/v2/clusterinfo': requests.exceptions.ConnectionError: HTTPSConnectionPool(host='[LB_IP_ADDRESS]', port=443): Max retries exceeded with url: /api/v2/clusterinfo (Caused by NewConnectionError('<urllib3.connection.HTTPSConnection object at 0x7ffa58aa8820>: Failed to establish a new connection: [Errno 111] ECONNREFUSED'))
2025-01-21 04:05:50.234 25 ERROR cinder.volume.drivers.lightos Traceback (most recent call last):
2025-01-21 04:05:50.234 25 ERROR cinder.volume.drivers.lightos   File "/var/lib/kolla/venv/lib/python3.10/site-packages/urllib3/connection.py", line 174, in _new_conn
2025-01-21 04:05:50.234 25 ERROR cinder.volume.drivers.lightos     conn = connection.create_connection(
2025-01-21 04:05:50.234 25 ERROR cinder.volume.drivers.lightos   File "/var/lib/kolla/venv/lib/python3.10/site-packages/urllib3/util/connection.py", line 95, in create_connection
2025-01-21 04:05:50.234 25 ERROR cinder.volume.drivers.lightos     raise err
2025-01-21 04:05:50.234 25 ERROR cinder.volume.drivers.lightos   File "/var/lib/kolla/venv/lib/python3.10/site-packages/urllib3/util/connection.py", line 85, in create_connection
2025-01-21 04:05:50.234 25 ERROR cinder.volume.drivers.lightos     sock.connect(sa)
2025-01-21 04:05:50.234 25 ERROR cinder.volume.drivers.lightos   File "/var/lib/kolla/venv/lib/python3.10/site-packages/eventlet/greenio/base.py", line 265, in connect
2025-01-21 04:05:50.234 25 ERROR cinder.volume.drivers.lightos     socket_checkerr(fd)
2025-01-21 04:05:50.234 25 ERROR cinder.volume.drivers.lightos   File "/var/lib/kolla/venv/lib/python3.10/site-packages/eventlet/greenio/base.py", line 50, in socket_checkerr
2025-01-21 04:05:50.234 25 ERROR cinder.volume.drivers.lightos     raise OSError(err, errno.errorcode[err])
2025-01-21 04:05:50.234 25 ERROR cinder.volume.drivers.lightos ConnectionRefusedError: [Errno 111] ECONNREFUSED
2025-01-21 04:05:50.234 25 ERROR cinder.volume.drivers.lightos 
2025-01-21 04:05:50.234 25 ERROR cinder.volume.drivers.lightos During handling of the above exception, another exception occurred:
2025-01-21 04:05:50.234 25 ERROR cinder.volume.drivers.lightos 
2025-01-21 04:05:50.234 25 ERROR cinder.volume.drivers.lightos Traceback (most recent call last):
2025-01-21 04:05:50.234 25 ERROR cinder.volume.drivers.lightos   File "/var/lib/kolla/venv/lib/python3.10/site-packages/urllib3/connectionpool.py", line 715, in urlopen
2025-01-21 04:05:50.234 25 ERROR cinder.volume.drivers.lightos     httplib_response = self._make_request(
2025-01-21 04:05:50.234 25 ERROR cinder.volume.drivers.lightos   File "/var/lib/kolla/venv/lib/python3.10/site-packages/urllib3/connectionpool.py", line 404, in _make_request
2025-01-21 04:05:50.234 25 ERROR cinder.volume.drivers.lightos     self._validate_conn(conn)
2025-01-21 04:05:50.234 25 ERROR cinder.volume.drivers.lightos   File "/var/lib/kolla/venv/lib/python3.10/site-packages/urllib3/connectionpool.py", line 1060, in _validate_conn
2025-01-21 04:05:50.234 25 ERROR cinder.volume.drivers.lightos     conn.connect()
2025-01-21 04:05:50.234 25 ERROR cinder.volume.drivers.lightos   File "/var/lib/kolla/venv/lib/python3.10/site-packages/urllib3/connection.py", line 363, in connect
2025-01-21 04:05:50.234 25 ERROR cinder.volume.drivers.lightos     self.sock = conn = self._new_conn()
2025-01-21 04:05:50.234 25 ERROR cinder.volume.drivers.lightos   File "/var/lib/kolla/venv/lib/python3.10/site-packages/urllib3/connection.py", line 186, in _new_conn
2025-01-21 04:05:50.234 25 ERROR cinder.volume.drivers.lightos     raise NewConnectionError(
2025-01-21 04:05:50.234 25 ERROR cinder.volume.drivers.lightos urllib3.exceptions.NewConnectionError: <urllib3.connection.HTTPSConnection object at 0x7ffa58aa8820>: Failed to establish a new connection: [Errno 111] ECONNREFUSED
2025-01-21 04:05:50.234 25 ERROR cinder.volume.drivers.lightos 
2025-01-21 04:05:50.234 25 ERROR cinder.volume.drivers.lightos During handling of the above exception, another exception occurred:
2025-01-21 04:05:50.234 25 ERROR cinder.volume.drivers.lightos 
2025-01-21 04:05:50.234 25 ERROR cinder.volume.drivers.lightos Traceback (most recent call last):
2025-01-21 04:05:50.234 25 ERROR cinder.volume.drivers.lightos   File "/var/lib/kolla/venv/lib/python3.10/site-packages/requests/adapters.py", line 667, in send
2025-01-21 04:05:50.234 25 ERROR cinder.volume.drivers.lightos     resp = conn.urlopen(
2025-01-21 04:05:50.234 25 ERROR cinder.volume.drivers.lightos   File "/var/lib/kolla/venv/lib/python3.10/site-packages/urllib3/connectionpool.py", line 801, in urlopen
2025-01-21 04:05:50.234 25 ERROR cinder.volume.drivers.lightos     retries = retries.increment(
2025-01-21 04:05:50.234 25 ERROR cinder.volume.drivers.lightos   File "/var/lib/kolla/venv/lib/python3.10/site-packages/urllib3/util/retry.py", line 594, in increment
2025-01-21 04:05:50.234 25 ERROR cinder.volume.drivers.lightos     raise MaxRetryError(_pool, url, error or ResponseError(cause))
2025-01-21 04:05:50.234 25 ERROR cinder.volume.drivers.lightos urllib3.exceptions.MaxRetryError: HTTPSConnectionPool(host='[LB_IP_ADDRESS]', port=443): Max retries exceeded with url: /api/v2/clusterinfo (Caused by NewConnectionError('<urllib3.connection.HTTPSConnection object at 0x7ffa58aa8820>: Failed to establish a new connection: [Errno 111] ECONNREFUSED'))
2025-01-21 04:05:50.234 25 ERROR cinder.volume.drivers.lightos 
2025-01-21 04:05:50.234 25 ERROR cinder.volume.drivers.lightos During handling of the above exception, another exception occurred:
2025-01-21 04:05:50.234 25 ERROR cinder.volume.drivers.lightos 
2025-01-21 04:05:50.234 25 ERROR cinder.volume.drivers.lightos Traceback (most recent call last):
2025-01-21 04:05:50.234 25 ERROR cinder.volume.drivers.lightos   File "/var/lib/kolla/venv/lib/python3.10/site-packages/cinder/volume/drivers/lightos.py", line 356, in __send_cmd
2025-01-21 04:05:50.234 25 ERROR cinder.volume.drivers.lightos     response = session.send(
2025-01-21 04:05:50.234 25 ERROR cinder.volume.drivers.lightos   File "/var/lib/kolla/venv/lib/python3.10/site-packages/requests/sessions.py", line 703, in send
2025-01-21 04:05:50.234 25 ERROR cinder.volume.drivers.lightos     r = adapter.send(request, **kwargs)
2025-01-21 04:05:50.234 25 ERROR cinder.volume.drivers.lightos   File "/var/lib/kolla/venv/lib/python3.10/site-packages/requests/adapters.py", line 700, in send
2025-01-21 04:05:50.234 25 ERROR cinder.volume.drivers.lightos     raise ConnectionError(e, request=request)
2025-01-21 04:05:50.234 25 ERROR cinder.volume.drivers.lightos requests.exceptions.ConnectionError: HTTPSConnectionPool(host='[LB_IP_ADDRESS]', port=443): Max retries exceeded with url: /api/v2/clusterinfo (Caused by NewConnectionError('<urllib3.connection.HTTPSConnection object at 0x7ffa58aa8820>: Failed to establish a new connection: [Errno 111] ECONNREFUSED'))
2025-01-21 04:05:50.234 25 ERROR cinder.volume.drivers.lightos 
2025-01-21 04:05:50.236 25 INFO cinder.volume.drivers.lightos [None req-571cc66b-a331-4771-8119-dcb3407556c2 - - - - - -] Invoking get_cluster_info using GET url: /api/v2/clusterinfo             request.body: {} ssl_verify: False
2025-01-21 04:05:52.289 25 ERROR cinder.volume.drivers.lightos [None req-571cc66b-a331-4771-8119-dcb3407556c2 - - - - - -] REST server not responding at 'https://[LB_IP_ADDRESS]:443/api/v2/clusterinfo': requests.exceptions.ConnectionError: HTTPSConnectionPool(host='[LB_IP_ADDRESS]', port=443): Max retries exceeded with url: /api/v2/clusterinfo (Caused by NewConnectionError('<urllib3.connection.HTTPSConnection object at 0x7ffa58aa9270>: Failed to establish a new connection: [Errno 113] EHOSTUNREACH'))
2025-01-21 04:05:52.289 25 ERROR cinder.volume.drivers.lightos Traceback (most recent call last):
2025-01-21 04:05:52.289 25 ERROR cinder.volume.drivers.lightos   File "/var/lib/kolla/venv/lib/python3.10/site-packages/urllib3/connection.py", line 174, in _new_conn
2025-01-21 04:05:52.289 25 ERROR cinder.volume.drivers.lightos     conn = connection.create_connection(
2025-01-21 04:05:52.289 25 ERROR cinder.volume.drivers.lightos   File "/var/lib/kolla/venv/lib/python3.10/site-packages/urllib3/util/connection.py", line 95, in create_connection
2025-01-21 04:05:52.289 25 ERROR cinder.volume.drivers.lightos     raise err
2025-01-21 04:05:52.289 25 ERROR cinder.volume.drivers.lightos   File "/var/lib/kolla/venv/lib/python3.10/site-packages/urllib3/util/connection.py", line 85, in create_connection
2025-01-21 04:05:52.289 25 ERROR cinder.volume.drivers.lightos     sock.connect(sa)
2025-01-21 04:05:52.289 25 ERROR cinder.volume.drivers.lightos   File "/var/lib/kolla/venv/lib/python3.10/site-packages/eventlet/greenio/base.py", line 265, in connect
2025-01-21 04:05:52.289 25 ERROR cinder.volume.drivers.lightos     socket_checkerr(fd)
2025-01-21 04:05:52.289 25 ERROR cinder.volume.drivers.lightos   File "/var/lib/kolla/venv/lib/python3.10/site-packages/eventlet/greenio/base.py", line 50, in socket_checkerr
2025-01-21 04:05:52.289 25 ERROR cinder.volume.drivers.lightos     raise OSError(err, errno.errorcode[err])
2025-01-21 04:05:52.289 25 ERROR cinder.volume.drivers.lightos OSError: [Errno 113] EHOSTUNREACH
2025-01-21 04:05:52.289 25 ERROR cinder.volume.drivers.lightos 
2025-01-21 04:05:52.289 25 ERROR cinder.volume.drivers.lightos During handling of the above exception, another exception occurred:
2025-01-21 04:05:52.289 25 ERROR cinder.volume.drivers.lightos 
2025-01-21 04:05:52.289 25 ERROR cinder.volume.drivers.lightos Traceback (most recent call last):
2025-01-21 04:05:52.289 25 ERROR cinder.volume.drivers.lightos   File "/var/lib/kolla/venv/lib/python3.10/site-packages/urllib3/connectionpool.py", line 715, in urlopen
2025-01-21 04:05:52.289 25 ERROR cinder.volume.drivers.lightos     httplib_response = self._make_request(
2025-01-21 04:05:52.289 25 ERROR cinder.volume.drivers.lightos   File "/var/lib/kolla/venv/lib/python3.10/site-packages/urllib3/connectionpool.py", line 404, in _make_request
2025-01-21 04:05:52.289 25 ERROR cinder.volume.drivers.lightos     self._validate_conn(conn)
2025-01-21 04:05:52.289 25 ERROR cinder.volume.drivers.lightos   File "/var/lib/kolla/venv/lib/python3.10/site-packages/urllib3/connectionpool.py", line 1060, in _validate_conn
2025-01-21 04:05:52.289 25 ERROR cinder.volume.drivers.lightos     conn.connect()
2025-01-21 04:05:52.289 25 ERROR cinder.volume.drivers.lightos   File "/var/lib/kolla/venv/lib/python3.10/site-packages/urllib3/connection.py", line 363, in connect
2025-01-21 04:05:52.289 25 ERROR cinder.volume.drivers.lightos     self.sock = conn = self._new_conn()
2025-01-21 04:05:52.289 25 ERROR cinder.volume.drivers.lightos   File "/var/lib/kolla/venv/lib/python3.10/site-packages/urllib3/connection.py", line 186, in _new_conn
2025-01-21 04:05:52.289 25 ERROR cinder.volume.drivers.lightos     raise NewConnectionError(
2025-01-21 04:05:52.289 25 ERROR cinder.volume.drivers.lightos urllib3.exceptions.NewConnectionError: <urllib3.connection.HTTPSConnection object at 0x7ffa58aa9270>: Failed to establish a new connection: [Errno 113] EHOSTUNREACH
2025-01-21 04:05:52.289 25 ERROR cinder.volume.drivers.lightos 
2025-01-21 04:05:52.289 25 ERROR cinder.volume.drivers.lightos During handling of the above exception, another exception occurred:
2025-01-21 04:05:52.289 25 ERROR cinder.volume.drivers.lightos 
2025-01-21 04:05:52.289 25 ERROR cinder.volume.drivers.lightos Traceback (most recent call last):
2025-01-21 04:05:52.289 25 ERROR cinder.volume.drivers.lightos   File "/var/lib/kolla/venv/lib/python3.10/site-packages/requests/adapters.py", line 667, in send
2025-01-21 04:05:52.289 25 ERROR cinder.volume.drivers.lightos     resp = conn.urlopen(
2025-01-21 04:05:52.289 25 ERROR cinder.volume.drivers.lightos   File "/var/lib/kolla/venv/lib/python3.10/site-packages/urllib3/connectionpool.py", line 801, in urlopen
2025-01-21 04:05:52.289 25 ERROR cinder.volume.drivers.lightos     retries = retries.increment(
2025-01-21 04:05:52.289 25 ERROR cinder.volume.drivers.lightos   File "/var/lib/kolla/venv/lib/python3.10/site-packages/urllib3/util/retry.py", line 594, in increment
2025-01-21 04:05:52.289 25 ERROR cinder.volume.drivers.lightos     raise MaxRetryError(_pool, url, error or ResponseError(cause))
2025-01-21 04:05:52.289 25 ERROR cinder.volume.drivers.lightos urllib3.exceptions.MaxRetryError: HTTPSConnectionPool(host='[LB_IP_ADDRESS]', port=443): Max retries exceeded with url: /api/v2/clusterinfo (Caused by NewConnectionError('<urllib3.connection.HTTPSConnection object at 0x7ffa58aa9270>: Failed to establish a new connection: [Errno 113] EHOSTUNREACH'))
2025-01-21 04:05:52.289 25 ERROR cinder.volume.drivers.lightos 
2025-01-21 04:05:52.289 25 ERROR cinder.volume.drivers.lightos During handling of the above exception, another exception occurred:
2025-01-21 04:05:52.289 25 ERROR cinder.volume.drivers.lightos 
2025-01-21 04:05:52.289 25 ERROR cinder.volume.drivers.lightos Traceback (most recent call last):
2025-01-21 04:05:52.289 25 ERROR cinder.volume.drivers.lightos   File "/var/lib/kolla/venv/lib/python3.10/site-packages/cinder/volume/drivers/lightos.py", line 356, in __send_cmd
2025-01-21 04:05:52.289 25 ERROR cinder.volume.drivers.lightos     response = session.send(
2025-01-21 04:05:52.289 25 ERROR cinder.volume.drivers.lightos   File "/var/lib/kolla/venv/lib/python3.10/site-packages/requests/sessions.py", line 703, in send
2025-01-21 04:05:52.289 25 ERROR cinder.volume.drivers.lightos     r = adapter.send(request, **kwargs)
2025-01-21 04:05:52.289 25 ERROR cinder.volume.drivers.lightos   File "/var/lib/kolla/venv/lib/python3.10/site-packages/requests/adapters.py", line 700, in send
2025-01-21 04:05:52.289 25 ERROR cinder.volume.drivers.lightos     raise ConnectionError(e, request=request)
2025-01-21 04:05:52.289 25 ERROR cinder.volume.drivers.lightos requests.exceptions.ConnectionError: HTTPSConnectionPool(host='[LB_IP_ADDRESS]', port=443): Max retries exceeded with url: /api/v2/clusterinfo (Caused by NewConnectionError('<urllib3.connection.HTTPSConnection object at 0x7ffa58aa9270>: Failed to establish a new connection: [Errno 113] EHOSTUNREACH'))
2025-01-21 04:05:52.289 25 ERROR cinder.volume.drivers.lightos 
2025-01-21 04:05:52.292 25 INFO cinder.volume.drivers.lightos [None req-571cc66b-a331-4771-8119-dcb3407556c2 - - - - - -] Invoking get_cluster_info using GET url: /api/v2/clusterinfo             request.body: {} ssl_verify: False
2025-01-21 04:05:52.295 25 ERROR cinder.volume.drivers.lightos [None req-571cc66b-a331-4771-8119-dcb3407556c2 - - - - - -] REST server not responding at 'https://[LB_IP_ADDRESS]:443/api/v2/clusterinfo': requests.exceptions.ConnectionError: HTTPSConnectionPool(host='[LB_IP_ADDRESS]', port=443): Max retries exceeded with url: /api/v2/clusterinfo (Caused by NewConnectionError('<urllib3.connection.HTTPSConnection object at 0x7ffa58aaa2f0>: Failed to establish a new connection: [Errno 111] ECONNREFUSED'))
2025-01-21 04:05:52.295 25 ERROR cinder.volume.drivers.lightos Traceback (most recent call last):
2025-01-21 04:05:52.295 25 ERROR cinder.volume.drivers.lightos   File "/var/lib/kolla/venv/lib/python3.10/site-packages/urllib3/connection.py", line 174, in _new_conn
2025-01-21 04:05:52.295 25 ERROR cinder.volume.drivers.lightos     conn = connection.create_connection(
2025-01-21 04:05:52.295 25 ERROR cinder.volume.drivers.lightos   File "/var/lib/kolla/venv/lib/python3.10/site-packages/urllib3/util/connection.py", line 95, in create_connection
2025-01-21 04:05:52.295 25 ERROR cinder.volume.drivers.lightos     raise err
2025-01-21 04:05:52.295 25 ERROR cinder.volume.drivers.lightos   File "/var/lib/kolla/venv/lib/python3.10/site-packages/urllib3/util/connection.py", line 85, in create_connection
2025-01-21 04:05:52.295 25 ERROR cinder.volume.drivers.lightos     sock.connect(sa)
2025-01-21 04:05:52.295 25 ERROR cinder.volume.drivers.lightos   File "/var/lib/kolla/venv/lib/python3.10/site-packages/eventlet/greenio/base.py", line 265, in connect
2025-01-21 04:05:52.295 25 ERROR cinder.volume.drivers.lightos     socket_checkerr(fd)
2025-01-21 04:05:52.295 25 ERROR cinder.volume.drivers.lightos   File "/var/lib/kolla/venv/lib/python3.10/site-packages/eventlet/greenio/base.py", line 50, in socket_checkerr
2025-01-21 04:05:52.295 25 ERROR cinder.volume.drivers.lightos     raise OSError(err, errno.errorcode[err])
2025-01-21 04:05:52.295 25 ERROR cinder.volume.drivers.lightos ConnectionRefusedError: [Errno 111] ECONNREFUSED
2025-01-21 04:05:52.295 25 ERROR cinder.volume.drivers.lightos 
2025-01-21 04:05:52.295 25 ERROR cinder.volume.drivers.lightos During handling of the above exception, another exception occurred:
2025-01-21 04:05:52.295 25 ERROR cinder.volume.drivers.lightos 
2025-01-21 04:05:52.295 25 ERROR cinder.volume.drivers.lightos Traceback (most recent call last):
2025-01-21 04:05:52.295 25 ERROR cinder.volume.drivers.lightos   File "/var/lib/kolla/venv/lib/python3.10/site-packages/urllib3/connectionpool.py", line 715, in urlopen
2025-01-21 04:05:52.295 25 ERROR cinder.volume.drivers.lightos     httplib_response = self._make_request(
2025-01-21 04:05:52.295 25 ERROR cinder.volume.drivers.lightos   File "/var/lib/kolla/venv/lib/python3.10/site-packages/urllib3/connectionpool.py", line 404, in _make_request
2025-01-21 04:05:52.295 25 ERROR cinder.volume.drivers.lightos     self._validate_conn(conn)
2025-01-21 04:05:52.295 25 ERROR cinder.volume.drivers.lightos   File "/var/lib/kolla/venv/lib/python3.10/site-packages/urllib3/connectionpool.py", line 1060, in _validate_conn
2025-01-21 04:05:52.295 25 ERROR cinder.volume.drivers.lightos     conn.connect()
2025-01-21 04:05:52.295 25 ERROR cinder.volume.drivers.lightos   File "/var/lib/kolla/venv/lib/python3.10/site-packages/urllib3/connection.py", line 363, in connect
2025-01-21 04:05:52.295 25 ERROR cinder.volume.drivers.lightos     self.sock = conn = self._new_conn()
2025-01-21 04:05:52.295 25 ERROR cinder.volume.drivers.lightos   File "/var/lib/kolla/venv/lib/python3.10/site-packages/urllib3/connection.py", line 186, in _new_conn
2025-01-21 04:05:52.295 25 ERROR cinder.volume.drivers.lightos     raise NewConnectionError(
2025-01-21 04:05:52.295 25 ERROR cinder.volume.drivers.lightos urllib3.exceptions.NewConnectionError: <urllib3.connection.HTTPSConnection object at 0x7ffa58aaa2f0>: Failed to establish a new connection: [Errno 111] ECONNREFUSED
2025-01-21 04:05:52.295 25 ERROR cinder.volume.drivers.lightos 
2025-01-21 04:05:52.295 25 ERROR cinder.volume.drivers.lightos During handling of the above exception, another exception occurred:
2025-01-21 04:05:52.295 25 ERROR cinder.volume.drivers.lightos 
2025-01-21 04:05:52.295 25 ERROR cinder.volume.drivers.lightos Traceback (most recent call last):
2025-01-21 04:05:52.295 25 ERROR cinder.volume.drivers.lightos   File "/var/lib/kolla/venv/lib/python3.10/site-packages/requests/adapters.py", line 667, in send
2025-01-21 04:05:52.295 25 ERROR cinder.volume.drivers.lightos     resp = conn.urlopen(
2025-01-21 04:05:52.295 25 ERROR cinder.volume.drivers.lightos   File "/var/lib/kolla/venv/lib/python3.10/site-packages/urllib3/connectionpool.py", line 801, in urlopen
2025-01-21 04:05:52.295 25 ERROR cinder.volume.drivers.lightos     retries = retries.increment(
2025-01-21 04:05:52.295 25 ERROR cinder.volume.drivers.lightos   File "/var/lib/kolla/venv/lib/python3.10/site-packages/urllib3/util/retry.py", line 594, in increment
2025-01-21 04:05:52.295 25 ERROR cinder.volume.drivers.lightos     raise MaxRetryError(_pool, url, error or ResponseError(cause))
2025-01-21 04:05:52.295 25 ERROR cinder.volume.drivers.lightos urllib3.exceptions.MaxRetryError: HTTPSConnectionPool(host='[LB_IP_ADDRESS]', port=443): Max retries exceeded with url: /api/v2/clusterinfo (Caused by NewConnectionError('<urllib3.connection.HTTPSConnection object at 0x7ffa58aaa2f0>: Failed to establish a new connection: [Errno 111] ECONNREFUSED'))
2025-01-21 04:05:52.295 25 ERROR cinder.volume.drivers.lightos 
2025-01-21 04:05:52.295 25 ERROR cinder.volume.drivers.lightos During handling of the above exception, another exception occurred:
2025-01-21 04:05:52.295 25 ERROR cinder.volume.drivers.lightos 
2025-01-21 04:05:52.295 25 ERROR cinder.volume.drivers.lightos Traceback (most recent call last):
2025-01-21 04:05:52.295 25 ERROR cinder.volume.drivers.lightos   File "/var/lib/kolla/venv/lib/python3.10/site-packages/cinder/volume/drivers/lightos.py", line 356, in __send_cmd
2025-01-21 04:05:52.295 25 ERROR cinder.volume.drivers.lightos     response = session.send(
2025-01-21 04:05:52.295 25 ERROR cinder.volume.drivers.lightos   File "/var/lib/kolla/venv/lib/python3.10/site-packages/requests/sessions.py", line 703, in send
2025-01-21 04:05:52.295 25 ERROR cinder.volume.drivers.lightos     r = adapter.send(request, **kwargs)
2025-01-21 04:05:52.295 25 ERROR cinder.volume.drivers.lightos   File "/var/lib/kolla/venv/lib/python3.10/site-packages/requests/adapters.py", line 700, in send
2025-01-21 04:05:52.295 25 ERROR cinder.volume.drivers.lightos     raise ConnectionError(e, request=request)
2025-01-21 04:05:52.295 25 ERROR cinder.volume.drivers.lightos requests.exceptions.ConnectionError: HTTPSConnectionPool(host='[LB_IP_ADDRESS]', port=443): Max retries exceeded with url: /api/v2/clusterinfo (Caused by NewConnectionError('<urllib3.connection.HTTPSConnection object at 0x7ffa58aaa2f0>: Failed to establish a new connection: [Errno 111] ECONNREFUSED'))
2025-01-21 04:05:52.295 25 ERROR cinder.volume.drivers.lightos 
2025-01-21 04:05:52.297 25 ERROR cinder.volume.manager [None req-571cc66b-a331-4771-8119-dcb3407556c2 - - - - - -] Failed to initialize driver.: cinder.exception.VolumeDriverException: Volume driver reported an error: Could not get a response from any API server
2025-01-21 04:05:52.297 25 ERROR cinder.volume.manager Traceback (most recent call last):
2025-01-21 04:05:52.297 25 ERROR cinder.volume.manager   File "/var/lib/kolla/venv/lib/python3.10/site-packages/cinder/volume/manager.py", line 523, in _init_host
2025-01-21 04:05:52.297 25 ERROR cinder.volume.manager     self.driver.do_setup(ctxt)
2025-01-21 04:05:52.297 25 ERROR cinder.volume.manager   File "/var/lib/kolla/venv/lib/python3.10/site-packages/cinder/volume/drivers/lightos.py", line 922, in do_setup
2025-01-21 04:05:52.297 25 ERROR cinder.volume.manager     self.get_cluster_info()
2025-01-21 04:05:52.297 25 ERROR cinder.volume.manager   File "/var/lib/kolla/venv/lib/python3.10/site-packages/cinder/volume/drivers/lightos.py", line 873, in get_cluster_info
2025-01-21 04:05:52.297 25 ERROR cinder.volume.manager     status_code, cluster_info = self.cluster.send_cmd(
2025-01-21 04:05:52.297 25 ERROR cinder.volume.manager   File "/var/lib/kolla/venv/lib/python3.10/site-packages/cinder/volume/drivers/lightos.py", line 315, in send_cmd
2025-01-21 04:05:52.297 25 ERROR cinder.volume.manager     raise exception.VolumeDriverException(
2025-01-21 04:05:52.297 25 ERROR cinder.volume.manager cinder.exception.VolumeDriverException: Volume driver reported an error: Could not get a response from any API server
2025-01-21 04:05:52.297 25 ERROR cinder.volume.manager 
2025-01-21 04:05:54.300 25 INFO cinder.volume.manager [None req-571cc66b-a331-4771-8119-dcb3407556c2 - - - - - -] Starting volume driver LightOSVolumeDriver (2.3.12)
2025-01-21 04:05:54.301 25 INFO cinder.volume.drivers.lightos [None req-571cc66b-a331-4771-8119-dcb3407556c2 - - - - - -] Invoking get_cluster_info using GET url: /api/v2/clusterinfo             request.body: {} ssl_verify: False
2025-01-21 04:05:54.304 25 ERROR cinder.volume.drivers.lightos [None req-571cc66b-a331-4771-8119-dcb3407556c2 - - - - - -] REST server not responding at 'https://[LB_IP_ADDRESS]:443/api/v2/clusterinfo': requests.exceptions.ConnectionError: HTTPSConnectionPool(host='[LB_IP_ADDRESS]', port=443): Max retries exceeded with url: /api/v2/clusterinfo (Caused by NewConnectionError('<urllib3.connection.HTTPSConnection object at 0x7ffa588407f0>: Failed to establish a new connection: [Errno 111] ECONNREFUSED'))
2025-01-21 04:05:54.304 25 ERROR cinder.volume.drivers.lightos Traceback (most recent call last):
2025-01-21 04:05:54.304 25 ERROR cinder.volume.drivers.lightos   File "/var/lib/kolla/venv/lib/python3.10/site-packages/urllib3/connection.py", line 174, in _new_conn
2025-01-21 04:05:54.304 25 ERROR cinder.volume.drivers.lightos     conn = connection.create_connection(
2025-01-21 04:05:54.304 25 ERROR cinder.volume.drivers.lightos   File "/var/lib/kolla/venv/lib/python3.10/site-packages/urllib3/util/connection.py", line 95, in create_connection
2025-01-21 04:05:54.304 25 ERROR cinder.volume.drivers.lightos     raise err
2025-01-21 04:05:54.304 25 ERROR cinder.volume.drivers.lightos   File "/var/lib/kolla/venv/lib/python3.10/site-packages/urllib3/util/connection.py", line 85, in create_connection
2025-01-21 04:05:54.304 25 ERROR cinder.volume.drivers.lightos     sock.connect(sa)
2025-01-21 04:05:54.304 25 ERROR cinder.volume.drivers.lightos   File "/var/lib/kolla/venv/lib/python3.10/site-packages/eventlet/greenio/base.py", line 265, in connect
2025-01-21 04:05:54.304 25 ERROR cinder.volume.drivers.lightos     socket_checkerr(fd)
2025-01-21 04:05:54.304 25 ERROR cinder.volume.drivers.lightos   File "/var/lib/kolla/venv/lib/python3.10/site-packages/eventlet/greenio/base.py", line 50, in socket_checkerr
2025-01-21 04:05:54.304 25 ERROR cinder.volume.drivers.lightos     raise OSError(err, errno.errorcode[err])
2025-01-21 04:05:54.304 25 ERROR cinder.volume.drivers.lightos ConnectionRefusedError: [Errno 111] ECONNREFUSED
2025-01-21 04:05:54.304 25 ERROR cinder.volume.drivers.lightos 
2025-01-21 04:05:54.304 25 ERROR cinder.volume.drivers.lightos During handling of the above exception, another exception occurred:
2025-01-21 04:05:54.304 25 ERROR cinder.volume.drivers.lightos 
2025-01-21 04:05:54.304 25 ERROR cinder.volume.drivers.lightos Traceback (most recent call last):
2025-01-21 04:05:54.304 25 ERROR cinder.volume.drivers.lightos   File "/var/lib/kolla/venv/lib/python3.10/site-packages/urllib3/connectionpool.py", line 715, in urlopen
2025-01-21 04:05:54.304 25 ERROR cinder.volume.drivers.lightos     httplib_response = self._make_request(
2025-01-21 04:05:54.304 25 ERROR cinder.volume.drivers.lightos   File "/var/lib/kolla/venv/lib/python3.10/site-packages/urllib3/connectionpool.py", line 404, in _make_request
2025-01-21 04:05:54.304 25 ERROR cinder.volume.drivers.lightos     self._validate_conn(conn)
2025-01-21 04:05:54.304 25 ERROR cinder.volume.drivers.lightos   File "/var/lib/kolla/venv/lib/python3.10/site-packages/urllib3/connectionpool.py", line 1060, in _validate_conn
2025-01-21 04:05:54.304 25 ERROR cinder.volume.drivers.lightos     conn.connect()
2025-01-21 04:05:54.304 25 ERROR cinder.volume.drivers.lightos   File "/var/lib/kolla/venv/lib/python3.10/site-packages/urllib3/connection.py", line 363, in connect
2025-01-21 04:05:54.304 25 ERROR cinder.volume.drivers.lightos     self.sock = conn = self._new_conn()
2025-01-21 04:05:54.304 25 ERROR cinder.volume.drivers.lightos   File "/var/lib/kolla/venv/lib/python3.10/site-packages/urllib3/connection.py", line 186, in _new_conn
2025-01-21 04:05:54.304 25 ERROR cinder.volume.drivers.lightos     raise NewConnectionError(
2025-01-21 04:05:54.304 25 ERROR cinder.volume.drivers.lightos urllib3.exceptions.NewConnectionError: <urllib3.connection.HTTPSConnection object at 0x7ffa588407f0>: Failed to establish a new connection: [Errno 111] ECONNREFUSED
2025-01-21 04:05:54.304 25 ERROR cinder.volume.drivers.lightos 
2025-01-21 04:05:54.304 25 ERROR cinder.volume.drivers.lightos During handling of the above exception, another exception occurred:
2025-01-21 04:05:54.304 25 ERROR cinder.volume.drivers.lightos 
2025-01-21 04:05:54.304 25 ERROR cinder.volume.drivers.lightos Traceback (most recent call last):
2025-01-21 04:05:54.304 25 ERROR cinder.volume.drivers.lightos   File "/var/lib/kolla/venv/lib/python3.10/site-packages/requests/adapters.py", line 667, in send
2025-01-21 04:05:54.304 25 ERROR cinder.volume.drivers.lightos     resp = conn.urlopen(
2025-01-21 04:05:54.304 25 ERROR cinder.volume.drivers.lightos   File "/var/lib/kolla/venv/lib/python3.10/site-packages/urllib3/connectionpool.py", line 801, in urlopen
2025-01-21 04:05:54.304 25 ERROR cinder.volume.drivers.lightos     retries = retries.increment(
2025-01-21 04:05:54.304 25 ERROR cinder.volume.drivers.lightos   File "/var/lib/kolla/venv/lib/python3.10/site-packages/urllib3/util/retry.py", line 594, in increment
2025-01-21 04:05:54.304 25 ERROR cinder.volume.drivers.lightos     raise MaxRetryError(_pool, url, error or ResponseError(cause))
2025-01-21 04:05:54.304 25 ERROR cinder.volume.drivers.lightos urllib3.exceptions.MaxRetryError: HTTPSConnectionPool(host='[LB_IP_ADDRESS]', port=443): Max retries exceeded with url: /api/v2/clusterinfo (Caused by NewConnectionError('<urllib3.connection.HTTPSConnection object at 0x7ffa588407f0>: Failed to establish a new connection: [Errno 111] ECONNREFUSED'))
2025-01-21 04:05:54.304 25 ERROR cinder.volume.drivers.lightos 
2025-01-21 04:05:54.304 25 ERROR cinder.volume.drivers.lightos During handling of the above exception, another exception occurred:
2025-01-21 04:05:54.304 25 ERROR cinder.volume.drivers.lightos 
2025-01-21 04:05:54.304 25 ERROR cinder.volume.drivers.lightos Traceback (most recent call last):
2025-01-21 04:05:54.304 25 ERROR cinder.volume.drivers.lightos   File "/var/lib/kolla/venv/lib/python3.10/site-packages/cinder/volume/drivers/lightos.py", line 356, in __send_cmd
2025-01-21 04:05:54.304 25 ERROR cinder.volume.drivers.lightos     response = session.send(
2025-01-21 04:05:54.304 25 ERROR cinder.volume.drivers.lightos   File "/var/lib/kolla/venv/lib/python3.10/site-packages/requests/sessions.py", line 703, in send
2025-01-21 04:05:54.304 25 ERROR cinder.volume.drivers.lightos     r = adapter.send(request, **kwargs)
2025-01-21 04:05:54.304 25 ERROR cinder.volume.drivers.lightos   File "/var/lib/kolla/venv/lib/python3.10/site-packages/requests/adapters.py", line 700, in send
2025-01-21 04:05:54.304 25 ERROR cinder.volume.drivers.lightos     raise ConnectionError(e, request=request)
2025-01-21 04:05:54.304 25 ERROR cinder.volume.drivers.lightos requests.exceptions.ConnectionError: HTTPSConnectionPool(host='[LB_IP_ADDRESS]', port=443): Max retries exceeded with url: /api/v2/clusterinfo (Caused by NewConnectionError('<urllib3.connection.HTTPSConnection object at 0x7ffa588407f0>: Failed to establish a new connection: [Errno 111] ECONNREFUSED'))
2025-01-21 04:05:54.304 25 ERROR cinder.volume.drivers.lightos 
2025-01-21 04:05:54.306 25 INFO cinder.volume.drivers.lightos [None req-571cc66b-a331-4771-8119-dcb3407556c2 - - - - - -] Invoking get_cluster_info using GET url: /api/v2/clusterinfo             request.body: {} ssl_verify: False
2025-01-21 04:05:55.361 25 ERROR cinder.volume.drivers.lightos [None req-571cc66b-a331-4771-8119-dcb3407556c2 - - - - - -] REST server not responding at 'https://[LB_IP_ADDRESS]:443/api/v2/clusterinfo': requests.exceptions.ConnectionError: HTTPSConnectionPool(host='[LB_IP_ADDRESS]', port=443): Max retries exceeded with url: /api/v2/clusterinfo (Caused by NewConnectionError('<urllib3.connection.HTTPSConnection object at 0x7ffa588412d0>: Failed to establish a new connection: [Errno 113] EHOSTUNREACH'))
2025-01-21 04:05:55.361 25 ERROR cinder.volume.drivers.lightos Traceback (most recent call last):
2025-01-21 04:05:55.361 25 ERROR cinder.volume.drivers.lightos   File "/var/lib/kolla/venv/lib/python3.10/site-packages/urllib3/connection.py", line 174, in _new_conn
2025-01-21 04:05:55.361 25 ERROR cinder.volume.drivers.lightos     conn = connection.create_connection(
2025-01-21 04:05:55.361 25 ERROR cinder.volume.drivers.lightos   File "/var/lib/kolla/venv/lib/python3.10/site-packages/urllib3/util/connection.py", line 95, in create_connection
2025-01-21 04:05:55.361 25 ERROR cinder.volume.drivers.lightos     raise err
2025-01-21 04:05:55.361 25 ERROR cinder.volume.drivers.lightos   File "/var/lib/kolla/venv/lib/python3.10/site-packages/urllib3/util/connection.py", line 85, in create_connection
2025-01-21 04:05:55.361 25 ERROR cinder.volume.drivers.lightos     sock.connect(sa)
2025-01-21 04:05:55.361 25 ERROR cinder.volume.drivers.lightos   File "/var/lib/kolla/venv/lib/python3.10/site-packages/eventlet/greenio/base.py", line 265, in connect
2025-01-21 04:05:55.361 25 ERROR cinder.volume.drivers.lightos     socket_checkerr(fd)
2025-01-21 04:05:55.361 25 ERROR cinder.volume.drivers.lightos   File "/var/lib/kolla/venv/lib/python3.10/site-packages/eventlet/greenio/base.py", line 50, in socket_checkerr
2025-01-21 04:05:55.361 25 ERROR cinder.volume.drivers.lightos     raise OSError(err, errno.errorcode[err])
2025-01-21 04:05:55.361 25 ERROR cinder.volume.drivers.lightos OSError: [Errno 113] EHOSTUNREACH
2025-01-21 04:05:55.361 25 ERROR cinder.volume.drivers.lightos 
2025-01-21 04:05:55.361 25 ERROR cinder.volume.drivers.lightos During handling of the above exception, another exception occurred:
2025-01-21 04:05:55.361 25 ERROR cinder.volume.drivers.lightos 
2025-01-21 04:05:55.361 25 ERROR cinder.volume.drivers.lightos Traceback (most recent call last):
2025-01-21 04:05:55.361 25 ERROR cinder.volume.drivers.lightos   File "/var/lib/kolla/venv/lib/python3.10/site-packages/urllib3/connectionpool.py", line 715, in urlopen
2025-01-21 04:05:55.361 25 ERROR cinder.volume.drivers.lightos     httplib_response = self._make_request(
2025-01-21 04:05:55.361 25 ERROR cinder.volume.drivers.lightos   File "/var/lib/kolla/venv/lib/python3.10/site-packages/urllib3/connectionpool.py", line 404, in _make_request
2025-01-21 04:05:55.361 25 ERROR cinder.volume.drivers.lightos     self._validate_conn(conn)
2025-01-21 04:05:55.361 25 ERROR cinder.volume.drivers.lightos   File "/var/lib/kolla/venv/lib/python3.10/site-packages/urllib3/connectionpool.py", line 1060, in _validate_conn
2025-01-21 04:05:55.361 25 ERROR cinder.volume.drivers.lightos     conn.connect()
2025-01-21 04:05:55.361 25 ERROR cinder.volume.drivers.lightos   File "/var/lib/kolla/venv/lib/python3.10/site-packages/urllib3/connection.py", line 363, in connect
2025-01-21 04:05:55.361 25 ERROR cinder.volume.drivers.lightos     self.sock = conn = self._new_conn()
2025-01-21 04:05:55.361 25 ERROR cinder.volume.drivers.lightos   File "/var/lib/kolla/venv/lib/python3.10/site-packages/urllib3/connection.py", line 186, in _new_conn
2025-01-21 04:05:55.361 25 ERROR cinder.volume.drivers.lightos     raise NewConnectionError(
2025-01-21 04:05:55.361 25 ERROR cinder.volume.drivers.lightos urllib3.exceptions.NewConnectionError: <urllib3.connection.HTTPSConnection object at 0x7ffa588412d0>: Failed to establish a new connection: [Errno 113] EHOSTUNREACH
2025-01-21 04:05:55.361 25 ERROR cinder.volume.drivers.lightos 
2025-01-21 04:05:55.361 25 ERROR cinder.volume.drivers.lightos During handling of the above exception, another exception occurred:
2025-01-21 04:05:55.361 25 ERROR cinder.volume.drivers.lightos 
2025-01-21 04:05:55.361 25 ERROR cinder.volume.drivers.lightos Traceback (most recent call last):
2025-01-21 04:05:55.361 25 ERROR cinder.volume.drivers.lightos   File "/var/lib/kolla/venv/lib/python3.10/site-packages/requests/adapters.py", line 667, in send
2025-01-21 04:05:55.361 25 ERROR cinder.volume.drivers.lightos     resp = conn.urlopen(
2025-01-21 04:05:55.361 25 ERROR cinder.volume.drivers.lightos   File "/var/lib/kolla/venv/lib/python3.10/site-packages/urllib3/connectionpool.py", line 801, in urlopen
2025-01-21 04:05:55.361 25 ERROR cinder.volume.drivers.lightos     retries = retries.increment(
2025-01-21 04:05:55.361 25 ERROR cinder.volume.drivers.lightos   File "/var/lib/kolla/venv/lib/python3.10/site-packages/urllib3/util/retry.py", line 594, in increment
2025-01-21 04:05:55.361 25 ERROR cinder.volume.drivers.lightos     raise MaxRetryError(_pool, url, error or ResponseError(cause))
2025-01-21 04:05:55.361 25 ERROR cinder.volume.drivers.lightos urllib3.exceptions.MaxRetryError: HTTPSConnectionPool(host='[LB_IP_ADDRESS]', port=443): Max retries exceeded with url: /api/v2/clusterinfo (Caused by NewConnectionError('<urllib3.connection.HTTPSConnection object at 0x7ffa588412d0>: Failed to establish a new connection: [Errno 113] EHOSTUNREACH'))
2025-01-21 04:05:55.361 25 ERROR cinder.volume.drivers.lightos 
2025-01-21 04:05:55.361 25 ERROR cinder.volume.drivers.lightos During handling of the above exception, another exception occurred:
2025-01-21 04:05:55.361 25 ERROR cinder.volume.drivers.lightos 
2025-01-21 04:05:55.361 25 ERROR cinder.volume.drivers.lightos Traceback (most recent call last):
2025-01-21 04:05:55.361 25 ERROR cinder.volume.drivers.lightos   File "/var/lib/kolla/venv/lib/python3.10/site-packages/cinder/volume/drivers/lightos.py", line 356, in __send_cmd
2025-01-21 04:05:55.361 25 ERROR cinder.volume.drivers.lightos     response = session.send(
2025-01-21 04:05:55.361 25 ERROR cinder.volume.drivers.lightos   File "/var/lib/kolla/venv/lib/python3.10/site-packages/requests/sessions.py", line 703, in send
2025-01-21 04:05:55.361 25 ERROR cinder.volume.drivers.lightos     r = adapter.send(request, **kwargs)
2025-01-21 04:05:55.361 25 ERROR cinder.volume.drivers.lightos   File "/var/lib/kolla/venv/lib/python3.10/site-packages/requests/adapters.py", line 700, in send
2025-01-21 04:05:55.361 25 ERROR cinder.volume.drivers.lightos     raise ConnectionError(e, request=request)
2025-01-21 04:05:55.361 25 ERROR cinder.volume.drivers.lightos requests.exceptions.ConnectionError: HTTPSConnectionPool(host='[LB_IP_ADDRESS]', port=443): Max retries exceeded with url: /api/v2/clusterinfo (Caused by NewConnectionError('<urllib3.connection.HTTPSConnection object at 0x7ffa588412d0>: Failed to establish a new connection: [Errno 113] EHOSTUNREACH'))
2025-01-21 04:05:55.361 25 ERROR cinder.volume.drivers.lightos 
2025-01-21 04:05:55.365 25 INFO cinder.volume.drivers.lightos [None req-571cc66b-a331-4771-8119-dcb3407556c2 - - - - - -] Invoking get_cluster_info using GET url: /api/v2/clusterinfo             request.body: {} ssl_verify: False
2025-01-21 04:05:55.368 25 ERROR cinder.volume.drivers.lightos [None req-571cc66b-a331-4771-8119-dcb3407556c2 - - - - - -] REST server not responding at 'https://[LB_IP_ADDRESS]:443/api/v2/clusterinfo': requests.exceptions.ConnectionError: HTTPSConnectionPool(host='[LB_IP_ADDRESS]', port=443): Max retries exceeded with url: /api/v2/clusterinfo (Caused by NewConnectionError('<urllib3.connection.HTTPSConnection object at 0x7ffa58aaa1a0>: Failed to establish a new connection: [Errno 111] ECONNREFUSED'))
2025-01-21 04:05:55.368 25 ERROR cinder.volume.drivers.lightos Traceback (most recent call last):
2025-01-21 04:05:55.368 25 ERROR cinder.volume.drivers.lightos   File "/var/lib/kolla/venv/lib/python3.10/site-packages/urllib3/connection.py", line 174, in _new_conn
2025-01-21 04:05:55.368 25 ERROR cinder.volume.drivers.lightos     conn = connection.create_connection(
2025-01-21 04:05:55.368 25 ERROR cinder.volume.drivers.lightos   File "/var/lib/kolla/venv/lib/python3.10/site-packages/urllib3/util/connection.py", line 95, in create_connection
2025-01-21 04:05:55.368 25 ERROR cinder.volume.drivers.lightos     raise err
2025-01-21 04:05:55.368 25 ERROR cinder.volume.drivers.lightos   File "/var/lib/kolla/venv/lib/python3.10/site-packages/urllib3/util/connection.py", line 85, in create_connection
2025-01-21 04:05:55.368 25 ERROR cinder.volume.drivers.lightos     sock.connect(sa)
2025-01-21 04:05:55.368 25 ERROR cinder.volume.drivers.lightos   File "/var/lib/kolla/venv/lib/python3.10/site-packages/eventlet/greenio/base.py", line 265, in connect
2025-01-21 04:05:55.368 25 ERROR cinder.volume.drivers.lightos     socket_checkerr(fd)
2025-01-21 04:05:55.368 25 ERROR cinder.volume.drivers.lightos   File "/var/lib/kolla/venv/lib/python3.10/site-packages/eventlet/greenio/base.py", line 50, in socket_checkerr
2025-01-21 04:05:55.368 25 ERROR cinder.volume.drivers.lightos     raise OSError(err, errno.errorcode[err])
2025-01-21 04:05:55.368 25 ERROR cinder.volume.drivers.lightos ConnectionRefusedError: [Errno 111] ECONNREFUSED
2025-01-21 04:05:55.368 25 ERROR cinder.volume.drivers.lightos 
2025-01-21 04:05:55.368 25 ERROR cinder.volume.drivers.lightos During handling of the above exception, another exception occurred:
2025-01-21 04:05:55.368 25 ERROR cinder.volume.drivers.lightos 
2025-01-21 04:05:55.368 25 ERROR cinder.volume.drivers.lightos Traceback (most recent call last):
2025-01-21 04:05:55.368 25 ERROR cinder.volume.drivers.lightos   File "/var/lib/kolla/venv/lib/python3.10/site-packages/urllib3/connectionpool.py", line 715, in urlopen
2025-01-21 04:05:55.368 25 ERROR cinder.volume.drivers.lightos     httplib_response = self._make_request(
2025-01-21 04:05:55.368 25 ERROR cinder.volume.drivers.lightos   File "/var/lib/kolla/venv/lib/python3.10/site-packages/urllib3/connectionpool.py", line 404, in _make_request
2025-01-21 04:05:55.368 25 ERROR cinder.volume.drivers.lightos     self._validate_conn(conn)
2025-01-21 04:05:55.368 25 ERROR cinder.volume.drivers.lightos   File "/var/lib/kolla/venv/lib/python3.10/site-packages/urllib3/connectionpool.py", line 1060, in _validate_conn
2025-01-21 04:05:55.368 25 ERROR cinder.volume.drivers.lightos     conn.connect()
2025-01-21 04:05:55.368 25 ERROR cinder.volume.drivers.lightos   File "/var/lib/kolla/venv/lib/python3.10/site-packages/urllib3/connection.py", line 363, in connect
2025-01-21 04:05:55.368 25 ERROR cinder.volume.drivers.lightos     self.sock = conn = self._new_conn()
2025-01-21 04:05:55.368 25 ERROR cinder.volume.drivers.lightos   File "/var/lib/kolla/venv/lib/python3.10/site-packages/urllib3/connection.py", line 186, in _new_conn
2025-01-21 04:05:55.368 25 ERROR cinder.volume.drivers.lightos     raise NewConnectionError(
2025-01-21 04:05:55.368 25 ERROR cinder.volume.drivers.lightos urllib3.exceptions.NewConnectionError: <urllib3.connection.HTTPSConnection object at 0x7ffa58aaa1a0>: Failed to establish a new connection: [Errno 111] ECONNREFUSED
2025-01-21 04:05:55.368 25 ERROR cinder.volume.drivers.lightos 
2025-01-21 04:05:55.368 25 ERROR cinder.volume.drivers.lightos During handling of the above exception, another exception occurred:
2025-01-21 04:05:55.368 25 ERROR cinder.volume.drivers.lightos 
2025-01-21 04:05:55.368 25 ERROR cinder.volume.drivers.lightos Traceback (most recent call last):
2025-01-21 04:05:55.368 25 ERROR cinder.volume.drivers.lightos   File "/var/lib/kolla/venv/lib/python3.10/site-packages/requests/adapters.py", line 667, in send
2025-01-21 04:05:55.368 25 ERROR cinder.volume.drivers.lightos     resp = conn.urlopen(
2025-01-21 04:05:55.368 25 ERROR cinder.volume.drivers.lightos   File "/var/lib/kolla/venv/lib/python3.10/site-packages/urllib3/connectionpool.py", line 801, in urlopen
2025-01-21 04:05:55.368 25 ERROR cinder.volume.drivers.lightos     retries = retries.increment(
2025-01-21 04:05:55.368 25 ERROR cinder.volume.drivers.lightos   File "/var/lib/kolla/venv/lib/python3.10/site-packages/urllib3/util/retry.py", line 594, in increment
2025-01-21 04:05:55.368 25 ERROR cinder.volume.drivers.lightos     raise MaxRetryError(_pool, url, error or ResponseError(cause))
2025-01-21 04:05:55.368 25 ERROR cinder.volume.drivers.lightos urllib3.exceptions.MaxRetryError: HTTPSConnectionPool(host='[LB_IP_ADDRESS]', port=443): Max retries exceeded with url: /api/v2/clusterinfo (Caused by NewConnectionError('<urllib3.connection.HTTPSConnection object at 0x7ffa58aaa1a0>: Failed to establish a new connection: [Errno 111] ECONNREFUSED'))
2025-01-21 04:05:55.368 25 ERROR cinder.volume.drivers.lightos 
2025-01-21 04:05:55.368 25 ERROR cinder.volume.drivers.lightos During handling of the above exception, another exception occurred:
2025-01-21 04:05:55.368 25 ERROR cinder.volume.drivers.lightos 
2025-01-21 04:05:55.368 25 ERROR cinder.volume.drivers.lightos Traceback (most recent call last):
2025-01-21 04:05:55.368 25 ERROR cinder.volume.drivers.lightos   File "/var/lib/kolla/venv/lib/python3.10/site-packages/cinder/volume/drivers/lightos.py", line 356, in __send_cmd
2025-01-21 04:05:55.368 25 ERROR cinder.volume.drivers.lightos     response = session.send(
2025-01-21 04:05:55.368 25 ERROR cinder.volume.drivers.lightos   File "/var/lib/kolla/venv/lib/python3.10/site-packages/requests/sessions.py", line 703, in send
2025-01-21 04:05:55.368 25 ERROR cinder.volume.drivers.lightos     r = adapter.send(request, **kwargs)
2025-01-21 04:05:55.368 25 ERROR cinder.volume.drivers.lightos   File "/var/lib/kolla/venv/lib/python3.10/site-packages/requests/adapters.py", line 700, in send
2025-01-21 04:05:55.368 25 ERROR cinder.volume.drivers.lightos     raise ConnectionError(e, request=request)
2025-01-21 04:05:55.368 25 ERROR cinder.volume.drivers.lightos requests.exceptions.ConnectionError: HTTPSConnectionPool(host='[LB_IP_ADDRESS]', port=443): Max retries exceeded with url: /api/v2/clusterinfo (Caused by NewConnectionError('<urllib3.connection.HTTPSConnection object at 0x7ffa58aaa1a0>: Failed to establish a new connection: [Errno 111] ECONNREFUSED'))
2025-01-21 04:05:55.368 25 ERROR cinder.volume.drivers.lightos 
2025-01-21 04:05:55.369 25 ERROR cinder.volume.manager [None req-571cc66b-a331-4771-8119-dcb3407556c2 - - - - - -] Failed to initialize driver.: cinder.exception.VolumeDriverException: Volume driver reported an error: Could not get a response from any API server
2025-01-21 04:05:55.369 25 ERROR cinder.volume.manager Traceback (most recent call last):
2025-01-21 04:05:55.369 25 ERROR cinder.volume.manager   File "/var/lib/kolla/venv/lib/python3.10/site-packages/cinder/volume/manager.py", line 523, in _init_host
2025-01-21 04:05:55.369 25 ERROR cinder.volume.manager     self.driver.do_setup(ctxt)
2025-01-21 04:05:55.369 25 ERROR cinder.volume.manager   File "/var/lib/kolla/venv/lib/python3.10/site-packages/cinder/volume/drivers/lightos.py", line 922, in do_setup
2025-01-21 04:05:55.369 25 ERROR cinder.volume.manager     self.get_cluster_info()
2025-01-21 04:05:55.369 25 ERROR cinder.volume.manager   File "/var/lib/kolla/venv/lib/python3.10/site-packages/cinder/volume/drivers/lightos.py", line 873, in get_cluster_info
2025-01-21 04:05:55.369 25 ERROR cinder.volume.manager     status_code, cluster_info = self.cluster.send_cmd(
2025-01-21 04:05:55.369 25 ERROR cinder.volume.manager   File "/var/lib/kolla/venv/lib/python3.10/site-packages/cinder/volume/drivers/lightos.py", line 315, in send_cmd
2025-01-21 04:05:55.369 25 ERROR cinder.volume.manager     raise exception.VolumeDriverException(
2025-01-21 04:05:55.369 25 ERROR cinder.volume.manager cinder.exception.VolumeDriverException: Volume driver reported an error: Could not get a response from any API server
2025-01-21 04:05:55.369 25 ERROR cinder.volume.manager 
2025-01-21 04:05:59.374 25 INFO cinder.volume.manager [None req-571cc66b-a331-4771-8119-dcb3407556c2 - - - - - -] Starting volume driver LightOSVolumeDriver (2.3.12)
2025-01-21 04:05:59.375 25 INFO cinder.volume.drivers.lightos [None req-571cc66b-a331-4771-8119-dcb3407556c2 - - - - - -] Invoking get_cluster_info using GET url: /api/v2/clusterinfo             request.body: {} ssl_verify: False
2025-01-21 04:05:59.383 25 ERROR cinder.volume.drivers.lightos [None req-571cc66b-a331-4771-8119-dcb3407556c2 - - - - - -] REST server not responding at 'https://[LB_IP_ADDRESS]:443/api/v2/clusterinfo': requests.exceptions.ConnectionError: HTTPSConnectionPool(host='[LB_IP_ADDRESS]', port=443): Max retries exceeded with url: /api/v2/clusterinfo (Caused by NewConnectionError('<urllib3.connection.HTTPSConnection object at 0x7ffa58aa8ac0>: Failed to establish a new connection: [Errno 111] ECONNREFUSED'))
2025-01-21 04:05:59.383 25 ERROR cinder.volume.drivers.lightos Traceback (most recent call last):
2025-01-21 04:05:59.383 25 ERROR cinder.volume.drivers.lightos   File "/var/lib/kolla/venv/lib/python3.10/site-packages/urllib3/connection.py", line 174, in _new_conn
2025-01-21 04:05:59.383 25 ERROR cinder.volume.drivers.lightos     conn = connection.create_connection(
2025-01-21 04:05:59.383 25 ERROR cinder.volume.drivers.lightos   File "/var/lib/kolla/venv/lib/python3.10/site-packages/urllib3/util/connection.py", line 95, in create_connection
2025-01-21 04:05:59.383 25 ERROR cinder.volume.drivers.lightos     raise err
2025-01-21 04:05:59.383 25 ERROR cinder.volume.drivers.lightos   File "/var/lib/kolla/venv/lib/python3.10/site-packages/urllib3/util/connection.py", line 85, in create_connection
2025-01-21 04:05:59.383 25 ERROR cinder.volume.drivers.lightos     sock.connect(sa)
2025-01-21 04:05:59.383 25 ERROR cinder.volume.drivers.lightos   File "/var/lib/kolla/venv/lib/python3.10/site-packages/eventlet/greenio/base.py", line 265, in connect
2025-01-21 04:05:59.383 25 ERROR cinder.volume.drivers.lightos     socket_checkerr(fd)
2025-01-21 04:05:59.383 25 ERROR cinder.volume.drivers.lightos   File "/var/lib/kolla/venv/lib/python3.10/site-packages/eventlet/greenio/base.py", line 50, in socket_checkerr
2025-01-21 04:05:59.383 25 ERROR cinder.volume.drivers.lightos     raise OSError(err, errno.errorcode[err])
2025-01-21 04:05:59.383 25 ERROR cinder.volume.drivers.lightos ConnectionRefusedError: [Errno 111] ECONNREFUSED
2025-01-21 04:05:59.383 25 ERROR cinder.volume.drivers.lightos 
2025-01-21 04:05:59.383 25 ERROR cinder.volume.drivers.lightos During handling of the above exception, another exception occurred:
2025-01-21 04:05:59.383 25 ERROR cinder.volume.drivers.lightos 
2025-01-21 04:05:59.383 25 ERROR cinder.volume.drivers.lightos Traceback (most recent call last):
2025-01-21 04:05:59.383 25 ERROR cinder.volume.drivers.lightos   File "/var/lib/kolla/venv/lib/python3.10/site-packages/urllib3/connectionpool.py", line 715, in urlopen
2025-01-21 04:05:59.383 25 ERROR cinder.volume.drivers.lightos     httplib_response = self._make_request(
2025-01-21 04:05:59.383 25 ERROR cinder.volume.drivers.lightos   File "/var/lib/kolla/venv/lib/python3.10/site-packages/urllib3/connectionpool.py", line 404, in _make_request
2025-01-21 04:05:59.383 25 ERROR cinder.volume.drivers.lightos     self._validate_conn(conn)
2025-01-21 04:05:59.383 25 ERROR cinder.volume.drivers.lightos   File "/var/lib/kolla/venv/lib/python3.10/site-packages/urllib3/connectionpool.py", line 1060, in _validate_conn
2025-01-21 04:05:59.383 25 ERROR cinder.volume.drivers.lightos     conn.connect()
2025-01-21 04:05:59.383 25 ERROR cinder.volume.drivers.lightos   File "/var/lib/kolla/venv/lib/python3.10/site-packages/urllib3/connection.py", line 363, in connect
2025-01-21 04:05:59.383 25 ERROR cinder.volume.drivers.lightos     self.sock = conn = self._new_conn()
2025-01-21 04:05:59.383 25 ERROR cinder.volume.drivers.lightos   File "/var/lib/kolla/venv/lib/python3.10/site-packages/urllib3/connection.py", line 186, in _new_conn
2025-01-21 04:05:59.383 25 ERROR cinder.volume.drivers.lightos     raise NewConnectionError(
2025-01-21 04:05:59.383 25 ERROR cinder.volume.drivers.lightos urllib3.exceptions.NewConnectionError: <urllib3.connection.HTTPSConnection object at 0x7ffa58aa8ac0>: Failed to establish a new connection: [Errno 111] ECONNREFUSED
2025-01-21 04:05:59.383 25 ERROR cinder.volume.drivers.lightos 
2025-01-21 04:05:59.383 25 ERROR cinder.volume.drivers.lightos During handling of the above exception, another exception occurred:
2025-01-21 04:05:59.383 25 ERROR cinder.volume.drivers.lightos 
2025-01-21 04:05:59.383 25 ERROR cinder.volume.drivers.lightos Traceback (most recent call last):
2025-01-21 04:05:59.383 25 ERROR cinder.volume.drivers.lightos   File "/var/lib/kolla/venv/lib/python3.10/site-packages/requests/adapters.py", line 667, in send
2025-01-21 04:05:59.383 25 ERROR cinder.volume.drivers.lightos     resp = conn.urlopen(
2025-01-21 04:05:59.383 25 ERROR cinder.volume.drivers.lightos   File "/var/lib/kolla/venv/lib/python3.10/site-packages/urllib3/connectionpool.py", line 801, in urlopen
2025-01-21 04:05:59.383 25 ERROR cinder.volume.drivers.lightos     retries = retries.increment(
2025-01-21 04:05:59.383 25 ERROR cinder.volume.drivers.lightos   File "/var/lib/kolla/venv/lib/python3.10/site-packages/urllib3/util/retry.py", line 594, in increment
2025-01-21 04:05:59.383 25 ERROR cinder.volume.drivers.lightos     raise MaxRetryError(_pool, url, error or ResponseError(cause))
2025-01-21 04:05:59.383 25 ERROR cinder.volume.drivers.lightos urllib3.exceptions.MaxRetryError: HTTPSConnectionPool(host='[LB_IP_ADDRESS]', port=443): Max retries exceeded with url: /api/v2/clusterinfo (Caused by NewConnectionError('<urllib3.connection.HTTPSConnection object at 0x7ffa58aa8ac0>: Failed to establish a new connection: [Errno 111] ECONNREFUSED'))
2025-01-21 04:05:59.383 25 ERROR cinder.volume.drivers.lightos 
2025-01-21 04:05:59.383 25 ERROR cinder.volume.drivers.lightos During handling of the above exception, another exception occurred:
2025-01-21 04:05:59.383 25 ERROR cinder.volume.drivers.lightos 
2025-01-21 04:05:59.383 25 ERROR cinder.volume.drivers.lightos Traceback (most recent call last):
2025-01-21 04:05:59.383 25 ERROR cinder.volume.drivers.lightos   File "/var/lib/kolla/venv/lib/python3.10/site-packages/cinder/volume/drivers/lightos.py", line 356, in __send_cmd
2025-01-21 04:05:59.383 25 ERROR cinder.volume.drivers.lightos     response = session.send(
2025-01-21 04:05:59.383 25 ERROR cinder.volume.drivers.lightos   File "/var/lib/kolla/venv/lib/python3.10/site-packages/requests/sessions.py", line 703, in send
2025-01-21 04:05:59.383 25 ERROR cinder.volume.drivers.lightos     r = adapter.send(request, **kwargs)
2025-01-21 04:05:59.383 25 ERROR cinder.volume.drivers.lightos   File "/var/lib/kolla/venv/lib/python3.10/site-packages/requests/adapters.py", line 700, in send
2025-01-21 04:05:59.383 25 ERROR cinder.volume.drivers.lightos     raise ConnectionError(e, request=request)
2025-01-21 04:05:59.383 25 ERROR cinder.volume.drivers.lightos requests.exceptions.ConnectionError: HTTPSConnectionPool(host='[LB_IP_ADDRESS]', port=443): Max retries exceeded with url: /api/v2/clusterinfo (Caused by NewConnectionError('<urllib3.connection.HTTPSConnection object at 0x7ffa58aa8ac0>: Failed to establish a new connection: [Errno 111] ECONNREFUSED'))
2025-01-21 04:05:59.383 25 ERROR cinder.volume.drivers.lightos 
2025-01-21 04:05:59.385 25 INFO cinder.volume.drivers.lightos [None req-571cc66b-a331-4771-8119-dcb3407556c2 - - - - - -] Invoking get_cluster_info using GET url: /api/v2/clusterinfo             request.body: {} ssl_verify: False
2025-01-21 04:06:02.465 25 ERROR cinder.volume.drivers.lightos [None req-571cc66b-a331-4771-8119-dcb3407556c2 - - - - - -] REST server not responding at 'https://[LB_IP_ADDRESS]:443/api/v2/clusterinfo': requests.exceptions.ConnectionError: HTTPSConnectionPool(host='[LB_IP_ADDRESS]', port=443): Max retries exceeded with url: /api/v2/clusterinfo (Caused by NewConnectionError('<urllib3.connection.HTTPSConnection object at 0x7ffa58aa8460>: Failed to establish a new connection: [Errno 113] EHOSTUNREACH'))
2025-01-21 04:06:02.465 25 ERROR cinder.volume.drivers.lightos Traceback (most recent call last):
2025-01-21 04:06:02.465 25 ERROR cinder.volume.drivers.lightos   File "/var/lib/kolla/venv/lib/python3.10/site-packages/urllib3/connection.py", line 174, in _new_conn
2025-01-21 04:06:02.465 25 ERROR cinder.volume.drivers.lightos     conn = connection.create_connection(
2025-01-21 04:06:02.465 25 ERROR cinder.volume.drivers.lightos   File "/var/lib/kolla/venv/lib/python3.10/site-packages/urllib3/util/connection.py", line 95, in create_connection
2025-01-21 04:06:02.465 25 ERROR cinder.volume.drivers.lightos     raise err
2025-01-21 04:06:02.465 25 ERROR cinder.volume.drivers.lightos   File "/var/lib/kolla/venv/lib/python3.10/site-packages/urllib3/util/connection.py", line 85, in create_connection
2025-01-21 04:06:02.465 25 ERROR cinder.volume.drivers.lightos     sock.connect(sa)
2025-01-21 04:06:02.465 25 ERROR cinder.volume.drivers.lightos   File "/var/lib/kolla/venv/lib/python3.10/site-packages/eventlet/greenio/base.py", line 265, in connect
2025-01-21 04:06:02.465 25 ERROR cinder.volume.drivers.lightos     socket_checkerr(fd)
2025-01-21 04:06:02.465 25 ERROR cinder.volume.drivers.lightos   File "/var/lib/kolla/venv/lib/python3.10/site-packages/eventlet/greenio/base.py", line 50, in socket_checkerr
2025-01-21 04:06:02.465 25 ERROR cinder.volume.drivers.lightos     raise OSError(err, errno.errorcode[err])
2025-01-21 04:06:02.465 25 ERROR cinder.volume.drivers.lightos OSError: [Errno 113] EHOSTUNREACH
2025-01-21 04:06:02.465 25 ERROR cinder.volume.drivers.lightos 
2025-01-21 04:06:02.465 25 ERROR cinder.volume.drivers.lightos During handling of the above exception, another exception occurred:
2025-01-21 04:06:02.465 25 ERROR cinder.volume.drivers.lightos 
2025-01-21 04:06:02.465 25 ERROR cinder.volume.drivers.lightos Traceback (most recent call last):
2025-01-21 04:06:02.465 25 ERROR cinder.volume.drivers.lightos   File "/var/lib/kolla/venv/lib/python3.10/site-packages/urllib3/connectionpool.py", line 715, in urlopen
2025-01-21 04:06:02.465 25 ERROR cinder.volume.drivers.lightos     httplib_response = self._make_request(
2025-01-21 04:06:02.465 25 ERROR cinder.volume.drivers.lightos   File "/var/lib/kolla/venv/lib/python3.10/site-packages/urllib3/connectionpool.py", line 404, in _make_request
2025-01-21 04:06:02.465 25 ERROR cinder.volume.drivers.lightos     self._validate_conn(conn)
2025-01-21 04:06:02.465 25 ERROR cinder.volume.drivers.lightos   File "/var/lib/kolla/venv/lib/python3.10/site-packages/urllib3/connectionpool.py", line 1060, in _validate_conn
2025-01-21 04:06:02.465 25 ERROR cinder.volume.drivers.lightos     conn.connect()
2025-01-21 04:06:02.465 25 ERROR cinder.volume.drivers.lightos   File "/var/lib/kolla/venv/lib/python3.10/site-packages/urllib3/connection.py", line 363, in connect
2025-01-21 04:06:02.465 25 ERROR cinder.volume.drivers.lightos     self.sock = conn = self._new_conn()
2025-01-21 04:06:02.465 25 ERROR cinder.volume.drivers.lightos   File "/var/lib/kolla/venv/lib/python3.10/site-packages/urllib3/connection.py", line 186, in _new_conn
2025-01-21 04:06:02.465 25 ERROR cinder.volume.drivers.lightos     raise NewConnectionError(
2025-01-21 04:06:02.465 25 ERROR cinder.volume.drivers.lightos urllib3.exceptions.NewConnectionError: <urllib3.connection.HTTPSConnection object at 0x7ffa58aa8460>: Failed to establish a new connection: [Errno 113] EHOSTUNREACH
2025-01-21 04:06:02.465 25 ERROR cinder.volume.drivers.lightos 
2025-01-21 04:06:02.465 25 ERROR cinder.volume.drivers.lightos During handling of the above exception, another exception occurred:
2025-01-21 04:06:02.465 25 ERROR cinder.volume.drivers.lightos 
2025-01-21 04:06:02.465 25 ERROR cinder.volume.drivers.lightos Traceback (most recent call last):
2025-01-21 04:06:02.465 25 ERROR cinder.volume.drivers.lightos   File "/var/lib/kolla/venv/lib/python3.10/site-packages/requests/adapters.py", line 667, in send
2025-01-21 04:06:02.465 25 ERROR cinder.volume.drivers.lightos     resp = conn.urlopen(
2025-01-21 04:06:02.465 25 ERROR cinder.volume.drivers.lightos   File "/var/lib/kolla/venv/lib/python3.10/site-packages/urllib3/connectionpool.py", line 801, in urlopen
2025-01-21 04:06:02.465 25 ERROR cinder.volume.drivers.lightos     retries = retries.increment(
2025-01-21 04:06:02.465 25 ERROR cinder.volume.drivers.lightos   File "/var/lib/kolla/venv/lib/python3.10/site-packages/urllib3/util/retry.py", line 594, in increment
2025-01-21 04:06:02.465 25 ERROR cinder.volume.drivers.lightos     raise MaxRetryError(_pool, url, error or ResponseError(cause))
2025-01-21 04:06:02.465 25 ERROR cinder.volume.drivers.lightos urllib3.exceptions.MaxRetryError: HTTPSConnectionPool(host='[LB_IP_ADDRESS]', port=443): Max retries exceeded with url: /api/v2/clusterinfo (Caused by NewConnectionError('<urllib3.connection.HTTPSConnection object at 0x7ffa58aa8460>: Failed to establish a new connection: [Errno 113] EHOSTUNREACH'))
2025-01-21 04:06:02.465 25 ERROR cinder.volume.drivers.lightos 
2025-01-21 04:06:02.465 25 ERROR cinder.volume.drivers.lightos During handling of the above exception, another exception occurred:
2025-01-21 04:06:02.465 25 ERROR cinder.volume.drivers.lightos 
2025-01-21 04:06:02.465 25 ERROR cinder.volume.drivers.lightos Traceback (most recent call last):
2025-01-21 04:06:02.465 25 ERROR cinder.volume.drivers.lightos   File "/var/lib/kolla/venv/lib/python3.10/site-packages/cinder/volume/drivers/lightos.py", line 356, in __send_cmd
2025-01-21 04:06:02.465 25 ERROR cinder.volume.drivers.lightos     response = session.send(
2025-01-21 04:06:02.465 25 ERROR cinder.volume.drivers.lightos   File "/var/lib/kolla/venv/lib/python3.10/site-packages/requests/sessions.py", line 703, in send
2025-01-21 04:06:02.465 25 ERROR cinder.volume.drivers.lightos     r = adapter.send(request, **kwargs)
2025-01-21 04:06:02.465 25 ERROR cinder.volume.drivers.lightos   File "/var/lib/kolla/venv/lib/python3.10/site-packages/requests/adapters.py", line 700, in send
2025-01-21 04:06:02.465 25 ERROR cinder.volume.drivers.lightos     raise ConnectionError(e, request=request)
2025-01-21 04:06:02.465 25 ERROR cinder.volume.drivers.lightos requests.exceptions.ConnectionError: HTTPSConnectionPool(host='[LB_IP_ADDRESS]', port=443): Max retries exceeded with url: /api/v2/clusterinfo (Caused by NewConnectionError('<urllib3.connection.HTTPSConnection object at 0x7ffa58aa8460>: Failed to establish a new connection: [Errno 113] EHOSTUNREACH'))
2025-01-21 04:06:02.465 25 ERROR cinder.volume.drivers.lightos 
2025-01-21 04:06:02.468 25 INFO cinder.volume.drivers.lightos [None req-571cc66b-a331-4771-8119-dcb3407556c2 - - - - - -] Invoking get_cluster_info using GET url: /api/v2/clusterinfo             request.body: {} ssl_verify: False
2025-01-21 04:06:02.471 25 ERROR cinder.volume.drivers.lightos [None req-571cc66b-a331-4771-8119-dcb3407556c2 - - - - - -] REST server not responding at 'https://[LB_IP_ADDRESS]:443/api/v2/clusterinfo': requests.exceptions.ConnectionError: HTTPSConnectionPool(host='[LB_IP_ADDRESS]', port=443): Max retries exceeded with url: /api/v2/clusterinfo (Caused by NewConnectionError('<urllib3.connection.HTTPSConnection object at 0x7ffa58840370>: Failed to establish a new connection: [Errno 111] ECONNREFUSED'))
2025-01-21 04:06:02.471 25 ERROR cinder.volume.drivers.lightos Traceback (most recent call last):
2025-01-21 04:06:02.471 25 ERROR cinder.volume.drivers.lightos   File "/var/lib/kolla/venv/lib/python3.10/site-packages/urllib3/connection.py", line 174, in _new_conn
2025-01-21 04:06:02.471 25 ERROR cinder.volume.drivers.lightos     conn = connection.create_connection(
2025-01-21 04:06:02.471 25 ERROR cinder.volume.drivers.lightos   File "/var/lib/kolla/venv/lib/python3.10/site-packages/urllib3/util/connection.py", line 95, in create_connection
2025-01-21 04:06:02.471 25 ERROR cinder.volume.drivers.lightos     raise err
2025-01-21 04:06:02.471 25 ERROR cinder.volume.drivers.lightos   File "/var/lib/kolla/venv/lib/python3.10/site-packages/urllib3/util/connection.py", line 85, in create_connection
2025-01-21 04:06:02.471 25 ERROR cinder.volume.drivers.lightos     sock.connect(sa)
2025-01-21 04:06:02.471 25 ERROR cinder.volume.drivers.lightos   File "/var/lib/kolla/venv/lib/python3.10/site-packages/eventlet/greenio/base.py", line 265, in connect
2025-01-21 04:06:02.471 25 ERROR cinder.volume.drivers.lightos     socket_checkerr(fd)
2025-01-21 04:06:02.471 25 ERROR cinder.volume.drivers.lightos   File "/var/lib/kolla/venv/lib/python3.10/site-packages/eventlet/greenio/base.py", line 50, in socket_checkerr
2025-01-21 04:06:02.471 25 ERROR cinder.volume.drivers.lightos     raise OSError(err, errno.errorcode[err])
2025-01-21 04:06:02.471 25 ERROR cinder.volume.drivers.lightos ConnectionRefusedError: [Errno 111] ECONNREFUSED
2025-01-21 04:06:02.471 25 ERROR cinder.volume.drivers.lightos 
2025-01-21 04:06:02.471 25 ERROR cinder.volume.drivers.lightos During handling of the above exception, another exception occurred:
2025-01-21 04:06:02.471 25 ERROR cinder.volume.drivers.lightos 
2025-01-21 04:06:02.471 25 ERROR cinder.volume.drivers.lightos Traceback (most recent call last):
2025-01-21 04:06:02.471 25 ERROR cinder.volume.drivers.lightos   File "/var/lib/kolla/venv/lib/python3.10/site-packages/urllib3/connectionpool.py", line 715, in urlopen
2025-01-21 04:06:02.471 25 ERROR cinder.volume.drivers.lightos     httplib_response = self._make_request(
2025-01-21 04:06:02.471 25 ERROR cinder.volume.drivers.lightos   File "/var/lib/kolla/venv/lib/python3.10/site-packages/urllib3/connectionpool.py", line 404, in _make_request
2025-01-21 04:06:02.471 25 ERROR cinder.volume.drivers.lightos     self._validate_conn(conn)
2025-01-21 04:06:02.471 25 ERROR cinder.volume.drivers.lightos   File "/var/lib/kolla/venv/lib/python3.10/site-packages/urllib3/connectionpool.py", line 1060, in _validate_conn
2025-01-21 04:06:02.471 25 ERROR cinder.volume.drivers.lightos     conn.connect()
2025-01-21 04:06:02.471 25 ERROR cinder.volume.drivers.lightos   File "/var/lib/kolla/venv/lib/python3.10/site-packages/urllib3/connection.py", line 363, in connect
2025-01-21 04:06:02.471 25 ERROR cinder.volume.drivers.lightos     self.sock = conn = self._new_conn()
2025-01-21 04:06:02.471 25 ERROR cinder.volume.drivers.lightos   File "/var/lib/kolla/venv/lib/python3.10/site-packages/urllib3/connection.py", line 186, in _new_conn
2025-01-21 04:06:02.471 25 ERROR cinder.volume.drivers.lightos     raise NewConnectionError(
2025-01-21 04:06:02.471 25 ERROR cinder.volume.drivers.lightos urllib3.exceptions.NewConnectionError: <urllib3.connection.HTTPSConnection object at 0x7ffa58840370>: Failed to establish a new connection: [Errno 111] ECONNREFUSED
2025-01-21 04:06:02.471 25 ERROR cinder.volume.drivers.lightos 
2025-01-21 04:06:02.471 25 ERROR cinder.volume.drivers.lightos During handling of the above exception, another exception occurred:
2025-01-21 04:06:02.471 25 ERROR cinder.volume.drivers.lightos 
2025-01-21 04:06:02.471 25 ERROR cinder.volume.drivers.lightos Traceback (most recent call last):
2025-01-21 04:06:02.471 25 ERROR cinder.volume.drivers.lightos   File "/var/lib/kolla/venv/lib/python3.10/site-packages/requests/adapters.py", line 667, in send
2025-01-21 04:06:02.471 25 ERROR cinder.volume.drivers.lightos     resp = conn.urlopen(
2025-01-21 04:06:02.471 25 ERROR cinder.volume.drivers.lightos   File "/var/lib/kolla/venv/lib/python3.10/site-packages/urllib3/connectionpool.py", line 801, in urlopen
2025-01-21 04:06:02.471 25 ERROR cinder.volume.drivers.lightos     retries = retries.increment(
2025-01-21 04:06:02.471 25 ERROR cinder.volume.drivers.lightos   File "/var/lib/kolla/venv/lib/python3.10/site-packages/urllib3/util/retry.py", line 594, in increment
2025-01-21 04:06:02.471 25 ERROR cinder.volume.drivers.lightos     raise MaxRetryError(_pool, url, error or ResponseError(cause))
2025-01-21 04:06:02.471 25 ERROR cinder.volume.drivers.lightos urllib3.exceptions.MaxRetryError: HTTPSConnectionPool(host='[LB_IP_ADDRESS]', port=443): Max retries exceeded with url: /api/v2/clusterinfo (Caused by NewConnectionError('<urllib3.connection.HTTPSConnection object at 0x7ffa58840370>: Failed to establish a new connection: [Errno 111] ECONNREFUSED'))
2025-01-21 04:06:02.471 25 ERROR cinder.volume.drivers.lightos 
2025-01-21 04:06:02.471 25 ERROR cinder.volume.drivers.lightos During handling of the above exception, another exception occurred:
2025-01-21 04:06:02.471 25 ERROR cinder.volume.drivers.lightos 
2025-01-21 04:06:02.471 25 ERROR cinder.volume.drivers.lightos Traceback (most recent call last):
2025-01-21 04:06:02.471 25 ERROR cinder.volume.drivers.lightos   File "/var/lib/kolla/venv/lib/python3.10/site-packages/cinder/volume/drivers/lightos.py", line 356, in __send_cmd
2025-01-21 04:06:02.471 25 ERROR cinder.volume.drivers.lightos     response = session.send(
2025-01-21 04:06:02.471 25 ERROR cinder.volume.drivers.lightos   File "/var/lib/kolla/venv/lib/python3.10/site-packages/requests/sessions.py", line 703, in send
2025-01-21 04:06:02.471 25 ERROR cinder.volume.drivers.lightos     r = adapter.send(request, **kwargs)
2025-01-21 04:06:02.471 25 ERROR cinder.volume.drivers.lightos   File "/var/lib/kolla/venv/lib/python3.10/site-packages/requests/adapters.py", line 700, in send
2025-01-21 04:06:02.471 25 ERROR cinder.volume.drivers.lightos     raise ConnectionError(e, request=request)
2025-01-21 04:06:02.471 25 ERROR cinder.volume.drivers.lightos requests.exceptions.ConnectionError: HTTPSConnectionPool(host='[LB_IP_ADDRESS]', port=443): Max retries exceeded with url: /api/v2/clusterinfo (Caused by NewConnectionError('<urllib3.connection.HTTPSConnection object at 0x7ffa58840370>: Failed to establish a new connection: [Errno 111] ECONNREFUSED'))
2025-01-21 04:06:02.471 25 ERROR cinder.volume.drivers.lightos 
2025-01-21 04:06:02.473 25 ERROR cinder.volume.manager [None req-571cc66b-a331-4771-8119-dcb3407556c2 - - - - - -] Failed to initialize driver.: cinder.exception.VolumeDriverException: Volume driver reported an error: Could not get a response from any API server
2025-01-21 04:06:02.473 25 ERROR cinder.volume.manager Traceback (most recent call last):
2025-01-21 04:06:02.473 25 ERROR cinder.volume.manager   File "/var/lib/kolla/venv/lib/python3.10/site-packages/cinder/volume/manager.py", line 523, in _init_host
2025-01-21 04:06:02.473 25 ERROR cinder.volume.manager     self.driver.do_setup(ctxt)
2025-01-21 04:06:02.473 25 ERROR cinder.volume.manager   File "/var/lib/kolla/venv/lib/python3.10/site-packages/cinder/volume/drivers/lightos.py", line 922, in do_setup
2025-01-21 04:06:02.473 25 ERROR cinder.volume.manager     self.get_cluster_info()
2025-01-21 04:06:02.473 25 ERROR cinder.volume.manager   File "/var/lib/kolla/venv/lib/python3.10/site-packages/cinder/volume/drivers/lightos.py", line 873, in get_cluster_info
2025-01-21 04:06:02.473 25 ERROR cinder.volume.manager     status_code, cluster_info = self.cluster.send_cmd(
2025-01-21 04:06:02.473 25 ERROR cinder.volume.manager   File "/var/lib/kolla/venv/lib/python3.10/site-packages/cinder/volume/drivers/lightos.py", line 315, in send_cmd
2025-01-21 04:06:02.473 25 ERROR cinder.volume.manager     raise exception.VolumeDriverException(
2025-01-21 04:06:02.473 25 ERROR cinder.volume.manager cinder.exception.VolumeDriverException: Volume driver reported an error: Could not get a response from any API server
2025-01-21 04:06:02.473 25 ERROR cinder.volume.manager 
2025-01-21 04:06:02.495 25 WARNING oslo_config.cfg [None req-571cc66b-a331-4771-8119-dcb3407556c2 - - - - - -] Deprecated: Option "heartbeat_in_pthread" from group "oslo_messaging_rabbit" is deprecated for removal (The option is related to Eventlet which will be removed. In addition this has never worked as expected with services using eventlet for core service framework.).  Its value may be silently ignored in the future.
2025-01-21 04:06:02.542 25 INFO cinder.service [None req-571cc66b-a331-4771-8119-dcb3407556c2 - - - - - -] Starting cinder-volume cluster lightos_cinder_cluster@LIGHTOSyilgqu (version 25.1.0)
2025-01-21 04:06:02.563 25 INFO cinder.volume.manager [None req-571cc66b-a331-4771-8119-dcb3407556c2 - - - - - -] Initializing RPC dependent components of volume driver LightOSVolumeDriver (2.3.12)
2025-01-21 04:06:02.563 25 ERROR cinder.volume.volume_utils [None req-571cc66b-a331-4771-8119-dcb3407556c2 - - - - - -] Volume driver LightOSVolumeDriver not initialized
2025-01-21 04:06:02.564 25 ERROR cinder.volume.manager [None req-571cc66b-a331-4771-8119-dcb3407556c2 - - - - - -] Cannot complete RPC initialization because driver isn't initialized properly.: cinder.exception.DriverNotInitialized: Volume driver not ready.
2025-01-21 04:06:12.566 25 ERROR cinder.service [-] Manager for service cinder-volume rack13-server67@LIGHTOSyilgqu is reporting problems, not sending heartbeat. Service will appear "down".
2025-01-21 04:06:22.568 25 ERROR cinder.service [-] Manager for service cinder-volume rack13-server67@LIGHTOSyilgqu is reporting problems, not sending heartbeat. Service will appear "down".
2025-01-21 04:06:32.569 25 ERROR cinder.service [-] Manager for service cinder-volume rack13-server67@LIGHTOSyilgqu is reporting problems, not sending heartbeat. Service will appear "down".
2025-01-21 04:06:42.571 25 ERROR cinder.service [-] Manager for service cinder-volume rack13-server67@LIGHTOSyilgqu is reporting problems, not sending heartbeat. Service will appear "down".
2025-01-21 04:06:50.569 25 WARNING cinder.volume.manager [None req-ac11f501-cb11-482e-94ac-b5ac5c640cc5 - - - - - -] Update driver status failed: (config name LIGHTOSyilgqu) is uninitialized.
2025-01-21 04:06:52.573 25 ERROR cinder.service [-] Manager for service cinder-volume rack13-server67@LIGHTOSyilgqu is reporting problems, not sending heartbeat. Service will appear "down".
2025-01-21 04:07:02.574 25 ERROR cinder.service [-] Manager for service cinder-volume rack13-server67@LIGHTOSyilgqu is reporting problems, not sending heartbeat. Service will appear "down".
2025-01-21 04:07:12.576 25 ERROR cinder.service [-] Manager for service cinder-volume rack13-server67@LIGHTOSyilgqu is reporting problems, not sending heartbeat. Service will appear "down".
2025-01-21 04:07:22.578 25 ERROR cinder.service [-] Manager for service cinder-volume rack13-server67@LIGHTOSyilgqu is reporting problems, not sending heartbeat. Service will appear "down".
2025-01-21 04:07:32.580 25 ERROR cinder.service [-] Manager for service cinder-volume rack13-server67@LIGHTOSyilgqu is reporting problems, not sending heartbeat. Service will appear "down".
2025-01-21 04:07:42.581 25 ERROR cinder.service [-] Manager for service cinder-volume rack13-server67@LIGHTOSyilgqu is reporting problems, not sending heartbeat. Service will appear "down".
2025-01-21 04:07:50.574 25 WARNING cinder.volume.manager [None req-ac11f501-cb11-482e-94ac-b5ac5c640cc5 - - - - - -] Update driver status failed: (config name LIGHTOSyilgqu) is uninitialized.
2025-01-21 04:07:52.583 25 ERROR cinder.service [-] Manager for service cinder-volume rack13-server67@LIGHTOSyilgqu is reporting problems, not sending heartbeat. Service will appear "down".
2025-01-21 04:08:02.584 25 ERROR cinder.service [-] Manager for service cinder-volume rack13-server67@LIGHTOSyilgqu is reporting problems, not sending heartbeat. Service will appear "down".
2025-01-21 04:08:12.585 25 ERROR cinder.service [-] Manager for service cinder-volume rack13-server67@LIGHTOSyilgqu is reporting problems, not sending heartbeat. Service will appear "down".
2025-01-21 04:08:22.587 25 ERROR cinder.service [-] Manager for service cinder-volume rack13-server67@LIGHTOSyilgqu is reporting problems, not sending heartbeat. Service will appear "down".
2025-01-21 04:08:32.589 25 ERROR cinder.service [-] Manager for service cinder-volume rack13-server67@LIGHTOSyilgqu is reporting problems, not sending heartbeat. Service will appear "down".
2025-01-21 04:08:42.590 25 ERROR cinder.service [-] Manager for service cinder-volume rack13-server67@LIGHTOSyilgqu is reporting problems, not sending heartbeat. Service will appear "down".
2025-01-21 04:08:50.579 25 WARNING cinder.volume.manager [None req-ac11f501-cb11-482e-94ac-b5ac5c640cc5 - - - - - -] Update driver status failed: (config name LIGHTOSyilgqu) is uninitialized.
2025-01-21 04:08:52.595 25 ERROR cinder.service [-] Manager for service cinder-volume rack13-server67@LIGHTOSyilgqu is reporting problems, not sending heartbeat. Service will appear "down".
2025-01-21 04:09:02.596 25 ERROR cinder.service [-] Manager for service cinder-volume rack13-server67@LIGHTOSyilgqu is reporting problems, not sending heartbeat. Service will appear "down".
2025-01-21 04:09:12.598 25 ERROR cinder.service [-] Manager for service cinder-volume rack13-server67@LIGHTOSyilgqu is reporting problems, not sending heartbeat. Service will appear "down".
2025-01-21 04:09:22.599 25 ERROR cinder.service [-] Manager for service cinder-volume rack13-server67@LIGHTOSyilgqu is reporting problems, not sending heartbeat. Service will appear "down".
