Build Started 20_01_2025_20_28_17
2025-01-20 20:28:27.294 7 INFO oslo_service.service [None req-fd297b53-da6d-40af-9666-2ddc5ca5c75a - - - - - -] Caught SIGTERM, stopping children
2025-01-20 20:28:27.297 7 INFO oslo_service.service [None req-fd297b53-da6d-40af-9666-2ddc5ca5c75a - - - - - -] Waiting on 1 children to exit
2025-01-20 20:28:29.479 25 WARNING amqp [None req-fd297b53-da6d-40af-9666-2ddc5ca5c75a - - - - - -] Received method (60, 30) during closing channel 1. This method will be ignored
2025-01-20 20:28:29.493 25 WARNING amqp [None req-fd297b53-da6d-40af-9666-2ddc5ca5c75a - - - - - -] Received method (60, 30) during closing channel 1. This method will be ignored
2025-01-20 20:28:29.503 25 WARNING amqp [None req-fd297b53-da6d-40af-9666-2ddc5ca5c75a - - - - - -] Received method (60, 30) during closing channel 1. This method will be ignored
2025-01-20 20:28:29.511 7 INFO oslo_service.service [None req-fd297b53-da6d-40af-9666-2ddc5ca5c75a - - - - - -] Child 25 exited with status 0
2025-01-20 20:28:44.948 7 INFO cinder.rpc [None req-64ee3b6d-671f-480b-96d4-791684f7954b - - - - - -] Automatically selected cinder-scheduler objects version 1.39 as minimum service version.
2025-01-20 20:28:44.953 7 INFO cinder.rpc [None req-64ee3b6d-671f-480b-96d4-791684f7954b - - - - - -] Automatically selected cinder-scheduler RPC version 3.12 as minimum service version.
2025-01-20 20:28:44.993 7 INFO cinder.volume.manager [None req-64ee3b6d-671f-480b-96d4-791684f7954b - - - - - -] Determined volume DB was empty at startup.
2025-01-20 20:28:45.012 7 INFO cinder.volume.manager [None req-64ee3b6d-671f-480b-96d4-791684f7954b - - - - - -] Image-volume cache disabled for host rack13-server67@LIGHTOSyilgqu.
2025-01-20 20:28:45.030 7 INFO oslo_service.service [None req-64ee3b6d-671f-480b-96d4-791684f7954b - - - - - -] Starting 1 workers
2025-01-20 20:28:45.041 25 INFO cinder.service [-] Starting cinder-volume node (version 25.1.0)
2025-01-20 20:28:45.046 7 WARNING oslo_config.cfg [None req-64ee3b6d-671f-480b-96d4-791684f7954b - - - - - -] Deprecated: Option "heartbeat_in_pthread" from group "oslo_messaging_rabbit" is deprecated for removal (The option is related to Eventlet which will be removed. In addition this has never worked as expected with services using eventlet for core service framework.).  Its value may be silently ignored in the future.
2025-01-20 20:28:45.060 25 INFO cinder.volume.manager [None req-64f7749e-7efe-402d-9521-a6cc88b11e14 - - - - - -] Starting volume driver LightOSVolumeDriver (2.3.12)
2025-01-20 20:28:45.061 25 INFO cinder.volume.drivers.lightos [None req-64f7749e-7efe-402d-9521-a6cc88b11e14 - - - - - -] Invoking get_cluster_info using GET url: /api/v2/clusterinfo             request.body: {} ssl_verify: False
2025-01-20 20:28:48.130 25 ERROR cinder.volume.drivers.lightos [None req-64f7749e-7efe-402d-9521-a6cc88b11e14 - - - - - -] REST server not responding at 'https://[LB_IP_ADDRESS]:443/api/v2/clusterinfo': requests.exceptions.ConnectionError: HTTPSConnectionPool(host='[LB_IP_ADDRESS]', port=443): Max retries exceeded with url: /api/v2/clusterinfo (Caused by NewConnectionError('<urllib3.connection.HTTPSConnection object at 0x7efceaaa5bd0>: Failed to establish a new connection: [Errno 113] EHOSTUNREACH'))
2025-01-20 20:28:48.130 25 ERROR cinder.volume.drivers.lightos Traceback (most recent call last):
2025-01-20 20:28:48.130 25 ERROR cinder.volume.drivers.lightos   File "/var/lib/kolla/venv/lib/python3.10/site-packages/urllib3/connection.py", line 174, in _new_conn
2025-01-20 20:28:48.130 25 ERROR cinder.volume.drivers.lightos     conn = connection.create_connection(
2025-01-20 20:28:48.130 25 ERROR cinder.volume.drivers.lightos   File "/var/lib/kolla/venv/lib/python3.10/site-packages/urllib3/util/connection.py", line 95, in create_connection
2025-01-20 20:28:48.130 25 ERROR cinder.volume.drivers.lightos     raise err
2025-01-20 20:28:48.130 25 ERROR cinder.volume.drivers.lightos   File "/var/lib/kolla/venv/lib/python3.10/site-packages/urllib3/util/connection.py", line 85, in create_connection
2025-01-20 20:28:48.130 25 ERROR cinder.volume.drivers.lightos     sock.connect(sa)
2025-01-20 20:28:48.130 25 ERROR cinder.volume.drivers.lightos   File "/var/lib/kolla/venv/lib/python3.10/site-packages/eventlet/greenio/base.py", line 265, in connect
2025-01-20 20:28:48.130 25 ERROR cinder.volume.drivers.lightos     socket_checkerr(fd)
2025-01-20 20:28:48.130 25 ERROR cinder.volume.drivers.lightos   File "/var/lib/kolla/venv/lib/python3.10/site-packages/eventlet/greenio/base.py", line 50, in socket_checkerr
2025-01-20 20:28:48.130 25 ERROR cinder.volume.drivers.lightos     raise OSError(err, errno.errorcode[err])
2025-01-20 20:28:48.130 25 ERROR cinder.volume.drivers.lightos OSError: [Errno 113] EHOSTUNREACH
2025-01-20 20:28:48.130 25 ERROR cinder.volume.drivers.lightos 
2025-01-20 20:28:48.130 25 ERROR cinder.volume.drivers.lightos During handling of the above exception, another exception occurred:
2025-01-20 20:28:48.130 25 ERROR cinder.volume.drivers.lightos 
2025-01-20 20:28:48.130 25 ERROR cinder.volume.drivers.lightos Traceback (most recent call last):
2025-01-20 20:28:48.130 25 ERROR cinder.volume.drivers.lightos   File "/var/lib/kolla/venv/lib/python3.10/site-packages/urllib3/connectionpool.py", line 715, in urlopen
2025-01-20 20:28:48.130 25 ERROR cinder.volume.drivers.lightos     httplib_response = self._make_request(
2025-01-20 20:28:48.130 25 ERROR cinder.volume.drivers.lightos   File "/var/lib/kolla/venv/lib/python3.10/site-packages/urllib3/connectionpool.py", line 404, in _make_request
2025-01-20 20:28:48.130 25 ERROR cinder.volume.drivers.lightos     self._validate_conn(conn)
2025-01-20 20:28:48.130 25 ERROR cinder.volume.drivers.lightos   File "/var/lib/kolla/venv/lib/python3.10/site-packages/urllib3/connectionpool.py", line 1060, in _validate_conn
2025-01-20 20:28:48.130 25 ERROR cinder.volume.drivers.lightos     conn.connect()
2025-01-20 20:28:48.130 25 ERROR cinder.volume.drivers.lightos   File "/var/lib/kolla/venv/lib/python3.10/site-packages/urllib3/connection.py", line 363, in connect
2025-01-20 20:28:48.130 25 ERROR cinder.volume.drivers.lightos     self.sock = conn = self._new_conn()
2025-01-20 20:28:48.130 25 ERROR cinder.volume.drivers.lightos   File "/var/lib/kolla/venv/lib/python3.10/site-packages/urllib3/connection.py", line 186, in _new_conn
2025-01-20 20:28:48.130 25 ERROR cinder.volume.drivers.lightos     raise NewConnectionError(
2025-01-20 20:28:48.130 25 ERROR cinder.volume.drivers.lightos urllib3.exceptions.NewConnectionError: <urllib3.connection.HTTPSConnection object at 0x7efceaaa5bd0>: Failed to establish a new connection: [Errno 113] EHOSTUNREACH
2025-01-20 20:28:48.130 25 ERROR cinder.volume.drivers.lightos 
2025-01-20 20:28:48.130 25 ERROR cinder.volume.drivers.lightos During handling of the above exception, another exception occurred:
2025-01-20 20:28:48.130 25 ERROR cinder.volume.drivers.lightos 
2025-01-20 20:28:48.130 25 ERROR cinder.volume.drivers.lightos Traceback (most recent call last):
2025-01-20 20:28:48.130 25 ERROR cinder.volume.drivers.lightos   File "/var/lib/kolla/venv/lib/python3.10/site-packages/requests/adapters.py", line 667, in send
2025-01-20 20:28:48.130 25 ERROR cinder.volume.drivers.lightos     resp = conn.urlopen(
2025-01-20 20:28:48.130 25 ERROR cinder.volume.drivers.lightos   File "/var/lib/kolla/venv/lib/python3.10/site-packages/urllib3/connectionpool.py", line 801, in urlopen
2025-01-20 20:28:48.130 25 ERROR cinder.volume.drivers.lightos     retries = retries.increment(
2025-01-20 20:28:48.130 25 ERROR cinder.volume.drivers.lightos   File "/var/lib/kolla/venv/lib/python3.10/site-packages/urllib3/util/retry.py", line 594, in increment
2025-01-20 20:28:48.130 25 ERROR cinder.volume.drivers.lightos     raise MaxRetryError(_pool, url, error or ResponseError(cause))
2025-01-20 20:28:48.130 25 ERROR cinder.volume.drivers.lightos urllib3.exceptions.MaxRetryError: HTTPSConnectionPool(host='[LB_IP_ADDRESS]', port=443): Max retries exceeded with url: /api/v2/clusterinfo (Caused by NewConnectionError('<urllib3.connection.HTTPSConnection object at 0x7efceaaa5bd0>: Failed to establish a new connection: [Errno 113] EHOSTUNREACH'))
2025-01-20 20:28:48.130 25 ERROR cinder.volume.drivers.lightos 
2025-01-20 20:28:48.130 25 ERROR cinder.volume.drivers.lightos During handling of the above exception, another exception occurred:
2025-01-20 20:28:48.130 25 ERROR cinder.volume.drivers.lightos 
2025-01-20 20:28:48.130 25 ERROR cinder.volume.drivers.lightos Traceback (most recent call last):
2025-01-20 20:28:48.130 25 ERROR cinder.volume.drivers.lightos   File "/var/lib/kolla/venv/lib/python3.10/site-packages/cinder/volume/drivers/lightos.py", line 356, in __send_cmd
2025-01-20 20:28:48.130 25 ERROR cinder.volume.drivers.lightos     response = session.send(
2025-01-20 20:28:48.130 25 ERROR cinder.volume.drivers.lightos   File "/var/lib/kolla/venv/lib/python3.10/site-packages/requests/sessions.py", line 703, in send
2025-01-20 20:28:48.130 25 ERROR cinder.volume.drivers.lightos     r = adapter.send(request, **kwargs)
2025-01-20 20:28:48.130 25 ERROR cinder.volume.drivers.lightos   File "/var/lib/kolla/venv/lib/python3.10/site-packages/requests/adapters.py", line 700, in send
2025-01-20 20:28:48.130 25 ERROR cinder.volume.drivers.lightos     raise ConnectionError(e, request=request)
2025-01-20 20:28:48.130 25 ERROR cinder.volume.drivers.lightos requests.exceptions.ConnectionError: HTTPSConnectionPool(host='[LB_IP_ADDRESS]', port=443): Max retries exceeded with url: /api/v2/clusterinfo (Caused by NewConnectionError('<urllib3.connection.HTTPSConnection object at 0x7efceaaa5bd0>: Failed to establish a new connection: [Errno 113] EHOSTUNREACH'))
2025-01-20 20:28:48.130 25 ERROR cinder.volume.drivers.lightos 
2025-01-20 20:28:48.136 25 INFO cinder.volume.drivers.lightos [None req-64f7749e-7efe-402d-9521-a6cc88b11e14 - - - - - -] Invoking get_cluster_info using GET url: /api/v2/clusterinfo             request.body: {} ssl_verify: False
2025-01-20 20:28:48.139 25 ERROR cinder.volume.drivers.lightos [None req-64f7749e-7efe-402d-9521-a6cc88b11e14 - - - - - -] REST server not responding at 'https://[LB_IP_ADDRESS]:443/api/v2/clusterinfo': requests.exceptions.ConnectionError: HTTPSConnectionPool(host='[LB_IP_ADDRESS]', port=443): Max retries exceeded with url: /api/v2/clusterinfo (Caused by NewConnectionError('<urllib3.connection.HTTPSConnection object at 0x7efceaaa4f10>: Failed to establish a new connection: [Errno 111] ECONNREFUSED'))
2025-01-20 20:28:48.139 25 ERROR cinder.volume.drivers.lightos Traceback (most recent call last):
2025-01-20 20:28:48.139 25 ERROR cinder.volume.drivers.lightos   File "/var/lib/kolla/venv/lib/python3.10/site-packages/urllib3/connection.py", line 174, in _new_conn
2025-01-20 20:28:48.139 25 ERROR cinder.volume.drivers.lightos     conn = connection.create_connection(
2025-01-20 20:28:48.139 25 ERROR cinder.volume.drivers.lightos   File "/var/lib/kolla/venv/lib/python3.10/site-packages/urllib3/util/connection.py", line 95, in create_connection
2025-01-20 20:28:48.139 25 ERROR cinder.volume.drivers.lightos     raise err
2025-01-20 20:28:48.139 25 ERROR cinder.volume.drivers.lightos   File "/var/lib/kolla/venv/lib/python3.10/site-packages/urllib3/util/connection.py", line 85, in create_connection
2025-01-20 20:28:48.139 25 ERROR cinder.volume.drivers.lightos     sock.connect(sa)
2025-01-20 20:28:48.139 25 ERROR cinder.volume.drivers.lightos   File "/var/lib/kolla/venv/lib/python3.10/site-packages/eventlet/greenio/base.py", line 265, in connect
2025-01-20 20:28:48.139 25 ERROR cinder.volume.drivers.lightos     socket_checkerr(fd)
2025-01-20 20:28:48.139 25 ERROR cinder.volume.drivers.lightos   File "/var/lib/kolla/venv/lib/python3.10/site-packages/eventlet/greenio/base.py", line 50, in socket_checkerr
2025-01-20 20:28:48.139 25 ERROR cinder.volume.drivers.lightos     raise OSError(err, errno.errorcode[err])
2025-01-20 20:28:48.139 25 ERROR cinder.volume.drivers.lightos ConnectionRefusedError: [Errno 111] ECONNREFUSED
2025-01-20 20:28:48.139 25 ERROR cinder.volume.drivers.lightos 
2025-01-20 20:28:48.139 25 ERROR cinder.volume.drivers.lightos During handling of the above exception, another exception occurred:
2025-01-20 20:28:48.139 25 ERROR cinder.volume.drivers.lightos 
2025-01-20 20:28:48.139 25 ERROR cinder.volume.drivers.lightos Traceback (most recent call last):
2025-01-20 20:28:48.139 25 ERROR cinder.volume.drivers.lightos   File "/var/lib/kolla/venv/lib/python3.10/site-packages/urllib3/connectionpool.py", line 715, in urlopen
2025-01-20 20:28:48.139 25 ERROR cinder.volume.drivers.lightos     httplib_response = self._make_request(
2025-01-20 20:28:48.139 25 ERROR cinder.volume.drivers.lightos   File "/var/lib/kolla/venv/lib/python3.10/site-packages/urllib3/connectionpool.py", line 404, in _make_request
2025-01-20 20:28:48.139 25 ERROR cinder.volume.drivers.lightos     self._validate_conn(conn)
2025-01-20 20:28:48.139 25 ERROR cinder.volume.drivers.lightos   File "/var/lib/kolla/venv/lib/python3.10/site-packages/urllib3/connectionpool.py", line 1060, in _validate_conn
2025-01-20 20:28:48.139 25 ERROR cinder.volume.drivers.lightos     conn.connect()
2025-01-20 20:28:48.139 25 ERROR cinder.volume.drivers.lightos   File "/var/lib/kolla/venv/lib/python3.10/site-packages/urllib3/connection.py", line 363, in connect
2025-01-20 20:28:48.139 25 ERROR cinder.volume.drivers.lightos     self.sock = conn = self._new_conn()
2025-01-20 20:28:48.139 25 ERROR cinder.volume.drivers.lightos   File "/var/lib/kolla/venv/lib/python3.10/site-packages/urllib3/connection.py", line 186, in _new_conn
2025-01-20 20:28:48.139 25 ERROR cinder.volume.drivers.lightos     raise NewConnectionError(
2025-01-20 20:28:48.139 25 ERROR cinder.volume.drivers.lightos urllib3.exceptions.NewConnectionError: <urllib3.connection.HTTPSConnection object at 0x7efceaaa4f10>: Failed to establish a new connection: [Errno 111] ECONNREFUSED
2025-01-20 20:28:48.139 25 ERROR cinder.volume.drivers.lightos 
2025-01-20 20:28:48.139 25 ERROR cinder.volume.drivers.lightos During handling of the above exception, another exception occurred:
2025-01-20 20:28:48.139 25 ERROR cinder.volume.drivers.lightos 
2025-01-20 20:28:48.139 25 ERROR cinder.volume.drivers.lightos Traceback (most recent call last):
2025-01-20 20:28:48.139 25 ERROR cinder.volume.drivers.lightos   File "/var/lib/kolla/venv/lib/python3.10/site-packages/requests/adapters.py", line 667, in send
2025-01-20 20:28:48.139 25 ERROR cinder.volume.drivers.lightos     resp = conn.urlopen(
2025-01-20 20:28:48.139 25 ERROR cinder.volume.drivers.lightos   File "/var/lib/kolla/venv/lib/python3.10/site-packages/urllib3/connectionpool.py", line 801, in urlopen
2025-01-20 20:28:48.139 25 ERROR cinder.volume.drivers.lightos     retries = retries.increment(
2025-01-20 20:28:48.139 25 ERROR cinder.volume.drivers.lightos   File "/var/lib/kolla/venv/lib/python3.10/site-packages/urllib3/util/retry.py", line 594, in increment
2025-01-20 20:28:48.139 25 ERROR cinder.volume.drivers.lightos     raise MaxRetryError(_pool, url, error or ResponseError(cause))
2025-01-20 20:28:48.139 25 ERROR cinder.volume.drivers.lightos urllib3.exceptions.MaxRetryError: HTTPSConnectionPool(host='[LB_IP_ADDRESS]', port=443): Max retries exceeded with url: /api/v2/clusterinfo (Caused by NewConnectionError('<urllib3.connection.HTTPSConnection object at 0x7efceaaa4f10>: Failed to establish a new connection: [Errno 111] ECONNREFUSED'))
2025-01-20 20:28:48.139 25 ERROR cinder.volume.drivers.lightos 
2025-01-20 20:28:48.139 25 ERROR cinder.volume.drivers.lightos During handling of the above exception, another exception occurred:
2025-01-20 20:28:48.139 25 ERROR cinder.volume.drivers.lightos 
2025-01-20 20:28:48.139 25 ERROR cinder.volume.drivers.lightos Traceback (most recent call last):
2025-01-20 20:28:48.139 25 ERROR cinder.volume.drivers.lightos   File "/var/lib/kolla/venv/lib/python3.10/site-packages/cinder/volume/drivers/lightos.py", line 356, in __send_cmd
2025-01-20 20:28:48.139 25 ERROR cinder.volume.drivers.lightos     response = session.send(
2025-01-20 20:28:48.139 25 ERROR cinder.volume.drivers.lightos   File "/var/lib/kolla/venv/lib/python3.10/site-packages/requests/sessions.py", line 703, in send
2025-01-20 20:28:48.139 25 ERROR cinder.volume.drivers.lightos     r = adapter.send(request, **kwargs)
2025-01-20 20:28:48.139 25 ERROR cinder.volume.drivers.lightos   File "/var/lib/kolla/venv/lib/python3.10/site-packages/requests/adapters.py", line 700, in send
2025-01-20 20:28:48.139 25 ERROR cinder.volume.drivers.lightos     raise ConnectionError(e, request=request)
2025-01-20 20:28:48.139 25 ERROR cinder.volume.drivers.lightos requests.exceptions.ConnectionError: HTTPSConnectionPool(host='[LB_IP_ADDRESS]', port=443): Max retries exceeded with url: /api/v2/clusterinfo (Caused by NewConnectionError('<urllib3.connection.HTTPSConnection object at 0x7efceaaa4f10>: Failed to establish a new connection: [Errno 111] ECONNREFUSED'))
2025-01-20 20:28:48.139 25 ERROR cinder.volume.drivers.lightos 
2025-01-20 20:28:48.141 25 INFO cinder.volume.drivers.lightos [None req-64f7749e-7efe-402d-9521-a6cc88b11e14 - - - - - -] Invoking get_cluster_info using GET url: /api/v2/clusterinfo             request.body: {} ssl_verify: False
2025-01-20 20:28:48.142 25 ERROR cinder.volume.drivers.lightos [None req-64f7749e-7efe-402d-9521-a6cc88b11e14 - - - - - -] REST server not responding at 'https://[LB_IP_ADDRESS]:443/api/v2/clusterinfo': requests.exceptions.ConnectionError: HTTPSConnectionPool(host='[LB_IP_ADDRESS]', port=443): Max retries exceeded with url: /api/v2/clusterinfo (Caused by NewConnectionError('<urllib3.connection.HTTPSConnection object at 0x7efceaaa4430>: Failed to establish a new connection: [Errno 111] ECONNREFUSED'))
2025-01-20 20:28:48.142 25 ERROR cinder.volume.drivers.lightos Traceback (most recent call last):
2025-01-20 20:28:48.142 25 ERROR cinder.volume.drivers.lightos   File "/var/lib/kolla/venv/lib/python3.10/site-packages/urllib3/connection.py", line 174, in _new_conn
2025-01-20 20:28:48.142 25 ERROR cinder.volume.drivers.lightos     conn = connection.create_connection(
2025-01-20 20:28:48.142 25 ERROR cinder.volume.drivers.lightos   File "/var/lib/kolla/venv/lib/python3.10/site-packages/urllib3/util/connection.py", line 95, in create_connection
2025-01-20 20:28:48.142 25 ERROR cinder.volume.drivers.lightos     raise err
2025-01-20 20:28:48.142 25 ERROR cinder.volume.drivers.lightos   File "/var/lib/kolla/venv/lib/python3.10/site-packages/urllib3/util/connection.py", line 85, in create_connection
2025-01-20 20:28:48.142 25 ERROR cinder.volume.drivers.lightos     sock.connect(sa)
2025-01-20 20:28:48.142 25 ERROR cinder.volume.drivers.lightos   File "/var/lib/kolla/venv/lib/python3.10/site-packages/eventlet/greenio/base.py", line 265, in connect
2025-01-20 20:28:48.142 25 ERROR cinder.volume.drivers.lightos     socket_checkerr(fd)
2025-01-20 20:28:48.142 25 ERROR cinder.volume.drivers.lightos   File "/var/lib/kolla/venv/lib/python3.10/site-packages/eventlet/greenio/base.py", line 50, in socket_checkerr
2025-01-20 20:28:48.142 25 ERROR cinder.volume.drivers.lightos     raise OSError(err, errno.errorcode[err])
2025-01-20 20:28:48.142 25 ERROR cinder.volume.drivers.lightos ConnectionRefusedError: [Errno 111] ECONNREFUSED
2025-01-20 20:28:48.142 25 ERROR cinder.volume.drivers.lightos 
2025-01-20 20:28:48.142 25 ERROR cinder.volume.drivers.lightos During handling of the above exception, another exception occurred:
2025-01-20 20:28:48.142 25 ERROR cinder.volume.drivers.lightos 
2025-01-20 20:28:48.142 25 ERROR cinder.volume.drivers.lightos Traceback (most recent call last):
2025-01-20 20:28:48.142 25 ERROR cinder.volume.drivers.lightos   File "/var/lib/kolla/venv/lib/python3.10/site-packages/urllib3/connectionpool.py", line 715, in urlopen
2025-01-20 20:28:48.142 25 ERROR cinder.volume.drivers.lightos     httplib_response = self._make_request(
2025-01-20 20:28:48.142 25 ERROR cinder.volume.drivers.lightos   File "/var/lib/kolla/venv/lib/python3.10/site-packages/urllib3/connectionpool.py", line 404, in _make_request
2025-01-20 20:28:48.142 25 ERROR cinder.volume.drivers.lightos     self._validate_conn(conn)
2025-01-20 20:28:48.142 25 ERROR cinder.volume.drivers.lightos   File "/var/lib/kolla/venv/lib/python3.10/site-packages/urllib3/connectionpool.py", line 1060, in _validate_conn
2025-01-20 20:28:48.142 25 ERROR cinder.volume.drivers.lightos     conn.connect()
2025-01-20 20:28:48.142 25 ERROR cinder.volume.drivers.lightos   File "/var/lib/kolla/venv/lib/python3.10/site-packages/urllib3/connection.py", line 363, in connect
2025-01-20 20:28:48.142 25 ERROR cinder.volume.drivers.lightos     self.sock = conn = self._new_conn()
2025-01-20 20:28:48.142 25 ERROR cinder.volume.drivers.lightos   File "/var/lib/kolla/venv/lib/python3.10/site-packages/urllib3/connection.py", line 186, in _new_conn
2025-01-20 20:28:48.142 25 ERROR cinder.volume.drivers.lightos     raise NewConnectionError(
2025-01-20 20:28:48.142 25 ERROR cinder.volume.drivers.lightos urllib3.exceptions.NewConnectionError: <urllib3.connection.HTTPSConnection object at 0x7efceaaa4430>: Failed to establish a new connection: [Errno 111] ECONNREFUSED
2025-01-20 20:28:48.142 25 ERROR cinder.volume.drivers.lightos 
2025-01-20 20:28:48.142 25 ERROR cinder.volume.drivers.lightos During handling of the above exception, another exception occurred:
2025-01-20 20:28:48.142 25 ERROR cinder.volume.drivers.lightos 
2025-01-20 20:28:48.142 25 ERROR cinder.volume.drivers.lightos Traceback (most recent call last):
2025-01-20 20:28:48.142 25 ERROR cinder.volume.drivers.lightos   File "/var/lib/kolla/venv/lib/python3.10/site-packages/requests/adapters.py", line 667, in send
2025-01-20 20:28:48.142 25 ERROR cinder.volume.drivers.lightos     resp = conn.urlopen(
2025-01-20 20:28:48.142 25 ERROR cinder.volume.drivers.lightos   File "/var/lib/kolla/venv/lib/python3.10/site-packages/urllib3/connectionpool.py", line 801, in urlopen
2025-01-20 20:28:48.142 25 ERROR cinder.volume.drivers.lightos     retries = retries.increment(
2025-01-20 20:28:48.142 25 ERROR cinder.volume.drivers.lightos   File "/var/lib/kolla/venv/lib/python3.10/site-packages/urllib3/util/retry.py", line 594, in increment
2025-01-20 20:28:48.142 25 ERROR cinder.volume.drivers.lightos     raise MaxRetryError(_pool, url, error or ResponseError(cause))
2025-01-20 20:28:48.142 25 ERROR cinder.volume.drivers.lightos urllib3.exceptions.MaxRetryError: HTTPSConnectionPool(host='[LB_IP_ADDRESS]', port=443): Max retries exceeded with url: /api/v2/clusterinfo (Caused by NewConnectionError('<urllib3.connection.HTTPSConnection object at 0x7efceaaa4430>: Failed to establish a new connection: [Errno 111] ECONNREFUSED'))
2025-01-20 20:28:48.142 25 ERROR cinder.volume.drivers.lightos 
2025-01-20 20:28:48.142 25 ERROR cinder.volume.drivers.lightos During handling of the above exception, another exception occurred:
2025-01-20 20:28:48.142 25 ERROR cinder.volume.drivers.lightos 
2025-01-20 20:28:48.142 25 ERROR cinder.volume.drivers.lightos Traceback (most recent call last):
2025-01-20 20:28:48.142 25 ERROR cinder.volume.drivers.lightos   File "/var/lib/kolla/venv/lib/python3.10/site-packages/cinder/volume/drivers/lightos.py", line 356, in __send_cmd
2025-01-20 20:28:48.142 25 ERROR cinder.volume.drivers.lightos     response = session.send(
2025-01-20 20:28:48.142 25 ERROR cinder.volume.drivers.lightos   File "/var/lib/kolla/venv/lib/python3.10/site-packages/requests/sessions.py", line 703, in send
2025-01-20 20:28:48.142 25 ERROR cinder.volume.drivers.lightos     r = adapter.send(request, **kwargs)
2025-01-20 20:28:48.142 25 ERROR cinder.volume.drivers.lightos   File "/var/lib/kolla/venv/lib/python3.10/site-packages/requests/adapters.py", line 700, in send
2025-01-20 20:28:48.142 25 ERROR cinder.volume.drivers.lightos     raise ConnectionError(e, request=request)
2025-01-20 20:28:48.142 25 ERROR cinder.volume.drivers.lightos requests.exceptions.ConnectionError: HTTPSConnectionPool(host='[LB_IP_ADDRESS]', port=443): Max retries exceeded with url: /api/v2/clusterinfo (Caused by NewConnectionError('<urllib3.connection.HTTPSConnection object at 0x7efceaaa4430>: Failed to establish a new connection: [Errno 111] ECONNREFUSED'))
2025-01-20 20:28:48.142 25 ERROR cinder.volume.drivers.lightos 
2025-01-20 20:28:48.143 25 ERROR cinder.volume.manager [None req-64f7749e-7efe-402d-9521-a6cc88b11e14 - - - - - -] Failed to initialize driver.: cinder.exception.VolumeDriverException: Volume driver reported an error: Could not get a response from any API server
2025-01-20 20:28:48.143 25 ERROR cinder.volume.manager Traceback (most recent call last):
2025-01-20 20:28:48.143 25 ERROR cinder.volume.manager   File "/var/lib/kolla/venv/lib/python3.10/site-packages/cinder/volume/manager.py", line 523, in _init_host
2025-01-20 20:28:48.143 25 ERROR cinder.volume.manager     self.driver.do_setup(ctxt)
2025-01-20 20:28:48.143 25 ERROR cinder.volume.manager   File "/var/lib/kolla/venv/lib/python3.10/site-packages/cinder/volume/drivers/lightos.py", line 922, in do_setup
2025-01-20 20:28:48.143 25 ERROR cinder.volume.manager     self.get_cluster_info()
2025-01-20 20:28:48.143 25 ERROR cinder.volume.manager   File "/var/lib/kolla/venv/lib/python3.10/site-packages/cinder/volume/drivers/lightos.py", line 873, in get_cluster_info
2025-01-20 20:28:48.143 25 ERROR cinder.volume.manager     status_code, cluster_info = self.cluster.send_cmd(
2025-01-20 20:28:48.143 25 ERROR cinder.volume.manager   File "/var/lib/kolla/venv/lib/python3.10/site-packages/cinder/volume/drivers/lightos.py", line 315, in send_cmd
2025-01-20 20:28:48.143 25 ERROR cinder.volume.manager     raise exception.VolumeDriverException(
2025-01-20 20:28:48.143 25 ERROR cinder.volume.manager cinder.exception.VolumeDriverException: Volume driver reported an error: Could not get a response from any API server
2025-01-20 20:28:48.143 25 ERROR cinder.volume.manager 
2025-01-20 20:28:49.147 25 INFO cinder.volume.manager [None req-64f7749e-7efe-402d-9521-a6cc88b11e14 - - - - - -] Starting volume driver LightOSVolumeDriver (2.3.12)
2025-01-20 20:28:49.148 25 INFO cinder.volume.drivers.lightos [None req-64f7749e-7efe-402d-9521-a6cc88b11e14 - - - - - -] Invoking get_cluster_info using GET url: /api/v2/clusterinfo             request.body: {} ssl_verify: False
2025-01-20 20:28:51.201 25 ERROR cinder.volume.drivers.lightos [None req-64f7749e-7efe-402d-9521-a6cc88b11e14 - - - - - -] REST server not responding at 'https://[LB_IP_ADDRESS]:443/api/v2/clusterinfo': requests.exceptions.ConnectionError: HTTPSConnectionPool(host='[LB_IP_ADDRESS]', port=443): Max retries exceeded with url: /api/v2/clusterinfo (Caused by NewConnectionError('<urllib3.connection.HTTPSConnection object at 0x7efceaaa47c0>: Failed to establish a new connection: [Errno 113] EHOSTUNREACH'))
2025-01-20 20:28:51.201 25 ERROR cinder.volume.drivers.lightos Traceback (most recent call last):
2025-01-20 20:28:51.201 25 ERROR cinder.volume.drivers.lightos   File "/var/lib/kolla/venv/lib/python3.10/site-packages/urllib3/connection.py", line 174, in _new_conn
2025-01-20 20:28:51.201 25 ERROR cinder.volume.drivers.lightos     conn = connection.create_connection(
2025-01-20 20:28:51.201 25 ERROR cinder.volume.drivers.lightos   File "/var/lib/kolla/venv/lib/python3.10/site-packages/urllib3/util/connection.py", line 95, in create_connection
2025-01-20 20:28:51.201 25 ERROR cinder.volume.drivers.lightos     raise err
2025-01-20 20:28:51.201 25 ERROR cinder.volume.drivers.lightos   File "/var/lib/kolla/venv/lib/python3.10/site-packages/urllib3/util/connection.py", line 85, in create_connection
2025-01-20 20:28:51.201 25 ERROR cinder.volume.drivers.lightos     sock.connect(sa)
2025-01-20 20:28:51.201 25 ERROR cinder.volume.drivers.lightos   File "/var/lib/kolla/venv/lib/python3.10/site-packages/eventlet/greenio/base.py", line 265, in connect
2025-01-20 20:28:51.201 25 ERROR cinder.volume.drivers.lightos     socket_checkerr(fd)
2025-01-20 20:28:51.201 25 ERROR cinder.volume.drivers.lightos   File "/var/lib/kolla/venv/lib/python3.10/site-packages/eventlet/greenio/base.py", line 50, in socket_checkerr
2025-01-20 20:28:51.201 25 ERROR cinder.volume.drivers.lightos     raise OSError(err, errno.errorcode[err])
2025-01-20 20:28:51.201 25 ERROR cinder.volume.drivers.lightos OSError: [Errno 113] EHOSTUNREACH
2025-01-20 20:28:51.201 25 ERROR cinder.volume.drivers.lightos 
2025-01-20 20:28:51.201 25 ERROR cinder.volume.drivers.lightos During handling of the above exception, another exception occurred:
2025-01-20 20:28:51.201 25 ERROR cinder.volume.drivers.lightos 
2025-01-20 20:28:51.201 25 ERROR cinder.volume.drivers.lightos Traceback (most recent call last):
2025-01-20 20:28:51.201 25 ERROR cinder.volume.drivers.lightos   File "/var/lib/kolla/venv/lib/python3.10/site-packages/urllib3/connectionpool.py", line 715, in urlopen
2025-01-20 20:28:51.201 25 ERROR cinder.volume.drivers.lightos     httplib_response = self._make_request(
2025-01-20 20:28:51.201 25 ERROR cinder.volume.drivers.lightos   File "/var/lib/kolla/venv/lib/python3.10/site-packages/urllib3/connectionpool.py", line 404, in _make_request
2025-01-20 20:28:51.201 25 ERROR cinder.volume.drivers.lightos     self._validate_conn(conn)
2025-01-20 20:28:51.201 25 ERROR cinder.volume.drivers.lightos   File "/var/lib/kolla/venv/lib/python3.10/site-packages/urllib3/connectionpool.py", line 1060, in _validate_conn
2025-01-20 20:28:51.201 25 ERROR cinder.volume.drivers.lightos     conn.connect()
2025-01-20 20:28:51.201 25 ERROR cinder.volume.drivers.lightos   File "/var/lib/kolla/venv/lib/python3.10/site-packages/urllib3/connection.py", line 363, in connect
2025-01-20 20:28:51.201 25 ERROR cinder.volume.drivers.lightos     self.sock = conn = self._new_conn()
2025-01-20 20:28:51.201 25 ERROR cinder.volume.drivers.lightos   File "/var/lib/kolla/venv/lib/python3.10/site-packages/urllib3/connection.py", line 186, in _new_conn
2025-01-20 20:28:51.201 25 ERROR cinder.volume.drivers.lightos     raise NewConnectionError(
2025-01-20 20:28:51.201 25 ERROR cinder.volume.drivers.lightos urllib3.exceptions.NewConnectionError: <urllib3.connection.HTTPSConnection object at 0x7efceaaa47c0>: Failed to establish a new connection: [Errno 113] EHOSTUNREACH
2025-01-20 20:28:51.201 25 ERROR cinder.volume.drivers.lightos 
2025-01-20 20:28:51.201 25 ERROR cinder.volume.drivers.lightos During handling of the above exception, another exception occurred:
2025-01-20 20:28:51.201 25 ERROR cinder.volume.drivers.lightos 
2025-01-20 20:28:51.201 25 ERROR cinder.volume.drivers.lightos Traceback (most recent call last):
2025-01-20 20:28:51.201 25 ERROR cinder.volume.drivers.lightos   File "/var/lib/kolla/venv/lib/python3.10/site-packages/requests/adapters.py", line 667, in send
2025-01-20 20:28:51.201 25 ERROR cinder.volume.drivers.lightos     resp = conn.urlopen(
2025-01-20 20:28:51.201 25 ERROR cinder.volume.drivers.lightos   File "/var/lib/kolla/venv/lib/python3.10/site-packages/urllib3/connectionpool.py", line 801, in urlopen
2025-01-20 20:28:51.201 25 ERROR cinder.volume.drivers.lightos     retries = retries.increment(
2025-01-20 20:28:51.201 25 ERROR cinder.volume.drivers.lightos   File "/var/lib/kolla/venv/lib/python3.10/site-packages/urllib3/util/retry.py", line 594, in increment
2025-01-20 20:28:51.201 25 ERROR cinder.volume.drivers.lightos     raise MaxRetryError(_pool, url, error or ResponseError(cause))
2025-01-20 20:28:51.201 25 ERROR cinder.volume.drivers.lightos urllib3.exceptions.MaxRetryError: HTTPSConnectionPool(host='[LB_IP_ADDRESS]', port=443): Max retries exceeded with url: /api/v2/clusterinfo (Caused by NewConnectionError('<urllib3.connection.HTTPSConnection object at 0x7efceaaa47c0>: Failed to establish a new connection: [Errno 113] EHOSTUNREACH'))
2025-01-20 20:28:51.201 25 ERROR cinder.volume.drivers.lightos 
2025-01-20 20:28:51.201 25 ERROR cinder.volume.drivers.lightos During handling of the above exception, another exception occurred:
2025-01-20 20:28:51.201 25 ERROR cinder.volume.drivers.lightos 
2025-01-20 20:28:51.201 25 ERROR cinder.volume.drivers.lightos Traceback (most recent call last):
2025-01-20 20:28:51.201 25 ERROR cinder.volume.drivers.lightos   File "/var/lib/kolla/venv/lib/python3.10/site-packages/cinder/volume/drivers/lightos.py", line 356, in __send_cmd
2025-01-20 20:28:51.201 25 ERROR cinder.volume.drivers.lightos     response = session.send(
2025-01-20 20:28:51.201 25 ERROR cinder.volume.drivers.lightos   File "/var/lib/kolla/venv/lib/python3.10/site-packages/requests/sessions.py", line 703, in send
2025-01-20 20:28:51.201 25 ERROR cinder.volume.drivers.lightos     r = adapter.send(request, **kwargs)
2025-01-20 20:28:51.201 25 ERROR cinder.volume.drivers.lightos   File "/var/lib/kolla/venv/lib/python3.10/site-packages/requests/adapters.py", line 700, in send
2025-01-20 20:28:51.201 25 ERROR cinder.volume.drivers.lightos     raise ConnectionError(e, request=request)
2025-01-20 20:28:51.201 25 ERROR cinder.volume.drivers.lightos requests.exceptions.ConnectionError: HTTPSConnectionPool(host='[LB_IP_ADDRESS]', port=443): Max retries exceeded with url: /api/v2/clusterinfo (Caused by NewConnectionError('<urllib3.connection.HTTPSConnection object at 0x7efceaaa47c0>: Failed to establish a new connection: [Errno 113] EHOSTUNREACH'))
2025-01-20 20:28:51.201 25 ERROR cinder.volume.drivers.lightos 
2025-01-20 20:28:51.204 25 INFO cinder.volume.drivers.lightos [None req-64f7749e-7efe-402d-9521-a6cc88b11e14 - - - - - -] Invoking get_cluster_info using GET url: /api/v2/clusterinfo             request.body: {} ssl_verify: False
2025-01-20 20:28:51.207 25 ERROR cinder.volume.drivers.lightos [None req-64f7749e-7efe-402d-9521-a6cc88b11e14 - - - - - -] REST server not responding at 'https://[LB_IP_ADDRESS]:443/api/v2/clusterinfo': requests.exceptions.ConnectionError: HTTPSConnectionPool(host='[LB_IP_ADDRESS]', port=443): Max retries exceeded with url: /api/v2/clusterinfo (Caused by NewConnectionError('<urllib3.connection.HTTPSConnection object at 0x7efceaaa5210>: Failed to establish a new connection: [Errno 111] ECONNREFUSED'))
2025-01-20 20:28:51.207 25 ERROR cinder.volume.drivers.lightos Traceback (most recent call last):
2025-01-20 20:28:51.207 25 ERROR cinder.volume.drivers.lightos   File "/var/lib/kolla/venv/lib/python3.10/site-packages/urllib3/connection.py", line 174, in _new_conn
2025-01-20 20:28:51.207 25 ERROR cinder.volume.drivers.lightos     conn = connection.create_connection(
2025-01-20 20:28:51.207 25 ERROR cinder.volume.drivers.lightos   File "/var/lib/kolla/venv/lib/python3.10/site-packages/urllib3/util/connection.py", line 95, in create_connection
2025-01-20 20:28:51.207 25 ERROR cinder.volume.drivers.lightos     raise err
2025-01-20 20:28:51.207 25 ERROR cinder.volume.drivers.lightos   File "/var/lib/kolla/venv/lib/python3.10/site-packages/urllib3/util/connection.py", line 85, in create_connection
2025-01-20 20:28:51.207 25 ERROR cinder.volume.drivers.lightos     sock.connect(sa)
2025-01-20 20:28:51.207 25 ERROR cinder.volume.drivers.lightos   File "/var/lib/kolla/venv/lib/python3.10/site-packages/eventlet/greenio/base.py", line 265, in connect
2025-01-20 20:28:51.207 25 ERROR cinder.volume.drivers.lightos     socket_checkerr(fd)
2025-01-20 20:28:51.207 25 ERROR cinder.volume.drivers.lightos   File "/var/lib/kolla/venv/lib/python3.10/site-packages/eventlet/greenio/base.py", line 50, in socket_checkerr
2025-01-20 20:28:51.207 25 ERROR cinder.volume.drivers.lightos     raise OSError(err, errno.errorcode[err])
2025-01-20 20:28:51.207 25 ERROR cinder.volume.drivers.lightos ConnectionRefusedError: [Errno 111] ECONNREFUSED
2025-01-20 20:28:51.207 25 ERROR cinder.volume.drivers.lightos 
2025-01-20 20:28:51.207 25 ERROR cinder.volume.drivers.lightos During handling of the above exception, another exception occurred:
2025-01-20 20:28:51.207 25 ERROR cinder.volume.drivers.lightos 
2025-01-20 20:28:51.207 25 ERROR cinder.volume.drivers.lightos Traceback (most recent call last):
2025-01-20 20:28:51.207 25 ERROR cinder.volume.drivers.lightos   File "/var/lib/kolla/venv/lib/python3.10/site-packages/urllib3/connectionpool.py", line 715, in urlopen
2025-01-20 20:28:51.207 25 ERROR cinder.volume.drivers.lightos     httplib_response = self._make_request(
2025-01-20 20:28:51.207 25 ERROR cinder.volume.drivers.lightos   File "/var/lib/kolla/venv/lib/python3.10/site-packages/urllib3/connectionpool.py", line 404, in _make_request
2025-01-20 20:28:51.207 25 ERROR cinder.volume.drivers.lightos     self._validate_conn(conn)
2025-01-20 20:28:51.207 25 ERROR cinder.volume.drivers.lightos   File "/var/lib/kolla/venv/lib/python3.10/site-packages/urllib3/connectionpool.py", line 1060, in _validate_conn
2025-01-20 20:28:51.207 25 ERROR cinder.volume.drivers.lightos     conn.connect()
2025-01-20 20:28:51.207 25 ERROR cinder.volume.drivers.lightos   File "/var/lib/kolla/venv/lib/python3.10/site-packages/urllib3/connection.py", line 363, in connect
2025-01-20 20:28:51.207 25 ERROR cinder.volume.drivers.lightos     self.sock = conn = self._new_conn()
2025-01-20 20:28:51.207 25 ERROR cinder.volume.drivers.lightos   File "/var/lib/kolla/venv/lib/python3.10/site-packages/urllib3/connection.py", line 186, in _new_conn
2025-01-20 20:28:51.207 25 ERROR cinder.volume.drivers.lightos     raise NewConnectionError(
2025-01-20 20:28:51.207 25 ERROR cinder.volume.drivers.lightos urllib3.exceptions.NewConnectionError: <urllib3.connection.HTTPSConnection object at 0x7efceaaa5210>: Failed to establish a new connection: [Errno 111] ECONNREFUSED
2025-01-20 20:28:51.207 25 ERROR cinder.volume.drivers.lightos 
2025-01-20 20:28:51.207 25 ERROR cinder.volume.drivers.lightos During handling of the above exception, another exception occurred:
2025-01-20 20:28:51.207 25 ERROR cinder.volume.drivers.lightos 
2025-01-20 20:28:51.207 25 ERROR cinder.volume.drivers.lightos Traceback (most recent call last):
2025-01-20 20:28:51.207 25 ERROR cinder.volume.drivers.lightos   File "/var/lib/kolla/venv/lib/python3.10/site-packages/requests/adapters.py", line 667, in send
2025-01-20 20:28:51.207 25 ERROR cinder.volume.drivers.lightos     resp = conn.urlopen(
2025-01-20 20:28:51.207 25 ERROR cinder.volume.drivers.lightos   File "/var/lib/kolla/venv/lib/python3.10/site-packages/urllib3/connectionpool.py", line 801, in urlopen
2025-01-20 20:28:51.207 25 ERROR cinder.volume.drivers.lightos     retries = retries.increment(
2025-01-20 20:28:51.207 25 ERROR cinder.volume.drivers.lightos   File "/var/lib/kolla/venv/lib/python3.10/site-packages/urllib3/util/retry.py", line 594, in increment
2025-01-20 20:28:51.207 25 ERROR cinder.volume.drivers.lightos     raise MaxRetryError(_pool, url, error or ResponseError(cause))
2025-01-20 20:28:51.207 25 ERROR cinder.volume.drivers.lightos urllib3.exceptions.MaxRetryError: HTTPSConnectionPool(host='[LB_IP_ADDRESS]', port=443): Max retries exceeded with url: /api/v2/clusterinfo (Caused by NewConnectionError('<urllib3.connection.HTTPSConnection object at 0x7efceaaa5210>: Failed to establish a new connection: [Errno 111] ECONNREFUSED'))
2025-01-20 20:28:51.207 25 ERROR cinder.volume.drivers.lightos 
2025-01-20 20:28:51.207 25 ERROR cinder.volume.drivers.lightos During handling of the above exception, another exception occurred:
2025-01-20 20:28:51.207 25 ERROR cinder.volume.drivers.lightos 
2025-01-20 20:28:51.207 25 ERROR cinder.volume.drivers.lightos Traceback (most recent call last):
2025-01-20 20:28:51.207 25 ERROR cinder.volume.drivers.lightos   File "/var/lib/kolla/venv/lib/python3.10/site-packages/cinder/volume/drivers/lightos.py", line 356, in __send_cmd
2025-01-20 20:28:51.207 25 ERROR cinder.volume.drivers.lightos     response = session.send(
2025-01-20 20:28:51.207 25 ERROR cinder.volume.drivers.lightos   File "/var/lib/kolla/venv/lib/python3.10/site-packages/requests/sessions.py", line 703, in send
2025-01-20 20:28:51.207 25 ERROR cinder.volume.drivers.lightos     r = adapter.send(request, **kwargs)
2025-01-20 20:28:51.207 25 ERROR cinder.volume.drivers.lightos   File "/var/lib/kolla/venv/lib/python3.10/site-packages/requests/adapters.py", line 700, in send
2025-01-20 20:28:51.207 25 ERROR cinder.volume.drivers.lightos     raise ConnectionError(e, request=request)
2025-01-20 20:28:51.207 25 ERROR cinder.volume.drivers.lightos requests.exceptions.ConnectionError: HTTPSConnectionPool(host='[LB_IP_ADDRESS]', port=443): Max retries exceeded with url: /api/v2/clusterinfo (Caused by NewConnectionError('<urllib3.connection.HTTPSConnection object at 0x7efceaaa5210>: Failed to establish a new connection: [Errno 111] ECONNREFUSED'))
2025-01-20 20:28:51.207 25 ERROR cinder.volume.drivers.lightos 
2025-01-20 20:28:51.209 25 INFO cinder.volume.drivers.lightos [None req-64f7749e-7efe-402d-9521-a6cc88b11e14 - - - - - -] Invoking get_cluster_info using GET url: /api/v2/clusterinfo             request.body: {} ssl_verify: False
2025-01-20 20:28:51.211 25 ERROR cinder.volume.drivers.lightos [None req-64f7749e-7efe-402d-9521-a6cc88b11e14 - - - - - -] REST server not responding at 'https://[LB_IP_ADDRESS]:443/api/v2/clusterinfo': requests.exceptions.ConnectionError: HTTPSConnectionPool(host='[LB_IP_ADDRESS]', port=443): Max retries exceeded with url: /api/v2/clusterinfo (Caused by NewConnectionError('<urllib3.connection.HTTPSConnection object at 0x7efceaaa6290>: Failed to establish a new connection: [Errno 111] ECONNREFUSED'))
2025-01-20 20:28:51.211 25 ERROR cinder.volume.drivers.lightos Traceback (most recent call last):
2025-01-20 20:28:51.211 25 ERROR cinder.volume.drivers.lightos   File "/var/lib/kolla/venv/lib/python3.10/site-packages/urllib3/connection.py", line 174, in _new_conn
2025-01-20 20:28:51.211 25 ERROR cinder.volume.drivers.lightos     conn = connection.create_connection(
2025-01-20 20:28:51.211 25 ERROR cinder.volume.drivers.lightos   File "/var/lib/kolla/venv/lib/python3.10/site-packages/urllib3/util/connection.py", line 95, in create_connection
2025-01-20 20:28:51.211 25 ERROR cinder.volume.drivers.lightos     raise err
2025-01-20 20:28:51.211 25 ERROR cinder.volume.drivers.lightos   File "/var/lib/kolla/venv/lib/python3.10/site-packages/urllib3/util/connection.py", line 85, in create_connection
2025-01-20 20:28:51.211 25 ERROR cinder.volume.drivers.lightos     sock.connect(sa)
2025-01-20 20:28:51.211 25 ERROR cinder.volume.drivers.lightos   File "/var/lib/kolla/venv/lib/python3.10/site-packages/eventlet/greenio/base.py", line 265, in connect
2025-01-20 20:28:51.211 25 ERROR cinder.volume.drivers.lightos     socket_checkerr(fd)
2025-01-20 20:28:51.211 25 ERROR cinder.volume.drivers.lightos   File "/var/lib/kolla/venv/lib/python3.10/site-packages/eventlet/greenio/base.py", line 50, in socket_checkerr
2025-01-20 20:28:51.211 25 ERROR cinder.volume.drivers.lightos     raise OSError(err, errno.errorcode[err])
2025-01-20 20:28:51.211 25 ERROR cinder.volume.drivers.lightos ConnectionRefusedError: [Errno 111] ECONNREFUSED
2025-01-20 20:28:51.211 25 ERROR cinder.volume.drivers.lightos 
2025-01-20 20:28:51.211 25 ERROR cinder.volume.drivers.lightos During handling of the above exception, another exception occurred:
2025-01-20 20:28:51.211 25 ERROR cinder.volume.drivers.lightos 
2025-01-20 20:28:51.211 25 ERROR cinder.volume.drivers.lightos Traceback (most recent call last):
2025-01-20 20:28:51.211 25 ERROR cinder.volume.drivers.lightos   File "/var/lib/kolla/venv/lib/python3.10/site-packages/urllib3/connectionpool.py", line 715, in urlopen
2025-01-20 20:28:51.211 25 ERROR cinder.volume.drivers.lightos     httplib_response = self._make_request(
2025-01-20 20:28:51.211 25 ERROR cinder.volume.drivers.lightos   File "/var/lib/kolla/venv/lib/python3.10/site-packages/urllib3/connectionpool.py", line 404, in _make_request
2025-01-20 20:28:51.211 25 ERROR cinder.volume.drivers.lightos     self._validate_conn(conn)
2025-01-20 20:28:51.211 25 ERROR cinder.volume.drivers.lightos   File "/var/lib/kolla/venv/lib/python3.10/site-packages/urllib3/connectionpool.py", line 1060, in _validate_conn
2025-01-20 20:28:51.211 25 ERROR cinder.volume.drivers.lightos     conn.connect()
2025-01-20 20:28:51.211 25 ERROR cinder.volume.drivers.lightos   File "/var/lib/kolla/venv/lib/python3.10/site-packages/urllib3/connection.py", line 363, in connect
2025-01-20 20:28:51.211 25 ERROR cinder.volume.drivers.lightos     self.sock = conn = self._new_conn()
2025-01-20 20:28:51.211 25 ERROR cinder.volume.drivers.lightos   File "/var/lib/kolla/venv/lib/python3.10/site-packages/urllib3/connection.py", line 186, in _new_conn
2025-01-20 20:28:51.211 25 ERROR cinder.volume.drivers.lightos     raise NewConnectionError(
2025-01-20 20:28:51.211 25 ERROR cinder.volume.drivers.lightos urllib3.exceptions.NewConnectionError: <urllib3.connection.HTTPSConnection object at 0x7efceaaa6290>: Failed to establish a new connection: [Errno 111] ECONNREFUSED
2025-01-20 20:28:51.211 25 ERROR cinder.volume.drivers.lightos 
2025-01-20 20:28:51.211 25 ERROR cinder.volume.drivers.lightos During handling of the above exception, another exception occurred:
2025-01-20 20:28:51.211 25 ERROR cinder.volume.drivers.lightos 
2025-01-20 20:28:51.211 25 ERROR cinder.volume.drivers.lightos Traceback (most recent call last):
2025-01-20 20:28:51.211 25 ERROR cinder.volume.drivers.lightos   File "/var/lib/kolla/venv/lib/python3.10/site-packages/requests/adapters.py", line 667, in send
2025-01-20 20:28:51.211 25 ERROR cinder.volume.drivers.lightos     resp = conn.urlopen(
2025-01-20 20:28:51.211 25 ERROR cinder.volume.drivers.lightos   File "/var/lib/kolla/venv/lib/python3.10/site-packages/urllib3/connectionpool.py", line 801, in urlopen
2025-01-20 20:28:51.211 25 ERROR cinder.volume.drivers.lightos     retries = retries.increment(
2025-01-20 20:28:51.211 25 ERROR cinder.volume.drivers.lightos   File "/var/lib/kolla/venv/lib/python3.10/site-packages/urllib3/util/retry.py", line 594, in increment
2025-01-20 20:28:51.211 25 ERROR cinder.volume.drivers.lightos     raise MaxRetryError(_pool, url, error or ResponseError(cause))
2025-01-20 20:28:51.211 25 ERROR cinder.volume.drivers.lightos urllib3.exceptions.MaxRetryError: HTTPSConnectionPool(host='[LB_IP_ADDRESS]', port=443): Max retries exceeded with url: /api/v2/clusterinfo (Caused by NewConnectionError('<urllib3.connection.HTTPSConnection object at 0x7efceaaa6290>: Failed to establish a new connection: [Errno 111] ECONNREFUSED'))
2025-01-20 20:28:51.211 25 ERROR cinder.volume.drivers.lightos 
2025-01-20 20:28:51.211 25 ERROR cinder.volume.drivers.lightos During handling of the above exception, another exception occurred:
2025-01-20 20:28:51.211 25 ERROR cinder.volume.drivers.lightos 
2025-01-20 20:28:51.211 25 ERROR cinder.volume.drivers.lightos Traceback (most recent call last):
2025-01-20 20:28:51.211 25 ERROR cinder.volume.drivers.lightos   File "/var/lib/kolla/venv/lib/python3.10/site-packages/cinder/volume/drivers/lightos.py", line 356, in __send_cmd
2025-01-20 20:28:51.211 25 ERROR cinder.volume.drivers.lightos     response = session.send(
2025-01-20 20:28:51.211 25 ERROR cinder.volume.drivers.lightos   File "/var/lib/kolla/venv/lib/python3.10/site-packages/requests/sessions.py", line 703, in send
2025-01-20 20:28:51.211 25 ERROR cinder.volume.drivers.lightos     r = adapter.send(request, **kwargs)
2025-01-20 20:28:51.211 25 ERROR cinder.volume.drivers.lightos   File "/var/lib/kolla/venv/lib/python3.10/site-packages/requests/adapters.py", line 700, in send
2025-01-20 20:28:51.211 25 ERROR cinder.volume.drivers.lightos     raise ConnectionError(e, request=request)
2025-01-20 20:28:51.211 25 ERROR cinder.volume.drivers.lightos requests.exceptions.ConnectionError: HTTPSConnectionPool(host='[LB_IP_ADDRESS]', port=443): Max retries exceeded with url: /api/v2/clusterinfo (Caused by NewConnectionError('<urllib3.connection.HTTPSConnection object at 0x7efceaaa6290>: Failed to establish a new connection: [Errno 111] ECONNREFUSED'))
2025-01-20 20:28:51.211 25 ERROR cinder.volume.drivers.lightos 
2025-01-20 20:28:51.213 25 ERROR cinder.volume.manager [None req-64f7749e-7efe-402d-9521-a6cc88b11e14 - - - - - -] Failed to initialize driver.: cinder.exception.VolumeDriverException: Volume driver reported an error: Could not get a response from any API server
2025-01-20 20:28:51.213 25 ERROR cinder.volume.manager Traceback (most recent call last):
2025-01-20 20:28:51.213 25 ERROR cinder.volume.manager   File "/var/lib/kolla/venv/lib/python3.10/site-packages/cinder/volume/manager.py", line 523, in _init_host
2025-01-20 20:28:51.213 25 ERROR cinder.volume.manager     self.driver.do_setup(ctxt)
2025-01-20 20:28:51.213 25 ERROR cinder.volume.manager   File "/var/lib/kolla/venv/lib/python3.10/site-packages/cinder/volume/drivers/lightos.py", line 922, in do_setup
2025-01-20 20:28:51.213 25 ERROR cinder.volume.manager     self.get_cluster_info()
2025-01-20 20:28:51.213 25 ERROR cinder.volume.manager   File "/var/lib/kolla/venv/lib/python3.10/site-packages/cinder/volume/drivers/lightos.py", line 873, in get_cluster_info
2025-01-20 20:28:51.213 25 ERROR cinder.volume.manager     status_code, cluster_info = self.cluster.send_cmd(
2025-01-20 20:28:51.213 25 ERROR cinder.volume.manager   File "/var/lib/kolla/venv/lib/python3.10/site-packages/cinder/volume/drivers/lightos.py", line 315, in send_cmd
2025-01-20 20:28:51.213 25 ERROR cinder.volume.manager     raise exception.VolumeDriverException(
2025-01-20 20:28:51.213 25 ERROR cinder.volume.manager cinder.exception.VolumeDriverException: Volume driver reported an error: Could not get a response from any API server
2025-01-20 20:28:51.213 25 ERROR cinder.volume.manager 
2025-01-20 20:28:53.216 25 INFO cinder.volume.manager [None req-64f7749e-7efe-402d-9521-a6cc88b11e14 - - - - - -] Starting volume driver LightOSVolumeDriver (2.3.12)
2025-01-20 20:28:53.217 25 INFO cinder.volume.drivers.lightos [None req-64f7749e-7efe-402d-9521-a6cc88b11e14 - - - - - -] Invoking get_cluster_info using GET url: /api/v2/clusterinfo             request.body: {} ssl_verify: False
2025-01-20 20:28:54.273 25 ERROR cinder.volume.drivers.lightos [None req-64f7749e-7efe-402d-9521-a6cc88b11e14 - - - - - -] REST server not responding at 'https://[LB_IP_ADDRESS]:443/api/v2/clusterinfo': requests.exceptions.ConnectionError: HTTPSConnectionPool(host='[LB_IP_ADDRESS]', port=443): Max retries exceeded with url: /api/v2/clusterinfo (Caused by NewConnectionError('<urllib3.connection.HTTPSConnection object at 0x7efcea83c850>: Failed to establish a new connection: [Errno 113] EHOSTUNREACH'))
2025-01-20 20:28:54.273 25 ERROR cinder.volume.drivers.lightos Traceback (most recent call last):
2025-01-20 20:28:54.273 25 ERROR cinder.volume.drivers.lightos   File "/var/lib/kolla/venv/lib/python3.10/site-packages/urllib3/connection.py", line 174, in _new_conn
2025-01-20 20:28:54.273 25 ERROR cinder.volume.drivers.lightos     conn = connection.create_connection(
2025-01-20 20:28:54.273 25 ERROR cinder.volume.drivers.lightos   File "/var/lib/kolla/venv/lib/python3.10/site-packages/urllib3/util/connection.py", line 95, in create_connection
2025-01-20 20:28:54.273 25 ERROR cinder.volume.drivers.lightos     raise err
2025-01-20 20:28:54.273 25 ERROR cinder.volume.drivers.lightos   File "/var/lib/kolla/venv/lib/python3.10/site-packages/urllib3/util/connection.py", line 85, in create_connection
2025-01-20 20:28:54.273 25 ERROR cinder.volume.drivers.lightos     sock.connect(sa)
2025-01-20 20:28:54.273 25 ERROR cinder.volume.drivers.lightos   File "/var/lib/kolla/venv/lib/python3.10/site-packages/eventlet/greenio/base.py", line 265, in connect
2025-01-20 20:28:54.273 25 ERROR cinder.volume.drivers.lightos     socket_checkerr(fd)
2025-01-20 20:28:54.273 25 ERROR cinder.volume.drivers.lightos   File "/var/lib/kolla/venv/lib/python3.10/site-packages/eventlet/greenio/base.py", line 50, in socket_checkerr
2025-01-20 20:28:54.273 25 ERROR cinder.volume.drivers.lightos     raise OSError(err, errno.errorcode[err])
2025-01-20 20:28:54.273 25 ERROR cinder.volume.drivers.lightos OSError: [Errno 113] EHOSTUNREACH
2025-01-20 20:28:54.273 25 ERROR cinder.volume.drivers.lightos 
2025-01-20 20:28:54.273 25 ERROR cinder.volume.drivers.lightos During handling of the above exception, another exception occurred:
2025-01-20 20:28:54.273 25 ERROR cinder.volume.drivers.lightos 
2025-01-20 20:28:54.273 25 ERROR cinder.volume.drivers.lightos Traceback (most recent call last):
2025-01-20 20:28:54.273 25 ERROR cinder.volume.drivers.lightos   File "/var/lib/kolla/venv/lib/python3.10/site-packages/urllib3/connectionpool.py", line 715, in urlopen
2025-01-20 20:28:54.273 25 ERROR cinder.volume.drivers.lightos     httplib_response = self._make_request(
2025-01-20 20:28:54.273 25 ERROR cinder.volume.drivers.lightos   File "/var/lib/kolla/venv/lib/python3.10/site-packages/urllib3/connectionpool.py", line 404, in _make_request
2025-01-20 20:28:54.273 25 ERROR cinder.volume.drivers.lightos     self._validate_conn(conn)
2025-01-20 20:28:54.273 25 ERROR cinder.volume.drivers.lightos   File "/var/lib/kolla/venv/lib/python3.10/site-packages/urllib3/connectionpool.py", line 1060, in _validate_conn
2025-01-20 20:28:54.273 25 ERROR cinder.volume.drivers.lightos     conn.connect()
2025-01-20 20:28:54.273 25 ERROR cinder.volume.drivers.lightos   File "/var/lib/kolla/venv/lib/python3.10/site-packages/urllib3/connection.py", line 363, in connect
2025-01-20 20:28:54.273 25 ERROR cinder.volume.drivers.lightos     self.sock = conn = self._new_conn()
2025-01-20 20:28:54.273 25 ERROR cinder.volume.drivers.lightos   File "/var/lib/kolla/venv/lib/python3.10/site-packages/urllib3/connection.py", line 186, in _new_conn
2025-01-20 20:28:54.273 25 ERROR cinder.volume.drivers.lightos     raise NewConnectionError(
2025-01-20 20:28:54.273 25 ERROR cinder.volume.drivers.lightos urllib3.exceptions.NewConnectionError: <urllib3.connection.HTTPSConnection object at 0x7efcea83c850>: Failed to establish a new connection: [Errno 113] EHOSTUNREACH
2025-01-20 20:28:54.273 25 ERROR cinder.volume.drivers.lightos 
2025-01-20 20:28:54.273 25 ERROR cinder.volume.drivers.lightos During handling of the above exception, another exception occurred:
2025-01-20 20:28:54.273 25 ERROR cinder.volume.drivers.lightos 
2025-01-20 20:28:54.273 25 ERROR cinder.volume.drivers.lightos Traceback (most recent call last):
2025-01-20 20:28:54.273 25 ERROR cinder.volume.drivers.lightos   File "/var/lib/kolla/venv/lib/python3.10/site-packages/requests/adapters.py", line 667, in send
2025-01-20 20:28:54.273 25 ERROR cinder.volume.drivers.lightos     resp = conn.urlopen(
2025-01-20 20:28:54.273 25 ERROR cinder.volume.drivers.lightos   File "/var/lib/kolla/venv/lib/python3.10/site-packages/urllib3/connectionpool.py", line 801, in urlopen
2025-01-20 20:28:54.273 25 ERROR cinder.volume.drivers.lightos     retries = retries.increment(
2025-01-20 20:28:54.273 25 ERROR cinder.volume.drivers.lightos   File "/var/lib/kolla/venv/lib/python3.10/site-packages/urllib3/util/retry.py", line 594, in increment
2025-01-20 20:28:54.273 25 ERROR cinder.volume.drivers.lightos     raise MaxRetryError(_pool, url, error or ResponseError(cause))
2025-01-20 20:28:54.273 25 ERROR cinder.volume.drivers.lightos urllib3.exceptions.MaxRetryError: HTTPSConnectionPool(host='[LB_IP_ADDRESS]', port=443): Max retries exceeded with url: /api/v2/clusterinfo (Caused by NewConnectionError('<urllib3.connection.HTTPSConnection object at 0x7efcea83c850>: Failed to establish a new connection: [Errno 113] EHOSTUNREACH'))
2025-01-20 20:28:54.273 25 ERROR cinder.volume.drivers.lightos 
2025-01-20 20:28:54.273 25 ERROR cinder.volume.drivers.lightos During handling of the above exception, another exception occurred:
2025-01-20 20:28:54.273 25 ERROR cinder.volume.drivers.lightos 
2025-01-20 20:28:54.273 25 ERROR cinder.volume.drivers.lightos Traceback (most recent call last):
2025-01-20 20:28:54.273 25 ERROR cinder.volume.drivers.lightos   File "/var/lib/kolla/venv/lib/python3.10/site-packages/cinder/volume/drivers/lightos.py", line 356, in __send_cmd
2025-01-20 20:28:54.273 25 ERROR cinder.volume.drivers.lightos     response = session.send(
2025-01-20 20:28:54.273 25 ERROR cinder.volume.drivers.lightos   File "/var/lib/kolla/venv/lib/python3.10/site-packages/requests/sessions.py", line 703, in send
2025-01-20 20:28:54.273 25 ERROR cinder.volume.drivers.lightos     r = adapter.send(request, **kwargs)
2025-01-20 20:28:54.273 25 ERROR cinder.volume.drivers.lightos   File "/var/lib/kolla/venv/lib/python3.10/site-packages/requests/adapters.py", line 700, in send
2025-01-20 20:28:54.273 25 ERROR cinder.volume.drivers.lightos     raise ConnectionError(e, request=request)
2025-01-20 20:28:54.273 25 ERROR cinder.volume.drivers.lightos requests.exceptions.ConnectionError: HTTPSConnectionPool(host='[LB_IP_ADDRESS]', port=443): Max retries exceeded with url: /api/v2/clusterinfo (Caused by NewConnectionError('<urllib3.connection.HTTPSConnection object at 0x7efcea83c850>: Failed to establish a new connection: [Errno 113] EHOSTUNREACH'))
2025-01-20 20:28:54.273 25 ERROR cinder.volume.drivers.lightos 
2025-01-20 20:28:54.276 25 INFO cinder.volume.drivers.lightos [None req-64f7749e-7efe-402d-9521-a6cc88b11e14 - - - - - -] Invoking get_cluster_info using GET url: /api/v2/clusterinfo             request.body: {} ssl_verify: False
2025-01-20 20:28:54.279 25 ERROR cinder.volume.drivers.lightos [None req-64f7749e-7efe-402d-9521-a6cc88b11e14 - - - - - -] REST server not responding at 'https://[LB_IP_ADDRESS]:443/api/v2/clusterinfo': requests.exceptions.ConnectionError: HTTPSConnectionPool(host='[LB_IP_ADDRESS]', port=443): Max retries exceeded with url: /api/v2/clusterinfo (Caused by NewConnectionError('<urllib3.connection.HTTPSConnection object at 0x7efcea83d330>: Failed to establish a new connection: [Errno 111] ECONNREFUSED'))
2025-01-20 20:28:54.279 25 ERROR cinder.volume.drivers.lightos Traceback (most recent call last):
2025-01-20 20:28:54.279 25 ERROR cinder.volume.drivers.lightos   File "/var/lib/kolla/venv/lib/python3.10/site-packages/urllib3/connection.py", line 174, in _new_conn
2025-01-20 20:28:54.279 25 ERROR cinder.volume.drivers.lightos     conn = connection.create_connection(
2025-01-20 20:28:54.279 25 ERROR cinder.volume.drivers.lightos   File "/var/lib/kolla/venv/lib/python3.10/site-packages/urllib3/util/connection.py", line 95, in create_connection
2025-01-20 20:28:54.279 25 ERROR cinder.volume.drivers.lightos     raise err
2025-01-20 20:28:54.279 25 ERROR cinder.volume.drivers.lightos   File "/var/lib/kolla/venv/lib/python3.10/site-packages/urllib3/util/connection.py", line 85, in create_connection
2025-01-20 20:28:54.279 25 ERROR cinder.volume.drivers.lightos     sock.connect(sa)
2025-01-20 20:28:54.279 25 ERROR cinder.volume.drivers.lightos   File "/var/lib/kolla/venv/lib/python3.10/site-packages/eventlet/greenio/base.py", line 265, in connect
2025-01-20 20:28:54.279 25 ERROR cinder.volume.drivers.lightos     socket_checkerr(fd)
2025-01-20 20:28:54.279 25 ERROR cinder.volume.drivers.lightos   File "/var/lib/kolla/venv/lib/python3.10/site-packages/eventlet/greenio/base.py", line 50, in socket_checkerr
2025-01-20 20:28:54.279 25 ERROR cinder.volume.drivers.lightos     raise OSError(err, errno.errorcode[err])
2025-01-20 20:28:54.279 25 ERROR cinder.volume.drivers.lightos ConnectionRefusedError: [Errno 111] ECONNREFUSED
2025-01-20 20:28:54.279 25 ERROR cinder.volume.drivers.lightos 
2025-01-20 20:28:54.279 25 ERROR cinder.volume.drivers.lightos During handling of the above exception, another exception occurred:
2025-01-20 20:28:54.279 25 ERROR cinder.volume.drivers.lightos 
2025-01-20 20:28:54.279 25 ERROR cinder.volume.drivers.lightos Traceback (most recent call last):
2025-01-20 20:28:54.279 25 ERROR cinder.volume.drivers.lightos   File "/var/lib/kolla/venv/lib/python3.10/site-packages/urllib3/connectionpool.py", line 715, in urlopen
2025-01-20 20:28:54.279 25 ERROR cinder.volume.drivers.lightos     httplib_response = self._make_request(
2025-01-20 20:28:54.279 25 ERROR cinder.volume.drivers.lightos   File "/var/lib/kolla/venv/lib/python3.10/site-packages/urllib3/connectionpool.py", line 404, in _make_request
2025-01-20 20:28:54.279 25 ERROR cinder.volume.drivers.lightos     self._validate_conn(conn)
2025-01-20 20:28:54.279 25 ERROR cinder.volume.drivers.lightos   File "/var/lib/kolla/venv/lib/python3.10/site-packages/urllib3/connectionpool.py", line 1060, in _validate_conn
2025-01-20 20:28:54.279 25 ERROR cinder.volume.drivers.lightos     conn.connect()
2025-01-20 20:28:54.279 25 ERROR cinder.volume.drivers.lightos   File "/var/lib/kolla/venv/lib/python3.10/site-packages/urllib3/connection.py", line 363, in connect
2025-01-20 20:28:54.279 25 ERROR cinder.volume.drivers.lightos     self.sock = conn = self._new_conn()
2025-01-20 20:28:54.279 25 ERROR cinder.volume.drivers.lightos   File "/var/lib/kolla/venv/lib/python3.10/site-packages/urllib3/connection.py", line 186, in _new_conn
2025-01-20 20:28:54.279 25 ERROR cinder.volume.drivers.lightos     raise NewConnectionError(
2025-01-20 20:28:54.279 25 ERROR cinder.volume.drivers.lightos urllib3.exceptions.NewConnectionError: <urllib3.connection.HTTPSConnection object at 0x7efcea83d330>: Failed to establish a new connection: [Errno 111] ECONNREFUSED
2025-01-20 20:28:54.279 25 ERROR cinder.volume.drivers.lightos 
2025-01-20 20:28:54.279 25 ERROR cinder.volume.drivers.lightos During handling of the above exception, another exception occurred:
2025-01-20 20:28:54.279 25 ERROR cinder.volume.drivers.lightos 
2025-01-20 20:28:54.279 25 ERROR cinder.volume.drivers.lightos Traceback (most recent call last):
2025-01-20 20:28:54.279 25 ERROR cinder.volume.drivers.lightos   File "/var/lib/kolla/venv/lib/python3.10/site-packages/requests/adapters.py", line 667, in send
2025-01-20 20:28:54.279 25 ERROR cinder.volume.drivers.lightos     resp = conn.urlopen(
2025-01-20 20:28:54.279 25 ERROR cinder.volume.drivers.lightos   File "/var/lib/kolla/venv/lib/python3.10/site-packages/urllib3/connectionpool.py", line 801, in urlopen
2025-01-20 20:28:54.279 25 ERROR cinder.volume.drivers.lightos     retries = retries.increment(
2025-01-20 20:28:54.279 25 ERROR cinder.volume.drivers.lightos   File "/var/lib/kolla/venv/lib/python3.10/site-packages/urllib3/util/retry.py", line 594, in increment
2025-01-20 20:28:54.279 25 ERROR cinder.volume.drivers.lightos     raise MaxRetryError(_pool, url, error or ResponseError(cause))
2025-01-20 20:28:54.279 25 ERROR cinder.volume.drivers.lightos urllib3.exceptions.MaxRetryError: HTTPSConnectionPool(host='[LB_IP_ADDRESS]', port=443): Max retries exceeded with url: /api/v2/clusterinfo (Caused by NewConnectionError('<urllib3.connection.HTTPSConnection object at 0x7efcea83d330>: Failed to establish a new connection: [Errno 111] ECONNREFUSED'))
2025-01-20 20:28:54.279 25 ERROR cinder.volume.drivers.lightos 
2025-01-20 20:28:54.279 25 ERROR cinder.volume.drivers.lightos During handling of the above exception, another exception occurred:
2025-01-20 20:28:54.279 25 ERROR cinder.volume.drivers.lightos 
2025-01-20 20:28:54.279 25 ERROR cinder.volume.drivers.lightos Traceback (most recent call last):
2025-01-20 20:28:54.279 25 ERROR cinder.volume.drivers.lightos   File "/var/lib/kolla/venv/lib/python3.10/site-packages/cinder/volume/drivers/lightos.py", line 356, in __send_cmd
2025-01-20 20:28:54.279 25 ERROR cinder.volume.drivers.lightos     response = session.send(
2025-01-20 20:28:54.279 25 ERROR cinder.volume.drivers.lightos   File "/var/lib/kolla/venv/lib/python3.10/site-packages/requests/sessions.py", line 703, in send
2025-01-20 20:28:54.279 25 ERROR cinder.volume.drivers.lightos     r = adapter.send(request, **kwargs)
2025-01-20 20:28:54.279 25 ERROR cinder.volume.drivers.lightos   File "/var/lib/kolla/venv/lib/python3.10/site-packages/requests/adapters.py", line 700, in send
2025-01-20 20:28:54.279 25 ERROR cinder.volume.drivers.lightos     raise ConnectionError(e, request=request)
2025-01-20 20:28:54.279 25 ERROR cinder.volume.drivers.lightos requests.exceptions.ConnectionError: HTTPSConnectionPool(host='[LB_IP_ADDRESS]', port=443): Max retries exceeded with url: /api/v2/clusterinfo (Caused by NewConnectionError('<urllib3.connection.HTTPSConnection object at 0x7efcea83d330>: Failed to establish a new connection: [Errno 111] ECONNREFUSED'))
2025-01-20 20:28:54.279 25 ERROR cinder.volume.drivers.lightos 
2025-01-20 20:28:54.282 25 INFO cinder.volume.drivers.lightos [None req-64f7749e-7efe-402d-9521-a6cc88b11e14 - - - - - -] Invoking get_cluster_info using GET url: /api/v2/clusterinfo             request.body: {} ssl_verify: False
2025-01-20 20:28:54.285 25 ERROR cinder.volume.drivers.lightos [None req-64f7749e-7efe-402d-9521-a6cc88b11e14 - - - - - -] REST server not responding at 'https://[LB_IP_ADDRESS]:443/api/v2/clusterinfo': requests.exceptions.ConnectionError: HTTPSConnectionPool(host='[LB_IP_ADDRESS]', port=443): Max retries exceeded with url: /api/v2/clusterinfo (Caused by NewConnectionError('<urllib3.connection.HTTPSConnection object at 0x7efceaaa6140>: Failed to establish a new connection: [Errno 111] ECONNREFUSED'))
2025-01-20 20:28:54.285 25 ERROR cinder.volume.drivers.lightos Traceback (most recent call last):
2025-01-20 20:28:54.285 25 ERROR cinder.volume.drivers.lightos   File "/var/lib/kolla/venv/lib/python3.10/site-packages/urllib3/connection.py", line 174, in _new_conn
2025-01-20 20:28:54.285 25 ERROR cinder.volume.drivers.lightos     conn = connection.create_connection(
2025-01-20 20:28:54.285 25 ERROR cinder.volume.drivers.lightos   File "/var/lib/kolla/venv/lib/python3.10/site-packages/urllib3/util/connection.py", line 95, in create_connection
2025-01-20 20:28:54.285 25 ERROR cinder.volume.drivers.lightos     raise err
2025-01-20 20:28:54.285 25 ERROR cinder.volume.drivers.lightos   File "/var/lib/kolla/venv/lib/python3.10/site-packages/urllib3/util/connection.py", line 85, in create_connection
2025-01-20 20:28:54.285 25 ERROR cinder.volume.drivers.lightos     sock.connect(sa)
2025-01-20 20:28:54.285 25 ERROR cinder.volume.drivers.lightos   File "/var/lib/kolla/venv/lib/python3.10/site-packages/eventlet/greenio/base.py", line 265, in connect
2025-01-20 20:28:54.285 25 ERROR cinder.volume.drivers.lightos     socket_checkerr(fd)
2025-01-20 20:28:54.285 25 ERROR cinder.volume.drivers.lightos   File "/var/lib/kolla/venv/lib/python3.10/site-packages/eventlet/greenio/base.py", line 50, in socket_checkerr
2025-01-20 20:28:54.285 25 ERROR cinder.volume.drivers.lightos     raise OSError(err, errno.errorcode[err])
2025-01-20 20:28:54.285 25 ERROR cinder.volume.drivers.lightos ConnectionRefusedError: [Errno 111] ECONNREFUSED
2025-01-20 20:28:54.285 25 ERROR cinder.volume.drivers.lightos 
2025-01-20 20:28:54.285 25 ERROR cinder.volume.drivers.lightos During handling of the above exception, another exception occurred:
2025-01-20 20:28:54.285 25 ERROR cinder.volume.drivers.lightos 
2025-01-20 20:28:54.285 25 ERROR cinder.volume.drivers.lightos Traceback (most recent call last):
2025-01-20 20:28:54.285 25 ERROR cinder.volume.drivers.lightos   File "/var/lib/kolla/venv/lib/python3.10/site-packages/urllib3/connectionpool.py", line 715, in urlopen
2025-01-20 20:28:54.285 25 ERROR cinder.volume.drivers.lightos     httplib_response = self._make_request(
2025-01-20 20:28:54.285 25 ERROR cinder.volume.drivers.lightos   File "/var/lib/kolla/venv/lib/python3.10/site-packages/urllib3/connectionpool.py", line 404, in _make_request
2025-01-20 20:28:54.285 25 ERROR cinder.volume.drivers.lightos     self._validate_conn(conn)
2025-01-20 20:28:54.285 25 ERROR cinder.volume.drivers.lightos   File "/var/lib/kolla/venv/lib/python3.10/site-packages/urllib3/connectionpool.py", line 1060, in _validate_conn
2025-01-20 20:28:54.285 25 ERROR cinder.volume.drivers.lightos     conn.connect()
2025-01-20 20:28:54.285 25 ERROR cinder.volume.drivers.lightos   File "/var/lib/kolla/venv/lib/python3.10/site-packages/urllib3/connection.py", line 363, in connect
2025-01-20 20:28:54.285 25 ERROR cinder.volume.drivers.lightos     self.sock = conn = self._new_conn()
2025-01-20 20:28:54.285 25 ERROR cinder.volume.drivers.lightos   File "/var/lib/kolla/venv/lib/python3.10/site-packages/urllib3/connection.py", line 186, in _new_conn
2025-01-20 20:28:54.285 25 ERROR cinder.volume.drivers.lightos     raise NewConnectionError(
2025-01-20 20:28:54.285 25 ERROR cinder.volume.drivers.lightos urllib3.exceptions.NewConnectionError: <urllib3.connection.HTTPSConnection object at 0x7efceaaa6140>: Failed to establish a new connection: [Errno 111] ECONNREFUSED
2025-01-20 20:28:54.285 25 ERROR cinder.volume.drivers.lightos 
2025-01-20 20:28:54.285 25 ERROR cinder.volume.drivers.lightos During handling of the above exception, another exception occurred:
2025-01-20 20:28:54.285 25 ERROR cinder.volume.drivers.lightos 
2025-01-20 20:28:54.285 25 ERROR cinder.volume.drivers.lightos Traceback (most recent call last):
2025-01-20 20:28:54.285 25 ERROR cinder.volume.drivers.lightos   File "/var/lib/kolla/venv/lib/python3.10/site-packages/requests/adapters.py", line 667, in send
2025-01-20 20:28:54.285 25 ERROR cinder.volume.drivers.lightos     resp = conn.urlopen(
2025-01-20 20:28:54.285 25 ERROR cinder.volume.drivers.lightos   File "/var/lib/kolla/venv/lib/python3.10/site-packages/urllib3/connectionpool.py", line 801, in urlopen
2025-01-20 20:28:54.285 25 ERROR cinder.volume.drivers.lightos     retries = retries.increment(
2025-01-20 20:28:54.285 25 ERROR cinder.volume.drivers.lightos   File "/var/lib/kolla/venv/lib/python3.10/site-packages/urllib3/util/retry.py", line 594, in increment
2025-01-20 20:28:54.285 25 ERROR cinder.volume.drivers.lightos     raise MaxRetryError(_pool, url, error or ResponseError(cause))
2025-01-20 20:28:54.285 25 ERROR cinder.volume.drivers.lightos urllib3.exceptions.MaxRetryError: HTTPSConnectionPool(host='[LB_IP_ADDRESS]', port=443): Max retries exceeded with url: /api/v2/clusterinfo (Caused by NewConnectionError('<urllib3.connection.HTTPSConnection object at 0x7efceaaa6140>: Failed to establish a new connection: [Errno 111] ECONNREFUSED'))
2025-01-20 20:28:54.285 25 ERROR cinder.volume.drivers.lightos 
2025-01-20 20:28:54.285 25 ERROR cinder.volume.drivers.lightos During handling of the above exception, another exception occurred:
2025-01-20 20:28:54.285 25 ERROR cinder.volume.drivers.lightos 
2025-01-20 20:28:54.285 25 ERROR cinder.volume.drivers.lightos Traceback (most recent call last):
2025-01-20 20:28:54.285 25 ERROR cinder.volume.drivers.lightos   File "/var/lib/kolla/venv/lib/python3.10/site-packages/cinder/volume/drivers/lightos.py", line 356, in __send_cmd
2025-01-20 20:28:54.285 25 ERROR cinder.volume.drivers.lightos     response = session.send(
2025-01-20 20:28:54.285 25 ERROR cinder.volume.drivers.lightos   File "/var/lib/kolla/venv/lib/python3.10/site-packages/requests/sessions.py", line 703, in send
2025-01-20 20:28:54.285 25 ERROR cinder.volume.drivers.lightos     r = adapter.send(request, **kwargs)
2025-01-20 20:28:54.285 25 ERROR cinder.volume.drivers.lightos   File "/var/lib/kolla/venv/lib/python3.10/site-packages/requests/adapters.py", line 700, in send
2025-01-20 20:28:54.285 25 ERROR cinder.volume.drivers.lightos     raise ConnectionError(e, request=request)
2025-01-20 20:28:54.285 25 ERROR cinder.volume.drivers.lightos requests.exceptions.ConnectionError: HTTPSConnectionPool(host='[LB_IP_ADDRESS]', port=443): Max retries exceeded with url: /api/v2/clusterinfo (Caused by NewConnectionError('<urllib3.connection.HTTPSConnection object at 0x7efceaaa6140>: Failed to establish a new connection: [Errno 111] ECONNREFUSED'))
2025-01-20 20:28:54.285 25 ERROR cinder.volume.drivers.lightos 
2025-01-20 20:28:54.287 25 ERROR cinder.volume.manager [None req-64f7749e-7efe-402d-9521-a6cc88b11e14 - - - - - -] Failed to initialize driver.: cinder.exception.VolumeDriverException: Volume driver reported an error: Could not get a response from any API server
2025-01-20 20:28:54.287 25 ERROR cinder.volume.manager Traceback (most recent call last):
2025-01-20 20:28:54.287 25 ERROR cinder.volume.manager   File "/var/lib/kolla/venv/lib/python3.10/site-packages/cinder/volume/manager.py", line 523, in _init_host
2025-01-20 20:28:54.287 25 ERROR cinder.volume.manager     self.driver.do_setup(ctxt)
2025-01-20 20:28:54.287 25 ERROR cinder.volume.manager   File "/var/lib/kolla/venv/lib/python3.10/site-packages/cinder/volume/drivers/lightos.py", line 922, in do_setup
2025-01-20 20:28:54.287 25 ERROR cinder.volume.manager     self.get_cluster_info()
2025-01-20 20:28:54.287 25 ERROR cinder.volume.manager   File "/var/lib/kolla/venv/lib/python3.10/site-packages/cinder/volume/drivers/lightos.py", line 873, in get_cluster_info
2025-01-20 20:28:54.287 25 ERROR cinder.volume.manager     status_code, cluster_info = self.cluster.send_cmd(
2025-01-20 20:28:54.287 25 ERROR cinder.volume.manager   File "/var/lib/kolla/venv/lib/python3.10/site-packages/cinder/volume/drivers/lightos.py", line 315, in send_cmd
2025-01-20 20:28:54.287 25 ERROR cinder.volume.manager     raise exception.VolumeDriverException(
2025-01-20 20:28:54.287 25 ERROR cinder.volume.manager cinder.exception.VolumeDriverException: Volume driver reported an error: Could not get a response from any API server
2025-01-20 20:28:54.287 25 ERROR cinder.volume.manager 
2025-01-20 20:28:58.292 25 INFO cinder.volume.manager [None req-64f7749e-7efe-402d-9521-a6cc88b11e14 - - - - - -] Starting volume driver LightOSVolumeDriver (2.3.12)
2025-01-20 20:28:58.293 25 INFO cinder.volume.drivers.lightos [None req-64f7749e-7efe-402d-9521-a6cc88b11e14 - - - - - -] Invoking get_cluster_info using GET url: /api/v2/clusterinfo             request.body: {} ssl_verify: False
2025-01-20 20:29:01.345 25 ERROR cinder.volume.drivers.lightos [None req-64f7749e-7efe-402d-9521-a6cc88b11e14 - - - - - -] REST server not responding at 'https://[LB_IP_ADDRESS]:443/api/v2/clusterinfo': requests.exceptions.ConnectionError: HTTPSConnectionPool(host='[LB_IP_ADDRESS]', port=443): Max retries exceeded with url: /api/v2/clusterinfo (Caused by NewConnectionError('<urllib3.connection.HTTPSConnection object at 0x7efceaaa4a60>: Failed to establish a new connection: [Errno 113] EHOSTUNREACH'))
2025-01-20 20:29:01.345 25 ERROR cinder.volume.drivers.lightos Traceback (most recent call last):
2025-01-20 20:29:01.345 25 ERROR cinder.volume.drivers.lightos   File "/var/lib/kolla/venv/lib/python3.10/site-packages/urllib3/connection.py", line 174, in _new_conn
2025-01-20 20:29:01.345 25 ERROR cinder.volume.drivers.lightos     conn = connection.create_connection(
2025-01-20 20:29:01.345 25 ERROR cinder.volume.drivers.lightos   File "/var/lib/kolla/venv/lib/python3.10/site-packages/urllib3/util/connection.py", line 95, in create_connection
2025-01-20 20:29:01.345 25 ERROR cinder.volume.drivers.lightos     raise err
2025-01-20 20:29:01.345 25 ERROR cinder.volume.drivers.lightos   File "/var/lib/kolla/venv/lib/python3.10/site-packages/urllib3/util/connection.py", line 85, in create_connection
2025-01-20 20:29:01.345 25 ERROR cinder.volume.drivers.lightos     sock.connect(sa)
2025-01-20 20:29:01.345 25 ERROR cinder.volume.drivers.lightos   File "/var/lib/kolla/venv/lib/python3.10/site-packages/eventlet/greenio/base.py", line 265, in connect
2025-01-20 20:29:01.345 25 ERROR cinder.volume.drivers.lightos     socket_checkerr(fd)
2025-01-20 20:29:01.345 25 ERROR cinder.volume.drivers.lightos   File "/var/lib/kolla/venv/lib/python3.10/site-packages/eventlet/greenio/base.py", line 50, in socket_checkerr
2025-01-20 20:29:01.345 25 ERROR cinder.volume.drivers.lightos     raise OSError(err, errno.errorcode[err])
2025-01-20 20:29:01.345 25 ERROR cinder.volume.drivers.lightos OSError: [Errno 113] EHOSTUNREACH
2025-01-20 20:29:01.345 25 ERROR cinder.volume.drivers.lightos 
2025-01-20 20:29:01.345 25 ERROR cinder.volume.drivers.lightos During handling of the above exception, another exception occurred:
2025-01-20 20:29:01.345 25 ERROR cinder.volume.drivers.lightos 
2025-01-20 20:29:01.345 25 ERROR cinder.volume.drivers.lightos Traceback (most recent call last):
2025-01-20 20:29:01.345 25 ERROR cinder.volume.drivers.lightos   File "/var/lib/kolla/venv/lib/python3.10/site-packages/urllib3/connectionpool.py", line 715, in urlopen
2025-01-20 20:29:01.345 25 ERROR cinder.volume.drivers.lightos     httplib_response = self._make_request(
2025-01-20 20:29:01.345 25 ERROR cinder.volume.drivers.lightos   File "/var/lib/kolla/venv/lib/python3.10/site-packages/urllib3/connectionpool.py", line 404, in _make_request
2025-01-20 20:29:01.345 25 ERROR cinder.volume.drivers.lightos     self._validate_conn(conn)
2025-01-20 20:29:01.345 25 ERROR cinder.volume.drivers.lightos   File "/var/lib/kolla/venv/lib/python3.10/site-packages/urllib3/connectionpool.py", line 1060, in _validate_conn
2025-01-20 20:29:01.345 25 ERROR cinder.volume.drivers.lightos     conn.connect()
2025-01-20 20:29:01.345 25 ERROR cinder.volume.drivers.lightos   File "/var/lib/kolla/venv/lib/python3.10/site-packages/urllib3/connection.py", line 363, in connect
2025-01-20 20:29:01.345 25 ERROR cinder.volume.drivers.lightos     self.sock = conn = self._new_conn()
2025-01-20 20:29:01.345 25 ERROR cinder.volume.drivers.lightos   File "/var/lib/kolla/venv/lib/python3.10/site-packages/urllib3/connection.py", line 186, in _new_conn
2025-01-20 20:29:01.345 25 ERROR cinder.volume.drivers.lightos     raise NewConnectionError(
2025-01-20 20:29:01.345 25 ERROR cinder.volume.drivers.lightos urllib3.exceptions.NewConnectionError: <urllib3.connection.HTTPSConnection object at 0x7efceaaa4a60>: Failed to establish a new connection: [Errno 113] EHOSTUNREACH
2025-01-20 20:29:01.345 25 ERROR cinder.volume.drivers.lightos 
2025-01-20 20:29:01.345 25 ERROR cinder.volume.drivers.lightos During handling of the above exception, another exception occurred:
2025-01-20 20:29:01.345 25 ERROR cinder.volume.drivers.lightos 
2025-01-20 20:29:01.345 25 ERROR cinder.volume.drivers.lightos Traceback (most recent call last):
2025-01-20 20:29:01.345 25 ERROR cinder.volume.drivers.lightos   File "/var/lib/kolla/venv/lib/python3.10/site-packages/requests/adapters.py", line 667, in send
2025-01-20 20:29:01.345 25 ERROR cinder.volume.drivers.lightos     resp = conn.urlopen(
2025-01-20 20:29:01.345 25 ERROR cinder.volume.drivers.lightos   File "/var/lib/kolla/venv/lib/python3.10/site-packages/urllib3/connectionpool.py", line 801, in urlopen
2025-01-20 20:29:01.345 25 ERROR cinder.volume.drivers.lightos     retries = retries.increment(
2025-01-20 20:29:01.345 25 ERROR cinder.volume.drivers.lightos   File "/var/lib/kolla/venv/lib/python3.10/site-packages/urllib3/util/retry.py", line 594, in increment
2025-01-20 20:29:01.345 25 ERROR cinder.volume.drivers.lightos     raise MaxRetryError(_pool, url, error or ResponseError(cause))
2025-01-20 20:29:01.345 25 ERROR cinder.volume.drivers.lightos urllib3.exceptions.MaxRetryError: HTTPSConnectionPool(host='[LB_IP_ADDRESS]', port=443): Max retries exceeded with url: /api/v2/clusterinfo (Caused by NewConnectionError('<urllib3.connection.HTTPSConnection object at 0x7efceaaa4a60>: Failed to establish a new connection: [Errno 113] EHOSTUNREACH'))
2025-01-20 20:29:01.345 25 ERROR cinder.volume.drivers.lightos 
2025-01-20 20:29:01.345 25 ERROR cinder.volume.drivers.lightos During handling of the above exception, another exception occurred:
2025-01-20 20:29:01.345 25 ERROR cinder.volume.drivers.lightos 
2025-01-20 20:29:01.345 25 ERROR cinder.volume.drivers.lightos Traceback (most recent call last):
2025-01-20 20:29:01.345 25 ERROR cinder.volume.drivers.lightos   File "/var/lib/kolla/venv/lib/python3.10/site-packages/cinder/volume/drivers/lightos.py", line 356, in __send_cmd
2025-01-20 20:29:01.345 25 ERROR cinder.volume.drivers.lightos     response = session.send(
2025-01-20 20:29:01.345 25 ERROR cinder.volume.drivers.lightos   File "/var/lib/kolla/venv/lib/python3.10/site-packages/requests/sessions.py", line 703, in send
2025-01-20 20:29:01.345 25 ERROR cinder.volume.drivers.lightos     r = adapter.send(request, **kwargs)
2025-01-20 20:29:01.345 25 ERROR cinder.volume.drivers.lightos   File "/var/lib/kolla/venv/lib/python3.10/site-packages/requests/adapters.py", line 700, in send
2025-01-20 20:29:01.345 25 ERROR cinder.volume.drivers.lightos     raise ConnectionError(e, request=request)
2025-01-20 20:29:01.345 25 ERROR cinder.volume.drivers.lightos requests.exceptions.ConnectionError: HTTPSConnectionPool(host='[LB_IP_ADDRESS]', port=443): Max retries exceeded with url: /api/v2/clusterinfo (Caused by NewConnectionError('<urllib3.connection.HTTPSConnection object at 0x7efceaaa4a60>: Failed to establish a new connection: [Errno 113] EHOSTUNREACH'))
2025-01-20 20:29:01.345 25 ERROR cinder.volume.drivers.lightos 
2025-01-20 20:29:01.348 25 INFO cinder.volume.drivers.lightos [None req-64f7749e-7efe-402d-9521-a6cc88b11e14 - - - - - -] Invoking get_cluster_info using GET url: /api/v2/clusterinfo             request.body: {} ssl_verify: False
2025-01-20 20:29:01.351 25 ERROR cinder.volume.drivers.lightos [None req-64f7749e-7efe-402d-9521-a6cc88b11e14 - - - - - -] REST server not responding at 'https://[LB_IP_ADDRESS]:443/api/v2/clusterinfo': requests.exceptions.ConnectionError: HTTPSConnectionPool(host='[LB_IP_ADDRESS]', port=443): Max retries exceeded with url: /api/v2/clusterinfo (Caused by NewConnectionError('<urllib3.connection.HTTPSConnection object at 0x7efceaaa4e80>: Failed to establish a new connection: [Errno 111] ECONNREFUSED'))
2025-01-20 20:29:01.351 25 ERROR cinder.volume.drivers.lightos Traceback (most recent call last):
2025-01-20 20:29:01.351 25 ERROR cinder.volume.drivers.lightos   File "/var/lib/kolla/venv/lib/python3.10/site-packages/urllib3/connection.py", line 174, in _new_conn
2025-01-20 20:29:01.351 25 ERROR cinder.volume.drivers.lightos     conn = connection.create_connection(
2025-01-20 20:29:01.351 25 ERROR cinder.volume.drivers.lightos   File "/var/lib/kolla/venv/lib/python3.10/site-packages/urllib3/util/connection.py", line 95, in create_connection
2025-01-20 20:29:01.351 25 ERROR cinder.volume.drivers.lightos     raise err
2025-01-20 20:29:01.351 25 ERROR cinder.volume.drivers.lightos   File "/var/lib/kolla/venv/lib/python3.10/site-packages/urllib3/util/connection.py", line 85, in create_connection
2025-01-20 20:29:01.351 25 ERROR cinder.volume.drivers.lightos     sock.connect(sa)
2025-01-20 20:29:01.351 25 ERROR cinder.volume.drivers.lightos   File "/var/lib/kolla/venv/lib/python3.10/site-packages/eventlet/greenio/base.py", line 265, in connect
2025-01-20 20:29:01.351 25 ERROR cinder.volume.drivers.lightos     socket_checkerr(fd)
2025-01-20 20:29:01.351 25 ERROR cinder.volume.drivers.lightos   File "/var/lib/kolla/venv/lib/python3.10/site-packages/eventlet/greenio/base.py", line 50, in socket_checkerr
2025-01-20 20:29:01.351 25 ERROR cinder.volume.drivers.lightos     raise OSError(err, errno.errorcode[err])
2025-01-20 20:29:01.351 25 ERROR cinder.volume.drivers.lightos ConnectionRefusedError: [Errno 111] ECONNREFUSED
2025-01-20 20:29:01.351 25 ERROR cinder.volume.drivers.lightos 
2025-01-20 20:29:01.351 25 ERROR cinder.volume.drivers.lightos During handling of the above exception, another exception occurred:
2025-01-20 20:29:01.351 25 ERROR cinder.volume.drivers.lightos 
2025-01-20 20:29:01.351 25 ERROR cinder.volume.drivers.lightos Traceback (most recent call last):
2025-01-20 20:29:01.351 25 ERROR cinder.volume.drivers.lightos   File "/var/lib/kolla/venv/lib/python3.10/site-packages/urllib3/connectionpool.py", line 715, in urlopen
2025-01-20 20:29:01.351 25 ERROR cinder.volume.drivers.lightos     httplib_response = self._make_request(
2025-01-20 20:29:01.351 25 ERROR cinder.volume.drivers.lightos   File "/var/lib/kolla/venv/lib/python3.10/site-packages/urllib3/connectionpool.py", line 404, in _make_request
2025-01-20 20:29:01.351 25 ERROR cinder.volume.drivers.lightos     self._validate_conn(conn)
2025-01-20 20:29:01.351 25 ERROR cinder.volume.drivers.lightos   File "/var/lib/kolla/venv/lib/python3.10/site-packages/urllib3/connectionpool.py", line 1060, in _validate_conn
2025-01-20 20:29:01.351 25 ERROR cinder.volume.drivers.lightos     conn.connect()
2025-01-20 20:29:01.351 25 ERROR cinder.volume.drivers.lightos   File "/var/lib/kolla/venv/lib/python3.10/site-packages/urllib3/connection.py", line 363, in connect
2025-01-20 20:29:01.351 25 ERROR cinder.volume.drivers.lightos     self.sock = conn = self._new_conn()
2025-01-20 20:29:01.351 25 ERROR cinder.volume.drivers.lightos   File "/var/lib/kolla/venv/lib/python3.10/site-packages/urllib3/connection.py", line 186, in _new_conn
2025-01-20 20:29:01.351 25 ERROR cinder.volume.drivers.lightos     raise NewConnectionError(
2025-01-20 20:29:01.351 25 ERROR cinder.volume.drivers.lightos urllib3.exceptions.NewConnectionError: <urllib3.connection.HTTPSConnection object at 0x7efceaaa4e80>: Failed to establish a new connection: [Errno 111] ECONNREFUSED
2025-01-20 20:29:01.351 25 ERROR cinder.volume.drivers.lightos 
2025-01-20 20:29:01.351 25 ERROR cinder.volume.drivers.lightos During handling of the above exception, another exception occurred:
2025-01-20 20:29:01.351 25 ERROR cinder.volume.drivers.lightos 
2025-01-20 20:29:01.351 25 ERROR cinder.volume.drivers.lightos Traceback (most recent call last):
2025-01-20 20:29:01.351 25 ERROR cinder.volume.drivers.lightos   File "/var/lib/kolla/venv/lib/python3.10/site-packages/requests/adapters.py", line 667, in send
2025-01-20 20:29:01.351 25 ERROR cinder.volume.drivers.lightos     resp = conn.urlopen(
2025-01-20 20:29:01.351 25 ERROR cinder.volume.drivers.lightos   File "/var/lib/kolla/venv/lib/python3.10/site-packages/urllib3/connectionpool.py", line 801, in urlopen
2025-01-20 20:29:01.351 25 ERROR cinder.volume.drivers.lightos     retries = retries.increment(
2025-01-20 20:29:01.351 25 ERROR cinder.volume.drivers.lightos   File "/var/lib/kolla/venv/lib/python3.10/site-packages/urllib3/util/retry.py", line 594, in increment
2025-01-20 20:29:01.351 25 ERROR cinder.volume.drivers.lightos     raise MaxRetryError(_pool, url, error or ResponseError(cause))
2025-01-20 20:29:01.351 25 ERROR cinder.volume.drivers.lightos urllib3.exceptions.MaxRetryError: HTTPSConnectionPool(host='[LB_IP_ADDRESS]', port=443): Max retries exceeded with url: /api/v2/clusterinfo (Caused by NewConnectionError('<urllib3.connection.HTTPSConnection object at 0x7efceaaa4e80>: Failed to establish a new connection: [Errno 111] ECONNREFUSED'))
2025-01-20 20:29:01.351 25 ERROR cinder.volume.drivers.lightos 
2025-01-20 20:29:01.351 25 ERROR cinder.volume.drivers.lightos During handling of the above exception, another exception occurred:
2025-01-20 20:29:01.351 25 ERROR cinder.volume.drivers.lightos 
2025-01-20 20:29:01.351 25 ERROR cinder.volume.drivers.lightos Traceback (most recent call last):
2025-01-20 20:29:01.351 25 ERROR cinder.volume.drivers.lightos   File "/var/lib/kolla/venv/lib/python3.10/site-packages/cinder/volume/drivers/lightos.py", line 356, in __send_cmd
2025-01-20 20:29:01.351 25 ERROR cinder.volume.drivers.lightos     response = session.send(
2025-01-20 20:29:01.351 25 ERROR cinder.volume.drivers.lightos   File "/var/lib/kolla/venv/lib/python3.10/site-packages/requests/sessions.py", line 703, in send
2025-01-20 20:29:01.351 25 ERROR cinder.volume.drivers.lightos     r = adapter.send(request, **kwargs)
2025-01-20 20:29:01.351 25 ERROR cinder.volume.drivers.lightos   File "/var/lib/kolla/venv/lib/python3.10/site-packages/requests/adapters.py", line 700, in send
2025-01-20 20:29:01.351 25 ERROR cinder.volume.drivers.lightos     raise ConnectionError(e, request=request)
2025-01-20 20:29:01.351 25 ERROR cinder.volume.drivers.lightos requests.exceptions.ConnectionError: HTTPSConnectionPool(host='[LB_IP_ADDRESS]', port=443): Max retries exceeded with url: /api/v2/clusterinfo (Caused by NewConnectionError('<urllib3.connection.HTTPSConnection object at 0x7efceaaa4e80>: Failed to establish a new connection: [Errno 111] ECONNREFUSED'))
2025-01-20 20:29:01.351 25 ERROR cinder.volume.drivers.lightos 
2025-01-20 20:29:01.353 25 INFO cinder.volume.drivers.lightos [None req-64f7749e-7efe-402d-9521-a6cc88b11e14 - - - - - -] Invoking get_cluster_info using GET url: /api/v2/clusterinfo             request.body: {} ssl_verify: False
2025-01-20 20:29:01.355 25 ERROR cinder.volume.drivers.lightos [None req-64f7749e-7efe-402d-9521-a6cc88b11e14 - - - - - -] REST server not responding at 'https://[LB_IP_ADDRESS]:443/api/v2/clusterinfo': requests.exceptions.ConnectionError: HTTPSConnectionPool(host='[LB_IP_ADDRESS]', port=443): Max retries exceeded with url: /api/v2/clusterinfo (Caused by NewConnectionError('<urllib3.connection.HTTPSConnection object at 0x7efcea83c1c0>: Failed to establish a new connection: [Errno 111] ECONNREFUSED'))
2025-01-20 20:29:01.355 25 ERROR cinder.volume.drivers.lightos Traceback (most recent call last):
2025-01-20 20:29:01.355 25 ERROR cinder.volume.drivers.lightos   File "/var/lib/kolla/venv/lib/python3.10/site-packages/urllib3/connection.py", line 174, in _new_conn
2025-01-20 20:29:01.355 25 ERROR cinder.volume.drivers.lightos     conn = connection.create_connection(
2025-01-20 20:29:01.355 25 ERROR cinder.volume.drivers.lightos   File "/var/lib/kolla/venv/lib/python3.10/site-packages/urllib3/util/connection.py", line 95, in create_connection
2025-01-20 20:29:01.355 25 ERROR cinder.volume.drivers.lightos     raise err
2025-01-20 20:29:01.355 25 ERROR cinder.volume.drivers.lightos   File "/var/lib/kolla/venv/lib/python3.10/site-packages/urllib3/util/connection.py", line 85, in create_connection
2025-01-20 20:29:01.355 25 ERROR cinder.volume.drivers.lightos     sock.connect(sa)
2025-01-20 20:29:01.355 25 ERROR cinder.volume.drivers.lightos   File "/var/lib/kolla/venv/lib/python3.10/site-packages/eventlet/greenio/base.py", line 265, in connect
2025-01-20 20:29:01.355 25 ERROR cinder.volume.drivers.lightos     socket_checkerr(fd)
2025-01-20 20:29:01.355 25 ERROR cinder.volume.drivers.lightos   File "/var/lib/kolla/venv/lib/python3.10/site-packages/eventlet/greenio/base.py", line 50, in socket_checkerr
2025-01-20 20:29:01.355 25 ERROR cinder.volume.drivers.lightos     raise OSError(err, errno.errorcode[err])
2025-01-20 20:29:01.355 25 ERROR cinder.volume.drivers.lightos ConnectionRefusedError: [Errno 111] ECONNREFUSED
2025-01-20 20:29:01.355 25 ERROR cinder.volume.drivers.lightos 
2025-01-20 20:29:01.355 25 ERROR cinder.volume.drivers.lightos During handling of the above exception, another exception occurred:
2025-01-20 20:29:01.355 25 ERROR cinder.volume.drivers.lightos 
2025-01-20 20:29:01.355 25 ERROR cinder.volume.drivers.lightos Traceback (most recent call last):
2025-01-20 20:29:01.355 25 ERROR cinder.volume.drivers.lightos   File "/var/lib/kolla/venv/lib/python3.10/site-packages/urllib3/connectionpool.py", line 715, in urlopen
2025-01-20 20:29:01.355 25 ERROR cinder.volume.drivers.lightos     httplib_response = self._make_request(
2025-01-20 20:29:01.355 25 ERROR cinder.volume.drivers.lightos   File "/var/lib/kolla/venv/lib/python3.10/site-packages/urllib3/connectionpool.py", line 404, in _make_request
2025-01-20 20:29:01.355 25 ERROR cinder.volume.drivers.lightos     self._validate_conn(conn)
2025-01-20 20:29:01.355 25 ERROR cinder.volume.drivers.lightos   File "/var/lib/kolla/venv/lib/python3.10/site-packages/urllib3/connectionpool.py", line 1060, in _validate_conn
2025-01-20 20:29:01.355 25 ERROR cinder.volume.drivers.lightos     conn.connect()
2025-01-20 20:29:01.355 25 ERROR cinder.volume.drivers.lightos   File "/var/lib/kolla/venv/lib/python3.10/site-packages/urllib3/connection.py", line 363, in connect
2025-01-20 20:29:01.355 25 ERROR cinder.volume.drivers.lightos     self.sock = conn = self._new_conn()
2025-01-20 20:29:01.355 25 ERROR cinder.volume.drivers.lightos   File "/var/lib/kolla/venv/lib/python3.10/site-packages/urllib3/connection.py", line 186, in _new_conn
2025-01-20 20:29:01.355 25 ERROR cinder.volume.drivers.lightos     raise NewConnectionError(
2025-01-20 20:29:01.355 25 ERROR cinder.volume.drivers.lightos urllib3.exceptions.NewConnectionError: <urllib3.connection.HTTPSConnection object at 0x7efcea83c1c0>: Failed to establish a new connection: [Errno 111] ECONNREFUSED
2025-01-20 20:29:01.355 25 ERROR cinder.volume.drivers.lightos 
2025-01-20 20:29:01.355 25 ERROR cinder.volume.drivers.lightos During handling of the above exception, another exception occurred:
2025-01-20 20:29:01.355 25 ERROR cinder.volume.drivers.lightos 
2025-01-20 20:29:01.355 25 ERROR cinder.volume.drivers.lightos Traceback (most recent call last):
2025-01-20 20:29:01.355 25 ERROR cinder.volume.drivers.lightos   File "/var/lib/kolla/venv/lib/python3.10/site-packages/requests/adapters.py", line 667, in send
2025-01-20 20:29:01.355 25 ERROR cinder.volume.drivers.lightos     resp = conn.urlopen(
2025-01-20 20:29:01.355 25 ERROR cinder.volume.drivers.lightos   File "/var/lib/kolla/venv/lib/python3.10/site-packages/urllib3/connectionpool.py", line 801, in urlopen
2025-01-20 20:29:01.355 25 ERROR cinder.volume.drivers.lightos     retries = retries.increment(
2025-01-20 20:29:01.355 25 ERROR cinder.volume.drivers.lightos   File "/var/lib/kolla/venv/lib/python3.10/site-packages/urllib3/util/retry.py", line 594, in increment
2025-01-20 20:29:01.355 25 ERROR cinder.volume.drivers.lightos     raise MaxRetryError(_pool, url, error or ResponseError(cause))
2025-01-20 20:29:01.355 25 ERROR cinder.volume.drivers.lightos urllib3.exceptions.MaxRetryError: HTTPSConnectionPool(host='[LB_IP_ADDRESS]', port=443): Max retries exceeded with url: /api/v2/clusterinfo (Caused by NewConnectionError('<urllib3.connection.HTTPSConnection object at 0x7efcea83c1c0>: Failed to establish a new connection: [Errno 111] ECONNREFUSED'))
2025-01-20 20:29:01.355 25 ERROR cinder.volume.drivers.lightos 
2025-01-20 20:29:01.355 25 ERROR cinder.volume.drivers.lightos During handling of the above exception, another exception occurred:
2025-01-20 20:29:01.355 25 ERROR cinder.volume.drivers.lightos 
2025-01-20 20:29:01.355 25 ERROR cinder.volume.drivers.lightos Traceback (most recent call last):
2025-01-20 20:29:01.355 25 ERROR cinder.volume.drivers.lightos   File "/var/lib/kolla/venv/lib/python3.10/site-packages/cinder/volume/drivers/lightos.py", line 356, in __send_cmd
2025-01-20 20:29:01.355 25 ERROR cinder.volume.drivers.lightos     response = session.send(
2025-01-20 20:29:01.355 25 ERROR cinder.volume.drivers.lightos   File "/var/lib/kolla/venv/lib/python3.10/site-packages/requests/sessions.py", line 703, in send
2025-01-20 20:29:01.355 25 ERROR cinder.volume.drivers.lightos     r = adapter.send(request, **kwargs)
2025-01-20 20:29:01.355 25 ERROR cinder.volume.drivers.lightos   File "/var/lib/kolla/venv/lib/python3.10/site-packages/requests/adapters.py", line 700, in send
2025-01-20 20:29:01.355 25 ERROR cinder.volume.drivers.lightos     raise ConnectionError(e, request=request)
2025-01-20 20:29:01.355 25 ERROR cinder.volume.drivers.lightos requests.exceptions.ConnectionError: HTTPSConnectionPool(host='[LB_IP_ADDRESS]', port=443): Max retries exceeded with url: /api/v2/clusterinfo (Caused by NewConnectionError('<urllib3.connection.HTTPSConnection object at 0x7efcea83c1c0>: Failed to establish a new connection: [Errno 111] ECONNREFUSED'))
2025-01-20 20:29:01.355 25 ERROR cinder.volume.drivers.lightos 
2025-01-20 20:29:01.356 25 ERROR cinder.volume.manager [None req-64f7749e-7efe-402d-9521-a6cc88b11e14 - - - - - -] Failed to initialize driver.: cinder.exception.VolumeDriverException: Volume driver reported an error: Could not get a response from any API server
2025-01-20 20:29:01.356 25 ERROR cinder.volume.manager Traceback (most recent call last):
2025-01-20 20:29:01.356 25 ERROR cinder.volume.manager   File "/var/lib/kolla/venv/lib/python3.10/site-packages/cinder/volume/manager.py", line 523, in _init_host
2025-01-20 20:29:01.356 25 ERROR cinder.volume.manager     self.driver.do_setup(ctxt)
2025-01-20 20:29:01.356 25 ERROR cinder.volume.manager   File "/var/lib/kolla/venv/lib/python3.10/site-packages/cinder/volume/drivers/lightos.py", line 922, in do_setup
2025-01-20 20:29:01.356 25 ERROR cinder.volume.manager     self.get_cluster_info()
2025-01-20 20:29:01.356 25 ERROR cinder.volume.manager   File "/var/lib/kolla/venv/lib/python3.10/site-packages/cinder/volume/drivers/lightos.py", line 873, in get_cluster_info
2025-01-20 20:29:01.356 25 ERROR cinder.volume.manager     status_code, cluster_info = self.cluster.send_cmd(
2025-01-20 20:29:01.356 25 ERROR cinder.volume.manager   File "/var/lib/kolla/venv/lib/python3.10/site-packages/cinder/volume/drivers/lightos.py", line 315, in send_cmd
2025-01-20 20:29:01.356 25 ERROR cinder.volume.manager     raise exception.VolumeDriverException(
2025-01-20 20:29:01.356 25 ERROR cinder.volume.manager cinder.exception.VolumeDriverException: Volume driver reported an error: Could not get a response from any API server
2025-01-20 20:29:01.356 25 ERROR cinder.volume.manager 
2025-01-20 20:29:01.374 25 WARNING oslo_config.cfg [None req-64f7749e-7efe-402d-9521-a6cc88b11e14 - - - - - -] Deprecated: Option "heartbeat_in_pthread" from group "oslo_messaging_rabbit" is deprecated for removal (The option is related to Eventlet which will be removed. In addition this has never worked as expected with services using eventlet for core service framework.).  Its value may be silently ignored in the future.
2025-01-20 20:29:01.419 25 INFO cinder.service [None req-64f7749e-7efe-402d-9521-a6cc88b11e14 - - - - - -] Starting cinder-volume cluster lightos_cinder_cluster@LIGHTOSyilgqu (version 25.1.0)
2025-01-20 20:29:01.438 25 INFO cinder.volume.manager [None req-64f7749e-7efe-402d-9521-a6cc88b11e14 - - - - - -] Initializing RPC dependent components of volume driver LightOSVolumeDriver (2.3.12)
2025-01-20 20:29:01.439 25 ERROR cinder.volume.volume_utils [None req-64f7749e-7efe-402d-9521-a6cc88b11e14 - - - - - -] Volume driver LightOSVolumeDriver not initialized
2025-01-20 20:29:01.439 25 ERROR cinder.volume.manager [None req-64f7749e-7efe-402d-9521-a6cc88b11e14 - - - - - -] Cannot complete RPC initialization because driver isn't initialized properly.: cinder.exception.DriverNotInitialized: Volume driver not ready.
2025-01-20 20:29:11.440 25 ERROR cinder.service [-] Manager for service cinder-volume rack13-server67@LIGHTOSyilgqu is reporting problems, not sending heartbeat. Service will appear "down".
2025-01-20 20:29:21.442 25 ERROR cinder.service [-] Manager for service cinder-volume rack13-server67@LIGHTOSyilgqu is reporting problems, not sending heartbeat. Service will appear "down".
2025-01-20 20:29:31.444 25 ERROR cinder.service [-] Manager for service cinder-volume rack13-server67@LIGHTOSyilgqu is reporting problems, not sending heartbeat. Service will appear "down".
2025-01-20 20:29:41.445 25 ERROR cinder.service [-] Manager for service cinder-volume rack13-server67@LIGHTOSyilgqu is reporting problems, not sending heartbeat. Service will appear "down".
2025-01-20 20:29:51.447 25 ERROR cinder.service [-] Manager for service cinder-volume rack13-server67@LIGHTOSyilgqu is reporting problems, not sending heartbeat. Service will appear "down".
2025-01-20 20:30:01.449 25 ERROR cinder.service [-] Manager for service cinder-volume rack13-server67@LIGHTOSyilgqu is reporting problems, not sending heartbeat. Service will appear "down".
2025-01-20 20:30:11.450 25 ERROR cinder.service [-] Manager for service cinder-volume rack13-server67@LIGHTOSyilgqu is reporting problems, not sending heartbeat. Service will appear "down".
2025-01-20 20:30:21.451 25 ERROR cinder.service [-] Manager for service cinder-volume rack13-server67@LIGHTOSyilgqu is reporting problems, not sending heartbeat. Service will appear "down".
2025-01-20 20:30:27.445 25 WARNING cinder.volume.manager [None req-4f8d0c03-0ecc-47aa-85a4-6c389e1ab97d - - - - - -] Update driver status failed: (config name LIGHTOSyilgqu) is uninitialized.
2025-01-20 20:30:31.453 25 ERROR cinder.service [-] Manager for service cinder-volume rack13-server67@LIGHTOSyilgqu is reporting problems, not sending heartbeat. Service will appear "down".
2025-01-20 20:30:41.454 25 ERROR cinder.service [-] Manager for service cinder-volume rack13-server67@LIGHTOSyilgqu is reporting problems, not sending heartbeat. Service will appear "down".
2025-01-20 20:30:51.455 25 ERROR cinder.service [-] Manager for service cinder-volume rack13-server67@LIGHTOSyilgqu is reporting problems, not sending heartbeat. Service will appear "down".
2025-01-20 20:31:01.457 25 ERROR cinder.service [-] Manager for service cinder-volume rack13-server67@LIGHTOSyilgqu is reporting problems, not sending heartbeat. Service will appear "down".
2025-01-20 20:31:11.459 25 ERROR cinder.service [-] Manager for service cinder-volume rack13-server67@LIGHTOSyilgqu is reporting problems, not sending heartbeat. Service will appear "down".
2025-01-20 20:31:21.461 25 ERROR cinder.service [-] Manager for service cinder-volume rack13-server67@LIGHTOSyilgqu is reporting problems, not sending heartbeat. Service will appear "down".
2025-01-20 20:31:27.448 25 WARNING cinder.volume.manager [None req-4f8d0c03-0ecc-47aa-85a4-6c389e1ab97d - - - - - -] Update driver status failed: (config name LIGHTOSyilgqu) is uninitialized.
2025-01-20 20:31:31.462 25 ERROR cinder.service [-] Manager for service cinder-volume rack13-server67@LIGHTOSyilgqu is reporting problems, not sending heartbeat. Service will appear "down".
2025-01-20 20:31:41.463 25 ERROR cinder.service [-] Manager for service cinder-volume rack13-server67@LIGHTOSyilgqu is reporting problems, not sending heartbeat. Service will appear "down".
2025-01-20 20:31:51.464 25 ERROR cinder.service [-] Manager for service cinder-volume rack13-server67@LIGHTOSyilgqu is reporting problems, not sending heartbeat. Service will appear "down".
2025-01-20 20:32:01.465 25 ERROR cinder.service [-] Manager for service cinder-volume rack13-server67@LIGHTOSyilgqu is reporting problems, not sending heartbeat. Service will appear "down".
2025-01-20 20:32:11.466 25 ERROR cinder.service [-] Manager for service cinder-volume rack13-server67@LIGHTOSyilgqu is reporting problems, not sending heartbeat. Service will appear "down".
2025-01-20 20:32:21.468 25 ERROR cinder.service [-] Manager for service cinder-volume rack13-server67@LIGHTOSyilgqu is reporting problems, not sending heartbeat. Service will appear "down".
