Build Started 23_01_2025_07_37_14
2025-01-23 07:37:23.649 25 ERROR cinder.service [-] Manager for service cinder-volume rack13-server67@LIGHTOSyilgqu is reporting problems, not sending heartbeat. Service will appear "down".
2025-01-23 07:37:24.061 7 INFO oslo_service.service [None req-9b2c1d81-efa5-4bec-abb0-ddec90c4ac95 - - - - - -] Caught SIGTERM, stopping children
2025-01-23 07:37:24.079 7 INFO oslo_service.service [None req-9b2c1d81-efa5-4bec-abb0-ddec90c4ac95 - - - - - -] Waiting on 1 children to exit
2025-01-23 07:37:26.809 25 WARNING amqp [None req-9b2c1d81-efa5-4bec-abb0-ddec90c4ac95 - - - - - -] Received method (60, 30) during closing channel 1. This method will be ignored
2025-01-23 07:37:26.817 25 WARNING amqp [None req-9b2c1d81-efa5-4bec-abb0-ddec90c4ac95 - - - - - -] Received method (60, 30) during closing channel 1. This method will be ignored
2025-01-23 07:37:26.825 25 WARNING amqp [None req-9b2c1d81-efa5-4bec-abb0-ddec90c4ac95 - - - - - -] Received method (60, 30) during closing channel 1. This method will be ignored
2025-01-23 07:37:26.836 7 INFO oslo_service.service [None req-9b2c1d81-efa5-4bec-abb0-ddec90c4ac95 - - - - - -] Child 25 exited with status 0
2025-01-23 07:37:42.189 7 INFO cinder.rpc [None req-55d70ca1-2019-4365-8bbf-302c4f18cf4b - - - - - -] Automatically selected cinder-scheduler objects version 1.39 as minimum service version.
2025-01-23 07:37:42.193 7 INFO cinder.rpc [None req-55d70ca1-2019-4365-8bbf-302c4f18cf4b - - - - - -] Automatically selected cinder-scheduler RPC version 3.12 as minimum service version.
2025-01-23 07:37:42.235 7 INFO cinder.volume.manager [None req-55d70ca1-2019-4365-8bbf-302c4f18cf4b - - - - - -] Determined volume DB was empty at startup.
2025-01-23 07:37:42.253 7 INFO cinder.volume.manager [None req-55d70ca1-2019-4365-8bbf-302c4f18cf4b - - - - - -] Image-volume cache disabled for host rack13-server67@LIGHTOSyilgqu.
2025-01-23 07:37:42.267 7 INFO oslo_service.service [None req-55d70ca1-2019-4365-8bbf-302c4f18cf4b - - - - - -] Starting 1 workers
2025-01-23 07:37:42.278 25 INFO cinder.service [-] Starting cinder-volume node (version 25.1.0)
2025-01-23 07:37:42.282 7 WARNING oslo_config.cfg [None req-55d70ca1-2019-4365-8bbf-302c4f18cf4b - - - - - -] Deprecated: Option "heartbeat_in_pthread" from group "oslo_messaging_rabbit" is deprecated for removal (The option is related to Eventlet which will be removed. In addition this has never worked as expected with services using eventlet for core service framework.).  Its value may be silently ignored in the future.
2025-01-23 07:37:42.294 25 INFO cinder.volume.manager [None req-066b0eec-78ec-4fb5-87d6-6609c5df9b40 - - - - - -] Starting volume driver LightOSVolumeDriver (2.3.12)
2025-01-23 07:37:42.295 25 INFO cinder.volume.drivers.lightos [None req-066b0eec-78ec-4fb5-87d6-6609c5df9b40 - - - - - -] Invoking get_cluster_info using GET url: /api/v2/clusterinfo             request.body: {} ssl_verify: False
2025-01-23 07:37:42.297 25 ERROR cinder.volume.drivers.lightos [None req-066b0eec-78ec-4fb5-87d6-6609c5df9b40 - - - - - -] REST server not responding at 'https://[LB_IP_ADDRESS]:443/api/v2/clusterinfo': requests.exceptions.ConnectionError: HTTPSConnectionPool(host='[LB_IP_ADDRESS]', port=443): Max retries exceeded with url: /api/v2/clusterinfo (Caused by NewConnectionError('<urllib3.connection.HTTPSConnection object at 0x7f67697c9bd0>: Failed to establish a new connection: [Errno 111] ECONNREFUSED'))
2025-01-23 07:37:42.297 25 ERROR cinder.volume.drivers.lightos Traceback (most recent call last):
2025-01-23 07:37:42.297 25 ERROR cinder.volume.drivers.lightos   File "/var/lib/kolla/venv/lib/python3.10/site-packages/urllib3/connection.py", line 174, in _new_conn
2025-01-23 07:37:42.297 25 ERROR cinder.volume.drivers.lightos     conn = connection.create_connection(
2025-01-23 07:37:42.297 25 ERROR cinder.volume.drivers.lightos   File "/var/lib/kolla/venv/lib/python3.10/site-packages/urllib3/util/connection.py", line 95, in create_connection
2025-01-23 07:37:42.297 25 ERROR cinder.volume.drivers.lightos     raise err
2025-01-23 07:37:42.297 25 ERROR cinder.volume.drivers.lightos   File "/var/lib/kolla/venv/lib/python3.10/site-packages/urllib3/util/connection.py", line 85, in create_connection
2025-01-23 07:37:42.297 25 ERROR cinder.volume.drivers.lightos     sock.connect(sa)
2025-01-23 07:37:42.297 25 ERROR cinder.volume.drivers.lightos   File "/var/lib/kolla/venv/lib/python3.10/site-packages/eventlet/greenio/base.py", line 265, in connect
2025-01-23 07:37:42.297 25 ERROR cinder.volume.drivers.lightos     socket_checkerr(fd)
2025-01-23 07:37:42.297 25 ERROR cinder.volume.drivers.lightos   File "/var/lib/kolla/venv/lib/python3.10/site-packages/eventlet/greenio/base.py", line 50, in socket_checkerr
2025-01-23 07:37:42.297 25 ERROR cinder.volume.drivers.lightos     raise OSError(err, errno.errorcode[err])
2025-01-23 07:37:42.297 25 ERROR cinder.volume.drivers.lightos ConnectionRefusedError: [Errno 111] ECONNREFUSED
2025-01-23 07:37:42.297 25 ERROR cinder.volume.drivers.lightos 
2025-01-23 07:37:42.297 25 ERROR cinder.volume.drivers.lightos During handling of the above exception, another exception occurred:
2025-01-23 07:37:42.297 25 ERROR cinder.volume.drivers.lightos 
2025-01-23 07:37:42.297 25 ERROR cinder.volume.drivers.lightos Traceback (most recent call last):
2025-01-23 07:37:42.297 25 ERROR cinder.volume.drivers.lightos   File "/var/lib/kolla/venv/lib/python3.10/site-packages/urllib3/connectionpool.py", line 715, in urlopen
2025-01-23 07:37:42.297 25 ERROR cinder.volume.drivers.lightos     httplib_response = self._make_request(
2025-01-23 07:37:42.297 25 ERROR cinder.volume.drivers.lightos   File "/var/lib/kolla/venv/lib/python3.10/site-packages/urllib3/connectionpool.py", line 404, in _make_request
2025-01-23 07:37:42.297 25 ERROR cinder.volume.drivers.lightos     self._validate_conn(conn)
2025-01-23 07:37:42.297 25 ERROR cinder.volume.drivers.lightos   File "/var/lib/kolla/venv/lib/python3.10/site-packages/urllib3/connectionpool.py", line 1060, in _validate_conn
2025-01-23 07:37:42.297 25 ERROR cinder.volume.drivers.lightos     conn.connect()
2025-01-23 07:37:42.297 25 ERROR cinder.volume.drivers.lightos   File "/var/lib/kolla/venv/lib/python3.10/site-packages/urllib3/connection.py", line 363, in connect
2025-01-23 07:37:42.297 25 ERROR cinder.volume.drivers.lightos     self.sock = conn = self._new_conn()
2025-01-23 07:37:42.297 25 ERROR cinder.volume.drivers.lightos   File "/var/lib/kolla/venv/lib/python3.10/site-packages/urllib3/connection.py", line 186, in _new_conn
2025-01-23 07:37:42.297 25 ERROR cinder.volume.drivers.lightos     raise NewConnectionError(
2025-01-23 07:37:42.297 25 ERROR cinder.volume.drivers.lightos urllib3.exceptions.NewConnectionError: <urllib3.connection.HTTPSConnection object at 0x7f67697c9bd0>: Failed to establish a new connection: [Errno 111] ECONNREFUSED
2025-01-23 07:37:42.297 25 ERROR cinder.volume.drivers.lightos 
2025-01-23 07:37:42.297 25 ERROR cinder.volume.drivers.lightos During handling of the above exception, another exception occurred:
2025-01-23 07:37:42.297 25 ERROR cinder.volume.drivers.lightos 
2025-01-23 07:37:42.297 25 ERROR cinder.volume.drivers.lightos Traceback (most recent call last):
2025-01-23 07:37:42.297 25 ERROR cinder.volume.drivers.lightos   File "/var/lib/kolla/venv/lib/python3.10/site-packages/requests/adapters.py", line 667, in send
2025-01-23 07:37:42.297 25 ERROR cinder.volume.drivers.lightos     resp = conn.urlopen(
2025-01-23 07:37:42.297 25 ERROR cinder.volume.drivers.lightos   File "/var/lib/kolla/venv/lib/python3.10/site-packages/urllib3/connectionpool.py", line 801, in urlopen
2025-01-23 07:37:42.297 25 ERROR cinder.volume.drivers.lightos     retries = retries.increment(
2025-01-23 07:37:42.297 25 ERROR cinder.volume.drivers.lightos   File "/var/lib/kolla/venv/lib/python3.10/site-packages/urllib3/util/retry.py", line 594, in increment
2025-01-23 07:37:42.297 25 ERROR cinder.volume.drivers.lightos     raise MaxRetryError(_pool, url, error or ResponseError(cause))
2025-01-23 07:37:42.297 25 ERROR cinder.volume.drivers.lightos urllib3.exceptions.MaxRetryError: HTTPSConnectionPool(host='[LB_IP_ADDRESS]', port=443): Max retries exceeded with url: /api/v2/clusterinfo (Caused by NewConnectionError('<urllib3.connection.HTTPSConnection object at 0x7f67697c9bd0>: Failed to establish a new connection: [Errno 111] ECONNREFUSED'))
2025-01-23 07:37:42.297 25 ERROR cinder.volume.drivers.lightos 
2025-01-23 07:37:42.297 25 ERROR cinder.volume.drivers.lightos During handling of the above exception, another exception occurred:
2025-01-23 07:37:42.297 25 ERROR cinder.volume.drivers.lightos 
2025-01-23 07:37:42.297 25 ERROR cinder.volume.drivers.lightos Traceback (most recent call last):
2025-01-23 07:37:42.297 25 ERROR cinder.volume.drivers.lightos   File "/var/lib/kolla/venv/lib/python3.10/site-packages/cinder/volume/drivers/lightos.py", line 356, in __send_cmd
2025-01-23 07:37:42.297 25 ERROR cinder.volume.drivers.lightos     response = session.send(
2025-01-23 07:37:42.297 25 ERROR cinder.volume.drivers.lightos   File "/var/lib/kolla/venv/lib/python3.10/site-packages/requests/sessions.py", line 703, in send
2025-01-23 07:37:42.297 25 ERROR cinder.volume.drivers.lightos     r = adapter.send(request, **kwargs)
2025-01-23 07:37:42.297 25 ERROR cinder.volume.drivers.lightos   File "/var/lib/kolla/venv/lib/python3.10/site-packages/requests/adapters.py", line 700, in send
2025-01-23 07:37:42.297 25 ERROR cinder.volume.drivers.lightos     raise ConnectionError(e, request=request)
2025-01-23 07:37:42.297 25 ERROR cinder.volume.drivers.lightos requests.exceptions.ConnectionError: HTTPSConnectionPool(host='[LB_IP_ADDRESS]', port=443): Max retries exceeded with url: /api/v2/clusterinfo (Caused by NewConnectionError('<urllib3.connection.HTTPSConnection object at 0x7f67697c9bd0>: Failed to establish a new connection: [Errno 111] ECONNREFUSED'))
2025-01-23 07:37:42.297 25 ERROR cinder.volume.drivers.lightos 
2025-01-23 07:37:42.299 25 INFO cinder.volume.drivers.lightos [None req-066b0eec-78ec-4fb5-87d6-6609c5df9b40 - - - - - -] Invoking get_cluster_info using GET url: /api/v2/clusterinfo             request.body: {} ssl_verify: False
2025-01-23 07:37:45.378 25 ERROR cinder.volume.drivers.lightos [None req-066b0eec-78ec-4fb5-87d6-6609c5df9b40 - - - - - -] REST server not responding at 'https://[LB_IP_ADDRESS]:443/api/v2/clusterinfo': requests.exceptions.ConnectionError: HTTPSConnectionPool(host='[LB_IP_ADDRESS]', port=443): Max retries exceeded with url: /api/v2/clusterinfo (Caused by NewConnectionError('<urllib3.connection.HTTPSConnection object at 0x7f67697c8f10>: Failed to establish a new connection: [Errno 113] EHOSTUNREACH'))
2025-01-23 07:37:45.378 25 ERROR cinder.volume.drivers.lightos Traceback (most recent call last):
2025-01-23 07:37:45.378 25 ERROR cinder.volume.drivers.lightos   File "/var/lib/kolla/venv/lib/python3.10/site-packages/urllib3/connection.py", line 174, in _new_conn
2025-01-23 07:37:45.378 25 ERROR cinder.volume.drivers.lightos     conn = connection.create_connection(
2025-01-23 07:37:45.378 25 ERROR cinder.volume.drivers.lightos   File "/var/lib/kolla/venv/lib/python3.10/site-packages/urllib3/util/connection.py", line 95, in create_connection
2025-01-23 07:37:45.378 25 ERROR cinder.volume.drivers.lightos     raise err
2025-01-23 07:37:45.378 25 ERROR cinder.volume.drivers.lightos   File "/var/lib/kolla/venv/lib/python3.10/site-packages/urllib3/util/connection.py", line 85, in create_connection
2025-01-23 07:37:45.378 25 ERROR cinder.volume.drivers.lightos     sock.connect(sa)
2025-01-23 07:37:45.378 25 ERROR cinder.volume.drivers.lightos   File "/var/lib/kolla/venv/lib/python3.10/site-packages/eventlet/greenio/base.py", line 265, in connect
2025-01-23 07:37:45.378 25 ERROR cinder.volume.drivers.lightos     socket_checkerr(fd)
2025-01-23 07:37:45.378 25 ERROR cinder.volume.drivers.lightos   File "/var/lib/kolla/venv/lib/python3.10/site-packages/eventlet/greenio/base.py", line 50, in socket_checkerr
2025-01-23 07:37:45.378 25 ERROR cinder.volume.drivers.lightos     raise OSError(err, errno.errorcode[err])
2025-01-23 07:37:45.378 25 ERROR cinder.volume.drivers.lightos OSError: [Errno 113] EHOSTUNREACH
2025-01-23 07:37:45.378 25 ERROR cinder.volume.drivers.lightos 
2025-01-23 07:37:45.378 25 ERROR cinder.volume.drivers.lightos During handling of the above exception, another exception occurred:
2025-01-23 07:37:45.378 25 ERROR cinder.volume.drivers.lightos 
2025-01-23 07:37:45.378 25 ERROR cinder.volume.drivers.lightos Traceback (most recent call last):
2025-01-23 07:37:45.378 25 ERROR cinder.volume.drivers.lightos   File "/var/lib/kolla/venv/lib/python3.10/site-packages/urllib3/connectionpool.py", line 715, in urlopen
2025-01-23 07:37:45.378 25 ERROR cinder.volume.drivers.lightos     httplib_response = self._make_request(
2025-01-23 07:37:45.378 25 ERROR cinder.volume.drivers.lightos   File "/var/lib/kolla/venv/lib/python3.10/site-packages/urllib3/connectionpool.py", line 404, in _make_request
2025-01-23 07:37:45.378 25 ERROR cinder.volume.drivers.lightos     self._validate_conn(conn)
2025-01-23 07:37:45.378 25 ERROR cinder.volume.drivers.lightos   File "/var/lib/kolla/venv/lib/python3.10/site-packages/urllib3/connectionpool.py", line 1060, in _validate_conn
2025-01-23 07:37:45.378 25 ERROR cinder.volume.drivers.lightos     conn.connect()
2025-01-23 07:37:45.378 25 ERROR cinder.volume.drivers.lightos   File "/var/lib/kolla/venv/lib/python3.10/site-packages/urllib3/connection.py", line 363, in connect
2025-01-23 07:37:45.378 25 ERROR cinder.volume.drivers.lightos     self.sock = conn = self._new_conn()
2025-01-23 07:37:45.378 25 ERROR cinder.volume.drivers.lightos   File "/var/lib/kolla/venv/lib/python3.10/site-packages/urllib3/connection.py", line 186, in _new_conn
2025-01-23 07:37:45.378 25 ERROR cinder.volume.drivers.lightos     raise NewConnectionError(
2025-01-23 07:37:45.378 25 ERROR cinder.volume.drivers.lightos urllib3.exceptions.NewConnectionError: <urllib3.connection.HTTPSConnection object at 0x7f67697c8f10>: Failed to establish a new connection: [Errno 113] EHOSTUNREACH
2025-01-23 07:37:45.378 25 ERROR cinder.volume.drivers.lightos 
2025-01-23 07:37:45.378 25 ERROR cinder.volume.drivers.lightos During handling of the above exception, another exception occurred:
2025-01-23 07:37:45.378 25 ERROR cinder.volume.drivers.lightos 
2025-01-23 07:37:45.378 25 ERROR cinder.volume.drivers.lightos Traceback (most recent call last):
2025-01-23 07:37:45.378 25 ERROR cinder.volume.drivers.lightos   File "/var/lib/kolla/venv/lib/python3.10/site-packages/requests/adapters.py", line 667, in send
2025-01-23 07:37:45.378 25 ERROR cinder.volume.drivers.lightos     resp = conn.urlopen(
2025-01-23 07:37:45.378 25 ERROR cinder.volume.drivers.lightos   File "/var/lib/kolla/venv/lib/python3.10/site-packages/urllib3/connectionpool.py", line 801, in urlopen
2025-01-23 07:37:45.378 25 ERROR cinder.volume.drivers.lightos     retries = retries.increment(
2025-01-23 07:37:45.378 25 ERROR cinder.volume.drivers.lightos   File "/var/lib/kolla/venv/lib/python3.10/site-packages/urllib3/util/retry.py", line 594, in increment
2025-01-23 07:37:45.378 25 ERROR cinder.volume.drivers.lightos     raise MaxRetryError(_pool, url, error or ResponseError(cause))
2025-01-23 07:37:45.378 25 ERROR cinder.volume.drivers.lightos urllib3.exceptions.MaxRetryError: HTTPSConnectionPool(host='[LB_IP_ADDRESS]', port=443): Max retries exceeded with url: /api/v2/clusterinfo (Caused by NewConnectionError('<urllib3.connection.HTTPSConnection object at 0x7f67697c8f10>: Failed to establish a new connection: [Errno 113] EHOSTUNREACH'))
2025-01-23 07:37:45.378 25 ERROR cinder.volume.drivers.lightos 
2025-01-23 07:37:45.378 25 ERROR cinder.volume.drivers.lightos During handling of the above exception, another exception occurred:
2025-01-23 07:37:45.378 25 ERROR cinder.volume.drivers.lightos 
2025-01-23 07:37:45.378 25 ERROR cinder.volume.drivers.lightos Traceback (most recent call last):
2025-01-23 07:37:45.378 25 ERROR cinder.volume.drivers.lightos   File "/var/lib/kolla/venv/lib/python3.10/site-packages/cinder/volume/drivers/lightos.py", line 356, in __send_cmd
2025-01-23 07:37:45.378 25 ERROR cinder.volume.drivers.lightos     response = session.send(
2025-01-23 07:37:45.378 25 ERROR cinder.volume.drivers.lightos   File "/var/lib/kolla/venv/lib/python3.10/site-packages/requests/sessions.py", line 703, in send
2025-01-23 07:37:45.378 25 ERROR cinder.volume.drivers.lightos     r = adapter.send(request, **kwargs)
2025-01-23 07:37:45.378 25 ERROR cinder.volume.drivers.lightos   File "/var/lib/kolla/venv/lib/python3.10/site-packages/requests/adapters.py", line 700, in send
2025-01-23 07:37:45.378 25 ERROR cinder.volume.drivers.lightos     raise ConnectionError(e, request=request)
2025-01-23 07:37:45.378 25 ERROR cinder.volume.drivers.lightos requests.exceptions.ConnectionError: HTTPSConnectionPool(host='[LB_IP_ADDRESS]', port=443): Max retries exceeded with url: /api/v2/clusterinfo (Caused by NewConnectionError('<urllib3.connection.HTTPSConnection object at 0x7f67697c8f10>: Failed to establish a new connection: [Errno 113] EHOSTUNREACH'))
2025-01-23 07:37:45.378 25 ERROR cinder.volume.drivers.lightos 
2025-01-23 07:37:45.380 25 INFO cinder.volume.drivers.lightos [None req-066b0eec-78ec-4fb5-87d6-6609c5df9b40 - - - - - -] Invoking get_cluster_info using GET url: /api/v2/clusterinfo             request.body: {} ssl_verify: False
2025-01-23 07:37:45.383 25 ERROR cinder.volume.drivers.lightos [None req-066b0eec-78ec-4fb5-87d6-6609c5df9b40 - - - - - -] REST server not responding at 'https://[LB_IP_ADDRESS]:443/api/v2/clusterinfo': requests.exceptions.ConnectionError: HTTPSConnectionPool(host='[LB_IP_ADDRESS]', port=443): Max retries exceeded with url: /api/v2/clusterinfo (Caused by NewConnectionError('<urllib3.connection.HTTPSConnection object at 0x7f67697c8430>: Failed to establish a new connection: [Errno 111] ECONNREFUSED'))
2025-01-23 07:37:45.383 25 ERROR cinder.volume.drivers.lightos Traceback (most recent call last):
2025-01-23 07:37:45.383 25 ERROR cinder.volume.drivers.lightos   File "/var/lib/kolla/venv/lib/python3.10/site-packages/urllib3/connection.py", line 174, in _new_conn
2025-01-23 07:37:45.383 25 ERROR cinder.volume.drivers.lightos     conn = connection.create_connection(
2025-01-23 07:37:45.383 25 ERROR cinder.volume.drivers.lightos   File "/var/lib/kolla/venv/lib/python3.10/site-packages/urllib3/util/connection.py", line 95, in create_connection
2025-01-23 07:37:45.383 25 ERROR cinder.volume.drivers.lightos     raise err
2025-01-23 07:37:45.383 25 ERROR cinder.volume.drivers.lightos   File "/var/lib/kolla/venv/lib/python3.10/site-packages/urllib3/util/connection.py", line 85, in create_connection
2025-01-23 07:37:45.383 25 ERROR cinder.volume.drivers.lightos     sock.connect(sa)
2025-01-23 07:37:45.383 25 ERROR cinder.volume.drivers.lightos   File "/var/lib/kolla/venv/lib/python3.10/site-packages/eventlet/greenio/base.py", line 265, in connect
2025-01-23 07:37:45.383 25 ERROR cinder.volume.drivers.lightos     socket_checkerr(fd)
2025-01-23 07:37:45.383 25 ERROR cinder.volume.drivers.lightos   File "/var/lib/kolla/venv/lib/python3.10/site-packages/eventlet/greenio/base.py", line 50, in socket_checkerr
2025-01-23 07:37:45.383 25 ERROR cinder.volume.drivers.lightos     raise OSError(err, errno.errorcode[err])
2025-01-23 07:37:45.383 25 ERROR cinder.volume.drivers.lightos ConnectionRefusedError: [Errno 111] ECONNREFUSED
2025-01-23 07:37:45.383 25 ERROR cinder.volume.drivers.lightos 
2025-01-23 07:37:45.383 25 ERROR cinder.volume.drivers.lightos During handling of the above exception, another exception occurred:
2025-01-23 07:37:45.383 25 ERROR cinder.volume.drivers.lightos 
2025-01-23 07:37:45.383 25 ERROR cinder.volume.drivers.lightos Traceback (most recent call last):
2025-01-23 07:37:45.383 25 ERROR cinder.volume.drivers.lightos   File "/var/lib/kolla/venv/lib/python3.10/site-packages/urllib3/connectionpool.py", line 715, in urlopen
2025-01-23 07:37:45.383 25 ERROR cinder.volume.drivers.lightos     httplib_response = self._make_request(
2025-01-23 07:37:45.383 25 ERROR cinder.volume.drivers.lightos   File "/var/lib/kolla/venv/lib/python3.10/site-packages/urllib3/connectionpool.py", line 404, in _make_request
2025-01-23 07:37:45.383 25 ERROR cinder.volume.drivers.lightos     self._validate_conn(conn)
2025-01-23 07:37:45.383 25 ERROR cinder.volume.drivers.lightos   File "/var/lib/kolla/venv/lib/python3.10/site-packages/urllib3/connectionpool.py", line 1060, in _validate_conn
2025-01-23 07:37:45.383 25 ERROR cinder.volume.drivers.lightos     conn.connect()
2025-01-23 07:37:45.383 25 ERROR cinder.volume.drivers.lightos   File "/var/lib/kolla/venv/lib/python3.10/site-packages/urllib3/connection.py", line 363, in connect
2025-01-23 07:37:45.383 25 ERROR cinder.volume.drivers.lightos     self.sock = conn = self._new_conn()
2025-01-23 07:37:45.383 25 ERROR cinder.volume.drivers.lightos   File "/var/lib/kolla/venv/lib/python3.10/site-packages/urllib3/connection.py", line 186, in _new_conn
2025-01-23 07:37:45.383 25 ERROR cinder.volume.drivers.lightos     raise NewConnectionError(
2025-01-23 07:37:45.383 25 ERROR cinder.volume.drivers.lightos urllib3.exceptions.NewConnectionError: <urllib3.connection.HTTPSConnection object at 0x7f67697c8430>: Failed to establish a new connection: [Errno 111] ECONNREFUSED
2025-01-23 07:37:45.383 25 ERROR cinder.volume.drivers.lightos 
2025-01-23 07:37:45.383 25 ERROR cinder.volume.drivers.lightos During handling of the above exception, another exception occurred:
2025-01-23 07:37:45.383 25 ERROR cinder.volume.drivers.lightos 
2025-01-23 07:37:45.383 25 ERROR cinder.volume.drivers.lightos Traceback (most recent call last):
2025-01-23 07:37:45.383 25 ERROR cinder.volume.drivers.lightos   File "/var/lib/kolla/venv/lib/python3.10/site-packages/requests/adapters.py", line 667, in send
2025-01-23 07:37:45.383 25 ERROR cinder.volume.drivers.lightos     resp = conn.urlopen(
2025-01-23 07:37:45.383 25 ERROR cinder.volume.drivers.lightos   File "/var/lib/kolla/venv/lib/python3.10/site-packages/urllib3/connectionpool.py", line 801, in urlopen
2025-01-23 07:37:45.383 25 ERROR cinder.volume.drivers.lightos     retries = retries.increment(
2025-01-23 07:37:45.383 25 ERROR cinder.volume.drivers.lightos   File "/var/lib/kolla/venv/lib/python3.10/site-packages/urllib3/util/retry.py", line 594, in increment
2025-01-23 07:37:45.383 25 ERROR cinder.volume.drivers.lightos     raise MaxRetryError(_pool, url, error or ResponseError(cause))
2025-01-23 07:37:45.383 25 ERROR cinder.volume.drivers.lightos urllib3.exceptions.MaxRetryError: HTTPSConnectionPool(host='[LB_IP_ADDRESS]', port=443): Max retries exceeded with url: /api/v2/clusterinfo (Caused by NewConnectionError('<urllib3.connection.HTTPSConnection object at 0x7f67697c8430>: Failed to establish a new connection: [Errno 111] ECONNREFUSED'))
2025-01-23 07:37:45.383 25 ERROR cinder.volume.drivers.lightos 
2025-01-23 07:37:45.383 25 ERROR cinder.volume.drivers.lightos During handling of the above exception, another exception occurred:
2025-01-23 07:37:45.383 25 ERROR cinder.volume.drivers.lightos 
2025-01-23 07:37:45.383 25 ERROR cinder.volume.drivers.lightos Traceback (most recent call last):
2025-01-23 07:37:45.383 25 ERROR cinder.volume.drivers.lightos   File "/var/lib/kolla/venv/lib/python3.10/site-packages/cinder/volume/drivers/lightos.py", line 356, in __send_cmd
2025-01-23 07:37:45.383 25 ERROR cinder.volume.drivers.lightos     response = session.send(
2025-01-23 07:37:45.383 25 ERROR cinder.volume.drivers.lightos   File "/var/lib/kolla/venv/lib/python3.10/site-packages/requests/sessions.py", line 703, in send
2025-01-23 07:37:45.383 25 ERROR cinder.volume.drivers.lightos     r = adapter.send(request, **kwargs)
2025-01-23 07:37:45.383 25 ERROR cinder.volume.drivers.lightos   File "/var/lib/kolla/venv/lib/python3.10/site-packages/requests/adapters.py", line 700, in send
2025-01-23 07:37:45.383 25 ERROR cinder.volume.drivers.lightos     raise ConnectionError(e, request=request)
2025-01-23 07:37:45.383 25 ERROR cinder.volume.drivers.lightos requests.exceptions.ConnectionError: HTTPSConnectionPool(host='[LB_IP_ADDRESS]', port=443): Max retries exceeded with url: /api/v2/clusterinfo (Caused by NewConnectionError('<urllib3.connection.HTTPSConnection object at 0x7f67697c8430>: Failed to establish a new connection: [Errno 111] ECONNREFUSED'))
2025-01-23 07:37:45.383 25 ERROR cinder.volume.drivers.lightos 
2025-01-23 07:37:45.386 25 ERROR cinder.volume.manager [None req-066b0eec-78ec-4fb5-87d6-6609c5df9b40 - - - - - -] Failed to initialize driver.: cinder.exception.VolumeDriverException: Volume driver reported an error: Could not get a response from any API server
2025-01-23 07:37:45.386 25 ERROR cinder.volume.manager Traceback (most recent call last):
2025-01-23 07:37:45.386 25 ERROR cinder.volume.manager   File "/var/lib/kolla/venv/lib/python3.10/site-packages/cinder/volume/manager.py", line 523, in _init_host
2025-01-23 07:37:45.386 25 ERROR cinder.volume.manager     self.driver.do_setup(ctxt)
2025-01-23 07:37:45.386 25 ERROR cinder.volume.manager   File "/var/lib/kolla/venv/lib/python3.10/site-packages/cinder/volume/drivers/lightos.py", line 922, in do_setup
2025-01-23 07:37:45.386 25 ERROR cinder.volume.manager     self.get_cluster_info()
2025-01-23 07:37:45.386 25 ERROR cinder.volume.manager   File "/var/lib/kolla/venv/lib/python3.10/site-packages/cinder/volume/drivers/lightos.py", line 873, in get_cluster_info
2025-01-23 07:37:45.386 25 ERROR cinder.volume.manager     status_code, cluster_info = self.cluster.send_cmd(
2025-01-23 07:37:45.386 25 ERROR cinder.volume.manager   File "/var/lib/kolla/venv/lib/python3.10/site-packages/cinder/volume/drivers/lightos.py", line 315, in send_cmd
2025-01-23 07:37:45.386 25 ERROR cinder.volume.manager     raise exception.VolumeDriverException(
2025-01-23 07:37:45.386 25 ERROR cinder.volume.manager cinder.exception.VolumeDriverException: Volume driver reported an error: Could not get a response from any API server
2025-01-23 07:37:45.386 25 ERROR cinder.volume.manager 
2025-01-23 07:37:46.391 25 INFO cinder.volume.manager [None req-066b0eec-78ec-4fb5-87d6-6609c5df9b40 - - - - - -] Starting volume driver LightOSVolumeDriver (2.3.12)
2025-01-23 07:37:46.391 25 INFO cinder.volume.drivers.lightos [None req-066b0eec-78ec-4fb5-87d6-6609c5df9b40 - - - - - -] Invoking get_cluster_info using GET url: /api/v2/clusterinfo             request.body: {} ssl_verify: False
2025-01-23 07:37:46.395 25 ERROR cinder.volume.drivers.lightos [None req-066b0eec-78ec-4fb5-87d6-6609c5df9b40 - - - - - -] REST server not responding at 'https://[LB_IP_ADDRESS]:443/api/v2/clusterinfo': requests.exceptions.ConnectionError: HTTPSConnectionPool(host='[LB_IP_ADDRESS]', port=443): Max retries exceeded with url: /api/v2/clusterinfo (Caused by NewConnectionError('<urllib3.connection.HTTPSConnection object at 0x7f67697c87c0>: Failed to establish a new connection: [Errno 111] ECONNREFUSED'))
2025-01-23 07:37:46.395 25 ERROR cinder.volume.drivers.lightos Traceback (most recent call last):
2025-01-23 07:37:46.395 25 ERROR cinder.volume.drivers.lightos   File "/var/lib/kolla/venv/lib/python3.10/site-packages/urllib3/connection.py", line 174, in _new_conn
2025-01-23 07:37:46.395 25 ERROR cinder.volume.drivers.lightos     conn = connection.create_connection(
2025-01-23 07:37:46.395 25 ERROR cinder.volume.drivers.lightos   File "/var/lib/kolla/venv/lib/python3.10/site-packages/urllib3/util/connection.py", line 95, in create_connection
2025-01-23 07:37:46.395 25 ERROR cinder.volume.drivers.lightos     raise err
2025-01-23 07:37:46.395 25 ERROR cinder.volume.drivers.lightos   File "/var/lib/kolla/venv/lib/python3.10/site-packages/urllib3/util/connection.py", line 85, in create_connection
2025-01-23 07:37:46.395 25 ERROR cinder.volume.drivers.lightos     sock.connect(sa)
2025-01-23 07:37:46.395 25 ERROR cinder.volume.drivers.lightos   File "/var/lib/kolla/venv/lib/python3.10/site-packages/eventlet/greenio/base.py", line 265, in connect
2025-01-23 07:37:46.395 25 ERROR cinder.volume.drivers.lightos     socket_checkerr(fd)
2025-01-23 07:37:46.395 25 ERROR cinder.volume.drivers.lightos   File "/var/lib/kolla/venv/lib/python3.10/site-packages/eventlet/greenio/base.py", line 50, in socket_checkerr
2025-01-23 07:37:46.395 25 ERROR cinder.volume.drivers.lightos     raise OSError(err, errno.errorcode[err])
2025-01-23 07:37:46.395 25 ERROR cinder.volume.drivers.lightos ConnectionRefusedError: [Errno 111] ECONNREFUSED
2025-01-23 07:37:46.395 25 ERROR cinder.volume.drivers.lightos 
2025-01-23 07:37:46.395 25 ERROR cinder.volume.drivers.lightos During handling of the above exception, another exception occurred:
2025-01-23 07:37:46.395 25 ERROR cinder.volume.drivers.lightos 
2025-01-23 07:37:46.395 25 ERROR cinder.volume.drivers.lightos Traceback (most recent call last):
2025-01-23 07:37:46.395 25 ERROR cinder.volume.drivers.lightos   File "/var/lib/kolla/venv/lib/python3.10/site-packages/urllib3/connectionpool.py", line 715, in urlopen
2025-01-23 07:37:46.395 25 ERROR cinder.volume.drivers.lightos     httplib_response = self._make_request(
2025-01-23 07:37:46.395 25 ERROR cinder.volume.drivers.lightos   File "/var/lib/kolla/venv/lib/python3.10/site-packages/urllib3/connectionpool.py", line 404, in _make_request
2025-01-23 07:37:46.395 25 ERROR cinder.volume.drivers.lightos     self._validate_conn(conn)
2025-01-23 07:37:46.395 25 ERROR cinder.volume.drivers.lightos   File "/var/lib/kolla/venv/lib/python3.10/site-packages/urllib3/connectionpool.py", line 1060, in _validate_conn
2025-01-23 07:37:46.395 25 ERROR cinder.volume.drivers.lightos     conn.connect()
2025-01-23 07:37:46.395 25 ERROR cinder.volume.drivers.lightos   File "/var/lib/kolla/venv/lib/python3.10/site-packages/urllib3/connection.py", line 363, in connect
2025-01-23 07:37:46.395 25 ERROR cinder.volume.drivers.lightos     self.sock = conn = self._new_conn()
2025-01-23 07:37:46.395 25 ERROR cinder.volume.drivers.lightos   File "/var/lib/kolla/venv/lib/python3.10/site-packages/urllib3/connection.py", line 186, in _new_conn
2025-01-23 07:37:46.395 25 ERROR cinder.volume.drivers.lightos     raise NewConnectionError(
2025-01-23 07:37:46.395 25 ERROR cinder.volume.drivers.lightos urllib3.exceptions.NewConnectionError: <urllib3.connection.HTTPSConnection object at 0x7f67697c87c0>: Failed to establish a new connection: [Errno 111] ECONNREFUSED
2025-01-23 07:37:46.395 25 ERROR cinder.volume.drivers.lightos 
2025-01-23 07:37:46.395 25 ERROR cinder.volume.drivers.lightos During handling of the above exception, another exception occurred:
2025-01-23 07:37:46.395 25 ERROR cinder.volume.drivers.lightos 
2025-01-23 07:37:46.395 25 ERROR cinder.volume.drivers.lightos Traceback (most recent call last):
2025-01-23 07:37:46.395 25 ERROR cinder.volume.drivers.lightos   File "/var/lib/kolla/venv/lib/python3.10/site-packages/requests/adapters.py", line 667, in send
2025-01-23 07:37:46.395 25 ERROR cinder.volume.drivers.lightos     resp = conn.urlopen(
2025-01-23 07:37:46.395 25 ERROR cinder.volume.drivers.lightos   File "/var/lib/kolla/venv/lib/python3.10/site-packages/urllib3/connectionpool.py", line 801, in urlopen
2025-01-23 07:37:46.395 25 ERROR cinder.volume.drivers.lightos     retries = retries.increment(
2025-01-23 07:37:46.395 25 ERROR cinder.volume.drivers.lightos   File "/var/lib/kolla/venv/lib/python3.10/site-packages/urllib3/util/retry.py", line 594, in increment
2025-01-23 07:37:46.395 25 ERROR cinder.volume.drivers.lightos     raise MaxRetryError(_pool, url, error or ResponseError(cause))
2025-01-23 07:37:46.395 25 ERROR cinder.volume.drivers.lightos urllib3.exceptions.MaxRetryError: HTTPSConnectionPool(host='[LB_IP_ADDRESS]', port=443): Max retries exceeded with url: /api/v2/clusterinfo (Caused by NewConnectionError('<urllib3.connection.HTTPSConnection object at 0x7f67697c87c0>: Failed to establish a new connection: [Errno 111] ECONNREFUSED'))
2025-01-23 07:37:46.395 25 ERROR cinder.volume.drivers.lightos 
2025-01-23 07:37:46.395 25 ERROR cinder.volume.drivers.lightos During handling of the above exception, another exception occurred:
2025-01-23 07:37:46.395 25 ERROR cinder.volume.drivers.lightos 
2025-01-23 07:37:46.395 25 ERROR cinder.volume.drivers.lightos Traceback (most recent call last):
2025-01-23 07:37:46.395 25 ERROR cinder.volume.drivers.lightos   File "/var/lib/kolla/venv/lib/python3.10/site-packages/cinder/volume/drivers/lightos.py", line 356, in __send_cmd
2025-01-23 07:37:46.395 25 ERROR cinder.volume.drivers.lightos     response = session.send(
2025-01-23 07:37:46.395 25 ERROR cinder.volume.drivers.lightos   File "/var/lib/kolla/venv/lib/python3.10/site-packages/requests/sessions.py", line 703, in send
2025-01-23 07:37:46.395 25 ERROR cinder.volume.drivers.lightos     r = adapter.send(request, **kwargs)
2025-01-23 07:37:46.395 25 ERROR cinder.volume.drivers.lightos   File "/var/lib/kolla/venv/lib/python3.10/site-packages/requests/adapters.py", line 700, in send
2025-01-23 07:37:46.395 25 ERROR cinder.volume.drivers.lightos     raise ConnectionError(e, request=request)
2025-01-23 07:37:46.395 25 ERROR cinder.volume.drivers.lightos requests.exceptions.ConnectionError: HTTPSConnectionPool(host='[LB_IP_ADDRESS]', port=443): Max retries exceeded with url: /api/v2/clusterinfo (Caused by NewConnectionError('<urllib3.connection.HTTPSConnection object at 0x7f67697c87c0>: Failed to establish a new connection: [Errno 111] ECONNREFUSED'))
2025-01-23 07:37:46.395 25 ERROR cinder.volume.drivers.lightos 
2025-01-23 07:37:46.398 25 INFO cinder.volume.drivers.lightos [None req-066b0eec-78ec-4fb5-87d6-6609c5df9b40 - - - - - -] Invoking get_cluster_info using GET url: /api/v2/clusterinfo             request.body: {} ssl_verify: False
2025-01-23 07:37:48.449 25 ERROR cinder.volume.drivers.lightos [None req-066b0eec-78ec-4fb5-87d6-6609c5df9b40 - - - - - -] REST server not responding at 'https://[LB_IP_ADDRESS]:443/api/v2/clusterinfo': requests.exceptions.ConnectionError: HTTPSConnectionPool(host='[LB_IP_ADDRESS]', port=443): Max retries exceeded with url: /api/v2/clusterinfo (Caused by NewConnectionError('<urllib3.connection.HTTPSConnection object at 0x7f67697c9210>: Failed to establish a new connection: [Errno 113] EHOSTUNREACH'))
2025-01-23 07:37:48.449 25 ERROR cinder.volume.drivers.lightos Traceback (most recent call last):
2025-01-23 07:37:48.449 25 ERROR cinder.volume.drivers.lightos   File "/var/lib/kolla/venv/lib/python3.10/site-packages/urllib3/connection.py", line 174, in _new_conn
2025-01-23 07:37:48.449 25 ERROR cinder.volume.drivers.lightos     conn = connection.create_connection(
2025-01-23 07:37:48.449 25 ERROR cinder.volume.drivers.lightos   File "/var/lib/kolla/venv/lib/python3.10/site-packages/urllib3/util/connection.py", line 95, in create_connection
2025-01-23 07:37:48.449 25 ERROR cinder.volume.drivers.lightos     raise err
2025-01-23 07:37:48.449 25 ERROR cinder.volume.drivers.lightos   File "/var/lib/kolla/venv/lib/python3.10/site-packages/urllib3/util/connection.py", line 85, in create_connection
2025-01-23 07:37:48.449 25 ERROR cinder.volume.drivers.lightos     sock.connect(sa)
2025-01-23 07:37:48.449 25 ERROR cinder.volume.drivers.lightos   File "/var/lib/kolla/venv/lib/python3.10/site-packages/eventlet/greenio/base.py", line 265, in connect
2025-01-23 07:37:48.449 25 ERROR cinder.volume.drivers.lightos     socket_checkerr(fd)
2025-01-23 07:37:48.449 25 ERROR cinder.volume.drivers.lightos   File "/var/lib/kolla/venv/lib/python3.10/site-packages/eventlet/greenio/base.py", line 50, in socket_checkerr
2025-01-23 07:37:48.449 25 ERROR cinder.volume.drivers.lightos     raise OSError(err, errno.errorcode[err])
2025-01-23 07:37:48.449 25 ERROR cinder.volume.drivers.lightos OSError: [Errno 113] EHOSTUNREACH
2025-01-23 07:37:48.449 25 ERROR cinder.volume.drivers.lightos 
2025-01-23 07:37:48.449 25 ERROR cinder.volume.drivers.lightos During handling of the above exception, another exception occurred:
2025-01-23 07:37:48.449 25 ERROR cinder.volume.drivers.lightos 
2025-01-23 07:37:48.449 25 ERROR cinder.volume.drivers.lightos Traceback (most recent call last):
2025-01-23 07:37:48.449 25 ERROR cinder.volume.drivers.lightos   File "/var/lib/kolla/venv/lib/python3.10/site-packages/urllib3/connectionpool.py", line 715, in urlopen
2025-01-23 07:37:48.449 25 ERROR cinder.volume.drivers.lightos     httplib_response = self._make_request(
2025-01-23 07:37:48.449 25 ERROR cinder.volume.drivers.lightos   File "/var/lib/kolla/venv/lib/python3.10/site-packages/urllib3/connectionpool.py", line 404, in _make_request
2025-01-23 07:37:48.449 25 ERROR cinder.volume.drivers.lightos     self._validate_conn(conn)
2025-01-23 07:37:48.449 25 ERROR cinder.volume.drivers.lightos   File "/var/lib/kolla/venv/lib/python3.10/site-packages/urllib3/connectionpool.py", line 1060, in _validate_conn
2025-01-23 07:37:48.449 25 ERROR cinder.volume.drivers.lightos     conn.connect()
2025-01-23 07:37:48.449 25 ERROR cinder.volume.drivers.lightos   File "/var/lib/kolla/venv/lib/python3.10/site-packages/urllib3/connection.py", line 363, in connect
2025-01-23 07:37:48.449 25 ERROR cinder.volume.drivers.lightos     self.sock = conn = self._new_conn()
2025-01-23 07:37:48.449 25 ERROR cinder.volume.drivers.lightos   File "/var/lib/kolla/venv/lib/python3.10/site-packages/urllib3/connection.py", line 186, in _new_conn
2025-01-23 07:37:48.449 25 ERROR cinder.volume.drivers.lightos     raise NewConnectionError(
2025-01-23 07:37:48.449 25 ERROR cinder.volume.drivers.lightos urllib3.exceptions.NewConnectionError: <urllib3.connection.HTTPSConnection object at 0x7f67697c9210>: Failed to establish a new connection: [Errno 113] EHOSTUNREACH
2025-01-23 07:37:48.449 25 ERROR cinder.volume.drivers.lightos 
2025-01-23 07:37:48.449 25 ERROR cinder.volume.drivers.lightos During handling of the above exception, another exception occurred:
2025-01-23 07:37:48.449 25 ERROR cinder.volume.drivers.lightos 
2025-01-23 07:37:48.449 25 ERROR cinder.volume.drivers.lightos Traceback (most recent call last):
2025-01-23 07:37:48.449 25 ERROR cinder.volume.drivers.lightos   File "/var/lib/kolla/venv/lib/python3.10/site-packages/requests/adapters.py", line 667, in send
2025-01-23 07:37:48.449 25 ERROR cinder.volume.drivers.lightos     resp = conn.urlopen(
2025-01-23 07:37:48.449 25 ERROR cinder.volume.drivers.lightos   File "/var/lib/kolla/venv/lib/python3.10/site-packages/urllib3/connectionpool.py", line 801, in urlopen
2025-01-23 07:37:48.449 25 ERROR cinder.volume.drivers.lightos     retries = retries.increment(
2025-01-23 07:37:48.449 25 ERROR cinder.volume.drivers.lightos   File "/var/lib/kolla/venv/lib/python3.10/site-packages/urllib3/util/retry.py", line 594, in increment
2025-01-23 07:37:48.449 25 ERROR cinder.volume.drivers.lightos     raise MaxRetryError(_pool, url, error or ResponseError(cause))
2025-01-23 07:37:48.449 25 ERROR cinder.volume.drivers.lightos urllib3.exceptions.MaxRetryError: HTTPSConnectionPool(host='[LB_IP_ADDRESS]', port=443): Max retries exceeded with url: /api/v2/clusterinfo (Caused by NewConnectionError('<urllib3.connection.HTTPSConnection object at 0x7f67697c9210>: Failed to establish a new connection: [Errno 113] EHOSTUNREACH'))
2025-01-23 07:37:48.449 25 ERROR cinder.volume.drivers.lightos 
2025-01-23 07:37:48.449 25 ERROR cinder.volume.drivers.lightos During handling of the above exception, another exception occurred:
2025-01-23 07:37:48.449 25 ERROR cinder.volume.drivers.lightos 
2025-01-23 07:37:48.449 25 ERROR cinder.volume.drivers.lightos Traceback (most recent call last):
2025-01-23 07:37:48.449 25 ERROR cinder.volume.drivers.lightos   File "/var/lib/kolla/venv/lib/python3.10/site-packages/cinder/volume/drivers/lightos.py", line 356, in __send_cmd
2025-01-23 07:37:48.449 25 ERROR cinder.volume.drivers.lightos     response = session.send(
2025-01-23 07:37:48.449 25 ERROR cinder.volume.drivers.lightos   File "/var/lib/kolla/venv/lib/python3.10/site-packages/requests/sessions.py", line 703, in send
2025-01-23 07:37:48.449 25 ERROR cinder.volume.drivers.lightos     r = adapter.send(request, **kwargs)
2025-01-23 07:37:48.449 25 ERROR cinder.volume.drivers.lightos   File "/var/lib/kolla/venv/lib/python3.10/site-packages/requests/adapters.py", line 700, in send
2025-01-23 07:37:48.449 25 ERROR cinder.volume.drivers.lightos     raise ConnectionError(e, request=request)
2025-01-23 07:37:48.449 25 ERROR cinder.volume.drivers.lightos requests.exceptions.ConnectionError: HTTPSConnectionPool(host='[LB_IP_ADDRESS]', port=443): Max retries exceeded with url: /api/v2/clusterinfo (Caused by NewConnectionError('<urllib3.connection.HTTPSConnection object at 0x7f67697c9210>: Failed to establish a new connection: [Errno 113] EHOSTUNREACH'))
2025-01-23 07:37:48.449 25 ERROR cinder.volume.drivers.lightos 
2025-01-23 07:37:48.452 25 INFO cinder.volume.drivers.lightos [None req-066b0eec-78ec-4fb5-87d6-6609c5df9b40 - - - - - -] Invoking get_cluster_info using GET url: /api/v2/clusterinfo             request.body: {} ssl_verify: False
2025-01-23 07:37:48.455 25 ERROR cinder.volume.drivers.lightos [None req-066b0eec-78ec-4fb5-87d6-6609c5df9b40 - - - - - -] REST server not responding at 'https://[LB_IP_ADDRESS]:443/api/v2/clusterinfo': requests.exceptions.ConnectionError: HTTPSConnectionPool(host='[LB_IP_ADDRESS]', port=443): Max retries exceeded with url: /api/v2/clusterinfo (Caused by NewConnectionError('<urllib3.connection.HTTPSConnection object at 0x7f67697ca290>: Failed to establish a new connection: [Errno 111] ECONNREFUSED'))
2025-01-23 07:37:48.455 25 ERROR cinder.volume.drivers.lightos Traceback (most recent call last):
2025-01-23 07:37:48.455 25 ERROR cinder.volume.drivers.lightos   File "/var/lib/kolla/venv/lib/python3.10/site-packages/urllib3/connection.py", line 174, in _new_conn
2025-01-23 07:37:48.455 25 ERROR cinder.volume.drivers.lightos     conn = connection.create_connection(
2025-01-23 07:37:48.455 25 ERROR cinder.volume.drivers.lightos   File "/var/lib/kolla/venv/lib/python3.10/site-packages/urllib3/util/connection.py", line 95, in create_connection
2025-01-23 07:37:48.455 25 ERROR cinder.volume.drivers.lightos     raise err
2025-01-23 07:37:48.455 25 ERROR cinder.volume.drivers.lightos   File "/var/lib/kolla/venv/lib/python3.10/site-packages/urllib3/util/connection.py", line 85, in create_connection
2025-01-23 07:37:48.455 25 ERROR cinder.volume.drivers.lightos     sock.connect(sa)
2025-01-23 07:37:48.455 25 ERROR cinder.volume.drivers.lightos   File "/var/lib/kolla/venv/lib/python3.10/site-packages/eventlet/greenio/base.py", line 265, in connect
2025-01-23 07:37:48.455 25 ERROR cinder.volume.drivers.lightos     socket_checkerr(fd)
2025-01-23 07:37:48.455 25 ERROR cinder.volume.drivers.lightos   File "/var/lib/kolla/venv/lib/python3.10/site-packages/eventlet/greenio/base.py", line 50, in socket_checkerr
2025-01-23 07:37:48.455 25 ERROR cinder.volume.drivers.lightos     raise OSError(err, errno.errorcode[err])
2025-01-23 07:37:48.455 25 ERROR cinder.volume.drivers.lightos ConnectionRefusedError: [Errno 111] ECONNREFUSED
2025-01-23 07:37:48.455 25 ERROR cinder.volume.drivers.lightos 
2025-01-23 07:37:48.455 25 ERROR cinder.volume.drivers.lightos During handling of the above exception, another exception occurred:
2025-01-23 07:37:48.455 25 ERROR cinder.volume.drivers.lightos 
2025-01-23 07:37:48.455 25 ERROR cinder.volume.drivers.lightos Traceback (most recent call last):
2025-01-23 07:37:48.455 25 ERROR cinder.volume.drivers.lightos   File "/var/lib/kolla/venv/lib/python3.10/site-packages/urllib3/connectionpool.py", line 715, in urlopen
2025-01-23 07:37:48.455 25 ERROR cinder.volume.drivers.lightos     httplib_response = self._make_request(
2025-01-23 07:37:48.455 25 ERROR cinder.volume.drivers.lightos   File "/var/lib/kolla/venv/lib/python3.10/site-packages/urllib3/connectionpool.py", line 404, in _make_request
2025-01-23 07:37:48.455 25 ERROR cinder.volume.drivers.lightos     self._validate_conn(conn)
2025-01-23 07:37:48.455 25 ERROR cinder.volume.drivers.lightos   File "/var/lib/kolla/venv/lib/python3.10/site-packages/urllib3/connectionpool.py", line 1060, in _validate_conn
2025-01-23 07:37:48.455 25 ERROR cinder.volume.drivers.lightos     conn.connect()
2025-01-23 07:37:48.455 25 ERROR cinder.volume.drivers.lightos   File "/var/lib/kolla/venv/lib/python3.10/site-packages/urllib3/connection.py", line 363, in connect
2025-01-23 07:37:48.455 25 ERROR cinder.volume.drivers.lightos     self.sock = conn = self._new_conn()
2025-01-23 07:37:48.455 25 ERROR cinder.volume.drivers.lightos   File "/var/lib/kolla/venv/lib/python3.10/site-packages/urllib3/connection.py", line 186, in _new_conn
2025-01-23 07:37:48.455 25 ERROR cinder.volume.drivers.lightos     raise NewConnectionError(
2025-01-23 07:37:48.455 25 ERROR cinder.volume.drivers.lightos urllib3.exceptions.NewConnectionError: <urllib3.connection.HTTPSConnection object at 0x7f67697ca290>: Failed to establish a new connection: [Errno 111] ECONNREFUSED
2025-01-23 07:37:48.455 25 ERROR cinder.volume.drivers.lightos 
2025-01-23 07:37:48.455 25 ERROR cinder.volume.drivers.lightos During handling of the above exception, another exception occurred:
2025-01-23 07:37:48.455 25 ERROR cinder.volume.drivers.lightos 
2025-01-23 07:37:48.455 25 ERROR cinder.volume.drivers.lightos Traceback (most recent call last):
2025-01-23 07:37:48.455 25 ERROR cinder.volume.drivers.lightos   File "/var/lib/kolla/venv/lib/python3.10/site-packages/requests/adapters.py", line 667, in send
2025-01-23 07:37:48.455 25 ERROR cinder.volume.drivers.lightos     resp = conn.urlopen(
2025-01-23 07:37:48.455 25 ERROR cinder.volume.drivers.lightos   File "/var/lib/kolla/venv/lib/python3.10/site-packages/urllib3/connectionpool.py", line 801, in urlopen
2025-01-23 07:37:48.455 25 ERROR cinder.volume.drivers.lightos     retries = retries.increment(
2025-01-23 07:37:48.455 25 ERROR cinder.volume.drivers.lightos   File "/var/lib/kolla/venv/lib/python3.10/site-packages/urllib3/util/retry.py", line 594, in increment
2025-01-23 07:37:48.455 25 ERROR cinder.volume.drivers.lightos     raise MaxRetryError(_pool, url, error or ResponseError(cause))
2025-01-23 07:37:48.455 25 ERROR cinder.volume.drivers.lightos urllib3.exceptions.MaxRetryError: HTTPSConnectionPool(host='[LB_IP_ADDRESS]', port=443): Max retries exceeded with url: /api/v2/clusterinfo (Caused by NewConnectionError('<urllib3.connection.HTTPSConnection object at 0x7f67697ca290>: Failed to establish a new connection: [Errno 111] ECONNREFUSED'))
2025-01-23 07:37:48.455 25 ERROR cinder.volume.drivers.lightos 
2025-01-23 07:37:48.455 25 ERROR cinder.volume.drivers.lightos During handling of the above exception, another exception occurred:
2025-01-23 07:37:48.455 25 ERROR cinder.volume.drivers.lightos 
2025-01-23 07:37:48.455 25 ERROR cinder.volume.drivers.lightos Traceback (most recent call last):
2025-01-23 07:37:48.455 25 ERROR cinder.volume.drivers.lightos   File "/var/lib/kolla/venv/lib/python3.10/site-packages/cinder/volume/drivers/lightos.py", line 356, in __send_cmd
2025-01-23 07:37:48.455 25 ERROR cinder.volume.drivers.lightos     response = session.send(
2025-01-23 07:37:48.455 25 ERROR cinder.volume.drivers.lightos   File "/var/lib/kolla/venv/lib/python3.10/site-packages/requests/sessions.py", line 703, in send
2025-01-23 07:37:48.455 25 ERROR cinder.volume.drivers.lightos     r = adapter.send(request, **kwargs)
2025-01-23 07:37:48.455 25 ERROR cinder.volume.drivers.lightos   File "/var/lib/kolla/venv/lib/python3.10/site-packages/requests/adapters.py", line 700, in send
2025-01-23 07:37:48.455 25 ERROR cinder.volume.drivers.lightos     raise ConnectionError(e, request=request)
2025-01-23 07:37:48.455 25 ERROR cinder.volume.drivers.lightos requests.exceptions.ConnectionError: HTTPSConnectionPool(host='[LB_IP_ADDRESS]', port=443): Max retries exceeded with url: /api/v2/clusterinfo (Caused by NewConnectionError('<urllib3.connection.HTTPSConnection object at 0x7f67697ca290>: Failed to establish a new connection: [Errno 111] ECONNREFUSED'))
2025-01-23 07:37:48.455 25 ERROR cinder.volume.drivers.lightos 
2025-01-23 07:37:48.457 25 ERROR cinder.volume.manager [None req-066b0eec-78ec-4fb5-87d6-6609c5df9b40 - - - - - -] Failed to initialize driver.: cinder.exception.VolumeDriverException: Volume driver reported an error: Could not get a response from any API server
2025-01-23 07:37:48.457 25 ERROR cinder.volume.manager Traceback (most recent call last):
2025-01-23 07:37:48.457 25 ERROR cinder.volume.manager   File "/var/lib/kolla/venv/lib/python3.10/site-packages/cinder/volume/manager.py", line 523, in _init_host
2025-01-23 07:37:48.457 25 ERROR cinder.volume.manager     self.driver.do_setup(ctxt)
2025-01-23 07:37:48.457 25 ERROR cinder.volume.manager   File "/var/lib/kolla/venv/lib/python3.10/site-packages/cinder/volume/drivers/lightos.py", line 922, in do_setup
2025-01-23 07:37:48.457 25 ERROR cinder.volume.manager     self.get_cluster_info()
2025-01-23 07:37:48.457 25 ERROR cinder.volume.manager   File "/var/lib/kolla/venv/lib/python3.10/site-packages/cinder/volume/drivers/lightos.py", line 873, in get_cluster_info
2025-01-23 07:37:48.457 25 ERROR cinder.volume.manager     status_code, cluster_info = self.cluster.send_cmd(
2025-01-23 07:37:48.457 25 ERROR cinder.volume.manager   File "/var/lib/kolla/venv/lib/python3.10/site-packages/cinder/volume/drivers/lightos.py", line 315, in send_cmd
2025-01-23 07:37:48.457 25 ERROR cinder.volume.manager     raise exception.VolumeDriverException(
2025-01-23 07:37:48.457 25 ERROR cinder.volume.manager cinder.exception.VolumeDriverException: Volume driver reported an error: Could not get a response from any API server
2025-01-23 07:37:48.457 25 ERROR cinder.volume.manager 
2025-01-23 07:37:50.461 25 INFO cinder.volume.manager [None req-066b0eec-78ec-4fb5-87d6-6609c5df9b40 - - - - - -] Starting volume driver LightOSVolumeDriver (2.3.12)
2025-01-23 07:37:50.461 25 INFO cinder.volume.drivers.lightos [None req-066b0eec-78ec-4fb5-87d6-6609c5df9b40 - - - - - -] Invoking get_cluster_info using GET url: /api/v2/clusterinfo             request.body: {} ssl_verify: False
2025-01-23 07:37:50.465 25 ERROR cinder.volume.drivers.lightos [None req-066b0eec-78ec-4fb5-87d6-6609c5df9b40 - - - - - -] REST server not responding at 'https://[LB_IP_ADDRESS]:443/api/v2/clusterinfo': requests.exceptions.ConnectionError: HTTPSConnectionPool(host='[LB_IP_ADDRESS]', port=443): Max retries exceeded with url: /api/v2/clusterinfo (Caused by NewConnectionError('<urllib3.connection.HTTPSConnection object at 0x7f6769564850>: Failed to establish a new connection: [Errno 111] ECONNREFUSED'))
2025-01-23 07:37:50.465 25 ERROR cinder.volume.drivers.lightos Traceback (most recent call last):
2025-01-23 07:37:50.465 25 ERROR cinder.volume.drivers.lightos   File "/var/lib/kolla/venv/lib/python3.10/site-packages/urllib3/connection.py", line 174, in _new_conn
2025-01-23 07:37:50.465 25 ERROR cinder.volume.drivers.lightos     conn = connection.create_connection(
2025-01-23 07:37:50.465 25 ERROR cinder.volume.drivers.lightos   File "/var/lib/kolla/venv/lib/python3.10/site-packages/urllib3/util/connection.py", line 95, in create_connection
2025-01-23 07:37:50.465 25 ERROR cinder.volume.drivers.lightos     raise err
2025-01-23 07:37:50.465 25 ERROR cinder.volume.drivers.lightos   File "/var/lib/kolla/venv/lib/python3.10/site-packages/urllib3/util/connection.py", line 85, in create_connection
2025-01-23 07:37:50.465 25 ERROR cinder.volume.drivers.lightos     sock.connect(sa)
2025-01-23 07:37:50.465 25 ERROR cinder.volume.drivers.lightos   File "/var/lib/kolla/venv/lib/python3.10/site-packages/eventlet/greenio/base.py", line 265, in connect
2025-01-23 07:37:50.465 25 ERROR cinder.volume.drivers.lightos     socket_checkerr(fd)
2025-01-23 07:37:50.465 25 ERROR cinder.volume.drivers.lightos   File "/var/lib/kolla/venv/lib/python3.10/site-packages/eventlet/greenio/base.py", line 50, in socket_checkerr
2025-01-23 07:37:50.465 25 ERROR cinder.volume.drivers.lightos     raise OSError(err, errno.errorcode[err])
2025-01-23 07:37:50.465 25 ERROR cinder.volume.drivers.lightos ConnectionRefusedError: [Errno 111] ECONNREFUSED
2025-01-23 07:37:50.465 25 ERROR cinder.volume.drivers.lightos 
2025-01-23 07:37:50.465 25 ERROR cinder.volume.drivers.lightos During handling of the above exception, another exception occurred:
2025-01-23 07:37:50.465 25 ERROR cinder.volume.drivers.lightos 
2025-01-23 07:37:50.465 25 ERROR cinder.volume.drivers.lightos Traceback (most recent call last):
2025-01-23 07:37:50.465 25 ERROR cinder.volume.drivers.lightos   File "/var/lib/kolla/venv/lib/python3.10/site-packages/urllib3/connectionpool.py", line 715, in urlopen
2025-01-23 07:37:50.465 25 ERROR cinder.volume.drivers.lightos     httplib_response = self._make_request(
2025-01-23 07:37:50.465 25 ERROR cinder.volume.drivers.lightos   File "/var/lib/kolla/venv/lib/python3.10/site-packages/urllib3/connectionpool.py", line 404, in _make_request
2025-01-23 07:37:50.465 25 ERROR cinder.volume.drivers.lightos     self._validate_conn(conn)
2025-01-23 07:37:50.465 25 ERROR cinder.volume.drivers.lightos   File "/var/lib/kolla/venv/lib/python3.10/site-packages/urllib3/connectionpool.py", line 1060, in _validate_conn
2025-01-23 07:37:50.465 25 ERROR cinder.volume.drivers.lightos     conn.connect()
2025-01-23 07:37:50.465 25 ERROR cinder.volume.drivers.lightos   File "/var/lib/kolla/venv/lib/python3.10/site-packages/urllib3/connection.py", line 363, in connect
2025-01-23 07:37:50.465 25 ERROR cinder.volume.drivers.lightos     self.sock = conn = self._new_conn()
2025-01-23 07:37:50.465 25 ERROR cinder.volume.drivers.lightos   File "/var/lib/kolla/venv/lib/python3.10/site-packages/urllib3/connection.py", line 186, in _new_conn
2025-01-23 07:37:50.465 25 ERROR cinder.volume.drivers.lightos     raise NewConnectionError(
2025-01-23 07:37:50.465 25 ERROR cinder.volume.drivers.lightos urllib3.exceptions.NewConnectionError: <urllib3.connection.HTTPSConnection object at 0x7f6769564850>: Failed to establish a new connection: [Errno 111] ECONNREFUSED
2025-01-23 07:37:50.465 25 ERROR cinder.volume.drivers.lightos 
2025-01-23 07:37:50.465 25 ERROR cinder.volume.drivers.lightos During handling of the above exception, another exception occurred:
2025-01-23 07:37:50.465 25 ERROR cinder.volume.drivers.lightos 
2025-01-23 07:37:50.465 25 ERROR cinder.volume.drivers.lightos Traceback (most recent call last):
2025-01-23 07:37:50.465 25 ERROR cinder.volume.drivers.lightos   File "/var/lib/kolla/venv/lib/python3.10/site-packages/requests/adapters.py", line 667, in send
2025-01-23 07:37:50.465 25 ERROR cinder.volume.drivers.lightos     resp = conn.urlopen(
2025-01-23 07:37:50.465 25 ERROR cinder.volume.drivers.lightos   File "/var/lib/kolla/venv/lib/python3.10/site-packages/urllib3/connectionpool.py", line 801, in urlopen
2025-01-23 07:37:50.465 25 ERROR cinder.volume.drivers.lightos     retries = retries.increment(
2025-01-23 07:37:50.465 25 ERROR cinder.volume.drivers.lightos   File "/var/lib/kolla/venv/lib/python3.10/site-packages/urllib3/util/retry.py", line 594, in increment
2025-01-23 07:37:50.465 25 ERROR cinder.volume.drivers.lightos     raise MaxRetryError(_pool, url, error or ResponseError(cause))
2025-01-23 07:37:50.465 25 ERROR cinder.volume.drivers.lightos urllib3.exceptions.MaxRetryError: HTTPSConnectionPool(host='[LB_IP_ADDRESS]', port=443): Max retries exceeded with url: /api/v2/clusterinfo (Caused by NewConnectionError('<urllib3.connection.HTTPSConnection object at 0x7f6769564850>: Failed to establish a new connection: [Errno 111] ECONNREFUSED'))
2025-01-23 07:37:50.465 25 ERROR cinder.volume.drivers.lightos 
2025-01-23 07:37:50.465 25 ERROR cinder.volume.drivers.lightos During handling of the above exception, another exception occurred:
2025-01-23 07:37:50.465 25 ERROR cinder.volume.drivers.lightos 
2025-01-23 07:37:50.465 25 ERROR cinder.volume.drivers.lightos Traceback (most recent call last):
2025-01-23 07:37:50.465 25 ERROR cinder.volume.drivers.lightos   File "/var/lib/kolla/venv/lib/python3.10/site-packages/cinder/volume/drivers/lightos.py", line 356, in __send_cmd
2025-01-23 07:37:50.465 25 ERROR cinder.volume.drivers.lightos     response = session.send(
2025-01-23 07:37:50.465 25 ERROR cinder.volume.drivers.lightos   File "/var/lib/kolla/venv/lib/python3.10/site-packages/requests/sessions.py", line 703, in send
2025-01-23 07:37:50.465 25 ERROR cinder.volume.drivers.lightos     r = adapter.send(request, **kwargs)
2025-01-23 07:37:50.465 25 ERROR cinder.volume.drivers.lightos   File "/var/lib/kolla/venv/lib/python3.10/site-packages/requests/adapters.py", line 700, in send
2025-01-23 07:37:50.465 25 ERROR cinder.volume.drivers.lightos     raise ConnectionError(e, request=request)
2025-01-23 07:37:50.465 25 ERROR cinder.volume.drivers.lightos requests.exceptions.ConnectionError: HTTPSConnectionPool(host='[LB_IP_ADDRESS]', port=443): Max retries exceeded with url: /api/v2/clusterinfo (Caused by NewConnectionError('<urllib3.connection.HTTPSConnection object at 0x7f6769564850>: Failed to establish a new connection: [Errno 111] ECONNREFUSED'))
2025-01-23 07:37:50.465 25 ERROR cinder.volume.drivers.lightos 
2025-01-23 07:37:50.467 25 INFO cinder.volume.drivers.lightos [None req-066b0eec-78ec-4fb5-87d6-6609c5df9b40 - - - - - -] Invoking get_cluster_info using GET url: /api/v2/clusterinfo             request.body: {} ssl_verify: False
2025-01-23 07:37:51.521 25 ERROR cinder.volume.drivers.lightos [None req-066b0eec-78ec-4fb5-87d6-6609c5df9b40 - - - - - -] REST server not responding at 'https://[LB_IP_ADDRESS]:443/api/v2/clusterinfo': requests.exceptions.ConnectionError: HTTPSConnectionPool(host='[LB_IP_ADDRESS]', port=443): Max retries exceeded with url: /api/v2/clusterinfo (Caused by NewConnectionError('<urllib3.connection.HTTPSConnection object at 0x7f6769565330>: Failed to establish a new connection: [Errno 113] EHOSTUNREACH'))
2025-01-23 07:37:51.521 25 ERROR cinder.volume.drivers.lightos Traceback (most recent call last):
2025-01-23 07:37:51.521 25 ERROR cinder.volume.drivers.lightos   File "/var/lib/kolla/venv/lib/python3.10/site-packages/urllib3/connection.py", line 174, in _new_conn
2025-01-23 07:37:51.521 25 ERROR cinder.volume.drivers.lightos     conn = connection.create_connection(
2025-01-23 07:37:51.521 25 ERROR cinder.volume.drivers.lightos   File "/var/lib/kolla/venv/lib/python3.10/site-packages/urllib3/util/connection.py", line 95, in create_connection
2025-01-23 07:37:51.521 25 ERROR cinder.volume.drivers.lightos     raise err
2025-01-23 07:37:51.521 25 ERROR cinder.volume.drivers.lightos   File "/var/lib/kolla/venv/lib/python3.10/site-packages/urllib3/util/connection.py", line 85, in create_connection
2025-01-23 07:37:51.521 25 ERROR cinder.volume.drivers.lightos     sock.connect(sa)
2025-01-23 07:37:51.521 25 ERROR cinder.volume.drivers.lightos   File "/var/lib/kolla/venv/lib/python3.10/site-packages/eventlet/greenio/base.py", line 265, in connect
2025-01-23 07:37:51.521 25 ERROR cinder.volume.drivers.lightos     socket_checkerr(fd)
2025-01-23 07:37:51.521 25 ERROR cinder.volume.drivers.lightos   File "/var/lib/kolla/venv/lib/python3.10/site-packages/eventlet/greenio/base.py", line 50, in socket_checkerr
2025-01-23 07:37:51.521 25 ERROR cinder.volume.drivers.lightos     raise OSError(err, errno.errorcode[err])
2025-01-23 07:37:51.521 25 ERROR cinder.volume.drivers.lightos OSError: [Errno 113] EHOSTUNREACH
2025-01-23 07:37:51.521 25 ERROR cinder.volume.drivers.lightos 
2025-01-23 07:37:51.521 25 ERROR cinder.volume.drivers.lightos During handling of the above exception, another exception occurred:
2025-01-23 07:37:51.521 25 ERROR cinder.volume.drivers.lightos 
2025-01-23 07:37:51.521 25 ERROR cinder.volume.drivers.lightos Traceback (most recent call last):
2025-01-23 07:37:51.521 25 ERROR cinder.volume.drivers.lightos   File "/var/lib/kolla/venv/lib/python3.10/site-packages/urllib3/connectionpool.py", line 715, in urlopen
2025-01-23 07:37:51.521 25 ERROR cinder.volume.drivers.lightos     httplib_response = self._make_request(
2025-01-23 07:37:51.521 25 ERROR cinder.volume.drivers.lightos   File "/var/lib/kolla/venv/lib/python3.10/site-packages/urllib3/connectionpool.py", line 404, in _make_request
2025-01-23 07:37:51.521 25 ERROR cinder.volume.drivers.lightos     self._validate_conn(conn)
2025-01-23 07:37:51.521 25 ERROR cinder.volume.drivers.lightos   File "/var/lib/kolla/venv/lib/python3.10/site-packages/urllib3/connectionpool.py", line 1060, in _validate_conn
2025-01-23 07:37:51.521 25 ERROR cinder.volume.drivers.lightos     conn.connect()
2025-01-23 07:37:51.521 25 ERROR cinder.volume.drivers.lightos   File "/var/lib/kolla/venv/lib/python3.10/site-packages/urllib3/connection.py", line 363, in connect
2025-01-23 07:37:51.521 25 ERROR cinder.volume.drivers.lightos     self.sock = conn = self._new_conn()
2025-01-23 07:37:51.521 25 ERROR cinder.volume.drivers.lightos   File "/var/lib/kolla/venv/lib/python3.10/site-packages/urllib3/connection.py", line 186, in _new_conn
2025-01-23 07:37:51.521 25 ERROR cinder.volume.drivers.lightos     raise NewConnectionError(
2025-01-23 07:37:51.521 25 ERROR cinder.volume.drivers.lightos urllib3.exceptions.NewConnectionError: <urllib3.connection.HTTPSConnection object at 0x7f6769565330>: Failed to establish a new connection: [Errno 113] EHOSTUNREACH
2025-01-23 07:37:51.521 25 ERROR cinder.volume.drivers.lightos 
2025-01-23 07:37:51.521 25 ERROR cinder.volume.drivers.lightos During handling of the above exception, another exception occurred:
2025-01-23 07:37:51.521 25 ERROR cinder.volume.drivers.lightos 
2025-01-23 07:37:51.521 25 ERROR cinder.volume.drivers.lightos Traceback (most recent call last):
2025-01-23 07:37:51.521 25 ERROR cinder.volume.drivers.lightos   File "/var/lib/kolla/venv/lib/python3.10/site-packages/requests/adapters.py", line 667, in send
2025-01-23 07:37:51.521 25 ERROR cinder.volume.drivers.lightos     resp = conn.urlopen(
2025-01-23 07:37:51.521 25 ERROR cinder.volume.drivers.lightos   File "/var/lib/kolla/venv/lib/python3.10/site-packages/urllib3/connectionpool.py", line 801, in urlopen
2025-01-23 07:37:51.521 25 ERROR cinder.volume.drivers.lightos     retries = retries.increment(
2025-01-23 07:37:51.521 25 ERROR cinder.volume.drivers.lightos   File "/var/lib/kolla/venv/lib/python3.10/site-packages/urllib3/util/retry.py", line 594, in increment
2025-01-23 07:37:51.521 25 ERROR cinder.volume.drivers.lightos     raise MaxRetryError(_pool, url, error or ResponseError(cause))
2025-01-23 07:37:51.521 25 ERROR cinder.volume.drivers.lightos urllib3.exceptions.MaxRetryError: HTTPSConnectionPool(host='[LB_IP_ADDRESS]', port=443): Max retries exceeded with url: /api/v2/clusterinfo (Caused by NewConnectionError('<urllib3.connection.HTTPSConnection object at 0x7f6769565330>: Failed to establish a new connection: [Errno 113] EHOSTUNREACH'))
2025-01-23 07:37:51.521 25 ERROR cinder.volume.drivers.lightos 
2025-01-23 07:37:51.521 25 ERROR cinder.volume.drivers.lightos During handling of the above exception, another exception occurred:
2025-01-23 07:37:51.521 25 ERROR cinder.volume.drivers.lightos 
2025-01-23 07:37:51.521 25 ERROR cinder.volume.drivers.lightos Traceback (most recent call last):
2025-01-23 07:37:51.521 25 ERROR cinder.volume.drivers.lightos   File "/var/lib/kolla/venv/lib/python3.10/site-packages/cinder/volume/drivers/lightos.py", line 356, in __send_cmd
2025-01-23 07:37:51.521 25 ERROR cinder.volume.drivers.lightos     response = session.send(
2025-01-23 07:37:51.521 25 ERROR cinder.volume.drivers.lightos   File "/var/lib/kolla/venv/lib/python3.10/site-packages/requests/sessions.py", line 703, in send
2025-01-23 07:37:51.521 25 ERROR cinder.volume.drivers.lightos     r = adapter.send(request, **kwargs)
2025-01-23 07:37:51.521 25 ERROR cinder.volume.drivers.lightos   File "/var/lib/kolla/venv/lib/python3.10/site-packages/requests/adapters.py", line 700, in send
2025-01-23 07:37:51.521 25 ERROR cinder.volume.drivers.lightos     raise ConnectionError(e, request=request)
2025-01-23 07:37:51.521 25 ERROR cinder.volume.drivers.lightos requests.exceptions.ConnectionError: HTTPSConnectionPool(host='[LB_IP_ADDRESS]', port=443): Max retries exceeded with url: /api/v2/clusterinfo (Caused by NewConnectionError('<urllib3.connection.HTTPSConnection object at 0x7f6769565330>: Failed to establish a new connection: [Errno 113] EHOSTUNREACH'))
2025-01-23 07:37:51.521 25 ERROR cinder.volume.drivers.lightos 
2025-01-23 07:37:51.525 25 INFO cinder.volume.drivers.lightos [None req-066b0eec-78ec-4fb5-87d6-6609c5df9b40 - - - - - -] Invoking get_cluster_info using GET url: /api/v2/clusterinfo             request.body: {} ssl_verify: False
2025-01-23 07:37:51.528 25 ERROR cinder.volume.drivers.lightos [None req-066b0eec-78ec-4fb5-87d6-6609c5df9b40 - - - - - -] REST server not responding at 'https://[LB_IP_ADDRESS]:443/api/v2/clusterinfo': requests.exceptions.ConnectionError: HTTPSConnectionPool(host='[LB_IP_ADDRESS]', port=443): Max retries exceeded with url: /api/v2/clusterinfo (Caused by NewConnectionError('<urllib3.connection.HTTPSConnection object at 0x7f67697ca140>: Failed to establish a new connection: [Errno 111] ECONNREFUSED'))
2025-01-23 07:37:51.528 25 ERROR cinder.volume.drivers.lightos Traceback (most recent call last):
2025-01-23 07:37:51.528 25 ERROR cinder.volume.drivers.lightos   File "/var/lib/kolla/venv/lib/python3.10/site-packages/urllib3/connection.py", line 174, in _new_conn
2025-01-23 07:37:51.528 25 ERROR cinder.volume.drivers.lightos     conn = connection.create_connection(
2025-01-23 07:37:51.528 25 ERROR cinder.volume.drivers.lightos   File "/var/lib/kolla/venv/lib/python3.10/site-packages/urllib3/util/connection.py", line 95, in create_connection
2025-01-23 07:37:51.528 25 ERROR cinder.volume.drivers.lightos     raise err
2025-01-23 07:37:51.528 25 ERROR cinder.volume.drivers.lightos   File "/var/lib/kolla/venv/lib/python3.10/site-packages/urllib3/util/connection.py", line 85, in create_connection
2025-01-23 07:37:51.528 25 ERROR cinder.volume.drivers.lightos     sock.connect(sa)
2025-01-23 07:37:51.528 25 ERROR cinder.volume.drivers.lightos   File "/var/lib/kolla/venv/lib/python3.10/site-packages/eventlet/greenio/base.py", line 265, in connect
2025-01-23 07:37:51.528 25 ERROR cinder.volume.drivers.lightos     socket_checkerr(fd)
2025-01-23 07:37:51.528 25 ERROR cinder.volume.drivers.lightos   File "/var/lib/kolla/venv/lib/python3.10/site-packages/eventlet/greenio/base.py", line 50, in socket_checkerr
2025-01-23 07:37:51.528 25 ERROR cinder.volume.drivers.lightos     raise OSError(err, errno.errorcode[err])
2025-01-23 07:37:51.528 25 ERROR cinder.volume.drivers.lightos ConnectionRefusedError: [Errno 111] ECONNREFUSED
2025-01-23 07:37:51.528 25 ERROR cinder.volume.drivers.lightos 
2025-01-23 07:37:51.528 25 ERROR cinder.volume.drivers.lightos During handling of the above exception, another exception occurred:
2025-01-23 07:37:51.528 25 ERROR cinder.volume.drivers.lightos 
2025-01-23 07:37:51.528 25 ERROR cinder.volume.drivers.lightos Traceback (most recent call last):
2025-01-23 07:37:51.528 25 ERROR cinder.volume.drivers.lightos   File "/var/lib/kolla/venv/lib/python3.10/site-packages/urllib3/connectionpool.py", line 715, in urlopen
2025-01-23 07:37:51.528 25 ERROR cinder.volume.drivers.lightos     httplib_response = self._make_request(
2025-01-23 07:37:51.528 25 ERROR cinder.volume.drivers.lightos   File "/var/lib/kolla/venv/lib/python3.10/site-packages/urllib3/connectionpool.py", line 404, in _make_request
2025-01-23 07:37:51.528 25 ERROR cinder.volume.drivers.lightos     self._validate_conn(conn)
2025-01-23 07:37:51.528 25 ERROR cinder.volume.drivers.lightos   File "/var/lib/kolla/venv/lib/python3.10/site-packages/urllib3/connectionpool.py", line 1060, in _validate_conn
2025-01-23 07:37:51.528 25 ERROR cinder.volume.drivers.lightos     conn.connect()
2025-01-23 07:37:51.528 25 ERROR cinder.volume.drivers.lightos   File "/var/lib/kolla/venv/lib/python3.10/site-packages/urllib3/connection.py", line 363, in connect
2025-01-23 07:37:51.528 25 ERROR cinder.volume.drivers.lightos     self.sock = conn = self._new_conn()
2025-01-23 07:37:51.528 25 ERROR cinder.volume.drivers.lightos   File "/var/lib/kolla/venv/lib/python3.10/site-packages/urllib3/connection.py", line 186, in _new_conn
2025-01-23 07:37:51.528 25 ERROR cinder.volume.drivers.lightos     raise NewConnectionError(
2025-01-23 07:37:51.528 25 ERROR cinder.volume.drivers.lightos urllib3.exceptions.NewConnectionError: <urllib3.connection.HTTPSConnection object at 0x7f67697ca140>: Failed to establish a new connection: [Errno 111] ECONNREFUSED
2025-01-23 07:37:51.528 25 ERROR cinder.volume.drivers.lightos 
2025-01-23 07:37:51.528 25 ERROR cinder.volume.drivers.lightos During handling of the above exception, another exception occurred:
2025-01-23 07:37:51.528 25 ERROR cinder.volume.drivers.lightos 
2025-01-23 07:37:51.528 25 ERROR cinder.volume.drivers.lightos Traceback (most recent call last):
2025-01-23 07:37:51.528 25 ERROR cinder.volume.drivers.lightos   File "/var/lib/kolla/venv/lib/python3.10/site-packages/requests/adapters.py", line 667, in send
2025-01-23 07:37:51.528 25 ERROR cinder.volume.drivers.lightos     resp = conn.urlopen(
2025-01-23 07:37:51.528 25 ERROR cinder.volume.drivers.lightos   File "/var/lib/kolla/venv/lib/python3.10/site-packages/urllib3/connectionpool.py", line 801, in urlopen
2025-01-23 07:37:51.528 25 ERROR cinder.volume.drivers.lightos     retries = retries.increment(
2025-01-23 07:37:51.528 25 ERROR cinder.volume.drivers.lightos   File "/var/lib/kolla/venv/lib/python3.10/site-packages/urllib3/util/retry.py", line 594, in increment
2025-01-23 07:37:51.528 25 ERROR cinder.volume.drivers.lightos     raise MaxRetryError(_pool, url, error or ResponseError(cause))
2025-01-23 07:37:51.528 25 ERROR cinder.volume.drivers.lightos urllib3.exceptions.MaxRetryError: HTTPSConnectionPool(host='[LB_IP_ADDRESS]', port=443): Max retries exceeded with url: /api/v2/clusterinfo (Caused by NewConnectionError('<urllib3.connection.HTTPSConnection object at 0x7f67697ca140>: Failed to establish a new connection: [Errno 111] ECONNREFUSED'))
2025-01-23 07:37:51.528 25 ERROR cinder.volume.drivers.lightos 
2025-01-23 07:37:51.528 25 ERROR cinder.volume.drivers.lightos During handling of the above exception, another exception occurred:
2025-01-23 07:37:51.528 25 ERROR cinder.volume.drivers.lightos 
2025-01-23 07:37:51.528 25 ERROR cinder.volume.drivers.lightos Traceback (most recent call last):
2025-01-23 07:37:51.528 25 ERROR cinder.volume.drivers.lightos   File "/var/lib/kolla/venv/lib/python3.10/site-packages/cinder/volume/drivers/lightos.py", line 356, in __send_cmd
2025-01-23 07:37:51.528 25 ERROR cinder.volume.drivers.lightos     response = session.send(
2025-01-23 07:37:51.528 25 ERROR cinder.volume.drivers.lightos   File "/var/lib/kolla/venv/lib/python3.10/site-packages/requests/sessions.py", line 703, in send
2025-01-23 07:37:51.528 25 ERROR cinder.volume.drivers.lightos     r = adapter.send(request, **kwargs)
2025-01-23 07:37:51.528 25 ERROR cinder.volume.drivers.lightos   File "/var/lib/kolla/venv/lib/python3.10/site-packages/requests/adapters.py", line 700, in send
2025-01-23 07:37:51.528 25 ERROR cinder.volume.drivers.lightos     raise ConnectionError(e, request=request)
2025-01-23 07:37:51.528 25 ERROR cinder.volume.drivers.lightos requests.exceptions.ConnectionError: HTTPSConnectionPool(host='[LB_IP_ADDRESS]', port=443): Max retries exceeded with url: /api/v2/clusterinfo (Caused by NewConnectionError('<urllib3.connection.HTTPSConnection object at 0x7f67697ca140>: Failed to establish a new connection: [Errno 111] ECONNREFUSED'))
2025-01-23 07:37:51.528 25 ERROR cinder.volume.drivers.lightos 
2025-01-23 07:37:51.530 25 ERROR cinder.volume.manager [None req-066b0eec-78ec-4fb5-87d6-6609c5df9b40 - - - - - -] Failed to initialize driver.: cinder.exception.VolumeDriverException: Volume driver reported an error: Could not get a response from any API server
2025-01-23 07:37:51.530 25 ERROR cinder.volume.manager Traceback (most recent call last):
2025-01-23 07:37:51.530 25 ERROR cinder.volume.manager   File "/var/lib/kolla/venv/lib/python3.10/site-packages/cinder/volume/manager.py", line 523, in _init_host
2025-01-23 07:37:51.530 25 ERROR cinder.volume.manager     self.driver.do_setup(ctxt)
2025-01-23 07:37:51.530 25 ERROR cinder.volume.manager   File "/var/lib/kolla/venv/lib/python3.10/site-packages/cinder/volume/drivers/lightos.py", line 922, in do_setup
2025-01-23 07:37:51.530 25 ERROR cinder.volume.manager     self.get_cluster_info()
2025-01-23 07:37:51.530 25 ERROR cinder.volume.manager   File "/var/lib/kolla/venv/lib/python3.10/site-packages/cinder/volume/drivers/lightos.py", line 873, in get_cluster_info
2025-01-23 07:37:51.530 25 ERROR cinder.volume.manager     status_code, cluster_info = self.cluster.send_cmd(
2025-01-23 07:37:51.530 25 ERROR cinder.volume.manager   File "/var/lib/kolla/venv/lib/python3.10/site-packages/cinder/volume/drivers/lightos.py", line 315, in send_cmd
2025-01-23 07:37:51.530 25 ERROR cinder.volume.manager     raise exception.VolumeDriverException(
2025-01-23 07:37:51.530 25 ERROR cinder.volume.manager cinder.exception.VolumeDriverException: Volume driver reported an error: Could not get a response from any API server
2025-01-23 07:37:51.530 25 ERROR cinder.volume.manager 
2025-01-23 07:37:55.534 25 INFO cinder.volume.manager [None req-066b0eec-78ec-4fb5-87d6-6609c5df9b40 - - - - - -] Starting volume driver LightOSVolumeDriver (2.3.12)
2025-01-23 07:37:55.535 25 INFO cinder.volume.drivers.lightos [None req-066b0eec-78ec-4fb5-87d6-6609c5df9b40 - - - - - -] Invoking get_cluster_info using GET url: /api/v2/clusterinfo             request.body: {} ssl_verify: False
2025-01-23 07:37:55.539 25 ERROR cinder.volume.drivers.lightos [None req-066b0eec-78ec-4fb5-87d6-6609c5df9b40 - - - - - -] REST server not responding at 'https://[LB_IP_ADDRESS]:443/api/v2/clusterinfo': requests.exceptions.ConnectionError: HTTPSConnectionPool(host='[LB_IP_ADDRESS]', port=443): Max retries exceeded with url: /api/v2/clusterinfo (Caused by NewConnectionError('<urllib3.connection.HTTPSConnection object at 0x7f67697c8a60>: Failed to establish a new connection: [Errno 111] ECONNREFUSED'))
2025-01-23 07:37:55.539 25 ERROR cinder.volume.drivers.lightos Traceback (most recent call last):
2025-01-23 07:37:55.539 25 ERROR cinder.volume.drivers.lightos   File "/var/lib/kolla/venv/lib/python3.10/site-packages/urllib3/connection.py", line 174, in _new_conn
2025-01-23 07:37:55.539 25 ERROR cinder.volume.drivers.lightos     conn = connection.create_connection(
2025-01-23 07:37:55.539 25 ERROR cinder.volume.drivers.lightos   File "/var/lib/kolla/venv/lib/python3.10/site-packages/urllib3/util/connection.py", line 95, in create_connection
2025-01-23 07:37:55.539 25 ERROR cinder.volume.drivers.lightos     raise err
2025-01-23 07:37:55.539 25 ERROR cinder.volume.drivers.lightos   File "/var/lib/kolla/venv/lib/python3.10/site-packages/urllib3/util/connection.py", line 85, in create_connection
2025-01-23 07:37:55.539 25 ERROR cinder.volume.drivers.lightos     sock.connect(sa)
2025-01-23 07:37:55.539 25 ERROR cinder.volume.drivers.lightos   File "/var/lib/kolla/venv/lib/python3.10/site-packages/eventlet/greenio/base.py", line 265, in connect
2025-01-23 07:37:55.539 25 ERROR cinder.volume.drivers.lightos     socket_checkerr(fd)
2025-01-23 07:37:55.539 25 ERROR cinder.volume.drivers.lightos   File "/var/lib/kolla/venv/lib/python3.10/site-packages/eventlet/greenio/base.py", line 50, in socket_checkerr
2025-01-23 07:37:55.539 25 ERROR cinder.volume.drivers.lightos     raise OSError(err, errno.errorcode[err])
2025-01-23 07:37:55.539 25 ERROR cinder.volume.drivers.lightos ConnectionRefusedError: [Errno 111] ECONNREFUSED
2025-01-23 07:37:55.539 25 ERROR cinder.volume.drivers.lightos 
2025-01-23 07:37:55.539 25 ERROR cinder.volume.drivers.lightos During handling of the above exception, another exception occurred:
2025-01-23 07:37:55.539 25 ERROR cinder.volume.drivers.lightos 
2025-01-23 07:37:55.539 25 ERROR cinder.volume.drivers.lightos Traceback (most recent call last):
2025-01-23 07:37:55.539 25 ERROR cinder.volume.drivers.lightos   File "/var/lib/kolla/venv/lib/python3.10/site-packages/urllib3/connectionpool.py", line 715, in urlopen
2025-01-23 07:37:55.539 25 ERROR cinder.volume.drivers.lightos     httplib_response = self._make_request(
2025-01-23 07:37:55.539 25 ERROR cinder.volume.drivers.lightos   File "/var/lib/kolla/venv/lib/python3.10/site-packages/urllib3/connectionpool.py", line 404, in _make_request
2025-01-23 07:37:55.539 25 ERROR cinder.volume.drivers.lightos     self._validate_conn(conn)
2025-01-23 07:37:55.539 25 ERROR cinder.volume.drivers.lightos   File "/var/lib/kolla/venv/lib/python3.10/site-packages/urllib3/connectionpool.py", line 1060, in _validate_conn
2025-01-23 07:37:55.539 25 ERROR cinder.volume.drivers.lightos     conn.connect()
2025-01-23 07:37:55.539 25 ERROR cinder.volume.drivers.lightos   File "/var/lib/kolla/venv/lib/python3.10/site-packages/urllib3/connection.py", line 363, in connect
2025-01-23 07:37:55.539 25 ERROR cinder.volume.drivers.lightos     self.sock = conn = self._new_conn()
2025-01-23 07:37:55.539 25 ERROR cinder.volume.drivers.lightos   File "/var/lib/kolla/venv/lib/python3.10/site-packages/urllib3/connection.py", line 186, in _new_conn
2025-01-23 07:37:55.539 25 ERROR cinder.volume.drivers.lightos     raise NewConnectionError(
2025-01-23 07:37:55.539 25 ERROR cinder.volume.drivers.lightos urllib3.exceptions.NewConnectionError: <urllib3.connection.HTTPSConnection object at 0x7f67697c8a60>: Failed to establish a new connection: [Errno 111] ECONNREFUSED
2025-01-23 07:37:55.539 25 ERROR cinder.volume.drivers.lightos 
2025-01-23 07:37:55.539 25 ERROR cinder.volume.drivers.lightos During handling of the above exception, another exception occurred:
2025-01-23 07:37:55.539 25 ERROR cinder.volume.drivers.lightos 
2025-01-23 07:37:55.539 25 ERROR cinder.volume.drivers.lightos Traceback (most recent call last):
2025-01-23 07:37:55.539 25 ERROR cinder.volume.drivers.lightos   File "/var/lib/kolla/venv/lib/python3.10/site-packages/requests/adapters.py", line 667, in send
2025-01-23 07:37:55.539 25 ERROR cinder.volume.drivers.lightos     resp = conn.urlopen(
2025-01-23 07:37:55.539 25 ERROR cinder.volume.drivers.lightos   File "/var/lib/kolla/venv/lib/python3.10/site-packages/urllib3/connectionpool.py", line 801, in urlopen
2025-01-23 07:37:55.539 25 ERROR cinder.volume.drivers.lightos     retries = retries.increment(
2025-01-23 07:37:55.539 25 ERROR cinder.volume.drivers.lightos   File "/var/lib/kolla/venv/lib/python3.10/site-packages/urllib3/util/retry.py", line 594, in increment
2025-01-23 07:37:55.539 25 ERROR cinder.volume.drivers.lightos     raise MaxRetryError(_pool, url, error or ResponseError(cause))
2025-01-23 07:37:55.539 25 ERROR cinder.volume.drivers.lightos urllib3.exceptions.MaxRetryError: HTTPSConnectionPool(host='[LB_IP_ADDRESS]', port=443): Max retries exceeded with url: /api/v2/clusterinfo (Caused by NewConnectionError('<urllib3.connection.HTTPSConnection object at 0x7f67697c8a60>: Failed to establish a new connection: [Errno 111] ECONNREFUSED'))
2025-01-23 07:37:55.539 25 ERROR cinder.volume.drivers.lightos 
2025-01-23 07:37:55.539 25 ERROR cinder.volume.drivers.lightos During handling of the above exception, another exception occurred:
2025-01-23 07:37:55.539 25 ERROR cinder.volume.drivers.lightos 
2025-01-23 07:37:55.539 25 ERROR cinder.volume.drivers.lightos Traceback (most recent call last):
2025-01-23 07:37:55.539 25 ERROR cinder.volume.drivers.lightos   File "/var/lib/kolla/venv/lib/python3.10/site-packages/cinder/volume/drivers/lightos.py", line 356, in __send_cmd
2025-01-23 07:37:55.539 25 ERROR cinder.volume.drivers.lightos     response = session.send(
2025-01-23 07:37:55.539 25 ERROR cinder.volume.drivers.lightos   File "/var/lib/kolla/venv/lib/python3.10/site-packages/requests/sessions.py", line 703, in send
2025-01-23 07:37:55.539 25 ERROR cinder.volume.drivers.lightos     r = adapter.send(request, **kwargs)
2025-01-23 07:37:55.539 25 ERROR cinder.volume.drivers.lightos   File "/var/lib/kolla/venv/lib/python3.10/site-packages/requests/adapters.py", line 700, in send
2025-01-23 07:37:55.539 25 ERROR cinder.volume.drivers.lightos     raise ConnectionError(e, request=request)
2025-01-23 07:37:55.539 25 ERROR cinder.volume.drivers.lightos requests.exceptions.ConnectionError: HTTPSConnectionPool(host='[LB_IP_ADDRESS]', port=443): Max retries exceeded with url: /api/v2/clusterinfo (Caused by NewConnectionError('<urllib3.connection.HTTPSConnection object at 0x7f67697c8a60>: Failed to establish a new connection: [Errno 111] ECONNREFUSED'))
2025-01-23 07:37:55.539 25 ERROR cinder.volume.drivers.lightos 
2025-01-23 07:37:55.541 25 INFO cinder.volume.drivers.lightos [None req-066b0eec-78ec-4fb5-87d6-6609c5df9b40 - - - - - -] Invoking get_cluster_info using GET url: /api/v2/clusterinfo             request.body: {} ssl_verify: False
2025-01-23 07:37:58.593 25 ERROR cinder.volume.drivers.lightos [None req-066b0eec-78ec-4fb5-87d6-6609c5df9b40 - - - - - -] REST server not responding at 'https://[LB_IP_ADDRESS]:443/api/v2/clusterinfo': requests.exceptions.ConnectionError: HTTPSConnectionPool(host='[LB_IP_ADDRESS]', port=443): Max retries exceeded with url: /api/v2/clusterinfo (Caused by NewConnectionError('<urllib3.connection.HTTPSConnection object at 0x7f67697c8e80>: Failed to establish a new connection: [Errno 113] EHOSTUNREACH'))
2025-01-23 07:37:58.593 25 ERROR cinder.volume.drivers.lightos Traceback (most recent call last):
2025-01-23 07:37:58.593 25 ERROR cinder.volume.drivers.lightos   File "/var/lib/kolla/venv/lib/python3.10/site-packages/urllib3/connection.py", line 174, in _new_conn
2025-01-23 07:37:58.593 25 ERROR cinder.volume.drivers.lightos     conn = connection.create_connection(
2025-01-23 07:37:58.593 25 ERROR cinder.volume.drivers.lightos   File "/var/lib/kolla/venv/lib/python3.10/site-packages/urllib3/util/connection.py", line 95, in create_connection
2025-01-23 07:37:58.593 25 ERROR cinder.volume.drivers.lightos     raise err
2025-01-23 07:37:58.593 25 ERROR cinder.volume.drivers.lightos   File "/var/lib/kolla/venv/lib/python3.10/site-packages/urllib3/util/connection.py", line 85, in create_connection
2025-01-23 07:37:58.593 25 ERROR cinder.volume.drivers.lightos     sock.connect(sa)
2025-01-23 07:37:58.593 25 ERROR cinder.volume.drivers.lightos   File "/var/lib/kolla/venv/lib/python3.10/site-packages/eventlet/greenio/base.py", line 265, in connect
2025-01-23 07:37:58.593 25 ERROR cinder.volume.drivers.lightos     socket_checkerr(fd)
2025-01-23 07:37:58.593 25 ERROR cinder.volume.drivers.lightos   File "/var/lib/kolla/venv/lib/python3.10/site-packages/eventlet/greenio/base.py", line 50, in socket_checkerr
2025-01-23 07:37:58.593 25 ERROR cinder.volume.drivers.lightos     raise OSError(err, errno.errorcode[err])
2025-01-23 07:37:58.593 25 ERROR cinder.volume.drivers.lightos OSError: [Errno 113] EHOSTUNREACH
2025-01-23 07:37:58.593 25 ERROR cinder.volume.drivers.lightos 
2025-01-23 07:37:58.593 25 ERROR cinder.volume.drivers.lightos During handling of the above exception, another exception occurred:
2025-01-23 07:37:58.593 25 ERROR cinder.volume.drivers.lightos 
2025-01-23 07:37:58.593 25 ERROR cinder.volume.drivers.lightos Traceback (most recent call last):
2025-01-23 07:37:58.593 25 ERROR cinder.volume.drivers.lightos   File "/var/lib/kolla/venv/lib/python3.10/site-packages/urllib3/connectionpool.py", line 715, in urlopen
2025-01-23 07:37:58.593 25 ERROR cinder.volume.drivers.lightos     httplib_response = self._make_request(
2025-01-23 07:37:58.593 25 ERROR cinder.volume.drivers.lightos   File "/var/lib/kolla/venv/lib/python3.10/site-packages/urllib3/connectionpool.py", line 404, in _make_request
2025-01-23 07:37:58.593 25 ERROR cinder.volume.drivers.lightos     self._validate_conn(conn)
2025-01-23 07:37:58.593 25 ERROR cinder.volume.drivers.lightos   File "/var/lib/kolla/venv/lib/python3.10/site-packages/urllib3/connectionpool.py", line 1060, in _validate_conn
2025-01-23 07:37:58.593 25 ERROR cinder.volume.drivers.lightos     conn.connect()
2025-01-23 07:37:58.593 25 ERROR cinder.volume.drivers.lightos   File "/var/lib/kolla/venv/lib/python3.10/site-packages/urllib3/connection.py", line 363, in connect
2025-01-23 07:37:58.593 25 ERROR cinder.volume.drivers.lightos     self.sock = conn = self._new_conn()
2025-01-23 07:37:58.593 25 ERROR cinder.volume.drivers.lightos   File "/var/lib/kolla/venv/lib/python3.10/site-packages/urllib3/connection.py", line 186, in _new_conn
2025-01-23 07:37:58.593 25 ERROR cinder.volume.drivers.lightos     raise NewConnectionError(
2025-01-23 07:37:58.593 25 ERROR cinder.volume.drivers.lightos urllib3.exceptions.NewConnectionError: <urllib3.connection.HTTPSConnection object at 0x7f67697c8e80>: Failed to establish a new connection: [Errno 113] EHOSTUNREACH
2025-01-23 07:37:58.593 25 ERROR cinder.volume.drivers.lightos 
2025-01-23 07:37:58.593 25 ERROR cinder.volume.drivers.lightos During handling of the above exception, another exception occurred:
2025-01-23 07:37:58.593 25 ERROR cinder.volume.drivers.lightos 
2025-01-23 07:37:58.593 25 ERROR cinder.volume.drivers.lightos Traceback (most recent call last):
2025-01-23 07:37:58.593 25 ERROR cinder.volume.drivers.lightos   File "/var/lib/kolla/venv/lib/python3.10/site-packages/requests/adapters.py", line 667, in send
2025-01-23 07:37:58.593 25 ERROR cinder.volume.drivers.lightos     resp = conn.urlopen(
2025-01-23 07:37:58.593 25 ERROR cinder.volume.drivers.lightos   File "/var/lib/kolla/venv/lib/python3.10/site-packages/urllib3/connectionpool.py", line 801, in urlopen
2025-01-23 07:37:58.593 25 ERROR cinder.volume.drivers.lightos     retries = retries.increment(
2025-01-23 07:37:58.593 25 ERROR cinder.volume.drivers.lightos   File "/var/lib/kolla/venv/lib/python3.10/site-packages/urllib3/util/retry.py", line 594, in increment
2025-01-23 07:37:58.593 25 ERROR cinder.volume.drivers.lightos     raise MaxRetryError(_pool, url, error or ResponseError(cause))
2025-01-23 07:37:58.593 25 ERROR cinder.volume.drivers.lightos urllib3.exceptions.MaxRetryError: HTTPSConnectionPool(host='[LB_IP_ADDRESS]', port=443): Max retries exceeded with url: /api/v2/clusterinfo (Caused by NewConnectionError('<urllib3.connection.HTTPSConnection object at 0x7f67697c8e80>: Failed to establish a new connection: [Errno 113] EHOSTUNREACH'))
2025-01-23 07:37:58.593 25 ERROR cinder.volume.drivers.lightos 
2025-01-23 07:37:58.593 25 ERROR cinder.volume.drivers.lightos During handling of the above exception, another exception occurred:
2025-01-23 07:37:58.593 25 ERROR cinder.volume.drivers.lightos 
2025-01-23 07:37:58.593 25 ERROR cinder.volume.drivers.lightos Traceback (most recent call last):
2025-01-23 07:37:58.593 25 ERROR cinder.volume.drivers.lightos   File "/var/lib/kolla/venv/lib/python3.10/site-packages/cinder/volume/drivers/lightos.py", line 356, in __send_cmd
2025-01-23 07:37:58.593 25 ERROR cinder.volume.drivers.lightos     response = session.send(
2025-01-23 07:37:58.593 25 ERROR cinder.volume.drivers.lightos   File "/var/lib/kolla/venv/lib/python3.10/site-packages/requests/sessions.py", line 703, in send
2025-01-23 07:37:58.593 25 ERROR cinder.volume.drivers.lightos     r = adapter.send(request, **kwargs)
2025-01-23 07:37:58.593 25 ERROR cinder.volume.drivers.lightos   File "/var/lib/kolla/venv/lib/python3.10/site-packages/requests/adapters.py", line 700, in send
2025-01-23 07:37:58.593 25 ERROR cinder.volume.drivers.lightos     raise ConnectionError(e, request=request)
2025-01-23 07:37:58.593 25 ERROR cinder.volume.drivers.lightos requests.exceptions.ConnectionError: HTTPSConnectionPool(host='[LB_IP_ADDRESS]', port=443): Max retries exceeded with url: /api/v2/clusterinfo (Caused by NewConnectionError('<urllib3.connection.HTTPSConnection object at 0x7f67697c8e80>: Failed to establish a new connection: [Errno 113] EHOSTUNREACH'))
2025-01-23 07:37:58.593 25 ERROR cinder.volume.drivers.lightos 
2025-01-23 07:37:58.596 25 INFO cinder.volume.drivers.lightos [None req-066b0eec-78ec-4fb5-87d6-6609c5df9b40 - - - - - -] Invoking get_cluster_info using GET url: /api/v2/clusterinfo             request.body: {} ssl_verify: False
2025-01-23 07:37:58.599 25 ERROR cinder.volume.drivers.lightos [None req-066b0eec-78ec-4fb5-87d6-6609c5df9b40 - - - - - -] REST server not responding at 'https://[LB_IP_ADDRESS]:443/api/v2/clusterinfo': requests.exceptions.ConnectionError: HTTPSConnectionPool(host='[LB_IP_ADDRESS]', port=443): Max retries exceeded with url: /api/v2/clusterinfo (Caused by NewConnectionError('<urllib3.connection.HTTPSConnection object at 0x7f67695641c0>: Failed to establish a new connection: [Errno 111] ECONNREFUSED'))
2025-01-23 07:37:58.599 25 ERROR cinder.volume.drivers.lightos Traceback (most recent call last):
2025-01-23 07:37:58.599 25 ERROR cinder.volume.drivers.lightos   File "/var/lib/kolla/venv/lib/python3.10/site-packages/urllib3/connection.py", line 174, in _new_conn
2025-01-23 07:37:58.599 25 ERROR cinder.volume.drivers.lightos     conn = connection.create_connection(
2025-01-23 07:37:58.599 25 ERROR cinder.volume.drivers.lightos   File "/var/lib/kolla/venv/lib/python3.10/site-packages/urllib3/util/connection.py", line 95, in create_connection
2025-01-23 07:37:58.599 25 ERROR cinder.volume.drivers.lightos     raise err
2025-01-23 07:37:58.599 25 ERROR cinder.volume.drivers.lightos   File "/var/lib/kolla/venv/lib/python3.10/site-packages/urllib3/util/connection.py", line 85, in create_connection
2025-01-23 07:37:58.599 25 ERROR cinder.volume.drivers.lightos     sock.connect(sa)
2025-01-23 07:37:58.599 25 ERROR cinder.volume.drivers.lightos   File "/var/lib/kolla/venv/lib/python3.10/site-packages/eventlet/greenio/base.py", line 265, in connect
2025-01-23 07:37:58.599 25 ERROR cinder.volume.drivers.lightos     socket_checkerr(fd)
2025-01-23 07:37:58.599 25 ERROR cinder.volume.drivers.lightos   File "/var/lib/kolla/venv/lib/python3.10/site-packages/eventlet/greenio/base.py", line 50, in socket_checkerr
2025-01-23 07:37:58.599 25 ERROR cinder.volume.drivers.lightos     raise OSError(err, errno.errorcode[err])
2025-01-23 07:37:58.599 25 ERROR cinder.volume.drivers.lightos ConnectionRefusedError: [Errno 111] ECONNREFUSED
2025-01-23 07:37:58.599 25 ERROR cinder.volume.drivers.lightos 
2025-01-23 07:37:58.599 25 ERROR cinder.volume.drivers.lightos During handling of the above exception, another exception occurred:
2025-01-23 07:37:58.599 25 ERROR cinder.volume.drivers.lightos 
2025-01-23 07:37:58.599 25 ERROR cinder.volume.drivers.lightos Traceback (most recent call last):
2025-01-23 07:37:58.599 25 ERROR cinder.volume.drivers.lightos   File "/var/lib/kolla/venv/lib/python3.10/site-packages/urllib3/connectionpool.py", line 715, in urlopen
2025-01-23 07:37:58.599 25 ERROR cinder.volume.drivers.lightos     httplib_response = self._make_request(
2025-01-23 07:37:58.599 25 ERROR cinder.volume.drivers.lightos   File "/var/lib/kolla/venv/lib/python3.10/site-packages/urllib3/connectionpool.py", line 404, in _make_request
2025-01-23 07:37:58.599 25 ERROR cinder.volume.drivers.lightos     self._validate_conn(conn)
2025-01-23 07:37:58.599 25 ERROR cinder.volume.drivers.lightos   File "/var/lib/kolla/venv/lib/python3.10/site-packages/urllib3/connectionpool.py", line 1060, in _validate_conn
2025-01-23 07:37:58.599 25 ERROR cinder.volume.drivers.lightos     conn.connect()
2025-01-23 07:37:58.599 25 ERROR cinder.volume.drivers.lightos   File "/var/lib/kolla/venv/lib/python3.10/site-packages/urllib3/connection.py", line 363, in connect
2025-01-23 07:37:58.599 25 ERROR cinder.volume.drivers.lightos     self.sock = conn = self._new_conn()
2025-01-23 07:37:58.599 25 ERROR cinder.volume.drivers.lightos   File "/var/lib/kolla/venv/lib/python3.10/site-packages/urllib3/connection.py", line 186, in _new_conn
2025-01-23 07:37:58.599 25 ERROR cinder.volume.drivers.lightos     raise NewConnectionError(
2025-01-23 07:37:58.599 25 ERROR cinder.volume.drivers.lightos urllib3.exceptions.NewConnectionError: <urllib3.connection.HTTPSConnection object at 0x7f67695641c0>: Failed to establish a new connection: [Errno 111] ECONNREFUSED
2025-01-23 07:37:58.599 25 ERROR cinder.volume.drivers.lightos 
2025-01-23 07:37:58.599 25 ERROR cinder.volume.drivers.lightos During handling of the above exception, another exception occurred:
2025-01-23 07:37:58.599 25 ERROR cinder.volume.drivers.lightos 
2025-01-23 07:37:58.599 25 ERROR cinder.volume.drivers.lightos Traceback (most recent call last):
2025-01-23 07:37:58.599 25 ERROR cinder.volume.drivers.lightos   File "/var/lib/kolla/venv/lib/python3.10/site-packages/requests/adapters.py", line 667, in send
2025-01-23 07:37:58.599 25 ERROR cinder.volume.drivers.lightos     resp = conn.urlopen(
2025-01-23 07:37:58.599 25 ERROR cinder.volume.drivers.lightos   File "/var/lib/kolla/venv/lib/python3.10/site-packages/urllib3/connectionpool.py", line 801, in urlopen
2025-01-23 07:37:58.599 25 ERROR cinder.volume.drivers.lightos     retries = retries.increment(
2025-01-23 07:37:58.599 25 ERROR cinder.volume.drivers.lightos   File "/var/lib/kolla/venv/lib/python3.10/site-packages/urllib3/util/retry.py", line 594, in increment
2025-01-23 07:37:58.599 25 ERROR cinder.volume.drivers.lightos     raise MaxRetryError(_pool, url, error or ResponseError(cause))
2025-01-23 07:37:58.599 25 ERROR cinder.volume.drivers.lightos urllib3.exceptions.MaxRetryError: HTTPSConnectionPool(host='[LB_IP_ADDRESS]', port=443): Max retries exceeded with url: /api/v2/clusterinfo (Caused by NewConnectionError('<urllib3.connection.HTTPSConnection object at 0x7f67695641c0>: Failed to establish a new connection: [Errno 111] ECONNREFUSED'))
2025-01-23 07:37:58.599 25 ERROR cinder.volume.drivers.lightos 
2025-01-23 07:37:58.599 25 ERROR cinder.volume.drivers.lightos During handling of the above exception, another exception occurred:
2025-01-23 07:37:58.599 25 ERROR cinder.volume.drivers.lightos 
2025-01-23 07:37:58.599 25 ERROR cinder.volume.drivers.lightos Traceback (most recent call last):
2025-01-23 07:37:58.599 25 ERROR cinder.volume.drivers.lightos   File "/var/lib/kolla/venv/lib/python3.10/site-packages/cinder/volume/drivers/lightos.py", line 356, in __send_cmd
2025-01-23 07:37:58.599 25 ERROR cinder.volume.drivers.lightos     response = session.send(
2025-01-23 07:37:58.599 25 ERROR cinder.volume.drivers.lightos   File "/var/lib/kolla/venv/lib/python3.10/site-packages/requests/sessions.py", line 703, in send
2025-01-23 07:37:58.599 25 ERROR cinder.volume.drivers.lightos     r = adapter.send(request, **kwargs)
2025-01-23 07:37:58.599 25 ERROR cinder.volume.drivers.lightos   File "/var/lib/kolla/venv/lib/python3.10/site-packages/requests/adapters.py", line 700, in send
2025-01-23 07:37:58.599 25 ERROR cinder.volume.drivers.lightos     raise ConnectionError(e, request=request)
2025-01-23 07:37:58.599 25 ERROR cinder.volume.drivers.lightos requests.exceptions.ConnectionError: HTTPSConnectionPool(host='[LB_IP_ADDRESS]', port=443): Max retries exceeded with url: /api/v2/clusterinfo (Caused by NewConnectionError('<urllib3.connection.HTTPSConnection object at 0x7f67695641c0>: Failed to establish a new connection: [Errno 111] ECONNREFUSED'))
2025-01-23 07:37:58.599 25 ERROR cinder.volume.drivers.lightos 
2025-01-23 07:37:58.602 25 ERROR cinder.volume.manager [None req-066b0eec-78ec-4fb5-87d6-6609c5df9b40 - - - - - -] Failed to initialize driver.: cinder.exception.VolumeDriverException: Volume driver reported an error: Could not get a response from any API server
2025-01-23 07:37:58.602 25 ERROR cinder.volume.manager Traceback (most recent call last):
2025-01-23 07:37:58.602 25 ERROR cinder.volume.manager   File "/var/lib/kolla/venv/lib/python3.10/site-packages/cinder/volume/manager.py", line 523, in _init_host
2025-01-23 07:37:58.602 25 ERROR cinder.volume.manager     self.driver.do_setup(ctxt)
2025-01-23 07:37:58.602 25 ERROR cinder.volume.manager   File "/var/lib/kolla/venv/lib/python3.10/site-packages/cinder/volume/drivers/lightos.py", line 922, in do_setup
2025-01-23 07:37:58.602 25 ERROR cinder.volume.manager     self.get_cluster_info()
2025-01-23 07:37:58.602 25 ERROR cinder.volume.manager   File "/var/lib/kolla/venv/lib/python3.10/site-packages/cinder/volume/drivers/lightos.py", line 873, in get_cluster_info
2025-01-23 07:37:58.602 25 ERROR cinder.volume.manager     status_code, cluster_info = self.cluster.send_cmd(
2025-01-23 07:37:58.602 25 ERROR cinder.volume.manager   File "/var/lib/kolla/venv/lib/python3.10/site-packages/cinder/volume/drivers/lightos.py", line 315, in send_cmd
2025-01-23 07:37:58.602 25 ERROR cinder.volume.manager     raise exception.VolumeDriverException(
2025-01-23 07:37:58.602 25 ERROR cinder.volume.manager cinder.exception.VolumeDriverException: Volume driver reported an error: Could not get a response from any API server
2025-01-23 07:37:58.602 25 ERROR cinder.volume.manager 
2025-01-23 07:37:58.621 25 WARNING oslo_config.cfg [None req-066b0eec-78ec-4fb5-87d6-6609c5df9b40 - - - - - -] Deprecated: Option "heartbeat_in_pthread" from group "oslo_messaging_rabbit" is deprecated for removal (The option is related to Eventlet which will be removed. In addition this has never worked as expected with services using eventlet for core service framework.).  Its value may be silently ignored in the future.
2025-01-23 07:37:58.668 25 INFO cinder.service [None req-066b0eec-78ec-4fb5-87d6-6609c5df9b40 - - - - - -] Starting cinder-volume cluster lightos_cinder_cluster@LIGHTOSyilgqu (version 25.1.0)
2025-01-23 07:37:58.690 25 INFO cinder.volume.manager [None req-066b0eec-78ec-4fb5-87d6-6609c5df9b40 - - - - - -] Initializing RPC dependent components of volume driver LightOSVolumeDriver (2.3.12)
2025-01-23 07:37:58.691 25 ERROR cinder.volume.volume_utils [None req-066b0eec-78ec-4fb5-87d6-6609c5df9b40 - - - - - -] Volume driver LightOSVolumeDriver not initialized
2025-01-23 07:37:58.691 25 ERROR cinder.volume.manager [None req-066b0eec-78ec-4fb5-87d6-6609c5df9b40 - - - - - -] Cannot complete RPC initialization because driver isn't initialized properly.: cinder.exception.DriverNotInitialized: Volume driver not ready.
2025-01-23 07:38:08.693 25 ERROR cinder.service [-] Manager for service cinder-volume rack13-server67@LIGHTOSyilgqu is reporting problems, not sending heartbeat. Service will appear "down".
2025-01-23 07:38:18.695 25 ERROR cinder.service [-] Manager for service cinder-volume rack13-server67@LIGHTOSyilgqu is reporting problems, not sending heartbeat. Service will appear "down".
2025-01-23 07:38:28.697 25 ERROR cinder.service [-] Manager for service cinder-volume rack13-server67@LIGHTOSyilgqu is reporting problems, not sending heartbeat. Service will appear "down".
2025-01-23 07:38:38.698 25 ERROR cinder.service [-] Manager for service cinder-volume rack13-server67@LIGHTOSyilgqu is reporting problems, not sending heartbeat. Service will appear "down".
2025-01-23 07:38:48.699 25 ERROR cinder.service [-] Manager for service cinder-volume rack13-server67@LIGHTOSyilgqu is reporting problems, not sending heartbeat. Service will appear "down".
2025-01-23 07:38:58.701 25 ERROR cinder.service [-] Manager for service cinder-volume rack13-server67@LIGHTOSyilgqu is reporting problems, not sending heartbeat. Service will appear "down".
2025-01-23 07:39:08.703 25 ERROR cinder.service [-] Manager for service cinder-volume rack13-server67@LIGHTOSyilgqu is reporting problems, not sending heartbeat. Service will appear "down".
2025-01-23 07:39:18.704 25 ERROR cinder.service [-] Manager for service cinder-volume rack13-server67@LIGHTOSyilgqu is reporting problems, not sending heartbeat. Service will appear "down".
2025-01-23 07:39:28.705 25 ERROR cinder.service [-] Manager for service cinder-volume rack13-server67@LIGHTOSyilgqu is reporting problems, not sending heartbeat. Service will appear "down".
2025-01-23 07:39:32.695 25 WARNING cinder.volume.manager [None req-f7abf0d1-d8e1-4132-a650-ed8949c4d121 - - - - - -] Update driver status failed: (config name LIGHTOSyilgqu) is uninitialized.
2025-01-23 07:39:38.706 25 ERROR cinder.service [-] Manager for service cinder-volume rack13-server67@LIGHTOSyilgqu is reporting problems, not sending heartbeat. Service will appear "down".
2025-01-23 07:39:48.708 25 ERROR cinder.service [-] Manager for service cinder-volume rack13-server67@LIGHTOSyilgqu is reporting problems, not sending heartbeat. Service will appear "down".
2025-01-23 07:39:58.709 25 ERROR cinder.service [-] Manager for service cinder-volume rack13-server67@LIGHTOSyilgqu is reporting problems, not sending heartbeat. Service will appear "down".
2025-01-23 07:40:08.710 25 ERROR cinder.service [-] Manager for service cinder-volume rack13-server67@LIGHTOSyilgqu is reporting problems, not sending heartbeat. Service will appear "down".
2025-01-23 07:40:18.712 25 ERROR cinder.service [-] Manager for service cinder-volume rack13-server67@LIGHTOSyilgqu is reporting problems, not sending heartbeat. Service will appear "down".
2025-01-23 07:40:28.713 25 ERROR cinder.service [-] Manager for service cinder-volume rack13-server67@LIGHTOSyilgqu is reporting problems, not sending heartbeat. Service will appear "down".
2025-01-23 07:40:32.698 25 WARNING cinder.volume.manager [None req-f7abf0d1-d8e1-4132-a650-ed8949c4d121 - - - - - -] Update driver status failed: (config name LIGHTOSyilgqu) is uninitialized.
2025-01-23 07:40:38.714 25 ERROR cinder.service [-] Manager for service cinder-volume rack13-server67@LIGHTOSyilgqu is reporting problems, not sending heartbeat. Service will appear "down".
2025-01-23 07:40:48.716 25 ERROR cinder.service [-] Manager for service cinder-volume rack13-server67@LIGHTOSyilgqu is reporting problems, not sending heartbeat. Service will appear "down".
2025-01-23 07:40:58.717 25 ERROR cinder.service [-] Manager for service cinder-volume rack13-server67@LIGHTOSyilgqu is reporting problems, not sending heartbeat. Service will appear "down".
2025-01-23 07:41:08.719 25 ERROR cinder.service [-] Manager for service cinder-volume rack13-server67@LIGHTOSyilgqu is reporting problems, not sending heartbeat. Service will appear "down".
2025-01-23 07:41:18.720 25 ERROR cinder.service [-] Manager for service cinder-volume rack13-server67@LIGHTOSyilgqu is reporting problems, not sending heartbeat. Service will appear "down".
2025-01-23 07:41:28.721 25 ERROR cinder.service [-] Manager for service cinder-volume rack13-server67@LIGHTOSyilgqu is reporting problems, not sending heartbeat. Service will appear "down".
2025-01-23 07:41:32.700 25 WARNING cinder.volume.manager [None req-f7abf0d1-d8e1-4132-a650-ed8949c4d121 - - - - - -] Update driver status failed: (config name LIGHTOSyilgqu) is uninitialized.
2025-01-23 07:41:38.723 25 ERROR cinder.service [-] Manager for service cinder-volume rack13-server67@LIGHTOSyilgqu is reporting problems, not sending heartbeat. Service will appear "down".
