Build Started 21_01_2025_10_51_07
2025-01-21 10:51:16.960 7 INFO oslo_service.service [None req-56b6df71-dd5e-4cd7-a304-650689278f4c - - - - - -] Caught SIGTERM, stopping children
2025-01-21 10:51:16.964 7 INFO oslo_service.service [None req-56b6df71-dd5e-4cd7-a304-650689278f4c - - - - - -] Waiting on 1 children to exit
2025-01-21 10:51:18.752 25 ERROR cinder.service [-] Manager for service cinder-volume rack13-server67@LIGHTOSyilgqu is reporting problems, not sending heartbeat. Service will appear "down".
2025-01-21 10:51:23.480 25 WARNING amqp [None req-56b6df71-dd5e-4cd7-a304-650689278f4c - - - - - -] Received method (60, 30) during closing channel 1. This method will be ignored
2025-01-21 10:51:23.487 25 WARNING amqp [None req-56b6df71-dd5e-4cd7-a304-650689278f4c - - - - - -] Received method (60, 30) during closing channel 1. This method will be ignored
2025-01-21 10:51:23.494 25 WARNING amqp [None req-56b6df71-dd5e-4cd7-a304-650689278f4c - - - - - -] Received method (60, 30) during closing channel 1. This method will be ignored
2025-01-21 10:51:23.500 7 INFO oslo_service.service [None req-56b6df71-dd5e-4cd7-a304-650689278f4c - - - - - -] Child 25 exited with status 0
2025-01-21 10:51:38.813 7 INFO cinder.rpc [None req-45086705-6caf-40c7-8a57-7b81be5bccfd - - - - - -] Automatically selected cinder-scheduler objects version 1.39 as minimum service version.
2025-01-21 10:51:38.817 7 INFO cinder.rpc [None req-45086705-6caf-40c7-8a57-7b81be5bccfd - - - - - -] Automatically selected cinder-scheduler RPC version 3.12 as minimum service version.
2025-01-21 10:51:38.848 7 INFO cinder.volume.manager [None req-45086705-6caf-40c7-8a57-7b81be5bccfd - - - - - -] Determined volume DB was empty at startup.
2025-01-21 10:51:38.864 7 INFO cinder.volume.manager [None req-45086705-6caf-40c7-8a57-7b81be5bccfd - - - - - -] Image-volume cache disabled for host rack13-server67@LIGHTOSyilgqu.
2025-01-21 10:51:38.878 7 INFO oslo_service.service [None req-45086705-6caf-40c7-8a57-7b81be5bccfd - - - - - -] Starting 1 workers
2025-01-21 10:51:38.889 25 INFO cinder.service [-] Starting cinder-volume node (version 25.1.0)
2025-01-21 10:51:38.893 7 WARNING oslo_config.cfg [None req-45086705-6caf-40c7-8a57-7b81be5bccfd - - - - - -] Deprecated: Option "heartbeat_in_pthread" from group "oslo_messaging_rabbit" is deprecated for removal (The option is related to Eventlet which will be removed. In addition this has never worked as expected with services using eventlet for core service framework.).  Its value may be silently ignored in the future.
2025-01-21 10:51:38.906 25 INFO cinder.volume.manager [None req-f5027d6f-3333-4cae-a38a-8718ac0670b1 - - - - - -] Starting volume driver LightOSVolumeDriver (2.3.12)
2025-01-21 10:51:38.906 25 INFO cinder.volume.drivers.lightos [None req-f5027d6f-3333-4cae-a38a-8718ac0670b1 - - - - - -] Invoking get_cluster_info using GET url: /api/v2/clusterinfo             request.body: {} ssl_verify: False
2025-01-21 10:51:38.909 25 ERROR cinder.volume.drivers.lightos [None req-f5027d6f-3333-4cae-a38a-8718ac0670b1 - - - - - -] REST server not responding at 'https://[LB_IP_ADDRESS]:443/api/v2/clusterinfo': requests.exceptions.ConnectionError: HTTPSConnectionPool(host='[LB_IP_ADDRESS]', port=443): Max retries exceeded with url: /api/v2/clusterinfo (Caused by NewConnectionError('<urllib3.connection.HTTPSConnection object at 0x7fb8b0e81c60>: Failed to establish a new connection: [Errno 111] ECONNREFUSED'))
2025-01-21 10:51:38.909 25 ERROR cinder.volume.drivers.lightos Traceback (most recent call last):
2025-01-21 10:51:38.909 25 ERROR cinder.volume.drivers.lightos   File "/var/lib/kolla/venv/lib/python3.10/site-packages/urllib3/connection.py", line 174, in _new_conn
2025-01-21 10:51:38.909 25 ERROR cinder.volume.drivers.lightos     conn = connection.create_connection(
2025-01-21 10:51:38.909 25 ERROR cinder.volume.drivers.lightos   File "/var/lib/kolla/venv/lib/python3.10/site-packages/urllib3/util/connection.py", line 95, in create_connection
2025-01-21 10:51:38.909 25 ERROR cinder.volume.drivers.lightos     raise err
2025-01-21 10:51:38.909 25 ERROR cinder.volume.drivers.lightos   File "/var/lib/kolla/venv/lib/python3.10/site-packages/urllib3/util/connection.py", line 85, in create_connection
2025-01-21 10:51:38.909 25 ERROR cinder.volume.drivers.lightos     sock.connect(sa)
2025-01-21 10:51:38.909 25 ERROR cinder.volume.drivers.lightos   File "/var/lib/kolla/venv/lib/python3.10/site-packages/eventlet/greenio/base.py", line 265, in connect
2025-01-21 10:51:38.909 25 ERROR cinder.volume.drivers.lightos     socket_checkerr(fd)
2025-01-21 10:51:38.909 25 ERROR cinder.volume.drivers.lightos   File "/var/lib/kolla/venv/lib/python3.10/site-packages/eventlet/greenio/base.py", line 50, in socket_checkerr
2025-01-21 10:51:38.909 25 ERROR cinder.volume.drivers.lightos     raise OSError(err, errno.errorcode[err])
2025-01-21 10:51:38.909 25 ERROR cinder.volume.drivers.lightos ConnectionRefusedError: [Errno 111] ECONNREFUSED
2025-01-21 10:51:38.909 25 ERROR cinder.volume.drivers.lightos 
2025-01-21 10:51:38.909 25 ERROR cinder.volume.drivers.lightos During handling of the above exception, another exception occurred:
2025-01-21 10:51:38.909 25 ERROR cinder.volume.drivers.lightos 
2025-01-21 10:51:38.909 25 ERROR cinder.volume.drivers.lightos Traceback (most recent call last):
2025-01-21 10:51:38.909 25 ERROR cinder.volume.drivers.lightos   File "/var/lib/kolla/venv/lib/python3.10/site-packages/urllib3/connectionpool.py", line 715, in urlopen
2025-01-21 10:51:38.909 25 ERROR cinder.volume.drivers.lightos     httplib_response = self._make_request(
2025-01-21 10:51:38.909 25 ERROR cinder.volume.drivers.lightos   File "/var/lib/kolla/venv/lib/python3.10/site-packages/urllib3/connectionpool.py", line 404, in _make_request
2025-01-21 10:51:38.909 25 ERROR cinder.volume.drivers.lightos     self._validate_conn(conn)
2025-01-21 10:51:38.909 25 ERROR cinder.volume.drivers.lightos   File "/var/lib/kolla/venv/lib/python3.10/site-packages/urllib3/connectionpool.py", line 1060, in _validate_conn
2025-01-21 10:51:38.909 25 ERROR cinder.volume.drivers.lightos     conn.connect()
2025-01-21 10:51:38.909 25 ERROR cinder.volume.drivers.lightos   File "/var/lib/kolla/venv/lib/python3.10/site-packages/urllib3/connection.py", line 363, in connect
2025-01-21 10:51:38.909 25 ERROR cinder.volume.drivers.lightos     self.sock = conn = self._new_conn()
2025-01-21 10:51:38.909 25 ERROR cinder.volume.drivers.lightos   File "/var/lib/kolla/venv/lib/python3.10/site-packages/urllib3/connection.py", line 186, in _new_conn
2025-01-21 10:51:38.909 25 ERROR cinder.volume.drivers.lightos     raise NewConnectionError(
2025-01-21 10:51:38.909 25 ERROR cinder.volume.drivers.lightos urllib3.exceptions.NewConnectionError: <urllib3.connection.HTTPSConnection object at 0x7fb8b0e81c60>: Failed to establish a new connection: [Errno 111] ECONNREFUSED
2025-01-21 10:51:38.909 25 ERROR cinder.volume.drivers.lightos 
2025-01-21 10:51:38.909 25 ERROR cinder.volume.drivers.lightos During handling of the above exception, another exception occurred:
2025-01-21 10:51:38.909 25 ERROR cinder.volume.drivers.lightos 
2025-01-21 10:51:38.909 25 ERROR cinder.volume.drivers.lightos Traceback (most recent call last):
2025-01-21 10:51:38.909 25 ERROR cinder.volume.drivers.lightos   File "/var/lib/kolla/venv/lib/python3.10/site-packages/requests/adapters.py", line 667, in send
2025-01-21 10:51:38.909 25 ERROR cinder.volume.drivers.lightos     resp = conn.urlopen(
2025-01-21 10:51:38.909 25 ERROR cinder.volume.drivers.lightos   File "/var/lib/kolla/venv/lib/python3.10/site-packages/urllib3/connectionpool.py", line 801, in urlopen
2025-01-21 10:51:38.909 25 ERROR cinder.volume.drivers.lightos     retries = retries.increment(
2025-01-21 10:51:38.909 25 ERROR cinder.volume.drivers.lightos   File "/var/lib/kolla/venv/lib/python3.10/site-packages/urllib3/util/retry.py", line 594, in increment
2025-01-21 10:51:38.909 25 ERROR cinder.volume.drivers.lightos     raise MaxRetryError(_pool, url, error or ResponseError(cause))
2025-01-21 10:51:38.909 25 ERROR cinder.volume.drivers.lightos urllib3.exceptions.MaxRetryError: HTTPSConnectionPool(host='[LB_IP_ADDRESS]', port=443): Max retries exceeded with url: /api/v2/clusterinfo (Caused by NewConnectionError('<urllib3.connection.HTTPSConnection object at 0x7fb8b0e81c60>: Failed to establish a new connection: [Errno 111] ECONNREFUSED'))
2025-01-21 10:51:38.909 25 ERROR cinder.volume.drivers.lightos 
2025-01-21 10:51:38.909 25 ERROR cinder.volume.drivers.lightos During handling of the above exception, another exception occurred:
2025-01-21 10:51:38.909 25 ERROR cinder.volume.drivers.lightos 
2025-01-21 10:51:38.909 25 ERROR cinder.volume.drivers.lightos Traceback (most recent call last):
2025-01-21 10:51:38.909 25 ERROR cinder.volume.drivers.lightos   File "/var/lib/kolla/venv/lib/python3.10/site-packages/cinder/volume/drivers/lightos.py", line 356, in __send_cmd
2025-01-21 10:51:38.909 25 ERROR cinder.volume.drivers.lightos     response = session.send(
2025-01-21 10:51:38.909 25 ERROR cinder.volume.drivers.lightos   File "/var/lib/kolla/venv/lib/python3.10/site-packages/requests/sessions.py", line 703, in send
2025-01-21 10:51:38.909 25 ERROR cinder.volume.drivers.lightos     r = adapter.send(request, **kwargs)
2025-01-21 10:51:38.909 25 ERROR cinder.volume.drivers.lightos   File "/var/lib/kolla/venv/lib/python3.10/site-packages/requests/adapters.py", line 700, in send
2025-01-21 10:51:38.909 25 ERROR cinder.volume.drivers.lightos     raise ConnectionError(e, request=request)
2025-01-21 10:51:38.909 25 ERROR cinder.volume.drivers.lightos requests.exceptions.ConnectionError: HTTPSConnectionPool(host='[LB_IP_ADDRESS]', port=443): Max retries exceeded with url: /api/v2/clusterinfo (Caused by NewConnectionError('<urllib3.connection.HTTPSConnection object at 0x7fb8b0e81c60>: Failed to establish a new connection: [Errno 111] ECONNREFUSED'))
2025-01-21 10:51:38.909 25 ERROR cinder.volume.drivers.lightos 
2025-01-21 10:51:38.912 25 INFO cinder.volume.drivers.lightos [None req-f5027d6f-3333-4cae-a38a-8718ac0670b1 - - - - - -] Invoking get_cluster_info using GET url: /api/v2/clusterinfo             request.body: {} ssl_verify: False
2025-01-21 10:51:38.913 25 ERROR cinder.volume.drivers.lightos [None req-f5027d6f-3333-4cae-a38a-8718ac0670b1 - - - - - -] REST server not responding at 'https://[LB_IP_ADDRESS]:443/api/v2/clusterinfo': requests.exceptions.ConnectionError: HTTPSConnectionPool(host='[LB_IP_ADDRESS]', port=443): Max retries exceeded with url: /api/v2/clusterinfo (Caused by NewConnectionError('<urllib3.connection.HTTPSConnection object at 0x7fb8b0e80fa0>: Failed to establish a new connection: [Errno 111] ECONNREFUSED'))
2025-01-21 10:51:38.913 25 ERROR cinder.volume.drivers.lightos Traceback (most recent call last):
2025-01-21 10:51:38.913 25 ERROR cinder.volume.drivers.lightos   File "/var/lib/kolla/venv/lib/python3.10/site-packages/urllib3/connection.py", line 174, in _new_conn
2025-01-21 10:51:38.913 25 ERROR cinder.volume.drivers.lightos     conn = connection.create_connection(
2025-01-21 10:51:38.913 25 ERROR cinder.volume.drivers.lightos   File "/var/lib/kolla/venv/lib/python3.10/site-packages/urllib3/util/connection.py", line 95, in create_connection
2025-01-21 10:51:38.913 25 ERROR cinder.volume.drivers.lightos     raise err
2025-01-21 10:51:38.913 25 ERROR cinder.volume.drivers.lightos   File "/var/lib/kolla/venv/lib/python3.10/site-packages/urllib3/util/connection.py", line 85, in create_connection
2025-01-21 10:51:38.913 25 ERROR cinder.volume.drivers.lightos     sock.connect(sa)
2025-01-21 10:51:38.913 25 ERROR cinder.volume.drivers.lightos   File "/var/lib/kolla/venv/lib/python3.10/site-packages/eventlet/greenio/base.py", line 265, in connect
2025-01-21 10:51:38.913 25 ERROR cinder.volume.drivers.lightos     socket_checkerr(fd)
2025-01-21 10:51:38.913 25 ERROR cinder.volume.drivers.lightos   File "/var/lib/kolla/venv/lib/python3.10/site-packages/eventlet/greenio/base.py", line 50, in socket_checkerr
2025-01-21 10:51:38.913 25 ERROR cinder.volume.drivers.lightos     raise OSError(err, errno.errorcode[err])
2025-01-21 10:51:38.913 25 ERROR cinder.volume.drivers.lightos ConnectionRefusedError: [Errno 111] ECONNREFUSED
2025-01-21 10:51:38.913 25 ERROR cinder.volume.drivers.lightos 
2025-01-21 10:51:38.913 25 ERROR cinder.volume.drivers.lightos During handling of the above exception, another exception occurred:
2025-01-21 10:51:38.913 25 ERROR cinder.volume.drivers.lightos 
2025-01-21 10:51:38.913 25 ERROR cinder.volume.drivers.lightos Traceback (most recent call last):
2025-01-21 10:51:38.913 25 ERROR cinder.volume.drivers.lightos   File "/var/lib/kolla/venv/lib/python3.10/site-packages/urllib3/connectionpool.py", line 715, in urlopen
2025-01-21 10:51:38.913 25 ERROR cinder.volume.drivers.lightos     httplib_response = self._make_request(
2025-01-21 10:51:38.913 25 ERROR cinder.volume.drivers.lightos   File "/var/lib/kolla/venv/lib/python3.10/site-packages/urllib3/connectionpool.py", line 404, in _make_request
2025-01-21 10:51:38.913 25 ERROR cinder.volume.drivers.lightos     self._validate_conn(conn)
2025-01-21 10:51:38.913 25 ERROR cinder.volume.drivers.lightos   File "/var/lib/kolla/venv/lib/python3.10/site-packages/urllib3/connectionpool.py", line 1060, in _validate_conn
2025-01-21 10:51:38.913 25 ERROR cinder.volume.drivers.lightos     conn.connect()
2025-01-21 10:51:38.913 25 ERROR cinder.volume.drivers.lightos   File "/var/lib/kolla/venv/lib/python3.10/site-packages/urllib3/connection.py", line 363, in connect
2025-01-21 10:51:38.913 25 ERROR cinder.volume.drivers.lightos     self.sock = conn = self._new_conn()
2025-01-21 10:51:38.913 25 ERROR cinder.volume.drivers.lightos   File "/var/lib/kolla/venv/lib/python3.10/site-packages/urllib3/connection.py", line 186, in _new_conn
2025-01-21 10:51:38.913 25 ERROR cinder.volume.drivers.lightos     raise NewConnectionError(
2025-01-21 10:51:38.913 25 ERROR cinder.volume.drivers.lightos urllib3.exceptions.NewConnectionError: <urllib3.connection.HTTPSConnection object at 0x7fb8b0e80fa0>: Failed to establish a new connection: [Errno 111] ECONNREFUSED
2025-01-21 10:51:38.913 25 ERROR cinder.volume.drivers.lightos 
2025-01-21 10:51:38.913 25 ERROR cinder.volume.drivers.lightos During handling of the above exception, another exception occurred:
2025-01-21 10:51:38.913 25 ERROR cinder.volume.drivers.lightos 
2025-01-21 10:51:38.913 25 ERROR cinder.volume.drivers.lightos Traceback (most recent call last):
2025-01-21 10:51:38.913 25 ERROR cinder.volume.drivers.lightos   File "/var/lib/kolla/venv/lib/python3.10/site-packages/requests/adapters.py", line 667, in send
2025-01-21 10:51:38.913 25 ERROR cinder.volume.drivers.lightos     resp = conn.urlopen(
2025-01-21 10:51:38.913 25 ERROR cinder.volume.drivers.lightos   File "/var/lib/kolla/venv/lib/python3.10/site-packages/urllib3/connectionpool.py", line 801, in urlopen
2025-01-21 10:51:38.913 25 ERROR cinder.volume.drivers.lightos     retries = retries.increment(
2025-01-21 10:51:38.913 25 ERROR cinder.volume.drivers.lightos   File "/var/lib/kolla/venv/lib/python3.10/site-packages/urllib3/util/retry.py", line 594, in increment
2025-01-21 10:51:38.913 25 ERROR cinder.volume.drivers.lightos     raise MaxRetryError(_pool, url, error or ResponseError(cause))
2025-01-21 10:51:38.913 25 ERROR cinder.volume.drivers.lightos urllib3.exceptions.MaxRetryError: HTTPSConnectionPool(host='[LB_IP_ADDRESS]', port=443): Max retries exceeded with url: /api/v2/clusterinfo (Caused by NewConnectionError('<urllib3.connection.HTTPSConnection object at 0x7fb8b0e80fa0>: Failed to establish a new connection: [Errno 111] ECONNREFUSED'))
2025-01-21 10:51:38.913 25 ERROR cinder.volume.drivers.lightos 
2025-01-21 10:51:38.913 25 ERROR cinder.volume.drivers.lightos During handling of the above exception, another exception occurred:
2025-01-21 10:51:38.913 25 ERROR cinder.volume.drivers.lightos 
2025-01-21 10:51:38.913 25 ERROR cinder.volume.drivers.lightos Traceback (most recent call last):
2025-01-21 10:51:38.913 25 ERROR cinder.volume.drivers.lightos   File "/var/lib/kolla/venv/lib/python3.10/site-packages/cinder/volume/drivers/lightos.py", line 356, in __send_cmd
2025-01-21 10:51:38.913 25 ERROR cinder.volume.drivers.lightos     response = session.send(
2025-01-21 10:51:38.913 25 ERROR cinder.volume.drivers.lightos   File "/var/lib/kolla/venv/lib/python3.10/site-packages/requests/sessions.py", line 703, in send
2025-01-21 10:51:38.913 25 ERROR cinder.volume.drivers.lightos     r = adapter.send(request, **kwargs)
2025-01-21 10:51:38.913 25 ERROR cinder.volume.drivers.lightos   File "/var/lib/kolla/venv/lib/python3.10/site-packages/requests/adapters.py", line 700, in send
2025-01-21 10:51:38.913 25 ERROR cinder.volume.drivers.lightos     raise ConnectionError(e, request=request)
2025-01-21 10:51:38.913 25 ERROR cinder.volume.drivers.lightos requests.exceptions.ConnectionError: HTTPSConnectionPool(host='[LB_IP_ADDRESS]', port=443): Max retries exceeded with url: /api/v2/clusterinfo (Caused by NewConnectionError('<urllib3.connection.HTTPSConnection object at 0x7fb8b0e80fa0>: Failed to establish a new connection: [Errno 111] ECONNREFUSED'))
2025-01-21 10:51:38.913 25 ERROR cinder.volume.drivers.lightos 
2025-01-21 10:51:38.914 25 INFO cinder.volume.drivers.lightos [None req-f5027d6f-3333-4cae-a38a-8718ac0670b1 - - - - - -] Invoking get_cluster_info using GET url: /api/v2/clusterinfo             request.body: {} ssl_verify: False
2025-01-21 10:51:41.986 25 ERROR cinder.volume.drivers.lightos [None req-f5027d6f-3333-4cae-a38a-8718ac0670b1 - - - - - -] REST server not responding at 'https://[LB_IP_ADDRESS]:443/api/v2/clusterinfo': requests.exceptions.ConnectionError: HTTPSConnectionPool(host='[LB_IP_ADDRESS]', port=443): Max retries exceeded with url: /api/v2/clusterinfo (Caused by NewConnectionError('<urllib3.connection.HTTPSConnection object at 0x7fb8b0e804c0>: Failed to establish a new connection: [Errno 113] EHOSTUNREACH'))
2025-01-21 10:51:41.986 25 ERROR cinder.volume.drivers.lightos Traceback (most recent call last):
2025-01-21 10:51:41.986 25 ERROR cinder.volume.drivers.lightos   File "/var/lib/kolla/venv/lib/python3.10/site-packages/urllib3/connection.py", line 174, in _new_conn
2025-01-21 10:51:41.986 25 ERROR cinder.volume.drivers.lightos     conn = connection.create_connection(
2025-01-21 10:51:41.986 25 ERROR cinder.volume.drivers.lightos   File "/var/lib/kolla/venv/lib/python3.10/site-packages/urllib3/util/connection.py", line 95, in create_connection
2025-01-21 10:51:41.986 25 ERROR cinder.volume.drivers.lightos     raise err
2025-01-21 10:51:41.986 25 ERROR cinder.volume.drivers.lightos   File "/var/lib/kolla/venv/lib/python3.10/site-packages/urllib3/util/connection.py", line 85, in create_connection
2025-01-21 10:51:41.986 25 ERROR cinder.volume.drivers.lightos     sock.connect(sa)
2025-01-21 10:51:41.986 25 ERROR cinder.volume.drivers.lightos   File "/var/lib/kolla/venv/lib/python3.10/site-packages/eventlet/greenio/base.py", line 265, in connect
2025-01-21 10:51:41.986 25 ERROR cinder.volume.drivers.lightos     socket_checkerr(fd)
2025-01-21 10:51:41.986 25 ERROR cinder.volume.drivers.lightos   File "/var/lib/kolla/venv/lib/python3.10/site-packages/eventlet/greenio/base.py", line 50, in socket_checkerr
2025-01-21 10:51:41.986 25 ERROR cinder.volume.drivers.lightos     raise OSError(err, errno.errorcode[err])
2025-01-21 10:51:41.986 25 ERROR cinder.volume.drivers.lightos OSError: [Errno 113] EHOSTUNREACH
2025-01-21 10:51:41.986 25 ERROR cinder.volume.drivers.lightos 
2025-01-21 10:51:41.986 25 ERROR cinder.volume.drivers.lightos During handling of the above exception, another exception occurred:
2025-01-21 10:51:41.986 25 ERROR cinder.volume.drivers.lightos 
2025-01-21 10:51:41.986 25 ERROR cinder.volume.drivers.lightos Traceback (most recent call last):
2025-01-21 10:51:41.986 25 ERROR cinder.volume.drivers.lightos   File "/var/lib/kolla/venv/lib/python3.10/site-packages/urllib3/connectionpool.py", line 715, in urlopen
2025-01-21 10:51:41.986 25 ERROR cinder.volume.drivers.lightos     httplib_response = self._make_request(
2025-01-21 10:51:41.986 25 ERROR cinder.volume.drivers.lightos   File "/var/lib/kolla/venv/lib/python3.10/site-packages/urllib3/connectionpool.py", line 404, in _make_request
2025-01-21 10:51:41.986 25 ERROR cinder.volume.drivers.lightos     self._validate_conn(conn)
2025-01-21 10:51:41.986 25 ERROR cinder.volume.drivers.lightos   File "/var/lib/kolla/venv/lib/python3.10/site-packages/urllib3/connectionpool.py", line 1060, in _validate_conn
2025-01-21 10:51:41.986 25 ERROR cinder.volume.drivers.lightos     conn.connect()
2025-01-21 10:51:41.986 25 ERROR cinder.volume.drivers.lightos   File "/var/lib/kolla/venv/lib/python3.10/site-packages/urllib3/connection.py", line 363, in connect
2025-01-21 10:51:41.986 25 ERROR cinder.volume.drivers.lightos     self.sock = conn = self._new_conn()
2025-01-21 10:51:41.986 25 ERROR cinder.volume.drivers.lightos   File "/var/lib/kolla/venv/lib/python3.10/site-packages/urllib3/connection.py", line 186, in _new_conn
2025-01-21 10:51:41.986 25 ERROR cinder.volume.drivers.lightos     raise NewConnectionError(
2025-01-21 10:51:41.986 25 ERROR cinder.volume.drivers.lightos urllib3.exceptions.NewConnectionError: <urllib3.connection.HTTPSConnection object at 0x7fb8b0e804c0>: Failed to establish a new connection: [Errno 113] EHOSTUNREACH
2025-01-21 10:51:41.986 25 ERROR cinder.volume.drivers.lightos 
2025-01-21 10:51:41.986 25 ERROR cinder.volume.drivers.lightos During handling of the above exception, another exception occurred:
2025-01-21 10:51:41.986 25 ERROR cinder.volume.drivers.lightos 
2025-01-21 10:51:41.986 25 ERROR cinder.volume.drivers.lightos Traceback (most recent call last):
2025-01-21 10:51:41.986 25 ERROR cinder.volume.drivers.lightos   File "/var/lib/kolla/venv/lib/python3.10/site-packages/requests/adapters.py", line 667, in send
2025-01-21 10:51:41.986 25 ERROR cinder.volume.drivers.lightos     resp = conn.urlopen(
2025-01-21 10:51:41.986 25 ERROR cinder.volume.drivers.lightos   File "/var/lib/kolla/venv/lib/python3.10/site-packages/urllib3/connectionpool.py", line 801, in urlopen
2025-01-21 10:51:41.986 25 ERROR cinder.volume.drivers.lightos     retries = retries.increment(
2025-01-21 10:51:41.986 25 ERROR cinder.volume.drivers.lightos   File "/var/lib/kolla/venv/lib/python3.10/site-packages/urllib3/util/retry.py", line 594, in increment
2025-01-21 10:51:41.986 25 ERROR cinder.volume.drivers.lightos     raise MaxRetryError(_pool, url, error or ResponseError(cause))
2025-01-21 10:51:41.986 25 ERROR cinder.volume.drivers.lightos urllib3.exceptions.MaxRetryError: HTTPSConnectionPool(host='[LB_IP_ADDRESS]', port=443): Max retries exceeded with url: /api/v2/clusterinfo (Caused by NewConnectionError('<urllib3.connection.HTTPSConnection object at 0x7fb8b0e804c0>: Failed to establish a new connection: [Errno 113] EHOSTUNREACH'))
2025-01-21 10:51:41.986 25 ERROR cinder.volume.drivers.lightos 
2025-01-21 10:51:41.986 25 ERROR cinder.volume.drivers.lightos During handling of the above exception, another exception occurred:
2025-01-21 10:51:41.986 25 ERROR cinder.volume.drivers.lightos 
2025-01-21 10:51:41.986 25 ERROR cinder.volume.drivers.lightos Traceback (most recent call last):
2025-01-21 10:51:41.986 25 ERROR cinder.volume.drivers.lightos   File "/var/lib/kolla/venv/lib/python3.10/site-packages/cinder/volume/drivers/lightos.py", line 356, in __send_cmd
2025-01-21 10:51:41.986 25 ERROR cinder.volume.drivers.lightos     response = session.send(
2025-01-21 10:51:41.986 25 ERROR cinder.volume.drivers.lightos   File "/var/lib/kolla/venv/lib/python3.10/site-packages/requests/sessions.py", line 703, in send
2025-01-21 10:51:41.986 25 ERROR cinder.volume.drivers.lightos     r = adapter.send(request, **kwargs)
2025-01-21 10:51:41.986 25 ERROR cinder.volume.drivers.lightos   File "/var/lib/kolla/venv/lib/python3.10/site-packages/requests/adapters.py", line 700, in send
2025-01-21 10:51:41.986 25 ERROR cinder.volume.drivers.lightos     raise ConnectionError(e, request=request)
2025-01-21 10:51:41.986 25 ERROR cinder.volume.drivers.lightos requests.exceptions.ConnectionError: HTTPSConnectionPool(host='[LB_IP_ADDRESS]', port=443): Max retries exceeded with url: /api/v2/clusterinfo (Caused by NewConnectionError('<urllib3.connection.HTTPSConnection object at 0x7fb8b0e804c0>: Failed to establish a new connection: [Errno 113] EHOSTUNREACH'))
2025-01-21 10:51:41.986 25 ERROR cinder.volume.drivers.lightos 
2025-01-21 10:51:41.988 25 ERROR cinder.volume.manager [None req-f5027d6f-3333-4cae-a38a-8718ac0670b1 - - - - - -] Failed to initialize driver.: cinder.exception.VolumeDriverException: Volume driver reported an error: Could not get a response from any API server
2025-01-21 10:51:41.988 25 ERROR cinder.volume.manager Traceback (most recent call last):
2025-01-21 10:51:41.988 25 ERROR cinder.volume.manager   File "/var/lib/kolla/venv/lib/python3.10/site-packages/cinder/volume/manager.py", line 523, in _init_host
2025-01-21 10:51:41.988 25 ERROR cinder.volume.manager     self.driver.do_setup(ctxt)
2025-01-21 10:51:41.988 25 ERROR cinder.volume.manager   File "/var/lib/kolla/venv/lib/python3.10/site-packages/cinder/volume/drivers/lightos.py", line 922, in do_setup
2025-01-21 10:51:41.988 25 ERROR cinder.volume.manager     self.get_cluster_info()
2025-01-21 10:51:41.988 25 ERROR cinder.volume.manager   File "/var/lib/kolla/venv/lib/python3.10/site-packages/cinder/volume/drivers/lightos.py", line 873, in get_cluster_info
2025-01-21 10:51:41.988 25 ERROR cinder.volume.manager     status_code, cluster_info = self.cluster.send_cmd(
2025-01-21 10:51:41.988 25 ERROR cinder.volume.manager   File "/var/lib/kolla/venv/lib/python3.10/site-packages/cinder/volume/drivers/lightos.py", line 315, in send_cmd
2025-01-21 10:51:41.988 25 ERROR cinder.volume.manager     raise exception.VolumeDriverException(
2025-01-21 10:51:41.988 25 ERROR cinder.volume.manager cinder.exception.VolumeDriverException: Volume driver reported an error: Could not get a response from any API server
2025-01-21 10:51:41.988 25 ERROR cinder.volume.manager 
2025-01-21 10:51:42.993 25 INFO cinder.volume.manager [None req-f5027d6f-3333-4cae-a38a-8718ac0670b1 - - - - - -] Starting volume driver LightOSVolumeDriver (2.3.12)
2025-01-21 10:51:42.994 25 INFO cinder.volume.drivers.lightos [None req-f5027d6f-3333-4cae-a38a-8718ac0670b1 - - - - - -] Invoking get_cluster_info using GET url: /api/v2/clusterinfo             request.body: {} ssl_verify: False
2025-01-21 10:51:42.998 25 ERROR cinder.volume.drivers.lightos [None req-f5027d6f-3333-4cae-a38a-8718ac0670b1 - - - - - -] REST server not responding at 'https://[LB_IP_ADDRESS]:443/api/v2/clusterinfo': requests.exceptions.ConnectionError: HTTPSConnectionPool(host='[LB_IP_ADDRESS]', port=443): Max retries exceeded with url: /api/v2/clusterinfo (Caused by NewConnectionError('<urllib3.connection.HTTPSConnection object at 0x7fb8b0e80850>: Failed to establish a new connection: [Errno 111] ECONNREFUSED'))
2025-01-21 10:51:42.998 25 ERROR cinder.volume.drivers.lightos Traceback (most recent call last):
2025-01-21 10:51:42.998 25 ERROR cinder.volume.drivers.lightos   File "/var/lib/kolla/venv/lib/python3.10/site-packages/urllib3/connection.py", line 174, in _new_conn
2025-01-21 10:51:42.998 25 ERROR cinder.volume.drivers.lightos     conn = connection.create_connection(
2025-01-21 10:51:42.998 25 ERROR cinder.volume.drivers.lightos   File "/var/lib/kolla/venv/lib/python3.10/site-packages/urllib3/util/connection.py", line 95, in create_connection
2025-01-21 10:51:42.998 25 ERROR cinder.volume.drivers.lightos     raise err
2025-01-21 10:51:42.998 25 ERROR cinder.volume.drivers.lightos   File "/var/lib/kolla/venv/lib/python3.10/site-packages/urllib3/util/connection.py", line 85, in create_connection
2025-01-21 10:51:42.998 25 ERROR cinder.volume.drivers.lightos     sock.connect(sa)
2025-01-21 10:51:42.998 25 ERROR cinder.volume.drivers.lightos   File "/var/lib/kolla/venv/lib/python3.10/site-packages/eventlet/greenio/base.py", line 265, in connect
2025-01-21 10:51:42.998 25 ERROR cinder.volume.drivers.lightos     socket_checkerr(fd)
2025-01-21 10:51:42.998 25 ERROR cinder.volume.drivers.lightos   File "/var/lib/kolla/venv/lib/python3.10/site-packages/eventlet/greenio/base.py", line 50, in socket_checkerr
2025-01-21 10:51:42.998 25 ERROR cinder.volume.drivers.lightos     raise OSError(err, errno.errorcode[err])
2025-01-21 10:51:42.998 25 ERROR cinder.volume.drivers.lightos ConnectionRefusedError: [Errno 111] ECONNREFUSED
2025-01-21 10:51:42.998 25 ERROR cinder.volume.drivers.lightos 
2025-01-21 10:51:42.998 25 ERROR cinder.volume.drivers.lightos During handling of the above exception, another exception occurred:
2025-01-21 10:51:42.998 25 ERROR cinder.volume.drivers.lightos 
2025-01-21 10:51:42.998 25 ERROR cinder.volume.drivers.lightos Traceback (most recent call last):
2025-01-21 10:51:42.998 25 ERROR cinder.volume.drivers.lightos   File "/var/lib/kolla/venv/lib/python3.10/site-packages/urllib3/connectionpool.py", line 715, in urlopen
2025-01-21 10:51:42.998 25 ERROR cinder.volume.drivers.lightos     httplib_response = self._make_request(
2025-01-21 10:51:42.998 25 ERROR cinder.volume.drivers.lightos   File "/var/lib/kolla/venv/lib/python3.10/site-packages/urllib3/connectionpool.py", line 404, in _make_request
2025-01-21 10:51:42.998 25 ERROR cinder.volume.drivers.lightos     self._validate_conn(conn)
2025-01-21 10:51:42.998 25 ERROR cinder.volume.drivers.lightos   File "/var/lib/kolla/venv/lib/python3.10/site-packages/urllib3/connectionpool.py", line 1060, in _validate_conn
2025-01-21 10:51:42.998 25 ERROR cinder.volume.drivers.lightos     conn.connect()
2025-01-21 10:51:42.998 25 ERROR cinder.volume.drivers.lightos   File "/var/lib/kolla/venv/lib/python3.10/site-packages/urllib3/connection.py", line 363, in connect
2025-01-21 10:51:42.998 25 ERROR cinder.volume.drivers.lightos     self.sock = conn = self._new_conn()
2025-01-21 10:51:42.998 25 ERROR cinder.volume.drivers.lightos   File "/var/lib/kolla/venv/lib/python3.10/site-packages/urllib3/connection.py", line 186, in _new_conn
2025-01-21 10:51:42.998 25 ERROR cinder.volume.drivers.lightos     raise NewConnectionError(
2025-01-21 10:51:42.998 25 ERROR cinder.volume.drivers.lightos urllib3.exceptions.NewConnectionError: <urllib3.connection.HTTPSConnection object at 0x7fb8b0e80850>: Failed to establish a new connection: [Errno 111] ECONNREFUSED
2025-01-21 10:51:42.998 25 ERROR cinder.volume.drivers.lightos 
2025-01-21 10:51:42.998 25 ERROR cinder.volume.drivers.lightos During handling of the above exception, another exception occurred:
2025-01-21 10:51:42.998 25 ERROR cinder.volume.drivers.lightos 
2025-01-21 10:51:42.998 25 ERROR cinder.volume.drivers.lightos Traceback (most recent call last):
2025-01-21 10:51:42.998 25 ERROR cinder.volume.drivers.lightos   File "/var/lib/kolla/venv/lib/python3.10/site-packages/requests/adapters.py", line 667, in send
2025-01-21 10:51:42.998 25 ERROR cinder.volume.drivers.lightos     resp = conn.urlopen(
2025-01-21 10:51:42.998 25 ERROR cinder.volume.drivers.lightos   File "/var/lib/kolla/venv/lib/python3.10/site-packages/urllib3/connectionpool.py", line 801, in urlopen
2025-01-21 10:51:42.998 25 ERROR cinder.volume.drivers.lightos     retries = retries.increment(
2025-01-21 10:51:42.998 25 ERROR cinder.volume.drivers.lightos   File "/var/lib/kolla/venv/lib/python3.10/site-packages/urllib3/util/retry.py", line 594, in increment
2025-01-21 10:51:42.998 25 ERROR cinder.volume.drivers.lightos     raise MaxRetryError(_pool, url, error or ResponseError(cause))
2025-01-21 10:51:42.998 25 ERROR cinder.volume.drivers.lightos urllib3.exceptions.MaxRetryError: HTTPSConnectionPool(host='[LB_IP_ADDRESS]', port=443): Max retries exceeded with url: /api/v2/clusterinfo (Caused by NewConnectionError('<urllib3.connection.HTTPSConnection object at 0x7fb8b0e80850>: Failed to establish a new connection: [Errno 111] ECONNREFUSED'))
2025-01-21 10:51:42.998 25 ERROR cinder.volume.drivers.lightos 
2025-01-21 10:51:42.998 25 ERROR cinder.volume.drivers.lightos During handling of the above exception, another exception occurred:
2025-01-21 10:51:42.998 25 ERROR cinder.volume.drivers.lightos 
2025-01-21 10:51:42.998 25 ERROR cinder.volume.drivers.lightos Traceback (most recent call last):
2025-01-21 10:51:42.998 25 ERROR cinder.volume.drivers.lightos   File "/var/lib/kolla/venv/lib/python3.10/site-packages/cinder/volume/drivers/lightos.py", line 356, in __send_cmd
2025-01-21 10:51:42.998 25 ERROR cinder.volume.drivers.lightos     response = session.send(
2025-01-21 10:51:42.998 25 ERROR cinder.volume.drivers.lightos   File "/var/lib/kolla/venv/lib/python3.10/site-packages/requests/sessions.py", line 703, in send
2025-01-21 10:51:42.998 25 ERROR cinder.volume.drivers.lightos     r = adapter.send(request, **kwargs)
2025-01-21 10:51:42.998 25 ERROR cinder.volume.drivers.lightos   File "/var/lib/kolla/venv/lib/python3.10/site-packages/requests/adapters.py", line 700, in send
2025-01-21 10:51:42.998 25 ERROR cinder.volume.drivers.lightos     raise ConnectionError(e, request=request)
2025-01-21 10:51:42.998 25 ERROR cinder.volume.drivers.lightos requests.exceptions.ConnectionError: HTTPSConnectionPool(host='[LB_IP_ADDRESS]', port=443): Max retries exceeded with url: /api/v2/clusterinfo (Caused by NewConnectionError('<urllib3.connection.HTTPSConnection object at 0x7fb8b0e80850>: Failed to establish a new connection: [Errno 111] ECONNREFUSED'))
2025-01-21 10:51:42.998 25 ERROR cinder.volume.drivers.lightos 
2025-01-21 10:51:43.000 25 INFO cinder.volume.drivers.lightos [None req-f5027d6f-3333-4cae-a38a-8718ac0670b1 - - - - - -] Invoking get_cluster_info using GET url: /api/v2/clusterinfo             request.body: {} ssl_verify: False
2025-01-21 10:51:43.003 25 ERROR cinder.volume.drivers.lightos [None req-f5027d6f-3333-4cae-a38a-8718ac0670b1 - - - - - -] REST server not responding at 'https://[LB_IP_ADDRESS]:443/api/v2/clusterinfo': requests.exceptions.ConnectionError: HTTPSConnectionPool(host='[LB_IP_ADDRESS]', port=443): Max retries exceeded with url: /api/v2/clusterinfo (Caused by NewConnectionError('<urllib3.connection.HTTPSConnection object at 0x7fb8b0e812a0>: Failed to establish a new connection: [Errno 111] ECONNREFUSED'))
2025-01-21 10:51:43.003 25 ERROR cinder.volume.drivers.lightos Traceback (most recent call last):
2025-01-21 10:51:43.003 25 ERROR cinder.volume.drivers.lightos   File "/var/lib/kolla/venv/lib/python3.10/site-packages/urllib3/connection.py", line 174, in _new_conn
2025-01-21 10:51:43.003 25 ERROR cinder.volume.drivers.lightos     conn = connection.create_connection(
2025-01-21 10:51:43.003 25 ERROR cinder.volume.drivers.lightos   File "/var/lib/kolla/venv/lib/python3.10/site-packages/urllib3/util/connection.py", line 95, in create_connection
2025-01-21 10:51:43.003 25 ERROR cinder.volume.drivers.lightos     raise err
2025-01-21 10:51:43.003 25 ERROR cinder.volume.drivers.lightos   File "/var/lib/kolla/venv/lib/python3.10/site-packages/urllib3/util/connection.py", line 85, in create_connection
2025-01-21 10:51:43.003 25 ERROR cinder.volume.drivers.lightos     sock.connect(sa)
2025-01-21 10:51:43.003 25 ERROR cinder.volume.drivers.lightos   File "/var/lib/kolla/venv/lib/python3.10/site-packages/eventlet/greenio/base.py", line 265, in connect
2025-01-21 10:51:43.003 25 ERROR cinder.volume.drivers.lightos     socket_checkerr(fd)
2025-01-21 10:51:43.003 25 ERROR cinder.volume.drivers.lightos   File "/var/lib/kolla/venv/lib/python3.10/site-packages/eventlet/greenio/base.py", line 50, in socket_checkerr
2025-01-21 10:51:43.003 25 ERROR cinder.volume.drivers.lightos     raise OSError(err, errno.errorcode[err])
2025-01-21 10:51:43.003 25 ERROR cinder.volume.drivers.lightos ConnectionRefusedError: [Errno 111] ECONNREFUSED
2025-01-21 10:51:43.003 25 ERROR cinder.volume.drivers.lightos 
2025-01-21 10:51:43.003 25 ERROR cinder.volume.drivers.lightos During handling of the above exception, another exception occurred:
2025-01-21 10:51:43.003 25 ERROR cinder.volume.drivers.lightos 
2025-01-21 10:51:43.003 25 ERROR cinder.volume.drivers.lightos Traceback (most recent call last):
2025-01-21 10:51:43.003 25 ERROR cinder.volume.drivers.lightos   File "/var/lib/kolla/venv/lib/python3.10/site-packages/urllib3/connectionpool.py", line 715, in urlopen
2025-01-21 10:51:43.003 25 ERROR cinder.volume.drivers.lightos     httplib_response = self._make_request(
2025-01-21 10:51:43.003 25 ERROR cinder.volume.drivers.lightos   File "/var/lib/kolla/venv/lib/python3.10/site-packages/urllib3/connectionpool.py", line 404, in _make_request
2025-01-21 10:51:43.003 25 ERROR cinder.volume.drivers.lightos     self._validate_conn(conn)
2025-01-21 10:51:43.003 25 ERROR cinder.volume.drivers.lightos   File "/var/lib/kolla/venv/lib/python3.10/site-packages/urllib3/connectionpool.py", line 1060, in _validate_conn
2025-01-21 10:51:43.003 25 ERROR cinder.volume.drivers.lightos     conn.connect()
2025-01-21 10:51:43.003 25 ERROR cinder.volume.drivers.lightos   File "/var/lib/kolla/venv/lib/python3.10/site-packages/urllib3/connection.py", line 363, in connect
2025-01-21 10:51:43.003 25 ERROR cinder.volume.drivers.lightos     self.sock = conn = self._new_conn()
2025-01-21 10:51:43.003 25 ERROR cinder.volume.drivers.lightos   File "/var/lib/kolla/venv/lib/python3.10/site-packages/urllib3/connection.py", line 186, in _new_conn
2025-01-21 10:51:43.003 25 ERROR cinder.volume.drivers.lightos     raise NewConnectionError(
2025-01-21 10:51:43.003 25 ERROR cinder.volume.drivers.lightos urllib3.exceptions.NewConnectionError: <urllib3.connection.HTTPSConnection object at 0x7fb8b0e812a0>: Failed to establish a new connection: [Errno 111] ECONNREFUSED
2025-01-21 10:51:43.003 25 ERROR cinder.volume.drivers.lightos 
2025-01-21 10:51:43.003 25 ERROR cinder.volume.drivers.lightos During handling of the above exception, another exception occurred:
2025-01-21 10:51:43.003 25 ERROR cinder.volume.drivers.lightos 
2025-01-21 10:51:43.003 25 ERROR cinder.volume.drivers.lightos Traceback (most recent call last):
2025-01-21 10:51:43.003 25 ERROR cinder.volume.drivers.lightos   File "/var/lib/kolla/venv/lib/python3.10/site-packages/requests/adapters.py", line 667, in send
2025-01-21 10:51:43.003 25 ERROR cinder.volume.drivers.lightos     resp = conn.urlopen(
2025-01-21 10:51:43.003 25 ERROR cinder.volume.drivers.lightos   File "/var/lib/kolla/venv/lib/python3.10/site-packages/urllib3/connectionpool.py", line 801, in urlopen
2025-01-21 10:51:43.003 25 ERROR cinder.volume.drivers.lightos     retries = retries.increment(
2025-01-21 10:51:43.003 25 ERROR cinder.volume.drivers.lightos   File "/var/lib/kolla/venv/lib/python3.10/site-packages/urllib3/util/retry.py", line 594, in increment
2025-01-21 10:51:43.003 25 ERROR cinder.volume.drivers.lightos     raise MaxRetryError(_pool, url, error or ResponseError(cause))
2025-01-21 10:51:43.003 25 ERROR cinder.volume.drivers.lightos urllib3.exceptions.MaxRetryError: HTTPSConnectionPool(host='[LB_IP_ADDRESS]', port=443): Max retries exceeded with url: /api/v2/clusterinfo (Caused by NewConnectionError('<urllib3.connection.HTTPSConnection object at 0x7fb8b0e812a0>: Failed to establish a new connection: [Errno 111] ECONNREFUSED'))
2025-01-21 10:51:43.003 25 ERROR cinder.volume.drivers.lightos 
2025-01-21 10:51:43.003 25 ERROR cinder.volume.drivers.lightos During handling of the above exception, another exception occurred:
2025-01-21 10:51:43.003 25 ERROR cinder.volume.drivers.lightos 
2025-01-21 10:51:43.003 25 ERROR cinder.volume.drivers.lightos Traceback (most recent call last):
2025-01-21 10:51:43.003 25 ERROR cinder.volume.drivers.lightos   File "/var/lib/kolla/venv/lib/python3.10/site-packages/cinder/volume/drivers/lightos.py", line 356, in __send_cmd
2025-01-21 10:51:43.003 25 ERROR cinder.volume.drivers.lightos     response = session.send(
2025-01-21 10:51:43.003 25 ERROR cinder.volume.drivers.lightos   File "/var/lib/kolla/venv/lib/python3.10/site-packages/requests/sessions.py", line 703, in send
2025-01-21 10:51:43.003 25 ERROR cinder.volume.drivers.lightos     r = adapter.send(request, **kwargs)
2025-01-21 10:51:43.003 25 ERROR cinder.volume.drivers.lightos   File "/var/lib/kolla/venv/lib/python3.10/site-packages/requests/adapters.py", line 700, in send
2025-01-21 10:51:43.003 25 ERROR cinder.volume.drivers.lightos     raise ConnectionError(e, request=request)
2025-01-21 10:51:43.003 25 ERROR cinder.volume.drivers.lightos requests.exceptions.ConnectionError: HTTPSConnectionPool(host='[LB_IP_ADDRESS]', port=443): Max retries exceeded with url: /api/v2/clusterinfo (Caused by NewConnectionError('<urllib3.connection.HTTPSConnection object at 0x7fb8b0e812a0>: Failed to establish a new connection: [Errno 111] ECONNREFUSED'))
2025-01-21 10:51:43.003 25 ERROR cinder.volume.drivers.lightos 
2025-01-21 10:51:43.006 25 INFO cinder.volume.drivers.lightos [None req-f5027d6f-3333-4cae-a38a-8718ac0670b1 - - - - - -] Invoking get_cluster_info using GET url: /api/v2/clusterinfo             request.body: {} ssl_verify: False
2025-01-21 10:51:45.057 25 ERROR cinder.volume.drivers.lightos [None req-f5027d6f-3333-4cae-a38a-8718ac0670b1 - - - - - -] REST server not responding at 'https://[LB_IP_ADDRESS]:443/api/v2/clusterinfo': requests.exceptions.ConnectionError: HTTPSConnectionPool(host='[LB_IP_ADDRESS]', port=443): Max retries exceeded with url: /api/v2/clusterinfo (Caused by NewConnectionError('<urllib3.connection.HTTPSConnection object at 0x7fb8b0e82320>: Failed to establish a new connection: [Errno 113] EHOSTUNREACH'))
2025-01-21 10:51:45.057 25 ERROR cinder.volume.drivers.lightos Traceback (most recent call last):
2025-01-21 10:51:45.057 25 ERROR cinder.volume.drivers.lightos   File "/var/lib/kolla/venv/lib/python3.10/site-packages/urllib3/connection.py", line 174, in _new_conn
2025-01-21 10:51:45.057 25 ERROR cinder.volume.drivers.lightos     conn = connection.create_connection(
2025-01-21 10:51:45.057 25 ERROR cinder.volume.drivers.lightos   File "/var/lib/kolla/venv/lib/python3.10/site-packages/urllib3/util/connection.py", line 95, in create_connection
2025-01-21 10:51:45.057 25 ERROR cinder.volume.drivers.lightos     raise err
2025-01-21 10:51:45.057 25 ERROR cinder.volume.drivers.lightos   File "/var/lib/kolla/venv/lib/python3.10/site-packages/urllib3/util/connection.py", line 85, in create_connection
2025-01-21 10:51:45.057 25 ERROR cinder.volume.drivers.lightos     sock.connect(sa)
2025-01-21 10:51:45.057 25 ERROR cinder.volume.drivers.lightos   File "/var/lib/kolla/venv/lib/python3.10/site-packages/eventlet/greenio/base.py", line 265, in connect
2025-01-21 10:51:45.057 25 ERROR cinder.volume.drivers.lightos     socket_checkerr(fd)
2025-01-21 10:51:45.057 25 ERROR cinder.volume.drivers.lightos   File "/var/lib/kolla/venv/lib/python3.10/site-packages/eventlet/greenio/base.py", line 50, in socket_checkerr
2025-01-21 10:51:45.057 25 ERROR cinder.volume.drivers.lightos     raise OSError(err, errno.errorcode[err])
2025-01-21 10:51:45.057 25 ERROR cinder.volume.drivers.lightos OSError: [Errno 113] EHOSTUNREACH
2025-01-21 10:51:45.057 25 ERROR cinder.volume.drivers.lightos 
2025-01-21 10:51:45.057 25 ERROR cinder.volume.drivers.lightos During handling of the above exception, another exception occurred:
2025-01-21 10:51:45.057 25 ERROR cinder.volume.drivers.lightos 
2025-01-21 10:51:45.057 25 ERROR cinder.volume.drivers.lightos Traceback (most recent call last):
2025-01-21 10:51:45.057 25 ERROR cinder.volume.drivers.lightos   File "/var/lib/kolla/venv/lib/python3.10/site-packages/urllib3/connectionpool.py", line 715, in urlopen
2025-01-21 10:51:45.057 25 ERROR cinder.volume.drivers.lightos     httplib_response = self._make_request(
2025-01-21 10:51:45.057 25 ERROR cinder.volume.drivers.lightos   File "/var/lib/kolla/venv/lib/python3.10/site-packages/urllib3/connectionpool.py", line 404, in _make_request
2025-01-21 10:51:45.057 25 ERROR cinder.volume.drivers.lightos     self._validate_conn(conn)
2025-01-21 10:51:45.057 25 ERROR cinder.volume.drivers.lightos   File "/var/lib/kolla/venv/lib/python3.10/site-packages/urllib3/connectionpool.py", line 1060, in _validate_conn
2025-01-21 10:51:45.057 25 ERROR cinder.volume.drivers.lightos     conn.connect()
2025-01-21 10:51:45.057 25 ERROR cinder.volume.drivers.lightos   File "/var/lib/kolla/venv/lib/python3.10/site-packages/urllib3/connection.py", line 363, in connect
2025-01-21 10:51:45.057 25 ERROR cinder.volume.drivers.lightos     self.sock = conn = self._new_conn()
2025-01-21 10:51:45.057 25 ERROR cinder.volume.drivers.lightos   File "/var/lib/kolla/venv/lib/python3.10/site-packages/urllib3/connection.py", line 186, in _new_conn
2025-01-21 10:51:45.057 25 ERROR cinder.volume.drivers.lightos     raise NewConnectionError(
2025-01-21 10:51:45.057 25 ERROR cinder.volume.drivers.lightos urllib3.exceptions.NewConnectionError: <urllib3.connection.HTTPSConnection object at 0x7fb8b0e82320>: Failed to establish a new connection: [Errno 113] EHOSTUNREACH
2025-01-21 10:51:45.057 25 ERROR cinder.volume.drivers.lightos 
2025-01-21 10:51:45.057 25 ERROR cinder.volume.drivers.lightos During handling of the above exception, another exception occurred:
2025-01-21 10:51:45.057 25 ERROR cinder.volume.drivers.lightos 
2025-01-21 10:51:45.057 25 ERROR cinder.volume.drivers.lightos Traceback (most recent call last):
2025-01-21 10:51:45.057 25 ERROR cinder.volume.drivers.lightos   File "/var/lib/kolla/venv/lib/python3.10/site-packages/requests/adapters.py", line 667, in send
2025-01-21 10:51:45.057 25 ERROR cinder.volume.drivers.lightos     resp = conn.urlopen(
2025-01-21 10:51:45.057 25 ERROR cinder.volume.drivers.lightos   File "/var/lib/kolla/venv/lib/python3.10/site-packages/urllib3/connectionpool.py", line 801, in urlopen
2025-01-21 10:51:45.057 25 ERROR cinder.volume.drivers.lightos     retries = retries.increment(
2025-01-21 10:51:45.057 25 ERROR cinder.volume.drivers.lightos   File "/var/lib/kolla/venv/lib/python3.10/site-packages/urllib3/util/retry.py", line 594, in increment
2025-01-21 10:51:45.057 25 ERROR cinder.volume.drivers.lightos     raise MaxRetryError(_pool, url, error or ResponseError(cause))
2025-01-21 10:51:45.057 25 ERROR cinder.volume.drivers.lightos urllib3.exceptions.MaxRetryError: HTTPSConnectionPool(host='[LB_IP_ADDRESS]', port=443): Max retries exceeded with url: /api/v2/clusterinfo (Caused by NewConnectionError('<urllib3.connection.HTTPSConnection object at 0x7fb8b0e82320>: Failed to establish a new connection: [Errno 113] EHOSTUNREACH'))
2025-01-21 10:51:45.057 25 ERROR cinder.volume.drivers.lightos 
2025-01-21 10:51:45.057 25 ERROR cinder.volume.drivers.lightos During handling of the above exception, another exception occurred:
2025-01-21 10:51:45.057 25 ERROR cinder.volume.drivers.lightos 
2025-01-21 10:51:45.057 25 ERROR cinder.volume.drivers.lightos Traceback (most recent call last):
2025-01-21 10:51:45.057 25 ERROR cinder.volume.drivers.lightos   File "/var/lib/kolla/venv/lib/python3.10/site-packages/cinder/volume/drivers/lightos.py", line 356, in __send_cmd
2025-01-21 10:51:45.057 25 ERROR cinder.volume.drivers.lightos     response = session.send(
2025-01-21 10:51:45.057 25 ERROR cinder.volume.drivers.lightos   File "/var/lib/kolla/venv/lib/python3.10/site-packages/requests/sessions.py", line 703, in send
2025-01-21 10:51:45.057 25 ERROR cinder.volume.drivers.lightos     r = adapter.send(request, **kwargs)
2025-01-21 10:51:45.057 25 ERROR cinder.volume.drivers.lightos   File "/var/lib/kolla/venv/lib/python3.10/site-packages/requests/adapters.py", line 700, in send
2025-01-21 10:51:45.057 25 ERROR cinder.volume.drivers.lightos     raise ConnectionError(e, request=request)
2025-01-21 10:51:45.057 25 ERROR cinder.volume.drivers.lightos requests.exceptions.ConnectionError: HTTPSConnectionPool(host='[LB_IP_ADDRESS]', port=443): Max retries exceeded with url: /api/v2/clusterinfo (Caused by NewConnectionError('<urllib3.connection.HTTPSConnection object at 0x7fb8b0e82320>: Failed to establish a new connection: [Errno 113] EHOSTUNREACH'))
2025-01-21 10:51:45.057 25 ERROR cinder.volume.drivers.lightos 
2025-01-21 10:51:45.060 25 ERROR cinder.volume.manager [None req-f5027d6f-3333-4cae-a38a-8718ac0670b1 - - - - - -] Failed to initialize driver.: cinder.exception.VolumeDriverException: Volume driver reported an error: Could not get a response from any API server
2025-01-21 10:51:45.060 25 ERROR cinder.volume.manager Traceback (most recent call last):
2025-01-21 10:51:45.060 25 ERROR cinder.volume.manager   File "/var/lib/kolla/venv/lib/python3.10/site-packages/cinder/volume/manager.py", line 523, in _init_host
2025-01-21 10:51:45.060 25 ERROR cinder.volume.manager     self.driver.do_setup(ctxt)
2025-01-21 10:51:45.060 25 ERROR cinder.volume.manager   File "/var/lib/kolla/venv/lib/python3.10/site-packages/cinder/volume/drivers/lightos.py", line 922, in do_setup
2025-01-21 10:51:45.060 25 ERROR cinder.volume.manager     self.get_cluster_info()
2025-01-21 10:51:45.060 25 ERROR cinder.volume.manager   File "/var/lib/kolla/venv/lib/python3.10/site-packages/cinder/volume/drivers/lightos.py", line 873, in get_cluster_info
2025-01-21 10:51:45.060 25 ERROR cinder.volume.manager     status_code, cluster_info = self.cluster.send_cmd(
2025-01-21 10:51:45.060 25 ERROR cinder.volume.manager   File "/var/lib/kolla/venv/lib/python3.10/site-packages/cinder/volume/drivers/lightos.py", line 315, in send_cmd
2025-01-21 10:51:45.060 25 ERROR cinder.volume.manager     raise exception.VolumeDriverException(
2025-01-21 10:51:45.060 25 ERROR cinder.volume.manager cinder.exception.VolumeDriverException: Volume driver reported an error: Could not get a response from any API server
2025-01-21 10:51:45.060 25 ERROR cinder.volume.manager 
2025-01-21 10:51:47.064 25 INFO cinder.volume.manager [None req-f5027d6f-3333-4cae-a38a-8718ac0670b1 - - - - - -] Starting volume driver LightOSVolumeDriver (2.3.12)
2025-01-21 10:51:47.064 25 INFO cinder.volume.drivers.lightos [None req-f5027d6f-3333-4cae-a38a-8718ac0670b1 - - - - - -] Invoking get_cluster_info using GET url: /api/v2/clusterinfo             request.body: {} ssl_verify: False
2025-01-21 10:51:47.068 25 ERROR cinder.volume.drivers.lightos [None req-f5027d6f-3333-4cae-a38a-8718ac0670b1 - - - - - -] REST server not responding at 'https://[LB_IP_ADDRESS]:443/api/v2/clusterinfo': requests.exceptions.ConnectionError: HTTPSConnectionPool(host='[LB_IP_ADDRESS]', port=443): Max retries exceeded with url: /api/v2/clusterinfo (Caused by NewConnectionError('<urllib3.connection.HTTPSConnection object at 0x7fb8b0c247c0>: Failed to establish a new connection: [Errno 111] ECONNREFUSED'))
2025-01-21 10:51:47.068 25 ERROR cinder.volume.drivers.lightos Traceback (most recent call last):
2025-01-21 10:51:47.068 25 ERROR cinder.volume.drivers.lightos   File "/var/lib/kolla/venv/lib/python3.10/site-packages/urllib3/connection.py", line 174, in _new_conn
2025-01-21 10:51:47.068 25 ERROR cinder.volume.drivers.lightos     conn = connection.create_connection(
2025-01-21 10:51:47.068 25 ERROR cinder.volume.drivers.lightos   File "/var/lib/kolla/venv/lib/python3.10/site-packages/urllib3/util/connection.py", line 95, in create_connection
2025-01-21 10:51:47.068 25 ERROR cinder.volume.drivers.lightos     raise err
2025-01-21 10:51:47.068 25 ERROR cinder.volume.drivers.lightos   File "/var/lib/kolla/venv/lib/python3.10/site-packages/urllib3/util/connection.py", line 85, in create_connection
2025-01-21 10:51:47.068 25 ERROR cinder.volume.drivers.lightos     sock.connect(sa)
2025-01-21 10:51:47.068 25 ERROR cinder.volume.drivers.lightos   File "/var/lib/kolla/venv/lib/python3.10/site-packages/eventlet/greenio/base.py", line 265, in connect
2025-01-21 10:51:47.068 25 ERROR cinder.volume.drivers.lightos     socket_checkerr(fd)
2025-01-21 10:51:47.068 25 ERROR cinder.volume.drivers.lightos   File "/var/lib/kolla/venv/lib/python3.10/site-packages/eventlet/greenio/base.py", line 50, in socket_checkerr
2025-01-21 10:51:47.068 25 ERROR cinder.volume.drivers.lightos     raise OSError(err, errno.errorcode[err])
2025-01-21 10:51:47.068 25 ERROR cinder.volume.drivers.lightos ConnectionRefusedError: [Errno 111] ECONNREFUSED
2025-01-21 10:51:47.068 25 ERROR cinder.volume.drivers.lightos 
2025-01-21 10:51:47.068 25 ERROR cinder.volume.drivers.lightos During handling of the above exception, another exception occurred:
2025-01-21 10:51:47.068 25 ERROR cinder.volume.drivers.lightos 
2025-01-21 10:51:47.068 25 ERROR cinder.volume.drivers.lightos Traceback (most recent call last):
2025-01-21 10:51:47.068 25 ERROR cinder.volume.drivers.lightos   File "/var/lib/kolla/venv/lib/python3.10/site-packages/urllib3/connectionpool.py", line 715, in urlopen
2025-01-21 10:51:47.068 25 ERROR cinder.volume.drivers.lightos     httplib_response = self._make_request(
2025-01-21 10:51:47.068 25 ERROR cinder.volume.drivers.lightos   File "/var/lib/kolla/venv/lib/python3.10/site-packages/urllib3/connectionpool.py", line 404, in _make_request
2025-01-21 10:51:47.068 25 ERROR cinder.volume.drivers.lightos     self._validate_conn(conn)
2025-01-21 10:51:47.068 25 ERROR cinder.volume.drivers.lightos   File "/var/lib/kolla/venv/lib/python3.10/site-packages/urllib3/connectionpool.py", line 1060, in _validate_conn
2025-01-21 10:51:47.068 25 ERROR cinder.volume.drivers.lightos     conn.connect()
2025-01-21 10:51:47.068 25 ERROR cinder.volume.drivers.lightos   File "/var/lib/kolla/venv/lib/python3.10/site-packages/urllib3/connection.py", line 363, in connect
2025-01-21 10:51:47.068 25 ERROR cinder.volume.drivers.lightos     self.sock = conn = self._new_conn()
2025-01-21 10:51:47.068 25 ERROR cinder.volume.drivers.lightos   File "/var/lib/kolla/venv/lib/python3.10/site-packages/urllib3/connection.py", line 186, in _new_conn
2025-01-21 10:51:47.068 25 ERROR cinder.volume.drivers.lightos     raise NewConnectionError(
2025-01-21 10:51:47.068 25 ERROR cinder.volume.drivers.lightos urllib3.exceptions.NewConnectionError: <urllib3.connection.HTTPSConnection object at 0x7fb8b0c247c0>: Failed to establish a new connection: [Errno 111] ECONNREFUSED
2025-01-21 10:51:47.068 25 ERROR cinder.volume.drivers.lightos 
2025-01-21 10:51:47.068 25 ERROR cinder.volume.drivers.lightos During handling of the above exception, another exception occurred:
2025-01-21 10:51:47.068 25 ERROR cinder.volume.drivers.lightos 
2025-01-21 10:51:47.068 25 ERROR cinder.volume.drivers.lightos Traceback (most recent call last):
2025-01-21 10:51:47.068 25 ERROR cinder.volume.drivers.lightos   File "/var/lib/kolla/venv/lib/python3.10/site-packages/requests/adapters.py", line 667, in send
2025-01-21 10:51:47.068 25 ERROR cinder.volume.drivers.lightos     resp = conn.urlopen(
2025-01-21 10:51:47.068 25 ERROR cinder.volume.drivers.lightos   File "/var/lib/kolla/venv/lib/python3.10/site-packages/urllib3/connectionpool.py", line 801, in urlopen
2025-01-21 10:51:47.068 25 ERROR cinder.volume.drivers.lightos     retries = retries.increment(
2025-01-21 10:51:47.068 25 ERROR cinder.volume.drivers.lightos   File "/var/lib/kolla/venv/lib/python3.10/site-packages/urllib3/util/retry.py", line 594, in increment
2025-01-21 10:51:47.068 25 ERROR cinder.volume.drivers.lightos     raise MaxRetryError(_pool, url, error or ResponseError(cause))
2025-01-21 10:51:47.068 25 ERROR cinder.volume.drivers.lightos urllib3.exceptions.MaxRetryError: HTTPSConnectionPool(host='[LB_IP_ADDRESS]', port=443): Max retries exceeded with url: /api/v2/clusterinfo (Caused by NewConnectionError('<urllib3.connection.HTTPSConnection object at 0x7fb8b0c247c0>: Failed to establish a new connection: [Errno 111] ECONNREFUSED'))
2025-01-21 10:51:47.068 25 ERROR cinder.volume.drivers.lightos 
2025-01-21 10:51:47.068 25 ERROR cinder.volume.drivers.lightos During handling of the above exception, another exception occurred:
2025-01-21 10:51:47.068 25 ERROR cinder.volume.drivers.lightos 
2025-01-21 10:51:47.068 25 ERROR cinder.volume.drivers.lightos Traceback (most recent call last):
2025-01-21 10:51:47.068 25 ERROR cinder.volume.drivers.lightos   File "/var/lib/kolla/venv/lib/python3.10/site-packages/cinder/volume/drivers/lightos.py", line 356, in __send_cmd
2025-01-21 10:51:47.068 25 ERROR cinder.volume.drivers.lightos     response = session.send(
2025-01-21 10:51:47.068 25 ERROR cinder.volume.drivers.lightos   File "/var/lib/kolla/venv/lib/python3.10/site-packages/requests/sessions.py", line 703, in send
2025-01-21 10:51:47.068 25 ERROR cinder.volume.drivers.lightos     r = adapter.send(request, **kwargs)
2025-01-21 10:51:47.068 25 ERROR cinder.volume.drivers.lightos   File "/var/lib/kolla/venv/lib/python3.10/site-packages/requests/adapters.py", line 700, in send
2025-01-21 10:51:47.068 25 ERROR cinder.volume.drivers.lightos     raise ConnectionError(e, request=request)
2025-01-21 10:51:47.068 25 ERROR cinder.volume.drivers.lightos requests.exceptions.ConnectionError: HTTPSConnectionPool(host='[LB_IP_ADDRESS]', port=443): Max retries exceeded with url: /api/v2/clusterinfo (Caused by NewConnectionError('<urllib3.connection.HTTPSConnection object at 0x7fb8b0c247c0>: Failed to establish a new connection: [Errno 111] ECONNREFUSED'))
2025-01-21 10:51:47.068 25 ERROR cinder.volume.drivers.lightos 
2025-01-21 10:51:47.070 25 INFO cinder.volume.drivers.lightos [None req-f5027d6f-3333-4cae-a38a-8718ac0670b1 - - - - - -] Invoking get_cluster_info using GET url: /api/v2/clusterinfo             request.body: {} ssl_verify: False
2025-01-21 10:51:47.073 25 ERROR cinder.volume.drivers.lightos [None req-f5027d6f-3333-4cae-a38a-8718ac0670b1 - - - - - -] REST server not responding at 'https://[LB_IP_ADDRESS]:443/api/v2/clusterinfo': requests.exceptions.ConnectionError: HTTPSConnectionPool(host='[LB_IP_ADDRESS]', port=443): Max retries exceeded with url: /api/v2/clusterinfo (Caused by NewConnectionError('<urllib3.connection.HTTPSConnection object at 0x7fb8b0c252a0>: Failed to establish a new connection: [Errno 111] ECONNREFUSED'))
2025-01-21 10:51:47.073 25 ERROR cinder.volume.drivers.lightos Traceback (most recent call last):
2025-01-21 10:51:47.073 25 ERROR cinder.volume.drivers.lightos   File "/var/lib/kolla/venv/lib/python3.10/site-packages/urllib3/connection.py", line 174, in _new_conn
2025-01-21 10:51:47.073 25 ERROR cinder.volume.drivers.lightos     conn = connection.create_connection(
2025-01-21 10:51:47.073 25 ERROR cinder.volume.drivers.lightos   File "/var/lib/kolla/venv/lib/python3.10/site-packages/urllib3/util/connection.py", line 95, in create_connection
2025-01-21 10:51:47.073 25 ERROR cinder.volume.drivers.lightos     raise err
2025-01-21 10:51:47.073 25 ERROR cinder.volume.drivers.lightos   File "/var/lib/kolla/venv/lib/python3.10/site-packages/urllib3/util/connection.py", line 85, in create_connection
2025-01-21 10:51:47.073 25 ERROR cinder.volume.drivers.lightos     sock.connect(sa)
2025-01-21 10:51:47.073 25 ERROR cinder.volume.drivers.lightos   File "/var/lib/kolla/venv/lib/python3.10/site-packages/eventlet/greenio/base.py", line 265, in connect
2025-01-21 10:51:47.073 25 ERROR cinder.volume.drivers.lightos     socket_checkerr(fd)
2025-01-21 10:51:47.073 25 ERROR cinder.volume.drivers.lightos   File "/var/lib/kolla/venv/lib/python3.10/site-packages/eventlet/greenio/base.py", line 50, in socket_checkerr
2025-01-21 10:51:47.073 25 ERROR cinder.volume.drivers.lightos     raise OSError(err, errno.errorcode[err])
2025-01-21 10:51:47.073 25 ERROR cinder.volume.drivers.lightos ConnectionRefusedError: [Errno 111] ECONNREFUSED
2025-01-21 10:51:47.073 25 ERROR cinder.volume.drivers.lightos 
2025-01-21 10:51:47.073 25 ERROR cinder.volume.drivers.lightos During handling of the above exception, another exception occurred:
2025-01-21 10:51:47.073 25 ERROR cinder.volume.drivers.lightos 
2025-01-21 10:51:47.073 25 ERROR cinder.volume.drivers.lightos Traceback (most recent call last):
2025-01-21 10:51:47.073 25 ERROR cinder.volume.drivers.lightos   File "/var/lib/kolla/venv/lib/python3.10/site-packages/urllib3/connectionpool.py", line 715, in urlopen
2025-01-21 10:51:47.073 25 ERROR cinder.volume.drivers.lightos     httplib_response = self._make_request(
2025-01-21 10:51:47.073 25 ERROR cinder.volume.drivers.lightos   File "/var/lib/kolla/venv/lib/python3.10/site-packages/urllib3/connectionpool.py", line 404, in _make_request
2025-01-21 10:51:47.073 25 ERROR cinder.volume.drivers.lightos     self._validate_conn(conn)
2025-01-21 10:51:47.073 25 ERROR cinder.volume.drivers.lightos   File "/var/lib/kolla/venv/lib/python3.10/site-packages/urllib3/connectionpool.py", line 1060, in _validate_conn
2025-01-21 10:51:47.073 25 ERROR cinder.volume.drivers.lightos     conn.connect()
2025-01-21 10:51:47.073 25 ERROR cinder.volume.drivers.lightos   File "/var/lib/kolla/venv/lib/python3.10/site-packages/urllib3/connection.py", line 363, in connect
2025-01-21 10:51:47.073 25 ERROR cinder.volume.drivers.lightos     self.sock = conn = self._new_conn()
2025-01-21 10:51:47.073 25 ERROR cinder.volume.drivers.lightos   File "/var/lib/kolla/venv/lib/python3.10/site-packages/urllib3/connection.py", line 186, in _new_conn
2025-01-21 10:51:47.073 25 ERROR cinder.volume.drivers.lightos     raise NewConnectionError(
2025-01-21 10:51:47.073 25 ERROR cinder.volume.drivers.lightos urllib3.exceptions.NewConnectionError: <urllib3.connection.HTTPSConnection object at 0x7fb8b0c252a0>: Failed to establish a new connection: [Errno 111] ECONNREFUSED
2025-01-21 10:51:47.073 25 ERROR cinder.volume.drivers.lightos 
2025-01-21 10:51:47.073 25 ERROR cinder.volume.drivers.lightos During handling of the above exception, another exception occurred:
2025-01-21 10:51:47.073 25 ERROR cinder.volume.drivers.lightos 
2025-01-21 10:51:47.073 25 ERROR cinder.volume.drivers.lightos Traceback (most recent call last):
2025-01-21 10:51:47.073 25 ERROR cinder.volume.drivers.lightos   File "/var/lib/kolla/venv/lib/python3.10/site-packages/requests/adapters.py", line 667, in send
2025-01-21 10:51:47.073 25 ERROR cinder.volume.drivers.lightos     resp = conn.urlopen(
2025-01-21 10:51:47.073 25 ERROR cinder.volume.drivers.lightos   File "/var/lib/kolla/venv/lib/python3.10/site-packages/urllib3/connectionpool.py", line 801, in urlopen
2025-01-21 10:51:47.073 25 ERROR cinder.volume.drivers.lightos     retries = retries.increment(
2025-01-21 10:51:47.073 25 ERROR cinder.volume.drivers.lightos   File "/var/lib/kolla/venv/lib/python3.10/site-packages/urllib3/util/retry.py", line 594, in increment
2025-01-21 10:51:47.073 25 ERROR cinder.volume.drivers.lightos     raise MaxRetryError(_pool, url, error or ResponseError(cause))
2025-01-21 10:51:47.073 25 ERROR cinder.volume.drivers.lightos urllib3.exceptions.MaxRetryError: HTTPSConnectionPool(host='[LB_IP_ADDRESS]', port=443): Max retries exceeded with url: /api/v2/clusterinfo (Caused by NewConnectionError('<urllib3.connection.HTTPSConnection object at 0x7fb8b0c252a0>: Failed to establish a new connection: [Errno 111] ECONNREFUSED'))
2025-01-21 10:51:47.073 25 ERROR cinder.volume.drivers.lightos 
2025-01-21 10:51:47.073 25 ERROR cinder.volume.drivers.lightos During handling of the above exception, another exception occurred:
2025-01-21 10:51:47.073 25 ERROR cinder.volume.drivers.lightos 
2025-01-21 10:51:47.073 25 ERROR cinder.volume.drivers.lightos Traceback (most recent call last):
2025-01-21 10:51:47.073 25 ERROR cinder.volume.drivers.lightos   File "/var/lib/kolla/venv/lib/python3.10/site-packages/cinder/volume/drivers/lightos.py", line 356, in __send_cmd
2025-01-21 10:51:47.073 25 ERROR cinder.volume.drivers.lightos     response = session.send(
2025-01-21 10:51:47.073 25 ERROR cinder.volume.drivers.lightos   File "/var/lib/kolla/venv/lib/python3.10/site-packages/requests/sessions.py", line 703, in send
2025-01-21 10:51:47.073 25 ERROR cinder.volume.drivers.lightos     r = adapter.send(request, **kwargs)
2025-01-21 10:51:47.073 25 ERROR cinder.volume.drivers.lightos   File "/var/lib/kolla/venv/lib/python3.10/site-packages/requests/adapters.py", line 700, in send
2025-01-21 10:51:47.073 25 ERROR cinder.volume.drivers.lightos     raise ConnectionError(e, request=request)
2025-01-21 10:51:47.073 25 ERROR cinder.volume.drivers.lightos requests.exceptions.ConnectionError: HTTPSConnectionPool(host='[LB_IP_ADDRESS]', port=443): Max retries exceeded with url: /api/v2/clusterinfo (Caused by NewConnectionError('<urllib3.connection.HTTPSConnection object at 0x7fb8b0c252a0>: Failed to establish a new connection: [Errno 111] ECONNREFUSED'))
2025-01-21 10:51:47.073 25 ERROR cinder.volume.drivers.lightos 
2025-01-21 10:51:47.075 25 INFO cinder.volume.drivers.lightos [None req-f5027d6f-3333-4cae-a38a-8718ac0670b1 - - - - - -] Invoking get_cluster_info using GET url: /api/v2/clusterinfo             request.body: {} ssl_verify: False
2025-01-21 10:51:48.129 25 ERROR cinder.volume.drivers.lightos [None req-f5027d6f-3333-4cae-a38a-8718ac0670b1 - - - - - -] REST server not responding at 'https://[LB_IP_ADDRESS]:443/api/v2/clusterinfo': requests.exceptions.ConnectionError: HTTPSConnectionPool(host='[LB_IP_ADDRESS]', port=443): Max retries exceeded with url: /api/v2/clusterinfo (Caused by NewConnectionError('<urllib3.connection.HTTPSConnection object at 0x7fb8b0e821d0>: Failed to establish a new connection: [Errno 113] EHOSTUNREACH'))
2025-01-21 10:51:48.129 25 ERROR cinder.volume.drivers.lightos Traceback (most recent call last):
2025-01-21 10:51:48.129 25 ERROR cinder.volume.drivers.lightos   File "/var/lib/kolla/venv/lib/python3.10/site-packages/urllib3/connection.py", line 174, in _new_conn
2025-01-21 10:51:48.129 25 ERROR cinder.volume.drivers.lightos     conn = connection.create_connection(
2025-01-21 10:51:48.129 25 ERROR cinder.volume.drivers.lightos   File "/var/lib/kolla/venv/lib/python3.10/site-packages/urllib3/util/connection.py", line 95, in create_connection
2025-01-21 10:51:48.129 25 ERROR cinder.volume.drivers.lightos     raise err
2025-01-21 10:51:48.129 25 ERROR cinder.volume.drivers.lightos   File "/var/lib/kolla/venv/lib/python3.10/site-packages/urllib3/util/connection.py", line 85, in create_connection
2025-01-21 10:51:48.129 25 ERROR cinder.volume.drivers.lightos     sock.connect(sa)
2025-01-21 10:51:48.129 25 ERROR cinder.volume.drivers.lightos   File "/var/lib/kolla/venv/lib/python3.10/site-packages/eventlet/greenio/base.py", line 265, in connect
2025-01-21 10:51:48.129 25 ERROR cinder.volume.drivers.lightos     socket_checkerr(fd)
2025-01-21 10:51:48.129 25 ERROR cinder.volume.drivers.lightos   File "/var/lib/kolla/venv/lib/python3.10/site-packages/eventlet/greenio/base.py", line 50, in socket_checkerr
2025-01-21 10:51:48.129 25 ERROR cinder.volume.drivers.lightos     raise OSError(err, errno.errorcode[err])
2025-01-21 10:51:48.129 25 ERROR cinder.volume.drivers.lightos OSError: [Errno 113] EHOSTUNREACH
2025-01-21 10:51:48.129 25 ERROR cinder.volume.drivers.lightos 
2025-01-21 10:51:48.129 25 ERROR cinder.volume.drivers.lightos During handling of the above exception, another exception occurred:
2025-01-21 10:51:48.129 25 ERROR cinder.volume.drivers.lightos 
2025-01-21 10:51:48.129 25 ERROR cinder.volume.drivers.lightos Traceback (most recent call last):
2025-01-21 10:51:48.129 25 ERROR cinder.volume.drivers.lightos   File "/var/lib/kolla/venv/lib/python3.10/site-packages/urllib3/connectionpool.py", line 715, in urlopen
2025-01-21 10:51:48.129 25 ERROR cinder.volume.drivers.lightos     httplib_response = self._make_request(
2025-01-21 10:51:48.129 25 ERROR cinder.volume.drivers.lightos   File "/var/lib/kolla/venv/lib/python3.10/site-packages/urllib3/connectionpool.py", line 404, in _make_request
2025-01-21 10:51:48.129 25 ERROR cinder.volume.drivers.lightos     self._validate_conn(conn)
2025-01-21 10:51:48.129 25 ERROR cinder.volume.drivers.lightos   File "/var/lib/kolla/venv/lib/python3.10/site-packages/urllib3/connectionpool.py", line 1060, in _validate_conn
2025-01-21 10:51:48.129 25 ERROR cinder.volume.drivers.lightos     conn.connect()
2025-01-21 10:51:48.129 25 ERROR cinder.volume.drivers.lightos   File "/var/lib/kolla/venv/lib/python3.10/site-packages/urllib3/connection.py", line 363, in connect
2025-01-21 10:51:48.129 25 ERROR cinder.volume.drivers.lightos     self.sock = conn = self._new_conn()
2025-01-21 10:51:48.129 25 ERROR cinder.volume.drivers.lightos   File "/var/lib/kolla/venv/lib/python3.10/site-packages/urllib3/connection.py", line 186, in _new_conn
2025-01-21 10:51:48.129 25 ERROR cinder.volume.drivers.lightos     raise NewConnectionError(
2025-01-21 10:51:48.129 25 ERROR cinder.volume.drivers.lightos urllib3.exceptions.NewConnectionError: <urllib3.connection.HTTPSConnection object at 0x7fb8b0e821d0>: Failed to establish a new connection: [Errno 113] EHOSTUNREACH
2025-01-21 10:51:48.129 25 ERROR cinder.volume.drivers.lightos 
2025-01-21 10:51:48.129 25 ERROR cinder.volume.drivers.lightos During handling of the above exception, another exception occurred:
2025-01-21 10:51:48.129 25 ERROR cinder.volume.drivers.lightos 
2025-01-21 10:51:48.129 25 ERROR cinder.volume.drivers.lightos Traceback (most recent call last):
2025-01-21 10:51:48.129 25 ERROR cinder.volume.drivers.lightos   File "/var/lib/kolla/venv/lib/python3.10/site-packages/requests/adapters.py", line 667, in send
2025-01-21 10:51:48.129 25 ERROR cinder.volume.drivers.lightos     resp = conn.urlopen(
2025-01-21 10:51:48.129 25 ERROR cinder.volume.drivers.lightos   File "/var/lib/kolla/venv/lib/python3.10/site-packages/urllib3/connectionpool.py", line 801, in urlopen
2025-01-21 10:51:48.129 25 ERROR cinder.volume.drivers.lightos     retries = retries.increment(
2025-01-21 10:51:48.129 25 ERROR cinder.volume.drivers.lightos   File "/var/lib/kolla/venv/lib/python3.10/site-packages/urllib3/util/retry.py", line 594, in increment
2025-01-21 10:51:48.129 25 ERROR cinder.volume.drivers.lightos     raise MaxRetryError(_pool, url, error or ResponseError(cause))
2025-01-21 10:51:48.129 25 ERROR cinder.volume.drivers.lightos urllib3.exceptions.MaxRetryError: HTTPSConnectionPool(host='[LB_IP_ADDRESS]', port=443): Max retries exceeded with url: /api/v2/clusterinfo (Caused by NewConnectionError('<urllib3.connection.HTTPSConnection object at 0x7fb8b0e821d0>: Failed to establish a new connection: [Errno 113] EHOSTUNREACH'))
2025-01-21 10:51:48.129 25 ERROR cinder.volume.drivers.lightos 
2025-01-21 10:51:48.129 25 ERROR cinder.volume.drivers.lightos During handling of the above exception, another exception occurred:
2025-01-21 10:51:48.129 25 ERROR cinder.volume.drivers.lightos 
2025-01-21 10:51:48.129 25 ERROR cinder.volume.drivers.lightos Traceback (most recent call last):
2025-01-21 10:51:48.129 25 ERROR cinder.volume.drivers.lightos   File "/var/lib/kolla/venv/lib/python3.10/site-packages/cinder/volume/drivers/lightos.py", line 356, in __send_cmd
2025-01-21 10:51:48.129 25 ERROR cinder.volume.drivers.lightos     response = session.send(
2025-01-21 10:51:48.129 25 ERROR cinder.volume.drivers.lightos   File "/var/lib/kolla/venv/lib/python3.10/site-packages/requests/sessions.py", line 703, in send
2025-01-21 10:51:48.129 25 ERROR cinder.volume.drivers.lightos     r = adapter.send(request, **kwargs)
2025-01-21 10:51:48.129 25 ERROR cinder.volume.drivers.lightos   File "/var/lib/kolla/venv/lib/python3.10/site-packages/requests/adapters.py", line 700, in send
2025-01-21 10:51:48.129 25 ERROR cinder.volume.drivers.lightos     raise ConnectionError(e, request=request)
2025-01-21 10:51:48.129 25 ERROR cinder.volume.drivers.lightos requests.exceptions.ConnectionError: HTTPSConnectionPool(host='[LB_IP_ADDRESS]', port=443): Max retries exceeded with url: /api/v2/clusterinfo (Caused by NewConnectionError('<urllib3.connection.HTTPSConnection object at 0x7fb8b0e821d0>: Failed to establish a new connection: [Errno 113] EHOSTUNREACH'))
2025-01-21 10:51:48.129 25 ERROR cinder.volume.drivers.lightos 
2025-01-21 10:51:48.132 25 ERROR cinder.volume.manager [None req-f5027d6f-3333-4cae-a38a-8718ac0670b1 - - - - - -] Failed to initialize driver.: cinder.exception.VolumeDriverException: Volume driver reported an error: Could not get a response from any API server
2025-01-21 10:51:48.132 25 ERROR cinder.volume.manager Traceback (most recent call last):
2025-01-21 10:51:48.132 25 ERROR cinder.volume.manager   File "/var/lib/kolla/venv/lib/python3.10/site-packages/cinder/volume/manager.py", line 523, in _init_host
2025-01-21 10:51:48.132 25 ERROR cinder.volume.manager     self.driver.do_setup(ctxt)
2025-01-21 10:51:48.132 25 ERROR cinder.volume.manager   File "/var/lib/kolla/venv/lib/python3.10/site-packages/cinder/volume/drivers/lightos.py", line 922, in do_setup
2025-01-21 10:51:48.132 25 ERROR cinder.volume.manager     self.get_cluster_info()
2025-01-21 10:51:48.132 25 ERROR cinder.volume.manager   File "/var/lib/kolla/venv/lib/python3.10/site-packages/cinder/volume/drivers/lightos.py", line 873, in get_cluster_info
2025-01-21 10:51:48.132 25 ERROR cinder.volume.manager     status_code, cluster_info = self.cluster.send_cmd(
2025-01-21 10:51:48.132 25 ERROR cinder.volume.manager   File "/var/lib/kolla/venv/lib/python3.10/site-packages/cinder/volume/drivers/lightos.py", line 315, in send_cmd
2025-01-21 10:51:48.132 25 ERROR cinder.volume.manager     raise exception.VolumeDriverException(
2025-01-21 10:51:48.132 25 ERROR cinder.volume.manager cinder.exception.VolumeDriverException: Volume driver reported an error: Could not get a response from any API server
2025-01-21 10:51:48.132 25 ERROR cinder.volume.manager 
2025-01-21 10:51:52.137 25 INFO cinder.volume.manager [None req-f5027d6f-3333-4cae-a38a-8718ac0670b1 - - - - - -] Starting volume driver LightOSVolumeDriver (2.3.12)
2025-01-21 10:51:52.138 25 INFO cinder.volume.drivers.lightos [None req-f5027d6f-3333-4cae-a38a-8718ac0670b1 - - - - - -] Invoking get_cluster_info using GET url: /api/v2/clusterinfo             request.body: {} ssl_verify: False
2025-01-21 10:51:52.146 25 ERROR cinder.volume.drivers.lightos [None req-f5027d6f-3333-4cae-a38a-8718ac0670b1 - - - - - -] REST server not responding at 'https://[LB_IP_ADDRESS]:443/api/v2/clusterinfo': requests.exceptions.ConnectionError: HTTPSConnectionPool(host='[LB_IP_ADDRESS]', port=443): Max retries exceeded with url: /api/v2/clusterinfo (Caused by NewConnectionError('<urllib3.connection.HTTPSConnection object at 0x7fb8b0e80af0>: Failed to establish a new connection: [Errno 111] ECONNREFUSED'))
2025-01-21 10:51:52.146 25 ERROR cinder.volume.drivers.lightos Traceback (most recent call last):
2025-01-21 10:51:52.146 25 ERROR cinder.volume.drivers.lightos   File "/var/lib/kolla/venv/lib/python3.10/site-packages/urllib3/connection.py", line 174, in _new_conn
2025-01-21 10:51:52.146 25 ERROR cinder.volume.drivers.lightos     conn = connection.create_connection(
2025-01-21 10:51:52.146 25 ERROR cinder.volume.drivers.lightos   File "/var/lib/kolla/venv/lib/python3.10/site-packages/urllib3/util/connection.py", line 95, in create_connection
2025-01-21 10:51:52.146 25 ERROR cinder.volume.drivers.lightos     raise err
2025-01-21 10:51:52.146 25 ERROR cinder.volume.drivers.lightos   File "/var/lib/kolla/venv/lib/python3.10/site-packages/urllib3/util/connection.py", line 85, in create_connection
2025-01-21 10:51:52.146 25 ERROR cinder.volume.drivers.lightos     sock.connect(sa)
2025-01-21 10:51:52.146 25 ERROR cinder.volume.drivers.lightos   File "/var/lib/kolla/venv/lib/python3.10/site-packages/eventlet/greenio/base.py", line 265, in connect
2025-01-21 10:51:52.146 25 ERROR cinder.volume.drivers.lightos     socket_checkerr(fd)
2025-01-21 10:51:52.146 25 ERROR cinder.volume.drivers.lightos   File "/var/lib/kolla/venv/lib/python3.10/site-packages/eventlet/greenio/base.py", line 50, in socket_checkerr
2025-01-21 10:51:52.146 25 ERROR cinder.volume.drivers.lightos     raise OSError(err, errno.errorcode[err])
2025-01-21 10:51:52.146 25 ERROR cinder.volume.drivers.lightos ConnectionRefusedError: [Errno 111] ECONNREFUSED
2025-01-21 10:51:52.146 25 ERROR cinder.volume.drivers.lightos 
2025-01-21 10:51:52.146 25 ERROR cinder.volume.drivers.lightos During handling of the above exception, another exception occurred:
2025-01-21 10:51:52.146 25 ERROR cinder.volume.drivers.lightos 
2025-01-21 10:51:52.146 25 ERROR cinder.volume.drivers.lightos Traceback (most recent call last):
2025-01-21 10:51:52.146 25 ERROR cinder.volume.drivers.lightos   File "/var/lib/kolla/venv/lib/python3.10/site-packages/urllib3/connectionpool.py", line 715, in urlopen
2025-01-21 10:51:52.146 25 ERROR cinder.volume.drivers.lightos     httplib_response = self._make_request(
2025-01-21 10:51:52.146 25 ERROR cinder.volume.drivers.lightos   File "/var/lib/kolla/venv/lib/python3.10/site-packages/urllib3/connectionpool.py", line 404, in _make_request
2025-01-21 10:51:52.146 25 ERROR cinder.volume.drivers.lightos     self._validate_conn(conn)
2025-01-21 10:51:52.146 25 ERROR cinder.volume.drivers.lightos   File "/var/lib/kolla/venv/lib/python3.10/site-packages/urllib3/connectionpool.py", line 1060, in _validate_conn
2025-01-21 10:51:52.146 25 ERROR cinder.volume.drivers.lightos     conn.connect()
2025-01-21 10:51:52.146 25 ERROR cinder.volume.drivers.lightos   File "/var/lib/kolla/venv/lib/python3.10/site-packages/urllib3/connection.py", line 363, in connect
2025-01-21 10:51:52.146 25 ERROR cinder.volume.drivers.lightos     self.sock = conn = self._new_conn()
2025-01-21 10:51:52.146 25 ERROR cinder.volume.drivers.lightos   File "/var/lib/kolla/venv/lib/python3.10/site-packages/urllib3/connection.py", line 186, in _new_conn
2025-01-21 10:51:52.146 25 ERROR cinder.volume.drivers.lightos     raise NewConnectionError(
2025-01-21 10:51:52.146 25 ERROR cinder.volume.drivers.lightos urllib3.exceptions.NewConnectionError: <urllib3.connection.HTTPSConnection object at 0x7fb8b0e80af0>: Failed to establish a new connection: [Errno 111] ECONNREFUSED
2025-01-21 10:51:52.146 25 ERROR cinder.volume.drivers.lightos 
2025-01-21 10:51:52.146 25 ERROR cinder.volume.drivers.lightos During handling of the above exception, another exception occurred:
2025-01-21 10:51:52.146 25 ERROR cinder.volume.drivers.lightos 
2025-01-21 10:51:52.146 25 ERROR cinder.volume.drivers.lightos Traceback (most recent call last):
2025-01-21 10:51:52.146 25 ERROR cinder.volume.drivers.lightos   File "/var/lib/kolla/venv/lib/python3.10/site-packages/requests/adapters.py", line 667, in send
2025-01-21 10:51:52.146 25 ERROR cinder.volume.drivers.lightos     resp = conn.urlopen(
2025-01-21 10:51:52.146 25 ERROR cinder.volume.drivers.lightos   File "/var/lib/kolla/venv/lib/python3.10/site-packages/urllib3/connectionpool.py", line 801, in urlopen
2025-01-21 10:51:52.146 25 ERROR cinder.volume.drivers.lightos     retries = retries.increment(
2025-01-21 10:51:52.146 25 ERROR cinder.volume.drivers.lightos   File "/var/lib/kolla/venv/lib/python3.10/site-packages/urllib3/util/retry.py", line 594, in increment
2025-01-21 10:51:52.146 25 ERROR cinder.volume.drivers.lightos     raise MaxRetryError(_pool, url, error or ResponseError(cause))
2025-01-21 10:51:52.146 25 ERROR cinder.volume.drivers.lightos urllib3.exceptions.MaxRetryError: HTTPSConnectionPool(host='[LB_IP_ADDRESS]', port=443): Max retries exceeded with url: /api/v2/clusterinfo (Caused by NewConnectionError('<urllib3.connection.HTTPSConnection object at 0x7fb8b0e80af0>: Failed to establish a new connection: [Errno 111] ECONNREFUSED'))
2025-01-21 10:51:52.146 25 ERROR cinder.volume.drivers.lightos 
2025-01-21 10:51:52.146 25 ERROR cinder.volume.drivers.lightos During handling of the above exception, another exception occurred:
2025-01-21 10:51:52.146 25 ERROR cinder.volume.drivers.lightos 
2025-01-21 10:51:52.146 25 ERROR cinder.volume.drivers.lightos Traceback (most recent call last):
2025-01-21 10:51:52.146 25 ERROR cinder.volume.drivers.lightos   File "/var/lib/kolla/venv/lib/python3.10/site-packages/cinder/volume/drivers/lightos.py", line 356, in __send_cmd
2025-01-21 10:51:52.146 25 ERROR cinder.volume.drivers.lightos     response = session.send(
2025-01-21 10:51:52.146 25 ERROR cinder.volume.drivers.lightos   File "/var/lib/kolla/venv/lib/python3.10/site-packages/requests/sessions.py", line 703, in send
2025-01-21 10:51:52.146 25 ERROR cinder.volume.drivers.lightos     r = adapter.send(request, **kwargs)
2025-01-21 10:51:52.146 25 ERROR cinder.volume.drivers.lightos   File "/var/lib/kolla/venv/lib/python3.10/site-packages/requests/adapters.py", line 700, in send
2025-01-21 10:51:52.146 25 ERROR cinder.volume.drivers.lightos     raise ConnectionError(e, request=request)
2025-01-21 10:51:52.146 25 ERROR cinder.volume.drivers.lightos requests.exceptions.ConnectionError: HTTPSConnectionPool(host='[LB_IP_ADDRESS]', port=443): Max retries exceeded with url: /api/v2/clusterinfo (Caused by NewConnectionError('<urllib3.connection.HTTPSConnection object at 0x7fb8b0e80af0>: Failed to establish a new connection: [Errno 111] ECONNREFUSED'))
2025-01-21 10:51:52.146 25 ERROR cinder.volume.drivers.lightos 
2025-01-21 10:51:52.148 25 INFO cinder.volume.drivers.lightos [None req-f5027d6f-3333-4cae-a38a-8718ac0670b1 - - - - - -] Invoking get_cluster_info using GET url: /api/v2/clusterinfo             request.body: {} ssl_verify: False
2025-01-21 10:51:52.151 25 ERROR cinder.volume.drivers.lightos [None req-f5027d6f-3333-4cae-a38a-8718ac0670b1 - - - - - -] REST server not responding at 'https://[LB_IP_ADDRESS]:443/api/v2/clusterinfo': requests.exceptions.ConnectionError: HTTPSConnectionPool(host='[LB_IP_ADDRESS]', port=443): Max retries exceeded with url: /api/v2/clusterinfo (Caused by NewConnectionError('<urllib3.connection.HTTPSConnection object at 0x7fb8b0e80610>: Failed to establish a new connection: [Errno 111] ECONNREFUSED'))
2025-01-21 10:51:52.151 25 ERROR cinder.volume.drivers.lightos Traceback (most recent call last):
2025-01-21 10:51:52.151 25 ERROR cinder.volume.drivers.lightos   File "/var/lib/kolla/venv/lib/python3.10/site-packages/urllib3/connection.py", line 174, in _new_conn
2025-01-21 10:51:52.151 25 ERROR cinder.volume.drivers.lightos     conn = connection.create_connection(
2025-01-21 10:51:52.151 25 ERROR cinder.volume.drivers.lightos   File "/var/lib/kolla/venv/lib/python3.10/site-packages/urllib3/util/connection.py", line 95, in create_connection
2025-01-21 10:51:52.151 25 ERROR cinder.volume.drivers.lightos     raise err
2025-01-21 10:51:52.151 25 ERROR cinder.volume.drivers.lightos   File "/var/lib/kolla/venv/lib/python3.10/site-packages/urllib3/util/connection.py", line 85, in create_connection
2025-01-21 10:51:52.151 25 ERROR cinder.volume.drivers.lightos     sock.connect(sa)
2025-01-21 10:51:52.151 25 ERROR cinder.volume.drivers.lightos   File "/var/lib/kolla/venv/lib/python3.10/site-packages/eventlet/greenio/base.py", line 265, in connect
2025-01-21 10:51:52.151 25 ERROR cinder.volume.drivers.lightos     socket_checkerr(fd)
2025-01-21 10:51:52.151 25 ERROR cinder.volume.drivers.lightos   File "/var/lib/kolla/venv/lib/python3.10/site-packages/eventlet/greenio/base.py", line 50, in socket_checkerr
2025-01-21 10:51:52.151 25 ERROR cinder.volume.drivers.lightos     raise OSError(err, errno.errorcode[err])
2025-01-21 10:51:52.151 25 ERROR cinder.volume.drivers.lightos ConnectionRefusedError: [Errno 111] ECONNREFUSED
2025-01-21 10:51:52.151 25 ERROR cinder.volume.drivers.lightos 
2025-01-21 10:51:52.151 25 ERROR cinder.volume.drivers.lightos During handling of the above exception, another exception occurred:
2025-01-21 10:51:52.151 25 ERROR cinder.volume.drivers.lightos 
2025-01-21 10:51:52.151 25 ERROR cinder.volume.drivers.lightos Traceback (most recent call last):
2025-01-21 10:51:52.151 25 ERROR cinder.volume.drivers.lightos   File "/var/lib/kolla/venv/lib/python3.10/site-packages/urllib3/connectionpool.py", line 715, in urlopen
2025-01-21 10:51:52.151 25 ERROR cinder.volume.drivers.lightos     httplib_response = self._make_request(
2025-01-21 10:51:52.151 25 ERROR cinder.volume.drivers.lightos   File "/var/lib/kolla/venv/lib/python3.10/site-packages/urllib3/connectionpool.py", line 404, in _make_request
2025-01-21 10:51:52.151 25 ERROR cinder.volume.drivers.lightos     self._validate_conn(conn)
2025-01-21 10:51:52.151 25 ERROR cinder.volume.drivers.lightos   File "/var/lib/kolla/venv/lib/python3.10/site-packages/urllib3/connectionpool.py", line 1060, in _validate_conn
2025-01-21 10:51:52.151 25 ERROR cinder.volume.drivers.lightos     conn.connect()
2025-01-21 10:51:52.151 25 ERROR cinder.volume.drivers.lightos   File "/var/lib/kolla/venv/lib/python3.10/site-packages/urllib3/connection.py", line 363, in connect
2025-01-21 10:51:52.151 25 ERROR cinder.volume.drivers.lightos     self.sock = conn = self._new_conn()
2025-01-21 10:51:52.151 25 ERROR cinder.volume.drivers.lightos   File "/var/lib/kolla/venv/lib/python3.10/site-packages/urllib3/connection.py", line 186, in _new_conn
2025-01-21 10:51:52.151 25 ERROR cinder.volume.drivers.lightos     raise NewConnectionError(
2025-01-21 10:51:52.151 25 ERROR cinder.volume.drivers.lightos urllib3.exceptions.NewConnectionError: <urllib3.connection.HTTPSConnection object at 0x7fb8b0e80610>: Failed to establish a new connection: [Errno 111] ECONNREFUSED
2025-01-21 10:51:52.151 25 ERROR cinder.volume.drivers.lightos 
2025-01-21 10:51:52.151 25 ERROR cinder.volume.drivers.lightos During handling of the above exception, another exception occurred:
2025-01-21 10:51:52.151 25 ERROR cinder.volume.drivers.lightos 
2025-01-21 10:51:52.151 25 ERROR cinder.volume.drivers.lightos Traceback (most recent call last):
2025-01-21 10:51:52.151 25 ERROR cinder.volume.drivers.lightos   File "/var/lib/kolla/venv/lib/python3.10/site-packages/requests/adapters.py", line 667, in send
2025-01-21 10:51:52.151 25 ERROR cinder.volume.drivers.lightos     resp = conn.urlopen(
2025-01-21 10:51:52.151 25 ERROR cinder.volume.drivers.lightos   File "/var/lib/kolla/venv/lib/python3.10/site-packages/urllib3/connectionpool.py", line 801, in urlopen
2025-01-21 10:51:52.151 25 ERROR cinder.volume.drivers.lightos     retries = retries.increment(
2025-01-21 10:51:52.151 25 ERROR cinder.volume.drivers.lightos   File "/var/lib/kolla/venv/lib/python3.10/site-packages/urllib3/util/retry.py", line 594, in increment
2025-01-21 10:51:52.151 25 ERROR cinder.volume.drivers.lightos     raise MaxRetryError(_pool, url, error or ResponseError(cause))
2025-01-21 10:51:52.151 25 ERROR cinder.volume.drivers.lightos urllib3.exceptions.MaxRetryError: HTTPSConnectionPool(host='[LB_IP_ADDRESS]', port=443): Max retries exceeded with url: /api/v2/clusterinfo (Caused by NewConnectionError('<urllib3.connection.HTTPSConnection object at 0x7fb8b0e80610>: Failed to establish a new connection: [Errno 111] ECONNREFUSED'))
2025-01-21 10:51:52.151 25 ERROR cinder.volume.drivers.lightos 
2025-01-21 10:51:52.151 25 ERROR cinder.volume.drivers.lightos During handling of the above exception, another exception occurred:
2025-01-21 10:51:52.151 25 ERROR cinder.volume.drivers.lightos 
2025-01-21 10:51:52.151 25 ERROR cinder.volume.drivers.lightos Traceback (most recent call last):
2025-01-21 10:51:52.151 25 ERROR cinder.volume.drivers.lightos   File "/var/lib/kolla/venv/lib/python3.10/site-packages/cinder/volume/drivers/lightos.py", line 356, in __send_cmd
2025-01-21 10:51:52.151 25 ERROR cinder.volume.drivers.lightos     response = session.send(
2025-01-21 10:51:52.151 25 ERROR cinder.volume.drivers.lightos   File "/var/lib/kolla/venv/lib/python3.10/site-packages/requests/sessions.py", line 703, in send
2025-01-21 10:51:52.151 25 ERROR cinder.volume.drivers.lightos     r = adapter.send(request, **kwargs)
2025-01-21 10:51:52.151 25 ERROR cinder.volume.drivers.lightos   File "/var/lib/kolla/venv/lib/python3.10/site-packages/requests/adapters.py", line 700, in send
2025-01-21 10:51:52.151 25 ERROR cinder.volume.drivers.lightos     raise ConnectionError(e, request=request)
2025-01-21 10:51:52.151 25 ERROR cinder.volume.drivers.lightos requests.exceptions.ConnectionError: HTTPSConnectionPool(host='[LB_IP_ADDRESS]', port=443): Max retries exceeded with url: /api/v2/clusterinfo (Caused by NewConnectionError('<urllib3.connection.HTTPSConnection object at 0x7fb8b0e80610>: Failed to establish a new connection: [Errno 111] ECONNREFUSED'))
2025-01-21 10:51:52.151 25 ERROR cinder.volume.drivers.lightos 
2025-01-21 10:51:52.153 25 INFO cinder.volume.drivers.lightos [None req-f5027d6f-3333-4cae-a38a-8718ac0670b1 - - - - - -] Invoking get_cluster_info using GET url: /api/v2/clusterinfo             request.body: {} ssl_verify: False
2025-01-21 10:51:55.233 25 ERROR cinder.volume.drivers.lightos [None req-f5027d6f-3333-4cae-a38a-8718ac0670b1 - - - - - -] REST server not responding at 'https://[LB_IP_ADDRESS]:443/api/v2/clusterinfo': requests.exceptions.ConnectionError: HTTPSConnectionPool(host='[LB_IP_ADDRESS]', port=443): Max retries exceeded with url: /api/v2/clusterinfo (Caused by NewConnectionError('<urllib3.connection.HTTPSConnection object at 0x7fb8b0c243a0>: Failed to establish a new connection: [Errno 113] EHOSTUNREACH'))
2025-01-21 10:51:55.233 25 ERROR cinder.volume.drivers.lightos Traceback (most recent call last):
2025-01-21 10:51:55.233 25 ERROR cinder.volume.drivers.lightos   File "/var/lib/kolla/venv/lib/python3.10/site-packages/urllib3/connection.py", line 174, in _new_conn
2025-01-21 10:51:55.233 25 ERROR cinder.volume.drivers.lightos     conn = connection.create_connection(
2025-01-21 10:51:55.233 25 ERROR cinder.volume.drivers.lightos   File "/var/lib/kolla/venv/lib/python3.10/site-packages/urllib3/util/connection.py", line 95, in create_connection
2025-01-21 10:51:55.233 25 ERROR cinder.volume.drivers.lightos     raise err
2025-01-21 10:51:55.233 25 ERROR cinder.volume.drivers.lightos   File "/var/lib/kolla/venv/lib/python3.10/site-packages/urllib3/util/connection.py", line 85, in create_connection
2025-01-21 10:51:55.233 25 ERROR cinder.volume.drivers.lightos     sock.connect(sa)
2025-01-21 10:51:55.233 25 ERROR cinder.volume.drivers.lightos   File "/var/lib/kolla/venv/lib/python3.10/site-packages/eventlet/greenio/base.py", line 265, in connect
2025-01-21 10:51:55.233 25 ERROR cinder.volume.drivers.lightos     socket_checkerr(fd)
2025-01-21 10:51:55.233 25 ERROR cinder.volume.drivers.lightos   File "/var/lib/kolla/venv/lib/python3.10/site-packages/eventlet/greenio/base.py", line 50, in socket_checkerr
2025-01-21 10:51:55.233 25 ERROR cinder.volume.drivers.lightos     raise OSError(err, errno.errorcode[err])
2025-01-21 10:51:55.233 25 ERROR cinder.volume.drivers.lightos OSError: [Errno 113] EHOSTUNREACH
2025-01-21 10:51:55.233 25 ERROR cinder.volume.drivers.lightos 
2025-01-21 10:51:55.233 25 ERROR cinder.volume.drivers.lightos During handling of the above exception, another exception occurred:
2025-01-21 10:51:55.233 25 ERROR cinder.volume.drivers.lightos 
2025-01-21 10:51:55.233 25 ERROR cinder.volume.drivers.lightos Traceback (most recent call last):
2025-01-21 10:51:55.233 25 ERROR cinder.volume.drivers.lightos   File "/var/lib/kolla/venv/lib/python3.10/site-packages/urllib3/connectionpool.py", line 715, in urlopen
2025-01-21 10:51:55.233 25 ERROR cinder.volume.drivers.lightos     httplib_response = self._make_request(
2025-01-21 10:51:55.233 25 ERROR cinder.volume.drivers.lightos   File "/var/lib/kolla/venv/lib/python3.10/site-packages/urllib3/connectionpool.py", line 404, in _make_request
2025-01-21 10:51:55.233 25 ERROR cinder.volume.drivers.lightos     self._validate_conn(conn)
2025-01-21 10:51:55.233 25 ERROR cinder.volume.drivers.lightos   File "/var/lib/kolla/venv/lib/python3.10/site-packages/urllib3/connectionpool.py", line 1060, in _validate_conn
2025-01-21 10:51:55.233 25 ERROR cinder.volume.drivers.lightos     conn.connect()
2025-01-21 10:51:55.233 25 ERROR cinder.volume.drivers.lightos   File "/var/lib/kolla/venv/lib/python3.10/site-packages/urllib3/connection.py", line 363, in connect
2025-01-21 10:51:55.233 25 ERROR cinder.volume.drivers.lightos     self.sock = conn = self._new_conn()
2025-01-21 10:51:55.233 25 ERROR cinder.volume.drivers.lightos   File "/var/lib/kolla/venv/lib/python3.10/site-packages/urllib3/connection.py", line 186, in _new_conn
2025-01-21 10:51:55.233 25 ERROR cinder.volume.drivers.lightos     raise NewConnectionError(
2025-01-21 10:51:55.233 25 ERROR cinder.volume.drivers.lightos urllib3.exceptions.NewConnectionError: <urllib3.connection.HTTPSConnection object at 0x7fb8b0c243a0>: Failed to establish a new connection: [Errno 113] EHOSTUNREACH
2025-01-21 10:51:55.233 25 ERROR cinder.volume.drivers.lightos 
2025-01-21 10:51:55.233 25 ERROR cinder.volume.drivers.lightos During handling of the above exception, another exception occurred:
2025-01-21 10:51:55.233 25 ERROR cinder.volume.drivers.lightos 
2025-01-21 10:51:55.233 25 ERROR cinder.volume.drivers.lightos Traceback (most recent call last):
2025-01-21 10:51:55.233 25 ERROR cinder.volume.drivers.lightos   File "/var/lib/kolla/venv/lib/python3.10/site-packages/requests/adapters.py", line 667, in send
2025-01-21 10:51:55.233 25 ERROR cinder.volume.drivers.lightos     resp = conn.urlopen(
2025-01-21 10:51:55.233 25 ERROR cinder.volume.drivers.lightos   File "/var/lib/kolla/venv/lib/python3.10/site-packages/urllib3/connectionpool.py", line 801, in urlopen
2025-01-21 10:51:55.233 25 ERROR cinder.volume.drivers.lightos     retries = retries.increment(
2025-01-21 10:51:55.233 25 ERROR cinder.volume.drivers.lightos   File "/var/lib/kolla/venv/lib/python3.10/site-packages/urllib3/util/retry.py", line 594, in increment
2025-01-21 10:51:55.233 25 ERROR cinder.volume.drivers.lightos     raise MaxRetryError(_pool, url, error or ResponseError(cause))
2025-01-21 10:51:55.233 25 ERROR cinder.volume.drivers.lightos urllib3.exceptions.MaxRetryError: HTTPSConnectionPool(host='[LB_IP_ADDRESS]', port=443): Max retries exceeded with url: /api/v2/clusterinfo (Caused by NewConnectionError('<urllib3.connection.HTTPSConnection object at 0x7fb8b0c243a0>: Failed to establish a new connection: [Errno 113] EHOSTUNREACH'))
2025-01-21 10:51:55.233 25 ERROR cinder.volume.drivers.lightos 
2025-01-21 10:51:55.233 25 ERROR cinder.volume.drivers.lightos During handling of the above exception, another exception occurred:
2025-01-21 10:51:55.233 25 ERROR cinder.volume.drivers.lightos 
2025-01-21 10:51:55.233 25 ERROR cinder.volume.drivers.lightos Traceback (most recent call last):
2025-01-21 10:51:55.233 25 ERROR cinder.volume.drivers.lightos   File "/var/lib/kolla/venv/lib/python3.10/site-packages/cinder/volume/drivers/lightos.py", line 356, in __send_cmd
2025-01-21 10:51:55.233 25 ERROR cinder.volume.drivers.lightos     response = session.send(
2025-01-21 10:51:55.233 25 ERROR cinder.volume.drivers.lightos   File "/var/lib/kolla/venv/lib/python3.10/site-packages/requests/sessions.py", line 703, in send
2025-01-21 10:51:55.233 25 ERROR cinder.volume.drivers.lightos     r = adapter.send(request, **kwargs)
2025-01-21 10:51:55.233 25 ERROR cinder.volume.drivers.lightos   File "/var/lib/kolla/venv/lib/python3.10/site-packages/requests/adapters.py", line 700, in send
2025-01-21 10:51:55.233 25 ERROR cinder.volume.drivers.lightos     raise ConnectionError(e, request=request)
2025-01-21 10:51:55.233 25 ERROR cinder.volume.drivers.lightos requests.exceptions.ConnectionError: HTTPSConnectionPool(host='[LB_IP_ADDRESS]', port=443): Max retries exceeded with url: /api/v2/clusterinfo (Caused by NewConnectionError('<urllib3.connection.HTTPSConnection object at 0x7fb8b0c243a0>: Failed to establish a new connection: [Errno 113] EHOSTUNREACH'))
2025-01-21 10:51:55.233 25 ERROR cinder.volume.drivers.lightos 
2025-01-21 10:51:55.236 25 ERROR cinder.volume.manager [None req-f5027d6f-3333-4cae-a38a-8718ac0670b1 - - - - - -] Failed to initialize driver.: cinder.exception.VolumeDriverException: Volume driver reported an error: Could not get a response from any API server
2025-01-21 10:51:55.236 25 ERROR cinder.volume.manager Traceback (most recent call last):
2025-01-21 10:51:55.236 25 ERROR cinder.volume.manager   File "/var/lib/kolla/venv/lib/python3.10/site-packages/cinder/volume/manager.py", line 523, in _init_host
2025-01-21 10:51:55.236 25 ERROR cinder.volume.manager     self.driver.do_setup(ctxt)
2025-01-21 10:51:55.236 25 ERROR cinder.volume.manager   File "/var/lib/kolla/venv/lib/python3.10/site-packages/cinder/volume/drivers/lightos.py", line 922, in do_setup
2025-01-21 10:51:55.236 25 ERROR cinder.volume.manager     self.get_cluster_info()
2025-01-21 10:51:55.236 25 ERROR cinder.volume.manager   File "/var/lib/kolla/venv/lib/python3.10/site-packages/cinder/volume/drivers/lightos.py", line 873, in get_cluster_info
2025-01-21 10:51:55.236 25 ERROR cinder.volume.manager     status_code, cluster_info = self.cluster.send_cmd(
2025-01-21 10:51:55.236 25 ERROR cinder.volume.manager   File "/var/lib/kolla/venv/lib/python3.10/site-packages/cinder/volume/drivers/lightos.py", line 315, in send_cmd
2025-01-21 10:51:55.236 25 ERROR cinder.volume.manager     raise exception.VolumeDriverException(
2025-01-21 10:51:55.236 25 ERROR cinder.volume.manager cinder.exception.VolumeDriverException: Volume driver reported an error: Could not get a response from any API server
2025-01-21 10:51:55.236 25 ERROR cinder.volume.manager 
2025-01-21 10:51:55.258 25 WARNING oslo_config.cfg [None req-f5027d6f-3333-4cae-a38a-8718ac0670b1 - - - - - -] Deprecated: Option "heartbeat_in_pthread" from group "oslo_messaging_rabbit" is deprecated for removal (The option is related to Eventlet which will be removed. In addition this has never worked as expected with services using eventlet for core service framework.).  Its value may be silently ignored in the future.
2025-01-21 10:51:55.300 25 INFO cinder.service [None req-f5027d6f-3333-4cae-a38a-8718ac0670b1 - - - - - -] Starting cinder-volume cluster lightos_cinder_cluster@LIGHTOSyilgqu (version 25.1.0)
2025-01-21 10:51:55.318 25 INFO cinder.volume.manager [None req-f5027d6f-3333-4cae-a38a-8718ac0670b1 - - - - - -] Initializing RPC dependent components of volume driver LightOSVolumeDriver (2.3.12)
2025-01-21 10:51:55.318 25 ERROR cinder.volume.volume_utils [None req-f5027d6f-3333-4cae-a38a-8718ac0670b1 - - - - - -] Volume driver LightOSVolumeDriver not initialized
2025-01-21 10:51:55.319 25 ERROR cinder.volume.manager [None req-f5027d6f-3333-4cae-a38a-8718ac0670b1 - - - - - -] Cannot complete RPC initialization because driver isn't initialized properly.: cinder.exception.DriverNotInitialized: Volume driver not ready.
2025-01-21 10:52:05.320 25 ERROR cinder.service [-] Manager for service cinder-volume rack13-server67@LIGHTOSyilgqu is reporting problems, not sending heartbeat. Service will appear "down".
2025-01-21 10:52:15.323 25 ERROR cinder.service [-] Manager for service cinder-volume rack13-server67@LIGHTOSyilgqu is reporting problems, not sending heartbeat. Service will appear "down".
2025-01-21 10:52:25.325 25 ERROR cinder.service [-] Manager for service cinder-volume rack13-server67@LIGHTOSyilgqu is reporting problems, not sending heartbeat. Service will appear "down".
2025-01-21 10:52:35.326 25 ERROR cinder.service [-] Manager for service cinder-volume rack13-server67@LIGHTOSyilgqu is reporting problems, not sending heartbeat. Service will appear "down".
2025-01-21 10:52:45.327 25 ERROR cinder.service [-] Manager for service cinder-volume rack13-server67@LIGHTOSyilgqu is reporting problems, not sending heartbeat. Service will appear "down".
2025-01-21 10:52:55.329 25 ERROR cinder.service [-] Manager for service cinder-volume rack13-server67@LIGHTOSyilgqu is reporting problems, not sending heartbeat. Service will appear "down".
2025-01-21 10:53:05.330 25 ERROR cinder.service [-] Manager for service cinder-volume rack13-server67@LIGHTOSyilgqu is reporting problems, not sending heartbeat. Service will appear "down".
2025-01-21 10:53:15.332 25 ERROR cinder.service [-] Manager for service cinder-volume rack13-server67@LIGHTOSyilgqu is reporting problems, not sending heartbeat. Service will appear "down".
2025-01-21 10:53:25.333 25 ERROR cinder.service [-] Manager for service cinder-volume rack13-server67@LIGHTOSyilgqu is reporting problems, not sending heartbeat. Service will appear "down".
2025-01-21 10:53:31.323 25 WARNING cinder.volume.manager [None req-7b71364b-9c6e-408e-873a-cf73eda357ca - - - - - -] Update driver status failed: (config name LIGHTOSyilgqu) is uninitialized.
2025-01-21 10:53:35.335 25 ERROR cinder.service [-] Manager for service cinder-volume rack13-server67@LIGHTOSyilgqu is reporting problems, not sending heartbeat. Service will appear "down".
2025-01-21 10:53:45.336 25 ERROR cinder.service [-] Manager for service cinder-volume rack13-server67@LIGHTOSyilgqu is reporting problems, not sending heartbeat. Service will appear "down".
2025-01-21 10:53:55.338 25 ERROR cinder.service [-] Manager for service cinder-volume rack13-server67@LIGHTOSyilgqu is reporting problems, not sending heartbeat. Service will appear "down".
2025-01-21 10:54:05.339 25 ERROR cinder.service [-] Manager for service cinder-volume rack13-server67@LIGHTOSyilgqu is reporting problems, not sending heartbeat. Service will appear "down".
2025-01-21 10:54:15.341 25 ERROR cinder.service [-] Manager for service cinder-volume rack13-server67@LIGHTOSyilgqu is reporting problems, not sending heartbeat. Service will appear "down".
2025-01-21 10:54:25.342 25 ERROR cinder.service [-] Manager for service cinder-volume rack13-server67@LIGHTOSyilgqu is reporting problems, not sending heartbeat. Service will appear "down".
2025-01-21 10:54:31.327 25 WARNING cinder.volume.manager [None req-7b71364b-9c6e-408e-873a-cf73eda357ca - - - - - -] Update driver status failed: (config name LIGHTOSyilgqu) is uninitialized.
2025-01-21 10:54:35.344 25 ERROR cinder.service [-] Manager for service cinder-volume rack13-server67@LIGHTOSyilgqu is reporting problems, not sending heartbeat. Service will appear "down".
2025-01-21 10:54:45.346 25 ERROR cinder.service [-] Manager for service cinder-volume rack13-server67@LIGHTOSyilgqu is reporting problems, not sending heartbeat. Service will appear "down".
2025-01-21 10:54:55.347 25 ERROR cinder.service [-] Manager for service cinder-volume rack13-server67@LIGHTOSyilgqu is reporting problems, not sending heartbeat. Service will appear "down".
2025-01-21 10:55:05.349 25 ERROR cinder.service [-] Manager for service cinder-volume rack13-server67@LIGHTOSyilgqu is reporting problems, not sending heartbeat. Service will appear "down".
2025-01-21 10:55:15.351 25 ERROR cinder.service [-] Manager for service cinder-volume rack13-server67@LIGHTOSyilgqu is reporting problems, not sending heartbeat. Service will appear "down".
2025-01-21 10:55:25.352 25 ERROR cinder.service [-] Manager for service cinder-volume rack13-server67@LIGHTOSyilgqu is reporting problems, not sending heartbeat. Service will appear "down".
2025-01-21 10:55:31.330 25 WARNING cinder.volume.manager [None req-7b71364b-9c6e-408e-873a-cf73eda357ca - - - - - -] Update driver status failed: (config name LIGHTOSyilgqu) is uninitialized.
2025-01-21 10:55:35.354 25 ERROR cinder.service [-] Manager for service cinder-volume rack13-server67@LIGHTOSyilgqu is reporting problems, not sending heartbeat. Service will appear "down".
