Build Started 23_01_2025_09_25_25
2025-01-23 09:25:29.802 25 ERROR cinder.service [-] Manager for service cinder-volume rack13-server67@LIGHTOSyilgqu is reporting problems, not sending heartbeat. Service will appear "down".
2025-01-23 09:25:33.259 25 WARNING cinder.volume.manager [None req-f7abf0d1-d8e1-4132-a650-ed8949c4d121 - - - - - -] Update driver status failed: (config name LIGHTOSyilgqu) is uninitialized.
2025-01-23 09:25:36.350 7 INFO oslo_service.service [None req-55d70ca1-2019-4365-8bbf-302c4f18cf4b - - - - - -] Caught SIGTERM, stopping children
2025-01-23 09:25:36.366 7 INFO oslo_service.service [None req-55d70ca1-2019-4365-8bbf-302c4f18cf4b - - - - - -] Waiting on 1 children to exit
2025-01-23 09:25:38.912 25 WARNING amqp [None req-55d70ca1-2019-4365-8bbf-302c4f18cf4b - - - - - -] Received method (60, 30) during closing channel 1. This method will be ignored
2025-01-23 09:25:38.920 25 WARNING amqp [None req-55d70ca1-2019-4365-8bbf-302c4f18cf4b - - - - - -] Received method (60, 30) during closing channel 1. This method will be ignored
2025-01-23 09:25:38.927 25 WARNING amqp [None req-55d70ca1-2019-4365-8bbf-302c4f18cf4b - - - - - -] Received method (60, 30) during closing channel 1. This method will be ignored
2025-01-23 09:25:38.939 7 INFO oslo_service.service [None req-55d70ca1-2019-4365-8bbf-302c4f18cf4b - - - - - -] Child 25 exited with status 0
2025-01-23 09:25:54.599 7 INFO cinder.rpc [None req-865a8f34-f609-43dc-b680-5ad4831094e6 - - - - - -] Automatically selected cinder-scheduler objects version 1.39 as minimum service version.
2025-01-23 09:25:54.604 7 INFO cinder.rpc [None req-865a8f34-f609-43dc-b680-5ad4831094e6 - - - - - -] Automatically selected cinder-scheduler RPC version 3.12 as minimum service version.
2025-01-23 09:25:54.644 7 INFO cinder.volume.manager [None req-865a8f34-f609-43dc-b680-5ad4831094e6 - - - - - -] Determined volume DB was empty at startup.
2025-01-23 09:25:54.662 7 INFO cinder.volume.manager [None req-865a8f34-f609-43dc-b680-5ad4831094e6 - - - - - -] Image-volume cache disabled for host rack13-server67@LIGHTOSyilgqu.
2025-01-23 09:25:54.679 7 INFO oslo_service.service [None req-865a8f34-f609-43dc-b680-5ad4831094e6 - - - - - -] Starting 1 workers
2025-01-23 09:25:54.690 25 INFO cinder.service [-] Starting cinder-volume node (version 25.1.0)
2025-01-23 09:25:54.693 7 WARNING oslo_config.cfg [None req-865a8f34-f609-43dc-b680-5ad4831094e6 - - - - - -] Deprecated: Option "heartbeat_in_pthread" from group "oslo_messaging_rabbit" is deprecated for removal (The option is related to Eventlet which will be removed. In addition this has never worked as expected with services using eventlet for core service framework.).  Its value may be silently ignored in the future.
2025-01-23 09:25:54.708 25 INFO cinder.volume.manager [None req-eeb56e5d-74a3-4b0a-a0b5-8e4e775c8d16 - - - - - -] Starting volume driver LightOSVolumeDriver (2.3.12)
2025-01-23 09:25:54.709 25 INFO cinder.volume.drivers.lightos [None req-eeb56e5d-74a3-4b0a-a0b5-8e4e775c8d16 - - - - - -] Invoking get_cluster_info using GET url: /api/v2/clusterinfo             request.body: {} ssl_verify: False
2025-01-23 09:25:57.762 25 ERROR cinder.volume.drivers.lightos [None req-eeb56e5d-74a3-4b0a-a0b5-8e4e775c8d16 - - - - - -] REST server not responding at 'https://[LB_IP_ADDRESS]:443/api/v2/clusterinfo': requests.exceptions.ConnectionError: HTTPSConnectionPool(host='[LB_IP_ADDRESS]', port=443): Max retries exceeded with url: /api/v2/clusterinfo (Caused by NewConnectionError('<urllib3.connection.HTTPSConnection object at 0x7f8fc7315c60>: Failed to establish a new connection: [Errno 113] EHOSTUNREACH'))
2025-01-23 09:25:57.762 25 ERROR cinder.volume.drivers.lightos Traceback (most recent call last):
2025-01-23 09:25:57.762 25 ERROR cinder.volume.drivers.lightos   File "/var/lib/kolla/venv/lib/python3.10/site-packages/urllib3/connection.py", line 174, in _new_conn
2025-01-23 09:25:57.762 25 ERROR cinder.volume.drivers.lightos     conn = connection.create_connection(
2025-01-23 09:25:57.762 25 ERROR cinder.volume.drivers.lightos   File "/var/lib/kolla/venv/lib/python3.10/site-packages/urllib3/util/connection.py", line 95, in create_connection
2025-01-23 09:25:57.762 25 ERROR cinder.volume.drivers.lightos     raise err
2025-01-23 09:25:57.762 25 ERROR cinder.volume.drivers.lightos   File "/var/lib/kolla/venv/lib/python3.10/site-packages/urllib3/util/connection.py", line 85, in create_connection
2025-01-23 09:25:57.762 25 ERROR cinder.volume.drivers.lightos     sock.connect(sa)
2025-01-23 09:25:57.762 25 ERROR cinder.volume.drivers.lightos   File "/var/lib/kolla/venv/lib/python3.10/site-packages/eventlet/greenio/base.py", line 265, in connect
2025-01-23 09:25:57.762 25 ERROR cinder.volume.drivers.lightos     socket_checkerr(fd)
2025-01-23 09:25:57.762 25 ERROR cinder.volume.drivers.lightos   File "/var/lib/kolla/venv/lib/python3.10/site-packages/eventlet/greenio/base.py", line 50, in socket_checkerr
2025-01-23 09:25:57.762 25 ERROR cinder.volume.drivers.lightos     raise OSError(err, errno.errorcode[err])
2025-01-23 09:25:57.762 25 ERROR cinder.volume.drivers.lightos OSError: [Errno 113] EHOSTUNREACH
2025-01-23 09:25:57.762 25 ERROR cinder.volume.drivers.lightos 
2025-01-23 09:25:57.762 25 ERROR cinder.volume.drivers.lightos During handling of the above exception, another exception occurred:
2025-01-23 09:25:57.762 25 ERROR cinder.volume.drivers.lightos 
2025-01-23 09:25:57.762 25 ERROR cinder.volume.drivers.lightos Traceback (most recent call last):
2025-01-23 09:25:57.762 25 ERROR cinder.volume.drivers.lightos   File "/var/lib/kolla/venv/lib/python3.10/site-packages/urllib3/connectionpool.py", line 715, in urlopen
2025-01-23 09:25:57.762 25 ERROR cinder.volume.drivers.lightos     httplib_response = self._make_request(
2025-01-23 09:25:57.762 25 ERROR cinder.volume.drivers.lightos   File "/var/lib/kolla/venv/lib/python3.10/site-packages/urllib3/connectionpool.py", line 404, in _make_request
2025-01-23 09:25:57.762 25 ERROR cinder.volume.drivers.lightos     self._validate_conn(conn)
2025-01-23 09:25:57.762 25 ERROR cinder.volume.drivers.lightos   File "/var/lib/kolla/venv/lib/python3.10/site-packages/urllib3/connectionpool.py", line 1060, in _validate_conn
2025-01-23 09:25:57.762 25 ERROR cinder.volume.drivers.lightos     conn.connect()
2025-01-23 09:25:57.762 25 ERROR cinder.volume.drivers.lightos   File "/var/lib/kolla/venv/lib/python3.10/site-packages/urllib3/connection.py", line 363, in connect
2025-01-23 09:25:57.762 25 ERROR cinder.volume.drivers.lightos     self.sock = conn = self._new_conn()
2025-01-23 09:25:57.762 25 ERROR cinder.volume.drivers.lightos   File "/var/lib/kolla/venv/lib/python3.10/site-packages/urllib3/connection.py", line 186, in _new_conn
2025-01-23 09:25:57.762 25 ERROR cinder.volume.drivers.lightos     raise NewConnectionError(
2025-01-23 09:25:57.762 25 ERROR cinder.volume.drivers.lightos urllib3.exceptions.NewConnectionError: <urllib3.connection.HTTPSConnection object at 0x7f8fc7315c60>: Failed to establish a new connection: [Errno 113] EHOSTUNREACH
2025-01-23 09:25:57.762 25 ERROR cinder.volume.drivers.lightos 
2025-01-23 09:25:57.762 25 ERROR cinder.volume.drivers.lightos During handling of the above exception, another exception occurred:
2025-01-23 09:25:57.762 25 ERROR cinder.volume.drivers.lightos 
2025-01-23 09:25:57.762 25 ERROR cinder.volume.drivers.lightos Traceback (most recent call last):
2025-01-23 09:25:57.762 25 ERROR cinder.volume.drivers.lightos   File "/var/lib/kolla/venv/lib/python3.10/site-packages/requests/adapters.py", line 667, in send
2025-01-23 09:25:57.762 25 ERROR cinder.volume.drivers.lightos     resp = conn.urlopen(
2025-01-23 09:25:57.762 25 ERROR cinder.volume.drivers.lightos   File "/var/lib/kolla/venv/lib/python3.10/site-packages/urllib3/connectionpool.py", line 801, in urlopen
2025-01-23 09:25:57.762 25 ERROR cinder.volume.drivers.lightos     retries = retries.increment(
2025-01-23 09:25:57.762 25 ERROR cinder.volume.drivers.lightos   File "/var/lib/kolla/venv/lib/python3.10/site-packages/urllib3/util/retry.py", line 594, in increment
2025-01-23 09:25:57.762 25 ERROR cinder.volume.drivers.lightos     raise MaxRetryError(_pool, url, error or ResponseError(cause))
2025-01-23 09:25:57.762 25 ERROR cinder.volume.drivers.lightos urllib3.exceptions.MaxRetryError: HTTPSConnectionPool(host='[LB_IP_ADDRESS]', port=443): Max retries exceeded with url: /api/v2/clusterinfo (Caused by NewConnectionError('<urllib3.connection.HTTPSConnection object at 0x7f8fc7315c60>: Failed to establish a new connection: [Errno 113] EHOSTUNREACH'))
2025-01-23 09:25:57.762 25 ERROR cinder.volume.drivers.lightos 
2025-01-23 09:25:57.762 25 ERROR cinder.volume.drivers.lightos During handling of the above exception, another exception occurred:
2025-01-23 09:25:57.762 25 ERROR cinder.volume.drivers.lightos 
2025-01-23 09:25:57.762 25 ERROR cinder.volume.drivers.lightos Traceback (most recent call last):
2025-01-23 09:25:57.762 25 ERROR cinder.volume.drivers.lightos   File "/var/lib/kolla/venv/lib/python3.10/site-packages/cinder/volume/drivers/lightos.py", line 356, in __send_cmd
2025-01-23 09:25:57.762 25 ERROR cinder.volume.drivers.lightos     response = session.send(
2025-01-23 09:25:57.762 25 ERROR cinder.volume.drivers.lightos   File "/var/lib/kolla/venv/lib/python3.10/site-packages/requests/sessions.py", line 703, in send
2025-01-23 09:25:57.762 25 ERROR cinder.volume.drivers.lightos     r = adapter.send(request, **kwargs)
2025-01-23 09:25:57.762 25 ERROR cinder.volume.drivers.lightos   File "/var/lib/kolla/venv/lib/python3.10/site-packages/requests/adapters.py", line 700, in send
2025-01-23 09:25:57.762 25 ERROR cinder.volume.drivers.lightos     raise ConnectionError(e, request=request)
2025-01-23 09:25:57.762 25 ERROR cinder.volume.drivers.lightos requests.exceptions.ConnectionError: HTTPSConnectionPool(host='[LB_IP_ADDRESS]', port=443): Max retries exceeded with url: /api/v2/clusterinfo (Caused by NewConnectionError('<urllib3.connection.HTTPSConnection object at 0x7f8fc7315c60>: Failed to establish a new connection: [Errno 113] EHOSTUNREACH'))
2025-01-23 09:25:57.762 25 ERROR cinder.volume.drivers.lightos 
2025-01-23 09:25:57.768 25 INFO cinder.volume.drivers.lightos [None req-eeb56e5d-74a3-4b0a-a0b5-8e4e775c8d16 - - - - - -] Invoking get_cluster_info using GET url: /api/v2/clusterinfo             request.body: {} ssl_verify: False
2025-01-23 09:25:57.772 25 ERROR cinder.volume.drivers.lightos [None req-eeb56e5d-74a3-4b0a-a0b5-8e4e775c8d16 - - - - - -] REST server not responding at 'https://[LB_IP_ADDRESS]:443/api/v2/clusterinfo': requests.exceptions.ConnectionError: HTTPSConnectionPool(host='[LB_IP_ADDRESS]', port=443): Max retries exceeded with url: /api/v2/clusterinfo (Caused by NewConnectionError('<urllib3.connection.HTTPSConnection object at 0x7f8fc7314fa0>: Failed to establish a new connection: [Errno 111] ECONNREFUSED'))
2025-01-23 09:25:57.772 25 ERROR cinder.volume.drivers.lightos Traceback (most recent call last):
2025-01-23 09:25:57.772 25 ERROR cinder.volume.drivers.lightos   File "/var/lib/kolla/venv/lib/python3.10/site-packages/urllib3/connection.py", line 174, in _new_conn
2025-01-23 09:25:57.772 25 ERROR cinder.volume.drivers.lightos     conn = connection.create_connection(
2025-01-23 09:25:57.772 25 ERROR cinder.volume.drivers.lightos   File "/var/lib/kolla/venv/lib/python3.10/site-packages/urllib3/util/connection.py", line 95, in create_connection
2025-01-23 09:25:57.772 25 ERROR cinder.volume.drivers.lightos     raise err
2025-01-23 09:25:57.772 25 ERROR cinder.volume.drivers.lightos   File "/var/lib/kolla/venv/lib/python3.10/site-packages/urllib3/util/connection.py", line 85, in create_connection
2025-01-23 09:25:57.772 25 ERROR cinder.volume.drivers.lightos     sock.connect(sa)
2025-01-23 09:25:57.772 25 ERROR cinder.volume.drivers.lightos   File "/var/lib/kolla/venv/lib/python3.10/site-packages/eventlet/greenio/base.py", line 265, in connect
2025-01-23 09:25:57.772 25 ERROR cinder.volume.drivers.lightos     socket_checkerr(fd)
2025-01-23 09:25:57.772 25 ERROR cinder.volume.drivers.lightos   File "/var/lib/kolla/venv/lib/python3.10/site-packages/eventlet/greenio/base.py", line 50, in socket_checkerr
2025-01-23 09:25:57.772 25 ERROR cinder.volume.drivers.lightos     raise OSError(err, errno.errorcode[err])
2025-01-23 09:25:57.772 25 ERROR cinder.volume.drivers.lightos ConnectionRefusedError: [Errno 111] ECONNREFUSED
2025-01-23 09:25:57.772 25 ERROR cinder.volume.drivers.lightos 
2025-01-23 09:25:57.772 25 ERROR cinder.volume.drivers.lightos During handling of the above exception, another exception occurred:
2025-01-23 09:25:57.772 25 ERROR cinder.volume.drivers.lightos 
2025-01-23 09:25:57.772 25 ERROR cinder.volume.drivers.lightos Traceback (most recent call last):
2025-01-23 09:25:57.772 25 ERROR cinder.volume.drivers.lightos   File "/var/lib/kolla/venv/lib/python3.10/site-packages/urllib3/connectionpool.py", line 715, in urlopen
2025-01-23 09:25:57.772 25 ERROR cinder.volume.drivers.lightos     httplib_response = self._make_request(
2025-01-23 09:25:57.772 25 ERROR cinder.volume.drivers.lightos   File "/var/lib/kolla/venv/lib/python3.10/site-packages/urllib3/connectionpool.py", line 404, in _make_request
2025-01-23 09:25:57.772 25 ERROR cinder.volume.drivers.lightos     self._validate_conn(conn)
2025-01-23 09:25:57.772 25 ERROR cinder.volume.drivers.lightos   File "/var/lib/kolla/venv/lib/python3.10/site-packages/urllib3/connectionpool.py", line 1060, in _validate_conn
2025-01-23 09:25:57.772 25 ERROR cinder.volume.drivers.lightos     conn.connect()
2025-01-23 09:25:57.772 25 ERROR cinder.volume.drivers.lightos   File "/var/lib/kolla/venv/lib/python3.10/site-packages/urllib3/connection.py", line 363, in connect
2025-01-23 09:25:57.772 25 ERROR cinder.volume.drivers.lightos     self.sock = conn = self._new_conn()
2025-01-23 09:25:57.772 25 ERROR cinder.volume.drivers.lightos   File "/var/lib/kolla/venv/lib/python3.10/site-packages/urllib3/connection.py", line 186, in _new_conn
2025-01-23 09:25:57.772 25 ERROR cinder.volume.drivers.lightos     raise NewConnectionError(
2025-01-23 09:25:57.772 25 ERROR cinder.volume.drivers.lightos urllib3.exceptions.NewConnectionError: <urllib3.connection.HTTPSConnection object at 0x7f8fc7314fa0>: Failed to establish a new connection: [Errno 111] ECONNREFUSED
2025-01-23 09:25:57.772 25 ERROR cinder.volume.drivers.lightos 
2025-01-23 09:25:57.772 25 ERROR cinder.volume.drivers.lightos During handling of the above exception, another exception occurred:
2025-01-23 09:25:57.772 25 ERROR cinder.volume.drivers.lightos 
2025-01-23 09:25:57.772 25 ERROR cinder.volume.drivers.lightos Traceback (most recent call last):
2025-01-23 09:25:57.772 25 ERROR cinder.volume.drivers.lightos   File "/var/lib/kolla/venv/lib/python3.10/site-packages/requests/adapters.py", line 667, in send
2025-01-23 09:25:57.772 25 ERROR cinder.volume.drivers.lightos     resp = conn.urlopen(
2025-01-23 09:25:57.772 25 ERROR cinder.volume.drivers.lightos   File "/var/lib/kolla/venv/lib/python3.10/site-packages/urllib3/connectionpool.py", line 801, in urlopen
2025-01-23 09:25:57.772 25 ERROR cinder.volume.drivers.lightos     retries = retries.increment(
2025-01-23 09:25:57.772 25 ERROR cinder.volume.drivers.lightos   File "/var/lib/kolla/venv/lib/python3.10/site-packages/urllib3/util/retry.py", line 594, in increment
2025-01-23 09:25:57.772 25 ERROR cinder.volume.drivers.lightos     raise MaxRetryError(_pool, url, error or ResponseError(cause))
2025-01-23 09:25:57.772 25 ERROR cinder.volume.drivers.lightos urllib3.exceptions.MaxRetryError: HTTPSConnectionPool(host='[LB_IP_ADDRESS]', port=443): Max retries exceeded with url: /api/v2/clusterinfo (Caused by NewConnectionError('<urllib3.connection.HTTPSConnection object at 0x7f8fc7314fa0>: Failed to establish a new connection: [Errno 111] ECONNREFUSED'))
2025-01-23 09:25:57.772 25 ERROR cinder.volume.drivers.lightos 
2025-01-23 09:25:57.772 25 ERROR cinder.volume.drivers.lightos During handling of the above exception, another exception occurred:
2025-01-23 09:25:57.772 25 ERROR cinder.volume.drivers.lightos 
2025-01-23 09:25:57.772 25 ERROR cinder.volume.drivers.lightos Traceback (most recent call last):
2025-01-23 09:25:57.772 25 ERROR cinder.volume.drivers.lightos   File "/var/lib/kolla/venv/lib/python3.10/site-packages/cinder/volume/drivers/lightos.py", line 356, in __send_cmd
2025-01-23 09:25:57.772 25 ERROR cinder.volume.drivers.lightos     response = session.send(
2025-01-23 09:25:57.772 25 ERROR cinder.volume.drivers.lightos   File "/var/lib/kolla/venv/lib/python3.10/site-packages/requests/sessions.py", line 703, in send
2025-01-23 09:25:57.772 25 ERROR cinder.volume.drivers.lightos     r = adapter.send(request, **kwargs)
2025-01-23 09:25:57.772 25 ERROR cinder.volume.drivers.lightos   File "/var/lib/kolla/venv/lib/python3.10/site-packages/requests/adapters.py", line 700, in send
2025-01-23 09:25:57.772 25 ERROR cinder.volume.drivers.lightos     raise ConnectionError(e, request=request)
2025-01-23 09:25:57.772 25 ERROR cinder.volume.drivers.lightos requests.exceptions.ConnectionError: HTTPSConnectionPool(host='[LB_IP_ADDRESS]', port=443): Max retries exceeded with url: /api/v2/clusterinfo (Caused by NewConnectionError('<urllib3.connection.HTTPSConnection object at 0x7f8fc7314fa0>: Failed to establish a new connection: [Errno 111] ECONNREFUSED'))
2025-01-23 09:25:57.772 25 ERROR cinder.volume.drivers.lightos 
2025-01-23 09:25:57.774 25 INFO cinder.volume.drivers.lightos [None req-eeb56e5d-74a3-4b0a-a0b5-8e4e775c8d16 - - - - - -] Invoking get_cluster_info using GET url: /api/v2/clusterinfo             request.body: {} ssl_verify: False
2025-01-23 09:25:57.776 25 ERROR cinder.volume.drivers.lightos [None req-eeb56e5d-74a3-4b0a-a0b5-8e4e775c8d16 - - - - - -] REST server not responding at 'https://[LB_IP_ADDRESS]:443/api/v2/clusterinfo': requests.exceptions.ConnectionError: HTTPSConnectionPool(host='[LB_IP_ADDRESS]', port=443): Max retries exceeded with url: /api/v2/clusterinfo (Caused by NewConnectionError('<urllib3.connection.HTTPSConnection object at 0x7f8fc73144c0>: Failed to establish a new connection: [Errno 111] ECONNREFUSED'))
2025-01-23 09:25:57.776 25 ERROR cinder.volume.drivers.lightos Traceback (most recent call last):
2025-01-23 09:25:57.776 25 ERROR cinder.volume.drivers.lightos   File "/var/lib/kolla/venv/lib/python3.10/site-packages/urllib3/connection.py", line 174, in _new_conn
2025-01-23 09:25:57.776 25 ERROR cinder.volume.drivers.lightos     conn = connection.create_connection(
2025-01-23 09:25:57.776 25 ERROR cinder.volume.drivers.lightos   File "/var/lib/kolla/venv/lib/python3.10/site-packages/urllib3/util/connection.py", line 95, in create_connection
2025-01-23 09:25:57.776 25 ERROR cinder.volume.drivers.lightos     raise err
2025-01-23 09:25:57.776 25 ERROR cinder.volume.drivers.lightos   File "/var/lib/kolla/venv/lib/python3.10/site-packages/urllib3/util/connection.py", line 85, in create_connection
2025-01-23 09:25:57.776 25 ERROR cinder.volume.drivers.lightos     sock.connect(sa)
2025-01-23 09:25:57.776 25 ERROR cinder.volume.drivers.lightos   File "/var/lib/kolla/venv/lib/python3.10/site-packages/eventlet/greenio/base.py", line 265, in connect
2025-01-23 09:25:57.776 25 ERROR cinder.volume.drivers.lightos     socket_checkerr(fd)
2025-01-23 09:25:57.776 25 ERROR cinder.volume.drivers.lightos   File "/var/lib/kolla/venv/lib/python3.10/site-packages/eventlet/greenio/base.py", line 50, in socket_checkerr
2025-01-23 09:25:57.776 25 ERROR cinder.volume.drivers.lightos     raise OSError(err, errno.errorcode[err])
2025-01-23 09:25:57.776 25 ERROR cinder.volume.drivers.lightos ConnectionRefusedError: [Errno 111] ECONNREFUSED
2025-01-23 09:25:57.776 25 ERROR cinder.volume.drivers.lightos 
2025-01-23 09:25:57.776 25 ERROR cinder.volume.drivers.lightos During handling of the above exception, another exception occurred:
2025-01-23 09:25:57.776 25 ERROR cinder.volume.drivers.lightos 
2025-01-23 09:25:57.776 25 ERROR cinder.volume.drivers.lightos Traceback (most recent call last):
2025-01-23 09:25:57.776 25 ERROR cinder.volume.drivers.lightos   File "/var/lib/kolla/venv/lib/python3.10/site-packages/urllib3/connectionpool.py", line 715, in urlopen
2025-01-23 09:25:57.776 25 ERROR cinder.volume.drivers.lightos     httplib_response = self._make_request(
2025-01-23 09:25:57.776 25 ERROR cinder.volume.drivers.lightos   File "/var/lib/kolla/venv/lib/python3.10/site-packages/urllib3/connectionpool.py", line 404, in _make_request
2025-01-23 09:25:57.776 25 ERROR cinder.volume.drivers.lightos     self._validate_conn(conn)
2025-01-23 09:25:57.776 25 ERROR cinder.volume.drivers.lightos   File "/var/lib/kolla/venv/lib/python3.10/site-packages/urllib3/connectionpool.py", line 1060, in _validate_conn
2025-01-23 09:25:57.776 25 ERROR cinder.volume.drivers.lightos     conn.connect()
2025-01-23 09:25:57.776 25 ERROR cinder.volume.drivers.lightos   File "/var/lib/kolla/venv/lib/python3.10/site-packages/urllib3/connection.py", line 363, in connect
2025-01-23 09:25:57.776 25 ERROR cinder.volume.drivers.lightos     self.sock = conn = self._new_conn()
2025-01-23 09:25:57.776 25 ERROR cinder.volume.drivers.lightos   File "/var/lib/kolla/venv/lib/python3.10/site-packages/urllib3/connection.py", line 186, in _new_conn
2025-01-23 09:25:57.776 25 ERROR cinder.volume.drivers.lightos     raise NewConnectionError(
2025-01-23 09:25:57.776 25 ERROR cinder.volume.drivers.lightos urllib3.exceptions.NewConnectionError: <urllib3.connection.HTTPSConnection object at 0x7f8fc73144c0>: Failed to establish a new connection: [Errno 111] ECONNREFUSED
2025-01-23 09:25:57.776 25 ERROR cinder.volume.drivers.lightos 
2025-01-23 09:25:57.776 25 ERROR cinder.volume.drivers.lightos During handling of the above exception, another exception occurred:
2025-01-23 09:25:57.776 25 ERROR cinder.volume.drivers.lightos 
2025-01-23 09:25:57.776 25 ERROR cinder.volume.drivers.lightos Traceback (most recent call last):
2025-01-23 09:25:57.776 25 ERROR cinder.volume.drivers.lightos   File "/var/lib/kolla/venv/lib/python3.10/site-packages/requests/adapters.py", line 667, in send
2025-01-23 09:25:57.776 25 ERROR cinder.volume.drivers.lightos     resp = conn.urlopen(
2025-01-23 09:25:57.776 25 ERROR cinder.volume.drivers.lightos   File "/var/lib/kolla/venv/lib/python3.10/site-packages/urllib3/connectionpool.py", line 801, in urlopen
2025-01-23 09:25:57.776 25 ERROR cinder.volume.drivers.lightos     retries = retries.increment(
2025-01-23 09:25:57.776 25 ERROR cinder.volume.drivers.lightos   File "/var/lib/kolla/venv/lib/python3.10/site-packages/urllib3/util/retry.py", line 594, in increment
2025-01-23 09:25:57.776 25 ERROR cinder.volume.drivers.lightos     raise MaxRetryError(_pool, url, error or ResponseError(cause))
2025-01-23 09:25:57.776 25 ERROR cinder.volume.drivers.lightos urllib3.exceptions.MaxRetryError: HTTPSConnectionPool(host='[LB_IP_ADDRESS]', port=443): Max retries exceeded with url: /api/v2/clusterinfo (Caused by NewConnectionError('<urllib3.connection.HTTPSConnection object at 0x7f8fc73144c0>: Failed to establish a new connection: [Errno 111] ECONNREFUSED'))
2025-01-23 09:25:57.776 25 ERROR cinder.volume.drivers.lightos 
2025-01-23 09:25:57.776 25 ERROR cinder.volume.drivers.lightos During handling of the above exception, another exception occurred:
2025-01-23 09:25:57.776 25 ERROR cinder.volume.drivers.lightos 
2025-01-23 09:25:57.776 25 ERROR cinder.volume.drivers.lightos Traceback (most recent call last):
2025-01-23 09:25:57.776 25 ERROR cinder.volume.drivers.lightos   File "/var/lib/kolla/venv/lib/python3.10/site-packages/cinder/volume/drivers/lightos.py", line 356, in __send_cmd
2025-01-23 09:25:57.776 25 ERROR cinder.volume.drivers.lightos     response = session.send(
2025-01-23 09:25:57.776 25 ERROR cinder.volume.drivers.lightos   File "/var/lib/kolla/venv/lib/python3.10/site-packages/requests/sessions.py", line 703, in send
2025-01-23 09:25:57.776 25 ERROR cinder.volume.drivers.lightos     r = adapter.send(request, **kwargs)
2025-01-23 09:25:57.776 25 ERROR cinder.volume.drivers.lightos   File "/var/lib/kolla/venv/lib/python3.10/site-packages/requests/adapters.py", line 700, in send
2025-01-23 09:25:57.776 25 ERROR cinder.volume.drivers.lightos     raise ConnectionError(e, request=request)
2025-01-23 09:25:57.776 25 ERROR cinder.volume.drivers.lightos requests.exceptions.ConnectionError: HTTPSConnectionPool(host='[LB_IP_ADDRESS]', port=443): Max retries exceeded with url: /api/v2/clusterinfo (Caused by NewConnectionError('<urllib3.connection.HTTPSConnection object at 0x7f8fc73144c0>: Failed to establish a new connection: [Errno 111] ECONNREFUSED'))
2025-01-23 09:25:57.776 25 ERROR cinder.volume.drivers.lightos 
2025-01-23 09:25:57.777 25 ERROR cinder.volume.manager [None req-eeb56e5d-74a3-4b0a-a0b5-8e4e775c8d16 - - - - - -] Failed to initialize driver.: cinder.exception.VolumeDriverException: Volume driver reported an error: Could not get a response from any API server
2025-01-23 09:25:57.777 25 ERROR cinder.volume.manager Traceback (most recent call last):
2025-01-23 09:25:57.777 25 ERROR cinder.volume.manager   File "/var/lib/kolla/venv/lib/python3.10/site-packages/cinder/volume/manager.py", line 523, in _init_host
2025-01-23 09:25:57.777 25 ERROR cinder.volume.manager     self.driver.do_setup(ctxt)
2025-01-23 09:25:57.777 25 ERROR cinder.volume.manager   File "/var/lib/kolla/venv/lib/python3.10/site-packages/cinder/volume/drivers/lightos.py", line 922, in do_setup
2025-01-23 09:25:57.777 25 ERROR cinder.volume.manager     self.get_cluster_info()
2025-01-23 09:25:57.777 25 ERROR cinder.volume.manager   File "/var/lib/kolla/venv/lib/python3.10/site-packages/cinder/volume/drivers/lightos.py", line 873, in get_cluster_info
2025-01-23 09:25:57.777 25 ERROR cinder.volume.manager     status_code, cluster_info = self.cluster.send_cmd(
2025-01-23 09:25:57.777 25 ERROR cinder.volume.manager   File "/var/lib/kolla/venv/lib/python3.10/site-packages/cinder/volume/drivers/lightos.py", line 315, in send_cmd
2025-01-23 09:25:57.777 25 ERROR cinder.volume.manager     raise exception.VolumeDriverException(
2025-01-23 09:25:57.777 25 ERROR cinder.volume.manager cinder.exception.VolumeDriverException: Volume driver reported an error: Could not get a response from any API server
2025-01-23 09:25:57.777 25 ERROR cinder.volume.manager 
2025-01-23 09:25:58.780 25 INFO cinder.volume.manager [None req-eeb56e5d-74a3-4b0a-a0b5-8e4e775c8d16 - - - - - -] Starting volume driver LightOSVolumeDriver (2.3.12)
2025-01-23 09:25:58.781 25 INFO cinder.volume.drivers.lightos [None req-eeb56e5d-74a3-4b0a-a0b5-8e4e775c8d16 - - - - - -] Invoking get_cluster_info using GET url: /api/v2/clusterinfo             request.body: {} ssl_verify: False
2025-01-23 09:26:00.833 25 ERROR cinder.volume.drivers.lightos [None req-eeb56e5d-74a3-4b0a-a0b5-8e4e775c8d16 - - - - - -] REST server not responding at 'https://[LB_IP_ADDRESS]:443/api/v2/clusterinfo': requests.exceptions.ConnectionError: HTTPSConnectionPool(host='[LB_IP_ADDRESS]', port=443): Max retries exceeded with url: /api/v2/clusterinfo (Caused by NewConnectionError('<urllib3.connection.HTTPSConnection object at 0x7f8fc7314850>: Failed to establish a new connection: [Errno 113] EHOSTUNREACH'))
2025-01-23 09:26:00.833 25 ERROR cinder.volume.drivers.lightos Traceback (most recent call last):
2025-01-23 09:26:00.833 25 ERROR cinder.volume.drivers.lightos   File "/var/lib/kolla/venv/lib/python3.10/site-packages/urllib3/connection.py", line 174, in _new_conn
2025-01-23 09:26:00.833 25 ERROR cinder.volume.drivers.lightos     conn = connection.create_connection(
2025-01-23 09:26:00.833 25 ERROR cinder.volume.drivers.lightos   File "/var/lib/kolla/venv/lib/python3.10/site-packages/urllib3/util/connection.py", line 95, in create_connection
2025-01-23 09:26:00.833 25 ERROR cinder.volume.drivers.lightos     raise err
2025-01-23 09:26:00.833 25 ERROR cinder.volume.drivers.lightos   File "/var/lib/kolla/venv/lib/python3.10/site-packages/urllib3/util/connection.py", line 85, in create_connection
2025-01-23 09:26:00.833 25 ERROR cinder.volume.drivers.lightos     sock.connect(sa)
2025-01-23 09:26:00.833 25 ERROR cinder.volume.drivers.lightos   File "/var/lib/kolla/venv/lib/python3.10/site-packages/eventlet/greenio/base.py", line 265, in connect
2025-01-23 09:26:00.833 25 ERROR cinder.volume.drivers.lightos     socket_checkerr(fd)
2025-01-23 09:26:00.833 25 ERROR cinder.volume.drivers.lightos   File "/var/lib/kolla/venv/lib/python3.10/site-packages/eventlet/greenio/base.py", line 50, in socket_checkerr
2025-01-23 09:26:00.833 25 ERROR cinder.volume.drivers.lightos     raise OSError(err, errno.errorcode[err])
2025-01-23 09:26:00.833 25 ERROR cinder.volume.drivers.lightos OSError: [Errno 113] EHOSTUNREACH
2025-01-23 09:26:00.833 25 ERROR cinder.volume.drivers.lightos 
2025-01-23 09:26:00.833 25 ERROR cinder.volume.drivers.lightos During handling of the above exception, another exception occurred:
2025-01-23 09:26:00.833 25 ERROR cinder.volume.drivers.lightos 
2025-01-23 09:26:00.833 25 ERROR cinder.volume.drivers.lightos Traceback (most recent call last):
2025-01-23 09:26:00.833 25 ERROR cinder.volume.drivers.lightos   File "/var/lib/kolla/venv/lib/python3.10/site-packages/urllib3/connectionpool.py", line 715, in urlopen
2025-01-23 09:26:00.833 25 ERROR cinder.volume.drivers.lightos     httplib_response = self._make_request(
2025-01-23 09:26:00.833 25 ERROR cinder.volume.drivers.lightos   File "/var/lib/kolla/venv/lib/python3.10/site-packages/urllib3/connectionpool.py", line 404, in _make_request
2025-01-23 09:26:00.833 25 ERROR cinder.volume.drivers.lightos     self._validate_conn(conn)
2025-01-23 09:26:00.833 25 ERROR cinder.volume.drivers.lightos   File "/var/lib/kolla/venv/lib/python3.10/site-packages/urllib3/connectionpool.py", line 1060, in _validate_conn
2025-01-23 09:26:00.833 25 ERROR cinder.volume.drivers.lightos     conn.connect()
2025-01-23 09:26:00.833 25 ERROR cinder.volume.drivers.lightos   File "/var/lib/kolla/venv/lib/python3.10/site-packages/urllib3/connection.py", line 363, in connect
2025-01-23 09:26:00.833 25 ERROR cinder.volume.drivers.lightos     self.sock = conn = self._new_conn()
2025-01-23 09:26:00.833 25 ERROR cinder.volume.drivers.lightos   File "/var/lib/kolla/venv/lib/python3.10/site-packages/urllib3/connection.py", line 186, in _new_conn
2025-01-23 09:26:00.833 25 ERROR cinder.volume.drivers.lightos     raise NewConnectionError(
2025-01-23 09:26:00.833 25 ERROR cinder.volume.drivers.lightos urllib3.exceptions.NewConnectionError: <urllib3.connection.HTTPSConnection object at 0x7f8fc7314850>: Failed to establish a new connection: [Errno 113] EHOSTUNREACH
2025-01-23 09:26:00.833 25 ERROR cinder.volume.drivers.lightos 
2025-01-23 09:26:00.833 25 ERROR cinder.volume.drivers.lightos During handling of the above exception, another exception occurred:
2025-01-23 09:26:00.833 25 ERROR cinder.volume.drivers.lightos 
2025-01-23 09:26:00.833 25 ERROR cinder.volume.drivers.lightos Traceback (most recent call last):
2025-01-23 09:26:00.833 25 ERROR cinder.volume.drivers.lightos   File "/var/lib/kolla/venv/lib/python3.10/site-packages/requests/adapters.py", line 667, in send
2025-01-23 09:26:00.833 25 ERROR cinder.volume.drivers.lightos     resp = conn.urlopen(
2025-01-23 09:26:00.833 25 ERROR cinder.volume.drivers.lightos   File "/var/lib/kolla/venv/lib/python3.10/site-packages/urllib3/connectionpool.py", line 801, in urlopen
2025-01-23 09:26:00.833 25 ERROR cinder.volume.drivers.lightos     retries = retries.increment(
2025-01-23 09:26:00.833 25 ERROR cinder.volume.drivers.lightos   File "/var/lib/kolla/venv/lib/python3.10/site-packages/urllib3/util/retry.py", line 594, in increment
2025-01-23 09:26:00.833 25 ERROR cinder.volume.drivers.lightos     raise MaxRetryError(_pool, url, error or ResponseError(cause))
2025-01-23 09:26:00.833 25 ERROR cinder.volume.drivers.lightos urllib3.exceptions.MaxRetryError: HTTPSConnectionPool(host='[LB_IP_ADDRESS]', port=443): Max retries exceeded with url: /api/v2/clusterinfo (Caused by NewConnectionError('<urllib3.connection.HTTPSConnection object at 0x7f8fc7314850>: Failed to establish a new connection: [Errno 113] EHOSTUNREACH'))
2025-01-23 09:26:00.833 25 ERROR cinder.volume.drivers.lightos 
2025-01-23 09:26:00.833 25 ERROR cinder.volume.drivers.lightos During handling of the above exception, another exception occurred:
2025-01-23 09:26:00.833 25 ERROR cinder.volume.drivers.lightos 
2025-01-23 09:26:00.833 25 ERROR cinder.volume.drivers.lightos Traceback (most recent call last):
2025-01-23 09:26:00.833 25 ERROR cinder.volume.drivers.lightos   File "/var/lib/kolla/venv/lib/python3.10/site-packages/cinder/volume/drivers/lightos.py", line 356, in __send_cmd
2025-01-23 09:26:00.833 25 ERROR cinder.volume.drivers.lightos     response = session.send(
2025-01-23 09:26:00.833 25 ERROR cinder.volume.drivers.lightos   File "/var/lib/kolla/venv/lib/python3.10/site-packages/requests/sessions.py", line 703, in send
2025-01-23 09:26:00.833 25 ERROR cinder.volume.drivers.lightos     r = adapter.send(request, **kwargs)
2025-01-23 09:26:00.833 25 ERROR cinder.volume.drivers.lightos   File "/var/lib/kolla/venv/lib/python3.10/site-packages/requests/adapters.py", line 700, in send
2025-01-23 09:26:00.833 25 ERROR cinder.volume.drivers.lightos     raise ConnectionError(e, request=request)
2025-01-23 09:26:00.833 25 ERROR cinder.volume.drivers.lightos requests.exceptions.ConnectionError: HTTPSConnectionPool(host='[LB_IP_ADDRESS]', port=443): Max retries exceeded with url: /api/v2/clusterinfo (Caused by NewConnectionError('<urllib3.connection.HTTPSConnection object at 0x7f8fc7314850>: Failed to establish a new connection: [Errno 113] EHOSTUNREACH'))
2025-01-23 09:26:00.833 25 ERROR cinder.volume.drivers.lightos 
2025-01-23 09:26:00.836 25 INFO cinder.volume.drivers.lightos [None req-eeb56e5d-74a3-4b0a-a0b5-8e4e775c8d16 - - - - - -] Invoking get_cluster_info using GET url: /api/v2/clusterinfo             request.body: {} ssl_verify: False
2025-01-23 09:26:00.843 25 ERROR cinder.volume.drivers.lightos [None req-eeb56e5d-74a3-4b0a-a0b5-8e4e775c8d16 - - - - - -] REST server not responding at 'https://[LB_IP_ADDRESS]:443/api/v2/clusterinfo': requests.exceptions.ConnectionError: HTTPSConnectionPool(host='[LB_IP_ADDRESS]', port=443): Max retries exceeded with url: /api/v2/clusterinfo (Caused by NewConnectionError('<urllib3.connection.HTTPSConnection object at 0x7f8fc73152a0>: Failed to establish a new connection: [Errno 111] ECONNREFUSED'))
2025-01-23 09:26:00.843 25 ERROR cinder.volume.drivers.lightos Traceback (most recent call last):
2025-01-23 09:26:00.843 25 ERROR cinder.volume.drivers.lightos   File "/var/lib/kolla/venv/lib/python3.10/site-packages/urllib3/connection.py", line 174, in _new_conn
2025-01-23 09:26:00.843 25 ERROR cinder.volume.drivers.lightos     conn = connection.create_connection(
2025-01-23 09:26:00.843 25 ERROR cinder.volume.drivers.lightos   File "/var/lib/kolla/venv/lib/python3.10/site-packages/urllib3/util/connection.py", line 95, in create_connection
2025-01-23 09:26:00.843 25 ERROR cinder.volume.drivers.lightos     raise err
2025-01-23 09:26:00.843 25 ERROR cinder.volume.drivers.lightos   File "/var/lib/kolla/venv/lib/python3.10/site-packages/urllib3/util/connection.py", line 85, in create_connection
2025-01-23 09:26:00.843 25 ERROR cinder.volume.drivers.lightos     sock.connect(sa)
2025-01-23 09:26:00.843 25 ERROR cinder.volume.drivers.lightos   File "/var/lib/kolla/venv/lib/python3.10/site-packages/eventlet/greenio/base.py", line 265, in connect
2025-01-23 09:26:00.843 25 ERROR cinder.volume.drivers.lightos     socket_checkerr(fd)
2025-01-23 09:26:00.843 25 ERROR cinder.volume.drivers.lightos   File "/var/lib/kolla/venv/lib/python3.10/site-packages/eventlet/greenio/base.py", line 50, in socket_checkerr
2025-01-23 09:26:00.843 25 ERROR cinder.volume.drivers.lightos     raise OSError(err, errno.errorcode[err])
2025-01-23 09:26:00.843 25 ERROR cinder.volume.drivers.lightos ConnectionRefusedError: [Errno 111] ECONNREFUSED
2025-01-23 09:26:00.843 25 ERROR cinder.volume.drivers.lightos 
2025-01-23 09:26:00.843 25 ERROR cinder.volume.drivers.lightos During handling of the above exception, another exception occurred:
2025-01-23 09:26:00.843 25 ERROR cinder.volume.drivers.lightos 
2025-01-23 09:26:00.843 25 ERROR cinder.volume.drivers.lightos Traceback (most recent call last):
2025-01-23 09:26:00.843 25 ERROR cinder.volume.drivers.lightos   File "/var/lib/kolla/venv/lib/python3.10/site-packages/urllib3/connectionpool.py", line 715, in urlopen
2025-01-23 09:26:00.843 25 ERROR cinder.volume.drivers.lightos     httplib_response = self._make_request(
2025-01-23 09:26:00.843 25 ERROR cinder.volume.drivers.lightos   File "/var/lib/kolla/venv/lib/python3.10/site-packages/urllib3/connectionpool.py", line 404, in _make_request
2025-01-23 09:26:00.843 25 ERROR cinder.volume.drivers.lightos     self._validate_conn(conn)
2025-01-23 09:26:00.843 25 ERROR cinder.volume.drivers.lightos   File "/var/lib/kolla/venv/lib/python3.10/site-packages/urllib3/connectionpool.py", line 1060, in _validate_conn
2025-01-23 09:26:00.843 25 ERROR cinder.volume.drivers.lightos     conn.connect()
2025-01-23 09:26:00.843 25 ERROR cinder.volume.drivers.lightos   File "/var/lib/kolla/venv/lib/python3.10/site-packages/urllib3/connection.py", line 363, in connect
2025-01-23 09:26:00.843 25 ERROR cinder.volume.drivers.lightos     self.sock = conn = self._new_conn()
2025-01-23 09:26:00.843 25 ERROR cinder.volume.drivers.lightos   File "/var/lib/kolla/venv/lib/python3.10/site-packages/urllib3/connection.py", line 186, in _new_conn
2025-01-23 09:26:00.843 25 ERROR cinder.volume.drivers.lightos     raise NewConnectionError(
2025-01-23 09:26:00.843 25 ERROR cinder.volume.drivers.lightos urllib3.exceptions.NewConnectionError: <urllib3.connection.HTTPSConnection object at 0x7f8fc73152a0>: Failed to establish a new connection: [Errno 111] ECONNREFUSED
2025-01-23 09:26:00.843 25 ERROR cinder.volume.drivers.lightos 
2025-01-23 09:26:00.843 25 ERROR cinder.volume.drivers.lightos During handling of the above exception, another exception occurred:
2025-01-23 09:26:00.843 25 ERROR cinder.volume.drivers.lightos 
2025-01-23 09:26:00.843 25 ERROR cinder.volume.drivers.lightos Traceback (most recent call last):
2025-01-23 09:26:00.843 25 ERROR cinder.volume.drivers.lightos   File "/var/lib/kolla/venv/lib/python3.10/site-packages/requests/adapters.py", line 667, in send
2025-01-23 09:26:00.843 25 ERROR cinder.volume.drivers.lightos     resp = conn.urlopen(
2025-01-23 09:26:00.843 25 ERROR cinder.volume.drivers.lightos   File "/var/lib/kolla/venv/lib/python3.10/site-packages/urllib3/connectionpool.py", line 801, in urlopen
2025-01-23 09:26:00.843 25 ERROR cinder.volume.drivers.lightos     retries = retries.increment(
2025-01-23 09:26:00.843 25 ERROR cinder.volume.drivers.lightos   File "/var/lib/kolla/venv/lib/python3.10/site-packages/urllib3/util/retry.py", line 594, in increment
2025-01-23 09:26:00.843 25 ERROR cinder.volume.drivers.lightos     raise MaxRetryError(_pool, url, error or ResponseError(cause))
2025-01-23 09:26:00.843 25 ERROR cinder.volume.drivers.lightos urllib3.exceptions.MaxRetryError: HTTPSConnectionPool(host='[LB_IP_ADDRESS]', port=443): Max retries exceeded with url: /api/v2/clusterinfo (Caused by NewConnectionError('<urllib3.connection.HTTPSConnection object at 0x7f8fc73152a0>: Failed to establish a new connection: [Errno 111] ECONNREFUSED'))
2025-01-23 09:26:00.843 25 ERROR cinder.volume.drivers.lightos 
2025-01-23 09:26:00.843 25 ERROR cinder.volume.drivers.lightos During handling of the above exception, another exception occurred:
2025-01-23 09:26:00.843 25 ERROR cinder.volume.drivers.lightos 
2025-01-23 09:26:00.843 25 ERROR cinder.volume.drivers.lightos Traceback (most recent call last):
2025-01-23 09:26:00.843 25 ERROR cinder.volume.drivers.lightos   File "/var/lib/kolla/venv/lib/python3.10/site-packages/cinder/volume/drivers/lightos.py", line 356, in __send_cmd
2025-01-23 09:26:00.843 25 ERROR cinder.volume.drivers.lightos     response = session.send(
2025-01-23 09:26:00.843 25 ERROR cinder.volume.drivers.lightos   File "/var/lib/kolla/venv/lib/python3.10/site-packages/requests/sessions.py", line 703, in send
2025-01-23 09:26:00.843 25 ERROR cinder.volume.drivers.lightos     r = adapter.send(request, **kwargs)
2025-01-23 09:26:00.843 25 ERROR cinder.volume.drivers.lightos   File "/var/lib/kolla/venv/lib/python3.10/site-packages/requests/adapters.py", line 700, in send
2025-01-23 09:26:00.843 25 ERROR cinder.volume.drivers.lightos     raise ConnectionError(e, request=request)
2025-01-23 09:26:00.843 25 ERROR cinder.volume.drivers.lightos requests.exceptions.ConnectionError: HTTPSConnectionPool(host='[LB_IP_ADDRESS]', port=443): Max retries exceeded with url: /api/v2/clusterinfo (Caused by NewConnectionError('<urllib3.connection.HTTPSConnection object at 0x7f8fc73152a0>: Failed to establish a new connection: [Errno 111] ECONNREFUSED'))
2025-01-23 09:26:00.843 25 ERROR cinder.volume.drivers.lightos 
2025-01-23 09:26:00.845 25 INFO cinder.volume.drivers.lightos [None req-eeb56e5d-74a3-4b0a-a0b5-8e4e775c8d16 - - - - - -] Invoking get_cluster_info using GET url: /api/v2/clusterinfo             request.body: {} ssl_verify: False
2025-01-23 09:26:00.847 25 ERROR cinder.volume.drivers.lightos [None req-eeb56e5d-74a3-4b0a-a0b5-8e4e775c8d16 - - - - - -] REST server not responding at 'https://[LB_IP_ADDRESS]:443/api/v2/clusterinfo': requests.exceptions.ConnectionError: HTTPSConnectionPool(host='[LB_IP_ADDRESS]', port=443): Max retries exceeded with url: /api/v2/clusterinfo (Caused by NewConnectionError('<urllib3.connection.HTTPSConnection object at 0x7f8fc7316320>: Failed to establish a new connection: [Errno 111] ECONNREFUSED'))
2025-01-23 09:26:00.847 25 ERROR cinder.volume.drivers.lightos Traceback (most recent call last):
2025-01-23 09:26:00.847 25 ERROR cinder.volume.drivers.lightos   File "/var/lib/kolla/venv/lib/python3.10/site-packages/urllib3/connection.py", line 174, in _new_conn
2025-01-23 09:26:00.847 25 ERROR cinder.volume.drivers.lightos     conn = connection.create_connection(
2025-01-23 09:26:00.847 25 ERROR cinder.volume.drivers.lightos   File "/var/lib/kolla/venv/lib/python3.10/site-packages/urllib3/util/connection.py", line 95, in create_connection
2025-01-23 09:26:00.847 25 ERROR cinder.volume.drivers.lightos     raise err
2025-01-23 09:26:00.847 25 ERROR cinder.volume.drivers.lightos   File "/var/lib/kolla/venv/lib/python3.10/site-packages/urllib3/util/connection.py", line 85, in create_connection
2025-01-23 09:26:00.847 25 ERROR cinder.volume.drivers.lightos     sock.connect(sa)
2025-01-23 09:26:00.847 25 ERROR cinder.volume.drivers.lightos   File "/var/lib/kolla/venv/lib/python3.10/site-packages/eventlet/greenio/base.py", line 265, in connect
2025-01-23 09:26:00.847 25 ERROR cinder.volume.drivers.lightos     socket_checkerr(fd)
2025-01-23 09:26:00.847 25 ERROR cinder.volume.drivers.lightos   File "/var/lib/kolla/venv/lib/python3.10/site-packages/eventlet/greenio/base.py", line 50, in socket_checkerr
2025-01-23 09:26:00.847 25 ERROR cinder.volume.drivers.lightos     raise OSError(err, errno.errorcode[err])
2025-01-23 09:26:00.847 25 ERROR cinder.volume.drivers.lightos ConnectionRefusedError: [Errno 111] ECONNREFUSED
2025-01-23 09:26:00.847 25 ERROR cinder.volume.drivers.lightos 
2025-01-23 09:26:00.847 25 ERROR cinder.volume.drivers.lightos During handling of the above exception, another exception occurred:
2025-01-23 09:26:00.847 25 ERROR cinder.volume.drivers.lightos 
2025-01-23 09:26:00.847 25 ERROR cinder.volume.drivers.lightos Traceback (most recent call last):
2025-01-23 09:26:00.847 25 ERROR cinder.volume.drivers.lightos   File "/var/lib/kolla/venv/lib/python3.10/site-packages/urllib3/connectionpool.py", line 715, in urlopen
2025-01-23 09:26:00.847 25 ERROR cinder.volume.drivers.lightos     httplib_response = self._make_request(
2025-01-23 09:26:00.847 25 ERROR cinder.volume.drivers.lightos   File "/var/lib/kolla/venv/lib/python3.10/site-packages/urllib3/connectionpool.py", line 404, in _make_request
2025-01-23 09:26:00.847 25 ERROR cinder.volume.drivers.lightos     self._validate_conn(conn)
2025-01-23 09:26:00.847 25 ERROR cinder.volume.drivers.lightos   File "/var/lib/kolla/venv/lib/python3.10/site-packages/urllib3/connectionpool.py", line 1060, in _validate_conn
2025-01-23 09:26:00.847 25 ERROR cinder.volume.drivers.lightos     conn.connect()
2025-01-23 09:26:00.847 25 ERROR cinder.volume.drivers.lightos   File "/var/lib/kolla/venv/lib/python3.10/site-packages/urllib3/connection.py", line 363, in connect
2025-01-23 09:26:00.847 25 ERROR cinder.volume.drivers.lightos     self.sock = conn = self._new_conn()
2025-01-23 09:26:00.847 25 ERROR cinder.volume.drivers.lightos   File "/var/lib/kolla/venv/lib/python3.10/site-packages/urllib3/connection.py", line 186, in _new_conn
2025-01-23 09:26:00.847 25 ERROR cinder.volume.drivers.lightos     raise NewConnectionError(
2025-01-23 09:26:00.847 25 ERROR cinder.volume.drivers.lightos urllib3.exceptions.NewConnectionError: <urllib3.connection.HTTPSConnection object at 0x7f8fc7316320>: Failed to establish a new connection: [Errno 111] ECONNREFUSED
2025-01-23 09:26:00.847 25 ERROR cinder.volume.drivers.lightos 
2025-01-23 09:26:00.847 25 ERROR cinder.volume.drivers.lightos During handling of the above exception, another exception occurred:
2025-01-23 09:26:00.847 25 ERROR cinder.volume.drivers.lightos 
2025-01-23 09:26:00.847 25 ERROR cinder.volume.drivers.lightos Traceback (most recent call last):
2025-01-23 09:26:00.847 25 ERROR cinder.volume.drivers.lightos   File "/var/lib/kolla/venv/lib/python3.10/site-packages/requests/adapters.py", line 667, in send
2025-01-23 09:26:00.847 25 ERROR cinder.volume.drivers.lightos     resp = conn.urlopen(
2025-01-23 09:26:00.847 25 ERROR cinder.volume.drivers.lightos   File "/var/lib/kolla/venv/lib/python3.10/site-packages/urllib3/connectionpool.py", line 801, in urlopen
2025-01-23 09:26:00.847 25 ERROR cinder.volume.drivers.lightos     retries = retries.increment(
2025-01-23 09:26:00.847 25 ERROR cinder.volume.drivers.lightos   File "/var/lib/kolla/venv/lib/python3.10/site-packages/urllib3/util/retry.py", line 594, in increment
2025-01-23 09:26:00.847 25 ERROR cinder.volume.drivers.lightos     raise MaxRetryError(_pool, url, error or ResponseError(cause))
2025-01-23 09:26:00.847 25 ERROR cinder.volume.drivers.lightos urllib3.exceptions.MaxRetryError: HTTPSConnectionPool(host='[LB_IP_ADDRESS]', port=443): Max retries exceeded with url: /api/v2/clusterinfo (Caused by NewConnectionError('<urllib3.connection.HTTPSConnection object at 0x7f8fc7316320>: Failed to establish a new connection: [Errno 111] ECONNREFUSED'))
2025-01-23 09:26:00.847 25 ERROR cinder.volume.drivers.lightos 
2025-01-23 09:26:00.847 25 ERROR cinder.volume.drivers.lightos During handling of the above exception, another exception occurred:
2025-01-23 09:26:00.847 25 ERROR cinder.volume.drivers.lightos 
2025-01-23 09:26:00.847 25 ERROR cinder.volume.drivers.lightos Traceback (most recent call last):
2025-01-23 09:26:00.847 25 ERROR cinder.volume.drivers.lightos   File "/var/lib/kolla/venv/lib/python3.10/site-packages/cinder/volume/drivers/lightos.py", line 356, in __send_cmd
2025-01-23 09:26:00.847 25 ERROR cinder.volume.drivers.lightos     response = session.send(
2025-01-23 09:26:00.847 25 ERROR cinder.volume.drivers.lightos   File "/var/lib/kolla/venv/lib/python3.10/site-packages/requests/sessions.py", line 703, in send
2025-01-23 09:26:00.847 25 ERROR cinder.volume.drivers.lightos     r = adapter.send(request, **kwargs)
2025-01-23 09:26:00.847 25 ERROR cinder.volume.drivers.lightos   File "/var/lib/kolla/venv/lib/python3.10/site-packages/requests/adapters.py", line 700, in send
2025-01-23 09:26:00.847 25 ERROR cinder.volume.drivers.lightos     raise ConnectionError(e, request=request)
2025-01-23 09:26:00.847 25 ERROR cinder.volume.drivers.lightos requests.exceptions.ConnectionError: HTTPSConnectionPool(host='[LB_IP_ADDRESS]', port=443): Max retries exceeded with url: /api/v2/clusterinfo (Caused by NewConnectionError('<urllib3.connection.HTTPSConnection object at 0x7f8fc7316320>: Failed to establish a new connection: [Errno 111] ECONNREFUSED'))
2025-01-23 09:26:00.847 25 ERROR cinder.volume.drivers.lightos 
2025-01-23 09:26:00.849 25 ERROR cinder.volume.manager [None req-eeb56e5d-74a3-4b0a-a0b5-8e4e775c8d16 - - - - - -] Failed to initialize driver.: cinder.exception.VolumeDriverException: Volume driver reported an error: Could not get a response from any API server
2025-01-23 09:26:00.849 25 ERROR cinder.volume.manager Traceback (most recent call last):
2025-01-23 09:26:00.849 25 ERROR cinder.volume.manager   File "/var/lib/kolla/venv/lib/python3.10/site-packages/cinder/volume/manager.py", line 523, in _init_host
2025-01-23 09:26:00.849 25 ERROR cinder.volume.manager     self.driver.do_setup(ctxt)
2025-01-23 09:26:00.849 25 ERROR cinder.volume.manager   File "/var/lib/kolla/venv/lib/python3.10/site-packages/cinder/volume/drivers/lightos.py", line 922, in do_setup
2025-01-23 09:26:00.849 25 ERROR cinder.volume.manager     self.get_cluster_info()
2025-01-23 09:26:00.849 25 ERROR cinder.volume.manager   File "/var/lib/kolla/venv/lib/python3.10/site-packages/cinder/volume/drivers/lightos.py", line 873, in get_cluster_info
2025-01-23 09:26:00.849 25 ERROR cinder.volume.manager     status_code, cluster_info = self.cluster.send_cmd(
2025-01-23 09:26:00.849 25 ERROR cinder.volume.manager   File "/var/lib/kolla/venv/lib/python3.10/site-packages/cinder/volume/drivers/lightos.py", line 315, in send_cmd
2025-01-23 09:26:00.849 25 ERROR cinder.volume.manager     raise exception.VolumeDriverException(
2025-01-23 09:26:00.849 25 ERROR cinder.volume.manager cinder.exception.VolumeDriverException: Volume driver reported an error: Could not get a response from any API server
2025-01-23 09:26:00.849 25 ERROR cinder.volume.manager 
2025-01-23 09:26:02.852 25 INFO cinder.volume.manager [None req-eeb56e5d-74a3-4b0a-a0b5-8e4e775c8d16 - - - - - -] Starting volume driver LightOSVolumeDriver (2.3.12)
2025-01-23 09:26:02.853 25 INFO cinder.volume.drivers.lightos [None req-eeb56e5d-74a3-4b0a-a0b5-8e4e775c8d16 - - - - - -] Invoking get_cluster_info using GET url: /api/v2/clusterinfo             request.body: {} ssl_verify: False
2025-01-23 09:26:03.905 25 ERROR cinder.volume.drivers.lightos [None req-eeb56e5d-74a3-4b0a-a0b5-8e4e775c8d16 - - - - - -] REST server not responding at 'https://[LB_IP_ADDRESS]:443/api/v2/clusterinfo': requests.exceptions.ConnectionError: HTTPSConnectionPool(host='[LB_IP_ADDRESS]', port=443): Max retries exceeded with url: /api/v2/clusterinfo (Caused by NewConnectionError('<urllib3.connection.HTTPSConnection object at 0x7f8fc72a47c0>: Failed to establish a new connection: [Errno 113] EHOSTUNREACH'))
2025-01-23 09:26:03.905 25 ERROR cinder.volume.drivers.lightos Traceback (most recent call last):
2025-01-23 09:26:03.905 25 ERROR cinder.volume.drivers.lightos   File "/var/lib/kolla/venv/lib/python3.10/site-packages/urllib3/connection.py", line 174, in _new_conn
2025-01-23 09:26:03.905 25 ERROR cinder.volume.drivers.lightos     conn = connection.create_connection(
2025-01-23 09:26:03.905 25 ERROR cinder.volume.drivers.lightos   File "/var/lib/kolla/venv/lib/python3.10/site-packages/urllib3/util/connection.py", line 95, in create_connection
2025-01-23 09:26:03.905 25 ERROR cinder.volume.drivers.lightos     raise err
2025-01-23 09:26:03.905 25 ERROR cinder.volume.drivers.lightos   File "/var/lib/kolla/venv/lib/python3.10/site-packages/urllib3/util/connection.py", line 85, in create_connection
2025-01-23 09:26:03.905 25 ERROR cinder.volume.drivers.lightos     sock.connect(sa)
2025-01-23 09:26:03.905 25 ERROR cinder.volume.drivers.lightos   File "/var/lib/kolla/venv/lib/python3.10/site-packages/eventlet/greenio/base.py", line 265, in connect
2025-01-23 09:26:03.905 25 ERROR cinder.volume.drivers.lightos     socket_checkerr(fd)
2025-01-23 09:26:03.905 25 ERROR cinder.volume.drivers.lightos   File "/var/lib/kolla/venv/lib/python3.10/site-packages/eventlet/greenio/base.py", line 50, in socket_checkerr
2025-01-23 09:26:03.905 25 ERROR cinder.volume.drivers.lightos     raise OSError(err, errno.errorcode[err])
2025-01-23 09:26:03.905 25 ERROR cinder.volume.drivers.lightos OSError: [Errno 113] EHOSTUNREACH
2025-01-23 09:26:03.905 25 ERROR cinder.volume.drivers.lightos 
2025-01-23 09:26:03.905 25 ERROR cinder.volume.drivers.lightos During handling of the above exception, another exception occurred:
2025-01-23 09:26:03.905 25 ERROR cinder.volume.drivers.lightos 
2025-01-23 09:26:03.905 25 ERROR cinder.volume.drivers.lightos Traceback (most recent call last):
2025-01-23 09:26:03.905 25 ERROR cinder.volume.drivers.lightos   File "/var/lib/kolla/venv/lib/python3.10/site-packages/urllib3/connectionpool.py", line 715, in urlopen
2025-01-23 09:26:03.905 25 ERROR cinder.volume.drivers.lightos     httplib_response = self._make_request(
2025-01-23 09:26:03.905 25 ERROR cinder.volume.drivers.lightos   File "/var/lib/kolla/venv/lib/python3.10/site-packages/urllib3/connectionpool.py", line 404, in _make_request
2025-01-23 09:26:03.905 25 ERROR cinder.volume.drivers.lightos     self._validate_conn(conn)
2025-01-23 09:26:03.905 25 ERROR cinder.volume.drivers.lightos   File "/var/lib/kolla/venv/lib/python3.10/site-packages/urllib3/connectionpool.py", line 1060, in _validate_conn
2025-01-23 09:26:03.905 25 ERROR cinder.volume.drivers.lightos     conn.connect()
2025-01-23 09:26:03.905 25 ERROR cinder.volume.drivers.lightos   File "/var/lib/kolla/venv/lib/python3.10/site-packages/urllib3/connection.py", line 363, in connect
2025-01-23 09:26:03.905 25 ERROR cinder.volume.drivers.lightos     self.sock = conn = self._new_conn()
2025-01-23 09:26:03.905 25 ERROR cinder.volume.drivers.lightos   File "/var/lib/kolla/venv/lib/python3.10/site-packages/urllib3/connection.py", line 186, in _new_conn
2025-01-23 09:26:03.905 25 ERROR cinder.volume.drivers.lightos     raise NewConnectionError(
2025-01-23 09:26:03.905 25 ERROR cinder.volume.drivers.lightos urllib3.exceptions.NewConnectionError: <urllib3.connection.HTTPSConnection object at 0x7f8fc72a47c0>: Failed to establish a new connection: [Errno 113] EHOSTUNREACH
2025-01-23 09:26:03.905 25 ERROR cinder.volume.drivers.lightos 
2025-01-23 09:26:03.905 25 ERROR cinder.volume.drivers.lightos During handling of the above exception, another exception occurred:
2025-01-23 09:26:03.905 25 ERROR cinder.volume.drivers.lightos 
2025-01-23 09:26:03.905 25 ERROR cinder.volume.drivers.lightos Traceback (most recent call last):
2025-01-23 09:26:03.905 25 ERROR cinder.volume.drivers.lightos   File "/var/lib/kolla/venv/lib/python3.10/site-packages/requests/adapters.py", line 667, in send
2025-01-23 09:26:03.905 25 ERROR cinder.volume.drivers.lightos     resp = conn.urlopen(
2025-01-23 09:26:03.905 25 ERROR cinder.volume.drivers.lightos   File "/var/lib/kolla/venv/lib/python3.10/site-packages/urllib3/connectionpool.py", line 801, in urlopen
2025-01-23 09:26:03.905 25 ERROR cinder.volume.drivers.lightos     retries = retries.increment(
2025-01-23 09:26:03.905 25 ERROR cinder.volume.drivers.lightos   File "/var/lib/kolla/venv/lib/python3.10/site-packages/urllib3/util/retry.py", line 594, in increment
2025-01-23 09:26:03.905 25 ERROR cinder.volume.drivers.lightos     raise MaxRetryError(_pool, url, error or ResponseError(cause))
2025-01-23 09:26:03.905 25 ERROR cinder.volume.drivers.lightos urllib3.exceptions.MaxRetryError: HTTPSConnectionPool(host='[LB_IP_ADDRESS]', port=443): Max retries exceeded with url: /api/v2/clusterinfo (Caused by NewConnectionError('<urllib3.connection.HTTPSConnection object at 0x7f8fc72a47c0>: Failed to establish a new connection: [Errno 113] EHOSTUNREACH'))
2025-01-23 09:26:03.905 25 ERROR cinder.volume.drivers.lightos 
2025-01-23 09:26:03.905 25 ERROR cinder.volume.drivers.lightos During handling of the above exception, another exception occurred:
2025-01-23 09:26:03.905 25 ERROR cinder.volume.drivers.lightos 
2025-01-23 09:26:03.905 25 ERROR cinder.volume.drivers.lightos Traceback (most recent call last):
2025-01-23 09:26:03.905 25 ERROR cinder.volume.drivers.lightos   File "/var/lib/kolla/venv/lib/python3.10/site-packages/cinder/volume/drivers/lightos.py", line 356, in __send_cmd
2025-01-23 09:26:03.905 25 ERROR cinder.volume.drivers.lightos     response = session.send(
2025-01-23 09:26:03.905 25 ERROR cinder.volume.drivers.lightos   File "/var/lib/kolla/venv/lib/python3.10/site-packages/requests/sessions.py", line 703, in send
2025-01-23 09:26:03.905 25 ERROR cinder.volume.drivers.lightos     r = adapter.send(request, **kwargs)
2025-01-23 09:26:03.905 25 ERROR cinder.volume.drivers.lightos   File "/var/lib/kolla/venv/lib/python3.10/site-packages/requests/adapters.py", line 700, in send
2025-01-23 09:26:03.905 25 ERROR cinder.volume.drivers.lightos     raise ConnectionError(e, request=request)
2025-01-23 09:26:03.905 25 ERROR cinder.volume.drivers.lightos requests.exceptions.ConnectionError: HTTPSConnectionPool(host='[LB_IP_ADDRESS]', port=443): Max retries exceeded with url: /api/v2/clusterinfo (Caused by NewConnectionError('<urllib3.connection.HTTPSConnection object at 0x7f8fc72a47c0>: Failed to establish a new connection: [Errno 113] EHOSTUNREACH'))
2025-01-23 09:26:03.905 25 ERROR cinder.volume.drivers.lightos 
2025-01-23 09:26:03.908 25 INFO cinder.volume.drivers.lightos [None req-eeb56e5d-74a3-4b0a-a0b5-8e4e775c8d16 - - - - - -] Invoking get_cluster_info using GET url: /api/v2/clusterinfo             request.body: {} ssl_verify: False
2025-01-23 09:26:03.911 25 ERROR cinder.volume.drivers.lightos [None req-eeb56e5d-74a3-4b0a-a0b5-8e4e775c8d16 - - - - - -] REST server not responding at 'https://[LB_IP_ADDRESS]:443/api/v2/clusterinfo': requests.exceptions.ConnectionError: HTTPSConnectionPool(host='[LB_IP_ADDRESS]', port=443): Max retries exceeded with url: /api/v2/clusterinfo (Caused by NewConnectionError('<urllib3.connection.HTTPSConnection object at 0x7f8fc72a52a0>: Failed to establish a new connection: [Errno 111] ECONNREFUSED'))
2025-01-23 09:26:03.911 25 ERROR cinder.volume.drivers.lightos Traceback (most recent call last):
2025-01-23 09:26:03.911 25 ERROR cinder.volume.drivers.lightos   File "/var/lib/kolla/venv/lib/python3.10/site-packages/urllib3/connection.py", line 174, in _new_conn
2025-01-23 09:26:03.911 25 ERROR cinder.volume.drivers.lightos     conn = connection.create_connection(
2025-01-23 09:26:03.911 25 ERROR cinder.volume.drivers.lightos   File "/var/lib/kolla/venv/lib/python3.10/site-packages/urllib3/util/connection.py", line 95, in create_connection
2025-01-23 09:26:03.911 25 ERROR cinder.volume.drivers.lightos     raise err
2025-01-23 09:26:03.911 25 ERROR cinder.volume.drivers.lightos   File "/var/lib/kolla/venv/lib/python3.10/site-packages/urllib3/util/connection.py", line 85, in create_connection
2025-01-23 09:26:03.911 25 ERROR cinder.volume.drivers.lightos     sock.connect(sa)
2025-01-23 09:26:03.911 25 ERROR cinder.volume.drivers.lightos   File "/var/lib/kolla/venv/lib/python3.10/site-packages/eventlet/greenio/base.py", line 265, in connect
2025-01-23 09:26:03.911 25 ERROR cinder.volume.drivers.lightos     socket_checkerr(fd)
2025-01-23 09:26:03.911 25 ERROR cinder.volume.drivers.lightos   File "/var/lib/kolla/venv/lib/python3.10/site-packages/eventlet/greenio/base.py", line 50, in socket_checkerr
2025-01-23 09:26:03.911 25 ERROR cinder.volume.drivers.lightos     raise OSError(err, errno.errorcode[err])
2025-01-23 09:26:03.911 25 ERROR cinder.volume.drivers.lightos ConnectionRefusedError: [Errno 111] ECONNREFUSED
2025-01-23 09:26:03.911 25 ERROR cinder.volume.drivers.lightos 
2025-01-23 09:26:03.911 25 ERROR cinder.volume.drivers.lightos During handling of the above exception, another exception occurred:
2025-01-23 09:26:03.911 25 ERROR cinder.volume.drivers.lightos 
2025-01-23 09:26:03.911 25 ERROR cinder.volume.drivers.lightos Traceback (most recent call last):
2025-01-23 09:26:03.911 25 ERROR cinder.volume.drivers.lightos   File "/var/lib/kolla/venv/lib/python3.10/site-packages/urllib3/connectionpool.py", line 715, in urlopen
2025-01-23 09:26:03.911 25 ERROR cinder.volume.drivers.lightos     httplib_response = self._make_request(
2025-01-23 09:26:03.911 25 ERROR cinder.volume.drivers.lightos   File "/var/lib/kolla/venv/lib/python3.10/site-packages/urllib3/connectionpool.py", line 404, in _make_request
2025-01-23 09:26:03.911 25 ERROR cinder.volume.drivers.lightos     self._validate_conn(conn)
2025-01-23 09:26:03.911 25 ERROR cinder.volume.drivers.lightos   File "/var/lib/kolla/venv/lib/python3.10/site-packages/urllib3/connectionpool.py", line 1060, in _validate_conn
2025-01-23 09:26:03.911 25 ERROR cinder.volume.drivers.lightos     conn.connect()
2025-01-23 09:26:03.911 25 ERROR cinder.volume.drivers.lightos   File "/var/lib/kolla/venv/lib/python3.10/site-packages/urllib3/connection.py", line 363, in connect
2025-01-23 09:26:03.911 25 ERROR cinder.volume.drivers.lightos     self.sock = conn = self._new_conn()
2025-01-23 09:26:03.911 25 ERROR cinder.volume.drivers.lightos   File "/var/lib/kolla/venv/lib/python3.10/site-packages/urllib3/connection.py", line 186, in _new_conn
2025-01-23 09:26:03.911 25 ERROR cinder.volume.drivers.lightos     raise NewConnectionError(
2025-01-23 09:26:03.911 25 ERROR cinder.volume.drivers.lightos urllib3.exceptions.NewConnectionError: <urllib3.connection.HTTPSConnection object at 0x7f8fc72a52a0>: Failed to establish a new connection: [Errno 111] ECONNREFUSED
2025-01-23 09:26:03.911 25 ERROR cinder.volume.drivers.lightos 
2025-01-23 09:26:03.911 25 ERROR cinder.volume.drivers.lightos During handling of the above exception, another exception occurred:
2025-01-23 09:26:03.911 25 ERROR cinder.volume.drivers.lightos 
2025-01-23 09:26:03.911 25 ERROR cinder.volume.drivers.lightos Traceback (most recent call last):
2025-01-23 09:26:03.911 25 ERROR cinder.volume.drivers.lightos   File "/var/lib/kolla/venv/lib/python3.10/site-packages/requests/adapters.py", line 667, in send
2025-01-23 09:26:03.911 25 ERROR cinder.volume.drivers.lightos     resp = conn.urlopen(
2025-01-23 09:26:03.911 25 ERROR cinder.volume.drivers.lightos   File "/var/lib/kolla/venv/lib/python3.10/site-packages/urllib3/connectionpool.py", line 801, in urlopen
2025-01-23 09:26:03.911 25 ERROR cinder.volume.drivers.lightos     retries = retries.increment(
2025-01-23 09:26:03.911 25 ERROR cinder.volume.drivers.lightos   File "/var/lib/kolla/venv/lib/python3.10/site-packages/urllib3/util/retry.py", line 594, in increment
2025-01-23 09:26:03.911 25 ERROR cinder.volume.drivers.lightos     raise MaxRetryError(_pool, url, error or ResponseError(cause))
2025-01-23 09:26:03.911 25 ERROR cinder.volume.drivers.lightos urllib3.exceptions.MaxRetryError: HTTPSConnectionPool(host='[LB_IP_ADDRESS]', port=443): Max retries exceeded with url: /api/v2/clusterinfo (Caused by NewConnectionError('<urllib3.connection.HTTPSConnection object at 0x7f8fc72a52a0>: Failed to establish a new connection: [Errno 111] ECONNREFUSED'))
2025-01-23 09:26:03.911 25 ERROR cinder.volume.drivers.lightos 
2025-01-23 09:26:03.911 25 ERROR cinder.volume.drivers.lightos During handling of the above exception, another exception occurred:
2025-01-23 09:26:03.911 25 ERROR cinder.volume.drivers.lightos 
2025-01-23 09:26:03.911 25 ERROR cinder.volume.drivers.lightos Traceback (most recent call last):
2025-01-23 09:26:03.911 25 ERROR cinder.volume.drivers.lightos   File "/var/lib/kolla/venv/lib/python3.10/site-packages/cinder/volume/drivers/lightos.py", line 356, in __send_cmd
2025-01-23 09:26:03.911 25 ERROR cinder.volume.drivers.lightos     response = session.send(
2025-01-23 09:26:03.911 25 ERROR cinder.volume.drivers.lightos   File "/var/lib/kolla/venv/lib/python3.10/site-packages/requests/sessions.py", line 703, in send
2025-01-23 09:26:03.911 25 ERROR cinder.volume.drivers.lightos     r = adapter.send(request, **kwargs)
2025-01-23 09:26:03.911 25 ERROR cinder.volume.drivers.lightos   File "/var/lib/kolla/venv/lib/python3.10/site-packages/requests/adapters.py", line 700, in send
2025-01-23 09:26:03.911 25 ERROR cinder.volume.drivers.lightos     raise ConnectionError(e, request=request)
2025-01-23 09:26:03.911 25 ERROR cinder.volume.drivers.lightos requests.exceptions.ConnectionError: HTTPSConnectionPool(host='[LB_IP_ADDRESS]', port=443): Max retries exceeded with url: /api/v2/clusterinfo (Caused by NewConnectionError('<urllib3.connection.HTTPSConnection object at 0x7f8fc72a52a0>: Failed to establish a new connection: [Errno 111] ECONNREFUSED'))
2025-01-23 09:26:03.911 25 ERROR cinder.volume.drivers.lightos 
2025-01-23 09:26:03.914 25 INFO cinder.volume.drivers.lightos [None req-eeb56e5d-74a3-4b0a-a0b5-8e4e775c8d16 - - - - - -] Invoking get_cluster_info using GET url: /api/v2/clusterinfo             request.body: {} ssl_verify: False
2025-01-23 09:26:03.916 25 ERROR cinder.volume.drivers.lightos [None req-eeb56e5d-74a3-4b0a-a0b5-8e4e775c8d16 - - - - - -] REST server not responding at 'https://[LB_IP_ADDRESS]:443/api/v2/clusterinfo': requests.exceptions.ConnectionError: HTTPSConnectionPool(host='[LB_IP_ADDRESS]', port=443): Max retries exceeded with url: /api/v2/clusterinfo (Caused by NewConnectionError('<urllib3.connection.HTTPSConnection object at 0x7f8fc73161d0>: Failed to establish a new connection: [Errno 111] ECONNREFUSED'))
2025-01-23 09:26:03.916 25 ERROR cinder.volume.drivers.lightos Traceback (most recent call last):
2025-01-23 09:26:03.916 25 ERROR cinder.volume.drivers.lightos   File "/var/lib/kolla/venv/lib/python3.10/site-packages/urllib3/connection.py", line 174, in _new_conn
2025-01-23 09:26:03.916 25 ERROR cinder.volume.drivers.lightos     conn = connection.create_connection(
2025-01-23 09:26:03.916 25 ERROR cinder.volume.drivers.lightos   File "/var/lib/kolla/venv/lib/python3.10/site-packages/urllib3/util/connection.py", line 95, in create_connection
2025-01-23 09:26:03.916 25 ERROR cinder.volume.drivers.lightos     raise err
2025-01-23 09:26:03.916 25 ERROR cinder.volume.drivers.lightos   File "/var/lib/kolla/venv/lib/python3.10/site-packages/urllib3/util/connection.py", line 85, in create_connection
2025-01-23 09:26:03.916 25 ERROR cinder.volume.drivers.lightos     sock.connect(sa)
2025-01-23 09:26:03.916 25 ERROR cinder.volume.drivers.lightos   File "/var/lib/kolla/venv/lib/python3.10/site-packages/eventlet/greenio/base.py", line 265, in connect
2025-01-23 09:26:03.916 25 ERROR cinder.volume.drivers.lightos     socket_checkerr(fd)
2025-01-23 09:26:03.916 25 ERROR cinder.volume.drivers.lightos   File "/var/lib/kolla/venv/lib/python3.10/site-packages/eventlet/greenio/base.py", line 50, in socket_checkerr
2025-01-23 09:26:03.916 25 ERROR cinder.volume.drivers.lightos     raise OSError(err, errno.errorcode[err])
2025-01-23 09:26:03.916 25 ERROR cinder.volume.drivers.lightos ConnectionRefusedError: [Errno 111] ECONNREFUSED
2025-01-23 09:26:03.916 25 ERROR cinder.volume.drivers.lightos 
2025-01-23 09:26:03.916 25 ERROR cinder.volume.drivers.lightos During handling of the above exception, another exception occurred:
2025-01-23 09:26:03.916 25 ERROR cinder.volume.drivers.lightos 
2025-01-23 09:26:03.916 25 ERROR cinder.volume.drivers.lightos Traceback (most recent call last):
2025-01-23 09:26:03.916 25 ERROR cinder.volume.drivers.lightos   File "/var/lib/kolla/venv/lib/python3.10/site-packages/urllib3/connectionpool.py", line 715, in urlopen
2025-01-23 09:26:03.916 25 ERROR cinder.volume.drivers.lightos     httplib_response = self._make_request(
2025-01-23 09:26:03.916 25 ERROR cinder.volume.drivers.lightos   File "/var/lib/kolla/venv/lib/python3.10/site-packages/urllib3/connectionpool.py", line 404, in _make_request
2025-01-23 09:26:03.916 25 ERROR cinder.volume.drivers.lightos     self._validate_conn(conn)
2025-01-23 09:26:03.916 25 ERROR cinder.volume.drivers.lightos   File "/var/lib/kolla/venv/lib/python3.10/site-packages/urllib3/connectionpool.py", line 1060, in _validate_conn
2025-01-23 09:26:03.916 25 ERROR cinder.volume.drivers.lightos     conn.connect()
2025-01-23 09:26:03.916 25 ERROR cinder.volume.drivers.lightos   File "/var/lib/kolla/venv/lib/python3.10/site-packages/urllib3/connection.py", line 363, in connect
2025-01-23 09:26:03.916 25 ERROR cinder.volume.drivers.lightos     self.sock = conn = self._new_conn()
2025-01-23 09:26:03.916 25 ERROR cinder.volume.drivers.lightos   File "/var/lib/kolla/venv/lib/python3.10/site-packages/urllib3/connection.py", line 186, in _new_conn
2025-01-23 09:26:03.916 25 ERROR cinder.volume.drivers.lightos     raise NewConnectionError(
2025-01-23 09:26:03.916 25 ERROR cinder.volume.drivers.lightos urllib3.exceptions.NewConnectionError: <urllib3.connection.HTTPSConnection object at 0x7f8fc73161d0>: Failed to establish a new connection: [Errno 111] ECONNREFUSED
2025-01-23 09:26:03.916 25 ERROR cinder.volume.drivers.lightos 
2025-01-23 09:26:03.916 25 ERROR cinder.volume.drivers.lightos During handling of the above exception, another exception occurred:
2025-01-23 09:26:03.916 25 ERROR cinder.volume.drivers.lightos 
2025-01-23 09:26:03.916 25 ERROR cinder.volume.drivers.lightos Traceback (most recent call last):
2025-01-23 09:26:03.916 25 ERROR cinder.volume.drivers.lightos   File "/var/lib/kolla/venv/lib/python3.10/site-packages/requests/adapters.py", line 667, in send
2025-01-23 09:26:03.916 25 ERROR cinder.volume.drivers.lightos     resp = conn.urlopen(
2025-01-23 09:26:03.916 25 ERROR cinder.volume.drivers.lightos   File "/var/lib/kolla/venv/lib/python3.10/site-packages/urllib3/connectionpool.py", line 801, in urlopen
2025-01-23 09:26:03.916 25 ERROR cinder.volume.drivers.lightos     retries = retries.increment(
2025-01-23 09:26:03.916 25 ERROR cinder.volume.drivers.lightos   File "/var/lib/kolla/venv/lib/python3.10/site-packages/urllib3/util/retry.py", line 594, in increment
2025-01-23 09:26:03.916 25 ERROR cinder.volume.drivers.lightos     raise MaxRetryError(_pool, url, error or ResponseError(cause))
2025-01-23 09:26:03.916 25 ERROR cinder.volume.drivers.lightos urllib3.exceptions.MaxRetryError: HTTPSConnectionPool(host='[LB_IP_ADDRESS]', port=443): Max retries exceeded with url: /api/v2/clusterinfo (Caused by NewConnectionError('<urllib3.connection.HTTPSConnection object at 0x7f8fc73161d0>: Failed to establish a new connection: [Errno 111] ECONNREFUSED'))
2025-01-23 09:26:03.916 25 ERROR cinder.volume.drivers.lightos 
2025-01-23 09:26:03.916 25 ERROR cinder.volume.drivers.lightos During handling of the above exception, another exception occurred:
2025-01-23 09:26:03.916 25 ERROR cinder.volume.drivers.lightos 
2025-01-23 09:26:03.916 25 ERROR cinder.volume.drivers.lightos Traceback (most recent call last):
2025-01-23 09:26:03.916 25 ERROR cinder.volume.drivers.lightos   File "/var/lib/kolla/venv/lib/python3.10/site-packages/cinder/volume/drivers/lightos.py", line 356, in __send_cmd
2025-01-23 09:26:03.916 25 ERROR cinder.volume.drivers.lightos     response = session.send(
2025-01-23 09:26:03.916 25 ERROR cinder.volume.drivers.lightos   File "/var/lib/kolla/venv/lib/python3.10/site-packages/requests/sessions.py", line 703, in send
2025-01-23 09:26:03.916 25 ERROR cinder.volume.drivers.lightos     r = adapter.send(request, **kwargs)
2025-01-23 09:26:03.916 25 ERROR cinder.volume.drivers.lightos   File "/var/lib/kolla/venv/lib/python3.10/site-packages/requests/adapters.py", line 700, in send
2025-01-23 09:26:03.916 25 ERROR cinder.volume.drivers.lightos     raise ConnectionError(e, request=request)
2025-01-23 09:26:03.916 25 ERROR cinder.volume.drivers.lightos requests.exceptions.ConnectionError: HTTPSConnectionPool(host='[LB_IP_ADDRESS]', port=443): Max retries exceeded with url: /api/v2/clusterinfo (Caused by NewConnectionError('<urllib3.connection.HTTPSConnection object at 0x7f8fc73161d0>: Failed to establish a new connection: [Errno 111] ECONNREFUSED'))
2025-01-23 09:26:03.916 25 ERROR cinder.volume.drivers.lightos 
2025-01-23 09:26:03.917 25 ERROR cinder.volume.manager [None req-eeb56e5d-74a3-4b0a-a0b5-8e4e775c8d16 - - - - - -] Failed to initialize driver.: cinder.exception.VolumeDriverException: Volume driver reported an error: Could not get a response from any API server
2025-01-23 09:26:03.917 25 ERROR cinder.volume.manager Traceback (most recent call last):
2025-01-23 09:26:03.917 25 ERROR cinder.volume.manager   File "/var/lib/kolla/venv/lib/python3.10/site-packages/cinder/volume/manager.py", line 523, in _init_host
2025-01-23 09:26:03.917 25 ERROR cinder.volume.manager     self.driver.do_setup(ctxt)
2025-01-23 09:26:03.917 25 ERROR cinder.volume.manager   File "/var/lib/kolla/venv/lib/python3.10/site-packages/cinder/volume/drivers/lightos.py", line 922, in do_setup
2025-01-23 09:26:03.917 25 ERROR cinder.volume.manager     self.get_cluster_info()
2025-01-23 09:26:03.917 25 ERROR cinder.volume.manager   File "/var/lib/kolla/venv/lib/python3.10/site-packages/cinder/volume/drivers/lightos.py", line 873, in get_cluster_info
2025-01-23 09:26:03.917 25 ERROR cinder.volume.manager     status_code, cluster_info = self.cluster.send_cmd(
2025-01-23 09:26:03.917 25 ERROR cinder.volume.manager   File "/var/lib/kolla/venv/lib/python3.10/site-packages/cinder/volume/drivers/lightos.py", line 315, in send_cmd
2025-01-23 09:26:03.917 25 ERROR cinder.volume.manager     raise exception.VolumeDriverException(
2025-01-23 09:26:03.917 25 ERROR cinder.volume.manager cinder.exception.VolumeDriverException: Volume driver reported an error: Could not get a response from any API server
2025-01-23 09:26:03.917 25 ERROR cinder.volume.manager 
2025-01-23 09:26:07.922 25 INFO cinder.volume.manager [None req-eeb56e5d-74a3-4b0a-a0b5-8e4e775c8d16 - - - - - -] Starting volume driver LightOSVolumeDriver (2.3.12)
2025-01-23 09:26:07.923 25 INFO cinder.volume.drivers.lightos [None req-eeb56e5d-74a3-4b0a-a0b5-8e4e775c8d16 - - - - - -] Invoking get_cluster_info using GET url: /api/v2/clusterinfo             request.body: {} ssl_verify: False
2025-01-23 09:26:10.977 25 ERROR cinder.volume.drivers.lightos [None req-eeb56e5d-74a3-4b0a-a0b5-8e4e775c8d16 - - - - - -] REST server not responding at 'https://[LB_IP_ADDRESS]:443/api/v2/clusterinfo': requests.exceptions.ConnectionError: HTTPSConnectionPool(host='[LB_IP_ADDRESS]', port=443): Max retries exceeded with url: /api/v2/clusterinfo (Caused by NewConnectionError('<urllib3.connection.HTTPSConnection object at 0x7f8fc7314af0>: Failed to establish a new connection: [Errno 113] EHOSTUNREACH'))
2025-01-23 09:26:10.977 25 ERROR cinder.volume.drivers.lightos Traceback (most recent call last):
2025-01-23 09:26:10.977 25 ERROR cinder.volume.drivers.lightos   File "/var/lib/kolla/venv/lib/python3.10/site-packages/urllib3/connection.py", line 174, in _new_conn
2025-01-23 09:26:10.977 25 ERROR cinder.volume.drivers.lightos     conn = connection.create_connection(
2025-01-23 09:26:10.977 25 ERROR cinder.volume.drivers.lightos   File "/var/lib/kolla/venv/lib/python3.10/site-packages/urllib3/util/connection.py", line 95, in create_connection
2025-01-23 09:26:10.977 25 ERROR cinder.volume.drivers.lightos     raise err
2025-01-23 09:26:10.977 25 ERROR cinder.volume.drivers.lightos   File "/var/lib/kolla/venv/lib/python3.10/site-packages/urllib3/util/connection.py", line 85, in create_connection
2025-01-23 09:26:10.977 25 ERROR cinder.volume.drivers.lightos     sock.connect(sa)
2025-01-23 09:26:10.977 25 ERROR cinder.volume.drivers.lightos   File "/var/lib/kolla/venv/lib/python3.10/site-packages/eventlet/greenio/base.py", line 265, in connect
2025-01-23 09:26:10.977 25 ERROR cinder.volume.drivers.lightos     socket_checkerr(fd)
2025-01-23 09:26:10.977 25 ERROR cinder.volume.drivers.lightos   File "/var/lib/kolla/venv/lib/python3.10/site-packages/eventlet/greenio/base.py", line 50, in socket_checkerr
2025-01-23 09:26:10.977 25 ERROR cinder.volume.drivers.lightos     raise OSError(err, errno.errorcode[err])
2025-01-23 09:26:10.977 25 ERROR cinder.volume.drivers.lightos OSError: [Errno 113] EHOSTUNREACH
2025-01-23 09:26:10.977 25 ERROR cinder.volume.drivers.lightos 
2025-01-23 09:26:10.977 25 ERROR cinder.volume.drivers.lightos During handling of the above exception, another exception occurred:
2025-01-23 09:26:10.977 25 ERROR cinder.volume.drivers.lightos 
2025-01-23 09:26:10.977 25 ERROR cinder.volume.drivers.lightos Traceback (most recent call last):
2025-01-23 09:26:10.977 25 ERROR cinder.volume.drivers.lightos   File "/var/lib/kolla/venv/lib/python3.10/site-packages/urllib3/connectionpool.py", line 715, in urlopen
2025-01-23 09:26:10.977 25 ERROR cinder.volume.drivers.lightos     httplib_response = self._make_request(
2025-01-23 09:26:10.977 25 ERROR cinder.volume.drivers.lightos   File "/var/lib/kolla/venv/lib/python3.10/site-packages/urllib3/connectionpool.py", line 404, in _make_request
2025-01-23 09:26:10.977 25 ERROR cinder.volume.drivers.lightos     self._validate_conn(conn)
2025-01-23 09:26:10.977 25 ERROR cinder.volume.drivers.lightos   File "/var/lib/kolla/venv/lib/python3.10/site-packages/urllib3/connectionpool.py", line 1060, in _validate_conn
2025-01-23 09:26:10.977 25 ERROR cinder.volume.drivers.lightos     conn.connect()
2025-01-23 09:26:10.977 25 ERROR cinder.volume.drivers.lightos   File "/var/lib/kolla/venv/lib/python3.10/site-packages/urllib3/connection.py", line 363, in connect
2025-01-23 09:26:10.977 25 ERROR cinder.volume.drivers.lightos     self.sock = conn = self._new_conn()
2025-01-23 09:26:10.977 25 ERROR cinder.volume.drivers.lightos   File "/var/lib/kolla/venv/lib/python3.10/site-packages/urllib3/connection.py", line 186, in _new_conn
2025-01-23 09:26:10.977 25 ERROR cinder.volume.drivers.lightos     raise NewConnectionError(
2025-01-23 09:26:10.977 25 ERROR cinder.volume.drivers.lightos urllib3.exceptions.NewConnectionError: <urllib3.connection.HTTPSConnection object at 0x7f8fc7314af0>: Failed to establish a new connection: [Errno 113] EHOSTUNREACH
2025-01-23 09:26:10.977 25 ERROR cinder.volume.drivers.lightos 
2025-01-23 09:26:10.977 25 ERROR cinder.volume.drivers.lightos During handling of the above exception, another exception occurred:
2025-01-23 09:26:10.977 25 ERROR cinder.volume.drivers.lightos 
2025-01-23 09:26:10.977 25 ERROR cinder.volume.drivers.lightos Traceback (most recent call last):
2025-01-23 09:26:10.977 25 ERROR cinder.volume.drivers.lightos   File "/var/lib/kolla/venv/lib/python3.10/site-packages/requests/adapters.py", line 667, in send
2025-01-23 09:26:10.977 25 ERROR cinder.volume.drivers.lightos     resp = conn.urlopen(
2025-01-23 09:26:10.977 25 ERROR cinder.volume.drivers.lightos   File "/var/lib/kolla/venv/lib/python3.10/site-packages/urllib3/connectionpool.py", line 801, in urlopen
2025-01-23 09:26:10.977 25 ERROR cinder.volume.drivers.lightos     retries = retries.increment(
2025-01-23 09:26:10.977 25 ERROR cinder.volume.drivers.lightos   File "/var/lib/kolla/venv/lib/python3.10/site-packages/urllib3/util/retry.py", line 594, in increment
2025-01-23 09:26:10.977 25 ERROR cinder.volume.drivers.lightos     raise MaxRetryError(_pool, url, error or ResponseError(cause))
2025-01-23 09:26:10.977 25 ERROR cinder.volume.drivers.lightos urllib3.exceptions.MaxRetryError: HTTPSConnectionPool(host='[LB_IP_ADDRESS]', port=443): Max retries exceeded with url: /api/v2/clusterinfo (Caused by NewConnectionError('<urllib3.connection.HTTPSConnection object at 0x7f8fc7314af0>: Failed to establish a new connection: [Errno 113] EHOSTUNREACH'))
2025-01-23 09:26:10.977 25 ERROR cinder.volume.drivers.lightos 
2025-01-23 09:26:10.977 25 ERROR cinder.volume.drivers.lightos During handling of the above exception, another exception occurred:
2025-01-23 09:26:10.977 25 ERROR cinder.volume.drivers.lightos 
2025-01-23 09:26:10.977 25 ERROR cinder.volume.drivers.lightos Traceback (most recent call last):
2025-01-23 09:26:10.977 25 ERROR cinder.volume.drivers.lightos   File "/var/lib/kolla/venv/lib/python3.10/site-packages/cinder/volume/drivers/lightos.py", line 356, in __send_cmd
2025-01-23 09:26:10.977 25 ERROR cinder.volume.drivers.lightos     response = session.send(
2025-01-23 09:26:10.977 25 ERROR cinder.volume.drivers.lightos   File "/var/lib/kolla/venv/lib/python3.10/site-packages/requests/sessions.py", line 703, in send
2025-01-23 09:26:10.977 25 ERROR cinder.volume.drivers.lightos     r = adapter.send(request, **kwargs)
2025-01-23 09:26:10.977 25 ERROR cinder.volume.drivers.lightos   File "/var/lib/kolla/venv/lib/python3.10/site-packages/requests/adapters.py", line 700, in send
2025-01-23 09:26:10.977 25 ERROR cinder.volume.drivers.lightos     raise ConnectionError(e, request=request)
2025-01-23 09:26:10.977 25 ERROR cinder.volume.drivers.lightos requests.exceptions.ConnectionError: HTTPSConnectionPool(host='[LB_IP_ADDRESS]', port=443): Max retries exceeded with url: /api/v2/clusterinfo (Caused by NewConnectionError('<urllib3.connection.HTTPSConnection object at 0x7f8fc7314af0>: Failed to establish a new connection: [Errno 113] EHOSTUNREACH'))
2025-01-23 09:26:10.977 25 ERROR cinder.volume.drivers.lightos 
2025-01-23 09:26:10.980 25 INFO cinder.volume.drivers.lightos [None req-eeb56e5d-74a3-4b0a-a0b5-8e4e775c8d16 - - - - - -] Invoking get_cluster_info using GET url: /api/v2/clusterinfo             request.body: {} ssl_verify: False
2025-01-23 09:26:10.983 25 ERROR cinder.volume.drivers.lightos [None req-eeb56e5d-74a3-4b0a-a0b5-8e4e775c8d16 - - - - - -] REST server not responding at 'https://[LB_IP_ADDRESS]:443/api/v2/clusterinfo': requests.exceptions.ConnectionError: HTTPSConnectionPool(host='[LB_IP_ADDRESS]', port=443): Max retries exceeded with url: /api/v2/clusterinfo (Caused by NewConnectionError('<urllib3.connection.HTTPSConnection object at 0x7f8fc7314610>: Failed to establish a new connection: [Errno 111] ECONNREFUSED'))
2025-01-23 09:26:10.983 25 ERROR cinder.volume.drivers.lightos Traceback (most recent call last):
2025-01-23 09:26:10.983 25 ERROR cinder.volume.drivers.lightos   File "/var/lib/kolla/venv/lib/python3.10/site-packages/urllib3/connection.py", line 174, in _new_conn
2025-01-23 09:26:10.983 25 ERROR cinder.volume.drivers.lightos     conn = connection.create_connection(
2025-01-23 09:26:10.983 25 ERROR cinder.volume.drivers.lightos   File "/var/lib/kolla/venv/lib/python3.10/site-packages/urllib3/util/connection.py", line 95, in create_connection
2025-01-23 09:26:10.983 25 ERROR cinder.volume.drivers.lightos     raise err
2025-01-23 09:26:10.983 25 ERROR cinder.volume.drivers.lightos   File "/var/lib/kolla/venv/lib/python3.10/site-packages/urllib3/util/connection.py", line 85, in create_connection
2025-01-23 09:26:10.983 25 ERROR cinder.volume.drivers.lightos     sock.connect(sa)
2025-01-23 09:26:10.983 25 ERROR cinder.volume.drivers.lightos   File "/var/lib/kolla/venv/lib/python3.10/site-packages/eventlet/greenio/base.py", line 265, in connect
2025-01-23 09:26:10.983 25 ERROR cinder.volume.drivers.lightos     socket_checkerr(fd)
2025-01-23 09:26:10.983 25 ERROR cinder.volume.drivers.lightos   File "/var/lib/kolla/venv/lib/python3.10/site-packages/eventlet/greenio/base.py", line 50, in socket_checkerr
2025-01-23 09:26:10.983 25 ERROR cinder.volume.drivers.lightos     raise OSError(err, errno.errorcode[err])
2025-01-23 09:26:10.983 25 ERROR cinder.volume.drivers.lightos ConnectionRefusedError: [Errno 111] ECONNREFUSED
2025-01-23 09:26:10.983 25 ERROR cinder.volume.drivers.lightos 
2025-01-23 09:26:10.983 25 ERROR cinder.volume.drivers.lightos During handling of the above exception, another exception occurred:
2025-01-23 09:26:10.983 25 ERROR cinder.volume.drivers.lightos 
2025-01-23 09:26:10.983 25 ERROR cinder.volume.drivers.lightos Traceback (most recent call last):
2025-01-23 09:26:10.983 25 ERROR cinder.volume.drivers.lightos   File "/var/lib/kolla/venv/lib/python3.10/site-packages/urllib3/connectionpool.py", line 715, in urlopen
2025-01-23 09:26:10.983 25 ERROR cinder.volume.drivers.lightos     httplib_response = self._make_request(
2025-01-23 09:26:10.983 25 ERROR cinder.volume.drivers.lightos   File "/var/lib/kolla/venv/lib/python3.10/site-packages/urllib3/connectionpool.py", line 404, in _make_request
2025-01-23 09:26:10.983 25 ERROR cinder.volume.drivers.lightos     self._validate_conn(conn)
2025-01-23 09:26:10.983 25 ERROR cinder.volume.drivers.lightos   File "/var/lib/kolla/venv/lib/python3.10/site-packages/urllib3/connectionpool.py", line 1060, in _validate_conn
2025-01-23 09:26:10.983 25 ERROR cinder.volume.drivers.lightos     conn.connect()
2025-01-23 09:26:10.983 25 ERROR cinder.volume.drivers.lightos   File "/var/lib/kolla/venv/lib/python3.10/site-packages/urllib3/connection.py", line 363, in connect
2025-01-23 09:26:10.983 25 ERROR cinder.volume.drivers.lightos     self.sock = conn = self._new_conn()
2025-01-23 09:26:10.983 25 ERROR cinder.volume.drivers.lightos   File "/var/lib/kolla/venv/lib/python3.10/site-packages/urllib3/connection.py", line 186, in _new_conn
2025-01-23 09:26:10.983 25 ERROR cinder.volume.drivers.lightos     raise NewConnectionError(
2025-01-23 09:26:10.983 25 ERROR cinder.volume.drivers.lightos urllib3.exceptions.NewConnectionError: <urllib3.connection.HTTPSConnection object at 0x7f8fc7314610>: Failed to establish a new connection: [Errno 111] ECONNREFUSED
2025-01-23 09:26:10.983 25 ERROR cinder.volume.drivers.lightos 
2025-01-23 09:26:10.983 25 ERROR cinder.volume.drivers.lightos During handling of the above exception, another exception occurred:
2025-01-23 09:26:10.983 25 ERROR cinder.volume.drivers.lightos 
2025-01-23 09:26:10.983 25 ERROR cinder.volume.drivers.lightos Traceback (most recent call last):
2025-01-23 09:26:10.983 25 ERROR cinder.volume.drivers.lightos   File "/var/lib/kolla/venv/lib/python3.10/site-packages/requests/adapters.py", line 667, in send
2025-01-23 09:26:10.983 25 ERROR cinder.volume.drivers.lightos     resp = conn.urlopen(
2025-01-23 09:26:10.983 25 ERROR cinder.volume.drivers.lightos   File "/var/lib/kolla/venv/lib/python3.10/site-packages/urllib3/connectionpool.py", line 801, in urlopen
2025-01-23 09:26:10.983 25 ERROR cinder.volume.drivers.lightos     retries = retries.increment(
2025-01-23 09:26:10.983 25 ERROR cinder.volume.drivers.lightos   File "/var/lib/kolla/venv/lib/python3.10/site-packages/urllib3/util/retry.py", line 594, in increment
2025-01-23 09:26:10.983 25 ERROR cinder.volume.drivers.lightos     raise MaxRetryError(_pool, url, error or ResponseError(cause))
2025-01-23 09:26:10.983 25 ERROR cinder.volume.drivers.lightos urllib3.exceptions.MaxRetryError: HTTPSConnectionPool(host='[LB_IP_ADDRESS]', port=443): Max retries exceeded with url: /api/v2/clusterinfo (Caused by NewConnectionError('<urllib3.connection.HTTPSConnection object at 0x7f8fc7314610>: Failed to establish a new connection: [Errno 111] ECONNREFUSED'))
2025-01-23 09:26:10.983 25 ERROR cinder.volume.drivers.lightos 
2025-01-23 09:26:10.983 25 ERROR cinder.volume.drivers.lightos During handling of the above exception, another exception occurred:
2025-01-23 09:26:10.983 25 ERROR cinder.volume.drivers.lightos 
2025-01-23 09:26:10.983 25 ERROR cinder.volume.drivers.lightos Traceback (most recent call last):
2025-01-23 09:26:10.983 25 ERROR cinder.volume.drivers.lightos   File "/var/lib/kolla/venv/lib/python3.10/site-packages/cinder/volume/drivers/lightos.py", line 356, in __send_cmd
2025-01-23 09:26:10.983 25 ERROR cinder.volume.drivers.lightos     response = session.send(
2025-01-23 09:26:10.983 25 ERROR cinder.volume.drivers.lightos   File "/var/lib/kolla/venv/lib/python3.10/site-packages/requests/sessions.py", line 703, in send
2025-01-23 09:26:10.983 25 ERROR cinder.volume.drivers.lightos     r = adapter.send(request, **kwargs)
2025-01-23 09:26:10.983 25 ERROR cinder.volume.drivers.lightos   File "/var/lib/kolla/venv/lib/python3.10/site-packages/requests/adapters.py", line 700, in send
2025-01-23 09:26:10.983 25 ERROR cinder.volume.drivers.lightos     raise ConnectionError(e, request=request)
2025-01-23 09:26:10.983 25 ERROR cinder.volume.drivers.lightos requests.exceptions.ConnectionError: HTTPSConnectionPool(host='[LB_IP_ADDRESS]', port=443): Max retries exceeded with url: /api/v2/clusterinfo (Caused by NewConnectionError('<urllib3.connection.HTTPSConnection object at 0x7f8fc7314610>: Failed to establish a new connection: [Errno 111] ECONNREFUSED'))
2025-01-23 09:26:10.983 25 ERROR cinder.volume.drivers.lightos 
2025-01-23 09:26:10.985 25 INFO cinder.volume.drivers.lightos [None req-eeb56e5d-74a3-4b0a-a0b5-8e4e775c8d16 - - - - - -] Invoking get_cluster_info using GET url: /api/v2/clusterinfo             request.body: {} ssl_verify: False
2025-01-23 09:26:10.988 25 ERROR cinder.volume.drivers.lightos [None req-eeb56e5d-74a3-4b0a-a0b5-8e4e775c8d16 - - - - - -] REST server not responding at 'https://[LB_IP_ADDRESS]:443/api/v2/clusterinfo': requests.exceptions.ConnectionError: HTTPSConnectionPool(host='[LB_IP_ADDRESS]', port=443): Max retries exceeded with url: /api/v2/clusterinfo (Caused by NewConnectionError('<urllib3.connection.HTTPSConnection object at 0x7f8fc72a43a0>: Failed to establish a new connection: [Errno 111] ECONNREFUSED'))
2025-01-23 09:26:10.988 25 ERROR cinder.volume.drivers.lightos Traceback (most recent call last):
2025-01-23 09:26:10.988 25 ERROR cinder.volume.drivers.lightos   File "/var/lib/kolla/venv/lib/python3.10/site-packages/urllib3/connection.py", line 174, in _new_conn
2025-01-23 09:26:10.988 25 ERROR cinder.volume.drivers.lightos     conn = connection.create_connection(
2025-01-23 09:26:10.988 25 ERROR cinder.volume.drivers.lightos   File "/var/lib/kolla/venv/lib/python3.10/site-packages/urllib3/util/connection.py", line 95, in create_connection
2025-01-23 09:26:10.988 25 ERROR cinder.volume.drivers.lightos     raise err
2025-01-23 09:26:10.988 25 ERROR cinder.volume.drivers.lightos   File "/var/lib/kolla/venv/lib/python3.10/site-packages/urllib3/util/connection.py", line 85, in create_connection
2025-01-23 09:26:10.988 25 ERROR cinder.volume.drivers.lightos     sock.connect(sa)
2025-01-23 09:26:10.988 25 ERROR cinder.volume.drivers.lightos   File "/var/lib/kolla/venv/lib/python3.10/site-packages/eventlet/greenio/base.py", line 265, in connect
2025-01-23 09:26:10.988 25 ERROR cinder.volume.drivers.lightos     socket_checkerr(fd)
2025-01-23 09:26:10.988 25 ERROR cinder.volume.drivers.lightos   File "/var/lib/kolla/venv/lib/python3.10/site-packages/eventlet/greenio/base.py", line 50, in socket_checkerr
2025-01-23 09:26:10.988 25 ERROR cinder.volume.drivers.lightos     raise OSError(err, errno.errorcode[err])
2025-01-23 09:26:10.988 25 ERROR cinder.volume.drivers.lightos ConnectionRefusedError: [Errno 111] ECONNREFUSED
2025-01-23 09:26:10.988 25 ERROR cinder.volume.drivers.lightos 
2025-01-23 09:26:10.988 25 ERROR cinder.volume.drivers.lightos During handling of the above exception, another exception occurred:
2025-01-23 09:26:10.988 25 ERROR cinder.volume.drivers.lightos 
2025-01-23 09:26:10.988 25 ERROR cinder.volume.drivers.lightos Traceback (most recent call last):
2025-01-23 09:26:10.988 25 ERROR cinder.volume.drivers.lightos   File "/var/lib/kolla/venv/lib/python3.10/site-packages/urllib3/connectionpool.py", line 715, in urlopen
2025-01-23 09:26:10.988 25 ERROR cinder.volume.drivers.lightos     httplib_response = self._make_request(
2025-01-23 09:26:10.988 25 ERROR cinder.volume.drivers.lightos   File "/var/lib/kolla/venv/lib/python3.10/site-packages/urllib3/connectionpool.py", line 404, in _make_request
2025-01-23 09:26:10.988 25 ERROR cinder.volume.drivers.lightos     self._validate_conn(conn)
2025-01-23 09:26:10.988 25 ERROR cinder.volume.drivers.lightos   File "/var/lib/kolla/venv/lib/python3.10/site-packages/urllib3/connectionpool.py", line 1060, in _validate_conn
2025-01-23 09:26:10.988 25 ERROR cinder.volume.drivers.lightos     conn.connect()
2025-01-23 09:26:10.988 25 ERROR cinder.volume.drivers.lightos   File "/var/lib/kolla/venv/lib/python3.10/site-packages/urllib3/connection.py", line 363, in connect
2025-01-23 09:26:10.988 25 ERROR cinder.volume.drivers.lightos     self.sock = conn = self._new_conn()
2025-01-23 09:26:10.988 25 ERROR cinder.volume.drivers.lightos   File "/var/lib/kolla/venv/lib/python3.10/site-packages/urllib3/connection.py", line 186, in _new_conn
2025-01-23 09:26:10.988 25 ERROR cinder.volume.drivers.lightos     raise NewConnectionError(
2025-01-23 09:26:10.988 25 ERROR cinder.volume.drivers.lightos urllib3.exceptions.NewConnectionError: <urllib3.connection.HTTPSConnection object at 0x7f8fc72a43a0>: Failed to establish a new connection: [Errno 111] ECONNREFUSED
2025-01-23 09:26:10.988 25 ERROR cinder.volume.drivers.lightos 
2025-01-23 09:26:10.988 25 ERROR cinder.volume.drivers.lightos During handling of the above exception, another exception occurred:
2025-01-23 09:26:10.988 25 ERROR cinder.volume.drivers.lightos 
2025-01-23 09:26:10.988 25 ERROR cinder.volume.drivers.lightos Traceback (most recent call last):
2025-01-23 09:26:10.988 25 ERROR cinder.volume.drivers.lightos   File "/var/lib/kolla/venv/lib/python3.10/site-packages/requests/adapters.py", line 667, in send
2025-01-23 09:26:10.988 25 ERROR cinder.volume.drivers.lightos     resp = conn.urlopen(
2025-01-23 09:26:10.988 25 ERROR cinder.volume.drivers.lightos   File "/var/lib/kolla/venv/lib/python3.10/site-packages/urllib3/connectionpool.py", line 801, in urlopen
2025-01-23 09:26:10.988 25 ERROR cinder.volume.drivers.lightos     retries = retries.increment(
2025-01-23 09:26:10.988 25 ERROR cinder.volume.drivers.lightos   File "/var/lib/kolla/venv/lib/python3.10/site-packages/urllib3/util/retry.py", line 594, in increment
2025-01-23 09:26:10.988 25 ERROR cinder.volume.drivers.lightos     raise MaxRetryError(_pool, url, error or ResponseError(cause))
2025-01-23 09:26:10.988 25 ERROR cinder.volume.drivers.lightos urllib3.exceptions.MaxRetryError: HTTPSConnectionPool(host='[LB_IP_ADDRESS]', port=443): Max retries exceeded with url: /api/v2/clusterinfo (Caused by NewConnectionError('<urllib3.connection.HTTPSConnection object at 0x7f8fc72a43a0>: Failed to establish a new connection: [Errno 111] ECONNREFUSED'))
2025-01-23 09:26:10.988 25 ERROR cinder.volume.drivers.lightos 
2025-01-23 09:26:10.988 25 ERROR cinder.volume.drivers.lightos During handling of the above exception, another exception occurred:
2025-01-23 09:26:10.988 25 ERROR cinder.volume.drivers.lightos 
2025-01-23 09:26:10.988 25 ERROR cinder.volume.drivers.lightos Traceback (most recent call last):
2025-01-23 09:26:10.988 25 ERROR cinder.volume.drivers.lightos   File "/var/lib/kolla/venv/lib/python3.10/site-packages/cinder/volume/drivers/lightos.py", line 356, in __send_cmd
2025-01-23 09:26:10.988 25 ERROR cinder.volume.drivers.lightos     response = session.send(
2025-01-23 09:26:10.988 25 ERROR cinder.volume.drivers.lightos   File "/var/lib/kolla/venv/lib/python3.10/site-packages/requests/sessions.py", line 703, in send
2025-01-23 09:26:10.988 25 ERROR cinder.volume.drivers.lightos     r = adapter.send(request, **kwargs)
2025-01-23 09:26:10.988 25 ERROR cinder.volume.drivers.lightos   File "/var/lib/kolla/venv/lib/python3.10/site-packages/requests/adapters.py", line 700, in send
2025-01-23 09:26:10.988 25 ERROR cinder.volume.drivers.lightos     raise ConnectionError(e, request=request)
2025-01-23 09:26:10.988 25 ERROR cinder.volume.drivers.lightos requests.exceptions.ConnectionError: HTTPSConnectionPool(host='[LB_IP_ADDRESS]', port=443): Max retries exceeded with url: /api/v2/clusterinfo (Caused by NewConnectionError('<urllib3.connection.HTTPSConnection object at 0x7f8fc72a43a0>: Failed to establish a new connection: [Errno 111] ECONNREFUSED'))
2025-01-23 09:26:10.988 25 ERROR cinder.volume.drivers.lightos 
2025-01-23 09:26:10.989 25 ERROR cinder.volume.manager [None req-eeb56e5d-74a3-4b0a-a0b5-8e4e775c8d16 - - - - - -] Failed to initialize driver.: cinder.exception.VolumeDriverException: Volume driver reported an error: Could not get a response from any API server
2025-01-23 09:26:10.989 25 ERROR cinder.volume.manager Traceback (most recent call last):
2025-01-23 09:26:10.989 25 ERROR cinder.volume.manager   File "/var/lib/kolla/venv/lib/python3.10/site-packages/cinder/volume/manager.py", line 523, in _init_host
2025-01-23 09:26:10.989 25 ERROR cinder.volume.manager     self.driver.do_setup(ctxt)
2025-01-23 09:26:10.989 25 ERROR cinder.volume.manager   File "/var/lib/kolla/venv/lib/python3.10/site-packages/cinder/volume/drivers/lightos.py", line 922, in do_setup
2025-01-23 09:26:10.989 25 ERROR cinder.volume.manager     self.get_cluster_info()
2025-01-23 09:26:10.989 25 ERROR cinder.volume.manager   File "/var/lib/kolla/venv/lib/python3.10/site-packages/cinder/volume/drivers/lightos.py", line 873, in get_cluster_info
2025-01-23 09:26:10.989 25 ERROR cinder.volume.manager     status_code, cluster_info = self.cluster.send_cmd(
2025-01-23 09:26:10.989 25 ERROR cinder.volume.manager   File "/var/lib/kolla/venv/lib/python3.10/site-packages/cinder/volume/drivers/lightos.py", line 315, in send_cmd
2025-01-23 09:26:10.989 25 ERROR cinder.volume.manager     raise exception.VolumeDriverException(
2025-01-23 09:26:10.989 25 ERROR cinder.volume.manager cinder.exception.VolumeDriverException: Volume driver reported an error: Could not get a response from any API server
2025-01-23 09:26:10.989 25 ERROR cinder.volume.manager 
2025-01-23 09:26:11.010 25 WARNING oslo_config.cfg [None req-eeb56e5d-74a3-4b0a-a0b5-8e4e775c8d16 - - - - - -] Deprecated: Option "heartbeat_in_pthread" from group "oslo_messaging_rabbit" is deprecated for removal (The option is related to Eventlet which will be removed. In addition this has never worked as expected with services using eventlet for core service framework.).  Its value may be silently ignored in the future.
2025-01-23 09:26:11.058 25 INFO cinder.service [None req-eeb56e5d-74a3-4b0a-a0b5-8e4e775c8d16 - - - - - -] Starting cinder-volume cluster lightos_cinder_cluster@LIGHTOSyilgqu (version 25.1.0)
2025-01-23 09:26:11.078 25 INFO cinder.volume.manager [None req-eeb56e5d-74a3-4b0a-a0b5-8e4e775c8d16 - - - - - -] Initializing RPC dependent components of volume driver LightOSVolumeDriver (2.3.12)
2025-01-23 09:26:11.078 25 ERROR cinder.volume.volume_utils [None req-eeb56e5d-74a3-4b0a-a0b5-8e4e775c8d16 - - - - - -] Volume driver LightOSVolumeDriver not initialized
2025-01-23 09:26:11.078 25 ERROR cinder.volume.manager [None req-eeb56e5d-74a3-4b0a-a0b5-8e4e775c8d16 - - - - - -] Cannot complete RPC initialization because driver isn't initialized properly.: cinder.exception.DriverNotInitialized: Volume driver not ready.
2025-01-23 09:26:21.080 25 ERROR cinder.service [-] Manager for service cinder-volume rack13-server67@LIGHTOSyilgqu is reporting problems, not sending heartbeat. Service will appear "down".
2025-01-23 09:26:31.082 25 ERROR cinder.service [-] Manager for service cinder-volume rack13-server67@LIGHTOSyilgqu is reporting problems, not sending heartbeat. Service will appear "down".
2025-01-23 09:26:41.084 25 ERROR cinder.service [-] Manager for service cinder-volume rack13-server67@LIGHTOSyilgqu is reporting problems, not sending heartbeat. Service will appear "down".
2025-01-23 09:26:51.085 25 ERROR cinder.service [-] Manager for service cinder-volume rack13-server67@LIGHTOSyilgqu is reporting problems, not sending heartbeat. Service will appear "down".
2025-01-23 09:27:01.087 25 ERROR cinder.service [-] Manager for service cinder-volume rack13-server67@LIGHTOSyilgqu is reporting problems, not sending heartbeat. Service will appear "down".
2025-01-23 09:27:11.079 25 WARNING cinder.volume.manager [None req-d64f7dbd-bc33-47de-aba0-8bffc4ae205d - - - - - -] Update driver status failed: (config name LIGHTOSyilgqu) is uninitialized.
2025-01-23 09:27:11.088 25 ERROR cinder.service [-] Manager for service cinder-volume rack13-server67@LIGHTOSyilgqu is reporting problems, not sending heartbeat. Service will appear "down".
2025-01-23 09:27:21.090 25 ERROR cinder.service [-] Manager for service cinder-volume rack13-server67@LIGHTOSyilgqu is reporting problems, not sending heartbeat. Service will appear "down".
2025-01-23 09:27:31.091 25 ERROR cinder.service [-] Manager for service cinder-volume rack13-server67@LIGHTOSyilgqu is reporting problems, not sending heartbeat. Service will appear "down".
2025-01-23 09:27:41.093 25 ERROR cinder.service [-] Manager for service cinder-volume rack13-server67@LIGHTOSyilgqu is reporting problems, not sending heartbeat. Service will appear "down".
2025-01-23 09:27:51.094 25 ERROR cinder.service [-] Manager for service cinder-volume rack13-server67@LIGHTOSyilgqu is reporting problems, not sending heartbeat. Service will appear "down".
2025-01-23 09:28:01.095 25 ERROR cinder.service [-] Manager for service cinder-volume rack13-server67@LIGHTOSyilgqu is reporting problems, not sending heartbeat. Service will appear "down".
2025-01-23 09:28:11.082 25 WARNING cinder.volume.manager [None req-d64f7dbd-bc33-47de-aba0-8bffc4ae205d - - - - - -] Update driver status failed: (config name LIGHTOSyilgqu) is uninitialized.
2025-01-23 09:28:11.096 25 ERROR cinder.service [-] Manager for service cinder-volume rack13-server67@LIGHTOSyilgqu is reporting problems, not sending heartbeat. Service will appear "down".
2025-01-23 09:28:21.097 25 ERROR cinder.service [-] Manager for service cinder-volume rack13-server67@LIGHTOSyilgqu is reporting problems, not sending heartbeat. Service will appear "down".
2025-01-23 09:28:31.098 25 ERROR cinder.service [-] Manager for service cinder-volume rack13-server67@LIGHTOSyilgqu is reporting problems, not sending heartbeat. Service will appear "down".
2025-01-23 09:28:41.100 25 ERROR cinder.service [-] Manager for service cinder-volume rack13-server67@LIGHTOSyilgqu is reporting problems, not sending heartbeat. Service will appear "down".
2025-01-23 09:28:51.101 25 ERROR cinder.service [-] Manager for service cinder-volume rack13-server67@LIGHTOSyilgqu is reporting problems, not sending heartbeat. Service will appear "down".
2025-01-23 09:29:01.105 25 ERROR cinder.service [-] Manager for service cinder-volume rack13-server67@LIGHTOSyilgqu is reporting problems, not sending heartbeat. Service will appear "down".
2025-01-23 09:29:11.084 25 WARNING cinder.volume.manager [None req-d64f7dbd-bc33-47de-aba0-8bffc4ae205d - - - - - -] Update driver status failed: (config name LIGHTOSyilgqu) is uninitialized.
2025-01-23 09:29:11.106 25 ERROR cinder.service [-] Manager for service cinder-volume rack13-server67@LIGHTOSyilgqu is reporting problems, not sending heartbeat. Service will appear "down".
2025-01-23 09:29:21.108 25 ERROR cinder.service [-] Manager for service cinder-volume rack13-server67@LIGHTOSyilgqu is reporting problems, not sending heartbeat. Service will appear "down".
2025-01-23 09:29:31.110 25 ERROR cinder.service [-] Manager for service cinder-volume rack13-server67@LIGHTOSyilgqu is reporting problems, not sending heartbeat. Service will appear "down".
2025-01-23 09:29:41.111 25 ERROR cinder.service [-] Manager for service cinder-volume rack13-server67@LIGHTOSyilgqu is reporting problems, not sending heartbeat. Service will appear "down".
2025-01-23 09:29:51.113 25 ERROR cinder.service [-] Manager for service cinder-volume rack13-server67@LIGHTOSyilgqu is reporting problems, not sending heartbeat. Service will appear "down".
