Build Started 21_01_2025_17_35_12
2025-01-21 17:35:21.935 7 INFO oslo_service.service [None req-696e8d8c-7b7c-47b0-9b03-465f8461f635 - - - - - -] Caught SIGTERM, stopping children
2025-01-21 17:35:21.941 7 INFO oslo_service.service [None req-696e8d8c-7b7c-47b0-9b03-465f8461f635 - - - - - -] Waiting on 1 children to exit
2025-01-21 17:35:25.120 25 WARNING amqp [None req-696e8d8c-7b7c-47b0-9b03-465f8461f635 - - - - - -] Received method (60, 30) during closing channel 1. This method will be ignored
2025-01-21 17:35:25.134 25 WARNING amqp [None req-696e8d8c-7b7c-47b0-9b03-465f8461f635 - - - - - -] Received method (60, 30) during closing channel 1. This method will be ignored
2025-01-21 17:35:25.141 25 WARNING amqp [None req-696e8d8c-7b7c-47b0-9b03-465f8461f635 - - - - - -] Received method (60, 30) during closing channel 1. This method will be ignored
2025-01-21 17:35:25.149 7 INFO oslo_service.service [None req-696e8d8c-7b7c-47b0-9b03-465f8461f635 - - - - - -] Child 25 exited with status 0
2025-01-21 17:35:40.427 7 INFO cinder.rpc [None req-31cc4e7c-d7d2-4c48-846d-423b7820b34c - - - - - -] Automatically selected cinder-scheduler objects version 1.39 as minimum service version.
2025-01-21 17:35:40.431 7 INFO cinder.rpc [None req-31cc4e7c-d7d2-4c48-846d-423b7820b34c - - - - - -] Automatically selected cinder-scheduler RPC version 3.12 as minimum service version.
2025-01-21 17:35:40.466 7 INFO cinder.volume.manager [None req-31cc4e7c-d7d2-4c48-846d-423b7820b34c - - - - - -] Determined volume DB was empty at startup.
2025-01-21 17:35:40.482 7 INFO cinder.volume.manager [None req-31cc4e7c-d7d2-4c48-846d-423b7820b34c - - - - - -] Image-volume cache disabled for host rack13-server67@LIGHTOSyilgqu.
2025-01-21 17:35:40.496 7 INFO oslo_service.service [None req-31cc4e7c-d7d2-4c48-846d-423b7820b34c - - - - - -] Starting 1 workers
2025-01-21 17:35:40.507 25 INFO cinder.service [-] Starting cinder-volume node (version 25.1.0)
2025-01-21 17:35:40.511 7 WARNING oslo_config.cfg [None req-31cc4e7c-d7d2-4c48-846d-423b7820b34c - - - - - -] Deprecated: Option "heartbeat_in_pthread" from group "oslo_messaging_rabbit" is deprecated for removal (The option is related to Eventlet which will be removed. In addition this has never worked as expected with services using eventlet for core service framework.).  Its value may be silently ignored in the future.
2025-01-21 17:35:40.526 25 INFO cinder.volume.manager [None req-c0a51630-b5a9-4475-9c7a-8d313e57175d - - - - - -] Starting volume driver LightOSVolumeDriver (2.3.12)
2025-01-21 17:35:40.527 25 INFO cinder.volume.drivers.lightos [None req-c0a51630-b5a9-4475-9c7a-8d313e57175d - - - - - -] Invoking get_cluster_info using GET url: /api/v2/clusterinfo             request.body: {} ssl_verify: False
2025-01-21 17:35:40.530 25 ERROR cinder.volume.drivers.lightos [None req-c0a51630-b5a9-4475-9c7a-8d313e57175d - - - - - -] REST server not responding at 'https://[LB_IP_ADDRESS]:443/api/v2/clusterinfo': requests.exceptions.ConnectionError: HTTPSConnectionPool(host='[LB_IP_ADDRESS]', port=443): Max retries exceeded with url: /api/v2/clusterinfo (Caused by NewConnectionError('<urllib3.connection.HTTPSConnection object at 0x7ff4fbfd9b10>: Failed to establish a new connection: [Errno 111] ECONNREFUSED'))
2025-01-21 17:35:40.530 25 ERROR cinder.volume.drivers.lightos Traceback (most recent call last):
2025-01-21 17:35:40.530 25 ERROR cinder.volume.drivers.lightos   File "/var/lib/kolla/venv/lib/python3.10/site-packages/urllib3/connection.py", line 174, in _new_conn
2025-01-21 17:35:40.530 25 ERROR cinder.volume.drivers.lightos     conn = connection.create_connection(
2025-01-21 17:35:40.530 25 ERROR cinder.volume.drivers.lightos   File "/var/lib/kolla/venv/lib/python3.10/site-packages/urllib3/util/connection.py", line 95, in create_connection
2025-01-21 17:35:40.530 25 ERROR cinder.volume.drivers.lightos     raise err
2025-01-21 17:35:40.530 25 ERROR cinder.volume.drivers.lightos   File "/var/lib/kolla/venv/lib/python3.10/site-packages/urllib3/util/connection.py", line 85, in create_connection
2025-01-21 17:35:40.530 25 ERROR cinder.volume.drivers.lightos     sock.connect(sa)
2025-01-21 17:35:40.530 25 ERROR cinder.volume.drivers.lightos   File "/var/lib/kolla/venv/lib/python3.10/site-packages/eventlet/greenio/base.py", line 265, in connect
2025-01-21 17:35:40.530 25 ERROR cinder.volume.drivers.lightos     socket_checkerr(fd)
2025-01-21 17:35:40.530 25 ERROR cinder.volume.drivers.lightos   File "/var/lib/kolla/venv/lib/python3.10/site-packages/eventlet/greenio/base.py", line 50, in socket_checkerr
2025-01-21 17:35:40.530 25 ERROR cinder.volume.drivers.lightos     raise OSError(err, errno.errorcode[err])
2025-01-21 17:35:40.530 25 ERROR cinder.volume.drivers.lightos ConnectionRefusedError: [Errno 111] ECONNREFUSED
2025-01-21 17:35:40.530 25 ERROR cinder.volume.drivers.lightos 
2025-01-21 17:35:40.530 25 ERROR cinder.volume.drivers.lightos During handling of the above exception, another exception occurred:
2025-01-21 17:35:40.530 25 ERROR cinder.volume.drivers.lightos 
2025-01-21 17:35:40.530 25 ERROR cinder.volume.drivers.lightos Traceback (most recent call last):
2025-01-21 17:35:40.530 25 ERROR cinder.volume.drivers.lightos   File "/var/lib/kolla/venv/lib/python3.10/site-packages/urllib3/connectionpool.py", line 715, in urlopen
2025-01-21 17:35:40.530 25 ERROR cinder.volume.drivers.lightos     httplib_response = self._make_request(
2025-01-21 17:35:40.530 25 ERROR cinder.volume.drivers.lightos   File "/var/lib/kolla/venv/lib/python3.10/site-packages/urllib3/connectionpool.py", line 404, in _make_request
2025-01-21 17:35:40.530 25 ERROR cinder.volume.drivers.lightos     self._validate_conn(conn)
2025-01-21 17:35:40.530 25 ERROR cinder.volume.drivers.lightos   File "/var/lib/kolla/venv/lib/python3.10/site-packages/urllib3/connectionpool.py", line 1060, in _validate_conn
2025-01-21 17:35:40.530 25 ERROR cinder.volume.drivers.lightos     conn.connect()
2025-01-21 17:35:40.530 25 ERROR cinder.volume.drivers.lightos   File "/var/lib/kolla/venv/lib/python3.10/site-packages/urllib3/connection.py", line 363, in connect
2025-01-21 17:35:40.530 25 ERROR cinder.volume.drivers.lightos     self.sock = conn = self._new_conn()
2025-01-21 17:35:40.530 25 ERROR cinder.volume.drivers.lightos   File "/var/lib/kolla/venv/lib/python3.10/site-packages/urllib3/connection.py", line 186, in _new_conn
2025-01-21 17:35:40.530 25 ERROR cinder.volume.drivers.lightos     raise NewConnectionError(
2025-01-21 17:35:40.530 25 ERROR cinder.volume.drivers.lightos urllib3.exceptions.NewConnectionError: <urllib3.connection.HTTPSConnection object at 0x7ff4fbfd9b10>: Failed to establish a new connection: [Errno 111] ECONNREFUSED
2025-01-21 17:35:40.530 25 ERROR cinder.volume.drivers.lightos 
2025-01-21 17:35:40.530 25 ERROR cinder.volume.drivers.lightos During handling of the above exception, another exception occurred:
2025-01-21 17:35:40.530 25 ERROR cinder.volume.drivers.lightos 
2025-01-21 17:35:40.530 25 ERROR cinder.volume.drivers.lightos Traceback (most recent call last):
2025-01-21 17:35:40.530 25 ERROR cinder.volume.drivers.lightos   File "/var/lib/kolla/venv/lib/python3.10/site-packages/requests/adapters.py", line 667, in send
2025-01-21 17:35:40.530 25 ERROR cinder.volume.drivers.lightos     resp = conn.urlopen(
2025-01-21 17:35:40.530 25 ERROR cinder.volume.drivers.lightos   File "/var/lib/kolla/venv/lib/python3.10/site-packages/urllib3/connectionpool.py", line 801, in urlopen
2025-01-21 17:35:40.530 25 ERROR cinder.volume.drivers.lightos     retries = retries.increment(
2025-01-21 17:35:40.530 25 ERROR cinder.volume.drivers.lightos   File "/var/lib/kolla/venv/lib/python3.10/site-packages/urllib3/util/retry.py", line 594, in increment
2025-01-21 17:35:40.530 25 ERROR cinder.volume.drivers.lightos     raise MaxRetryError(_pool, url, error or ResponseError(cause))
2025-01-21 17:35:40.530 25 ERROR cinder.volume.drivers.lightos urllib3.exceptions.MaxRetryError: HTTPSConnectionPool(host='[LB_IP_ADDRESS]', port=443): Max retries exceeded with url: /api/v2/clusterinfo (Caused by NewConnectionError('<urllib3.connection.HTTPSConnection object at 0x7ff4fbfd9b10>: Failed to establish a new connection: [Errno 111] ECONNREFUSED'))
2025-01-21 17:35:40.530 25 ERROR cinder.volume.drivers.lightos 
2025-01-21 17:35:40.530 25 ERROR cinder.volume.drivers.lightos During handling of the above exception, another exception occurred:
2025-01-21 17:35:40.530 25 ERROR cinder.volume.drivers.lightos 
2025-01-21 17:35:40.530 25 ERROR cinder.volume.drivers.lightos Traceback (most recent call last):
2025-01-21 17:35:40.530 25 ERROR cinder.volume.drivers.lightos   File "/var/lib/kolla/venv/lib/python3.10/site-packages/cinder/volume/drivers/lightos.py", line 356, in __send_cmd
2025-01-21 17:35:40.530 25 ERROR cinder.volume.drivers.lightos     response = session.send(
2025-01-21 17:35:40.530 25 ERROR cinder.volume.drivers.lightos   File "/var/lib/kolla/venv/lib/python3.10/site-packages/requests/sessions.py", line 703, in send
2025-01-21 17:35:40.530 25 ERROR cinder.volume.drivers.lightos     r = adapter.send(request, **kwargs)
2025-01-21 17:35:40.530 25 ERROR cinder.volume.drivers.lightos   File "/var/lib/kolla/venv/lib/python3.10/site-packages/requests/adapters.py", line 700, in send
2025-01-21 17:35:40.530 25 ERROR cinder.volume.drivers.lightos     raise ConnectionError(e, request=request)
2025-01-21 17:35:40.530 25 ERROR cinder.volume.drivers.lightos requests.exceptions.ConnectionError: HTTPSConnectionPool(host='[LB_IP_ADDRESS]', port=443): Max retries exceeded with url: /api/v2/clusterinfo (Caused by NewConnectionError('<urllib3.connection.HTTPSConnection object at 0x7ff4fbfd9b10>: Failed to establish a new connection: [Errno 111] ECONNREFUSED'))
2025-01-21 17:35:40.530 25 ERROR cinder.volume.drivers.lightos 
2025-01-21 17:35:40.532 25 INFO cinder.volume.drivers.lightos [None req-c0a51630-b5a9-4475-9c7a-8d313e57175d - - - - - -] Invoking get_cluster_info using GET url: /api/v2/clusterinfo             request.body: {} ssl_verify: False
2025-01-21 17:35:40.533 25 ERROR cinder.volume.drivers.lightos [None req-c0a51630-b5a9-4475-9c7a-8d313e57175d - - - - - -] REST server not responding at 'https://[LB_IP_ADDRESS]:443/api/v2/clusterinfo': requests.exceptions.ConnectionError: HTTPSConnectionPool(host='[LB_IP_ADDRESS]', port=443): Max retries exceeded with url: /api/v2/clusterinfo (Caused by NewConnectionError('<urllib3.connection.HTTPSConnection object at 0x7ff4fbfd8e50>: Failed to establish a new connection: [Errno 111] ECONNREFUSED'))
2025-01-21 17:35:40.533 25 ERROR cinder.volume.drivers.lightos Traceback (most recent call last):
2025-01-21 17:35:40.533 25 ERROR cinder.volume.drivers.lightos   File "/var/lib/kolla/venv/lib/python3.10/site-packages/urllib3/connection.py", line 174, in _new_conn
2025-01-21 17:35:40.533 25 ERROR cinder.volume.drivers.lightos     conn = connection.create_connection(
2025-01-21 17:35:40.533 25 ERROR cinder.volume.drivers.lightos   File "/var/lib/kolla/venv/lib/python3.10/site-packages/urllib3/util/connection.py", line 95, in create_connection
2025-01-21 17:35:40.533 25 ERROR cinder.volume.drivers.lightos     raise err
2025-01-21 17:35:40.533 25 ERROR cinder.volume.drivers.lightos   File "/var/lib/kolla/venv/lib/python3.10/site-packages/urllib3/util/connection.py", line 85, in create_connection
2025-01-21 17:35:40.533 25 ERROR cinder.volume.drivers.lightos     sock.connect(sa)
2025-01-21 17:35:40.533 25 ERROR cinder.volume.drivers.lightos   File "/var/lib/kolla/venv/lib/python3.10/site-packages/eventlet/greenio/base.py", line 265, in connect
2025-01-21 17:35:40.533 25 ERROR cinder.volume.drivers.lightos     socket_checkerr(fd)
2025-01-21 17:35:40.533 25 ERROR cinder.volume.drivers.lightos   File "/var/lib/kolla/venv/lib/python3.10/site-packages/eventlet/greenio/base.py", line 50, in socket_checkerr
2025-01-21 17:35:40.533 25 ERROR cinder.volume.drivers.lightos     raise OSError(err, errno.errorcode[err])
2025-01-21 17:35:40.533 25 ERROR cinder.volume.drivers.lightos ConnectionRefusedError: [Errno 111] ECONNREFUSED
2025-01-21 17:35:40.533 25 ERROR cinder.volume.drivers.lightos 
2025-01-21 17:35:40.533 25 ERROR cinder.volume.drivers.lightos During handling of the above exception, another exception occurred:
2025-01-21 17:35:40.533 25 ERROR cinder.volume.drivers.lightos 
2025-01-21 17:35:40.533 25 ERROR cinder.volume.drivers.lightos Traceback (most recent call last):
2025-01-21 17:35:40.533 25 ERROR cinder.volume.drivers.lightos   File "/var/lib/kolla/venv/lib/python3.10/site-packages/urllib3/connectionpool.py", line 715, in urlopen
2025-01-21 17:35:40.533 25 ERROR cinder.volume.drivers.lightos     httplib_response = self._make_request(
2025-01-21 17:35:40.533 25 ERROR cinder.volume.drivers.lightos   File "/var/lib/kolla/venv/lib/python3.10/site-packages/urllib3/connectionpool.py", line 404, in _make_request
2025-01-21 17:35:40.533 25 ERROR cinder.volume.drivers.lightos     self._validate_conn(conn)
2025-01-21 17:35:40.533 25 ERROR cinder.volume.drivers.lightos   File "/var/lib/kolla/venv/lib/python3.10/site-packages/urllib3/connectionpool.py", line 1060, in _validate_conn
2025-01-21 17:35:40.533 25 ERROR cinder.volume.drivers.lightos     conn.connect()
2025-01-21 17:35:40.533 25 ERROR cinder.volume.drivers.lightos   File "/var/lib/kolla/venv/lib/python3.10/site-packages/urllib3/connection.py", line 363, in connect
2025-01-21 17:35:40.533 25 ERROR cinder.volume.drivers.lightos     self.sock = conn = self._new_conn()
2025-01-21 17:35:40.533 25 ERROR cinder.volume.drivers.lightos   File "/var/lib/kolla/venv/lib/python3.10/site-packages/urllib3/connection.py", line 186, in _new_conn
2025-01-21 17:35:40.533 25 ERROR cinder.volume.drivers.lightos     raise NewConnectionError(
2025-01-21 17:35:40.533 25 ERROR cinder.volume.drivers.lightos urllib3.exceptions.NewConnectionError: <urllib3.connection.HTTPSConnection object at 0x7ff4fbfd8e50>: Failed to establish a new connection: [Errno 111] ECONNREFUSED
2025-01-21 17:35:40.533 25 ERROR cinder.volume.drivers.lightos 
2025-01-21 17:35:40.533 25 ERROR cinder.volume.drivers.lightos During handling of the above exception, another exception occurred:
2025-01-21 17:35:40.533 25 ERROR cinder.volume.drivers.lightos 
2025-01-21 17:35:40.533 25 ERROR cinder.volume.drivers.lightos Traceback (most recent call last):
2025-01-21 17:35:40.533 25 ERROR cinder.volume.drivers.lightos   File "/var/lib/kolla/venv/lib/python3.10/site-packages/requests/adapters.py", line 667, in send
2025-01-21 17:35:40.533 25 ERROR cinder.volume.drivers.lightos     resp = conn.urlopen(
2025-01-21 17:35:40.533 25 ERROR cinder.volume.drivers.lightos   File "/var/lib/kolla/venv/lib/python3.10/site-packages/urllib3/connectionpool.py", line 801, in urlopen
2025-01-21 17:35:40.533 25 ERROR cinder.volume.drivers.lightos     retries = retries.increment(
2025-01-21 17:35:40.533 25 ERROR cinder.volume.drivers.lightos   File "/var/lib/kolla/venv/lib/python3.10/site-packages/urllib3/util/retry.py", line 594, in increment
2025-01-21 17:35:40.533 25 ERROR cinder.volume.drivers.lightos     raise MaxRetryError(_pool, url, error or ResponseError(cause))
2025-01-21 17:35:40.533 25 ERROR cinder.volume.drivers.lightos urllib3.exceptions.MaxRetryError: HTTPSConnectionPool(host='[LB_IP_ADDRESS]', port=443): Max retries exceeded with url: /api/v2/clusterinfo (Caused by NewConnectionError('<urllib3.connection.HTTPSConnection object at 0x7ff4fbfd8e50>: Failed to establish a new connection: [Errno 111] ECONNREFUSED'))
2025-01-21 17:35:40.533 25 ERROR cinder.volume.drivers.lightos 
2025-01-21 17:35:40.533 25 ERROR cinder.volume.drivers.lightos During handling of the above exception, another exception occurred:
2025-01-21 17:35:40.533 25 ERROR cinder.volume.drivers.lightos 
2025-01-21 17:35:40.533 25 ERROR cinder.volume.drivers.lightos Traceback (most recent call last):
2025-01-21 17:35:40.533 25 ERROR cinder.volume.drivers.lightos   File "/var/lib/kolla/venv/lib/python3.10/site-packages/cinder/volume/drivers/lightos.py", line 356, in __send_cmd
2025-01-21 17:35:40.533 25 ERROR cinder.volume.drivers.lightos     response = session.send(
2025-01-21 17:35:40.533 25 ERROR cinder.volume.drivers.lightos   File "/var/lib/kolla/venv/lib/python3.10/site-packages/requests/sessions.py", line 703, in send
2025-01-21 17:35:40.533 25 ERROR cinder.volume.drivers.lightos     r = adapter.send(request, **kwargs)
2025-01-21 17:35:40.533 25 ERROR cinder.volume.drivers.lightos   File "/var/lib/kolla/venv/lib/python3.10/site-packages/requests/adapters.py", line 700, in send
2025-01-21 17:35:40.533 25 ERROR cinder.volume.drivers.lightos     raise ConnectionError(e, request=request)
2025-01-21 17:35:40.533 25 ERROR cinder.volume.drivers.lightos requests.exceptions.ConnectionError: HTTPSConnectionPool(host='[LB_IP_ADDRESS]', port=443): Max retries exceeded with url: /api/v2/clusterinfo (Caused by NewConnectionError('<urllib3.connection.HTTPSConnection object at 0x7ff4fbfd8e50>: Failed to establish a new connection: [Errno 111] ECONNREFUSED'))
2025-01-21 17:35:40.533 25 ERROR cinder.volume.drivers.lightos 
2025-01-21 17:35:40.533 25 INFO cinder.volume.drivers.lightos [None req-c0a51630-b5a9-4475-9c7a-8d313e57175d - - - - - -] Invoking get_cluster_info using GET url: /api/v2/clusterinfo             request.body: {} ssl_verify: False
2025-01-21 17:35:43.585 25 ERROR cinder.volume.drivers.lightos [None req-c0a51630-b5a9-4475-9c7a-8d313e57175d - - - - - -] REST server not responding at 'https://[LB_IP_ADDRESS]:443/api/v2/clusterinfo': requests.exceptions.ConnectionError: HTTPSConnectionPool(host='[LB_IP_ADDRESS]', port=443): Max retries exceeded with url: /api/v2/clusterinfo (Caused by NewConnectionError('<urllib3.connection.HTTPSConnection object at 0x7ff4fbfd8370>: Failed to establish a new connection: [Errno 113] EHOSTUNREACH'))
2025-01-21 17:35:43.585 25 ERROR cinder.volume.drivers.lightos Traceback (most recent call last):
2025-01-21 17:35:43.585 25 ERROR cinder.volume.drivers.lightos   File "/var/lib/kolla/venv/lib/python3.10/site-packages/urllib3/connection.py", line 174, in _new_conn
2025-01-21 17:35:43.585 25 ERROR cinder.volume.drivers.lightos     conn = connection.create_connection(
2025-01-21 17:35:43.585 25 ERROR cinder.volume.drivers.lightos   File "/var/lib/kolla/venv/lib/python3.10/site-packages/urllib3/util/connection.py", line 95, in create_connection
2025-01-21 17:35:43.585 25 ERROR cinder.volume.drivers.lightos     raise err
2025-01-21 17:35:43.585 25 ERROR cinder.volume.drivers.lightos   File "/var/lib/kolla/venv/lib/python3.10/site-packages/urllib3/util/connection.py", line 85, in create_connection
2025-01-21 17:35:43.585 25 ERROR cinder.volume.drivers.lightos     sock.connect(sa)
2025-01-21 17:35:43.585 25 ERROR cinder.volume.drivers.lightos   File "/var/lib/kolla/venv/lib/python3.10/site-packages/eventlet/greenio/base.py", line 265, in connect
2025-01-21 17:35:43.585 25 ERROR cinder.volume.drivers.lightos     socket_checkerr(fd)
2025-01-21 17:35:43.585 25 ERROR cinder.volume.drivers.lightos   File "/var/lib/kolla/venv/lib/python3.10/site-packages/eventlet/greenio/base.py", line 50, in socket_checkerr
2025-01-21 17:35:43.585 25 ERROR cinder.volume.drivers.lightos     raise OSError(err, errno.errorcode[err])
2025-01-21 17:35:43.585 25 ERROR cinder.volume.drivers.lightos OSError: [Errno 113] EHOSTUNREACH
2025-01-21 17:35:43.585 25 ERROR cinder.volume.drivers.lightos 
2025-01-21 17:35:43.585 25 ERROR cinder.volume.drivers.lightos During handling of the above exception, another exception occurred:
2025-01-21 17:35:43.585 25 ERROR cinder.volume.drivers.lightos 
2025-01-21 17:35:43.585 25 ERROR cinder.volume.drivers.lightos Traceback (most recent call last):
2025-01-21 17:35:43.585 25 ERROR cinder.volume.drivers.lightos   File "/var/lib/kolla/venv/lib/python3.10/site-packages/urllib3/connectionpool.py", line 715, in urlopen
2025-01-21 17:35:43.585 25 ERROR cinder.volume.drivers.lightos     httplib_response = self._make_request(
2025-01-21 17:35:43.585 25 ERROR cinder.volume.drivers.lightos   File "/var/lib/kolla/venv/lib/python3.10/site-packages/urllib3/connectionpool.py", line 404, in _make_request
2025-01-21 17:35:43.585 25 ERROR cinder.volume.drivers.lightos     self._validate_conn(conn)
2025-01-21 17:35:43.585 25 ERROR cinder.volume.drivers.lightos   File "/var/lib/kolla/venv/lib/python3.10/site-packages/urllib3/connectionpool.py", line 1060, in _validate_conn
2025-01-21 17:35:43.585 25 ERROR cinder.volume.drivers.lightos     conn.connect()
2025-01-21 17:35:43.585 25 ERROR cinder.volume.drivers.lightos   File "/var/lib/kolla/venv/lib/python3.10/site-packages/urllib3/connection.py", line 363, in connect
2025-01-21 17:35:43.585 25 ERROR cinder.volume.drivers.lightos     self.sock = conn = self._new_conn()
2025-01-21 17:35:43.585 25 ERROR cinder.volume.drivers.lightos   File "/var/lib/kolla/venv/lib/python3.10/site-packages/urllib3/connection.py", line 186, in _new_conn
2025-01-21 17:35:43.585 25 ERROR cinder.volume.drivers.lightos     raise NewConnectionError(
2025-01-21 17:35:43.585 25 ERROR cinder.volume.drivers.lightos urllib3.exceptions.NewConnectionError: <urllib3.connection.HTTPSConnection object at 0x7ff4fbfd8370>: Failed to establish a new connection: [Errno 113] EHOSTUNREACH
2025-01-21 17:35:43.585 25 ERROR cinder.volume.drivers.lightos 
2025-01-21 17:35:43.585 25 ERROR cinder.volume.drivers.lightos During handling of the above exception, another exception occurred:
2025-01-21 17:35:43.585 25 ERROR cinder.volume.drivers.lightos 
2025-01-21 17:35:43.585 25 ERROR cinder.volume.drivers.lightos Traceback (most recent call last):
2025-01-21 17:35:43.585 25 ERROR cinder.volume.drivers.lightos   File "/var/lib/kolla/venv/lib/python3.10/site-packages/requests/adapters.py", line 667, in send
2025-01-21 17:35:43.585 25 ERROR cinder.volume.drivers.lightos     resp = conn.urlopen(
2025-01-21 17:35:43.585 25 ERROR cinder.volume.drivers.lightos   File "/var/lib/kolla/venv/lib/python3.10/site-packages/urllib3/connectionpool.py", line 801, in urlopen
2025-01-21 17:35:43.585 25 ERROR cinder.volume.drivers.lightos     retries = retries.increment(
2025-01-21 17:35:43.585 25 ERROR cinder.volume.drivers.lightos   File "/var/lib/kolla/venv/lib/python3.10/site-packages/urllib3/util/retry.py", line 594, in increment
2025-01-21 17:35:43.585 25 ERROR cinder.volume.drivers.lightos     raise MaxRetryError(_pool, url, error or ResponseError(cause))
2025-01-21 17:35:43.585 25 ERROR cinder.volume.drivers.lightos urllib3.exceptions.MaxRetryError: HTTPSConnectionPool(host='[LB_IP_ADDRESS]', port=443): Max retries exceeded with url: /api/v2/clusterinfo (Caused by NewConnectionError('<urllib3.connection.HTTPSConnection object at 0x7ff4fbfd8370>: Failed to establish a new connection: [Errno 113] EHOSTUNREACH'))
2025-01-21 17:35:43.585 25 ERROR cinder.volume.drivers.lightos 
2025-01-21 17:35:43.585 25 ERROR cinder.volume.drivers.lightos During handling of the above exception, another exception occurred:
2025-01-21 17:35:43.585 25 ERROR cinder.volume.drivers.lightos 
2025-01-21 17:35:43.585 25 ERROR cinder.volume.drivers.lightos Traceback (most recent call last):
2025-01-21 17:35:43.585 25 ERROR cinder.volume.drivers.lightos   File "/var/lib/kolla/venv/lib/python3.10/site-packages/cinder/volume/drivers/lightos.py", line 356, in __send_cmd
2025-01-21 17:35:43.585 25 ERROR cinder.volume.drivers.lightos     response = session.send(
2025-01-21 17:35:43.585 25 ERROR cinder.volume.drivers.lightos   File "/var/lib/kolla/venv/lib/python3.10/site-packages/requests/sessions.py", line 703, in send
2025-01-21 17:35:43.585 25 ERROR cinder.volume.drivers.lightos     r = adapter.send(request, **kwargs)
2025-01-21 17:35:43.585 25 ERROR cinder.volume.drivers.lightos   File "/var/lib/kolla/venv/lib/python3.10/site-packages/requests/adapters.py", line 700, in send
2025-01-21 17:35:43.585 25 ERROR cinder.volume.drivers.lightos     raise ConnectionError(e, request=request)
2025-01-21 17:35:43.585 25 ERROR cinder.volume.drivers.lightos requests.exceptions.ConnectionError: HTTPSConnectionPool(host='[LB_IP_ADDRESS]', port=443): Max retries exceeded with url: /api/v2/clusterinfo (Caused by NewConnectionError('<urllib3.connection.HTTPSConnection object at 0x7ff4fbfd8370>: Failed to establish a new connection: [Errno 113] EHOSTUNREACH'))
2025-01-21 17:35:43.585 25 ERROR cinder.volume.drivers.lightos 
2025-01-21 17:35:43.588 25 ERROR cinder.volume.manager [None req-c0a51630-b5a9-4475-9c7a-8d313e57175d - - - - - -] Failed to initialize driver.: cinder.exception.VolumeDriverException: Volume driver reported an error: Could not get a response from any API server
2025-01-21 17:35:43.588 25 ERROR cinder.volume.manager Traceback (most recent call last):
2025-01-21 17:35:43.588 25 ERROR cinder.volume.manager   File "/var/lib/kolla/venv/lib/python3.10/site-packages/cinder/volume/manager.py", line 523, in _init_host
2025-01-21 17:35:43.588 25 ERROR cinder.volume.manager     self.driver.do_setup(ctxt)
2025-01-21 17:35:43.588 25 ERROR cinder.volume.manager   File "/var/lib/kolla/venv/lib/python3.10/site-packages/cinder/volume/drivers/lightos.py", line 922, in do_setup
2025-01-21 17:35:43.588 25 ERROR cinder.volume.manager     self.get_cluster_info()
2025-01-21 17:35:43.588 25 ERROR cinder.volume.manager   File "/var/lib/kolla/venv/lib/python3.10/site-packages/cinder/volume/drivers/lightos.py", line 873, in get_cluster_info
2025-01-21 17:35:43.588 25 ERROR cinder.volume.manager     status_code, cluster_info = self.cluster.send_cmd(
2025-01-21 17:35:43.588 25 ERROR cinder.volume.manager   File "/var/lib/kolla/venv/lib/python3.10/site-packages/cinder/volume/drivers/lightos.py", line 315, in send_cmd
2025-01-21 17:35:43.588 25 ERROR cinder.volume.manager     raise exception.VolumeDriverException(
2025-01-21 17:35:43.588 25 ERROR cinder.volume.manager cinder.exception.VolumeDriverException: Volume driver reported an error: Could not get a response from any API server
2025-01-21 17:35:43.588 25 ERROR cinder.volume.manager 
2025-01-21 17:35:44.593 25 INFO cinder.volume.manager [None req-c0a51630-b5a9-4475-9c7a-8d313e57175d - - - - - -] Starting volume driver LightOSVolumeDriver (2.3.12)
2025-01-21 17:35:44.594 25 INFO cinder.volume.drivers.lightos [None req-c0a51630-b5a9-4475-9c7a-8d313e57175d - - - - - -] Invoking get_cluster_info using GET url: /api/v2/clusterinfo             request.body: {} ssl_verify: False
2025-01-21 17:35:44.598 25 ERROR cinder.volume.drivers.lightos [None req-c0a51630-b5a9-4475-9c7a-8d313e57175d - - - - - -] REST server not responding at 'https://[LB_IP_ADDRESS]:443/api/v2/clusterinfo': requests.exceptions.ConnectionError: HTTPSConnectionPool(host='[LB_IP_ADDRESS]', port=443): Max retries exceeded with url: /api/v2/clusterinfo (Caused by NewConnectionError('<urllib3.connection.HTTPSConnection object at 0x7ff4fbfd8700>: Failed to establish a new connection: [Errno 111] ECONNREFUSED'))
2025-01-21 17:35:44.598 25 ERROR cinder.volume.drivers.lightos Traceback (most recent call last):
2025-01-21 17:35:44.598 25 ERROR cinder.volume.drivers.lightos   File "/var/lib/kolla/venv/lib/python3.10/site-packages/urllib3/connection.py", line 174, in _new_conn
2025-01-21 17:35:44.598 25 ERROR cinder.volume.drivers.lightos     conn = connection.create_connection(
2025-01-21 17:35:44.598 25 ERROR cinder.volume.drivers.lightos   File "/var/lib/kolla/venv/lib/python3.10/site-packages/urllib3/util/connection.py", line 95, in create_connection
2025-01-21 17:35:44.598 25 ERROR cinder.volume.drivers.lightos     raise err
2025-01-21 17:35:44.598 25 ERROR cinder.volume.drivers.lightos   File "/var/lib/kolla/venv/lib/python3.10/site-packages/urllib3/util/connection.py", line 85, in create_connection
2025-01-21 17:35:44.598 25 ERROR cinder.volume.drivers.lightos     sock.connect(sa)
2025-01-21 17:35:44.598 25 ERROR cinder.volume.drivers.lightos   File "/var/lib/kolla/venv/lib/python3.10/site-packages/eventlet/greenio/base.py", line 265, in connect
2025-01-21 17:35:44.598 25 ERROR cinder.volume.drivers.lightos     socket_checkerr(fd)
2025-01-21 17:35:44.598 25 ERROR cinder.volume.drivers.lightos   File "/var/lib/kolla/venv/lib/python3.10/site-packages/eventlet/greenio/base.py", line 50, in socket_checkerr
2025-01-21 17:35:44.598 25 ERROR cinder.volume.drivers.lightos     raise OSError(err, errno.errorcode[err])
2025-01-21 17:35:44.598 25 ERROR cinder.volume.drivers.lightos ConnectionRefusedError: [Errno 111] ECONNREFUSED
2025-01-21 17:35:44.598 25 ERROR cinder.volume.drivers.lightos 
2025-01-21 17:35:44.598 25 ERROR cinder.volume.drivers.lightos During handling of the above exception, another exception occurred:
2025-01-21 17:35:44.598 25 ERROR cinder.volume.drivers.lightos 
2025-01-21 17:35:44.598 25 ERROR cinder.volume.drivers.lightos Traceback (most recent call last):
2025-01-21 17:35:44.598 25 ERROR cinder.volume.drivers.lightos   File "/var/lib/kolla/venv/lib/python3.10/site-packages/urllib3/connectionpool.py", line 715, in urlopen
2025-01-21 17:35:44.598 25 ERROR cinder.volume.drivers.lightos     httplib_response = self._make_request(
2025-01-21 17:35:44.598 25 ERROR cinder.volume.drivers.lightos   File "/var/lib/kolla/venv/lib/python3.10/site-packages/urllib3/connectionpool.py", line 404, in _make_request
2025-01-21 17:35:44.598 25 ERROR cinder.volume.drivers.lightos     self._validate_conn(conn)
2025-01-21 17:35:44.598 25 ERROR cinder.volume.drivers.lightos   File "/var/lib/kolla/venv/lib/python3.10/site-packages/urllib3/connectionpool.py", line 1060, in _validate_conn
2025-01-21 17:35:44.598 25 ERROR cinder.volume.drivers.lightos     conn.connect()
2025-01-21 17:35:44.598 25 ERROR cinder.volume.drivers.lightos   File "/var/lib/kolla/venv/lib/python3.10/site-packages/urllib3/connection.py", line 363, in connect
2025-01-21 17:35:44.598 25 ERROR cinder.volume.drivers.lightos     self.sock = conn = self._new_conn()
2025-01-21 17:35:44.598 25 ERROR cinder.volume.drivers.lightos   File "/var/lib/kolla/venv/lib/python3.10/site-packages/urllib3/connection.py", line 186, in _new_conn
2025-01-21 17:35:44.598 25 ERROR cinder.volume.drivers.lightos     raise NewConnectionError(
2025-01-21 17:35:44.598 25 ERROR cinder.volume.drivers.lightos urllib3.exceptions.NewConnectionError: <urllib3.connection.HTTPSConnection object at 0x7ff4fbfd8700>: Failed to establish a new connection: [Errno 111] ECONNREFUSED
2025-01-21 17:35:44.598 25 ERROR cinder.volume.drivers.lightos 
2025-01-21 17:35:44.598 25 ERROR cinder.volume.drivers.lightos During handling of the above exception, another exception occurred:
2025-01-21 17:35:44.598 25 ERROR cinder.volume.drivers.lightos 
2025-01-21 17:35:44.598 25 ERROR cinder.volume.drivers.lightos Traceback (most recent call last):
2025-01-21 17:35:44.598 25 ERROR cinder.volume.drivers.lightos   File "/var/lib/kolla/venv/lib/python3.10/site-packages/requests/adapters.py", line 667, in send
2025-01-21 17:35:44.598 25 ERROR cinder.volume.drivers.lightos     resp = conn.urlopen(
2025-01-21 17:35:44.598 25 ERROR cinder.volume.drivers.lightos   File "/var/lib/kolla/venv/lib/python3.10/site-packages/urllib3/connectionpool.py", line 801, in urlopen
2025-01-21 17:35:44.598 25 ERROR cinder.volume.drivers.lightos     retries = retries.increment(
2025-01-21 17:35:44.598 25 ERROR cinder.volume.drivers.lightos   File "/var/lib/kolla/venv/lib/python3.10/site-packages/urllib3/util/retry.py", line 594, in increment
2025-01-21 17:35:44.598 25 ERROR cinder.volume.drivers.lightos     raise MaxRetryError(_pool, url, error or ResponseError(cause))
2025-01-21 17:35:44.598 25 ERROR cinder.volume.drivers.lightos urllib3.exceptions.MaxRetryError: HTTPSConnectionPool(host='[LB_IP_ADDRESS]', port=443): Max retries exceeded with url: /api/v2/clusterinfo (Caused by NewConnectionError('<urllib3.connection.HTTPSConnection object at 0x7ff4fbfd8700>: Failed to establish a new connection: [Errno 111] ECONNREFUSED'))
2025-01-21 17:35:44.598 25 ERROR cinder.volume.drivers.lightos 
2025-01-21 17:35:44.598 25 ERROR cinder.volume.drivers.lightos During handling of the above exception, another exception occurred:
2025-01-21 17:35:44.598 25 ERROR cinder.volume.drivers.lightos 
2025-01-21 17:35:44.598 25 ERROR cinder.volume.drivers.lightos Traceback (most recent call last):
2025-01-21 17:35:44.598 25 ERROR cinder.volume.drivers.lightos   File "/var/lib/kolla/venv/lib/python3.10/site-packages/cinder/volume/drivers/lightos.py", line 356, in __send_cmd
2025-01-21 17:35:44.598 25 ERROR cinder.volume.drivers.lightos     response = session.send(
2025-01-21 17:35:44.598 25 ERROR cinder.volume.drivers.lightos   File "/var/lib/kolla/venv/lib/python3.10/site-packages/requests/sessions.py", line 703, in send
2025-01-21 17:35:44.598 25 ERROR cinder.volume.drivers.lightos     r = adapter.send(request, **kwargs)
2025-01-21 17:35:44.598 25 ERROR cinder.volume.drivers.lightos   File "/var/lib/kolla/venv/lib/python3.10/site-packages/requests/adapters.py", line 700, in send
2025-01-21 17:35:44.598 25 ERROR cinder.volume.drivers.lightos     raise ConnectionError(e, request=request)
2025-01-21 17:35:44.598 25 ERROR cinder.volume.drivers.lightos requests.exceptions.ConnectionError: HTTPSConnectionPool(host='[LB_IP_ADDRESS]', port=443): Max retries exceeded with url: /api/v2/clusterinfo (Caused by NewConnectionError('<urllib3.connection.HTTPSConnection object at 0x7ff4fbfd8700>: Failed to establish a new connection: [Errno 111] ECONNREFUSED'))
2025-01-21 17:35:44.598 25 ERROR cinder.volume.drivers.lightos 
2025-01-21 17:35:44.600 25 INFO cinder.volume.drivers.lightos [None req-c0a51630-b5a9-4475-9c7a-8d313e57175d - - - - - -] Invoking get_cluster_info using GET url: /api/v2/clusterinfo             request.body: {} ssl_verify: False
2025-01-21 17:35:44.602 25 ERROR cinder.volume.drivers.lightos [None req-c0a51630-b5a9-4475-9c7a-8d313e57175d - - - - - -] REST server not responding at 'https://[LB_IP_ADDRESS]:443/api/v2/clusterinfo': requests.exceptions.ConnectionError: HTTPSConnectionPool(host='[LB_IP_ADDRESS]', port=443): Max retries exceeded with url: /api/v2/clusterinfo (Caused by NewConnectionError('<urllib3.connection.HTTPSConnection object at 0x7ff4fbfd9150>: Failed to establish a new connection: [Errno 111] ECONNREFUSED'))
2025-01-21 17:35:44.602 25 ERROR cinder.volume.drivers.lightos Traceback (most recent call last):
2025-01-21 17:35:44.602 25 ERROR cinder.volume.drivers.lightos   File "/var/lib/kolla/venv/lib/python3.10/site-packages/urllib3/connection.py", line 174, in _new_conn
2025-01-21 17:35:44.602 25 ERROR cinder.volume.drivers.lightos     conn = connection.create_connection(
2025-01-21 17:35:44.602 25 ERROR cinder.volume.drivers.lightos   File "/var/lib/kolla/venv/lib/python3.10/site-packages/urllib3/util/connection.py", line 95, in create_connection
2025-01-21 17:35:44.602 25 ERROR cinder.volume.drivers.lightos     raise err
2025-01-21 17:35:44.602 25 ERROR cinder.volume.drivers.lightos   File "/var/lib/kolla/venv/lib/python3.10/site-packages/urllib3/util/connection.py", line 85, in create_connection
2025-01-21 17:35:44.602 25 ERROR cinder.volume.drivers.lightos     sock.connect(sa)
2025-01-21 17:35:44.602 25 ERROR cinder.volume.drivers.lightos   File "/var/lib/kolla/venv/lib/python3.10/site-packages/eventlet/greenio/base.py", line 265, in connect
2025-01-21 17:35:44.602 25 ERROR cinder.volume.drivers.lightos     socket_checkerr(fd)
2025-01-21 17:35:44.602 25 ERROR cinder.volume.drivers.lightos   File "/var/lib/kolla/venv/lib/python3.10/site-packages/eventlet/greenio/base.py", line 50, in socket_checkerr
2025-01-21 17:35:44.602 25 ERROR cinder.volume.drivers.lightos     raise OSError(err, errno.errorcode[err])
2025-01-21 17:35:44.602 25 ERROR cinder.volume.drivers.lightos ConnectionRefusedError: [Errno 111] ECONNREFUSED
2025-01-21 17:35:44.602 25 ERROR cinder.volume.drivers.lightos 
2025-01-21 17:35:44.602 25 ERROR cinder.volume.drivers.lightos During handling of the above exception, another exception occurred:
2025-01-21 17:35:44.602 25 ERROR cinder.volume.drivers.lightos 
2025-01-21 17:35:44.602 25 ERROR cinder.volume.drivers.lightos Traceback (most recent call last):
2025-01-21 17:35:44.602 25 ERROR cinder.volume.drivers.lightos   File "/var/lib/kolla/venv/lib/python3.10/site-packages/urllib3/connectionpool.py", line 715, in urlopen
2025-01-21 17:35:44.602 25 ERROR cinder.volume.drivers.lightos     httplib_response = self._make_request(
2025-01-21 17:35:44.602 25 ERROR cinder.volume.drivers.lightos   File "/var/lib/kolla/venv/lib/python3.10/site-packages/urllib3/connectionpool.py", line 404, in _make_request
2025-01-21 17:35:44.602 25 ERROR cinder.volume.drivers.lightos     self._validate_conn(conn)
2025-01-21 17:35:44.602 25 ERROR cinder.volume.drivers.lightos   File "/var/lib/kolla/venv/lib/python3.10/site-packages/urllib3/connectionpool.py", line 1060, in _validate_conn
2025-01-21 17:35:44.602 25 ERROR cinder.volume.drivers.lightos     conn.connect()
2025-01-21 17:35:44.602 25 ERROR cinder.volume.drivers.lightos   File "/var/lib/kolla/venv/lib/python3.10/site-packages/urllib3/connection.py", line 363, in connect
2025-01-21 17:35:44.602 25 ERROR cinder.volume.drivers.lightos     self.sock = conn = self._new_conn()
2025-01-21 17:35:44.602 25 ERROR cinder.volume.drivers.lightos   File "/var/lib/kolla/venv/lib/python3.10/site-packages/urllib3/connection.py", line 186, in _new_conn
2025-01-21 17:35:44.602 25 ERROR cinder.volume.drivers.lightos     raise NewConnectionError(
2025-01-21 17:35:44.602 25 ERROR cinder.volume.drivers.lightos urllib3.exceptions.NewConnectionError: <urllib3.connection.HTTPSConnection object at 0x7ff4fbfd9150>: Failed to establish a new connection: [Errno 111] ECONNREFUSED
2025-01-21 17:35:44.602 25 ERROR cinder.volume.drivers.lightos 
2025-01-21 17:35:44.602 25 ERROR cinder.volume.drivers.lightos During handling of the above exception, another exception occurred:
2025-01-21 17:35:44.602 25 ERROR cinder.volume.drivers.lightos 
2025-01-21 17:35:44.602 25 ERROR cinder.volume.drivers.lightos Traceback (most recent call last):
2025-01-21 17:35:44.602 25 ERROR cinder.volume.drivers.lightos   File "/var/lib/kolla/venv/lib/python3.10/site-packages/requests/adapters.py", line 667, in send
2025-01-21 17:35:44.602 25 ERROR cinder.volume.drivers.lightos     resp = conn.urlopen(
2025-01-21 17:35:44.602 25 ERROR cinder.volume.drivers.lightos   File "/var/lib/kolla/venv/lib/python3.10/site-packages/urllib3/connectionpool.py", line 801, in urlopen
2025-01-21 17:35:44.602 25 ERROR cinder.volume.drivers.lightos     retries = retries.increment(
2025-01-21 17:35:44.602 25 ERROR cinder.volume.drivers.lightos   File "/var/lib/kolla/venv/lib/python3.10/site-packages/urllib3/util/retry.py", line 594, in increment
2025-01-21 17:35:44.602 25 ERROR cinder.volume.drivers.lightos     raise MaxRetryError(_pool, url, error or ResponseError(cause))
2025-01-21 17:35:44.602 25 ERROR cinder.volume.drivers.lightos urllib3.exceptions.MaxRetryError: HTTPSConnectionPool(host='[LB_IP_ADDRESS]', port=443): Max retries exceeded with url: /api/v2/clusterinfo (Caused by NewConnectionError('<urllib3.connection.HTTPSConnection object at 0x7ff4fbfd9150>: Failed to establish a new connection: [Errno 111] ECONNREFUSED'))
2025-01-21 17:35:44.602 25 ERROR cinder.volume.drivers.lightos 
2025-01-21 17:35:44.602 25 ERROR cinder.volume.drivers.lightos During handling of the above exception, another exception occurred:
2025-01-21 17:35:44.602 25 ERROR cinder.volume.drivers.lightos 
2025-01-21 17:35:44.602 25 ERROR cinder.volume.drivers.lightos Traceback (most recent call last):
2025-01-21 17:35:44.602 25 ERROR cinder.volume.drivers.lightos   File "/var/lib/kolla/venv/lib/python3.10/site-packages/cinder/volume/drivers/lightos.py", line 356, in __send_cmd
2025-01-21 17:35:44.602 25 ERROR cinder.volume.drivers.lightos     response = session.send(
2025-01-21 17:35:44.602 25 ERROR cinder.volume.drivers.lightos   File "/var/lib/kolla/venv/lib/python3.10/site-packages/requests/sessions.py", line 703, in send
2025-01-21 17:35:44.602 25 ERROR cinder.volume.drivers.lightos     r = adapter.send(request, **kwargs)
2025-01-21 17:35:44.602 25 ERROR cinder.volume.drivers.lightos   File "/var/lib/kolla/venv/lib/python3.10/site-packages/requests/adapters.py", line 700, in send
2025-01-21 17:35:44.602 25 ERROR cinder.volume.drivers.lightos     raise ConnectionError(e, request=request)
2025-01-21 17:35:44.602 25 ERROR cinder.volume.drivers.lightos requests.exceptions.ConnectionError: HTTPSConnectionPool(host='[LB_IP_ADDRESS]', port=443): Max retries exceeded with url: /api/v2/clusterinfo (Caused by NewConnectionError('<urllib3.connection.HTTPSConnection object at 0x7ff4fbfd9150>: Failed to establish a new connection: [Errno 111] ECONNREFUSED'))
2025-01-21 17:35:44.602 25 ERROR cinder.volume.drivers.lightos 
2025-01-21 17:35:44.604 25 INFO cinder.volume.drivers.lightos [None req-c0a51630-b5a9-4475-9c7a-8d313e57175d - - - - - -] Invoking get_cluster_info using GET url: /api/v2/clusterinfo             request.body: {} ssl_verify: False
2025-01-21 17:35:46.657 25 ERROR cinder.volume.drivers.lightos [None req-c0a51630-b5a9-4475-9c7a-8d313e57175d - - - - - -] REST server not responding at 'https://[LB_IP_ADDRESS]:443/api/v2/clusterinfo': requests.exceptions.ConnectionError: HTTPSConnectionPool(host='[LB_IP_ADDRESS]', port=443): Max retries exceeded with url: /api/v2/clusterinfo (Caused by NewConnectionError('<urllib3.connection.HTTPSConnection object at 0x7ff4fbfda1d0>: Failed to establish a new connection: [Errno 113] EHOSTUNREACH'))
2025-01-21 17:35:46.657 25 ERROR cinder.volume.drivers.lightos Traceback (most recent call last):
2025-01-21 17:35:46.657 25 ERROR cinder.volume.drivers.lightos   File "/var/lib/kolla/venv/lib/python3.10/site-packages/urllib3/connection.py", line 174, in _new_conn
2025-01-21 17:35:46.657 25 ERROR cinder.volume.drivers.lightos     conn = connection.create_connection(
2025-01-21 17:35:46.657 25 ERROR cinder.volume.drivers.lightos   File "/var/lib/kolla/venv/lib/python3.10/site-packages/urllib3/util/connection.py", line 95, in create_connection
2025-01-21 17:35:46.657 25 ERROR cinder.volume.drivers.lightos     raise err
2025-01-21 17:35:46.657 25 ERROR cinder.volume.drivers.lightos   File "/var/lib/kolla/venv/lib/python3.10/site-packages/urllib3/util/connection.py", line 85, in create_connection
2025-01-21 17:35:46.657 25 ERROR cinder.volume.drivers.lightos     sock.connect(sa)
2025-01-21 17:35:46.657 25 ERROR cinder.volume.drivers.lightos   File "/var/lib/kolla/venv/lib/python3.10/site-packages/eventlet/greenio/base.py", line 265, in connect
2025-01-21 17:35:46.657 25 ERROR cinder.volume.drivers.lightos     socket_checkerr(fd)
2025-01-21 17:35:46.657 25 ERROR cinder.volume.drivers.lightos   File "/var/lib/kolla/venv/lib/python3.10/site-packages/eventlet/greenio/base.py", line 50, in socket_checkerr
2025-01-21 17:35:46.657 25 ERROR cinder.volume.drivers.lightos     raise OSError(err, errno.errorcode[err])
2025-01-21 17:35:46.657 25 ERROR cinder.volume.drivers.lightos OSError: [Errno 113] EHOSTUNREACH
2025-01-21 17:35:46.657 25 ERROR cinder.volume.drivers.lightos 
2025-01-21 17:35:46.657 25 ERROR cinder.volume.drivers.lightos During handling of the above exception, another exception occurred:
2025-01-21 17:35:46.657 25 ERROR cinder.volume.drivers.lightos 
2025-01-21 17:35:46.657 25 ERROR cinder.volume.drivers.lightos Traceback (most recent call last):
2025-01-21 17:35:46.657 25 ERROR cinder.volume.drivers.lightos   File "/var/lib/kolla/venv/lib/python3.10/site-packages/urllib3/connectionpool.py", line 715, in urlopen
2025-01-21 17:35:46.657 25 ERROR cinder.volume.drivers.lightos     httplib_response = self._make_request(
2025-01-21 17:35:46.657 25 ERROR cinder.volume.drivers.lightos   File "/var/lib/kolla/venv/lib/python3.10/site-packages/urllib3/connectionpool.py", line 404, in _make_request
2025-01-21 17:35:46.657 25 ERROR cinder.volume.drivers.lightos     self._validate_conn(conn)
2025-01-21 17:35:46.657 25 ERROR cinder.volume.drivers.lightos   File "/var/lib/kolla/venv/lib/python3.10/site-packages/urllib3/connectionpool.py", line 1060, in _validate_conn
2025-01-21 17:35:46.657 25 ERROR cinder.volume.drivers.lightos     conn.connect()
2025-01-21 17:35:46.657 25 ERROR cinder.volume.drivers.lightos   File "/var/lib/kolla/venv/lib/python3.10/site-packages/urllib3/connection.py", line 363, in connect
2025-01-21 17:35:46.657 25 ERROR cinder.volume.drivers.lightos     self.sock = conn = self._new_conn()
2025-01-21 17:35:46.657 25 ERROR cinder.volume.drivers.lightos   File "/var/lib/kolla/venv/lib/python3.10/site-packages/urllib3/connection.py", line 186, in _new_conn
2025-01-21 17:35:46.657 25 ERROR cinder.volume.drivers.lightos     raise NewConnectionError(
2025-01-21 17:35:46.657 25 ERROR cinder.volume.drivers.lightos urllib3.exceptions.NewConnectionError: <urllib3.connection.HTTPSConnection object at 0x7ff4fbfda1d0>: Failed to establish a new connection: [Errno 113] EHOSTUNREACH
2025-01-21 17:35:46.657 25 ERROR cinder.volume.drivers.lightos 
2025-01-21 17:35:46.657 25 ERROR cinder.volume.drivers.lightos During handling of the above exception, another exception occurred:
2025-01-21 17:35:46.657 25 ERROR cinder.volume.drivers.lightos 
2025-01-21 17:35:46.657 25 ERROR cinder.volume.drivers.lightos Traceback (most recent call last):
2025-01-21 17:35:46.657 25 ERROR cinder.volume.drivers.lightos   File "/var/lib/kolla/venv/lib/python3.10/site-packages/requests/adapters.py", line 667, in send
2025-01-21 17:35:46.657 25 ERROR cinder.volume.drivers.lightos     resp = conn.urlopen(
2025-01-21 17:35:46.657 25 ERROR cinder.volume.drivers.lightos   File "/var/lib/kolla/venv/lib/python3.10/site-packages/urllib3/connectionpool.py", line 801, in urlopen
2025-01-21 17:35:46.657 25 ERROR cinder.volume.drivers.lightos     retries = retries.increment(
2025-01-21 17:35:46.657 25 ERROR cinder.volume.drivers.lightos   File "/var/lib/kolla/venv/lib/python3.10/site-packages/urllib3/util/retry.py", line 594, in increment
2025-01-21 17:35:46.657 25 ERROR cinder.volume.drivers.lightos     raise MaxRetryError(_pool, url, error or ResponseError(cause))
2025-01-21 17:35:46.657 25 ERROR cinder.volume.drivers.lightos urllib3.exceptions.MaxRetryError: HTTPSConnectionPool(host='[LB_IP_ADDRESS]', port=443): Max retries exceeded with url: /api/v2/clusterinfo (Caused by NewConnectionError('<urllib3.connection.HTTPSConnection object at 0x7ff4fbfda1d0>: Failed to establish a new connection: [Errno 113] EHOSTUNREACH'))
2025-01-21 17:35:46.657 25 ERROR cinder.volume.drivers.lightos 
2025-01-21 17:35:46.657 25 ERROR cinder.volume.drivers.lightos During handling of the above exception, another exception occurred:
2025-01-21 17:35:46.657 25 ERROR cinder.volume.drivers.lightos 
2025-01-21 17:35:46.657 25 ERROR cinder.volume.drivers.lightos Traceback (most recent call last):
2025-01-21 17:35:46.657 25 ERROR cinder.volume.drivers.lightos   File "/var/lib/kolla/venv/lib/python3.10/site-packages/cinder/volume/drivers/lightos.py", line 356, in __send_cmd
2025-01-21 17:35:46.657 25 ERROR cinder.volume.drivers.lightos     response = session.send(
2025-01-21 17:35:46.657 25 ERROR cinder.volume.drivers.lightos   File "/var/lib/kolla/venv/lib/python3.10/site-packages/requests/sessions.py", line 703, in send
2025-01-21 17:35:46.657 25 ERROR cinder.volume.drivers.lightos     r = adapter.send(request, **kwargs)
2025-01-21 17:35:46.657 25 ERROR cinder.volume.drivers.lightos   File "/var/lib/kolla/venv/lib/python3.10/site-packages/requests/adapters.py", line 700, in send
2025-01-21 17:35:46.657 25 ERROR cinder.volume.drivers.lightos     raise ConnectionError(e, request=request)
2025-01-21 17:35:46.657 25 ERROR cinder.volume.drivers.lightos requests.exceptions.ConnectionError: HTTPSConnectionPool(host='[LB_IP_ADDRESS]', port=443): Max retries exceeded with url: /api/v2/clusterinfo (Caused by NewConnectionError('<urllib3.connection.HTTPSConnection object at 0x7ff4fbfda1d0>: Failed to establish a new connection: [Errno 113] EHOSTUNREACH'))
2025-01-21 17:35:46.657 25 ERROR cinder.volume.drivers.lightos 
2025-01-21 17:35:46.660 25 ERROR cinder.volume.manager [None req-c0a51630-b5a9-4475-9c7a-8d313e57175d - - - - - -] Failed to initialize driver.: cinder.exception.VolumeDriverException: Volume driver reported an error: Could not get a response from any API server
2025-01-21 17:35:46.660 25 ERROR cinder.volume.manager Traceback (most recent call last):
2025-01-21 17:35:46.660 25 ERROR cinder.volume.manager   File "/var/lib/kolla/venv/lib/python3.10/site-packages/cinder/volume/manager.py", line 523, in _init_host
2025-01-21 17:35:46.660 25 ERROR cinder.volume.manager     self.driver.do_setup(ctxt)
2025-01-21 17:35:46.660 25 ERROR cinder.volume.manager   File "/var/lib/kolla/venv/lib/python3.10/site-packages/cinder/volume/drivers/lightos.py", line 922, in do_setup
2025-01-21 17:35:46.660 25 ERROR cinder.volume.manager     self.get_cluster_info()
2025-01-21 17:35:46.660 25 ERROR cinder.volume.manager   File "/var/lib/kolla/venv/lib/python3.10/site-packages/cinder/volume/drivers/lightos.py", line 873, in get_cluster_info
2025-01-21 17:35:46.660 25 ERROR cinder.volume.manager     status_code, cluster_info = self.cluster.send_cmd(
2025-01-21 17:35:46.660 25 ERROR cinder.volume.manager   File "/var/lib/kolla/venv/lib/python3.10/site-packages/cinder/volume/drivers/lightos.py", line 315, in send_cmd
2025-01-21 17:35:46.660 25 ERROR cinder.volume.manager     raise exception.VolumeDriverException(
2025-01-21 17:35:46.660 25 ERROR cinder.volume.manager cinder.exception.VolumeDriverException: Volume driver reported an error: Could not get a response from any API server
2025-01-21 17:35:46.660 25 ERROR cinder.volume.manager 
2025-01-21 17:35:48.663 25 INFO cinder.volume.manager [None req-c0a51630-b5a9-4475-9c7a-8d313e57175d - - - - - -] Starting volume driver LightOSVolumeDriver (2.3.12)
2025-01-21 17:35:48.664 25 INFO cinder.volume.drivers.lightos [None req-c0a51630-b5a9-4475-9c7a-8d313e57175d - - - - - -] Invoking get_cluster_info using GET url: /api/v2/clusterinfo             request.body: {} ssl_verify: False
2025-01-21 17:35:48.668 25 ERROR cinder.volume.drivers.lightos [None req-c0a51630-b5a9-4475-9c7a-8d313e57175d - - - - - -] REST server not responding at 'https://[LB_IP_ADDRESS]:443/api/v2/clusterinfo': requests.exceptions.ConnectionError: HTTPSConnectionPool(host='[LB_IP_ADDRESS]', port=443): Max retries exceeded with url: /api/v2/clusterinfo (Caused by NewConnectionError('<urllib3.connection.HTTPSConnection object at 0x7ff4fbef4910>: Failed to establish a new connection: [Errno 111] ECONNREFUSED'))
2025-01-21 17:35:48.668 25 ERROR cinder.volume.drivers.lightos Traceback (most recent call last):
2025-01-21 17:35:48.668 25 ERROR cinder.volume.drivers.lightos   File "/var/lib/kolla/venv/lib/python3.10/site-packages/urllib3/connection.py", line 174, in _new_conn
2025-01-21 17:35:48.668 25 ERROR cinder.volume.drivers.lightos     conn = connection.create_connection(
2025-01-21 17:35:48.668 25 ERROR cinder.volume.drivers.lightos   File "/var/lib/kolla/venv/lib/python3.10/site-packages/urllib3/util/connection.py", line 95, in create_connection
2025-01-21 17:35:48.668 25 ERROR cinder.volume.drivers.lightos     raise err
2025-01-21 17:35:48.668 25 ERROR cinder.volume.drivers.lightos   File "/var/lib/kolla/venv/lib/python3.10/site-packages/urllib3/util/connection.py", line 85, in create_connection
2025-01-21 17:35:48.668 25 ERROR cinder.volume.drivers.lightos     sock.connect(sa)
2025-01-21 17:35:48.668 25 ERROR cinder.volume.drivers.lightos   File "/var/lib/kolla/venv/lib/python3.10/site-packages/eventlet/greenio/base.py", line 265, in connect
2025-01-21 17:35:48.668 25 ERROR cinder.volume.drivers.lightos     socket_checkerr(fd)
2025-01-21 17:35:48.668 25 ERROR cinder.volume.drivers.lightos   File "/var/lib/kolla/venv/lib/python3.10/site-packages/eventlet/greenio/base.py", line 50, in socket_checkerr
2025-01-21 17:35:48.668 25 ERROR cinder.volume.drivers.lightos     raise OSError(err, errno.errorcode[err])
2025-01-21 17:35:48.668 25 ERROR cinder.volume.drivers.lightos ConnectionRefusedError: [Errno 111] ECONNREFUSED
2025-01-21 17:35:48.668 25 ERROR cinder.volume.drivers.lightos 
2025-01-21 17:35:48.668 25 ERROR cinder.volume.drivers.lightos During handling of the above exception, another exception occurred:
2025-01-21 17:35:48.668 25 ERROR cinder.volume.drivers.lightos 
2025-01-21 17:35:48.668 25 ERROR cinder.volume.drivers.lightos Traceback (most recent call last):
2025-01-21 17:35:48.668 25 ERROR cinder.volume.drivers.lightos   File "/var/lib/kolla/venv/lib/python3.10/site-packages/urllib3/connectionpool.py", line 715, in urlopen
2025-01-21 17:35:48.668 25 ERROR cinder.volume.drivers.lightos     httplib_response = self._make_request(
2025-01-21 17:35:48.668 25 ERROR cinder.volume.drivers.lightos   File "/var/lib/kolla/venv/lib/python3.10/site-packages/urllib3/connectionpool.py", line 404, in _make_request
2025-01-21 17:35:48.668 25 ERROR cinder.volume.drivers.lightos     self._validate_conn(conn)
2025-01-21 17:35:48.668 25 ERROR cinder.volume.drivers.lightos   File "/var/lib/kolla/venv/lib/python3.10/site-packages/urllib3/connectionpool.py", line 1060, in _validate_conn
2025-01-21 17:35:48.668 25 ERROR cinder.volume.drivers.lightos     conn.connect()
2025-01-21 17:35:48.668 25 ERROR cinder.volume.drivers.lightos   File "/var/lib/kolla/venv/lib/python3.10/site-packages/urllib3/connection.py", line 363, in connect
2025-01-21 17:35:48.668 25 ERROR cinder.volume.drivers.lightos     self.sock = conn = self._new_conn()
2025-01-21 17:35:48.668 25 ERROR cinder.volume.drivers.lightos   File "/var/lib/kolla/venv/lib/python3.10/site-packages/urllib3/connection.py", line 186, in _new_conn
2025-01-21 17:35:48.668 25 ERROR cinder.volume.drivers.lightos     raise NewConnectionError(
2025-01-21 17:35:48.668 25 ERROR cinder.volume.drivers.lightos urllib3.exceptions.NewConnectionError: <urllib3.connection.HTTPSConnection object at 0x7ff4fbef4910>: Failed to establish a new connection: [Errno 111] ECONNREFUSED
2025-01-21 17:35:48.668 25 ERROR cinder.volume.drivers.lightos 
2025-01-21 17:35:48.668 25 ERROR cinder.volume.drivers.lightos During handling of the above exception, another exception occurred:
2025-01-21 17:35:48.668 25 ERROR cinder.volume.drivers.lightos 
2025-01-21 17:35:48.668 25 ERROR cinder.volume.drivers.lightos Traceback (most recent call last):
2025-01-21 17:35:48.668 25 ERROR cinder.volume.drivers.lightos   File "/var/lib/kolla/venv/lib/python3.10/site-packages/requests/adapters.py", line 667, in send
2025-01-21 17:35:48.668 25 ERROR cinder.volume.drivers.lightos     resp = conn.urlopen(
2025-01-21 17:35:48.668 25 ERROR cinder.volume.drivers.lightos   File "/var/lib/kolla/venv/lib/python3.10/site-packages/urllib3/connectionpool.py", line 801, in urlopen
2025-01-21 17:35:48.668 25 ERROR cinder.volume.drivers.lightos     retries = retries.increment(
2025-01-21 17:35:48.668 25 ERROR cinder.volume.drivers.lightos   File "/var/lib/kolla/venv/lib/python3.10/site-packages/urllib3/util/retry.py", line 594, in increment
2025-01-21 17:35:48.668 25 ERROR cinder.volume.drivers.lightos     raise MaxRetryError(_pool, url, error or ResponseError(cause))
2025-01-21 17:35:48.668 25 ERROR cinder.volume.drivers.lightos urllib3.exceptions.MaxRetryError: HTTPSConnectionPool(host='[LB_IP_ADDRESS]', port=443): Max retries exceeded with url: /api/v2/clusterinfo (Caused by NewConnectionError('<urllib3.connection.HTTPSConnection object at 0x7ff4fbef4910>: Failed to establish a new connection: [Errno 111] ECONNREFUSED'))
2025-01-21 17:35:48.668 25 ERROR cinder.volume.drivers.lightos 
2025-01-21 17:35:48.668 25 ERROR cinder.volume.drivers.lightos During handling of the above exception, another exception occurred:
2025-01-21 17:35:48.668 25 ERROR cinder.volume.drivers.lightos 
2025-01-21 17:35:48.668 25 ERROR cinder.volume.drivers.lightos Traceback (most recent call last):
2025-01-21 17:35:48.668 25 ERROR cinder.volume.drivers.lightos   File "/var/lib/kolla/venv/lib/python3.10/site-packages/cinder/volume/drivers/lightos.py", line 356, in __send_cmd
2025-01-21 17:35:48.668 25 ERROR cinder.volume.drivers.lightos     response = session.send(
2025-01-21 17:35:48.668 25 ERROR cinder.volume.drivers.lightos   File "/var/lib/kolla/venv/lib/python3.10/site-packages/requests/sessions.py", line 703, in send
2025-01-21 17:35:48.668 25 ERROR cinder.volume.drivers.lightos     r = adapter.send(request, **kwargs)
2025-01-21 17:35:48.668 25 ERROR cinder.volume.drivers.lightos   File "/var/lib/kolla/venv/lib/python3.10/site-packages/requests/adapters.py", line 700, in send
2025-01-21 17:35:48.668 25 ERROR cinder.volume.drivers.lightos     raise ConnectionError(e, request=request)
2025-01-21 17:35:48.668 25 ERROR cinder.volume.drivers.lightos requests.exceptions.ConnectionError: HTTPSConnectionPool(host='[LB_IP_ADDRESS]', port=443): Max retries exceeded with url: /api/v2/clusterinfo (Caused by NewConnectionError('<urllib3.connection.HTTPSConnection object at 0x7ff4fbef4910>: Failed to establish a new connection: [Errno 111] ECONNREFUSED'))
2025-01-21 17:35:48.668 25 ERROR cinder.volume.drivers.lightos 
2025-01-21 17:35:48.670 25 INFO cinder.volume.drivers.lightos [None req-c0a51630-b5a9-4475-9c7a-8d313e57175d - - - - - -] Invoking get_cluster_info using GET url: /api/v2/clusterinfo             request.body: {} ssl_verify: False
2025-01-21 17:35:48.673 25 ERROR cinder.volume.drivers.lightos [None req-c0a51630-b5a9-4475-9c7a-8d313e57175d - - - - - -] REST server not responding at 'https://[LB_IP_ADDRESS]:443/api/v2/clusterinfo': requests.exceptions.ConnectionError: HTTPSConnectionPool(host='[LB_IP_ADDRESS]', port=443): Max retries exceeded with url: /api/v2/clusterinfo (Caused by NewConnectionError('<urllib3.connection.HTTPSConnection object at 0x7ff4fbef53f0>: Failed to establish a new connection: [Errno 111] ECONNREFUSED'))
2025-01-21 17:35:48.673 25 ERROR cinder.volume.drivers.lightos Traceback (most recent call last):
2025-01-21 17:35:48.673 25 ERROR cinder.volume.drivers.lightos   File "/var/lib/kolla/venv/lib/python3.10/site-packages/urllib3/connection.py", line 174, in _new_conn
2025-01-21 17:35:48.673 25 ERROR cinder.volume.drivers.lightos     conn = connection.create_connection(
2025-01-21 17:35:48.673 25 ERROR cinder.volume.drivers.lightos   File "/var/lib/kolla/venv/lib/python3.10/site-packages/urllib3/util/connection.py", line 95, in create_connection
2025-01-21 17:35:48.673 25 ERROR cinder.volume.drivers.lightos     raise err
2025-01-21 17:35:48.673 25 ERROR cinder.volume.drivers.lightos   File "/var/lib/kolla/venv/lib/python3.10/site-packages/urllib3/util/connection.py", line 85, in create_connection
2025-01-21 17:35:48.673 25 ERROR cinder.volume.drivers.lightos     sock.connect(sa)
2025-01-21 17:35:48.673 25 ERROR cinder.volume.drivers.lightos   File "/var/lib/kolla/venv/lib/python3.10/site-packages/eventlet/greenio/base.py", line 265, in connect
2025-01-21 17:35:48.673 25 ERROR cinder.volume.drivers.lightos     socket_checkerr(fd)
2025-01-21 17:35:48.673 25 ERROR cinder.volume.drivers.lightos   File "/var/lib/kolla/venv/lib/python3.10/site-packages/eventlet/greenio/base.py", line 50, in socket_checkerr
2025-01-21 17:35:48.673 25 ERROR cinder.volume.drivers.lightos     raise OSError(err, errno.errorcode[err])
2025-01-21 17:35:48.673 25 ERROR cinder.volume.drivers.lightos ConnectionRefusedError: [Errno 111] ECONNREFUSED
2025-01-21 17:35:48.673 25 ERROR cinder.volume.drivers.lightos 
2025-01-21 17:35:48.673 25 ERROR cinder.volume.drivers.lightos During handling of the above exception, another exception occurred:
2025-01-21 17:35:48.673 25 ERROR cinder.volume.drivers.lightos 
2025-01-21 17:35:48.673 25 ERROR cinder.volume.drivers.lightos Traceback (most recent call last):
2025-01-21 17:35:48.673 25 ERROR cinder.volume.drivers.lightos   File "/var/lib/kolla/venv/lib/python3.10/site-packages/urllib3/connectionpool.py", line 715, in urlopen
2025-01-21 17:35:48.673 25 ERROR cinder.volume.drivers.lightos     httplib_response = self._make_request(
2025-01-21 17:35:48.673 25 ERROR cinder.volume.drivers.lightos   File "/var/lib/kolla/venv/lib/python3.10/site-packages/urllib3/connectionpool.py", line 404, in _make_request
2025-01-21 17:35:48.673 25 ERROR cinder.volume.drivers.lightos     self._validate_conn(conn)
2025-01-21 17:35:48.673 25 ERROR cinder.volume.drivers.lightos   File "/var/lib/kolla/venv/lib/python3.10/site-packages/urllib3/connectionpool.py", line 1060, in _validate_conn
2025-01-21 17:35:48.673 25 ERROR cinder.volume.drivers.lightos     conn.connect()
2025-01-21 17:35:48.673 25 ERROR cinder.volume.drivers.lightos   File "/var/lib/kolla/venv/lib/python3.10/site-packages/urllib3/connection.py", line 363, in connect
2025-01-21 17:35:48.673 25 ERROR cinder.volume.drivers.lightos     self.sock = conn = self._new_conn()
2025-01-21 17:35:48.673 25 ERROR cinder.volume.drivers.lightos   File "/var/lib/kolla/venv/lib/python3.10/site-packages/urllib3/connection.py", line 186, in _new_conn
2025-01-21 17:35:48.673 25 ERROR cinder.volume.drivers.lightos     raise NewConnectionError(
2025-01-21 17:35:48.673 25 ERROR cinder.volume.drivers.lightos urllib3.exceptions.NewConnectionError: <urllib3.connection.HTTPSConnection object at 0x7ff4fbef53f0>: Failed to establish a new connection: [Errno 111] ECONNREFUSED
2025-01-21 17:35:48.673 25 ERROR cinder.volume.drivers.lightos 
2025-01-21 17:35:48.673 25 ERROR cinder.volume.drivers.lightos During handling of the above exception, another exception occurred:
2025-01-21 17:35:48.673 25 ERROR cinder.volume.drivers.lightos 
2025-01-21 17:35:48.673 25 ERROR cinder.volume.drivers.lightos Traceback (most recent call last):
2025-01-21 17:35:48.673 25 ERROR cinder.volume.drivers.lightos   File "/var/lib/kolla/venv/lib/python3.10/site-packages/requests/adapters.py", line 667, in send
2025-01-21 17:35:48.673 25 ERROR cinder.volume.drivers.lightos     resp = conn.urlopen(
2025-01-21 17:35:48.673 25 ERROR cinder.volume.drivers.lightos   File "/var/lib/kolla/venv/lib/python3.10/site-packages/urllib3/connectionpool.py", line 801, in urlopen
2025-01-21 17:35:48.673 25 ERROR cinder.volume.drivers.lightos     retries = retries.increment(
2025-01-21 17:35:48.673 25 ERROR cinder.volume.drivers.lightos   File "/var/lib/kolla/venv/lib/python3.10/site-packages/urllib3/util/retry.py", line 594, in increment
2025-01-21 17:35:48.673 25 ERROR cinder.volume.drivers.lightos     raise MaxRetryError(_pool, url, error or ResponseError(cause))
2025-01-21 17:35:48.673 25 ERROR cinder.volume.drivers.lightos urllib3.exceptions.MaxRetryError: HTTPSConnectionPool(host='[LB_IP_ADDRESS]', port=443): Max retries exceeded with url: /api/v2/clusterinfo (Caused by NewConnectionError('<urllib3.connection.HTTPSConnection object at 0x7ff4fbef53f0>: Failed to establish a new connection: [Errno 111] ECONNREFUSED'))
2025-01-21 17:35:48.673 25 ERROR cinder.volume.drivers.lightos 
2025-01-21 17:35:48.673 25 ERROR cinder.volume.drivers.lightos During handling of the above exception, another exception occurred:
2025-01-21 17:35:48.673 25 ERROR cinder.volume.drivers.lightos 
2025-01-21 17:35:48.673 25 ERROR cinder.volume.drivers.lightos Traceback (most recent call last):
2025-01-21 17:35:48.673 25 ERROR cinder.volume.drivers.lightos   File "/var/lib/kolla/venv/lib/python3.10/site-packages/cinder/volume/drivers/lightos.py", line 356, in __send_cmd
2025-01-21 17:35:48.673 25 ERROR cinder.volume.drivers.lightos     response = session.send(
2025-01-21 17:35:48.673 25 ERROR cinder.volume.drivers.lightos   File "/var/lib/kolla/venv/lib/python3.10/site-packages/requests/sessions.py", line 703, in send
2025-01-21 17:35:48.673 25 ERROR cinder.volume.drivers.lightos     r = adapter.send(request, **kwargs)
2025-01-21 17:35:48.673 25 ERROR cinder.volume.drivers.lightos   File "/var/lib/kolla/venv/lib/python3.10/site-packages/requests/adapters.py", line 700, in send
2025-01-21 17:35:48.673 25 ERROR cinder.volume.drivers.lightos     raise ConnectionError(e, request=request)
2025-01-21 17:35:48.673 25 ERROR cinder.volume.drivers.lightos requests.exceptions.ConnectionError: HTTPSConnectionPool(host='[LB_IP_ADDRESS]', port=443): Max retries exceeded with url: /api/v2/clusterinfo (Caused by NewConnectionError('<urllib3.connection.HTTPSConnection object at 0x7ff4fbef53f0>: Failed to establish a new connection: [Errno 111] ECONNREFUSED'))
2025-01-21 17:35:48.673 25 ERROR cinder.volume.drivers.lightos 
2025-01-21 17:35:48.675 25 INFO cinder.volume.drivers.lightos [None req-c0a51630-b5a9-4475-9c7a-8d313e57175d - - - - - -] Invoking get_cluster_info using GET url: /api/v2/clusterinfo             request.body: {} ssl_verify: False
2025-01-21 17:35:49.729 25 ERROR cinder.volume.drivers.lightos [None req-c0a51630-b5a9-4475-9c7a-8d313e57175d - - - - - -] REST server not responding at 'https://[LB_IP_ADDRESS]:443/api/v2/clusterinfo': requests.exceptions.ConnectionError: HTTPSConnectionPool(host='[LB_IP_ADDRESS]', port=443): Max retries exceeded with url: /api/v2/clusterinfo (Caused by NewConnectionError('<urllib3.connection.HTTPSConnection object at 0x7ff4fbfda080>: Failed to establish a new connection: [Errno 113] EHOSTUNREACH'))
2025-01-21 17:35:49.729 25 ERROR cinder.volume.drivers.lightos Traceback (most recent call last):
2025-01-21 17:35:49.729 25 ERROR cinder.volume.drivers.lightos   File "/var/lib/kolla/venv/lib/python3.10/site-packages/urllib3/connection.py", line 174, in _new_conn
2025-01-21 17:35:49.729 25 ERROR cinder.volume.drivers.lightos     conn = connection.create_connection(
2025-01-21 17:35:49.729 25 ERROR cinder.volume.drivers.lightos   File "/var/lib/kolla/venv/lib/python3.10/site-packages/urllib3/util/connection.py", line 95, in create_connection
2025-01-21 17:35:49.729 25 ERROR cinder.volume.drivers.lightos     raise err
2025-01-21 17:35:49.729 25 ERROR cinder.volume.drivers.lightos   File "/var/lib/kolla/venv/lib/python3.10/site-packages/urllib3/util/connection.py", line 85, in create_connection
2025-01-21 17:35:49.729 25 ERROR cinder.volume.drivers.lightos     sock.connect(sa)
2025-01-21 17:35:49.729 25 ERROR cinder.volume.drivers.lightos   File "/var/lib/kolla/venv/lib/python3.10/site-packages/eventlet/greenio/base.py", line 265, in connect
2025-01-21 17:35:49.729 25 ERROR cinder.volume.drivers.lightos     socket_checkerr(fd)
2025-01-21 17:35:49.729 25 ERROR cinder.volume.drivers.lightos   File "/var/lib/kolla/venv/lib/python3.10/site-packages/eventlet/greenio/base.py", line 50, in socket_checkerr
2025-01-21 17:35:49.729 25 ERROR cinder.volume.drivers.lightos     raise OSError(err, errno.errorcode[err])
2025-01-21 17:35:49.729 25 ERROR cinder.volume.drivers.lightos OSError: [Errno 113] EHOSTUNREACH
2025-01-21 17:35:49.729 25 ERROR cinder.volume.drivers.lightos 
2025-01-21 17:35:49.729 25 ERROR cinder.volume.drivers.lightos During handling of the above exception, another exception occurred:
2025-01-21 17:35:49.729 25 ERROR cinder.volume.drivers.lightos 
2025-01-21 17:35:49.729 25 ERROR cinder.volume.drivers.lightos Traceback (most recent call last):
2025-01-21 17:35:49.729 25 ERROR cinder.volume.drivers.lightos   File "/var/lib/kolla/venv/lib/python3.10/site-packages/urllib3/connectionpool.py", line 715, in urlopen
2025-01-21 17:35:49.729 25 ERROR cinder.volume.drivers.lightos     httplib_response = self._make_request(
2025-01-21 17:35:49.729 25 ERROR cinder.volume.drivers.lightos   File "/var/lib/kolla/venv/lib/python3.10/site-packages/urllib3/connectionpool.py", line 404, in _make_request
2025-01-21 17:35:49.729 25 ERROR cinder.volume.drivers.lightos     self._validate_conn(conn)
2025-01-21 17:35:49.729 25 ERROR cinder.volume.drivers.lightos   File "/var/lib/kolla/venv/lib/python3.10/site-packages/urllib3/connectionpool.py", line 1060, in _validate_conn
2025-01-21 17:35:49.729 25 ERROR cinder.volume.drivers.lightos     conn.connect()
2025-01-21 17:35:49.729 25 ERROR cinder.volume.drivers.lightos   File "/var/lib/kolla/venv/lib/python3.10/site-packages/urllib3/connection.py", line 363, in connect
2025-01-21 17:35:49.729 25 ERROR cinder.volume.drivers.lightos     self.sock = conn = self._new_conn()
2025-01-21 17:35:49.729 25 ERROR cinder.volume.drivers.lightos   File "/var/lib/kolla/venv/lib/python3.10/site-packages/urllib3/connection.py", line 186, in _new_conn
2025-01-21 17:35:49.729 25 ERROR cinder.volume.drivers.lightos     raise NewConnectionError(
2025-01-21 17:35:49.729 25 ERROR cinder.volume.drivers.lightos urllib3.exceptions.NewConnectionError: <urllib3.connection.HTTPSConnection object at 0x7ff4fbfda080>: Failed to establish a new connection: [Errno 113] EHOSTUNREACH
2025-01-21 17:35:49.729 25 ERROR cinder.volume.drivers.lightos 
2025-01-21 17:35:49.729 25 ERROR cinder.volume.drivers.lightos During handling of the above exception, another exception occurred:
2025-01-21 17:35:49.729 25 ERROR cinder.volume.drivers.lightos 
2025-01-21 17:35:49.729 25 ERROR cinder.volume.drivers.lightos Traceback (most recent call last):
2025-01-21 17:35:49.729 25 ERROR cinder.volume.drivers.lightos   File "/var/lib/kolla/venv/lib/python3.10/site-packages/requests/adapters.py", line 667, in send
2025-01-21 17:35:49.729 25 ERROR cinder.volume.drivers.lightos     resp = conn.urlopen(
2025-01-21 17:35:49.729 25 ERROR cinder.volume.drivers.lightos   File "/var/lib/kolla/venv/lib/python3.10/site-packages/urllib3/connectionpool.py", line 801, in urlopen
2025-01-21 17:35:49.729 25 ERROR cinder.volume.drivers.lightos     retries = retries.increment(
2025-01-21 17:35:49.729 25 ERROR cinder.volume.drivers.lightos   File "/var/lib/kolla/venv/lib/python3.10/site-packages/urllib3/util/retry.py", line 594, in increment
2025-01-21 17:35:49.729 25 ERROR cinder.volume.drivers.lightos     raise MaxRetryError(_pool, url, error or ResponseError(cause))
2025-01-21 17:35:49.729 25 ERROR cinder.volume.drivers.lightos urllib3.exceptions.MaxRetryError: HTTPSConnectionPool(host='[LB_IP_ADDRESS]', port=443): Max retries exceeded with url: /api/v2/clusterinfo (Caused by NewConnectionError('<urllib3.connection.HTTPSConnection object at 0x7ff4fbfda080>: Failed to establish a new connection: [Errno 113] EHOSTUNREACH'))
2025-01-21 17:35:49.729 25 ERROR cinder.volume.drivers.lightos 
2025-01-21 17:35:49.729 25 ERROR cinder.volume.drivers.lightos During handling of the above exception, another exception occurred:
2025-01-21 17:35:49.729 25 ERROR cinder.volume.drivers.lightos 
2025-01-21 17:35:49.729 25 ERROR cinder.volume.drivers.lightos Traceback (most recent call last):
2025-01-21 17:35:49.729 25 ERROR cinder.volume.drivers.lightos   File "/var/lib/kolla/venv/lib/python3.10/site-packages/cinder/volume/drivers/lightos.py", line 356, in __send_cmd
2025-01-21 17:35:49.729 25 ERROR cinder.volume.drivers.lightos     response = session.send(
2025-01-21 17:35:49.729 25 ERROR cinder.volume.drivers.lightos   File "/var/lib/kolla/venv/lib/python3.10/site-packages/requests/sessions.py", line 703, in send
2025-01-21 17:35:49.729 25 ERROR cinder.volume.drivers.lightos     r = adapter.send(request, **kwargs)
2025-01-21 17:35:49.729 25 ERROR cinder.volume.drivers.lightos   File "/var/lib/kolla/venv/lib/python3.10/site-packages/requests/adapters.py", line 700, in send
2025-01-21 17:35:49.729 25 ERROR cinder.volume.drivers.lightos     raise ConnectionError(e, request=request)
2025-01-21 17:35:49.729 25 ERROR cinder.volume.drivers.lightos requests.exceptions.ConnectionError: HTTPSConnectionPool(host='[LB_IP_ADDRESS]', port=443): Max retries exceeded with url: /api/v2/clusterinfo (Caused by NewConnectionError('<urllib3.connection.HTTPSConnection object at 0x7ff4fbfda080>: Failed to establish a new connection: [Errno 113] EHOSTUNREACH'))
2025-01-21 17:35:49.729 25 ERROR cinder.volume.drivers.lightos 
2025-01-21 17:35:49.732 25 ERROR cinder.volume.manager [None req-c0a51630-b5a9-4475-9c7a-8d313e57175d - - - - - -] Failed to initialize driver.: cinder.exception.VolumeDriverException: Volume driver reported an error: Could not get a response from any API server
2025-01-21 17:35:49.732 25 ERROR cinder.volume.manager Traceback (most recent call last):
2025-01-21 17:35:49.732 25 ERROR cinder.volume.manager   File "/var/lib/kolla/venv/lib/python3.10/site-packages/cinder/volume/manager.py", line 523, in _init_host
2025-01-21 17:35:49.732 25 ERROR cinder.volume.manager     self.driver.do_setup(ctxt)
2025-01-21 17:35:49.732 25 ERROR cinder.volume.manager   File "/var/lib/kolla/venv/lib/python3.10/site-packages/cinder/volume/drivers/lightos.py", line 922, in do_setup
2025-01-21 17:35:49.732 25 ERROR cinder.volume.manager     self.get_cluster_info()
2025-01-21 17:35:49.732 25 ERROR cinder.volume.manager   File "/var/lib/kolla/venv/lib/python3.10/site-packages/cinder/volume/drivers/lightos.py", line 873, in get_cluster_info
2025-01-21 17:35:49.732 25 ERROR cinder.volume.manager     status_code, cluster_info = self.cluster.send_cmd(
2025-01-21 17:35:49.732 25 ERROR cinder.volume.manager   File "/var/lib/kolla/venv/lib/python3.10/site-packages/cinder/volume/drivers/lightos.py", line 315, in send_cmd
2025-01-21 17:35:49.732 25 ERROR cinder.volume.manager     raise exception.VolumeDriverException(
2025-01-21 17:35:49.732 25 ERROR cinder.volume.manager cinder.exception.VolumeDriverException: Volume driver reported an error: Could not get a response from any API server
2025-01-21 17:35:49.732 25 ERROR cinder.volume.manager 
2025-01-21 17:35:53.737 25 INFO cinder.volume.manager [None req-c0a51630-b5a9-4475-9c7a-8d313e57175d - - - - - -] Starting volume driver LightOSVolumeDriver (2.3.12)
2025-01-21 17:35:53.738 25 INFO cinder.volume.drivers.lightos [None req-c0a51630-b5a9-4475-9c7a-8d313e57175d - - - - - -] Invoking get_cluster_info using GET url: /api/v2/clusterinfo             request.body: {} ssl_verify: False
2025-01-21 17:35:53.741 25 ERROR cinder.volume.drivers.lightos [None req-c0a51630-b5a9-4475-9c7a-8d313e57175d - - - - - -] REST server not responding at 'https://[LB_IP_ADDRESS]:443/api/v2/clusterinfo': requests.exceptions.ConnectionError: HTTPSConnectionPool(host='[LB_IP_ADDRESS]', port=443): Max retries exceeded with url: /api/v2/clusterinfo (Caused by NewConnectionError('<urllib3.connection.HTTPSConnection object at 0x7ff4fbfd89a0>: Failed to establish a new connection: [Errno 111] ECONNREFUSED'))
2025-01-21 17:35:53.741 25 ERROR cinder.volume.drivers.lightos Traceback (most recent call last):
2025-01-21 17:35:53.741 25 ERROR cinder.volume.drivers.lightos   File "/var/lib/kolla/venv/lib/python3.10/site-packages/urllib3/connection.py", line 174, in _new_conn
2025-01-21 17:35:53.741 25 ERROR cinder.volume.drivers.lightos     conn = connection.create_connection(
2025-01-21 17:35:53.741 25 ERROR cinder.volume.drivers.lightos   File "/var/lib/kolla/venv/lib/python3.10/site-packages/urllib3/util/connection.py", line 95, in create_connection
2025-01-21 17:35:53.741 25 ERROR cinder.volume.drivers.lightos     raise err
2025-01-21 17:35:53.741 25 ERROR cinder.volume.drivers.lightos   File "/var/lib/kolla/venv/lib/python3.10/site-packages/urllib3/util/connection.py", line 85, in create_connection
2025-01-21 17:35:53.741 25 ERROR cinder.volume.drivers.lightos     sock.connect(sa)
2025-01-21 17:35:53.741 25 ERROR cinder.volume.drivers.lightos   File "/var/lib/kolla/venv/lib/python3.10/site-packages/eventlet/greenio/base.py", line 265, in connect
2025-01-21 17:35:53.741 25 ERROR cinder.volume.drivers.lightos     socket_checkerr(fd)
2025-01-21 17:35:53.741 25 ERROR cinder.volume.drivers.lightos   File "/var/lib/kolla/venv/lib/python3.10/site-packages/eventlet/greenio/base.py", line 50, in socket_checkerr
2025-01-21 17:35:53.741 25 ERROR cinder.volume.drivers.lightos     raise OSError(err, errno.errorcode[err])
2025-01-21 17:35:53.741 25 ERROR cinder.volume.drivers.lightos ConnectionRefusedError: [Errno 111] ECONNREFUSED
2025-01-21 17:35:53.741 25 ERROR cinder.volume.drivers.lightos 
2025-01-21 17:35:53.741 25 ERROR cinder.volume.drivers.lightos During handling of the above exception, another exception occurred:
2025-01-21 17:35:53.741 25 ERROR cinder.volume.drivers.lightos 
2025-01-21 17:35:53.741 25 ERROR cinder.volume.drivers.lightos Traceback (most recent call last):
2025-01-21 17:35:53.741 25 ERROR cinder.volume.drivers.lightos   File "/var/lib/kolla/venv/lib/python3.10/site-packages/urllib3/connectionpool.py", line 715, in urlopen
2025-01-21 17:35:53.741 25 ERROR cinder.volume.drivers.lightos     httplib_response = self._make_request(
2025-01-21 17:35:53.741 25 ERROR cinder.volume.drivers.lightos   File "/var/lib/kolla/venv/lib/python3.10/site-packages/urllib3/connectionpool.py", line 404, in _make_request
2025-01-21 17:35:53.741 25 ERROR cinder.volume.drivers.lightos     self._validate_conn(conn)
2025-01-21 17:35:53.741 25 ERROR cinder.volume.drivers.lightos   File "/var/lib/kolla/venv/lib/python3.10/site-packages/urllib3/connectionpool.py", line 1060, in _validate_conn
2025-01-21 17:35:53.741 25 ERROR cinder.volume.drivers.lightos     conn.connect()
2025-01-21 17:35:53.741 25 ERROR cinder.volume.drivers.lightos   File "/var/lib/kolla/venv/lib/python3.10/site-packages/urllib3/connection.py", line 363, in connect
2025-01-21 17:35:53.741 25 ERROR cinder.volume.drivers.lightos     self.sock = conn = self._new_conn()
2025-01-21 17:35:53.741 25 ERROR cinder.volume.drivers.lightos   File "/var/lib/kolla/venv/lib/python3.10/site-packages/urllib3/connection.py", line 186, in _new_conn
2025-01-21 17:35:53.741 25 ERROR cinder.volume.drivers.lightos     raise NewConnectionError(
2025-01-21 17:35:53.741 25 ERROR cinder.volume.drivers.lightos urllib3.exceptions.NewConnectionError: <urllib3.connection.HTTPSConnection object at 0x7ff4fbfd89a0>: Failed to establish a new connection: [Errno 111] ECONNREFUSED
2025-01-21 17:35:53.741 25 ERROR cinder.volume.drivers.lightos 
2025-01-21 17:35:53.741 25 ERROR cinder.volume.drivers.lightos During handling of the above exception, another exception occurred:
2025-01-21 17:35:53.741 25 ERROR cinder.volume.drivers.lightos 
2025-01-21 17:35:53.741 25 ERROR cinder.volume.drivers.lightos Traceback (most recent call last):
2025-01-21 17:35:53.741 25 ERROR cinder.volume.drivers.lightos   File "/var/lib/kolla/venv/lib/python3.10/site-packages/requests/adapters.py", line 667, in send
2025-01-21 17:35:53.741 25 ERROR cinder.volume.drivers.lightos     resp = conn.urlopen(
2025-01-21 17:35:53.741 25 ERROR cinder.volume.drivers.lightos   File "/var/lib/kolla/venv/lib/python3.10/site-packages/urllib3/connectionpool.py", line 801, in urlopen
2025-01-21 17:35:53.741 25 ERROR cinder.volume.drivers.lightos     retries = retries.increment(
2025-01-21 17:35:53.741 25 ERROR cinder.volume.drivers.lightos   File "/var/lib/kolla/venv/lib/python3.10/site-packages/urllib3/util/retry.py", line 594, in increment
2025-01-21 17:35:53.741 25 ERROR cinder.volume.drivers.lightos     raise MaxRetryError(_pool, url, error or ResponseError(cause))
2025-01-21 17:35:53.741 25 ERROR cinder.volume.drivers.lightos urllib3.exceptions.MaxRetryError: HTTPSConnectionPool(host='[LB_IP_ADDRESS]', port=443): Max retries exceeded with url: /api/v2/clusterinfo (Caused by NewConnectionError('<urllib3.connection.HTTPSConnection object at 0x7ff4fbfd89a0>: Failed to establish a new connection: [Errno 111] ECONNREFUSED'))
2025-01-21 17:35:53.741 25 ERROR cinder.volume.drivers.lightos 
2025-01-21 17:35:53.741 25 ERROR cinder.volume.drivers.lightos During handling of the above exception, another exception occurred:
2025-01-21 17:35:53.741 25 ERROR cinder.volume.drivers.lightos 
2025-01-21 17:35:53.741 25 ERROR cinder.volume.drivers.lightos Traceback (most recent call last):
2025-01-21 17:35:53.741 25 ERROR cinder.volume.drivers.lightos   File "/var/lib/kolla/venv/lib/python3.10/site-packages/cinder/volume/drivers/lightos.py", line 356, in __send_cmd
2025-01-21 17:35:53.741 25 ERROR cinder.volume.drivers.lightos     response = session.send(
2025-01-21 17:35:53.741 25 ERROR cinder.volume.drivers.lightos   File "/var/lib/kolla/venv/lib/python3.10/site-packages/requests/sessions.py", line 703, in send
2025-01-21 17:35:53.741 25 ERROR cinder.volume.drivers.lightos     r = adapter.send(request, **kwargs)
2025-01-21 17:35:53.741 25 ERROR cinder.volume.drivers.lightos   File "/var/lib/kolla/venv/lib/python3.10/site-packages/requests/adapters.py", line 700, in send
2025-01-21 17:35:53.741 25 ERROR cinder.volume.drivers.lightos     raise ConnectionError(e, request=request)
2025-01-21 17:35:53.741 25 ERROR cinder.volume.drivers.lightos requests.exceptions.ConnectionError: HTTPSConnectionPool(host='[LB_IP_ADDRESS]', port=443): Max retries exceeded with url: /api/v2/clusterinfo (Caused by NewConnectionError('<urllib3.connection.HTTPSConnection object at 0x7ff4fbfd89a0>: Failed to establish a new connection: [Errno 111] ECONNREFUSED'))
2025-01-21 17:35:53.741 25 ERROR cinder.volume.drivers.lightos 
2025-01-21 17:35:53.743 25 INFO cinder.volume.drivers.lightos [None req-c0a51630-b5a9-4475-9c7a-8d313e57175d - - - - - -] Invoking get_cluster_info using GET url: /api/v2/clusterinfo             request.body: {} ssl_verify: False
2025-01-21 17:35:53.746 25 ERROR cinder.volume.drivers.lightos [None req-c0a51630-b5a9-4475-9c7a-8d313e57175d - - - - - -] REST server not responding at 'https://[LB_IP_ADDRESS]:443/api/v2/clusterinfo': requests.exceptions.ConnectionError: HTTPSConnectionPool(host='[LB_IP_ADDRESS]', port=443): Max retries exceeded with url: /api/v2/clusterinfo (Caused by NewConnectionError('<urllib3.connection.HTTPSConnection object at 0x7ff4fbfd98a0>: Failed to establish a new connection: [Errno 111] ECONNREFUSED'))
2025-01-21 17:35:53.746 25 ERROR cinder.volume.drivers.lightos Traceback (most recent call last):
2025-01-21 17:35:53.746 25 ERROR cinder.volume.drivers.lightos   File "/var/lib/kolla/venv/lib/python3.10/site-packages/urllib3/connection.py", line 174, in _new_conn
2025-01-21 17:35:53.746 25 ERROR cinder.volume.drivers.lightos     conn = connection.create_connection(
2025-01-21 17:35:53.746 25 ERROR cinder.volume.drivers.lightos   File "/var/lib/kolla/venv/lib/python3.10/site-packages/urllib3/util/connection.py", line 95, in create_connection
2025-01-21 17:35:53.746 25 ERROR cinder.volume.drivers.lightos     raise err
2025-01-21 17:35:53.746 25 ERROR cinder.volume.drivers.lightos   File "/var/lib/kolla/venv/lib/python3.10/site-packages/urllib3/util/connection.py", line 85, in create_connection
2025-01-21 17:35:53.746 25 ERROR cinder.volume.drivers.lightos     sock.connect(sa)
2025-01-21 17:35:53.746 25 ERROR cinder.volume.drivers.lightos   File "/var/lib/kolla/venv/lib/python3.10/site-packages/eventlet/greenio/base.py", line 265, in connect
2025-01-21 17:35:53.746 25 ERROR cinder.volume.drivers.lightos     socket_checkerr(fd)
2025-01-21 17:35:53.746 25 ERROR cinder.volume.drivers.lightos   File "/var/lib/kolla/venv/lib/python3.10/site-packages/eventlet/greenio/base.py", line 50, in socket_checkerr
2025-01-21 17:35:53.746 25 ERROR cinder.volume.drivers.lightos     raise OSError(err, errno.errorcode[err])
2025-01-21 17:35:53.746 25 ERROR cinder.volume.drivers.lightos ConnectionRefusedError: [Errno 111] ECONNREFUSED
2025-01-21 17:35:53.746 25 ERROR cinder.volume.drivers.lightos 
2025-01-21 17:35:53.746 25 ERROR cinder.volume.drivers.lightos During handling of the above exception, another exception occurred:
2025-01-21 17:35:53.746 25 ERROR cinder.volume.drivers.lightos 
2025-01-21 17:35:53.746 25 ERROR cinder.volume.drivers.lightos Traceback (most recent call last):
2025-01-21 17:35:53.746 25 ERROR cinder.volume.drivers.lightos   File "/var/lib/kolla/venv/lib/python3.10/site-packages/urllib3/connectionpool.py", line 715, in urlopen
2025-01-21 17:35:53.746 25 ERROR cinder.volume.drivers.lightos     httplib_response = self._make_request(
2025-01-21 17:35:53.746 25 ERROR cinder.volume.drivers.lightos   File "/var/lib/kolla/venv/lib/python3.10/site-packages/urllib3/connectionpool.py", line 404, in _make_request
2025-01-21 17:35:53.746 25 ERROR cinder.volume.drivers.lightos     self._validate_conn(conn)
2025-01-21 17:35:53.746 25 ERROR cinder.volume.drivers.lightos   File "/var/lib/kolla/venv/lib/python3.10/site-packages/urllib3/connectionpool.py", line 1060, in _validate_conn
2025-01-21 17:35:53.746 25 ERROR cinder.volume.drivers.lightos     conn.connect()
2025-01-21 17:35:53.746 25 ERROR cinder.volume.drivers.lightos   File "/var/lib/kolla/venv/lib/python3.10/site-packages/urllib3/connection.py", line 363, in connect
2025-01-21 17:35:53.746 25 ERROR cinder.volume.drivers.lightos     self.sock = conn = self._new_conn()
2025-01-21 17:35:53.746 25 ERROR cinder.volume.drivers.lightos   File "/var/lib/kolla/venv/lib/python3.10/site-packages/urllib3/connection.py", line 186, in _new_conn
2025-01-21 17:35:53.746 25 ERROR cinder.volume.drivers.lightos     raise NewConnectionError(
2025-01-21 17:35:53.746 25 ERROR cinder.volume.drivers.lightos urllib3.exceptions.NewConnectionError: <urllib3.connection.HTTPSConnection object at 0x7ff4fbfd98a0>: Failed to establish a new connection: [Errno 111] ECONNREFUSED
2025-01-21 17:35:53.746 25 ERROR cinder.volume.drivers.lightos 
2025-01-21 17:35:53.746 25 ERROR cinder.volume.drivers.lightos During handling of the above exception, another exception occurred:
2025-01-21 17:35:53.746 25 ERROR cinder.volume.drivers.lightos 
2025-01-21 17:35:53.746 25 ERROR cinder.volume.drivers.lightos Traceback (most recent call last):
2025-01-21 17:35:53.746 25 ERROR cinder.volume.drivers.lightos   File "/var/lib/kolla/venv/lib/python3.10/site-packages/requests/adapters.py", line 667, in send
2025-01-21 17:35:53.746 25 ERROR cinder.volume.drivers.lightos     resp = conn.urlopen(
2025-01-21 17:35:53.746 25 ERROR cinder.volume.drivers.lightos   File "/var/lib/kolla/venv/lib/python3.10/site-packages/urllib3/connectionpool.py", line 801, in urlopen
2025-01-21 17:35:53.746 25 ERROR cinder.volume.drivers.lightos     retries = retries.increment(
2025-01-21 17:35:53.746 25 ERROR cinder.volume.drivers.lightos   File "/var/lib/kolla/venv/lib/python3.10/site-packages/urllib3/util/retry.py", line 594, in increment
2025-01-21 17:35:53.746 25 ERROR cinder.volume.drivers.lightos     raise MaxRetryError(_pool, url, error or ResponseError(cause))
2025-01-21 17:35:53.746 25 ERROR cinder.volume.drivers.lightos urllib3.exceptions.MaxRetryError: HTTPSConnectionPool(host='[LB_IP_ADDRESS]', port=443): Max retries exceeded with url: /api/v2/clusterinfo (Caused by NewConnectionError('<urllib3.connection.HTTPSConnection object at 0x7ff4fbfd98a0>: Failed to establish a new connection: [Errno 111] ECONNREFUSED'))
2025-01-21 17:35:53.746 25 ERROR cinder.volume.drivers.lightos 
2025-01-21 17:35:53.746 25 ERROR cinder.volume.drivers.lightos During handling of the above exception, another exception occurred:
2025-01-21 17:35:53.746 25 ERROR cinder.volume.drivers.lightos 
2025-01-21 17:35:53.746 25 ERROR cinder.volume.drivers.lightos Traceback (most recent call last):
2025-01-21 17:35:53.746 25 ERROR cinder.volume.drivers.lightos   File "/var/lib/kolla/venv/lib/python3.10/site-packages/cinder/volume/drivers/lightos.py", line 356, in __send_cmd
2025-01-21 17:35:53.746 25 ERROR cinder.volume.drivers.lightos     response = session.send(
2025-01-21 17:35:53.746 25 ERROR cinder.volume.drivers.lightos   File "/var/lib/kolla/venv/lib/python3.10/site-packages/requests/sessions.py", line 703, in send
2025-01-21 17:35:53.746 25 ERROR cinder.volume.drivers.lightos     r = adapter.send(request, **kwargs)
2025-01-21 17:35:53.746 25 ERROR cinder.volume.drivers.lightos   File "/var/lib/kolla/venv/lib/python3.10/site-packages/requests/adapters.py", line 700, in send
2025-01-21 17:35:53.746 25 ERROR cinder.volume.drivers.lightos     raise ConnectionError(e, request=request)
2025-01-21 17:35:53.746 25 ERROR cinder.volume.drivers.lightos requests.exceptions.ConnectionError: HTTPSConnectionPool(host='[LB_IP_ADDRESS]', port=443): Max retries exceeded with url: /api/v2/clusterinfo (Caused by NewConnectionError('<urllib3.connection.HTTPSConnection object at 0x7ff4fbfd98a0>: Failed to establish a new connection: [Errno 111] ECONNREFUSED'))
2025-01-21 17:35:53.746 25 ERROR cinder.volume.drivers.lightos 
2025-01-21 17:35:53.749 25 INFO cinder.volume.drivers.lightos [None req-c0a51630-b5a9-4475-9c7a-8d313e57175d - - - - - -] Invoking get_cluster_info using GET url: /api/v2/clusterinfo             request.body: {} ssl_verify: False
2025-01-21 17:35:56.801 25 ERROR cinder.volume.drivers.lightos [None req-c0a51630-b5a9-4475-9c7a-8d313e57175d - - - - - -] REST server not responding at 'https://[LB_IP_ADDRESS]:443/api/v2/clusterinfo': requests.exceptions.ConnectionError: HTTPSConnectionPool(host='[LB_IP_ADDRESS]', port=443): Max retries exceeded with url: /api/v2/clusterinfo (Caused by NewConnectionError('<urllib3.connection.HTTPSConnection object at 0x7ff4fbef4340>: Failed to establish a new connection: [Errno 113] EHOSTUNREACH'))
2025-01-21 17:35:56.801 25 ERROR cinder.volume.drivers.lightos Traceback (most recent call last):
2025-01-21 17:35:56.801 25 ERROR cinder.volume.drivers.lightos   File "/var/lib/kolla/venv/lib/python3.10/site-packages/urllib3/connection.py", line 174, in _new_conn
2025-01-21 17:35:56.801 25 ERROR cinder.volume.drivers.lightos     conn = connection.create_connection(
2025-01-21 17:35:56.801 25 ERROR cinder.volume.drivers.lightos   File "/var/lib/kolla/venv/lib/python3.10/site-packages/urllib3/util/connection.py", line 95, in create_connection
2025-01-21 17:35:56.801 25 ERROR cinder.volume.drivers.lightos     raise err
2025-01-21 17:35:56.801 25 ERROR cinder.volume.drivers.lightos   File "/var/lib/kolla/venv/lib/python3.10/site-packages/urllib3/util/connection.py", line 85, in create_connection
2025-01-21 17:35:56.801 25 ERROR cinder.volume.drivers.lightos     sock.connect(sa)
2025-01-21 17:35:56.801 25 ERROR cinder.volume.drivers.lightos   File "/var/lib/kolla/venv/lib/python3.10/site-packages/eventlet/greenio/base.py", line 265, in connect
2025-01-21 17:35:56.801 25 ERROR cinder.volume.drivers.lightos     socket_checkerr(fd)
2025-01-21 17:35:56.801 25 ERROR cinder.volume.drivers.lightos   File "/var/lib/kolla/venv/lib/python3.10/site-packages/eventlet/greenio/base.py", line 50, in socket_checkerr
2025-01-21 17:35:56.801 25 ERROR cinder.volume.drivers.lightos     raise OSError(err, errno.errorcode[err])
2025-01-21 17:35:56.801 25 ERROR cinder.volume.drivers.lightos OSError: [Errno 113] EHOSTUNREACH
2025-01-21 17:35:56.801 25 ERROR cinder.volume.drivers.lightos 
2025-01-21 17:35:56.801 25 ERROR cinder.volume.drivers.lightos During handling of the above exception, another exception occurred:
2025-01-21 17:35:56.801 25 ERROR cinder.volume.drivers.lightos 
2025-01-21 17:35:56.801 25 ERROR cinder.volume.drivers.lightos Traceback (most recent call last):
2025-01-21 17:35:56.801 25 ERROR cinder.volume.drivers.lightos   File "/var/lib/kolla/venv/lib/python3.10/site-packages/urllib3/connectionpool.py", line 715, in urlopen
2025-01-21 17:35:56.801 25 ERROR cinder.volume.drivers.lightos     httplib_response = self._make_request(
2025-01-21 17:35:56.801 25 ERROR cinder.volume.drivers.lightos   File "/var/lib/kolla/venv/lib/python3.10/site-packages/urllib3/connectionpool.py", line 404, in _make_request
2025-01-21 17:35:56.801 25 ERROR cinder.volume.drivers.lightos     self._validate_conn(conn)
2025-01-21 17:35:56.801 25 ERROR cinder.volume.drivers.lightos   File "/var/lib/kolla/venv/lib/python3.10/site-packages/urllib3/connectionpool.py", line 1060, in _validate_conn
2025-01-21 17:35:56.801 25 ERROR cinder.volume.drivers.lightos     conn.connect()
2025-01-21 17:35:56.801 25 ERROR cinder.volume.drivers.lightos   File "/var/lib/kolla/venv/lib/python3.10/site-packages/urllib3/connection.py", line 363, in connect
2025-01-21 17:35:56.801 25 ERROR cinder.volume.drivers.lightos     self.sock = conn = self._new_conn()
2025-01-21 17:35:56.801 25 ERROR cinder.volume.drivers.lightos   File "/var/lib/kolla/venv/lib/python3.10/site-packages/urllib3/connection.py", line 186, in _new_conn
2025-01-21 17:35:56.801 25 ERROR cinder.volume.drivers.lightos     raise NewConnectionError(
2025-01-21 17:35:56.801 25 ERROR cinder.volume.drivers.lightos urllib3.exceptions.NewConnectionError: <urllib3.connection.HTTPSConnection object at 0x7ff4fbef4340>: Failed to establish a new connection: [Errno 113] EHOSTUNREACH
2025-01-21 17:35:56.801 25 ERROR cinder.volume.drivers.lightos 
2025-01-21 17:35:56.801 25 ERROR cinder.volume.drivers.lightos During handling of the above exception, another exception occurred:
2025-01-21 17:35:56.801 25 ERROR cinder.volume.drivers.lightos 
2025-01-21 17:35:56.801 25 ERROR cinder.volume.drivers.lightos Traceback (most recent call last):
2025-01-21 17:35:56.801 25 ERROR cinder.volume.drivers.lightos   File "/var/lib/kolla/venv/lib/python3.10/site-packages/requests/adapters.py", line 667, in send
2025-01-21 17:35:56.801 25 ERROR cinder.volume.drivers.lightos     resp = conn.urlopen(
2025-01-21 17:35:56.801 25 ERROR cinder.volume.drivers.lightos   File "/var/lib/kolla/venv/lib/python3.10/site-packages/urllib3/connectionpool.py", line 801, in urlopen
2025-01-21 17:35:56.801 25 ERROR cinder.volume.drivers.lightos     retries = retries.increment(
2025-01-21 17:35:56.801 25 ERROR cinder.volume.drivers.lightos   File "/var/lib/kolla/venv/lib/python3.10/site-packages/urllib3/util/retry.py", line 594, in increment
2025-01-21 17:35:56.801 25 ERROR cinder.volume.drivers.lightos     raise MaxRetryError(_pool, url, error or ResponseError(cause))
2025-01-21 17:35:56.801 25 ERROR cinder.volume.drivers.lightos urllib3.exceptions.MaxRetryError: HTTPSConnectionPool(host='[LB_IP_ADDRESS]', port=443): Max retries exceeded with url: /api/v2/clusterinfo (Caused by NewConnectionError('<urllib3.connection.HTTPSConnection object at 0x7ff4fbef4340>: Failed to establish a new connection: [Errno 113] EHOSTUNREACH'))
2025-01-21 17:35:56.801 25 ERROR cinder.volume.drivers.lightos 
2025-01-21 17:35:56.801 25 ERROR cinder.volume.drivers.lightos During handling of the above exception, another exception occurred:
2025-01-21 17:35:56.801 25 ERROR cinder.volume.drivers.lightos 
2025-01-21 17:35:56.801 25 ERROR cinder.volume.drivers.lightos Traceback (most recent call last):
2025-01-21 17:35:56.801 25 ERROR cinder.volume.drivers.lightos   File "/var/lib/kolla/venv/lib/python3.10/site-packages/cinder/volume/drivers/lightos.py", line 356, in __send_cmd
2025-01-21 17:35:56.801 25 ERROR cinder.volume.drivers.lightos     response = session.send(
2025-01-21 17:35:56.801 25 ERROR cinder.volume.drivers.lightos   File "/var/lib/kolla/venv/lib/python3.10/site-packages/requests/sessions.py", line 703, in send
2025-01-21 17:35:56.801 25 ERROR cinder.volume.drivers.lightos     r = adapter.send(request, **kwargs)
2025-01-21 17:35:56.801 25 ERROR cinder.volume.drivers.lightos   File "/var/lib/kolla/venv/lib/python3.10/site-packages/requests/adapters.py", line 700, in send
2025-01-21 17:35:56.801 25 ERROR cinder.volume.drivers.lightos     raise ConnectionError(e, request=request)
2025-01-21 17:35:56.801 25 ERROR cinder.volume.drivers.lightos requests.exceptions.ConnectionError: HTTPSConnectionPool(host='[LB_IP_ADDRESS]', port=443): Max retries exceeded with url: /api/v2/clusterinfo (Caused by NewConnectionError('<urllib3.connection.HTTPSConnection object at 0x7ff4fbef4340>: Failed to establish a new connection: [Errno 113] EHOSTUNREACH'))
2025-01-21 17:35:56.801 25 ERROR cinder.volume.drivers.lightos 
2025-01-21 17:35:56.804 25 ERROR cinder.volume.manager [None req-c0a51630-b5a9-4475-9c7a-8d313e57175d - - - - - -] Failed to initialize driver.: cinder.exception.VolumeDriverException: Volume driver reported an error: Could not get a response from any API server
2025-01-21 17:35:56.804 25 ERROR cinder.volume.manager Traceback (most recent call last):
2025-01-21 17:35:56.804 25 ERROR cinder.volume.manager   File "/var/lib/kolla/venv/lib/python3.10/site-packages/cinder/volume/manager.py", line 523, in _init_host
2025-01-21 17:35:56.804 25 ERROR cinder.volume.manager     self.driver.do_setup(ctxt)
2025-01-21 17:35:56.804 25 ERROR cinder.volume.manager   File "/var/lib/kolla/venv/lib/python3.10/site-packages/cinder/volume/drivers/lightos.py", line 922, in do_setup
2025-01-21 17:35:56.804 25 ERROR cinder.volume.manager     self.get_cluster_info()
2025-01-21 17:35:56.804 25 ERROR cinder.volume.manager   File "/var/lib/kolla/venv/lib/python3.10/site-packages/cinder/volume/drivers/lightos.py", line 873, in get_cluster_info
2025-01-21 17:35:56.804 25 ERROR cinder.volume.manager     status_code, cluster_info = self.cluster.send_cmd(
2025-01-21 17:35:56.804 25 ERROR cinder.volume.manager   File "/var/lib/kolla/venv/lib/python3.10/site-packages/cinder/volume/drivers/lightos.py", line 315, in send_cmd
2025-01-21 17:35:56.804 25 ERROR cinder.volume.manager     raise exception.VolumeDriverException(
2025-01-21 17:35:56.804 25 ERROR cinder.volume.manager cinder.exception.VolumeDriverException: Volume driver reported an error: Could not get a response from any API server
2025-01-21 17:35:56.804 25 ERROR cinder.volume.manager 
2025-01-21 17:35:56.826 25 WARNING oslo_config.cfg [None req-c0a51630-b5a9-4475-9c7a-8d313e57175d - - - - - -] Deprecated: Option "heartbeat_in_pthread" from group "oslo_messaging_rabbit" is deprecated for removal (The option is related to Eventlet which will be removed. In addition this has never worked as expected with services using eventlet for core service framework.).  Its value may be silently ignored in the future.
2025-01-21 17:35:56.870 25 INFO cinder.service [None req-c0a51630-b5a9-4475-9c7a-8d313e57175d - - - - - -] Starting cinder-volume cluster lightos_cinder_cluster@LIGHTOSyilgqu (version 25.1.0)
2025-01-21 17:35:56.891 25 INFO cinder.volume.manager [None req-c0a51630-b5a9-4475-9c7a-8d313e57175d - - - - - -] Initializing RPC dependent components of volume driver LightOSVolumeDriver (2.3.12)
2025-01-21 17:35:56.891 25 ERROR cinder.volume.volume_utils [None req-c0a51630-b5a9-4475-9c7a-8d313e57175d - - - - - -] Volume driver LightOSVolumeDriver not initialized
2025-01-21 17:35:56.892 25 ERROR cinder.volume.manager [None req-c0a51630-b5a9-4475-9c7a-8d313e57175d - - - - - -] Cannot complete RPC initialization because driver isn't initialized properly.: cinder.exception.DriverNotInitialized: Volume driver not ready.
2025-01-21 17:36:06.893 25 ERROR cinder.service [-] Manager for service cinder-volume rack13-server67@LIGHTOSyilgqu is reporting problems, not sending heartbeat. Service will appear "down".
2025-01-21 17:36:16.897 25 ERROR cinder.service [-] Manager for service cinder-volume rack13-server67@LIGHTOSyilgqu is reporting problems, not sending heartbeat. Service will appear "down".
2025-01-21 17:36:26.898 25 ERROR cinder.service [-] Manager for service cinder-volume rack13-server67@LIGHTOSyilgqu is reporting problems, not sending heartbeat. Service will appear "down".
2025-01-21 17:36:36.900 25 ERROR cinder.service [-] Manager for service cinder-volume rack13-server67@LIGHTOSyilgqu is reporting problems, not sending heartbeat. Service will appear "down".
2025-01-21 17:36:46.901 25 ERROR cinder.service [-] Manager for service cinder-volume rack13-server67@LIGHTOSyilgqu is reporting problems, not sending heartbeat. Service will appear "down".
2025-01-21 17:36:56.902 25 ERROR cinder.service [-] Manager for service cinder-volume rack13-server67@LIGHTOSyilgqu is reporting problems, not sending heartbeat. Service will appear "down".
2025-01-21 17:37:06.904 25 ERROR cinder.service [-] Manager for service cinder-volume rack13-server67@LIGHTOSyilgqu is reporting problems, not sending heartbeat. Service will appear "down".
2025-01-21 17:37:16.905 25 ERROR cinder.service [-] Manager for service cinder-volume rack13-server67@LIGHTOSyilgqu is reporting problems, not sending heartbeat. Service will appear "down".
2025-01-21 17:37:26.907 25 ERROR cinder.service [-] Manager for service cinder-volume rack13-server67@LIGHTOSyilgqu is reporting problems, not sending heartbeat. Service will appear "down".
2025-01-21 17:37:36.908 25 ERROR cinder.service [-] Manager for service cinder-volume rack13-server67@LIGHTOSyilgqu is reporting problems, not sending heartbeat. Service will appear "down".
2025-01-21 17:37:37.897 25 WARNING cinder.volume.manager [None req-ddba5303-75f2-42c2-8e63-5f81c9fc2f68 - - - - - -] Update driver status failed: (config name LIGHTOSyilgqu) is uninitialized.
2025-01-21 17:37:46.909 25 ERROR cinder.service [-] Manager for service cinder-volume rack13-server67@LIGHTOSyilgqu is reporting problems, not sending heartbeat. Service will appear "down".
2025-01-21 17:37:56.911 25 ERROR cinder.service [-] Manager for service cinder-volume rack13-server67@LIGHTOSyilgqu is reporting problems, not sending heartbeat. Service will appear "down".
2025-01-21 17:38:06.912 25 ERROR cinder.service [-] Manager for service cinder-volume rack13-server67@LIGHTOSyilgqu is reporting problems, not sending heartbeat. Service will appear "down".
2025-01-21 17:38:16.913 25 ERROR cinder.service [-] Manager for service cinder-volume rack13-server67@LIGHTOSyilgqu is reporting problems, not sending heartbeat. Service will appear "down".
2025-01-21 17:38:26.915 25 ERROR cinder.service [-] Manager for service cinder-volume rack13-server67@LIGHTOSyilgqu is reporting problems, not sending heartbeat. Service will appear "down".
2025-01-21 17:38:36.916 25 ERROR cinder.service [-] Manager for service cinder-volume rack13-server67@LIGHTOSyilgqu is reporting problems, not sending heartbeat. Service will appear "down".
2025-01-21 17:38:37.900 25 WARNING cinder.volume.manager [None req-ddba5303-75f2-42c2-8e63-5f81c9fc2f68 - - - - - -] Update driver status failed: (config name LIGHTOSyilgqu) is uninitialized.
2025-01-21 17:38:46.918 25 ERROR cinder.service [-] Manager for service cinder-volume rack13-server67@LIGHTOSyilgqu is reporting problems, not sending heartbeat. Service will appear "down".
2025-01-21 17:38:56.919 25 ERROR cinder.service [-] Manager for service cinder-volume rack13-server67@LIGHTOSyilgqu is reporting problems, not sending heartbeat. Service will appear "down".
2025-01-21 17:39:06.920 25 ERROR cinder.service [-] Manager for service cinder-volume rack13-server67@LIGHTOSyilgqu is reporting problems, not sending heartbeat. Service will appear "down".
2025-01-21 17:39:16.922 25 ERROR cinder.service [-] Manager for service cinder-volume rack13-server67@LIGHTOSyilgqu is reporting problems, not sending heartbeat. Service will appear "down".
