{3} setUpClass (cinder_tempest_plugin.api.volume.admin.test_consistencygroups.ConsistencyGroupsV2Test) ... SKIPPED: Cinder consistency group feature disabled
{2} setUpClass (cinder_tempest_plugin.rbac.v3.test_capabilities.ProjectReaderTests) ... SKIPPED: Tempest is not configured to enforce_scope for cinder, skipping RBAC tests. To enable these tests set `tempest.conf [enforce_scope] cinder=True`.
{3} setUpClass (cinder_tempest_plugin.scenario.test_snapshots.SnapshotDataIntegrityTests) [0.000000s] ... FAILED

Captured traceback:
~~~~~~~~~~~~~~~~~~~
    Traceback (most recent call last):

      File "/usr/local/lib/python3.6/site-packages/tempest/test.py", line 181, in setUpClass
    raise value.with_traceback(trace)

      File "/usr/local/lib/python3.6/site-packages/tempest/test.py", line 166, in setUpClass
    cls.setup_credentials()

      File "/usr/local/lib/python3.6/site-packages/tempest/test.py", line 388, in setup_credentials
    credential_type=credentials_type)

      File "/usr/local/lib/python3.6/site-packages/tempest/test.py", line 688, in get_client_manager
    cred_provider = cls._get_credentials_provider()

      File "/usr/local/lib/python3.6/site-packages/tempest/test.py", line 665, in _get_credentials_provider
    force_tenant_isolation=force_tenant_isolation)

      File "/usr/local/lib/python3.6/site-packages/tempest/common/credentials_factory.py", line 141, in get_credentials_provider
    **get_dynamic_provider_params(identity_version))

      File "/usr/local/lib/python3.6/site-packages/tempest/common/credentials_factory.py", line 73, in get_dynamic_provider_params
    fill_in=True, identity_version=identity_version)

      File "/usr/local/lib/python3.6/site-packages/tempest/common/credentials_factory.py", line 258, in get_configured_admin_credentials
    identity_version=identity_version, **params)

      File "/usr/local/lib/python3.6/site-packages/tempest/common/credentials_factory.py", line 303, in get_credentials
    **params)

      File "/usr/local/lib/python3.6/site-packages/tempest/lib/auth.py", line 653, in get_credentials
    creds = auth_provider.fill_credentials()

      File "/usr/local/lib/python3.6/site-packages/tempest/lib/auth.py", line 122, in fill_credentials
    auth_data = self.get_auth()

      File "/usr/local/lib/python3.6/site-packages/tempest/lib/auth.py", line 148, in get_auth
    self.set_auth()

      File "/usr/local/lib/python3.6/site-packages/tempest/lib/auth.py", line 157, in set_auth
    self.cache = self._get_auth()

      File "/usr/local/lib/python3.6/site-packages/tempest/lib/auth.py", line 312, in _get_auth
    token, auth_data = auth_func(**auth_params)

      File "/usr/local/lib/python3.6/site-packages/tempest/lib/services/identity/v3/token_client.py", line 190, in get_token
    body = self.auth(**kwargs)

      File "/usr/local/lib/python3.6/site-packages/tempest/lib/services/identity/v3/token_client.py", line 143, in auth
    resp, body = self.post(self.auth_url, body=body)

      File "/usr/local/lib/python3.6/site-packages/tempest/lib/common/rest_client.py", line 299, in post
    return self.request('POST', url, extra_headers, headers, body, chunked)

      File "/usr/local/lib/python3.6/site-packages/tempest/lib/services/identity/v3/token_client.py", line 170, in request
    raise exceptions.Unauthorized(resp_body['error']['message'])

    tempest.lib.exceptions.Unauthorized: Unauthorized
Details: The request you have made requires authentication.

{1} setUpClass (cinder_tempest_plugin.api.volume.test_create_from_image.VolumeFromImageTest) [0.000000s] ... FAILED

Captured traceback:
~~~~~~~~~~~~~~~~~~~
    Traceback (most recent call last):

      File "/usr/local/lib/python3.6/site-packages/tempest/test.py", line 181, in setUpClass
    raise value.with_traceback(trace)

      File "/usr/local/lib/python3.6/site-packages/tempest/test.py", line 166, in setUpClass
    cls.setup_credentials()

      File "/root/tempest-plugins/cinder-tempest-plugin/cinder_tempest_plugin/api/volume/base.py", line 56, in setup_credentials
    super(BaseVolumeTest, cls).setup_credentials()

      File "/usr/local/lib/python3.6/site-packages/tempest/test.py", line 388, in setup_credentials
    credential_type=credentials_type)

      File "/usr/local/lib/python3.6/site-packages/tempest/test.py", line 688, in get_client_manager
    cred_provider = cls._get_credentials_provider()

      File "/usr/local/lib/python3.6/site-packages/tempest/test.py", line 665, in _get_credentials_provider
    force_tenant_isolation=force_tenant_isolation)

      File "/usr/local/lib/python3.6/site-packages/tempest/common/credentials_factory.py", line 141, in get_credentials_provider
    **get_dynamic_provider_params(identity_version))

      File "/usr/local/lib/python3.6/site-packages/tempest/common/credentials_factory.py", line 73, in get_dynamic_provider_params
    fill_in=True, identity_version=identity_version)

      File "/usr/local/lib/python3.6/site-packages/tempest/common/credentials_factory.py", line 258, in get_configured_admin_credentials
    identity_version=identity_version, **params)

      File "/usr/local/lib/python3.6/site-packages/tempest/common/credentials_factory.py", line 303, in get_credentials
    **params)

      File "/usr/local/lib/python3.6/site-packages/tempest/lib/auth.py", line 653, in get_credentials
    creds = auth_provider.fill_credentials()

      File "/usr/local/lib/python3.6/site-packages/tempest/lib/auth.py", line 122, in fill_credentials
    auth_data = self.get_auth()

      File "/usr/local/lib/python3.6/site-packages/tempest/lib/auth.py", line 148, in get_auth
    self.set_auth()

      File "/usr/local/lib/python3.6/site-packages/tempest/lib/auth.py", line 157, in set_auth
    self.cache = self._get_auth()

      File "/usr/local/lib/python3.6/site-packages/tempest/lib/auth.py", line 312, in _get_auth
    token, auth_data = auth_func(**auth_params)

      File "/usr/local/lib/python3.6/site-packages/tempest/lib/services/identity/v3/token_client.py", line 190, in get_token
    body = self.auth(**kwargs)

      File "/usr/local/lib/python3.6/site-packages/tempest/lib/services/identity/v3/token_client.py", line 143, in auth
    resp, body = self.post(self.auth_url, body=body)

      File "/usr/local/lib/python3.6/site-packages/tempest/lib/common/rest_client.py", line 299, in post
    return self.request('POST', url, extra_headers, headers, body, chunked)

      File "/usr/local/lib/python3.6/site-packages/tempest/lib/services/identity/v3/token_client.py", line 170, in request
    raise exceptions.Unauthorized(resp_body['error']['message'])

    tempest.lib.exceptions.Unauthorized: Unauthorized
Details: The request you have made requires authentication.

{1} setUpClass (cinder_tempest_plugin.api.volume.test_volume_revert.VolumeRevertTests) ... SKIPPED: The microversion range[3.40 - latest] of this test is out of the configuration range[None - None].
{1} setUpClass (cinder_tempest_plugin.rbac.v3.test_capabilities.ProjectMemberTests) ... SKIPPED: Tempest is not configured to enforce_scope for cinder, skipping RBAC tests. To enable these tests set `tempest.conf [enforce_scope] cinder=True`.
{2} setUpClass (cinder_tempest_plugin.scenario.test_volume_encrypted.TestEncryptedCinderVolumes) [0.000000s] ... FAILED

Captured traceback:
~~~~~~~~~~~~~~~~~~~
    Traceback (most recent call last):

      File "/usr/local/lib/python3.6/site-packages/tempest/test.py", line 181, in setUpClass
    raise value.with_traceback(trace)

      File "/usr/local/lib/python3.6/site-packages/tempest/test.py", line 166, in setUpClass
    cls.setup_credentials()

      File "/usr/local/lib/python3.6/site-packages/tempest/test.py", line 388, in setup_credentials
    credential_type=credentials_type)

      File "/usr/local/lib/python3.6/site-packages/tempest/test.py", line 688, in get_client_manager
    cred_provider = cls._get_credentials_provider()

      File "/usr/local/lib/python3.6/site-packages/tempest/test.py", line 665, in _get_credentials_provider
    force_tenant_isolation=force_tenant_isolation)

      File "/usr/local/lib/python3.6/site-packages/tempest/common/credentials_factory.py", line 141, in get_credentials_provider
    **get_dynamic_provider_params(identity_version))

      File "/usr/local/lib/python3.6/site-packages/tempest/common/credentials_factory.py", line 73, in get_dynamic_provider_params
    fill_in=True, identity_version=identity_version)

      File "/usr/local/lib/python3.6/site-packages/tempest/common/credentials_factory.py", line 258, in get_configured_admin_credentials
    identity_version=identity_version, **params)

      File "/usr/local/lib/python3.6/site-packages/tempest/common/credentials_factory.py", line 303, in get_credentials
    **params)

      File "/usr/local/lib/python3.6/site-packages/tempest/lib/auth.py", line 653, in get_credentials
    creds = auth_provider.fill_credentials()

      File "/usr/local/lib/python3.6/site-packages/tempest/lib/auth.py", line 122, in fill_credentials
    auth_data = self.get_auth()

      File "/usr/local/lib/python3.6/site-packages/tempest/lib/auth.py", line 148, in get_auth
    self.set_auth()

      File "/usr/local/lib/python3.6/site-packages/tempest/lib/auth.py", line 157, in set_auth
    self.cache = self._get_auth()

      File "/usr/local/lib/python3.6/site-packages/tempest/lib/auth.py", line 312, in _get_auth
    token, auth_data = auth_func(**auth_params)

      File "/usr/local/lib/python3.6/site-packages/tempest/lib/services/identity/v3/token_client.py", line 190, in get_token
    body = self.auth(**kwargs)

      File "/usr/local/lib/python3.6/site-packages/tempest/lib/services/identity/v3/token_client.py", line 143, in auth
    resp, body = self.post(self.auth_url, body=body)

      File "/usr/local/lib/python3.6/site-packages/tempest/lib/common/rest_client.py", line 299, in post
    return self.request('POST', url, extra_headers, headers, body, chunked)

      File "/usr/local/lib/python3.6/site-packages/tempest/lib/services/identity/v3/token_client.py", line 170, in request
    raise exceptions.Unauthorized(resp_body['error']['message'])

    tempest.lib.exceptions.Unauthorized: Unauthorized
Details: The request you have made requires authentication.

{0} setUpClass (cinder_tempest_plugin.api.volume.test_create_from_image.VolumeAndVolumeTypeFromImageTest) [0.000000s] ... FAILED

Captured traceback:
~~~~~~~~~~~~~~~~~~~
    Traceback (most recent call last):

      File "/usr/local/lib/python3.6/site-packages/tempest/test.py", line 181, in setUpClass
    raise value.with_traceback(trace)

      File "/usr/local/lib/python3.6/site-packages/tempest/test.py", line 166, in setUpClass
    cls.setup_credentials()

      File "/root/tempest-plugins/cinder-tempest-plugin/cinder_tempest_plugin/api/volume/base.py", line 56, in setup_credentials
    super(BaseVolumeTest, cls).setup_credentials()

      File "/usr/local/lib/python3.6/site-packages/tempest/test.py", line 388, in setup_credentials
    credential_type=credentials_type)

      File "/usr/local/lib/python3.6/site-packages/tempest/test.py", line 688, in get_client_manager
    cred_provider = cls._get_credentials_provider()

      File "/usr/local/lib/python3.6/site-packages/tempest/test.py", line 665, in _get_credentials_provider
    force_tenant_isolation=force_tenant_isolation)

      File "/usr/local/lib/python3.6/site-packages/tempest/common/credentials_factory.py", line 141, in get_credentials_provider
    **get_dynamic_provider_params(identity_version))

      File "/usr/local/lib/python3.6/site-packages/tempest/common/credentials_factory.py", line 73, in get_dynamic_provider_params
    fill_in=True, identity_version=identity_version)

      File "/usr/local/lib/python3.6/site-packages/tempest/common/credentials_factory.py", line 258, in get_configured_admin_credentials
    identity_version=identity_version, **params)

      File "/usr/local/lib/python3.6/site-packages/tempest/common/credentials_factory.py", line 303, in get_credentials
    **params)

      File "/usr/local/lib/python3.6/site-packages/tempest/lib/auth.py", line 653, in get_credentials
    creds = auth_provider.fill_credentials()

      File "/usr/local/lib/python3.6/site-packages/tempest/lib/auth.py", line 122, in fill_credentials
    auth_data = self.get_auth()

      File "/usr/local/lib/python3.6/site-packages/tempest/lib/auth.py", line 148, in get_auth
    self.set_auth()

      File "/usr/local/lib/python3.6/site-packages/tempest/lib/auth.py", line 157, in set_auth
    self.cache = self._get_auth()

      File "/usr/local/lib/python3.6/site-packages/tempest/lib/auth.py", line 312, in _get_auth
    token, auth_data = auth_func(**auth_params)

      File "/usr/local/lib/python3.6/site-packages/tempest/lib/services/identity/v3/token_client.py", line 190, in get_token
    body = self.auth(**kwargs)

      File "/usr/local/lib/python3.6/site-packages/tempest/lib/services/identity/v3/token_client.py", line 143, in auth
    resp, body = self.post(self.auth_url, body=body)

      File "/usr/local/lib/python3.6/site-packages/tempest/lib/common/rest_client.py", line 299, in post
    return self.request('POST', url, extra_headers, headers, body, chunked)

      File "/usr/local/lib/python3.6/site-packages/tempest/lib/services/identity/v3/token_client.py", line 170, in request
    raise exceptions.Unauthorized(resp_body['error']['message'])

    tempest.lib.exceptions.Unauthorized: Unauthorized
Details: The request you have made requires authentication.

{0} setUpClass (cinder_tempest_plugin.api.volume.test_volume_unicode.CinderUnicodeTest) [0.000000s] ... FAILED

Captured traceback:
~~~~~~~~~~~~~~~~~~~
    Traceback (most recent call last):

      File "/usr/local/lib/python3.6/site-packages/tempest/test.py", line 181, in setUpClass
    raise value.with_traceback(trace)

      File "/usr/local/lib/python3.6/site-packages/tempest/test.py", line 166, in setUpClass
    cls.setup_credentials()

      File "/root/tempest-plugins/cinder-tempest-plugin/cinder_tempest_plugin/api/volume/base.py", line 56, in setup_credentials
    super(BaseVolumeTest, cls).setup_credentials()

      File "/usr/local/lib/python3.6/site-packages/tempest/test.py", line 388, in setup_credentials
    credential_type=credentials_type)

      File "/usr/local/lib/python3.6/site-packages/tempest/test.py", line 688, in get_client_manager
    cred_provider = cls._get_credentials_provider()

      File "/usr/local/lib/python3.6/site-packages/tempest/test.py", line 665, in _get_credentials_provider
    force_tenant_isolation=force_tenant_isolation)

      File "/usr/local/lib/python3.6/site-packages/tempest/common/credentials_factory.py", line 141, in get_credentials_provider
    **get_dynamic_provider_params(identity_version))

      File "/usr/local/lib/python3.6/site-packages/tempest/common/credentials_factory.py", line 73, in get_dynamic_provider_params
    fill_in=True, identity_version=identity_version)

      File "/usr/local/lib/python3.6/site-packages/tempest/common/credentials_factory.py", line 258, in get_configured_admin_credentials
    identity_version=identity_version, **params)

      File "/usr/local/lib/python3.6/site-packages/tempest/common/credentials_factory.py", line 303, in get_credentials
    **params)

      File "/usr/local/lib/python3.6/site-packages/tempest/lib/auth.py", line 653, in get_credentials
    creds = auth_provider.fill_credentials()

      File "/usr/local/lib/python3.6/site-packages/tempest/lib/auth.py", line 122, in fill_credentials
    auth_data = self.get_auth()

      File "/usr/local/lib/python3.6/site-packages/tempest/lib/auth.py", line 148, in get_auth
    self.set_auth()

      File "/usr/local/lib/python3.6/site-packages/tempest/lib/auth.py", line 157, in set_auth
    self.cache = self._get_auth()

      File "/usr/local/lib/python3.6/site-packages/tempest/lib/auth.py", line 312, in _get_auth
    token, auth_data = auth_func(**auth_params)

      File "/usr/local/lib/python3.6/site-packages/tempest/lib/services/identity/v3/token_client.py", line 190, in get_token
    body = self.auth(**kwargs)

      File "/usr/local/lib/python3.6/site-packages/tempest/lib/services/identity/v3/token_client.py", line 143, in auth
    resp, body = self.post(self.auth_url, body=body)

      File "/usr/local/lib/python3.6/site-packages/tempest/lib/common/rest_client.py", line 299, in post
    return self.request('POST', url, extra_headers, headers, body, chunked)

      File "/usr/local/lib/python3.6/site-packages/tempest/lib/services/identity/v3/token_client.py", line 170, in request
    raise exceptions.Unauthorized(resp_body['error']['message'])

    tempest.lib.exceptions.Unauthorized: Unauthorized
Details: The request you have made requires authentication.

{0} setUpClass (cinder_tempest_plugin.rbac.v3.test_capabilities.ProjectAdminTests) ... SKIPPED: Tempest is not configured to enforce_scope for cinder, skipping RBAC tests. To enable these tests set `tempest.conf [enforce_scope] cinder=True`.

==============================
Failed 5 tests - output below:
==============================

setUpClass (cinder_tempest_plugin.scenario.test_snapshots.SnapshotDataIntegrityTests)
-------------------------------------------------------------------------------------

Captured traceback:
~~~~~~~~~~~~~~~~~~~
    Traceback (most recent call last):

      File "/usr/local/lib/python3.6/site-packages/tempest/test.py", line 181, in setUpClass
    raise value.with_traceback(trace)

      File "/usr/local/lib/python3.6/site-packages/tempest/test.py", line 166, in setUpClass
    cls.setup_credentials()

      File "/usr/local/lib/python3.6/site-packages/tempest/test.py", line 388, in setup_credentials
    credential_type=credentials_type)

      File "/usr/local/lib/python3.6/site-packages/tempest/test.py", line 688, in get_client_manager
    cred_provider = cls._get_credentials_provider()

      File "/usr/local/lib/python3.6/site-packages/tempest/test.py", line 665, in _get_credentials_provider
    force_tenant_isolation=force_tenant_isolation)

      File "/usr/local/lib/python3.6/site-packages/tempest/common/credentials_factory.py", line 141, in get_credentials_provider
    **get_dynamic_provider_params(identity_version))

      File "/usr/local/lib/python3.6/site-packages/tempest/common/credentials_factory.py", line 73, in get_dynamic_provider_params
    fill_in=True, identity_version=identity_version)

      File "/usr/local/lib/python3.6/site-packages/tempest/common/credentials_factory.py", line 258, in get_configured_admin_credentials
    identity_version=identity_version, **params)

      File "/usr/local/lib/python3.6/site-packages/tempest/common/credentials_factory.py", line 303, in get_credentials
    **params)

      File "/usr/local/lib/python3.6/site-packages/tempest/lib/auth.py", line 653, in get_credentials
    creds = auth_provider.fill_credentials()

      File "/usr/local/lib/python3.6/site-packages/tempest/lib/auth.py", line 122, in fill_credentials
    auth_data = self.get_auth()

      File "/usr/local/lib/python3.6/site-packages/tempest/lib/auth.py", line 148, in get_auth
    self.set_auth()

      File "/usr/local/lib/python3.6/site-packages/tempest/lib/auth.py", line 157, in set_auth
    self.cache = self._get_auth()

      File "/usr/local/lib/python3.6/site-packages/tempest/lib/auth.py", line 312, in _get_auth
    token, auth_data = auth_func(**auth_params)

      File "/usr/local/lib/python3.6/site-packages/tempest/lib/services/identity/v3/token_client.py", line 190, in get_token
    body = self.auth(**kwargs)

      File "/usr/local/lib/python3.6/site-packages/tempest/lib/services/identity/v3/token_client.py", line 143, in auth
    resp, body = self.post(self.auth_url, body=body)

      File "/usr/local/lib/python3.6/site-packages/tempest/lib/common/rest_client.py", line 299, in post
    return self.request('POST', url, extra_headers, headers, body, chunked)

      File "/usr/local/lib/python3.6/site-packages/tempest/lib/services/identity/v3/token_client.py", line 170, in request
    raise exceptions.Unauthorized(resp_body['error']['message'])

    tempest.lib.exceptions.Unauthorized: Unauthorized
Details: The request you have made requires authentication.


setUpClass (cinder_tempest_plugin.api.volume.test_create_from_image.VolumeFromImageTest)
----------------------------------------------------------------------------------------

Captured traceback:
~~~~~~~~~~~~~~~~~~~
    Traceback (most recent call last):

      File "/usr/local/lib/python3.6/site-packages/tempest/test.py", line 181, in setUpClass
    raise value.with_traceback(trace)

      File "/usr/local/lib/python3.6/site-packages/tempest/test.py", line 166, in setUpClass
    cls.setup_credentials()

      File "/root/tempest-plugins/cinder-tempest-plugin/cinder_tempest_plugin/api/volume/base.py", line 56, in setup_credentials
    super(BaseVolumeTest, cls).setup_credentials()

      File "/usr/local/lib/python3.6/site-packages/tempest/test.py", line 388, in setup_credentials
    credential_type=credentials_type)

      File "/usr/local/lib/python3.6/site-packages/tempest/test.py", line 688, in get_client_manager
    cred_provider = cls._get_credentials_provider()

      File "/usr/local/lib/python3.6/site-packages/tempest/test.py", line 665, in _get_credentials_provider
    force_tenant_isolation=force_tenant_isolation)

      File "/usr/local/lib/python3.6/site-packages/tempest/common/credentials_factory.py", line 141, in get_credentials_provider
    **get_dynamic_provider_params(identity_version))

      File "/usr/local/lib/python3.6/site-packages/tempest/common/credentials_factory.py", line 73, in get_dynamic_provider_params
    fill_in=True, identity_version=identity_version)

      File "/usr/local/lib/python3.6/site-packages/tempest/common/credentials_factory.py", line 258, in get_configured_admin_credentials
    identity_version=identity_version, **params)

      File "/usr/local/lib/python3.6/site-packages/tempest/common/credentials_factory.py", line 303, in get_credentials
    **params)

      File "/usr/local/lib/python3.6/site-packages/tempest/lib/auth.py", line 653, in get_credentials
    creds = auth_provider.fill_credentials()

      File "/usr/local/lib/python3.6/site-packages/tempest/lib/auth.py", line 122, in fill_credentials
    auth_data = self.get_auth()

      File "/usr/local/lib/python3.6/site-packages/tempest/lib/auth.py", line 148, in get_auth
    self.set_auth()

      File "/usr/local/lib/python3.6/site-packages/tempest/lib/auth.py", line 157, in set_auth
    self.cache = self._get_auth()

      File "/usr/local/lib/python3.6/site-packages/tempest/lib/auth.py", line 312, in _get_auth
    token, auth_data = auth_func(**auth_params)

      File "/usr/local/lib/python3.6/site-packages/tempest/lib/services/identity/v3/token_client.py", line 190, in get_token
    body = self.auth(**kwargs)

      File "/usr/local/lib/python3.6/site-packages/tempest/lib/services/identity/v3/token_client.py", line 143, in auth
    resp, body = self.post(self.auth_url, body=body)

      File "/usr/local/lib/python3.6/site-packages/tempest/lib/common/rest_client.py", line 299, in post
    return self.request('POST', url, extra_headers, headers, body, chunked)

      File "/usr/local/lib/python3.6/site-packages/tempest/lib/services/identity/v3/token_client.py", line 170, in request
    raise exceptions.Unauthorized(resp_body['error']['message'])

    tempest.lib.exceptions.Unauthorized: Unauthorized
Details: The request you have made requires authentication.


setUpClass (cinder_tempest_plugin.scenario.test_volume_encrypted.TestEncryptedCinderVolumes)
--------------------------------------------------------------------------------------------

Captured traceback:
~~~~~~~~~~~~~~~~~~~
    Traceback (most recent call last):

      File "/usr/local/lib/python3.6/site-packages/tempest/test.py", line 181, in setUpClass
    raise value.with_traceback(trace)

      File "/usr/local/lib/python3.6/site-packages/tempest/test.py", line 166, in setUpClass
    cls.setup_credentials()

      File "/usr/local/lib/python3.6/site-packages/tempest/test.py", line 388, in setup_credentials
    credential_type=credentials_type)

      File "/usr/local/lib/python3.6/site-packages/tempest/test.py", line 688, in get_client_manager
    cred_provider = cls._get_credentials_provider()

      File "/usr/local/lib/python3.6/site-packages/tempest/test.py", line 665, in _get_credentials_provider
    force_tenant_isolation=force_tenant_isolation)

      File "/usr/local/lib/python3.6/site-packages/tempest/common/credentials_factory.py", line 141, in get_credentials_provider
    **get_dynamic_provider_params(identity_version))

      File "/usr/local/lib/python3.6/site-packages/tempest/common/credentials_factory.py", line 73, in get_dynamic_provider_params
    fill_in=True, identity_version=identity_version)

      File "/usr/local/lib/python3.6/site-packages/tempest/common/credentials_factory.py", line 258, in get_configured_admin_credentials
    identity_version=identity_version, **params)

      File "/usr/local/lib/python3.6/site-packages/tempest/common/credentials_factory.py", line 303, in get_credentials
    **params)

      File "/usr/local/lib/python3.6/site-packages/tempest/lib/auth.py", line 653, in get_credentials
    creds = auth_provider.fill_credentials()

      File "/usr/local/lib/python3.6/site-packages/tempest/lib/auth.py", line 122, in fill_credentials
    auth_data = self.get_auth()

      File "/usr/local/lib/python3.6/site-packages/tempest/lib/auth.py", line 148, in get_auth
    self.set_auth()

      File "/usr/local/lib/python3.6/site-packages/tempest/lib/auth.py", line 157, in set_auth
    self.cache = self._get_auth()

      File "/usr/local/lib/python3.6/site-packages/tempest/lib/auth.py", line 312, in _get_auth
    token, auth_data = auth_func(**auth_params)

      File "/usr/local/lib/python3.6/site-packages/tempest/lib/services/identity/v3/token_client.py", line 190, in get_token
    body = self.auth(**kwargs)

      File "/usr/local/lib/python3.6/site-packages/tempest/lib/services/identity/v3/token_client.py", line 143, in auth
    resp, body = self.post(self.auth_url, body=body)

      File "/usr/local/lib/python3.6/site-packages/tempest/lib/common/rest_client.py", line 299, in post
    return self.request('POST', url, extra_headers, headers, body, chunked)

      File "/usr/local/lib/python3.6/site-packages/tempest/lib/services/identity/v3/token_client.py", line 170, in request
    raise exceptions.Unauthorized(resp_body['error']['message'])

    tempest.lib.exceptions.Unauthorized: Unauthorized
Details: The request you have made requires authentication.


setUpClass (cinder_tempest_plugin.api.volume.test_create_from_image.VolumeAndVolumeTypeFromImageTest)
-----------------------------------------------------------------------------------------------------

Captured traceback:
~~~~~~~~~~~~~~~~~~~
    Traceback (most recent call last):

      File "/usr/local/lib/python3.6/site-packages/tempest/test.py", line 181, in setUpClass
    raise value.with_traceback(trace)

      File "/usr/local/lib/python3.6/site-packages/tempest/test.py", line 166, in setUpClass
    cls.setup_credentials()

      File "/root/tempest-plugins/cinder-tempest-plugin/cinder_tempest_plugin/api/volume/base.py", line 56, in setup_credentials
    super(BaseVolumeTest, cls).setup_credentials()

      File "/usr/local/lib/python3.6/site-packages/tempest/test.py", line 388, in setup_credentials
    credential_type=credentials_type)

      File "/usr/local/lib/python3.6/site-packages/tempest/test.py", line 688, in get_client_manager
    cred_provider = cls._get_credentials_provider()

      File "/usr/local/lib/python3.6/site-packages/tempest/test.py", line 665, in _get_credentials_provider
    force_tenant_isolation=force_tenant_isolation)

      File "/usr/local/lib/python3.6/site-packages/tempest/common/credentials_factory.py", line 141, in get_credentials_provider
    **get_dynamic_provider_params(identity_version))

      File "/usr/local/lib/python3.6/site-packages/tempest/common/credentials_factory.py", line 73, in get_dynamic_provider_params
    fill_in=True, identity_version=identity_version)

      File "/usr/local/lib/python3.6/site-packages/tempest/common/credentials_factory.py", line 258, in get_configured_admin_credentials
    identity_version=identity_version, **params)

      File "/usr/local/lib/python3.6/site-packages/tempest/common/credentials_factory.py", line 303, in get_credentials
    **params)

      File "/usr/local/lib/python3.6/site-packages/tempest/lib/auth.py", line 653, in get_credentials
    creds = auth_provider.fill_credentials()

      File "/usr/local/lib/python3.6/site-packages/tempest/lib/auth.py", line 122, in fill_credentials
    auth_data = self.get_auth()

      File "/usr/local/lib/python3.6/site-packages/tempest/lib/auth.py", line 148, in get_auth
    self.set_auth()

      File "/usr/local/lib/python3.6/site-packages/tempest/lib/auth.py", line 157, in set_auth
    self.cache = self._get_auth()

      File "/usr/local/lib/python3.6/site-packages/tempest/lib/auth.py", line 312, in _get_auth
    token, auth_data = auth_func(**auth_params)

      File "/usr/local/lib/python3.6/site-packages/tempest/lib/services/identity/v3/token_client.py", line 190, in get_token
    body = self.auth(**kwargs)

      File "/usr/local/lib/python3.6/site-packages/tempest/lib/services/identity/v3/token_client.py", line 143, in auth
    resp, body = self.post(self.auth_url, body=body)

      File "/usr/local/lib/python3.6/site-packages/tempest/lib/common/rest_client.py", line 299, in post
    return self.request('POST', url, extra_headers, headers, body, chunked)

      File "/usr/local/lib/python3.6/site-packages/tempest/lib/services/identity/v3/token_client.py", line 170, in request
    raise exceptions.Unauthorized(resp_body['error']['message'])

    tempest.lib.exceptions.Unauthorized: Unauthorized
Details: The request you have made requires authentication.


setUpClass (cinder_tempest_plugin.api.volume.test_volume_unicode.CinderUnicodeTest)
-----------------------------------------------------------------------------------

Captured traceback:
~~~~~~~~~~~~~~~~~~~
    Traceback (most recent call last):

      File "/usr/local/lib/python3.6/site-packages/tempest/test.py", line 181, in setUpClass
    raise value.with_traceback(trace)

      File "/usr/local/lib/python3.6/site-packages/tempest/test.py", line 166, in setUpClass
    cls.setup_credentials()

      File "/root/tempest-plugins/cinder-tempest-plugin/cinder_tempest_plugin/api/volume/base.py", line 56, in setup_credentials
    super(BaseVolumeTest, cls).setup_credentials()

      File "/usr/local/lib/python3.6/site-packages/tempest/test.py", line 388, in setup_credentials
    credential_type=credentials_type)

      File "/usr/local/lib/python3.6/site-packages/tempest/test.py", line 688, in get_client_manager
    cred_provider = cls._get_credentials_provider()

      File "/usr/local/lib/python3.6/site-packages/tempest/test.py", line 665, in _get_credentials_provider
    force_tenant_isolation=force_tenant_isolation)

      File "/usr/local/lib/python3.6/site-packages/tempest/common/credentials_factory.py", line 141, in get_credentials_provider
    **get_dynamic_provider_params(identity_version))

      File "/usr/local/lib/python3.6/site-packages/tempest/common/credentials_factory.py", line 73, in get_dynamic_provider_params
    fill_in=True, identity_version=identity_version)

      File "/usr/local/lib/python3.6/site-packages/tempest/common/credentials_factory.py", line 258, in get_configured_admin_credentials
    identity_version=identity_version, **params)

      File "/usr/local/lib/python3.6/site-packages/tempest/common/credentials_factory.py", line 303, in get_credentials
    **params)

      File "/usr/local/lib/python3.6/site-packages/tempest/lib/auth.py", line 653, in get_credentials
    creds = auth_provider.fill_credentials()

      File "/usr/local/lib/python3.6/site-packages/tempest/lib/auth.py", line 122, in fill_credentials
    auth_data = self.get_auth()

      File "/usr/local/lib/python3.6/site-packages/tempest/lib/auth.py", line 148, in get_auth
    self.set_auth()

      File "/usr/local/lib/python3.6/site-packages/tempest/lib/auth.py", line 157, in set_auth
    self.cache = self._get_auth()

      File "/usr/local/lib/python3.6/site-packages/tempest/lib/auth.py", line 312, in _get_auth
    token, auth_data = auth_func(**auth_params)

      File "/usr/local/lib/python3.6/site-packages/tempest/lib/services/identity/v3/token_client.py", line 190, in get_token
    body = self.auth(**kwargs)

      File "/usr/local/lib/python3.6/site-packages/tempest/lib/services/identity/v3/token_client.py", line 143, in auth
    resp, body = self.post(self.auth_url, body=body)

      File "/usr/local/lib/python3.6/site-packages/tempest/lib/common/rest_client.py", line 299, in post
    return self.request('POST', url, extra_headers, headers, body, chunked)

      File "/usr/local/lib/python3.6/site-packages/tempest/lib/services/identity/v3/token_client.py", line 170, in request
    raise exceptions.Unauthorized(resp_body['error']['message'])

    tempest.lib.exceptions.Unauthorized: Unauthorized
Details: The request you have made requires authentication.



======
Totals
======
Ran: 10 tests in 0.9299 sec.
 - Passed: 0
 - Skipped: 5
 - Expected Fail: 0
 - Unexpected Success: 0
 - Failed: 5
Sum of execute time for each test: 0.0000 sec.

==============
Worker Balance
==============
 - Worker 0 (3 tests) => 0:00:00.449705
 - Worker 1 (3 tests) => 0:00:00.007610
 - Worker 2 (2 tests) => 0:00:00.440324
 - Worker 3 (2 tests) => 0:00:00.447845
