Build Started 10_03_2025_18_23_31
2025-03-10 18:31:42.908 7 ERROR cinder.scheduler.filter_scheduler [None req-e5504f39-8073-42e2-b5e2-748b57b6d08a 3ac829440cae424a8f1df23faf2aff4e 7c2fb1f400b04f6d81551ad44364d9f1 - - - -] Error scheduling 974b1109-4a74-4386-b811-cdeeb7e94e1d from last vol-service: rack11-server76@LIGHTOShwlzto#hwlzto : ['Traceback (most recent call last):\n', '  File "/var/lib/kolla/venv/lib/python3.10/site-packages/taskflow/engines/action_engine/executor.py", line 52, in _execute_task\n    result = task.execute(**arguments)\n', '  File "/var/lib/kolla/venv/lib/python3.10/site-packages/cinder/volume/flows/manager/create_volume.py", line 1235, in execute\n    model_update = self._create_raw_volume(\n', '  File "/var/lib/kolla/venv/lib/python3.10/site-packages/cinder/volume/flows/manager/create_volume.py", line 1198, in _create_raw_volume\n    with excutils.save_and_reraise_exception():\n', '  File "/var/lib/kolla/venv/lib/python3.10/site-packages/oslo_utils/excutils.py", line 227, in __exit__\n    self.force_reraise()\n', '  File "/var/lib/kolla/venv/lib/python3.10/site-packages/oslo_utils/excutils.py", line 200, in force_reraise\n    raise self.value\n', '  File "/var/lib/kolla/venv/lib/python3.10/site-packages/cinder/volume/flows/manager/create_volume.py", line 1196, in _create_raw_volume\n    ret = self.driver.create_volume(volume)\n', '  File "/var/lib/kolla/venv/lib/python3.10/site-packages/cinder/volume/drivers/lightos.py", line 669, in create_volume\n    return self._create_volume(volume, src_snapshot_lightos_name=None)\n', '  File "/var/lib/kolla/venv/lib/python3.10/site-packages/cinder/volume/drivers/lightos.py", line 734, in _create_volume\n    raise exception.VolumeBackendAPIException(message=msg)\n', 'cinder.exception.VolumeBackendAPIException: Did not succeed creating LightOS volume with UUID 1d2a8355-9d4b-483e-9f76-f1b2b1ecc0a2 status_code 200 last state Creating\n']
2025-03-10 18:33:49.821 7 INFO cinder.scheduler.base_filter [None req-ba9fed4d-7d77-405c-802e-a5f36c4a9d85 eefa52ec62fa4afaaefd7cf0b39226bd 0dfb5759173d44b29ffe196c06bdd649 - - - -] Filtering removed all hosts for the request with volume ID '319889f7-8015-4c90-9be6-086c7cf09aad'. Filter results: AvailabilityZoneFilter: (start: 1, end: 1), CapacityFilter: (start: 1, end: 1), CapabilitiesFilter: (start: 1, end: 0)
2025-03-10 18:33:49.822 7 WARNING cinder.scheduler.filter_scheduler [None req-ba9fed4d-7d77-405c-802e-a5f36c4a9d85 eefa52ec62fa4afaaefd7cf0b39226bd 0dfb5759173d44b29ffe196c06bdd649 - - - -] No weighed backend found for volume with properties: {'id': '8d4c3c52-194b-48bd-9db3-cc47c9b349e2', 'name': 'tempest-UserMessagesTest-volume-type-481393602', 'description': None, 'is_public': True, 'projects': [], 'extra_specs': {'storage_protocol': 'tempest-storage_protocol-934540381', 'vendor_name': 'tempest-vendor_name-695255004'}, 'qos_specs_id': None, 'created_at': '2025-03-10T18:33:49.000000', 'updated_at': None, 'deleted_at': None, 'deleted': False}
2025-03-10 18:33:49.823 7 INFO cinder.message.api [None req-ba9fed4d-7d77-405c-802e-a5f36c4a9d85 eefa52ec62fa4afaaefd7cf0b39226bd 0dfb5759173d44b29ffe196c06bdd649 - - - -] Creating message record for request_id = req-ba9fed4d-7d77-405c-802e-a5f36c4a9d85
2025-03-10 18:33:49.829 7 ERROR cinder.scheduler.flows.create_volume [None req-ba9fed4d-7d77-405c-802e-a5f36c4a9d85 eefa52ec62fa4afaaefd7cf0b39226bd 0dfb5759173d44b29ffe196c06bdd649 - - - -] Failed to run task cinder.scheduler.flows.create_volume.ScheduleCreateVolumeTask;volume:create: No valid backend was found. No weighed backends available: cinder.exception.NoValidBackend: No valid backend was found. No weighed backends available
2025-03-10 18:33:51.871 7 INFO cinder.scheduler.base_filter [None req-b593f378-61dc-4dd0-8379-a1163653cb8b eefa52ec62fa4afaaefd7cf0b39226bd 0dfb5759173d44b29ffe196c06bdd649 - - - -] Filtering removed all hosts for the request with volume ID '46e7f30b-40ce-4e4f-a1fe-c34d046ceade'. Filter results: AvailabilityZoneFilter: (start: 1, end: 1), CapacityFilter: (start: 1, end: 1), CapabilitiesFilter: (start: 1, end: 0)
2025-03-10 18:33:51.872 7 WARNING cinder.scheduler.filter_scheduler [None req-b593f378-61dc-4dd0-8379-a1163653cb8b eefa52ec62fa4afaaefd7cf0b39226bd 0dfb5759173d44b29ffe196c06bdd649 - - - -] No weighed backend found for volume with properties: {'id': 'c0b8a9be-1c9e-412d-8c38-e9464c69115c', 'name': 'tempest-UserMessagesTest-volume-type-1632885288', 'description': None, 'is_public': True, 'projects': [], 'extra_specs': {'storage_protocol': 'tempest-storage_protocol-1794297476', 'vendor_name': 'tempest-vendor_name-1215969867'}, 'qos_specs_id': None, 'created_at': '2025-03-10T18:33:51.000000', 'updated_at': None, 'deleted_at': None, 'deleted': False}
2025-03-10 18:33:51.873 7 INFO cinder.message.api [None req-b593f378-61dc-4dd0-8379-a1163653cb8b eefa52ec62fa4afaaefd7cf0b39226bd 0dfb5759173d44b29ffe196c06bdd649 - - - -] Creating message record for request_id = req-b593f378-61dc-4dd0-8379-a1163653cb8b
2025-03-10 18:33:51.878 7 ERROR cinder.scheduler.flows.create_volume [None req-b593f378-61dc-4dd0-8379-a1163653cb8b eefa52ec62fa4afaaefd7cf0b39226bd 0dfb5759173d44b29ffe196c06bdd649 - - - -] Failed to run task cinder.scheduler.flows.create_volume.ScheduleCreateVolumeTask;volume:create: No valid backend was found. No weighed backends available: cinder.exception.NoValidBackend: No valid backend was found. No weighed backends available
2025-03-10 18:34:37.745 7 ERROR cinder.scheduler.filter_scheduler [None req-0304f007-614d-4bc0-bcc6-9ebf0b6c4ad7 bc186dfb2ca848938dc6cf6aaaf874dc 11ff2e7870264c49be9f37ac0962f991 - - - -] Error scheduling f33b7ff9-a56e-4022-a4c0-475d741552e9 from last vol-service: rack11-server76@LIGHTOShwlzto#hwlzto : ['Traceback (most recent call last):\n', '  File "/var/lib/kolla/venv/lib/python3.10/site-packages/taskflow/engines/action_engine/executor.py", line 52, in _execute_task\n    result = task.execute(**arguments)\n', '  File "/var/lib/kolla/venv/lib/python3.10/site-packages/cinder/volume/flows/manager/create_volume.py", line 1235, in execute\n    model_update = self._create_raw_volume(\n', '  File "/var/lib/kolla/venv/lib/python3.10/site-packages/cinder/volume/flows/manager/create_volume.py", line 1198, in _create_raw_volume\n    with excutils.save_and_reraise_exception():\n', '  File "/var/lib/kolla/venv/lib/python3.10/site-packages/oslo_utils/excutils.py", line 227, in __exit__\n    self.force_reraise()\n', '  File "/var/lib/kolla/venv/lib/python3.10/site-packages/oslo_utils/excutils.py", line 200, in force_reraise\n    raise self.value\n', '  File "/var/lib/kolla/venv/lib/python3.10/site-packages/cinder/volume/flows/manager/create_volume.py", line 1196, in _create_raw_volume\n    ret = self.driver.create_volume(volume)\n', '  File "/var/lib/kolla/venv/lib/python3.10/site-packages/cinder/volume/drivers/lightos.py", line 669, in create_volume\n    return self._create_volume(volume, src_snapshot_lightos_name=None)\n', '  File "/var/lib/kolla/venv/lib/python3.10/site-packages/cinder/volume/drivers/lightos.py", line 693, in _create_volume\n    status_code, resp = self._create_new_lightos_volume(\n', '  File "/var/lib/kolla/venv/lib/python3.10/site-packages/cinder/volume/drivers/lightos.py", line 630, in _create_new_lightos_volume\n    return self.cluster.send_cmd(\n', '  File "/var/lib/kolla/venv/lib/python3.10/site-packages/cinder/volume/drivers/lightos.py", line 318, in send_cmd\n    raise exception.VolumeDriverException(\n', 'cinder.exception.VolumeDriverException: Volume driver reported an error: Could not get a response from any API server\n']
2025-03-10 18:35:11.347 7 ERROR cinder.scheduler.filter_scheduler [None req-01e2b067-3611-4782-b512-38c9b829437a a2f58e193a7b49fda8eda6fa08c4b7f2 5b2e175f05674ce1b480d20bd359cd5f - - - -] Error scheduling 37da9c40-631c-4847-a28c-9b3ae5eb704b from last vol-service: rack11-server76@LIGHTOShwlzto#hwlzto : ['Traceback (most recent call last):\n', '  File "/var/lib/kolla/venv/lib/python3.10/site-packages/taskflow/engines/action_engine/executor.py", line 52, in _execute_task\n    result = task.execute(**arguments)\n', '  File "/var/lib/kolla/venv/lib/python3.10/site-packages/cinder/volume/flows/manager/create_volume.py", line 1235, in execute\n    model_update = self._create_raw_volume(\n', '  File "/var/lib/kolla/venv/lib/python3.10/site-packages/cinder/volume/flows/manager/create_volume.py", line 1198, in _create_raw_volume\n    with excutils.save_and_reraise_exception():\n', '  File "/var/lib/kolla/venv/lib/python3.10/site-packages/oslo_utils/excutils.py", line 227, in __exit__\n    self.force_reraise()\n', '  File "/var/lib/kolla/venv/lib/python3.10/site-packages/oslo_utils/excutils.py", line 200, in force_reraise\n    raise self.value\n', '  File "/var/lib/kolla/venv/lib/python3.10/site-packages/cinder/volume/flows/manager/create_volume.py", line 1196, in _create_raw_volume\n    ret = self.driver.create_volume(volume)\n', '  File "/var/lib/kolla/venv/lib/python3.10/site-packages/cinder/volume/drivers/lightos.py", line 669, in create_volume\n    return self._create_volume(volume, src_snapshot_lightos_name=None)\n', '  File "/var/lib/kolla/venv/lib/python3.10/site-packages/cinder/volume/drivers/lightos.py", line 693, in _create_volume\n    status_code, resp = self._create_new_lightos_volume(\n', '  File "/var/lib/kolla/venv/lib/python3.10/site-packages/cinder/volume/drivers/lightos.py", line 630, in _create_new_lightos_volume\n    return self.cluster.send_cmd(\n', '  File "/var/lib/kolla/venv/lib/python3.10/site-packages/cinder/volume/drivers/lightos.py", line 318, in send_cmd\n    raise exception.VolumeDriverException(\n', 'cinder.exception.VolumeDriverException: Volume driver reported an error: Could not get a response from any API server\n']
2025-03-10 18:38:36.333 7 ERROR cinder.scheduler.filter_scheduler [None req-01e2b067-3611-4782-b512-38c9b829437a a2f58e193a7b49fda8eda6fa08c4b7f2 5b2e175f05674ce1b480d20bd359cd5f - - - -] Error scheduling 37da9c40-631c-4847-a28c-9b3ae5eb704b from last vol-service: rack11-server76@LIGHTOShwlzto#hwlzto : ['Traceback (most recent call last):\n', '  File "/var/lib/kolla/venv/lib/python3.10/site-packages/taskflow/engines/action_engine/executor.py", line 52, in _execute_task\n    result = task.execute(**arguments)\n', '  File "/var/lib/kolla/venv/lib/python3.10/site-packages/cinder/volume/flows/manager/create_volume.py", line 1235, in execute\n    model_update = self._create_raw_volume(\n', '  File "/var/lib/kolla/venv/lib/python3.10/site-packages/cinder/volume/flows/manager/create_volume.py", line 1198, in _create_raw_volume\n    with excutils.save_and_reraise_exception():\n', '  File "/var/lib/kolla/venv/lib/python3.10/site-packages/oslo_utils/excutils.py", line 227, in __exit__\n    self.force_reraise()\n', '  File "/var/lib/kolla/venv/lib/python3.10/site-packages/oslo_utils/excutils.py", line 200, in force_reraise\n    raise self.value\n', '  File "/var/lib/kolla/venv/lib/python3.10/site-packages/cinder/volume/flows/manager/create_volume.py", line 1196, in _create_raw_volume\n    ret = self.driver.create_volume(volume)\n', '  File "/var/lib/kolla/venv/lib/python3.10/site-packages/cinder/volume/drivers/lightos.py", line 669, in create_volume\n    return self._create_volume(volume, src_snapshot_lightos_name=None)\n', '  File "/var/lib/kolla/venv/lib/python3.10/site-packages/cinder/volume/drivers/lightos.py", line 734, in _create_volume\n    raise exception.VolumeBackendAPIException(message=msg)\n', 'cinder.exception.VolumeBackendAPIException: Did not succeed creating LightOS volume with UUID b51ea50d-2b3b-4965-ae0f-d6b5a7270b06 status_code 200 last state Creating\n']
2025-03-10 18:38:45.583 7 ERROR cinder.scheduler.filter_scheduler [None req-0304f007-614d-4bc0-bcc6-9ebf0b6c4ad7 bc186dfb2ca848938dc6cf6aaaf874dc 11ff2e7870264c49be9f37ac0962f991 - - - -] Error scheduling f33b7ff9-a56e-4022-a4c0-475d741552e9 from last vol-service: rack11-server76@LIGHTOShwlzto#hwlzto : ['Traceback (most recent call last):\n', '  File "/var/lib/kolla/venv/lib/python3.10/site-packages/taskflow/engines/action_engine/executor.py", line 52, in _execute_task\n    result = task.execute(**arguments)\n', '  File "/var/lib/kolla/venv/lib/python3.10/site-packages/cinder/volume/flows/manager/create_volume.py", line 1235, in execute\n    model_update = self._create_raw_volume(\n', '  File "/var/lib/kolla/venv/lib/python3.10/site-packages/cinder/volume/flows/manager/create_volume.py", line 1198, in _create_raw_volume\n    with excutils.save_and_reraise_exception():\n', '  File "/var/lib/kolla/venv/lib/python3.10/site-packages/oslo_utils/excutils.py", line 227, in __exit__\n    self.force_reraise()\n', '  File "/var/lib/kolla/venv/lib/python3.10/site-packages/oslo_utils/excutils.py", line 200, in force_reraise\n    raise self.value\n', '  File "/var/lib/kolla/venv/lib/python3.10/site-packages/cinder/volume/flows/manager/create_volume.py", line 1196, in _create_raw_volume\n    ret = self.driver.create_volume(volume)\n', '  File "/var/lib/kolla/venv/lib/python3.10/site-packages/cinder/volume/drivers/lightos.py", line 669, in create_volume\n    return self._create_volume(volume, src_snapshot_lightos_name=None)\n', '  File "/var/lib/kolla/venv/lib/python3.10/site-packages/cinder/volume/drivers/lightos.py", line 734, in _create_volume\n    raise exception.VolumeBackendAPIException(message=msg)\n', 'cinder.exception.VolumeBackendAPIException: Did not succeed creating LightOS volume with UUID b370e2a0-cac1-462d-aeb4-684eac253a3d status_code 200 last state Creating\n']
2025-03-10 18:40:26.776 7 ERROR cinder.scheduler.filter_scheduler [None req-01e2b067-3611-4782-b512-38c9b829437a a2f58e193a7b49fda8eda6fa08c4b7f2 5b2e175f05674ce1b480d20bd359cd5f - - - -] Error scheduling 37da9c40-631c-4847-a28c-9b3ae5eb704b from last vol-service: rack11-server76@LIGHTOShwlzto#hwlzto : ['Traceback (most recent call last):\n', '  File "/var/lib/kolla/venv/lib/python3.10/site-packages/taskflow/engines/action_engine/executor.py", line 52, in _execute_task\n    result = task.execute(**arguments)\n', '  File "/var/lib/kolla/venv/lib/python3.10/site-packages/cinder/volume/flows/manager/create_volume.py", line 1235, in execute\n    model_update = self._create_raw_volume(\n', '  File "/var/lib/kolla/venv/lib/python3.10/site-packages/cinder/volume/flows/manager/create_volume.py", line 1198, in _create_raw_volume\n    with excutils.save_and_reraise_exception():\n', '  File "/var/lib/kolla/venv/lib/python3.10/site-packages/oslo_utils/excutils.py", line 227, in __exit__\n    self.force_reraise()\n', '  File "/var/lib/kolla/venv/lib/python3.10/site-packages/oslo_utils/excutils.py", line 200, in force_reraise\n    raise self.value\n', '  File "/var/lib/kolla/venv/lib/python3.10/site-packages/cinder/volume/flows/manager/create_volume.py", line 1196, in _create_raw_volume\n    ret = self.driver.create_volume(volume)\n', '  File "/var/lib/kolla/venv/lib/python3.10/site-packages/cinder/volume/drivers/lightos.py", line 669, in create_volume\n    return self._create_volume(volume, src_snapshot_lightos_name=None)\n', '  File "/var/lib/kolla/venv/lib/python3.10/site-packages/cinder/volume/drivers/lightos.py", line 734, in _create_volume\n    raise exception.VolumeBackendAPIException(message=msg)\n', 'cinder.exception.VolumeBackendAPIException: Did not succeed creating LightOS volume with UUID b51ea50d-2b3b-4965-ae0f-d6b5a7270b06 status_code 200 last state Deleting\n']
2025-03-10 18:40:26.777 7 INFO cinder.message.api [None req-01e2b067-3611-4782-b512-38c9b829437a a2f58e193a7b49fda8eda6fa08c4b7f2 5b2e175f05674ce1b480d20bd359cd5f - - - -] Creating message record for request_id = req-01e2b067-3611-4782-b512-38c9b829437a
2025-03-10 18:40:26.797 7 ERROR cinder.scheduler.flows.create_volume [None req-01e2b067-3611-4782-b512-38c9b829437a a2f58e193a7b49fda8eda6fa08c4b7f2 5b2e175f05674ce1b480d20bd359cd5f - - - -] Failed to run task cinder.scheduler.flows.create_volume.ScheduleCreateVolumeTask;volume:create: No valid backend was found. Exceeded max scheduling attempts 3 for resource 37da9c40-631c-4847-a28c-9b3ae5eb704b: cinder.exception.NoValidBackend: No valid backend was found. Exceeded max scheduling attempts 3 for resource 37da9c40-631c-4847-a28c-9b3ae5eb704b
2025-03-10 18:41:10.983 7 ERROR cinder.scheduler.filter_scheduler [None req-6d29e5b3-db4f-4668-89ec-314e4c83c942 10444f1f00ac497ba564a22871140b9b a6e06ef4368e4b4a94fba95218796f4e - - - -] Error scheduling 25ec4a62-b1bb-49e6-8b4f-f93f2ba81add from last vol-service: rack11-server76@LIGHTOShwlzto#hwlzto : ['Traceback (most recent call last):\n', '  File "/var/lib/kolla/venv/lib/python3.10/site-packages/taskflow/engines/action_engine/executor.py", line 52, in _execute_task\n    result = task.execute(**arguments)\n', '  File "/var/lib/kolla/venv/lib/python3.10/site-packages/cinder/volume/flows/manager/create_volume.py", line 1235, in execute\n    model_update = self._create_raw_volume(\n', '  File "/var/lib/kolla/venv/lib/python3.10/site-packages/cinder/volume/flows/manager/create_volume.py", line 1198, in _create_raw_volume\n    with excutils.save_and_reraise_exception():\n', '  File "/var/lib/kolla/venv/lib/python3.10/site-packages/oslo_utils/excutils.py", line 227, in __exit__\n    self.force_reraise()\n', '  File "/var/lib/kolla/venv/lib/python3.10/site-packages/oslo_utils/excutils.py", line 200, in force_reraise\n    raise self.value\n', '  File "/var/lib/kolla/venv/lib/python3.10/site-packages/cinder/volume/flows/manager/create_volume.py", line 1196, in _create_raw_volume\n    ret = self.driver.create_volume(volume)\n', '  File "/var/lib/kolla/venv/lib/python3.10/site-packages/cinder/volume/drivers/lightos.py", line 669, in create_volume\n    return self._create_volume(volume, src_snapshot_lightos_name=None)\n', '  File "/var/lib/kolla/venv/lib/python3.10/site-packages/cinder/volume/drivers/lightos.py", line 693, in _create_volume\n    status_code, resp = self._create_new_lightos_volume(\n', '  File "/var/lib/kolla/venv/lib/python3.10/site-packages/cinder/volume/drivers/lightos.py", line 630, in _create_new_lightos_volume\n    return self.cluster.send_cmd(\n', '  File "/var/lib/kolla/venv/lib/python3.10/site-packages/cinder/volume/drivers/lightos.py", line 318, in send_cmd\n    raise exception.VolumeDriverException(\n', 'cinder.exception.VolumeDriverException: Volume driver reported an error: Could not get a response from any API server\n']
2025-03-10 18:42:41.253 7 ERROR cinder.scheduler.filter_scheduler [None req-6d29e5b3-db4f-4668-89ec-314e4c83c942 10444f1f00ac497ba564a22871140b9b a6e06ef4368e4b4a94fba95218796f4e - - - -] Error scheduling 25ec4a62-b1bb-49e6-8b4f-f93f2ba81add from last vol-service: rack11-server76@LIGHTOShwlzto#hwlzto : ['Traceback (most recent call last):\n', '  File "/var/lib/kolla/venv/lib/python3.10/site-packages/taskflow/engines/action_engine/executor.py", line 52, in _execute_task\n    result = task.execute(**arguments)\n', '  File "/var/lib/kolla/venv/lib/python3.10/site-packages/cinder/volume/flows/manager/create_volume.py", line 1235, in execute\n    model_update = self._create_raw_volume(\n', '  File "/var/lib/kolla/venv/lib/python3.10/site-packages/cinder/volume/flows/manager/create_volume.py", line 1198, in _create_raw_volume\n    with excutils.save_and_reraise_exception():\n', '  File "/var/lib/kolla/venv/lib/python3.10/site-packages/oslo_utils/excutils.py", line 227, in __exit__\n    self.force_reraise()\n', '  File "/var/lib/kolla/venv/lib/python3.10/site-packages/oslo_utils/excutils.py", line 200, in force_reraise\n    raise self.value\n', '  File "/var/lib/kolla/venv/lib/python3.10/site-packages/cinder/volume/flows/manager/create_volume.py", line 1196, in _create_raw_volume\n    ret = self.driver.create_volume(volume)\n', '  File "/var/lib/kolla/venv/lib/python3.10/site-packages/cinder/volume/drivers/lightos.py", line 669, in create_volume\n    return self._create_volume(volume, src_snapshot_lightos_name=None)\n', '  File "/var/lib/kolla/venv/lib/python3.10/site-packages/cinder/volume/drivers/lightos.py", line 693, in _create_volume\n    status_code, resp = self._create_new_lightos_volume(\n', '  File "/var/lib/kolla/venv/lib/python3.10/site-packages/cinder/volume/drivers/lightos.py", line 630, in _create_new_lightos_volume\n    return self.cluster.send_cmd(\n', '  File "/var/lib/kolla/venv/lib/python3.10/site-packages/cinder/volume/drivers/lightos.py", line 318, in send_cmd\n    raise exception.VolumeDriverException(\n', 'cinder.exception.VolumeDriverException: Volume driver reported an error: Could not get a response from any API server\n']
2025-03-10 18:44:03.517 7 ERROR cinder.scheduler.filter_scheduler [None req-70456bba-4316-45e0-b17d-6062e3159acf 24718f50645f4baeae0961d1366e5371 5a740b39fc774065b3900d5d117d9ecf - - - -] Error scheduling 43b6ed7e-0084-44fb-b989-546854c1615c from last vol-service: rack11-server76@LIGHTOShwlzto#hwlzto : ['Traceback (most recent call last):\n', '  File "/var/lib/kolla/venv/lib/python3.10/site-packages/taskflow/engines/action_engine/executor.py", line 52, in _execute_task\n    result = task.execute(**arguments)\n', '  File "/var/lib/kolla/venv/lib/python3.10/site-packages/cinder/volume/flows/manager/create_volume.py", line 1235, in execute\n    model_update = self._create_raw_volume(\n', '  File "/var/lib/kolla/venv/lib/python3.10/site-packages/cinder/volume/flows/manager/create_volume.py", line 1198, in _create_raw_volume\n    with excutils.save_and_reraise_exception():\n', '  File "/var/lib/kolla/venv/lib/python3.10/site-packages/oslo_utils/excutils.py", line 227, in __exit__\n    self.force_reraise()\n', '  File "/var/lib/kolla/venv/lib/python3.10/site-packages/oslo_utils/excutils.py", line 200, in force_reraise\n    raise self.value\n', '  File "/var/lib/kolla/venv/lib/python3.10/site-packages/cinder/volume/flows/manager/create_volume.py", line 1196, in _create_raw_volume\n    ret = self.driver.create_volume(volume)\n', '  File "/var/lib/kolla/venv/lib/python3.10/site-packages/cinder/volume/drivers/lightos.py", line 669, in create_volume\n    return self._create_volume(volume, src_snapshot_lightos_name=None)\n', '  File "/var/lib/kolla/venv/lib/python3.10/site-packages/cinder/volume/drivers/lightos.py", line 734, in _create_volume\n    raise exception.VolumeBackendAPIException(message=msg)\n', 'cinder.exception.VolumeBackendAPIException: Did not succeed creating LightOS volume with UUID 8a3bbe33-41b3-4dfe-b804-943151b5e3d8 status_code 200 last state Creating\n']
2025-03-10 18:44:11.498 7 ERROR cinder.scheduler.filter_scheduler [None req-6d29e5b3-db4f-4668-89ec-314e4c83c942 10444f1f00ac497ba564a22871140b9b a6e06ef4368e4b4a94fba95218796f4e - - - -] Error scheduling 25ec4a62-b1bb-49e6-8b4f-f93f2ba81add from last vol-service: rack11-server76@LIGHTOShwlzto#hwlzto : ['Traceback (most recent call last):\n', '  File "/var/lib/kolla/venv/lib/python3.10/site-packages/taskflow/engines/action_engine/executor.py", line 52, in _execute_task\n    result = task.execute(**arguments)\n', '  File "/var/lib/kolla/venv/lib/python3.10/site-packages/cinder/volume/flows/manager/create_volume.py", line 1235, in execute\n    model_update = self._create_raw_volume(\n', '  File "/var/lib/kolla/venv/lib/python3.10/site-packages/cinder/volume/flows/manager/create_volume.py", line 1198, in _create_raw_volume\n    with excutils.save_and_reraise_exception():\n', '  File "/var/lib/kolla/venv/lib/python3.10/site-packages/oslo_utils/excutils.py", line 227, in __exit__\n    self.force_reraise()\n', '  File "/var/lib/kolla/venv/lib/python3.10/site-packages/oslo_utils/excutils.py", line 200, in force_reraise\n    raise self.value\n', '  File "/var/lib/kolla/venv/lib/python3.10/site-packages/cinder/volume/flows/manager/create_volume.py", line 1196, in _create_raw_volume\n    ret = self.driver.create_volume(volume)\n', '  File "/var/lib/kolla/venv/lib/python3.10/site-packages/cinder/volume/drivers/lightos.py", line 669, in create_volume\n    return self._create_volume(volume, src_snapshot_lightos_name=None)\n', '  File "/var/lib/kolla/venv/lib/python3.10/site-packages/cinder/volume/drivers/lightos.py", line 693, in _create_volume\n    status_code, resp = self._create_new_lightos_volume(\n', '  File "/var/lib/kolla/venv/lib/python3.10/site-packages/cinder/volume/drivers/lightos.py", line 630, in _create_new_lightos_volume\n    return self.cluster.send_cmd(\n', '  File "/var/lib/kolla/venv/lib/python3.10/site-packages/cinder/volume/drivers/lightos.py", line 318, in send_cmd\n    raise exception.VolumeDriverException(\n', 'cinder.exception.VolumeDriverException: Volume driver reported an error: Could not get a response from any API server\n']
2025-03-10 18:44:11.498 7 INFO cinder.message.api [None req-6d29e5b3-db4f-4668-89ec-314e4c83c942 10444f1f00ac497ba564a22871140b9b a6e06ef4368e4b4a94fba95218796f4e - - - -] Creating message record for request_id = req-6d29e5b3-db4f-4668-89ec-314e4c83c942
2025-03-10 18:44:11.507 7 ERROR cinder.scheduler.flows.create_volume [None req-6d29e5b3-db4f-4668-89ec-314e4c83c942 10444f1f00ac497ba564a22871140b9b a6e06ef4368e4b4a94fba95218796f4e - - - -] Failed to run task cinder.scheduler.flows.create_volume.ScheduleCreateVolumeTask;volume:create: No valid backend was found. Exceeded max scheduling attempts 3 for resource 25ec4a62-b1bb-49e6-8b4f-f93f2ba81add: cinder.exception.NoValidBackend: No valid backend was found. Exceeded max scheduling attempts 3 for resource 25ec4a62-b1bb-49e6-8b4f-f93f2ba81add
2025-03-10 18:45:29.285 7 ERROR cinder.scheduler.filter_scheduler [None req-70456bba-4316-45e0-b17d-6062e3159acf 24718f50645f4baeae0961d1366e5371 5a740b39fc774065b3900d5d117d9ecf - - - -] Error scheduling 43b6ed7e-0084-44fb-b989-546854c1615c from last vol-service: rack11-server76@LIGHTOShwlzto#hwlzto : ['Traceback (most recent call last):\n', '  File "/var/lib/kolla/venv/lib/python3.10/site-packages/taskflow/engines/action_engine/executor.py", line 52, in _execute_task\n    result = task.execute(**arguments)\n', '  File "/var/lib/kolla/venv/lib/python3.10/site-packages/cinder/volume/flows/manager/create_volume.py", line 1235, in execute\n    model_update = self._create_raw_volume(\n', '  File "/var/lib/kolla/venv/lib/python3.10/site-packages/cinder/volume/flows/manager/create_volume.py", line 1198, in _create_raw_volume\n    with excutils.save_and_reraise_exception():\n', '  File "/var/lib/kolla/venv/lib/python3.10/site-packages/oslo_utils/excutils.py", line 227, in __exit__\n    self.force_reraise()\n', '  File "/var/lib/kolla/venv/lib/python3.10/site-packages/oslo_utils/excutils.py", line 200, in force_reraise\n    raise self.value\n', '  File "/var/lib/kolla/venv/lib/python3.10/site-packages/cinder/volume/flows/manager/create_volume.py", line 1196, in _create_raw_volume\n    ret = self.driver.create_volume(volume)\n', '  File "/var/lib/kolla/venv/lib/python3.10/site-packages/cinder/volume/drivers/lightos.py", line 669, in create_volume\n    return self._create_volume(volume, src_snapshot_lightos_name=None)\n', '  File "/var/lib/kolla/venv/lib/python3.10/site-packages/cinder/volume/drivers/lightos.py", line 701, in _create_volume\n    vol_state = self._wait_for_volume_available(\n', '  File "/var/lib/kolla/venv/lib/python3.10/site-packages/cinder/volume/drivers/lightos.py", line 580, in _wait_for_volume_available\n    resp) = self._get_lightos_volume(project_name,\n', '  File "/var/lib/kolla/venv/lib/python3.10/site-packages/cinder/volume/drivers/lightos.py", line 503, in _get_lightos_volume\n    return self.cluster.send_cmd(\n', '  File "/var/lib/kolla/venv/lib/python3.10/site-packages/cinder/volume/drivers/lightos.py", line 318, in send_cmd\n    raise exception.VolumeDriverException(\n', 'cinder.exception.VolumeDriverException: Volume driver reported an error: Could not get a response from any API server\n']
2025-03-10 18:47:15.829 7 ERROR cinder.scheduler.filter_scheduler [None req-cca1008b-cd44-41bd-b751-3288150dd1fe 59ef7d11058f41d7a4b4a4c28bb76b7f 5b8fff427a4144eb8a2972dd69b23c2b - - - -] Error scheduling fb87541a-46ec-4e84-aa39-abae1e69b585 from last vol-service: rack11-server76@LIGHTOShwlzto#hwlzto : ['Traceback (most recent call last):\n', '  File "/var/lib/kolla/venv/lib/python3.10/site-packages/taskflow/engines/action_engine/executor.py", line 52, in _execute_task\n    result = task.execute(**arguments)\n', '  File "/var/lib/kolla/venv/lib/python3.10/site-packages/cinder/volume/flows/manager/create_volume.py", line 1235, in execute\n    model_update = self._create_raw_volume(\n', '  File "/var/lib/kolla/venv/lib/python3.10/site-packages/cinder/volume/flows/manager/create_volume.py", line 1198, in _create_raw_volume\n    with excutils.save_and_reraise_exception():\n', '  File "/var/lib/kolla/venv/lib/python3.10/site-packages/oslo_utils/excutils.py", line 227, in __exit__\n    self.force_reraise()\n', '  File "/var/lib/kolla/venv/lib/python3.10/site-packages/oslo_utils/excutils.py", line 200, in force_reraise\n    raise self.value\n', '  File "/var/lib/kolla/venv/lib/python3.10/site-packages/cinder/volume/flows/manager/create_volume.py", line 1196, in _create_raw_volume\n    ret = self.driver.create_volume(volume)\n', '  File "/var/lib/kolla/venv/lib/python3.10/site-packages/cinder/volume/drivers/lightos.py", line 669, in create_volume\n    return self._create_volume(volume, src_snapshot_lightos_name=None)\n', '  File "/var/lib/kolla/venv/lib/python3.10/site-packages/cinder/volume/drivers/lightos.py", line 693, in _create_volume\n    status_code, resp = self._create_new_lightos_volume(\n', '  File "/var/lib/kolla/venv/lib/python3.10/site-packages/cinder/volume/drivers/lightos.py", line 630, in _create_new_lightos_volume\n    return self.cluster.send_cmd(\n', '  File "/var/lib/kolla/venv/lib/python3.10/site-packages/cinder/volume/drivers/lightos.py", line 318, in send_cmd\n    raise exception.VolumeDriverException(\n', 'cinder.exception.VolumeDriverException: Volume driver reported an error: Could not get a response from any API server\n']
2025-03-10 18:47:28.260 7 ERROR cinder.scheduler.filter_scheduler [None req-b2243eaa-b656-45a4-93ea-cfd669eac81e 10444f1f00ac497ba564a22871140b9b a6e06ef4368e4b4a94fba95218796f4e - - - -] Error scheduling e1050a7b-3a33-4885-a919-678087d5e5e6 from last vol-service: rack11-server76@LIGHTOShwlzto#hwlzto : ['Traceback (most recent call last):\n', '  File "/var/lib/kolla/venv/lib/python3.10/site-packages/taskflow/engines/action_engine/executor.py", line 52, in _execute_task\n    result = task.execute(**arguments)\n', '  File "/var/lib/kolla/venv/lib/python3.10/site-packages/cinder/volume/flows/manager/create_volume.py", line 1235, in execute\n    model_update = self._create_raw_volume(\n', '  File "/var/lib/kolla/venv/lib/python3.10/site-packages/cinder/volume/flows/manager/create_volume.py", line 1198, in _create_raw_volume\n    with excutils.save_and_reraise_exception():\n', '  File "/var/lib/kolla/venv/lib/python3.10/site-packages/oslo_utils/excutils.py", line 227, in __exit__\n    self.force_reraise()\n', '  File "/var/lib/kolla/venv/lib/python3.10/site-packages/oslo_utils/excutils.py", line 200, in force_reraise\n    raise self.value\n', '  File "/var/lib/kolla/venv/lib/python3.10/site-packages/cinder/volume/flows/manager/create_volume.py", line 1196, in _create_raw_volume\n    ret = self.driver.create_volume(volume)\n', '  File "/var/lib/kolla/venv/lib/python3.10/site-packages/cinder/volume/drivers/lightos.py", line 669, in create_volume\n    return self._create_volume(volume, src_snapshot_lightos_name=None)\n', '  File "/var/lib/kolla/venv/lib/python3.10/site-packages/cinder/volume/drivers/lightos.py", line 693, in _create_volume\n    status_code, resp = self._create_new_lightos_volume(\n', '  File "/var/lib/kolla/venv/lib/python3.10/site-packages/cinder/volume/drivers/lightos.py", line 630, in _create_new_lightos_volume\n    return self.cluster.send_cmd(\n', '  File "/var/lib/kolla/venv/lib/python3.10/site-packages/cinder/volume/drivers/lightos.py", line 318, in send_cmd\n    raise exception.VolumeDriverException(\n', 'cinder.exception.VolumeDriverException: Volume driver reported an error: Could not get a response from any API server\n']
2025-03-10 18:48:46.065 7 ERROR cinder.scheduler.filter_scheduler [None req-cca1008b-cd44-41bd-b751-3288150dd1fe 59ef7d11058f41d7a4b4a4c28bb76b7f 5b8fff427a4144eb8a2972dd69b23c2b - - - -] Error scheduling fb87541a-46ec-4e84-aa39-abae1e69b585 from last vol-service: rack11-server76@LIGHTOShwlzto#hwlzto : ['Traceback (most recent call last):\n', '  File "/var/lib/kolla/venv/lib/python3.10/site-packages/taskflow/engines/action_engine/executor.py", line 52, in _execute_task\n    result = task.execute(**arguments)\n', '  File "/var/lib/kolla/venv/lib/python3.10/site-packages/cinder/volume/flows/manager/create_volume.py", line 1235, in execute\n    model_update = self._create_raw_volume(\n', '  File "/var/lib/kolla/venv/lib/python3.10/site-packages/cinder/volume/flows/manager/create_volume.py", line 1198, in _create_raw_volume\n    with excutils.save_and_reraise_exception():\n', '  File "/var/lib/kolla/venv/lib/python3.10/site-packages/oslo_utils/excutils.py", line 227, in __exit__\n    self.force_reraise()\n', '  File "/var/lib/kolla/venv/lib/python3.10/site-packages/oslo_utils/excutils.py", line 200, in force_reraise\n    raise self.value\n', '  File "/var/lib/kolla/venv/lib/python3.10/site-packages/cinder/volume/flows/manager/create_volume.py", line 1196, in _create_raw_volume\n    ret = self.driver.create_volume(volume)\n', '  File "/var/lib/kolla/venv/lib/python3.10/site-packages/cinder/volume/drivers/lightos.py", line 669, in create_volume\n    return self._create_volume(volume, src_snapshot_lightos_name=None)\n', '  File "/var/lib/kolla/venv/lib/python3.10/site-packages/cinder/volume/drivers/lightos.py", line 693, in _create_volume\n    status_code, resp = self._create_new_lightos_volume(\n', '  File "/var/lib/kolla/venv/lib/python3.10/site-packages/cinder/volume/drivers/lightos.py", line 630, in _create_new_lightos_volume\n    return self.cluster.send_cmd(\n', '  File "/var/lib/kolla/venv/lib/python3.10/site-packages/cinder/volume/drivers/lightos.py", line 318, in send_cmd\n    raise exception.VolumeDriverException(\n', 'cinder.exception.VolumeDriverException: Volume driver reported an error: Could not get a response from any API server\n']
2025-03-10 18:48:58.523 7 ERROR cinder.scheduler.filter_scheduler [None req-b2243eaa-b656-45a4-93ea-cfd669eac81e 10444f1f00ac497ba564a22871140b9b a6e06ef4368e4b4a94fba95218796f4e - - - -] Error scheduling e1050a7b-3a33-4885-a919-678087d5e5e6 from last vol-service: rack11-server76@LIGHTOShwlzto#hwlzto : ['Traceback (most recent call last):\n', '  File "/var/lib/kolla/venv/lib/python3.10/site-packages/taskflow/engines/action_engine/executor.py", line 52, in _execute_task\n    result = task.execute(**arguments)\n', '  File "/var/lib/kolla/venv/lib/python3.10/site-packages/cinder/volume/flows/manager/create_volume.py", line 1235, in execute\n    model_update = self._create_raw_volume(\n', '  File "/var/lib/kolla/venv/lib/python3.10/site-packages/cinder/volume/flows/manager/create_volume.py", line 1198, in _create_raw_volume\n    with excutils.save_and_reraise_exception():\n', '  File "/var/lib/kolla/venv/lib/python3.10/site-packages/oslo_utils/excutils.py", line 227, in __exit__\n    self.force_reraise()\n', '  File "/var/lib/kolla/venv/lib/python3.10/site-packages/oslo_utils/excutils.py", line 200, in force_reraise\n    raise self.value\n', '  File "/var/lib/kolla/venv/lib/python3.10/site-packages/cinder/volume/flows/manager/create_volume.py", line 1196, in _create_raw_volume\n    ret = self.driver.create_volume(volume)\n', '  File "/var/lib/kolla/venv/lib/python3.10/site-packages/cinder/volume/drivers/lightos.py", line 669, in create_volume\n    return self._create_volume(volume, src_snapshot_lightos_name=None)\n', '  File "/var/lib/kolla/venv/lib/python3.10/site-packages/cinder/volume/drivers/lightos.py", line 693, in _create_volume\n    status_code, resp = self._create_new_lightos_volume(\n', '  File "/var/lib/kolla/venv/lib/python3.10/site-packages/cinder/volume/drivers/lightos.py", line 630, in _create_new_lightos_volume\n    return self.cluster.send_cmd(\n', '  File "/var/lib/kolla/venv/lib/python3.10/site-packages/cinder/volume/drivers/lightos.py", line 318, in send_cmd\n    raise exception.VolumeDriverException(\n', 'cinder.exception.VolumeDriverException: Volume driver reported an error: Could not get a response from any API server\n']
2025-03-10 18:48:58.550 7 ERROR cinder.scheduler.filter_scheduler [None req-70456bba-4316-45e0-b17d-6062e3159acf 24718f50645f4baeae0961d1366e5371 5a740b39fc774065b3900d5d117d9ecf - - - -] Error scheduling 43b6ed7e-0084-44fb-b989-546854c1615c from last vol-service: rack11-server76@LIGHTOShwlzto#hwlzto : ['Traceback (most recent call last):\n', '  File "/var/lib/kolla/venv/lib/python3.10/site-packages/taskflow/engines/action_engine/executor.py", line 52, in _execute_task\n    result = task.execute(**arguments)\n', '  File "/var/lib/kolla/venv/lib/python3.10/site-packages/cinder/volume/flows/manager/create_volume.py", line 1235, in execute\n    model_update = self._create_raw_volume(\n', '  File "/var/lib/kolla/venv/lib/python3.10/site-packages/cinder/volume/flows/manager/create_volume.py", line 1198, in _create_raw_volume\n    with excutils.save_and_reraise_exception():\n', '  File "/var/lib/kolla/venv/lib/python3.10/site-packages/oslo_utils/excutils.py", line 227, in __exit__\n    self.force_reraise()\n', '  File "/var/lib/kolla/venv/lib/python3.10/site-packages/oslo_utils/excutils.py", line 200, in force_reraise\n    raise self.value\n', '  File "/var/lib/kolla/venv/lib/python3.10/site-packages/cinder/volume/flows/manager/create_volume.py", line 1196, in _create_raw_volume\n    ret = self.driver.create_volume(volume)\n', '  File "/var/lib/kolla/venv/lib/python3.10/site-packages/cinder/volume/drivers/lightos.py", line 669, in create_volume\n    return self._create_volume(volume, src_snapshot_lightos_name=None)\n', '  File "/var/lib/kolla/venv/lib/python3.10/site-packages/cinder/volume/drivers/lightos.py", line 726, in _create_volume\n    self._delete_lightos_volume(project_name, lightos_uuid)\n', '  File "/var/lib/kolla/venv/lib/python3.10/site-packages/cinder/volume/drivers/lightos.py", line 813, in _delete_lightos_volume\n    self.cluster.send_cmd(\n', '  File "/var/lib/kolla/venv/lib/python3.10/site-packages/cinder/volume/drivers/lightos.py", line 318, in send_cmd\n    raise exception.VolumeDriverException(\n', 'cinder.exception.VolumeDriverException: Volume driver reported an error: Could not get a response from any API server\n']
2025-03-10 18:48:58.551 7 INFO cinder.message.api [None req-70456bba-4316-45e0-b17d-6062e3159acf 24718f50645f4baeae0961d1366e5371 5a740b39fc774065b3900d5d117d9ecf - - - -] Creating message record for request_id = req-70456bba-4316-45e0-b17d-6062e3159acf
2025-03-10 18:48:58.566 7 ERROR cinder.scheduler.flows.create_volume [None req-70456bba-4316-45e0-b17d-6062e3159acf 24718f50645f4baeae0961d1366e5371 5a740b39fc774065b3900d5d117d9ecf - - - -] Failed to run task cinder.scheduler.flows.create_volume.ScheduleCreateVolumeTask;volume:create: No valid backend was found. Exceeded max scheduling attempts 3 for resource 43b6ed7e-0084-44fb-b989-546854c1615c: cinder.exception.NoValidBackend: No valid backend was found. Exceeded max scheduling attempts 3 for resource 43b6ed7e-0084-44fb-b989-546854c1615c
2025-03-10 18:51:57.326 7 ERROR cinder.scheduler.filter_scheduler [None req-b2243eaa-b656-45a4-93ea-cfd669eac81e 10444f1f00ac497ba564a22871140b9b a6e06ef4368e4b4a94fba95218796f4e - - - -] Error scheduling e1050a7b-3a33-4885-a919-678087d5e5e6 from last vol-service: rack11-server76@LIGHTOShwlzto#hwlzto : ['Traceback (most recent call last):\n', '  File "/var/lib/kolla/venv/lib/python3.10/site-packages/taskflow/engines/action_engine/executor.py", line 52, in _execute_task\n    result = task.execute(**arguments)\n', '  File "/var/lib/kolla/venv/lib/python3.10/site-packages/cinder/volume/flows/manager/create_volume.py", line 1235, in execute\n    model_update = self._create_raw_volume(\n', '  File "/var/lib/kolla/venv/lib/python3.10/site-packages/cinder/volume/flows/manager/create_volume.py", line 1198, in _create_raw_volume\n    with excutils.save_and_reraise_exception():\n', '  File "/var/lib/kolla/venv/lib/python3.10/site-packages/oslo_utils/excutils.py", line 227, in __exit__\n    self.force_reraise()\n', '  File "/var/lib/kolla/venv/lib/python3.10/site-packages/oslo_utils/excutils.py", line 200, in force_reraise\n    raise self.value\n', '  File "/var/lib/kolla/venv/lib/python3.10/site-packages/cinder/volume/flows/manager/create_volume.py", line 1196, in _create_raw_volume\n    ret = self.driver.create_volume(volume)\n', '  File "/var/lib/kolla/venv/lib/python3.10/site-packages/cinder/volume/drivers/lightos.py", line 669, in create_volume\n    return self._create_volume(volume, src_snapshot_lightos_name=None)\n', '  File "/var/lib/kolla/venv/lib/python3.10/site-packages/cinder/volume/drivers/lightos.py", line 726, in _create_volume\n    self._delete_lightos_volume(project_name, lightos_uuid)\n', '  File "/var/lib/kolla/venv/lib/python3.10/site-packages/cinder/volume/drivers/lightos.py", line 813, in _delete_lightos_volume\n    self.cluster.send_cmd(\n', '  File "/var/lib/kolla/venv/lib/python3.10/site-packages/cinder/volume/drivers/lightos.py", line 318, in send_cmd\n    raise exception.VolumeDriverException(\n', 'cinder.exception.VolumeDriverException: Volume driver reported an error: Could not get a response from any API server\n']
2025-03-10 18:51:57.328 7 INFO cinder.message.api [None req-b2243eaa-b656-45a4-93ea-cfd669eac81e 10444f1f00ac497ba564a22871140b9b a6e06ef4368e4b4a94fba95218796f4e - - - -] Creating message record for request_id = req-b2243eaa-b656-45a4-93ea-cfd669eac81e
2025-03-10 18:51:57.337 7 ERROR cinder.scheduler.flows.create_volume [None req-b2243eaa-b656-45a4-93ea-cfd669eac81e 10444f1f00ac497ba564a22871140b9b a6e06ef4368e4b4a94fba95218796f4e - - - -] Failed to run task cinder.scheduler.flows.create_volume.ScheduleCreateVolumeTask;volume:create: No valid backend was found. Exceeded max scheduling attempts 3 for resource e1050a7b-3a33-4885-a919-678087d5e5e6: cinder.exception.NoValidBackend: No valid backend was found. Exceeded max scheduling attempts 3 for resource e1050a7b-3a33-4885-a919-678087d5e5e6
2025-03-10 18:52:31.270 7 ERROR cinder.scheduler.filter_scheduler [None req-cca1008b-cd44-41bd-b751-3288150dd1fe 59ef7d11058f41d7a4b4a4c28bb76b7f 5b8fff427a4144eb8a2972dd69b23c2b - - - -] Error scheduling fb87541a-46ec-4e84-aa39-abae1e69b585 from last vol-service: rack11-server76@LIGHTOShwlzto#hwlzto : ['Traceback (most recent call last):\n', '  File "/var/lib/kolla/venv/lib/python3.10/site-packages/taskflow/engines/action_engine/executor.py", line 52, in _execute_task\n    result = task.execute(**arguments)\n', '  File "/var/lib/kolla/venv/lib/python3.10/site-packages/cinder/volume/flows/manager/create_volume.py", line 1235, in execute\n    model_update = self._create_raw_volume(\n', '  File "/var/lib/kolla/venv/lib/python3.10/site-packages/cinder/volume/flows/manager/create_volume.py", line 1198, in _create_raw_volume\n    with excutils.save_and_reraise_exception():\n', '  File "/var/lib/kolla/venv/lib/python3.10/site-packages/oslo_utils/excutils.py", line 227, in __exit__\n    self.force_reraise()\n', '  File "/var/lib/kolla/venv/lib/python3.10/site-packages/oslo_utils/excutils.py", line 200, in force_reraise\n    raise self.value\n', '  File "/var/lib/kolla/venv/lib/python3.10/site-packages/cinder/volume/flows/manager/create_volume.py", line 1196, in _create_raw_volume\n    ret = self.driver.create_volume(volume)\n', '  File "/var/lib/kolla/venv/lib/python3.10/site-packages/cinder/volume/drivers/lightos.py", line 669, in create_volume\n    return self._create_volume(volume, src_snapshot_lightos_name=None)\n', '  File "/var/lib/kolla/venv/lib/python3.10/site-packages/cinder/volume/drivers/lightos.py", line 734, in _create_volume\n    raise exception.VolumeBackendAPIException(message=msg)\n', 'cinder.exception.VolumeBackendAPIException: Did not succeed creating LightOS volume with UUID 8b837163-140c-4a67-8d25-1a983f9e88b8 status_code 200 last state Creating\n']
2025-03-10 18:52:31.271 7 INFO cinder.message.api [None req-cca1008b-cd44-41bd-b751-3288150dd1fe 59ef7d11058f41d7a4b4a4c28bb76b7f 5b8fff427a4144eb8a2972dd69b23c2b - - - -] Creating message record for request_id = req-cca1008b-cd44-41bd-b751-3288150dd1fe
2025-03-10 18:52:31.281 7 ERROR cinder.scheduler.flows.create_volume [None req-cca1008b-cd44-41bd-b751-3288150dd1fe 59ef7d11058f41d7a4b4a4c28bb76b7f 5b8fff427a4144eb8a2972dd69b23c2b - - - -] Failed to run task cinder.scheduler.flows.create_volume.ScheduleCreateVolumeTask;volume:create: No valid backend was found. Exceeded max scheduling attempts 3 for resource fb87541a-46ec-4e84-aa39-abae1e69b585: cinder.exception.NoValidBackend: No valid backend was found. Exceeded max scheduling attempts 3 for resource fb87541a-46ec-4e84-aa39-abae1e69b585
